ts_recv,ts_event,rtype,publisher_id,instrument_id,action,side,price,size,channel_id,order_id,flags,ts_in_delta,sequence,symbol
2025-07-17T16:21:05.035171590Z,2025-07-17T16:21:05.035006249Z,160,2,1108,C,B,13.140000000,11,0,349100461,130,165341,290207081,ARL
2025-07-17T16:21:13.027776086Z,2025-07-17T16:21:13.027610071Z,160,2,1108,C,A,13.290000000,15,0,348428649,130,166015,290382552,ARL
2025-07-17T16:21:13.028208678Z,2025-07-17T16:21:13.028039954Z,160,2,1108,C,A,13.450000000,100,0,347605041,128,168724,290382699,ARL
2025-07-17T16:21:13.028616852Z,2025-07-17T16:21:13.028451265Z,160,2,1108,A,A,15.650000000,100,0,349364025,130,165587,290382792,ARL
2025-07-17T16:21:13.028629760Z,2025-07-17T16:21:13.028464223Z,160,2,1108,C,A,15.340000000,100,0,347605973,130,165537,290382794,ARL
2025-07-17T16:21:13.028929613Z,2025-07-17T16:21:13.028763898Z,160,2,1108,C,A,14.240000000,100,0,347760485,0,165715,290382878,ARL
2025-07-17T16:21:13.028929613Z,2025-07-17T16:21:13.028763898Z,160,2,1108,A,A,14.630000000,100,0,349364085,130,165715,290382878,ARL
2025-07-17T16:21:13.028960654Z,2025-07-17T16:21:13.028792918Z,160,2,1108,C,A,14.050000000,100,0,347605081,128,167736,290382883,ARL
2025-07-17T16:21:13.029314299Z,2025-07-17T16:21:13.029148929Z,160,2,1108,A,A,14.330000000,100,0,349364205,130,165370,290382993,ARL
2025-07-17T16:21:13.029395561Z,2025-07-17T16:21:13.029229862Z,160,2,1108,C,A,14.490000000,100,0,347605073,0,165699,290383014,ARL
2025-07-17T16:21:13.029395561Z,2025-07-17T16:21:13.029229862Z,160,2,1108,A,A,14.780000000,100,0,349364213,130,165699,290383014,ARL
2025-07-17T16:21:13.029433752Z,2025-07-17T16:21:13.029267150Z,160,2,1108,C,A,14.170000000,700,0,347717317,130,166602,290383019,ARL
2025-07-17T16:21:13.029461868Z,2025-07-17T16:21:13.029296174Z,160,2,1108,C,A,14.240000000,100,0,347760469,0,165694,290383027,ARL
2025-07-17T16:21:13.029461868Z,2025-07-17T16:21:13.029296174Z,160,2,1108,A,A,14.630000000,100,0,349364233,130,165694,290383027,ARL
2025-07-17T16:21:13.029500611Z,2025-07-17T16:21:13.029335284Z,160,2,1108,A,A,14.410000000,700,0,349364241,130,165327,290383043,ARL
2025-07-17T16:21:13.033525905Z,2025-07-17T16:21:13.033360385Z,160,2,1108,C,A,14.240000000,100,0,347605969,0,165520,290383910,ARL
2025-07-17T16:21:13.033525905Z,2025-07-17T16:21:13.033360385Z,160,2,1108,A,A,14.510000000,100,0,349364905,130,165520,290383910,ARL
2025-07-17T16:21:13.041339278Z,2025-07-17T16:21:13.041173935Z,160,2,1108,C,A,13.720000000,100,0,347605397,130,165343,290385083,ARL
2025-07-17T16:21:13.041376591Z,2025-07-17T16:21:13.041211567Z,160,2,1108,C,A,14.410000000,700,0,349364241,130,165024,290385085,ARL
2025-07-17T16:21:13.041396412Z,2025-07-17T16:21:13.041231123Z,160,2,1108,A,A,13.990000000,100,0,349365741,130,165289,290385086,ARL
2025-07-17T16:21:13.041424493Z,2025-07-17T16:21:13.041258565Z,160,2,1108,A,A,15.940000000,100,0,349365749,130,165928,290385092,ARL
2025-07-17T16:21:13.041438649Z,2025-07-17T16:21:13.041270862Z,160,2,1108,C,A,15.650000000,100,0,349364025,128,167787,290385094,ARL
2025-07-17T16:21:13.042377442Z,2025-07-17T16:21:13.042212059Z,160,2,1108,A,B,13.110000000,10,0,349365825,130,165383,290385162,ARL
2025-07-17T16:21:13.046254420Z,2025-07-17T16:21:13.046088887Z,160,2,1108,C,A,14.800000000,100,0,347605085,0,165533,290385477,ARL
2025-07-17T16:21:13.046254420Z,2025-07-17T16:21:13.046088887Z,160,2,1108,A,A,15.380000000,100,0,349366105,130,165533,290385477,ARL
2025-07-17T16:21:13.046293088Z,2025-07-17T16:21:13.046127777Z,160,2,1108,C,A,13.990000000,100,0,349365741,130,165311,290385480,ARL
2025-07-17T16:21:13.046345105Z,2025-07-17T16:21:13.046179769Z,160,2,1108,A,A,14.220000000,100,0,349366121,130,165336,290385481,ARL
2025-07-17T16:21:13.051207283Z,2025-07-17T16:21:13.051041384Z,160,2,1108,C,A,13.650000000,2,0,349094877,0,165899,290385730,ARL
2025-07-17T16:21:13.051207283Z,2025-07-17T16:21:13.051041384Z,160,2,1108,A,A,13.980000000,2,0,349366297,130,165899,290385730,ARL
2025-07-17T16:21:13.054107724Z,2025-07-17T16:21:13.053942197Z,160,2,1108,C,A,14.400000000,100,0,347605109,0,165527,290385849,ARL
2025-07-17T16:21:13.054107724Z,2025-07-17T16:21:13.053942197Z,160,2,1108,A,A,14.960000000,100,0,349366637,130,165527,290385849,ARL
2025-07-17T16:21:13.075812200Z,2025-07-17T16:21:13.075646700Z,160,2,1108,C,A,17.090000000,100,0,347605101,0,165500,290387275,ARL
2025-07-17T16:21:13.075812200Z,2025-07-17T16:21:13.075646700Z,160,2,1108,A,A,17.760000000,100,0,349368025,130,165500,290387275,ARL
2025-07-17T16:21:13.080134481Z,2025-07-17T16:21:13.079968994Z,160,2,1108,C,A,14.780000000,100,0,349364213,0,165487,290387380,ARL
2025-07-17T16:21:13.080134481Z,2025-07-17T16:21:13.079968994Z,160,2,1108,A,A,15.060000000,100,0,349368089,130,165487,290387380,ARL
2025-07-17T16:21:13.094849052Z,2025-07-17T16:21:13.094683355Z,160,2,1108,C,A,15.470000000,100,0,347605105,0,165697,290387682,ARL
2025-07-17T16:21:13.094849052Z,2025-07-17T16:21:13.094683355Z,160,2,1108,A,A,16.080000000,100,0,349368861,130,165697,290387682,ARL
2025-07-17T16:21:13.155686293Z,2025-07-17T16:21:13.155520730Z,160,2,1108,C,A,14.800000000,100,0,347605169,0,165563,290388741,ARL
2025-07-17T16:21:13.155686293Z,2025-07-17T16:21:13.155520730Z,160,2,1108,A,A,15.380000000,100,0,349370077,130,165563,290388741,ARL
2025-07-17T16:21:13.214483898Z,2025-07-17T16:21:13.214317987Z,160,2,1108,C,A,14.400000000,100,0,347605617,0,165911,290389756,ARL
2025-07-17T16:21:13.214483898Z,2025-07-17T16:21:13.214317987Z,160,2,1108,A,A,14.960000000,100,0,349371829,130,165911,290389756,ARL
2025-07-17T16:21:13.236533203Z,2025-07-17T16:21:13.236367880Z,160,2,1108,A,A,14.680000000,700,0,349372241,130,165323,290390045,ARL
2025-07-17T16:21:13.533219934Z,2025-07-17T16:21:13.533054792Z,160,2,1108,C,A,14.330000000,100,0,349364205,130,165142,290394645,ARL
2025-07-17T16:21:13.533568871Z,2025-07-17T16:21:13.533403508Z,160,2,1108,A,A,14.600000000,100,0,349378277,130,165363,290394647,ARL
2025-07-17T16:21:13.617836532Z,2025-07-17T16:21:13.617670801Z,160,2,1108,A,A,14.810000000,100,0,349380345,130,165731,290395763,ARL
2025-07-17T16:21:13.617850005Z,2025-07-17T16:21:13.617684550Z,160,2,1108,C,A,14.250000000,100,0,347615553,130,165455,290395764,ARL
2025-07-17T16:21:13.652214194Z,2025-07-17T16:21:13.652048799Z,160,2,1108,A,A,13.990000000,100,0,349380925,130,165395,290396554,ARL
2025-07-17T16:21:13.742867781Z,2025-07-17T16:21:13.742700842Z,160,2,1108,A,A,14.530000000,100,0,349382189,0,166939,290397623,ARL
2025-07-17T16:21:13.742867781Z,2025-07-17T16:21:13.742701630Z,160,2,1108,C,A,13.980000000,100,0,347613877,130,166151,290397624,ARL
2025-07-17T16:21:14.030935993Z,2025-07-17T16:21:14.030770739Z,160,2,1108,C,A,14.510000000,100,0,349364905,130,165254,290403111,ARL
2025-07-17T16:21:14.031072602Z,2025-07-17T16:21:14.030907193Z,160,2,1108,A,A,14.770000000,100,0,349388057,130,165409,290403117,ARL
2025-07-17T16:21:14.045944611Z,2025-07-17T16:21:14.045778918Z,160,2,1108,C,A,14.630000000,100,0,349364233,0,165693,290403302,ARL
2025-07-17T16:21:14.045944611Z,2025-07-17T16:21:14.045778918Z,160,2,1108,A,A,14.870000000,100,0,349388377,130,165693,290403302,ARL
2025-07-17T16:21:14.046189449Z,2025-07-17T16:21:14.046023656Z,160,2,1108,C,A,14.630000000,100,0,349364085,0,165793,290403303,ARL
2025-07-17T16:21:14.046189449Z,2025-07-17T16:21:14.046023656Z,160,2,1108,A,A,14.870000000,100,0,349388385,130,165793,290403303,ARL
2025-07-17T16:21:18.838792785Z,2025-07-17T16:21:18.838627443Z,160,2,1108,C,B,13.110000000,10,0,349365825,130,165342,290472869,ARL
2025-07-17T16:21:19.432468330Z,2025-07-17T16:21:19.432302263Z,160,2,1108,C,A,14.870000000,100,0,349388377,0,166067,290480833,ARL
2025-07-17T16:21:19.432468330Z,2025-07-17T16:21:19.432302263Z,160,2,1108,A,A,14.320000000,100,0,349491773,130,166067,290480833,ARL
2025-07-17T16:21:19.432869322Z,2025-07-17T16:21:19.432703556Z,160,2,1108,C,A,14.870000000,100,0,349388385,0,165766,290480840,ARL
2025-07-17T16:21:19.432869322Z,2025-07-17T16:21:19.432703556Z,160,2,1108,A,A,14.320000000,100,0,349491781,130,165766,290480840,ARL
2025-07-17T16:21:21.559994951Z,2025-07-17T16:21:21.559829242Z,160,2,1108,C,A,14.320000000,100,0,349491781,0,165709,290520485,ARL
2025-07-17T16:21:21.559994951Z,2025-07-17T16:21:21.559829242Z,160,2,1108,A,A,14.880000000,100,0,349547193,130,165709,290520485,ARL
2025-07-17T16:21:21.560117656Z,2025-07-17T16:21:21.559952130Z,160,2,1108,C,A,14.320000000,100,0,349491773,0,165526,290520492,ARL
2025-07-17T16:21:21.560117656Z,2025-07-17T16:21:21.559952130Z,160,2,1108,A,A,14.880000000,100,0,349547205,130,165526,290520492,ARL
2025-07-17T16:21:24.785963512Z,2025-07-17T16:21:24.785797985Z,160,2,1108,C,B,12.960000000,2,0,348838809,0,165527,290591357,ARL
2025-07-17T16:21:24.785963512Z,2025-07-17T16:21:24.785797985Z,160,2,1108,A,B,13.040000000,2,0,349635277,130,165527,290591357,ARL
2025-07-17T16:21:30.041882933Z,2025-07-17T16:21:30.041717299Z,160,2,1108,C,A,14.880000000,100,0,349547205,0,165634,290665095,ARL
2025-07-17T16:21:30.041882933Z,2025-07-17T16:21:30.041717299Z,160,2,1108,A,A,14.330000000,100,0,349727893,130,165634,290665095,ARL
2025-07-17T16:21:30.042068124Z,2025-07-17T16:21:30.041902504Z,160,2,1108,C,A,14.880000000,100,0,349547193,0,165620,290665107,ARL
2025-07-17T16:21:30.042068124Z,2025-07-17T16:21:30.041902504Z,160,2,1108,A,A,14.330000000,100,0,349727897,130,165620,290665107,ARL
2025-07-17T16:21:32.891561821Z,2025-07-17T16:21:32.891396207Z,160,2,1108,C,A,14.330000000,100,0,349727893,0,165614,290706797,ARL
2025-07-17T16:21:32.891561821Z,2025-07-17T16:21:32.891396207Z,160,2,1108,A,A,14.880000000,100,0,349786361,130,165614,290706797,ARL
2025-07-17T16:21:32.920860700Z,2025-07-17T16:21:32.920695054Z,160,2,1108,C,A,14.330000000,100,0,349727897,0,165646,290707080,ARL
2025-07-17T16:21:32.920860700Z,2025-07-17T16:21:32.920695054Z,160,2,1108,A,A,14.880000000,100,0,349786613,130,165646,290707080,ARL
2025-07-17T16:22:10.251959183Z,2025-07-17T16:22:10.251792275Z,160,2,1108,A,A,13.430000000,15,0,350555261,128,166908,291313152,ARL
2025-07-17T16:22:10.252448946Z,2025-07-17T16:22:10.252282744Z,160,2,1108,C,A,14.880000000,100,0,349786361,0,166202,291313277,ARL
2025-07-17T16:22:10.252448946Z,2025-07-17T16:22:10.252282744Z,160,2,1108,A,A,14.330000000,100,0,350555469,130,166202,291313277,ARL
2025-07-17T16:22:10.253186614Z,2025-07-17T16:22:10.253020717Z,160,2,1108,C,A,14.880000000,100,0,349786613,0,165897,291313433,ARL
2025-07-17T16:22:10.253186614Z,2025-07-17T16:22:10.253020717Z,160,2,1108,A,A,14.330000000,100,0,350555717,130,165897,291313433,ARL
2025-07-17T16:22:10.259208076Z,2025-07-17T16:22:10.259042453Z,160,2,1108,C,A,13.990000000,100,0,349380925,0,165623,291313986,ARL
2025-07-17T16:22:10.259208076Z,2025-07-17T16:22:10.259042453Z,160,2,1108,A,A,13.960000000,100,0,350556253,130,165623,291313986,ARL
2025-07-17T16:22:10.651568698Z,2025-07-17T16:22:10.651403186Z,160,2,1108,C,A,13.430000000,15,0,350555261,130,165512,291322198,ARL
2025-07-17T16:22:11.256335174Z,2025-07-17T16:22:11.256169948Z,160,2,1108,C,A,14.330000000,100,0,350555717,0,165226,291329858,ARL
2025-07-17T16:22:11.256335174Z,2025-07-17T16:22:11.256169948Z,160,2,1108,A,A,14.860000000,100,0,350573865,130,165226,291329858,ARL
2025-07-17T16:22:11.294105967Z,2025-07-17T16:22:11.293940494Z,160,2,1108,C,A,14.330000000,100,0,350555469,0,165473,291330189,ARL
2025-07-17T16:22:11.294105967Z,2025-07-17T16:22:11.293940494Z,160,2,1108,A,A,14.860000000,100,0,350574501,130,165473,291330189,ARL
2025-07-17T16:23:50.726518986Z,2025-07-17T16:23:50.726353370Z,160,2,1108,C,A,14.860000000,100,0,350573865,0,165616,292930335,ARL
2025-07-17T16:23:50.726518986Z,2025-07-17T16:23:50.726353370Z,160,2,1108,A,A,14.330000000,100,0,352599713,130,165616,292930335,ARL
2025-07-17T16:23:50.751793627Z,2025-07-17T16:23:50.751628250Z,160,2,1108,C,A,14.860000000,100,0,350574501,0,165377,292931023,ARL
2025-07-17T16:23:50.751793627Z,2025-07-17T16:23:50.751628250Z,160,2,1108,A,A,14.330000000,100,0,352600973,130,165377,292931023,ARL
2025-07-17T16:23:55.522925458Z,2025-07-17T16:23:55.522760301Z,160,2,1108,A,A,13.420000000,15,0,352702077,130,165157,293010586,ARL
2025-07-17T16:23:56.914860179Z,2025-07-17T16:23:56.914694445Z,160,2,1108,C,A,13.960000000,100,0,350556253,0,165734,293025765,ARL
2025-07-17T16:23:56.914860179Z,2025-07-17T16:23:56.914694445Z,160,2,1108,A,A,13.950000000,100,0,352722381,130,165734,293025765,ARL
2025-07-17T16:23:58.527884533Z,2025-07-17T16:23:58.527719150Z,160,2,1108,A,A,13.400000000,15,0,352791109,130,165383,293099007,ARL
2025-07-17T16:23:58.631872329Z,2025-07-17T16:23:58.631706924Z,160,2,1108,C,A,13.950000000,100,0,352722381,0,165405,293104471,ARL
2025-07-17T16:23:58.631872329Z,2025-07-17T16:23:58.631706924Z,160,2,1108,A,A,13.930000000,100,0,352794377,130,165405,293104471,ARL
2025-07-17T16:23:58.632628403Z,2025-07-17T16:23:58.632462522Z,160,2,1108,C,A,15.060000000,100,0,349368089,0,165881,293104479,ARL
2025-07-17T16:23:58.632628403Z,2025-07-17T16:23:58.632462522Z,160,2,1108,A,A,15.010000000,100,0,352794417,130,165881,293104479,ARL
2025-07-17T16:24:02.427373552Z,2025-07-17T16:24:02.427208036Z,160,2,1108,C,A,13.420000000,15,0,352702077,130,165516,293179655,ARL
2025-07-17T16:24:04.377837794Z,2025-07-17T16:24:04.377672438Z,160,2,1108,A,A,13.380000000,15,0,352939445,130,165356,293217696,ARL
2025-07-17T16:24:04.378891069Z,2025-07-17T16:24:04.378725117Z,160,2,1108,C,A,13.930000000,100,0,352794377,0,165952,293217731,ARL
2025-07-17T16:24:04.378891069Z,2025-07-17T16:24:04.378725117Z,160,2,1108,A,A,13.910000000,100,0,352939465,130,165952,293217731,ARL
2025-07-17T16:25:06.191451123Z,2025-07-17T16:25:06.191285410Z,160,2,1108,C,B,13.040000000,2,0,349635277,0,165713,294247609,ARL
2025-07-17T16:25:06.191451123Z,2025-07-17T16:25:06.191285410Z,160,2,1108,A,B,13.110000000,2,0,354187617,130,165713,294247609,ARL
2025-07-17T16:25:08.976415732Z,2025-07-17T16:25:08.976249966Z,160,2,1108,C,A,13.980000000,2,0,349366297,0,165766,294349676,ARL
2025-07-17T16:25:08.976415732Z,2025-07-17T16:25:08.976249966Z,160,2,1108,A,A,13.910000000,2,0,354292533,130,165766,294349676,ARL
2025-07-17T16:25:35.129072184Z,2025-07-17T16:25:35.128903877Z,160,2,1108,C,A,13.380000000,15,0,352939445,128,168307,294934217,ARL
2025-07-17T16:25:39.510507211Z,2025-07-17T16:25:39.510341866Z,160,2,1108,C,A,13.400000000,15,0,352791109,130,165345,295034059,ARL
2025-07-17T16:25:39.511158862Z,2025-07-17T16:25:39.510992800Z,160,2,1108,C,A,14.330000000,100,0,352599713,0,166062,295034078,ARL
2025-07-17T16:25:39.511158862Z,2025-07-17T16:25:39.510992800Z,160,2,1108,A,A,14.800000000,100,0,355038285,130,166062,295034078,ARL
2025-07-17T16:25:39.511772004Z,2025-07-17T16:25:39.511606124Z,160,2,1108,C,A,14.330000000,100,0,352600973,0,165880,295034094,ARL
2025-07-17T16:25:39.511772004Z,2025-07-17T16:25:39.511606124Z,160,2,1108,A,A,14.800000000,100,0,355038317,130,165880,295034094,ARL
2025-07-17T16:25:39.513587612Z,2025-07-17T16:25:39.513422230Z,160,2,1108,A,B,13.110000000,10,0,355038373,130,165382,295034123,ARL
2025-07-17T16:25:40.874979428Z,2025-07-17T16:25:40.874808027Z,160,2,1108,A,A,13.900000000,15,0,355097305,130,171401,295093819,ARL
2025-07-17T16:25:49.509607483Z,2025-07-17T16:25:49.509442229Z,160,2,1108,C,B,13.110000000,10,0,355038373,130,165254,295316849,ARL
2025-07-17T16:25:54.511931358Z,2025-07-17T16:25:54.511765715Z,160,2,1108,A,A,13.840000000,15,0,355455441,130,165643,295392773,ARL
2025-07-17T16:25:54.512201450Z,2025-07-17T16:25:54.512035936Z,160,2,1108,C,A,13.910000000,100,0,352939465,0,165514,295392775,ARL
2025-07-17T16:25:54.512201450Z,2025-07-17T16:25:54.512035936Z,160,2,1108,A,A,13.850000000,100,0,355455445,130,165514,295392775,ARL
2025-07-17T16:25:54.512955771Z,2025-07-17T16:25:54.512790302Z,160,2,1108,C,A,15.010000000,100,0,352794417,0,165469,295392784,ARL
2025-07-17T16:25:54.512955771Z,2025-07-17T16:25:54.512790302Z,160,2,1108,A,A,14.920000000,100,0,355455465,130,165469,295392784,ARL
2025-07-17T16:25:54.513534883Z,2025-07-17T16:25:54.513369439Z,160,2,1108,C,A,16.080000000,100,0,349368861,0,165444,295392793,ARL
2025-07-17T16:25:54.513534883Z,2025-07-17T16:25:54.513369439Z,160,2,1108,A,A,15.930000000,100,0,355455477,130,165444,295392793,ARL
2025-07-17T16:25:54.514549812Z,2025-07-17T16:25:54.514384374Z,160,2,1108,C,A,17.760000000,100,0,349368025,0,165438,295392795,ARL
2025-07-17T16:25:54.514549812Z,2025-07-17T16:25:54.514384374Z,160,2,1108,A,A,17.590000000,100,0,355455481,130,165438,295392795,ARL
2025-07-17T16:25:54.535083079Z,2025-07-17T16:25:54.534917732Z,160,2,1108,C,A,14.220000000,100,0,349366121,130,165347,295392911,ARL
2025-07-17T16:25:54.535135667Z,2025-07-17T16:25:54.534970016Z,160,2,1108,A,A,14.130000000,100,0,355455809,130,165651,295392912,ARL
2025-07-17T16:26:01.563589927Z,2025-07-17T16:26:01.563424507Z,160,2,1108,C,A,13.900000000,15,0,355097305,130,165420,295507323,ARL
2025-07-17T16:26:05.322538883Z,2025-07-17T16:26:05.322373598Z,160,2,1108,A,A,13.820000000,15,0,355692501,130,165285,295580795,ARL
2025-07-17T16:26:05.323669349Z,2025-07-17T16:26:05.323503152Z,160,2,1108,C,A,13.850000000,100,0,355455445,0,166197,295580842,ARL
2025-07-17T16:26:05.323669349Z,2025-07-17T16:26:05.323503152Z,160,2,1108,A,A,13.830000000,100,0,355692553,130,166197,295580842,ARL
2025-07-17T16:26:05.327062368Z,2025-07-17T16:26:05.326896218Z,160,2,1108,C,A,14.960000000,100,0,349366637,0,166150,295580934,ARL
2025-07-17T16:26:05.327062368Z,2025-07-17T16:26:05.326896218Z,160,2,1108,A,A,14.800000000,100,0,355692625,130,166150,295580934,ARL
2025-07-17T16:26:05.328320637Z,2025-07-17T16:26:05.328155098Z,160,2,1108,C,A,14.770000000,100,0,349388057,0,165539,295581043,ARL
2025-07-17T16:26:05.328320637Z,2025-07-17T16:26:05.328155098Z,160,2,1108,A,A,14.620000000,100,0,355692649,130,165539,295581043,ARL
2025-07-17T16:26:05.484333510Z,2025-07-17T16:26:05.484167986Z,160,2,1108,C,A,14.960000000,100,0,349371829,0,165524,295584234,ARL
2025-07-17T16:26:05.484333510Z,2025-07-17T16:26:05.484167986Z,160,2,1108,A,A,14.800000000,100,0,355696605,130,165524,295584234,ARL
2025-07-17T16:26:10.885379151Z,2025-07-17T16:26:10.885204270Z,160,2,1108,C,A,13.840000000,15,0,355455441,128,174881,295674513,ARL
2025-07-17T16:26:12.458773012Z,2025-07-17T16:26:12.458607766Z,160,2,1108,A,A,13.800000000,15,0,355834369,130,165246,295697152,ARL
2025-07-17T16:26:12.459039500Z,2025-07-17T16:26:12.458873979Z,160,2,1108,C,A,13.830000000,100,0,355692553,0,165521,295697153,ARL
2025-07-17T16:26:12.459039500Z,2025-07-17T16:26:12.458873979Z,160,2,1108,A,A,13.810000000,100,0,355834377,130,165521,295697153,ARL
2025-07-17T16:26:12.459776321Z,2025-07-17T16:26:12.459610620Z,160,2,1108,C,A,14.920000000,100,0,355455465,0,165701,295697155,ARL
2025-07-17T16:26:12.459776321Z,2025-07-17T16:26:12.459610620Z,160,2,1108,A,A,14.880000000,100,0,355834401,130,165701,295697155,ARL
2025-07-17T16:26:12.460786896Z,2025-07-17T16:26:12.460621327Z,160,2,1108,C,A,14.800000000,100,0,355038285,0,165569,295697158,ARL
2025-07-17T16:26:12.460786896Z,2025-07-17T16:26:12.460621327Z,160,2,1108,A,A,14.680000000,100,0,355834413,130,165569,295697158,ARL
2025-07-17T16:26:12.461189446Z,2025-07-17T16:26:12.461023943Z,160,2,1108,C,A,14.800000000,100,0,355038317,0,165503,295697159,ARL
2025-07-17T16:26:12.461189446Z,2025-07-17T16:26:12.461023943Z,160,2,1108,A,A,14.680000000,100,0,355834425,130,165503,295697159,ARL
2025-07-17T16:26:21.188384358Z,2025-07-17T16:26:21.188218529Z,160,2,1108,C,B,13.110000000,2,0,354187617,0,165829,295810309,ARL
2025-07-17T16:26:21.188384358Z,2025-07-17T16:26:21.188218529Z,160,2,1108,A,B,13.010000000,2,0,355990209,130,165829,295810309,ARL
2025-07-17T16:26:22.849649042Z,2025-07-17T16:26:22.849483693Z,160,2,1108,C,A,13.820000000,15,0,355692501,130,165349,295833352,ARL
2025-07-17T16:26:32.848769442Z,2025-07-17T16:26:32.848604005Z,160,2,1108,A,A,13.760000000,15,0,356212397,130,165437,295978389,ARL
2025-07-17T16:26:34.579093883Z,2025-07-17T16:26:34.578928535Z,160,2,1108,C,A,13.810000000,100,0,355834377,0,165348,296006812,ARL
2025-07-17T16:26:34.579093883Z,2025-07-17T16:26:34.578928535Z,160,2,1108,A,A,13.770000000,100,0,356249197,130,165348,296006812,ARL
2025-07-17T16:26:34.579833477Z,2025-07-17T16:26:34.579668245Z,160,2,1108,C,A,14.600000000,100,0,349378277,130,165232,296006823,ARL
2025-07-17T16:26:34.579845082Z,2025-07-17T16:26:34.579679681Z,160,2,1108,C,A,14.880000000,100,0,355834401,0,165401,296006824,ARL
2025-07-17T16:26:34.579845082Z,2025-07-17T16:26:34.579679681Z,160,2,1108,A,A,14.840000000,100,0,356249233,130,165401,296006824,ARL
2025-07-17T16:26:34.580190182Z,2025-07-17T16:26:34.580024867Z,160,2,1108,A,A,14.380000000,100,0,356249249,130,165315,296006828,ARL
2025-07-17T16:26:34.598179865Z,2025-07-17T16:26:34.598014487Z,160,2,1108,C,A,14.130000000,100,0,355455809,130,165378,296007149,ARL
2025-07-17T16:26:34.598231978Z,2025-07-17T16:26:34.598066762Z,160,2,1108,A,A,14.050000000,100,0,356249781,130,165216,296007150,ARL
2025-07-17T16:26:40.082074080Z,2025-07-17T16:26:40.081907812Z,160,2,1108,C,A,13.800000000,15,0,355834369,130,166268,296079992,ARL
2025-07-17T16:26:41.283116801Z,2025-07-17T16:26:41.282951271Z,160,2,1108,A,A,13.730000000,15,0,356366025,130,165530,296093549,ARL
2025-07-17T16:26:41.283384784Z,2025-07-17T16:26:41.283218820Z,160,2,1108,C,A,13.770000000,100,0,356249197,0,165964,296093550,ARL
2025-07-17T16:26:41.283384784Z,2025-07-17T16:26:41.283218820Z,160,2,1108,A,A,13.740000000,100,0,356366029,130,165964,296093550,ARL
2025-07-17T16:26:41.284118659Z,2025-07-17T16:26:41.283952956Z,160,2,1108,C,A,14.840000000,100,0,356249233,0,165703,296093553,ARL
2025-07-17T16:26:41.284118659Z,2025-07-17T16:26:41.283952956Z,160,2,1108,A,A,14.810000000,100,0,356366045,130,165703,296093553,ARL
2025-07-17T16:26:41.314178208Z,2025-07-17T16:26:41.314012815Z,160,2,1108,A,A,15.670000000,100,0,356366353,130,165393,296093718,ARL
2025-07-17T16:26:41.314191513Z,2025-07-17T16:26:41.314026122Z,160,2,1108,C,A,15.940000000,100,0,349365749,130,165391,296093719,ARL
2025-07-17T16:26:52.849929707Z,2025-07-17T16:26:52.849764152Z,160,2,1108,C,A,13.760000000,15,0,356212397,130,165555,296250544,ARL
2025-07-17T16:26:59.805421094Z,2025-07-17T16:26:59.805255232Z,160,2,1108,A,A,13.700000000,15,0,356686001,130,165862,296350781,ARL
2025-07-17T16:27:00.881244327Z,2025-07-17T16:27:00.881078814Z,160,2,1108,C,A,13.740000000,100,0,356366029,0,165513,296372801,ARL
2025-07-17T16:27:00.881244327Z,2025-07-17T16:27:00.881078814Z,160,2,1108,A,A,13.710000000,100,0,356714633,130,165513,296372801,ARL
2025-07-17T16:27:00.881989942Z,2025-07-17T16:27:00.881824069Z,160,2,1108,C,A,14.810000000,100,0,356366045,0,165873,296372816,ARL
2025-07-17T16:27:00.881989942Z,2025-07-17T16:27:00.881824069Z,160,2,1108,A,A,14.770000000,100,0,356714681,130,165873,296372816,ARL
2025-07-17T16:27:00.882266738Z,2025-07-17T16:27:00.882101298Z,160,2,1108,C,A,15.380000000,100,0,349366105,0,165440,296372818,ARL
2025-07-17T16:27:00.882266738Z,2025-07-17T16:27:00.882101298Z,160,2,1108,A,A,15.090000000,100,0,356714685,130,165440,296372818,ARL
2025-07-17T16:27:00.883118958Z,2025-07-17T16:27:00.882953564Z,160,2,1108,C,A,15.930000000,100,0,355455477,0,165394,296372822,ARL
2025-07-17T16:27:00.883118958Z,2025-07-17T16:27:00.882953564Z,160,2,1108,A,A,15.770000000,100,0,356714693,130,165394,296372822,ARL
2025-07-17T16:27:00.883816171Z,2025-07-17T16:27:00.883650775Z,160,2,1108,C,A,17.590000000,100,0,355455481,0,165396,296372832,ARL
2025-07-17T16:27:00.883816171Z,2025-07-17T16:27:00.883650775Z,160,2,1108,A,A,17.420000000,100,0,356714705,130,165396,296372832,ARL
2025-07-17T16:27:00.888986182Z,2025-07-17T16:27:00.888818817Z,160,2,1108,C,A,14.050000000,100,0,356249781,130,167365,296372958,ARL
2025-07-17T16:27:00.889034168Z,2025-07-17T16:27:00.888868946Z,160,2,1108,A,A,13.980000000,100,0,356714765,130,165222,296372964,ARL
2025-07-17T16:27:00.900024405Z,2025-07-17T16:27:00.899858838Z,160,2,1108,C,A,15.380000000,100,0,349370077,0,165567,296373146,ARL
2025-07-17T16:27:00.900024405Z,2025-07-17T16:27:00.899858838Z,160,2,1108,A,A,15.090000000,100,0,356714861,130,165567,296373146,ARL
2025-07-17T16:27:01.382794826Z,2025-07-17T16:27:01.382629641Z,160,2,1108,A,A,14.530000000,100,0,356722649,130,165185,296378810,ARL
2025-07-17T16:27:01.382808358Z,2025-07-17T16:27:01.382642532Z,160,2,1108,C,A,14.810000000,100,0,349380345,130,165826,296378811,ARL
2025-07-17T16:27:03.871788936Z,2025-07-17T16:27:03.871623478Z,160,2,1108,C,A,13.730000000,15,0,356366025,130,165458,296454461,ARL
2025-07-17T16:27:06.196975879Z,2025-07-17T16:27:06.196810370Z,160,2,1108,A,A,13.670000000,15,0,356868209,130,165509,296495602,ARL
2025-07-17T16:27:06.197822714Z,2025-07-17T16:27:06.197657115Z,160,2,1108,C,A,14.680000000,100,0,355834425,0,165599,296495681,ARL
2025-07-17T16:27:06.197822714Z,2025-07-17T16:27:06.197657115Z,160,2,1108,A,A,14.570000000,100,0,356868353,130,165599,296495681,ARL
2025-07-17T16:27:06.198071760Z,2025-07-17T16:27:06.197902486Z,160,2,1108,C,A,14.680000000,100,0,355834413,0,169274,296495716,ARL
2025-07-17T16:27:06.198071760Z,2025-07-17T16:27:06.197902486Z,160,2,1108,A,A,14.570000000,100,0,356868473,128,169274,296495716,ARL
2025-07-17T16:27:06.203786192Z,2025-07-17T16:27:06.203607410Z,160,2,1108,C,A,13.710000000,100,0,356714633,0,178782,296497538,ARL
2025-07-17T16:27:06.203786192Z,2025-07-17T16:27:06.203607410Z,160,2,1108,A,A,13.680000000,100,0,356870513,128,178782,296497538,ARL
2025-07-17T16:27:06.222195424Z,2025-07-17T16:27:06.222029734Z,160,2,1108,C,A,14.800000000,100,0,355692625,0,165690,296501469,ARL
2025-07-17T16:27:06.222195424Z,2025-07-17T16:27:06.222029734Z,160,2,1108,A,A,14.640000000,100,0,356874709,130,165690,296501469,ARL
2025-07-17T16:27:06.323534103Z,2025-07-17T16:27:06.323368593Z,160,2,1108,C,A,14.800000000,100,0,355696605,0,165510,296504437,ARL
2025-07-17T16:27:06.323534103Z,2025-07-17T16:27:06.323368593Z,160,2,1108,A,A,14.640000000,100,0,356877837,130,165510,296504437,ARL
2025-07-17T16:27:06.367859180Z,2025-07-17T16:27:06.367693589Z,160,2,1108,C,A,14.530000000,100,0,349382189,130,165591,296505003,ARL
2025-07-17T16:27:06.367860753Z,2025-07-17T16:27:06.367695483Z,160,2,1108,A,A,14.230000000,100,0,356878397,130,165270,296505004,ARL
2025-07-17T16:27:06.379411315Z,2025-07-17T16:27:06.379245919Z,160,2,1108,C,A,14.620000000,100,0,355692649,130,165396,296505372,ARL
2025-07-17T16:27:06.379540151Z,2025-07-17T16:27:06.379374401Z,160,2,1108,A,A,14.470000000,100,0,356878557,130,165750,296505373,ARL
2025-07-17T16:27:16.850332913Z,2025-07-17T16:27:16.850167737Z,160,2,1108,C,A,13.700000000,15,0,356686001,130,165176,296665928,ARL
2025-07-17T16:27:26.589073481Z,2025-07-17T16:27:26.588907795Z,160,2,1108,C,B,13.010000000,2,0,355990209,0,165686,296801845,ARL
2025-07-17T16:27:26.589073481Z,2025-07-17T16:27:26.588907795Z,160,2,1108,A,B,12.900000000,2,0,357261961,130,165686,296801845,ARL
2025-07-17T16:27:26.850588946Z,2025-07-17T16:27:26.850423539Z,160,2,1108,A,A,13.650000000,15,0,357266817,130,165407,296804447,ARL
2025-07-17T16:27:26.850854853Z,2025-07-17T16:27:26.850689196Z,160,2,1108,C,A,13.680000000,100,0,356870513,0,165657,296804468,ARL
2025-07-17T16:27:26.850854853Z,2025-07-17T16:27:26.850689196Z,160,2,1108,A,A,13.660000000,100,0,357266825,130,165657,296804468,ARL
2025-07-17T16:27:26.851601231Z,2025-07-17T16:27:26.851435675Z,160,2,1108,C,A,14.770000000,100,0,356714681,0,165556,296804532,ARL
2025-07-17T16:27:26.851601231Z,2025-07-17T16:27:26.851435675Z,160,2,1108,A,A,14.720000000,100,0,357266857,130,165556,296804532,ARL
2025-07-17T16:27:44.755470864Z,2025-07-17T16:27:44.755305413Z,160,2,1108,C,A,13.670000000,15,0,356868209,130,165451,297181709,ARL
2025-07-17T16:27:51.274193747Z,2025-07-17T16:27:51.274028105Z,160,2,1108,A,A,13.630000000,15,0,357831017,130,165642,297262308,ARL
2025-07-17T16:27:51.287994820Z,2025-07-17T16:27:51.287829323Z,160,2,1108,C,A,13.660000000,100,0,357266825,0,165497,297264561,ARL
2025-07-17T16:27:51.287994820Z,2025-07-17T16:27:51.287829323Z,160,2,1108,A,A,13.640000000,100,0,357833401,130,165497,297264561,ARL
2025-07-17T16:27:51.309894790Z,2025-07-17T16:27:51.309729367Z,160,2,1108,C,A,13.980000000,100,0,356714765,130,165423,297265448,ARL
2025-07-17T16:27:51.309945367Z,2025-07-17T16:27:51.309780024Z,160,2,1108,A,A,13.910000000,100,0,357834073,130,165343,297265452,ARL
2025-07-17T16:28:02.851437866Z,2025-07-17T16:28:02.851272527Z,160,2,1108,C,A,13.650000000,15,0,357266817,130,165339,297397036,ARL
2025-07-17T16:28:09.315288028Z,2025-07-17T16:28:09.315122562Z,160,2,1108,A,A,13.610000000,15,0,358150085,130,165466,297494103,ARL
2025-07-17T16:28:09.320408712Z,2025-07-17T16:28:09.320239872Z,160,2,1108,C,A,13.640000000,100,0,357833401,0,168840,297494317,ARL
2025-07-17T16:28:09.320408712Z,2025-07-17T16:28:09.320239872Z,160,2,1108,A,A,13.620000000,100,0,358150237,130,168840,297494317,ARL
2025-07-17T16:28:09.321142495Z,2025-07-17T16:28:09.320976916Z,160,2,1108,C,A,14.720000000,100,0,357266857,0,165579,297494369,ARL
2025-07-17T16:28:09.321142495Z,2025-07-17T16:28:09.320976916Z,160,2,1108,A,A,14.680000000,100,0,358150261,130,165579,297494369,ARL
2025-07-17T16:28:20.851638007Z,2025-07-17T16:28:20.851472409Z,160,2,1108,C,A,13.630000000,15,0,357831017,130,165598,297651898,ARL
2025-07-17T16:28:24.674509358Z,2025-07-17T16:28:24.674343969Z,160,2,1108,A,A,13.590000000,15,0,358449973,130,165389,297733885,ARL
2025-07-17T16:28:25.348396135Z,2025-07-17T16:28:25.348230623Z,160,2,1108,C,A,13.620000000,100,0,358150237,0,165512,297742434,ARL
2025-07-17T16:28:25.348396135Z,2025-07-17T16:28:25.348230623Z,160,2,1108,A,A,13.600000000,100,0,358463553,130,165512,297742434,ARL
2025-07-17T16:28:25.349760305Z,2025-07-17T16:28:25.349594693Z,160,2,1108,C,A,17.420000000,100,0,356714705,0,165612,297742451,ARL
2025-07-17T16:28:25.349760305Z,2025-07-17T16:28:25.349594693Z,160,2,1108,A,A,17.280000000,100,0,358463581,130,165612,297742451,ARL
2025-07-17T16:28:30.151777566Z,2025-07-17T16:28:30.151612118Z,160,2,1108,C,A,13.610000000,15,0,358150085,130,165448,297801782,ARL
2025-07-17T16:28:31.156530154Z,2025-07-17T16:28:31.156364385Z,160,2,1108,A,A,13.570000000,15,0,358570565,130,165769,297818676,ARL
2025-07-17T16:28:31.749789697Z,2025-07-17T16:28:31.749624268Z,160,2,1108,C,A,13.600000000,100,0,358463553,0,165429,297824579,ARL
2025-07-17T16:28:31.749789697Z,2025-07-17T16:28:31.749624268Z,160,2,1108,A,A,13.580000000,100,0,358578625,130,165429,297824579,ARL
2025-07-17T16:28:31.750525686Z,2025-07-17T16:28:31.750359970Z,160,2,1108,C,A,14.680000000,100,0,358150261,0,165716,297824590,ARL
2025-07-17T16:28:31.750525686Z,2025-07-17T16:28:31.750359970Z,160,2,1108,A,A,14.630000000,100,0,358578645,130,165716,297824590,ARL
2025-07-17T16:28:31.752884275Z,2025-07-17T16:28:31.752718708Z,160,2,1108,C,A,15.770000000,100,0,356714693,0,165567,297824647,ARL
2025-07-17T16:28:31.752884275Z,2025-07-17T16:28:31.752718708Z,160,2,1108,A,A,15.620000000,100,0,358578669,130,165567,297824647,ARL
2025-07-17T16:28:32.698672164Z,2025-07-17T16:28:32.698506029Z,160,2,1108,C,A,14.570000000,100,0,356868353,0,166135,297835499,ARL
2025-07-17T16:28:32.698672164Z,2025-07-17T16:28:32.698506029Z,160,2,1108,A,A,14.460000000,100,0,358596029,130,166135,297835499,ARL
2025-07-17T16:28:32.699117780Z,2025-07-17T16:28:32.698952035Z,160,2,1108,C,A,14.570000000,100,0,356868473,0,165745,297835506,ARL
2025-07-17T16:28:32.699117780Z,2025-07-17T16:28:32.698952035Z,160,2,1108,A,A,14.460000000,100,0,358596037,130,165745,297835506,ARL
2025-07-17T16:28:40.030676303Z,2025-07-17T16:28:40.030511022Z,160,2,1108,A,A,14.260000000,700,0,358712189,130,165281,297918373,ARL
2025-07-17T16:28:40.030732031Z,2025-07-17T16:28:40.030566652Z,160,2,1108,C,A,14.680000000,700,0,349372241,130,165379,297918374,ARL
2025-07-17T16:28:42.853463655Z,2025-07-17T16:28:42.853298390Z,160,2,1108,C,A,13.590000000,15,0,358449973,130,165265,297952225,ARL
2025-07-17T16:28:52.853526381Z,2025-07-17T16:28:52.853361257Z,160,2,1108,A,A,13.550000000,15,0,358923309,130,165124,298071838,ARL
2025-07-17T16:28:52.853793896Z,2025-07-17T16:28:52.853628543Z,160,2,1108,C,A,13.580000000,100,0,358578625,0,165353,298071841,ARL
2025-07-17T16:28:52.853793896Z,2025-07-17T16:28:52.853628543Z,160,2,1108,A,A,13.560000000,100,0,358923321,130,165353,298071841,ARL
2025-07-17T16:28:52.854531051Z,2025-07-17T16:28:52.854365748Z,160,2,1108,C,A,14.380000000,100,0,356249249,130,165303,298071844,ARL
2025-07-17T16:28:52.854892733Z,2025-07-17T16:28:52.854727375Z,160,2,1108,A,A,14.170000000,100,0,358923345,130,165358,298071846,ARL
2025-07-17T16:28:52.874969164Z,2025-07-17T16:28:52.874803773Z,160,2,1108,C,A,13.910000000,100,0,357834073,130,165391,298071937,ARL
2025-07-17T16:28:52.875019400Z,2025-07-17T16:28:52.874854173Z,160,2,1108,A,A,13.830000000,100,0,358923457,130,165227,298071938,ARL
2025-07-17T16:29:12.853224917Z,2025-07-17T16:29:12.853059452Z,160,2,1108,C,A,13.570000000,15,0,358570565,130,165465,298434087,ARL
2025-07-17T16:29:15.051636723Z,2025-07-17T16:29:15.051471390Z,160,2,1108,A,A,13.530000000,15,0,359402805,130,165333,298465823,ARL
2025-07-17T16:29:15.091786299Z,2025-07-17T16:29:15.091620748Z,160,2,1108,C,A,13.560000000,100,0,358923321,0,165551,298467504,ARL
2025-07-17T16:29:15.091786299Z,2025-07-17T16:29:15.091620748Z,160,2,1108,A,A,13.540000000,100,0,359403945,130,165551,298467504,ARL
2025-07-17T16:29:15.092532920Z,2025-07-17T16:29:15.092366698Z,160,2,1108,C,A,14.630000000,100,0,358578645,0,166222,298467517,ARL
2025-07-17T16:29:15.092532920Z,2025-07-17T16:29:15.092366698Z,160,2,1108,A,A,14.590000000,100,0,359403961,130,166222,298467517,ARL
2025-07-17T16:29:15.093165408Z,2025-07-17T16:29:15.092999970Z,160,2,1108,C,A,14.640000000,100,0,356874709,0,165438,298467529,ARL
2025-07-17T16:29:15.093165408Z,2025-07-17T16:29:15.092999970Z,160,2,1108,A,A,14.490000000,100,0,359403985,130,165438,298467529,ARL
2025-07-17T16:29:15.137819150Z,2025-07-17T16:29:15.137653676Z,160,2,1108,C,A,14.640000000,100,0,356877837,0,165474,298468861,ARL
2025-07-17T16:29:15.137819150Z,2025-07-17T16:29:15.137653676Z,160,2,1108,A,A,14.490000000,100,0,359404829,130,165474,298468861,ARL
2025-07-17T16:29:15.203931372Z,2025-07-17T16:29:15.203765956Z,160,2,1108,C,A,14.470000000,100,0,356878557,0,165416,298471150,ARL
2025-07-17T16:29:15.203931372Z,2025-07-17T16:29:15.203765956Z,160,2,1108,A,A,14.330000000,100,0,359406981,130,165416,298471150,ARL
2025-07-17T16:29:18.186126235Z,2025-07-17T16:29:18.185960448Z,160,2,1108,C,A,13.910000000,2,0,354292533,0,165787,298518298,ARL
2025-07-17T16:29:18.186126235Z,2025-07-17T16:29:18.185960448Z,160,2,1108,A,A,13.820000000,2,0,359459321,130,165787,298518298,ARL
2025-07-17T16:29:22.814624817Z,2025-07-17T16:29:22.814459272Z,160,2,1108,C,A,13.550000000,15,0,358923309,130,165545,298597575,ARL
2025-07-17T16:29:34.353525366Z,2025-07-17T16:29:34.353360056Z,160,2,1108,A,A,13.510000000,15,0,359747973,130,165310,298768484,ARL
2025-07-17T16:29:37.353817686Z,2025-07-17T16:29:37.353652254Z,160,2,1108,C,A,13.530000000,15,0,359402805,130,165432,298809584,ARL
2025-07-17T16:29:38.016710092Z,2025-07-17T16:29:38.016544503Z,160,2,1108,C,A,13.540000000,100,0,359403945,0,165589,298816720,ARL
2025-07-17T16:29:38.016710092Z,2025-07-17T16:29:38.016544503Z,160,2,1108,A,A,13.520000000,100,0,359803101,130,165589,298816720,ARL
2025-07-17T16:29:38.358698380Z,2025-07-17T16:29:38.358532978Z,160,2,1108,A,A,13.490000000,15,0,359807057,130,165402,298820897,ARL
2025-07-17T16:29:39.396413450Z,2025-07-17T16:29:39.396248056Z,160,2,1108,C,A,13.520000000,100,0,359803101,0,165394,298834883,ARL
2025-07-17T16:29:39.396413450Z,2025-07-17T16:29:39.396248056Z,160,2,1108,A,A,13.500000000,100,0,359822513,130,165394,298834883,ARL
2025-07-17T16:29:39.397150448Z,2025-07-17T16:29:39.396984566Z,160,2,1108,C,A,14.590000000,100,0,359403961,0,165882,298834892,ARL
2025-07-17T16:29:39.397150448Z,2025-07-17T16:29:39.396984566Z,160,2,1108,A,A,14.550000000,100,0,359822537,130,165882,298834892,ARL
2025-07-17T16:29:39.423766082Z,2025-07-17T16:29:39.423600461Z,160,2,1108,A,A,15.390000000,100,0,359823113,130,165621,298835297,ARL
2025-07-17T16:29:39.423779118Z,2025-07-17T16:29:39.423613737Z,160,2,1108,C,A,15.670000000,100,0,356366353,130,165381,298835298,ARL
2025-07-17T16:29:44.669038478Z,2025-07-17T16:29:44.668873033Z,160,2,1108,C,A,13.510000000,15,0,359747973,130,165445,298899512,ARL
2025-07-17T16:29:56.855566592Z,2025-07-17T16:29:56.855401137Z,160,2,1108,A,A,13.470000000,15,0,360132781,130,165455,299064196,ARL
2025-07-17T16:29:57.332830897Z,2025-07-17T16:29:57.332665339Z,160,2,1108,C,A,13.500000000,100,0,359822513,130,165558,299070813,ARL
2025-07-17T16:29:57.333105446Z,2025-07-17T16:29:57.332939872Z,160,2,1108,C,A,14.260000000,700,0,358712189,130,165574,299070819,ARL
2025-07-17T16:29:57.333156116Z,2025-07-17T16:29:57.332990460Z,160,2,1108,A,A,14.460000000,700,0,360140477,130,165656,299070821,ARL
2025-07-17T16:29:57.333195864Z,2025-07-17T16:29:57.333030552Z,160,2,1108,A,A,15.700000000,100,0,360140481,130,165312,299070822,ARL
2025-07-17T16:29:57.333208890Z,2025-07-17T16:29:57.333043614Z,160,2,1108,C,A,15.390000000,100,0,359823113,130,165276,299070823,ARL
2025-07-17T16:29:57.333568888Z,2025-07-17T16:29:57.333403536Z,160,2,1108,C,A,14.170000000,100,0,358923345,130,165352,299070833,ARL
2025-07-17T16:29:57.333572711Z,2025-07-17T16:29:57.333406750Z,160,2,1108,C,A,14.550000000,100,0,359822537,0,165961,299070835,ARL
2025-07-17T16:29:57.333572711Z,2025-07-17T16:29:57.333406750Z,160,2,1108,A,A,14.600000000,100,0,360140517,130,165961,299070835,ARL
2025-07-17T16:29:57.333925540Z,2025-07-17T16:29:57.333760331Z,160,2,1108,A,A,14.380000000,100,0,360140533,130,165209,299070841,ARL
2025-07-17T16:29:57.334822203Z,2025-07-17T16:29:57.334656229Z,160,2,1108,C,A,14.490000000,100,0,359403985,0,165974,299070877,ARL
2025-07-17T16:29:57.334822203Z,2025-07-17T16:29:57.334656229Z,160,2,1108,A,A,14.800000000,100,0,360140589,130,165974,299070877,ARL
2025-07-17T16:29:57.339901613Z,2025-07-17T16:29:57.339736011Z,160,2,1108,C,A,17.280000000,100,0,358463581,0,165602,299070971,ARL
2025-07-17T16:29:57.339901613Z,2025-07-17T16:29:57.339736011Z,160,2,1108,A,A,17.570000000,100,0,360140717,130,165602,299070971,ARL
2025-07-17T16:29:57.341854711Z,2025-07-17T16:29:57.341688864Z,160,2,1108,C,A,15.620000000,100,0,358578669,0,165847,299071008,ARL
2025-07-17T16:29:57.341854711Z,2025-07-17T16:29:57.341688864Z,160,2,1108,A,A,15.910000000,100,0,360140821,130,165847,299071008,ARL
2025-07-17T16:29:57.342525486Z,2025-07-17T16:29:57.342360168Z,160,2,1108,C,A,14.330000000,100,0,359406981,130,165318,299071022,ARL
2025-07-17T16:29:57.342639692Z,2025-07-17T16:29:57.342474455Z,160,2,1108,A,A,14.620000000,100,0,360140857,130,165237,299071026,ARL
2025-07-17T16:29:57.346688326Z,2025-07-17T16:29:57.346522920Z,160,2,1108,C,A,13.830000000,100,0,358923457,130,165406,299071131,ARL
2025-07-17T16:29:57.346720621Z,2025-07-17T16:29:57.346555573Z,160,2,1108,C,A,14.460000000,700,0,360140477,130,165048,299071132,ARL
2025-07-17T16:29:57.346741243Z,2025-07-17T16:29:57.346575752Z,160,2,1108,A,A,14.050000000,100,0,360140905,130,165491,299071133,ARL
2025-07-17T16:29:57.348000139Z,2025-07-17T16:29:57.347834867Z,160,2,1108,C,A,15.910000000,100,0,360140821,0,165272,299071141,ARL
2025-07-17T16:29:57.348000139Z,2025-07-17T16:29:57.347834867Z,160,2,1108,A,A,16.080000000,100,0,360140929,130,165272,299071141,ARL
2025-07-17T16:29:57.348124513Z,2025-07-17T16:29:57.347958845Z,160,2,1108,C,A,15.090000000,100,0,356714685,0,165668,299071143,ARL
2025-07-17T16:29:57.348124513Z,2025-07-17T16:29:57.347958845Z,160,2,1108,A,A,15.380000000,100,0,360140933,130,165668,299071143,ARL
2025-07-17T16:29:57.349049138Z,2025-07-17T16:29:57.348883825Z,160,2,1108,C,A,14.800000000,100,0,360140589,0,165313,299071153,ARL
2025-07-17T16:29:57.349049138Z,2025-07-17T16:29:57.348883825Z,160,2,1108,A,A,14.960000000,100,0,360140941,130,165313,299071153,ARL
2025-07-17T16:29:57.351343046Z,2025-07-17T16:29:57.351177695Z,160,2,1108,A,A,13.480000000,100,0,360140981,130,165351,299071172,ARL
2025-07-17T16:29:57.352287132Z,2025-07-17T16:29:57.352121749Z,160,2,1108,C,A,17.570000000,100,0,360140717,0,165383,299071176,ARL
2025-07-17T16:29:57.352287132Z,2025-07-17T16:29:57.352121749Z,160,2,1108,A,A,17.120000000,100,0,360141021,130,165383,299071176,ARL
2025-07-17T16:29:57.352419974Z,2025-07-17T16:29:57.352254615Z,160,2,1108,C,A,15.380000000,100,0,360140933,0,165359,299071177,ARL
2025-07-17T16:29:57.352419974Z,2025-07-17T16:29:57.352254615Z,160,2,1108,A,A,14.830000000,100,0,360141029,130,165359,299071177,ARL
2025-07-17T16:29:57.353067391Z,2025-07-17T16:29:57.352902068Z,160,2,1108,C,A,14.960000000,100,0,360140941,0,165323,299071184,ARL
2025-07-17T16:29:57.353067391Z,2025-07-17T16:29:57.352902068Z,160,2,1108,A,A,14.430000000,100,0,360141061,130,165323,299071184,ARL
2025-07-17T16:29:57.354071099Z,2025-07-17T16:29:57.353905657Z,160,2,1108,C,A,16.080000000,100,0,360140929,0,165442,299071185,ARL
2025-07-17T16:29:57.354071099Z,2025-07-17T16:29:57.353905657Z,160,2,1108,A,A,15.510000000,100,0,360141065,130,165442,299071185,ARL
2025-07-17T16:29:57.365451513Z,2025-07-17T16:29:57.365286456Z,160,2,1108,C,A,14.050000000,100,0,360140905,130,165057,299071406,ARL
2025-07-17T16:29:57.365498767Z,2025-07-17T16:29:57.365333299Z,160,2,1108,A,A,14.260000000,100,0,360141269,130,165468,299071407,ARL
2025-07-17T16:29:57.366314396Z,2025-07-17T16:29:57.366149175Z,160,2,1108,C,A,14.260000000,100,0,360141269,130,165221,299071411,ARL
2025-07-17T16:29:57.366362094Z,2025-07-17T16:29:57.366196404Z,160,2,1108,A,A,13.750000000,100,0,360141273,130,165690,299071412,ARL
2025-07-17T16:29:57.383704211Z,2025-07-17T16:29:57.383538065Z,160,2,1108,C,A,14.600000000,100,0,360140517,0,166146,299071564,ARL
2025-07-17T16:29:57.383704211Z,2025-07-17T16:29:57.383538065Z,160,2,1108,A,A,14.530000000,100,0,360141385,130,166146,299071564,ARL
2025-07-17T16:29:57.383797807Z,2025-07-17T16:29:57.383632309Z,160,2,1108,A,A,15.370000000,100,0,360141393,130,165498,299071565,ARL
2025-07-17T16:29:57.383809834Z,2025-07-17T16:29:57.383644780Z,160,2,1108,C,A,15.700000000,100,0,360140481,130,165054,299071566,ARL
2025-07-17T16:29:57.430868958Z,2025-07-17T16:29:57.430703540Z,160,2,1108,A,A,14.680000000,700,0,360142241,130,165418,299072188,ARL
2025-07-17T16:29:57.981902498Z,2025-07-17T16:29:57.981737315Z,160,2,1108,C,A,14.380000000,100,0,360140533,130,165183,299079629,ARL
2025-07-17T16:29:57.982255734Z,2025-07-17T16:29:57.982089749Z,160,2,1108,A,A,14.080000000,100,0,360153053,130,165985,299079655,ARL
2025-07-17T16:29:58.344563086Z,2025-07-17T16:29:58.344397545Z,160,2,1108,C,A,14.620000000,100,0,360140857,0,165541,299094491,ARL
2025-07-17T16:29:58.344563086Z,2025-07-17T16:29:58.344397545Z,160,2,1108,A,A,14.270000000,100,0,360169365,130,165541,299094491,ARL
2025-07-17T16:30:02.830939841Z,2025-07-17T16:30:02.830774434Z,160,2,1108,A,A,14.190000000,700,0,360283881,130,165407,299196935,ARL
2025-07-17T16:30:02.830993081Z,2025-07-17T16:30:02.830827620Z,160,2,1108,C,A,14.680000000,700,0,360142241,130,165461,299196937,ARL
2025-07-17T16:30:05.499571762Z,2025-07-17T16:30:05.499406444Z,160,2,1108,C,A,13.490000000,15,0,359807057,130,165318,299240923,ARL
2025-07-17T16:30:10.414277885Z,2025-07-17T16:30:10.414112314Z,160,2,1108,C,A,13.470000000,15,0,360132781,130,165571,299312853,ARL
2025-07-17T16:30:10.416282484Z,2025-07-17T16:30:10.416115247Z,160,2,1108,A,A,13.450000000,15,0,360438585,130,167237,299313346,ARL
2025-07-17T16:30:10.418989003Z,2025-07-17T16:30:10.418822976Z,160,2,1108,C,A,14.460000000,100,0,358596029,0,166027,299313811,ARL
2025-07-17T16:30:10.418989003Z,2025-07-17T16:30:10.418822976Z,160,2,1108,A,A,14.350000000,100,0,360438973,130,166027,299313811,ARL
2025-07-17T16:30:10.422019848Z,2025-07-17T16:30:10.421853908Z,160,2,1108,C,A,14.460000000,100,0,358596037,0,165940,299314095,ARL
2025-07-17T16:30:10.422019848Z,2025-07-17T16:30:10.421853908Z,160,2,1108,A,A,14.350000000,100,0,360439617,130,165940,299314095,ARL
2025-07-17T16:30:10.853783416Z,2025-07-17T16:30:10.853617251Z,160,2,1108,C,A,13.450000000,15,0,360438585,128,166165,299339139,ARL
2025-07-17T16:30:17.586107006Z,2025-07-17T16:30:17.585941385Z,160,2,1108,C,A,13.820000000,2,0,359459321,0,165621,299471791,ARL
2025-07-17T16:30:17.586107006Z,2025-07-17T16:30:17.585941385Z,160,2,1108,A,A,13.740000000,2,0,360630309,130,165621,299471791,ARL
2025-07-17T16:30:20.998286323Z,2025-07-17T16:30:20.998120507Z,160,2,1108,C,A,13.480000000,100,0,360140981,130,165816,299514720,ARL
2025-07-17T16:30:22.627301648Z,2025-07-17T16:30:22.627136264Z,160,2,1108,A,A,13.760000000,100,0,360721497,130,165384,299534828,ARL
2025-07-17T16:30:22.654496103Z,2025-07-17T16:30:22.654329199Z,160,2,1108,A,A,13.470000000,15,0,360725173,128,166904,299538824,ARL
2025-07-17T16:30:22.654651825Z,2025-07-17T16:30:22.654486255Z,160,2,1108,C,A,13.760000000,100,0,360721497,0,165570,299538851,ARL
2025-07-17T16:30:22.654651825Z,2025-07-17T16:30:22.654486255Z,160,2,1108,A,A,13.480000000,100,0,360725257,130,165570,299538851,ARL
2025-07-17T16:30:22.654971708Z,2025-07-17T16:30:22.654806446Z,160,2,1108,A,A,15.680000000,100,0,360725401,130,165262,299538910,ARL
2025-07-17T16:30:22.654985047Z,2025-07-17T16:30:22.654819822Z,160,2,1108,C,A,15.370000000,100,0,360141393,130,165225,299538913,ARL
2025-07-17T16:30:22.682455022Z,2025-07-17T16:30:22.682289668Z,160,2,1108,A,A,15.370000000,100,0,360728161,130,165354,299541291,ARL
2025-07-17T16:30:22.682466689Z,2025-07-17T16:30:22.682301345Z,160,2,1108,C,A,15.680000000,100,0,360725401,130,165344,299541295,ARL
2025-07-17T16:30:32.855757165Z,2025-07-17T16:30:32.855591892Z,160,2,1108,A,A,13.450000000,15,0,360937965,130,165273,299703863,ARL
2025-07-17T16:30:37.085122421Z,2025-07-17T16:30:37.084955904Z,160,2,1108,C,A,13.480000000,100,0,360725257,0,166517,299811310,ARL
2025-07-17T16:30:37.085122421Z,2025-07-17T16:30:37.084955904Z,160,2,1108,A,A,13.460000000,100,0,361057077,128,166517,299811310,ARL
2025-07-17T16:30:37.085501718Z,2025-07-17T16:30:37.085335514Z,160,2,1108,A,A,15.680000000,100,0,361057217,130,166204,299811461,ARL
2025-07-17T16:30:37.085519774Z,2025-07-17T16:30:37.085351095Z,160,2,1108,C,A,15.370000000,100,0,360728161,128,168679,299811466,ARL
2025-07-17T16:30:37.112324295Z,2025-07-17T16:30:37.112159012Z,160,2,1108,A,A,15.350000000,100,0,361058745,130,165283,299812963,ARL
2025-07-17T16:30:37.112347226Z,2025-07-17T16:30:37.112182272Z,160,2,1108,C,A,15.680000000,100,0,361057217,130,164954,299812965,ARL
2025-07-17T16:30:37.137757858Z,2025-07-17T16:30:37.137592621Z,160,2,1108,C,A,13.470000000,15,0,360725173,130,165237,299813487,ARL
2025-07-17T16:30:37.141082421Z,2025-07-17T16:30:37.140913077Z,160,2,1108,C,A,15.090000000,100,0,356714861,0,169344,299815532,ARL
2025-07-17T16:30:37.141082421Z,2025-07-17T16:30:37.140913077Z,160,2,1108,A,A,14.810000000,100,0,361061909,128,169344,299815532,ARL
2025-07-17T16:30:38.141405894Z,2025-07-17T16:30:38.141240528Z,160,2,1108,A,A,13.430000000,15,0,361107853,130,165366,299865395,ARL
2025-07-17T16:30:47.573465649Z,2025-07-17T16:30:47.573300334Z,160,2,1108,C,A,13.450000000,15,0,360937965,130,165315,300016920,ARL
2025-07-17T16:30:48.578361111Z,2025-07-17T16:30:48.578195765Z,160,2,1108,A,A,13.410000000,15,0,361297545,130,165346,300031495,ARL
2025-07-17T16:31:01.839958311Z,2025-07-17T16:31:01.839792805Z,160,2,1108,C,A,13.430000000,15,0,361107853,130,165506,300264348,ARL
2025-07-17T16:31:03.518517508Z,2025-07-17T16:31:03.518351610Z,160,2,1108,A,A,13.390000000,15,0,361608869,130,165898,300289961,ARL
2025-07-17T16:31:54.027799461Z,2025-07-17T16:31:54.027625924Z,160,2,1108,C,A,13.390000000,15,0,361608869,128,173537,301134389,ARL
2025-07-17T16:31:54.028392397Z,2025-07-17T16:31:54.028224104Z,160,2,1108,C,A,13.410000000,15,0,361297545,128,168293,301134777,ARL
2025-07-17T16:31:54.032841763Z,2025-07-17T16:31:54.032676481Z,160,2,1108,A,A,13.400000000,15,0,362676381,130,165282,301135720,ARL
2025-07-17T16:31:54.397251889Z,2025-07-17T16:31:54.397082756Z,160,2,1108,C,A,13.400000000,15,0,362676381,128,169133,301159766,ARL
2025-07-17T16:32:07.237674436Z,2025-07-17T16:32:07.237509237Z,160,2,1108,A,A,13.430000000,15,0,363127401,130,165199,301520854,ARL
2025-07-17T16:32:11.247820316Z,2025-07-17T16:32:11.247654753Z,160,2,1108,A,A,13.410000000,15,0,363219933,130,165563,301601389,ARL
2025-07-17T16:32:14.460342711Z,2025-07-17T16:32:14.460177384Z,160,2,1108,C,A,13.430000000,15,0,363127401,130,165327,301668882,ARL
2025-07-17T16:32:15.800152246Z,2025-07-17T16:32:15.799985302Z,160,2,1108,A,A,13.390000000,15,0,363311909,128,166944,301682529,ARL
2025-07-17T16:32:24.791231377Z,2025-07-17T16:32:24.791064822Z,160,2,1108,C,A,13.390000000,15,0,363311909,130,166555,301841660,ARL
2025-07-17T16:32:24.791366155Z,2025-07-17T16:32:24.791200959Z,160,2,1108,C,A,13.410000000,15,0,363219933,130,165196,301841671,ARL
2025-07-17T16:32:29.844824236Z,2025-07-17T16:32:29.844658946Z,160,2,1108,A,A,13.450000000,15,0,363610537,130,165290,301914964,ARL
2025-07-17T16:32:29.844877268Z,2025-07-17T16:32:29.844711976Z,160,2,1108,C,A,13.460000000,100,0,361057077,130,165292,301914968,ARL
2025-07-17T16:32:29.845608090Z,2025-07-17T16:32:29.845442602Z,160,2,1108,C,A,14.190000000,700,0,360283881,130,165488,301914978,ARL
2025-07-17T16:32:29.845650966Z,2025-07-17T16:32:29.845485675Z,160,2,1108,A,A,14.440000000,700,0,363610557,130,165291,301914979,ARL
2025-07-17T16:32:29.845730661Z,2025-07-17T16:32:29.845565337Z,160,2,1108,A,A,15.680000000,100,0,363610573,130,165324,301914981,ARL
2025-07-17T16:32:29.845743278Z,2025-07-17T16:32:29.845577876Z,160,2,1108,C,A,15.350000000,100,0,361058745,130,165402,301914982,ARL
2025-07-17T16:32:29.846177627Z,2025-07-17T16:32:29.846012015Z,160,2,1108,C,A,14.080000000,100,0,360153053,130,165612,301914986,ARL
2025-07-17T16:32:29.846205975Z,2025-07-17T16:32:29.846040477Z,160,2,1108,C,A,14.530000000,100,0,360141385,0,165498,301914987,ARL
2025-07-17T16:32:29.846205975Z,2025-07-17T16:32:29.846040477Z,160,2,1108,A,A,14.820000000,100,0,363610585,130,165498,301914987,ARL
2025-07-17T16:32:29.846533245Z,2025-07-17T16:32:29.846367579Z,160,2,1108,A,A,14.360000000,100,0,363610593,130,165666,301914994,ARL
2025-07-17T16:32:29.846947063Z,2025-07-17T16:32:29.846781244Z,160,2,1108,C,A,14.830000000,100,0,360141029,0,165819,301914995,ARL
2025-07-17T16:32:29.846947063Z,2025-07-17T16:32:29.846781244Z,160,2,1108,A,A,15.130000000,100,0,363610597,130,165819,301914995,ARL
2025-07-17T16:32:29.848251064Z,2025-07-17T16:32:29.848085539Z,160,2,1108,C,A,14.430000000,100,0,360141061,0,165525,301915015,ARL
2025-07-17T16:32:29.848251064Z,2025-07-17T16:32:29.848085539Z,160,2,1108,A,A,14.720000000,100,0,363610609,130,165525,301915015,ARL
2025-07-17T16:32:29.852212038Z,2025-07-17T16:32:29.852046762Z,160,2,1108,C,A,14.270000000,100,0,360169365,130,165276,301915065,ARL
2025-07-17T16:32:29.852330001Z,2025-07-17T16:32:29.852164762Z,160,2,1108,A,A,14.540000000,100,0,363610649,130,165239,301915069,ARL
2025-07-17T16:32:29.856094796Z,2025-07-17T16:32:29.855929386Z,160,2,1108,C,A,13.750000000,100,0,360141273,130,165410,301915115,ARL
2025-07-17T16:32:29.856125341Z,2025-07-17T16:32:29.855960388Z,160,2,1108,C,A,14.440000000,700,0,363610557,130,164953,301915116,ARL
2025-07-17T16:32:29.856146919Z,2025-07-17T16:32:29.855981505Z,160,2,1108,A,A,14.030000000,100,0,363610673,130,165414,301915117,ARL
2025-07-17T16:32:29.856633974Z,2025-07-17T16:32:29.856468614Z,160,2,1108,C,A,17.120000000,100,0,360141021,0,165360,301915132,ARL
2025-07-17T16:32:29.856633974Z,2025-07-17T16:32:29.856468614Z,160,2,1108,A,A,17.470000000,100,0,363610693,130,165360,301915132,ARL
2025-07-17T16:32:29.858388801Z,2025-07-17T16:32:29.858223356Z,160,2,1108,C,A,14.720000000,100,0,363610609,0,165445,301915141,ARL
2025-07-17T16:32:29.858388801Z,2025-07-17T16:32:29.858223356Z,160,2,1108,A,A,14.960000000,100,0,363610717,130,165445,301915141,ARL
2025-07-17T16:32:29.858677341Z,2025-07-17T16:32:29.858512166Z,160,2,1108,C,A,17.470000000,100,0,363610693,0,165175,301915143,ARL
2025-07-17T16:32:29.858677341Z,2025-07-17T16:32:29.858512166Z,160,2,1108,A,A,17.760000000,100,0,363610725,130,165175,301915143,ARL
2025-07-17T16:32:29.858881677Z,2025-07-17T16:32:29.858716093Z,160,2,1108,C,A,13.740000000,2,0,360630309,0,165584,301915144,ARL
2025-07-17T16:32:29.858881677Z,2025-07-17T16:32:29.858716093Z,160,2,1108,A,A,13.980000000,2,0,363610729,130,165584,301915144,ARL
2025-07-17T16:32:29.863575931Z,2025-07-17T16:32:29.863410456Z,160,2,1108,C,A,15.510000000,100,0,360141065,0,165475,301915198,ARL
2025-07-17T16:32:29.863575931Z,2025-07-17T16:32:29.863410456Z,160,2,1108,A,A,16.080000000,100,0,363610781,130,165475,301915198,ARL
2025-07-17T16:32:29.876261150Z,2025-07-17T16:32:29.876096205Z,160,2,1108,C,A,14.030000000,100,0,363610673,130,164945,301915267,ARL
2025-07-17T16:32:29.876312329Z,2025-07-17T16:32:29.876146665Z,160,2,1108,A,A,14.250000000,100,0,363610909,130,165664,301915268,ARL
2025-07-17T16:32:29.896881841Z,2025-07-17T16:32:29.896716493Z,160,2,1108,C,A,14.820000000,100,0,363610585,0,165348,301915452,ARL
2025-07-17T16:32:29.896881841Z,2025-07-17T16:32:29.896716493Z,160,2,1108,A,A,15.050000000,100,0,363611165,130,165348,301915452,ARL
2025-07-17T16:32:29.911727568Z,2025-07-17T16:32:29.911561450Z,160,2,1108,C,A,14.810000000,100,0,361061909,0,166118,301915916,ARL
2025-07-17T16:32:29.911727568Z,2025-07-17T16:32:29.911561450Z,160,2,1108,A,A,15.380000000,100,0,363611625,130,166118,301915916,ARL
2025-07-17T16:32:29.912427241Z,2025-07-17T16:32:29.912262068Z,160,2,1108,A,A,13.460000000,100,0,363611637,130,165173,301915922,ARL
2025-07-17T16:32:29.912463917Z,2025-07-17T16:32:29.912298767Z,160,2,1108,A,A,14.680000000,700,0,363611641,130,165150,301915924,ARL
2025-07-17T16:32:29.913247496Z,2025-07-17T16:32:29.913082173Z,160,2,1108,C,A,14.960000000,100,0,363610717,0,165323,301915949,ARL
2025-07-17T16:32:29.913247496Z,2025-07-17T16:32:29.913082173Z,160,2,1108,A,A,14.410000000,100,0,363611673,130,165323,301915949,ARL
2025-07-17T16:32:29.914160360Z,2025-07-17T16:32:29.913994843Z,160,2,1108,C,A,16.080000000,100,0,363610781,0,165517,301915983,ARL
2025-07-17T16:32:29.914160360Z,2025-07-17T16:32:29.913994843Z,160,2,1108,A,A,15.480000000,100,0,363611705,130,165517,301915983,ARL
2025-07-17T16:32:29.914524992Z,2025-07-17T16:32:29.914359529Z,160,2,1108,C,A,15.130000000,100,0,363610597,0,165463,301915988,ARL
2025-07-17T16:32:29.914524992Z,2025-07-17T16:32:29.914359529Z,160,2,1108,A,A,14.810000000,100,0,363611729,130,165463,301915988,ARL
2025-07-17T16:32:29.915512824Z,2025-07-17T16:32:29.915347468Z,160,2,1108,C,A,17.760000000,100,0,363610725,0,165356,301915999,ARL
2025-07-17T16:32:29.915512824Z,2025-07-17T16:32:29.915347468Z,160,2,1108,A,A,17.100000000,100,0,363611757,130,165356,301915999,ARL
2025-07-17T16:32:29.935991671Z,2025-07-17T16:32:29.935826022Z,160,2,1108,C,A,14.250000000,100,0,363610909,130,165649,301916340,ARL
2025-07-17T16:32:29.936042528Z,2025-07-17T16:32:29.935877281Z,160,2,1108,A,A,13.730000000,100,0,363612541,130,165247,301916344,ARL
2025-07-17T16:32:29.947196531Z,2025-07-17T16:32:29.947031116Z,160,2,1108,C,A,15.050000000,100,0,363611165,0,165415,301916544,ARL
2025-07-17T16:32:29.947196531Z,2025-07-17T16:32:29.947031116Z,160,2,1108,A,A,14.500000000,100,0,363612705,130,165415,301916544,ARL
2025-07-17T16:32:29.947345343Z,2025-07-17T16:32:29.947180178Z,160,2,1108,A,A,15.350000000,100,0,363612709,130,165165,301916556,ARL
2025-07-17T16:32:29.947357860Z,2025-07-17T16:32:29.947192760Z,160,2,1108,C,A,15.680000000,100,0,363610573,130,165100,301916557,ARL
2025-07-17T16:32:29.961306182Z,2025-07-17T16:32:29.961140793Z,160,2,1108,C,A,15.380000000,100,0,363611625,0,165389,301916908,ARL
2025-07-17T16:32:29.961306182Z,2025-07-17T16:32:29.961140793Z,160,2,1108,A,A,14.810000000,100,0,363613421,130,165389,301916908,ARL
2025-07-17T16:32:30.189607246Z,2025-07-17T16:32:30.189441584Z,160,2,1108,C,A,13.980000000,2,0,363610729,0,165662,301922126,ARL
2025-07-17T16:32:30.189607246Z,2025-07-17T16:32:30.189441584Z,160,2,1108,A,A,13.700000000,2,0,363619809,130,165662,301922126,ARL
2025-07-17T16:32:30.540993820Z,2025-07-17T16:32:30.540828846Z,160,2,1108,C,A,14.360000000,100,0,363610593,130,164974,301928173,ARL
2025-07-17T16:32:30.541354303Z,2025-07-17T16:32:30.541188934Z,160,2,1108,A,A,14.060000000,100,0,363629061,130,165369,301928175,ARL
2025-07-17T16:32:30.850033052Z,2025-07-17T16:32:30.849867081Z,160,2,1108,C,A,14.540000000,100,0,363610649,0,165971,301933741,ARL
2025-07-17T16:32:30.850033052Z,2025-07-17T16:32:30.849867081Z,160,2,1108,A,A,14.250000000,100,0,363634009,130,165971,301933741,ARL
2025-07-17T16:32:34.631558459Z,2025-07-17T16:32:34.631393080Z,160,2,1108,A,A,14.180000000,700,0,363687721,130,165379,301979109,ARL
2025-07-17T16:32:34.631614296Z,2025-07-17T16:32:34.631448936Z,160,2,1108,C,A,14.680000000,700,0,363611641,130,165360,301979110,ARL
2025-07-17T16:32:34.860112637Z,2025-07-17T16:32:34.859947247Z,160,2,1108,C,A,13.450000000,15,0,363610537,130,165390,301982608,ARL
2025-07-17T16:33:30.089876358Z,2025-07-17T16:33:30.089711013Z,160,2,1108,C,A,13.460000000,100,0,363611637,130,165345,302886447,ARL
2025-07-17T16:33:30.090411681Z,2025-07-17T16:33:30.090246420Z,160,2,1108,C,A,14.180000000,700,0,363687721,130,165261,302886453,ARL
2025-07-17T16:33:30.090471806Z,2025-07-17T16:33:30.090305998Z,160,2,1108,A,A,14.420000000,700,0,364850805,130,165808,302886454,ARL
2025-07-17T16:33:30.090529831Z,2025-07-17T16:33:30.090364347Z,160,2,1108,A,A,15.660000000,100,0,364850813,130,165484,302886455,ARL
2025-07-17T16:33:30.090542969Z,2025-07-17T16:33:30.090377015Z,160,2,1108,C,A,15.350000000,100,0,363612709,130,165954,302886456,ARL
2025-07-17T16:33:30.090979781Z,2025-07-17T16:33:30.090814383Z,160,2,1108,C,A,14.500000000,100,0,363612705,0,165398,302886457,ARL
2025-07-17T16:33:30.090979781Z,2025-07-17T16:33:30.090814383Z,160,2,1108,A,A,14.790000000,100,0,364850825,130,165398,302886457,ARL
2025-07-17T16:33:30.090981115Z,2025-07-17T16:33:30.090815784Z,160,2,1108,C,A,14.060000000,100,0,363629061,130,165331,302886458,ARL
2025-07-17T16:33:30.091339021Z,2025-07-17T16:33:30.091173730Z,160,2,1108,A,A,14.340000000,100,0,364850829,130,165291,302886460,ARL
2025-07-17T16:33:30.091704420Z,2025-07-17T16:33:30.091538911Z,160,2,1108,C,A,14.810000000,100,0,363611729,0,165509,302886484,ARL
2025-07-17T16:33:30.091704420Z,2025-07-17T16:33:30.091538911Z,160,2,1108,A,A,15.110000000,100,0,364850837,130,165509,302886484,ARL
2025-07-17T16:33:30.092954819Z,2025-07-17T16:33:30.092789154Z,160,2,1108,C,A,14.410000000,100,0,363611673,0,165665,302886527,ARL
2025-07-17T16:33:30.092954819Z,2025-07-17T16:33:30.092789154Z,160,2,1108,A,A,14.700000000,100,0,364850845,130,165665,302886527,ARL
2025-07-17T16:33:30.096101526Z,2025-07-17T16:33:30.095936436Z,160,2,1108,C,A,14.250000000,100,0,363634009,130,165090,302886538,ARL
2025-07-17T16:33:30.096245867Z,2025-07-17T16:33:30.096080731Z,160,2,1108,A,A,14.520000000,100,0,364850857,130,165136,302886541,ARL
2025-07-17T16:33:30.098419156Z,2025-07-17T16:33:30.098253924Z,160,2,1108,C,A,13.730000000,100,0,363612541,130,165232,302886562,ARL
2025-07-17T16:33:30.098450406Z,2025-07-17T16:33:30.098285415Z,160,2,1108,C,A,14.420000000,700,0,364850805,130,164991,302886563,ARL
2025-07-17T16:33:30.098470153Z,2025-07-17T16:33:30.098305102Z,160,2,1108,A,A,14.000000000,100,0,364850865,130,165051,302886564,ARL
2025-07-17T16:33:30.098761100Z,2025-07-17T16:33:30.098595621Z,160,2,1108,C,A,13.700000000,2,0,363619809,0,165479,302886565,ARL
2025-07-17T16:33:30.098761100Z,2025-07-17T16:33:30.098595621Z,160,2,1108,A,A,13.950000000,2,0,364850881,130,165479,302886565,ARL
2025-07-17T16:33:30.101155441Z,2025-07-17T16:33:30.100990024Z,160,2,1108,C,A,14.700000000,100,0,364850845,0,165417,302886578,ARL
2025-07-17T16:33:30.101155441Z,2025-07-17T16:33:30.100990024Z,160,2,1108,A,A,14.960000000,100,0,364850901,130,165417,302886578,ARL
2025-07-17T16:33:30.108057014Z,2025-07-17T16:33:30.107892023Z,160,2,1108,C,A,14.000000000,100,0,364850865,130,164991,302887072,ARL
2025-07-17T16:33:30.108104876Z,2025-07-17T16:33:30.107939741Z,160,2,1108,A,A,14.230000000,100,0,364851745,130,165135,302887073,ARL
2025-07-17T16:33:30.141192726Z,2025-07-17T16:33:30.141027528Z,160,2,1108,C,A,14.790000000,100,0,364850825,0,165198,302887727,ARL
2025-07-17T16:33:30.141192726Z,2025-07-17T16:33:30.141027528Z,160,2,1108,A,A,15.030000000,100,0,364852537,130,165198,302887727,ARL
2025-07-17T16:33:30.231850974Z,2025-07-17T16:33:30.231685682Z,160,2,1108,A,A,14.680000000,700,0,364854641,130,165292,302888895,ARL
2025-07-17T16:33:30.282473088Z,2025-07-17T16:33:30.282307803Z,160,2,1108,C,A,17.100000000,100,0,363611757,0,165285,302889833,ARL
2025-07-17T16:33:30.282473088Z,2025-07-17T16:33:30.282307803Z,160,2,1108,A,A,17.760000000,100,0,364856173,130,165285,302889833,ARL
2025-07-17T16:33:30.282512638Z,2025-07-17T16:33:30.282347113Z,160,2,1108,C,A,15.480000000,100,0,363611705,0,165525,302889834,ARL
2025-07-17T16:33:30.282512638Z,2025-07-17T16:33:30.282347113Z,160,2,1108,A,A,16.080000000,100,0,364856177,130,165525,302889834,ARL
2025-07-17T16:33:30.550834917Z,2025-07-17T16:33:30.550669776Z,160,2,1108,A,A,14.810000000,100,0,364862229,130,165141,302893143,ARL
2025-07-17T16:33:30.550848293Z,2025-07-17T16:33:30.550682972Z,160,2,1108,C,A,14.530000000,100,0,356722649,130,165321,302893144,ARL
2025-07-17T16:33:30.604637872Z,2025-07-17T16:33:30.604472710Z,160,2,1108,C,A,14.810000000,100,0,363613421,0,165162,302893497,ARL
2025-07-17T16:33:30.604637872Z,2025-07-17T16:33:30.604472710Z,160,2,1108,A,A,15.380000000,100,0,364862793,130,165162,302893497,ARL
2025-07-17T16:33:30.612521721Z,2025-07-17T16:33:30.612356156Z,160,2,1108,C,A,14.490000000,100,0,359404829,0,165565,302893537,ARL
2025-07-17T16:33:30.612521721Z,2025-07-17T16:33:30.612356156Z,160,2,1108,A,A,14.960000000,100,0,364862829,130,165565,302893537,ARL
2025-07-17T16:33:30.817241936Z,2025-07-17T16:33:30.817076178Z,160,2,1108,C,A,14.340000000,100,0,364850829,130,165758,302896626,ARL
2025-07-17T16:33:30.817590929Z,2025-07-17T16:33:30.817425307Z,160,2,1108,A,A,14.600000000,100,0,364866209,130,165622,302896627,ARL
2025-07-17T16:33:30.966227665Z,2025-07-17T16:33:30.966062395Z,160,2,1108,A,A,13.960000000,100,0,364868901,130,165270,302898973,ARL
2025-07-17T16:33:31.084776432Z,2025-07-17T16:33:31.084610021Z,160,2,1108,A,A,14.510000000,100,0,364870969,0,166411,302900128,ARL
2025-07-17T16:33:31.084776432Z,2025-07-17T16:33:31.084610406Z,160,2,1108,C,A,14.230000000,100,0,356878397,130,166026,302900129,ARL
2025-07-17T16:33:31.101033838Z,2025-07-17T16:33:31.100868523Z,160,2,1108,C,A,14.520000000,100,0,364850857,0,165315,302900253,ARL
2025-07-17T16:33:31.101033838Z,2025-07-17T16:33:31.100868523Z,160,2,1108,A,A,14.750000000,100,0,364871373,130,165315,302900253,ARL
2025-07-17T16:33:44.518160840Z,2025-07-17T16:33:44.517994545Z,160,2,1108,A,A,13.430000000,15,0,365099977,130,166295,303072465,ARL
2025-07-17T16:33:44.586150696Z,2025-07-17T16:33:44.585985363Z,160,2,1108,C,B,12.900000000,2,0,357261961,0,165333,303074172,ARL
2025-07-17T16:33:44.586150696Z,2025-07-17T16:33:44.585985363Z,160,2,1108,A,B,12.990000000,2,0,365101121,130,165333,303074172,ARL
2025-07-17T16:33:54.862730370Z,2025-07-17T16:33:54.862565014Z,160,2,1108,A,A,13.410000000,15,0,365283485,130,165356,303210030,ARL
2025-07-17T16:33:59.769411538Z,2025-07-17T16:33:59.769246037Z,160,2,1108,C,A,13.960000000,100,0,364868901,0,165501,303268214,ARL
2025-07-17T16:33:59.769411538Z,2025-07-17T16:33:59.769246037Z,160,2,1108,A,A,13.940000000,100,0,365359953,130,165501,303268214,ARL
2025-07-17T16:33:59.769696813Z,2025-07-17T16:33:59.769531404Z,160,2,1108,C,A,13.950000000,2,0,364850881,0,165409,303268221,ARL
2025-07-17T16:33:59.769696813Z,2025-07-17T16:33:59.769531404Z,160,2,1108,A,A,13.940000000,2,0,365359981,130,165409,303268221,ARL
2025-07-17T16:34:17.588352560Z,2025-07-17T16:34:17.588187064Z,160,2,1108,C,B,12.990000000,2,0,365101121,0,165496,303567720,ARL
2025-07-17T16:34:17.588352560Z,2025-07-17T16:34:17.588187064Z,160,2,1108,A,B,13.070000000,2,0,365743281,130,165496,303567720,ARL
2025-07-17T16:34:22.930893268Z,2025-07-17T16:34:22.930728013Z,160,2,1108,C,A,13.430000000,15,0,365099977,130,165255,303633305,ARL
2025-07-17T16:34:23.935665713Z,2025-07-17T16:34:23.935500330Z,160,2,1108,A,A,13.390000000,15,0,365868793,130,165383,303659749,ARL
2025-07-17T16:34:24.279536922Z,2025-07-17T16:34:24.279370835Z,160,2,1108,C,A,13.940000000,100,0,365359953,0,166087,303666139,ARL
2025-07-17T16:34:24.279536922Z,2025-07-17T16:34:24.279370835Z,160,2,1108,A,A,13.920000000,100,0,365876341,130,166087,303666139,ARL
2025-07-17T16:36:08.787698556Z,2025-07-17T16:36:08.787533217Z,160,2,1108,A,A,13.420000000,100,0,367721465,130,165339,305042754,ARL
2025-07-17T16:36:08.788442796Z,2025-07-17T16:36:08.788277510Z,160,2,1108,C,A,14.600000000,100,0,364866209,130,165286,305042787,ARL
2025-07-17T16:36:08.788471709Z,2025-07-17T16:36:08.788305174Z,160,2,1108,C,A,15.030000000,100,0,364852537,0,166535,305042788,ARL
2025-07-17T16:36:08.788471709Z,2025-07-17T16:36:08.788305174Z,160,2,1108,A,A,14.460000000,100,0,367721513,128,166535,305042788,ARL
2025-07-17T16:36:08.788838644Z,2025-07-17T16:36:08.788673150Z,160,2,1108,A,A,14.020000000,100,0,367721521,130,165494,305042798,ARL
2025-07-17T16:36:08.789146698Z,2025-07-17T16:36:08.788981147Z,160,2,1108,C,A,15.110000000,100,0,364850837,0,165551,305042803,ARL
2025-07-17T16:36:08.789146698Z,2025-07-17T16:36:08.788981147Z,160,2,1108,A,A,14.770000000,100,0,367721529,130,165551,305042803,ARL
2025-07-17T16:36:08.791164652Z,2025-07-17T16:36:08.790998871Z,160,2,1108,C,A,14.960000000,100,0,364850901,0,165781,305042843,ARL
2025-07-17T16:36:08.791164652Z,2025-07-17T16:36:08.790998871Z,160,2,1108,A,A,14.360000000,100,0,367721617,130,165781,305042843,ARL
2025-07-17T16:36:08.802593384Z,2025-07-17T16:36:08.802427847Z,160,2,1108,C,A,17.760000000,100,0,364856173,0,165537,305042999,ARL
2025-07-17T16:36:08.802593384Z,2025-07-17T16:36:08.802427847Z,160,2,1108,A,A,17.050000000,100,0,367721809,130,165537,305042999,ARL
2025-07-17T16:36:08.812971603Z,2025-07-17T16:36:08.812806109Z,160,2,1108,C,A,16.080000000,100,0,364856177,0,165494,305043103,ARL
2025-07-17T16:36:08.812971603Z,2025-07-17T16:36:08.812806109Z,160,2,1108,A,A,15.440000000,100,0,367721961,130,165494,305043103,ARL
2025-07-17T16:36:08.813050203Z,2025-07-17T16:36:08.812884878Z,160,2,1108,A,A,15.300000000,100,0,367721965,130,165325,305043104,ARL
2025-07-17T16:36:08.813063372Z,2025-07-17T16:36:08.812897639Z,160,2,1108,C,A,15.660000000,100,0,364850813,130,165733,305043107,ARL
2025-07-17T16:36:08.813263755Z,2025-07-17T16:36:08.813098222Z,160,2,1108,C,A,14.230000000,100,0,364851745,130,165533,305043109,ARL
2025-07-17T16:36:08.813315868Z,2025-07-17T16:36:08.813150617Z,160,2,1108,A,A,13.690000000,100,0,367721969,130,165251,305043110,ARL
2025-07-17T16:36:08.846656621Z,2025-07-17T16:36:08.846490705Z,160,2,1108,C,A,15.380000000,100,0,364862793,0,165916,305043330,ARL
2025-07-17T16:36:08.846656621Z,2025-07-17T16:36:08.846490705Z,160,2,1108,A,A,14.770000000,100,0,367722305,130,165916,305043330,ARL
2025-07-17T16:36:08.861304636Z,2025-07-17T16:36:08.861139066Z,160,2,1108,C,A,14.960000000,100,0,364862829,0,165570,305043519,ARL
2025-07-17T16:36:08.861304636Z,2025-07-17T16:36:08.861139066Z,160,2,1108,A,A,14.360000000,100,0,367722697,130,165570,305043519,ARL
2025-07-17T16:36:08.927786326Z,2025-07-17T16:36:08.927620800Z,160,2,1108,A,A,14.220000000,100,0,367724041,130,165526,305044162,ARL
2025-07-17T16:36:08.927798815Z,2025-07-17T16:36:08.927633466Z,160,2,1108,C,A,14.810000000,100,0,364862229,130,165349,305044165,ARL
2025-07-17T16:36:08.966850725Z,2025-07-17T16:36:08.966685380Z,160,2,1108,A,A,13.950000000,100,0,367724713,130,165345,305045055,ARL
2025-07-17T16:36:08.966851572Z,2025-07-17T16:36:08.966686422Z,160,2,1108,C,A,14.510000000,100,0,364870969,130,165150,305045056,ARL
2025-07-17T16:36:08.984637170Z,2025-07-17T16:36:08.984471681Z,160,2,1108,C,A,14.750000000,100,0,364871373,130,165489,305045288,ARL
2025-07-17T16:36:08.984778799Z,2025-07-17T16:36:08.984613329Z,160,2,1108,A,A,14.210000000,100,0,367724841,130,165470,305045290,ARL
2025-07-17T16:36:09.002025490Z,2025-07-17T16:36:09.001859949Z,160,2,1108,C,A,13.920000000,100,0,365876341,0,165541,305045747,ARL
2025-07-17T16:36:09.002025490Z,2025-07-17T16:36:09.001859949Z,160,2,1108,A,A,13.430000000,100,0,367725181,130,165541,305045747,ARL
2025-07-17T16:36:09.186314332Z,2025-07-17T16:36:09.186148784Z,160,2,1108,C,B,13.070000000,2,0,365743281,0,165548,305049492,ARL
2025-07-17T16:36:09.186314332Z,2025-07-17T16:36:09.186148784Z,160,2,1108,A,B,12.990000000,2,0,367731761,130,165548,305049492,ARL
2025-07-17T16:36:15.432347217Z,2025-07-17T16:36:15.432181896Z,160,2,1108,A,A,14.160000000,700,0,367862613,130,165321,305159106,ARL
2025-07-17T16:36:15.432402085Z,2025-07-17T16:36:15.432236641Z,160,2,1108,C,A,14.680000000,700,0,364854641,130,165444,305159107,ARL
2025-07-17T16:36:15.790152351Z,2025-07-17T16:36:15.789986725Z,160,2,1108,C,A,13.940000000,2,0,365359981,0,165626,305163657,ARL
2025-07-17T16:36:15.790152351Z,2025-07-17T16:36:15.789986725Z,160,2,1108,A,A,13.850000000,2,0,367868161,130,165626,305163657,ARL
2025-07-17T16:36:25.985864517Z,2025-07-17T16:36:25.985698920Z,160,2,1108,C,A,13.850000000,2,0,367868161,0,165597,305274495,ARL
2025-07-17T16:36:25.985864517Z,2025-07-17T16:36:25.985698920Z,160,2,1108,A,A,13.770000000,2,0,368018937,130,165597,305274495,ARL
2025-07-17T16:37:00.790007451Z,2025-07-17T16:37:00.789841841Z,160,2,1108,C,A,13.770000000,2,0,368018937,0,165610,305798904,ARL
2025-07-17T16:37:00.790007451Z,2025-07-17T16:37:00.789841841Z,160,2,1108,A,A,13.700000000,2,0,368710393,130,165610,305798904,ARL
2025-07-17T16:37:37.386246890Z,2025-07-17T16:37:37.386081296Z,160,2,1108,C,B,12.990000000,2,0,367731761,0,165594,306324624,ARL
2025-07-17T16:37:37.386246890Z,2025-07-17T16:37:37.386081296Z,160,2,1108,A,B,12.910000000,2,0,369392197,130,165594,306324624,ARL
2025-07-17T16:38:28.877605130Z,2025-07-17T16:38:28.877439870Z,160,2,1108,C,A,13.420000000,100,0,367721465,130,165260,307157610,ARL
2025-07-17T16:38:28.883758401Z,2025-07-17T16:38:28.883590127Z,160,2,1108,C,A,13.390000000,15,0,365868793,130,168274,307158368,ARL
2025-07-17T16:38:28.883887122Z,2025-07-17T16:38:28.883720539Z,160,2,1108,C,A,13.410000000,15,0,365283485,130,166583,307158422,ARL
2025-07-17T16:38:28.883934720Z,2025-07-17T16:38:28.883766503Z,160,2,1108,C,A,13.430000000,100,0,367725181,128,168217,307158437,ARL
2025-07-17T16:38:28.884318504Z,2025-07-17T16:38:28.884148996Z,160,2,1108,A,A,15.610000000,100,0,370436969,128,169508,307158593,ARL
2025-07-17T16:38:28.884351321Z,2025-07-17T16:38:28.884182090Z,160,2,1108,C,A,15.300000000,100,0,367721965,128,169231,307158605,ARL
2025-07-17T16:38:28.884686671Z,2025-07-17T16:38:28.884518373Z,160,2,1108,C,A,14.020000000,100,0,367721521,128,168298,307158750,ARL
2025-07-17T16:38:28.884970150Z,2025-07-17T16:38:28.884800337Z,160,2,1108,C,A,14.460000000,100,0,367721513,0,169813,307158964,ARL
2025-07-17T16:38:28.884970150Z,2025-07-17T16:38:28.884800337Z,160,2,1108,A,A,14.750000000,100,0,370437189,128,169813,307158964,ARL
2025-07-17T16:38:28.885052688Z,2025-07-17T16:38:28.884882340Z,160,2,1108,A,A,14.300000000,100,0,370437229,128,170348,307159022,ARL
2025-07-17T16:38:28.885228455Z,2025-07-17T16:38:28.885058824Z,160,2,1108,C,A,14.160000000,700,0,367862613,128,169631,307159152,ARL
2025-07-17T16:38:28.885283551Z,2025-07-17T16:38:28.885115892Z,160,2,1108,A,A,14.380000000,700,0,370437313,128,167659,307159202,ARL
2025-07-17T16:38:28.887253724Z,2025-07-17T16:38:28.887087949Z,160,2,1108,C,A,14.210000000,100,0,367724841,0,165775,307160536,ARL
2025-07-17T16:38:28.887253724Z,2025-07-17T16:38:28.887087949Z,160,2,1108,A,A,14.480000000,100,0,370438201,130,165775,307160536,ARL
2025-07-17T16:38:28.889826283Z,2025-07-17T16:38:28.889660801Z,160,2,1108,C,A,14.770000000,100,0,367721529,0,165482,307160792,ARL
2025-07-17T16:38:28.889826283Z,2025-07-17T16:38:28.889660801Z,160,2,1108,A,A,15.060000000,100,0,370438421,130,165482,307160792,ARL
2025-07-17T16:38:28.890349366Z,2025-07-17T16:38:28.890183678Z,160,2,1108,C,A,13.690000000,100,0,367721969,130,165688,307160811,ARL
2025-07-17T16:38:28.890403384Z,2025-07-17T16:38:28.890238112Z,160,2,1108,A,A,13.960000000,100,0,370438445,130,165272,307160812,ARL
2025-07-17T16:38:28.890431413Z,2025-07-17T16:38:28.890265892Z,160,2,1108,A,A,15.910000000,100,0,370438453,130,165521,307160813,ARL
2025-07-17T16:38:28.890443766Z,2025-07-17T16:38:28.890278750Z,160,2,1108,C,A,15.610000000,100,0,370436969,130,165016,307160814,ARL
2025-07-17T16:38:28.890618429Z,2025-07-17T16:38:28.890453007Z,160,2,1108,C,A,17.050000000,100,0,367721809,0,165422,307160820,ARL
2025-07-17T16:38:28.890618429Z,2025-07-17T16:38:28.890453007Z,160,2,1108,A,A,17.390000000,100,0,370438461,130,165422,307160820,ARL
2025-07-17T16:38:28.890944566Z,2025-07-17T16:38:28.890779005Z,160,2,1108,C,A,14.360000000,100,0,367721617,0,165561,307160837,ARL
2025-07-17T16:38:28.890944566Z,2025-07-17T16:38:28.890779005Z,160,2,1108,A,A,14.650000000,100,0,370438481,130,165561,307160837,ARL
2025-07-17T16:38:28.891575770Z,2025-07-17T16:38:28.891410504Z,160,2,1108,C,A,14.380000000,700,0,370437313,130,165266,307160861,ARL
2025-07-17T16:38:28.895968390Z,2025-07-17T16:38:28.895803145Z,160,2,1108,C,A,15.060000000,100,0,370438421,0,165245,307161275,ARL
2025-07-17T16:38:28.895968390Z,2025-07-17T16:38:28.895803145Z,160,2,1108,A,A,15.350000000,100,0,370438965,130,165245,307161275,ARL
2025-07-17T16:38:28.897123213Z,2025-07-17T16:38:28.896958047Z,160,2,1108,C,A,14.650000000,100,0,370438481,0,165166,307161432,ARL
2025-07-17T16:38:28.897123213Z,2025-07-17T16:38:28.896958047Z,160,2,1108,A,A,14.930000000,100,0,370439269,130,165166,307161432,ARL
2025-07-17T16:38:28.897838481Z,2025-07-17T16:38:28.897673510Z,160,2,1108,C,A,13.960000000,100,0,370438445,130,164971,307161526,ARL
2025-07-17T16:38:28.897891864Z,2025-07-17T16:38:28.897725631Z,160,2,1108,A,A,14.190000000,100,0,370439549,130,166233,307161541,ARL
2025-07-17T16:38:28.898754842Z,2025-07-17T16:38:28.898589292Z,160,2,1108,C,A,13.700000000,2,0,368710393,0,165550,307161601,ARL
2025-07-17T16:38:28.898754842Z,2025-07-17T16:38:28.898589292Z,160,2,1108,A,A,13.950000000,2,0,370439617,130,165550,307161601,ARL
2025-07-17T16:38:28.898966117Z,2025-07-17T16:38:28.898800185Z,160,2,1108,C,A,15.440000000,100,0,367721961,0,165932,307161618,ARL
2025-07-17T16:38:28.898966117Z,2025-07-17T16:38:28.898800185Z,160,2,1108,A,A,16.050000000,100,0,370439621,130,165932,307161618,ARL
2025-07-17T16:38:28.918317468Z,2025-07-17T16:38:28.918152257Z,160,2,1108,A,A,13.960000000,100,0,370441181,130,165211,307162629,ARL
2025-07-17T16:38:28.925611932Z,2025-07-17T16:38:28.925445126Z,160,2,1108,C,A,17.390000000,100,0,370438461,0,166806,307163085,ARL
2025-07-17T16:38:28.925611932Z,2025-07-17T16:38:28.925445126Z,160,2,1108,A,A,17.720000000,100,0,370441693,128,166806,307163085,ARL
2025-07-17T16:38:28.927371798Z,2025-07-17T16:38:28.927205812Z,160,2,1108,C,A,14.770000000,100,0,367722305,0,165986,307163133,ARL
2025-07-17T16:38:28.927371798Z,2025-07-17T16:38:28.927205812Z,160,2,1108,A,A,15.350000000,100,0,370441789,130,165986,307163133,ARL
2025-07-17T16:38:28.936136896Z,2025-07-17T16:38:28.935971160Z,160,2,1108,C,A,14.750000000,100,0,370437189,0,165736,307163278,ARL
2025-07-17T16:38:28.936136896Z,2025-07-17T16:38:28.935971160Z,160,2,1108,A,A,15.030000000,100,0,370442005,130,165736,307163278,ARL
2025-07-17T16:38:28.952681986Z,2025-07-17T16:38:28.952516142Z,160,2,1108,C,A,14.360000000,100,0,367722697,0,165844,307163820,ARL
2025-07-17T16:38:28.952681986Z,2025-07-17T16:38:28.952516142Z,160,2,1108,A,A,14.930000000,100,0,370442725,130,165844,307163820,ARL
2025-07-17T16:38:29.032769021Z,2025-07-17T16:38:29.032603839Z,160,2,1108,A,A,14.650000000,700,0,370445145,130,165182,307165797,ARL
2025-07-17T16:38:29.148813737Z,2025-07-17T16:38:29.148648535Z,160,2,1108,A,A,14.780000000,100,0,370447077,130,165202,307167133,ARL
2025-07-17T16:38:29.148834353Z,2025-07-17T16:38:29.148668992Z,160,2,1108,C,A,14.220000000,100,0,367724041,130,165361,307167134,ARL
2025-07-17T16:38:29.426836238Z,2025-07-17T16:38:29.426670903Z,160,2,1108,C,A,14.300000000,100,0,370437229,130,165335,307173923,ARL
2025-07-17T16:38:29.427188198Z,2025-07-17T16:38:29.427022633Z,160,2,1108,A,A,14.570000000,100,0,370453877,130,165565,307173925,ARL
2025-07-17T16:38:29.676879357Z,2025-07-17T16:38:29.676713920Z,160,2,1108,C,A,13.950000000,100,0,367724713,130,165437,307176261,ARL
2025-07-17T16:38:29.676880707Z,2025-07-17T16:38:29.676715468Z,160,2,1108,A,A,14.500000000,100,0,370456865,130,165239,307176262,ARL
2025-07-17T16:38:29.885303008Z,2025-07-17T16:38:29.885137793Z,160,2,1108,A,A,13.450000000,15,0,370459453,130,165215,307178053,ARL
2025-07-17T16:38:29.888483332Z,2025-07-17T16:38:29.888318043Z,160,2,1108,C,A,14.480000000,100,0,370438201,130,165289,307178079,ARL
2025-07-17T16:38:29.888602233Z,2025-07-17T16:38:29.888436890Z,160,2,1108,A,A,14.750000000,100,0,370459493,130,165343,307178084,ARL
2025-07-17T16:38:29.941014789Z,2025-07-17T16:38:29.940849318Z,160,2,1108,C,A,13.960000000,100,0,370441181,0,165471,307179401,ARL
2025-07-17T16:38:29.941014789Z,2025-07-17T16:38:29.940849318Z,160,2,1108,A,A,13.460000000,100,0,370461533,130,165471,307179401,ARL
2025-07-17T16:38:29.941750054Z,2025-07-17T16:38:29.941583872Z,160,2,1108,C,A,15.030000000,100,0,370442005,0,166182,307179436,ARL
2025-07-17T16:38:29.941750054Z,2025-07-17T16:38:29.941583872Z,160,2,1108,A,A,14.500000000,100,0,370461549,0,166182,307179436,ARL
2025-07-17T16:38:29.941750054Z,2025-07-17T16:38:29.941584913Z,160,2,1108,C,A,14.570000000,100,0,370453877,130,165141,307179437,ARL
2025-07-17T16:38:29.942103994Z,2025-07-17T16:38:29.941938640Z,160,2,1108,A,A,14.060000000,100,0,370461553,130,165354,307179451,ARL
2025-07-17T16:38:29.942232058Z,2025-07-17T16:38:29.942066601Z,160,2,1108,C,A,16.050000000,100,0,370439621,0,165457,307179452,ARL
2025-07-17T16:38:29.942232058Z,2025-07-17T16:38:29.942066601Z,160,2,1108,A,A,15.480000000,100,0,370461557,130,165457,307179452,ARL
2025-07-17T16:38:29.942499783Z,2025-07-17T16:38:29.942334155Z,160,2,1108,C,A,14.930000000,100,0,370439269,0,165628,307179459,ARL
2025-07-17T16:38:29.942499783Z,2025-07-17T16:38:29.942334155Z,160,2,1108,A,A,14.410000000,100,0,370461565,130,165628,307179459,ARL
2025-07-17T16:38:29.943290365Z,2025-07-17T16:38:29.943124936Z,160,2,1108,C,A,15.350000000,100,0,370438965,0,165429,307179471,ARL
2025-07-17T16:38:29.943290365Z,2025-07-17T16:38:29.943124936Z,160,2,1108,A,A,14.810000000,100,0,370461577,130,165429,307179471,ARL
2025-07-17T16:38:29.943302802Z,2025-07-17T16:38:29.943137534Z,160,2,1108,C,A,17.720000000,100,0,370441693,0,165268,307179472,ARL
2025-07-17T16:38:29.943302802Z,2025-07-17T16:38:29.943137534Z,160,2,1108,A,A,17.100000000,100,0,370461581,130,165268,307179472,ARL
2025-07-17T16:38:29.947455917Z,2025-07-17T16:38:29.947290480Z,160,2,1108,C,A,13.950000000,2,0,370439617,0,165437,307179507,ARL
2025-07-17T16:38:29.947455917Z,2025-07-17T16:38:29.947290480Z,160,2,1108,A,A,13.670000000,2,0,370461621,130,165437,307179507,ARL
2025-07-17T16:38:29.948127549Z,2025-07-17T16:38:29.947962321Z,160,2,1108,C,A,14.190000000,100,0,370439549,130,165228,307179509,ARL
2025-07-17T16:38:29.948180463Z,2025-07-17T16:38:29.948015176Z,160,2,1108,A,A,13.730000000,100,0,370461625,130,165287,307179510,ARL
2025-07-17T16:38:29.957942180Z,2025-07-17T16:38:29.957776761Z,160,2,1108,C,A,15.350000000,100,0,370441789,0,165419,307179609,ARL
2025-07-17T16:38:29.957942180Z,2025-07-17T16:38:29.957776761Z,160,2,1108,A,A,14.810000000,100,0,370461725,130,165419,307179609,ARL
2025-07-17T16:38:29.970845105Z,2025-07-17T16:38:29.970679785Z,160,2,1108,A,A,15.350000000,100,0,370461881,130,165320,307179785,ARL
2025-07-17T16:38:29.970846281Z,2025-07-17T16:38:29.970680913Z,160,2,1108,C,A,14.930000000,100,0,370442725,0,165368,307179786,ARL
2025-07-17T16:38:29.970846281Z,2025-07-17T16:38:29.970680913Z,160,2,1108,A,A,14.410000000,100,0,370461885,130,165368,307179786,ARL
2025-07-17T16:38:29.970857471Z,2025-07-17T16:38:29.970692164Z,160,2,1108,C,A,15.910000000,100,0,370438453,130,165307,307179787,ARL
2025-07-17T16:38:30.253787558Z,2025-07-17T16:38:30.253622210Z,160,2,1108,A,A,14.260000000,100,0,370467237,130,165348,307185663,ARL
2025-07-17T16:38:30.253800720Z,2025-07-17T16:38:30.253635404Z,160,2,1108,C,A,14.780000000,100,0,370447077,130,165316,307185664,ARL
2025-07-17T16:38:30.904150735Z,2025-07-17T16:38:30.903985079Z,160,2,1108,C,A,14.750000000,100,0,370459493,0,165656,307190980,ARL
2025-07-17T16:38:30.904150735Z,2025-07-17T16:38:30.903985079Z,160,2,1108,A,A,14.250000000,100,0,370476497,130,165656,307190980,ARL
2025-07-17T16:38:31.559864192Z,2025-07-17T16:38:31.559699014Z,160,2,1108,C,A,14.500000000,100,0,370456865,130,165178,307199960,ARL
2025-07-17T16:38:31.559865365Z,2025-07-17T16:38:31.559700071Z,160,2,1108,A,A,13.990000000,100,0,370489233,130,165294,307199961,ARL
2025-07-17T16:38:38.032884239Z,2025-07-17T16:38:38.032718859Z,160,2,1108,A,A,14.180000000,700,0,370582469,130,165380,307265517,ARL
2025-07-17T16:38:38.032938347Z,2025-07-17T16:38:38.032772895Z,160,2,1108,C,A,14.650000000,700,0,370445145,130,165452,307265518,ARL
2025-07-17T16:38:40.071053065Z,2025-07-17T16:38:40.070887680Z,160,2,1108,C,A,13.460000000,100,0,370461533,130,165385,307283804,ARL
2025-07-17T16:38:40.071319071Z,2025-07-17T16:38:40.071154064Z,160,2,1108,C,A,14.180000000,700,0,370582469,130,165007,307283810,ARL
2025-07-17T16:38:40.071364017Z,2025-07-17T16:38:40.071198819Z,160,2,1108,A,A,14.420000000,700,0,370605993,130,165198,307283812,ARL
2025-07-17T16:38:40.071419817Z,2025-07-17T16:38:40.071254343Z,160,2,1108,A,A,13.430000000,15,0,370606001,130,165474,307283813,ARL
2025-07-17T16:38:40.071445928Z,2025-07-17T16:38:40.071280551Z,160,2,1108,A,A,15.660000000,100,0,370606013,130,165377,307283815,ARL
2025-07-17T16:38:40.071459000Z,2025-07-17T16:38:40.071293734Z,160,2,1108,C,A,15.350000000,100,0,370461881,130,165266,307283816,ARL
2025-07-17T16:38:40.071787295Z,2025-07-17T16:38:40.071621746Z,160,2,1108,C,A,14.500000000,100,0,370461549,0,165549,307283821,ARL
2025-07-17T16:38:40.071787295Z,2025-07-17T16:38:40.071621746Z,160,2,1108,A,A,14.790000000,100,0,370606017,130,165549,307283821,ARL
2025-07-17T16:38:40.071794956Z,2025-07-17T16:38:40.071629854Z,160,2,1108,C,A,14.060000000,100,0,370461553,130,165102,307283822,ARL
2025-07-17T16:38:40.072139081Z,2025-07-17T16:38:40.071973553Z,160,2,1108,C,A,14.410000000,100,0,370461565,0,165528,307283824,ARL
2025-07-17T16:38:40.072139081Z,2025-07-17T16:38:40.071973553Z,160,2,1108,A,A,14.700000000,100,0,370606025,130,165528,307283824,ARL
2025-07-17T16:38:40.072156795Z,2025-07-17T16:38:40.071991669Z,160,2,1108,A,A,14.340000000,100,0,370606029,130,165126,307283825,ARL
2025-07-17T16:38:40.072253482Z,2025-07-17T16:38:40.072087702Z,160,2,1108,C,A,14.810000000,100,0,370461577,0,165780,307283830,ARL
2025-07-17T16:38:40.072253482Z,2025-07-17T16:38:40.072087702Z,160,2,1108,A,A,15.110000000,100,0,370606049,130,165780,307283830,ARL
2025-07-17T16:38:40.075044980Z,2025-07-17T16:38:40.074879393Z,160,2,1108,C,A,14.250000000,100,0,370476497,130,165587,307283845,ARL
2025-07-17T16:38:40.075205801Z,2025-07-17T16:38:40.075040299Z,160,2,1108,A,A,14.520000000,100,0,370606097,130,165502,307283846,ARL
2025-07-17T16:38:40.076414935Z,2025-07-17T16:38:40.076249398Z,160,2,1108,C,A,17.100000000,100,0,370461581,0,165537,307283860,ARL
2025-07-17T16:38:40.076414935Z,2025-07-17T16:38:40.076249398Z,160,2,1108,A,A,17.440000000,100,0,370606133,130,165537,307283860,ARL
2025-07-17T16:38:40.077020558Z,2025-07-17T16:38:40.076855256Z,160,2,1108,C,A,15.480000000,100,0,370461557,0,165302,307283865,ARL
2025-07-17T16:38:40.077020558Z,2025-07-17T16:38:40.076855256Z,160,2,1108,A,A,15.790000000,100,0,370606189,130,165302,307283865,ARL
2025-07-17T16:38:40.083988648Z,2025-07-17T16:38:40.083823366Z,160,2,1108,C,A,13.730000000,100,0,370461625,130,165282,307283911,ARL
2025-07-17T16:38:40.084019246Z,2025-07-17T16:38:40.083854409Z,160,2,1108,C,A,14.420000000,700,0,370605993,130,164837,307283912,ARL
2025-07-17T16:38:40.084042962Z,2025-07-17T16:38:40.083877729Z,160,2,1108,A,A,14.000000000,100,0,370606301,130,165233,307283913,ARL
2025-07-17T16:38:40.084983393Z,2025-07-17T16:38:40.084817954Z,160,2,1108,C,A,13.670000000,2,0,370461621,0,165439,307283919,ARL
2025-07-17T16:38:40.084983393Z,2025-07-17T16:38:40.084817954Z,160,2,1108,A,A,13.950000000,2,0,370606329,130,165439,307283919,ARL
2025-07-17T16:38:40.085118655Z,2025-07-17T16:38:40.084953094Z,160,2,1108,C,A,14.810000000,100,0,370461725,0,165561,307283920,ARL
2025-07-17T16:38:40.085118655Z,2025-07-17T16:38:40.084953094Z,160,2,1108,A,A,15.350000000,100,0,370606333,130,165561,307283920,ARL
2025-07-17T16:38:40.085436753Z,2025-07-17T16:38:40.085271657Z,160,2,1108,C,A,15.790000000,100,0,370606189,0,165096,307283922,ARL
2025-07-17T16:38:40.085436753Z,2025-07-17T16:38:40.085271657Z,160,2,1108,A,A,16.080000000,100,0,370606345,130,165096,307283922,ARL
2025-07-17T16:38:40.085865451Z,2025-07-17T16:38:40.085700203Z,160,2,1108,C,A,14.700000000,100,0,370606025,0,165248,307283924,ARL
2025-07-17T16:38:40.085865451Z,2025-07-17T16:38:40.085700203Z,160,2,1108,A,A,14.960000000,100,0,370606349,130,165248,307283924,ARL
2025-07-17T16:38:40.086710037Z,2025-07-17T16:38:40.086544839Z,160,2,1108,C,A,17.440000000,100,0,370606133,0,165198,307283927,ARL
2025-07-17T16:38:40.086710037Z,2025-07-17T16:38:40.086544839Z,160,2,1108,A,A,17.760000000,100,0,370606361,130,165198,307283927,ARL
2025-07-17T16:38:40.091476523Z,2025-07-17T16:38:40.091311137Z,160,2,1108,C,A,14.410000000,100,0,370461885,0,165386,307283939,ARL
2025-07-17T16:38:40.091476523Z,2025-07-17T16:38:40.091311137Z,160,2,1108,A,A,14.960000000,100,0,370606381,130,165386,307283939,ARL
2025-07-17T16:38:40.104056045Z,2025-07-17T16:38:40.103890619Z,160,2,1108,C,A,14.000000000,100,0,370606301,130,165426,307283993,ARL
2025-07-17T16:38:40.104103420Z,2025-07-17T16:38:40.103938254Z,160,2,1108,A,A,14.230000000,100,0,370606485,130,165166,307283994,ARL
2025-07-17T16:38:40.121772801Z,2025-07-17T16:38:40.121607584Z,160,2,1108,C,A,14.790000000,100,0,370606017,0,165217,307284075,ARL
2025-07-17T16:38:40.121772801Z,2025-07-17T16:38:40.121607584Z,160,2,1108,A,A,15.030000000,100,0,370606649,130,165217,307284075,ARL
2025-07-17T16:38:40.232870261Z,2025-07-17T16:38:40.232704698Z,160,2,1108,A,A,14.680000000,700,0,370608105,130,165563,307285501,ARL
2025-07-17T16:38:40.619891381Z,2025-07-17T16:38:40.619725968Z,160,2,1108,A,A,14.810000000,100,0,370616093,130,165413,307292056,ARL
2025-07-17T16:38:40.619905273Z,2025-07-17T16:38:40.619739793Z,160,2,1108,C,A,14.260000000,100,0,370467237,130,165480,307292058,ARL
2025-07-17T16:38:40.679615139Z,2025-07-17T16:38:40.679449976Z,160,2,1108,C,A,14.340000000,100,0,370606029,130,165163,307292662,ARL
2025-07-17T16:38:40.679963059Z,2025-07-17T16:38:40.679797676Z,160,2,1108,A,A,14.600000000,100,0,370617053,130,165383,307292683,ARL
2025-07-17T16:38:40.980886187Z,2025-07-17T16:38:40.980719660Z,160,2,1108,A,A,14.530000000,100,0,370619813,0,166527,307295303,ARL
2025-07-17T16:38:40.980886187Z,2025-07-17T16:38:40.980720043Z,160,2,1108,C,A,13.990000000,100,0,370489233,130,166144,307295304,ARL
2025-07-17T16:38:41.077087344Z,2025-07-17T16:38:41.076921744Z,160,2,1108,C,A,14.520000000,100,0,370606097,0,165600,307296322,ARL
2025-07-17T16:38:41.077087344Z,2025-07-17T16:38:41.076921744Z,160,2,1108,A,A,14.770000000,100,0,370622009,130,165600,307296322,ARL
2025-07-17T16:38:42.071060459Z,2025-07-17T16:38:42.070895211Z,160,2,1108,A,A,13.440000000,100,0,370638733,130,165248,307311258,ARL
2025-07-17T16:38:42.071797100Z,2025-07-17T16:38:42.071631589Z,160,2,1108,C,A,14.600000000,100,0,370617053,130,165511,307311262,ARL
2025-07-17T16:38:42.071798952Z,2025-07-17T16:38:42.071632569Z,160,2,1108,C,A,15.030000000,100,0,370606649,0,166383,307311263,ARL
2025-07-17T16:38:42.071798952Z,2025-07-17T16:38:42.071632569Z,160,2,1108,A,A,14.480000000,100,0,370638757,130,166383,307311263,ARL
2025-07-17T16:38:42.072149798Z,2025-07-17T16:38:42.071984594Z,160,2,1108,A,A,14.040000000,100,0,370638761,130,165204,307311265,ARL
2025-07-17T16:38:42.072229987Z,2025-07-17T16:38:42.072063883Z,160,2,1108,C,A,14.960000000,100,0,370606349,0,166104,307311266,ARL
2025-07-17T16:38:42.072229987Z,2025-07-17T16:38:42.072063883Z,160,2,1108,A,A,14.390000000,100,0,370638765,130,166104,307311266,ARL
2025-07-17T16:38:42.073729609Z,2025-07-17T16:38:42.073564156Z,160,2,1108,C,A,15.110000000,100,0,370606049,0,165453,307311286,ARL
2025-07-17T16:38:42.073729609Z,2025-07-17T16:38:42.073564156Z,160,2,1108,A,A,14.790000000,100,0,370638797,130,165453,307311286,ARL
2025-07-17T16:38:42.074211752Z,2025-07-17T16:38:42.074046298Z,160,2,1108,C,A,13.950000000,2,0,370606329,0,165454,307311292,ARL
2025-07-17T16:38:42.074211752Z,2025-07-17T16:38:42.074046298Z,160,2,1108,A,A,13.710000000,2,0,370638805,130,165454,307311292,ARL
2025-07-17T16:38:42.075830349Z,2025-07-17T16:38:42.075665016Z,160,2,1108,C,A,17.760000000,100,0,370606361,0,165333,307311306,ARL
2025-07-17T16:38:42.075830349Z,2025-07-17T16:38:42.075665016Z,160,2,1108,A,A,17.070000000,100,0,370638817,130,165333,307311306,ARL
2025-07-17T16:38:42.078193720Z,2025-07-17T16:38:42.078028325Z,160,2,1108,C,A,16.080000000,100,0,370606345,0,165395,307311343,ARL
2025-07-17T16:38:42.078193720Z,2025-07-17T16:38:42.078028325Z,160,2,1108,A,A,15.460000000,100,0,370638825,130,165395,307311343,ARL
2025-07-17T16:38:42.078232224Z,2025-07-17T16:38:42.078067093Z,160,2,1108,C,A,14.230000000,100,0,370606485,130,165131,307311344,ARL
2025-07-17T16:38:42.078281818Z,2025-07-17T16:38:42.078116589Z,160,2,1108,A,A,13.710000000,100,0,370638829,130,165229,307311345,ARL
2025-07-17T16:38:42.078454085Z,2025-07-17T16:38:42.078288777Z,160,2,1108,C,A,14.770000000,100,0,370622009,130,165308,307311346,ARL
2025-07-17T16:38:42.078565517Z,2025-07-17T16:38:42.078400348Z,160,2,1108,A,A,14.230000000,100,0,370638833,130,165169,307311347,ARL
2025-07-17T16:38:42.085603593Z,2025-07-17T16:38:42.085438103Z,160,2,1108,C,A,15.350000000,100,0,370606333,0,165490,307311411,ARL
2025-07-17T16:38:42.085603593Z,2025-07-17T16:38:42.085438103Z,160,2,1108,A,A,14.790000000,100,0,370638929,130,165490,307311411,ARL
2025-07-17T16:38:42.088647035Z,2025-07-17T16:38:42.088481675Z,160,2,1108,C,A,14.960000000,100,0,370606381,0,165360,307311591,ARL
2025-07-17T16:38:42.088647035Z,2025-07-17T16:38:42.088481675Z,160,2,1108,A,A,14.390000000,100,0,370638997,130,165360,307311591,ARL
2025-07-17T16:38:42.115050265Z,2025-07-17T16:38:42.114885012Z,160,2,1108,A,A,15.330000000,100,0,370640177,130,165253,307312338,ARL
2025-07-17T16:38:42.115062795Z,2025-07-17T16:38:42.114897649Z,160,2,1108,C,A,15.660000000,100,0,370606013,130,165146,307312339,ARL
2025-07-17T16:38:42.253796551Z,2025-07-17T16:38:42.253631195Z,160,2,1108,A,A,14.240000000,100,0,370641493,130,165356,307313171,ARL
2025-07-17T16:38:42.253820282Z,2025-07-17T16:38:42.253655026Z,160,2,1108,C,A,14.810000000,100,0,370616093,130,165256,307313172,ARL
2025-07-17T16:38:42.858867827Z,2025-07-17T16:38:42.858701545Z,160,2,1108,A,A,13.970000000,100,0,370648729,0,166282,307318631,ARL
2025-07-17T16:38:42.858867827Z,2025-07-17T16:38:42.858701973Z,160,2,1108,C,A,14.530000000,100,0,370619813,130,165854,307318632,ARL
2025-07-17T16:38:47.232918544Z,2025-07-17T16:38:47.232753264Z,160,2,1108,A,A,14.170000000,700,0,370738933,130,165280,307383998,ARL
2025-07-17T16:38:47.232998038Z,2025-07-17T16:38:47.232832790Z,160,2,1108,C,A,14.680000000,700,0,370608105,130,165248,307383999,ARL
2025-07-17T16:39:58.874293523Z,2025-07-17T16:39:58.874128495Z,160,2,1108,C,A,13.430000000,15,0,370606001,130,165028,309108049,ARL
2025-07-17T16:40:01.981585967Z,2025-07-17T16:40:01.981419959Z,160,2,1108,A,A,13.420000000,15,0,372913209,128,166008,309194219,ARL
2025-07-17T16:40:02.086681947Z,2025-07-17T16:40:02.086515046Z,160,2,1108,C,A,13.440000000,100,0,370638733,0,166901,309196660,ARL
2025-07-17T16:40:02.086681947Z,2025-07-17T16:40:02.086515046Z,160,2,1108,A,A,13.430000000,100,0,372916289,130,166901,309196660,ARL
2025-07-17T16:40:24.333916297Z,2025-07-17T16:40:24.333742996Z,160,2,1108,C,A,13.420000000,15,0,372913209,128,173301,309657551,ARL
2025-07-17T16:40:24.333925326Z,2025-07-17T16:40:24.333748583Z,160,2,1108,C,A,13.450000000,15,0,370459453,128,176743,309657561,ARL
2025-07-17T16:40:27.510997872Z,2025-07-17T16:40:27.510832450Z,160,2,1108,A,A,13.430000000,15,0,373568805,130,165422,309727211,ARL
2025-07-17T16:40:30.874687699Z,2025-07-17T16:40:30.874522389Z,160,2,1108,C,A,13.430000000,15,0,373568805,130,165310,309772472,ARL
2025-07-17T16:41:16.989343671Z,2025-07-17T16:41:16.989178019Z,160,2,1108,C,A,13.710000000,2,0,370638805,0,165652,310649827,ARL
2025-07-17T16:41:16.989343671Z,2025-07-17T16:41:16.989178019Z,160,2,1108,A,A,13.640000000,2,0,374709161,130,165652,310649827,ARL
2025-07-17T16:41:43.139096645Z,2025-07-17T16:41:43.138931223Z,160,2,1108,C,A,13.430000000,100,0,372916289,130,165422,311182878,ARL
2025-07-17T16:41:43.139367855Z,2025-07-17T16:41:43.139202376Z,160,2,1108,C,A,14.170000000,700,0,370738933,130,165479,311182881,ARL
2025-07-17T16:41:43.139410669Z,2025-07-17T16:41:43.139245098Z,160,2,1108,A,A,14.400000000,700,0,375327817,130,165571,311182882,ARL
2025-07-17T16:41:43.139437683Z,2025-07-17T16:41:43.139272073Z,160,2,1108,A,A,15.630000000,100,0,375327821,130,165610,311182884,ARL
2025-07-17T16:41:43.139452068Z,2025-07-17T16:41:43.139285892Z,160,2,1108,C,A,15.330000000,100,0,370640177,130,166176,311182887,ARL
2025-07-17T16:41:43.139834195Z,2025-07-17T16:41:43.139668821Z,160,2,1108,C,A,14.040000000,100,0,370638761,130,165374,311182892,ARL
2025-07-17T16:41:43.139848710Z,2025-07-17T16:41:43.139683114Z,160,2,1108,C,A,14.480000000,100,0,370638757,0,165596,311182893,ARL
2025-07-17T16:41:43.139848710Z,2025-07-17T16:41:43.139683114Z,160,2,1108,A,A,14.540000000,100,0,375327841,130,165596,311182893,ARL
2025-07-17T16:41:43.140140620Z,2025-07-17T16:41:43.139975016Z,160,2,1108,C,A,14.390000000,100,0,370638765,0,165604,311182897,ARL
2025-07-17T16:41:43.140140620Z,2025-07-17T16:41:43.139975016Z,160,2,1108,A,A,14.670000000,100,0,375327849,130,165604,311182897,ARL
2025-07-17T16:41:43.140190853Z,2025-07-17T16:41:43.140025431Z,160,2,1108,A,A,14.320000000,100,0,375327857,130,165422,311182898,ARL
2025-07-17T16:41:43.141093375Z,2025-07-17T16:41:43.140927693Z,160,2,1108,C,A,14.790000000,100,0,370638929,0,165682,311182903,ARL
2025-07-17T16:41:43.141093375Z,2025-07-17T16:41:43.140927693Z,160,2,1108,A,A,15.090000000,100,0,375327873,130,165682,311182903,ARL
2025-07-17T16:41:43.141460822Z,2025-07-17T16:41:43.141295003Z,160,2,1108,C,A,15.460000000,100,0,370638825,0,165819,311182910,ARL
2025-07-17T16:41:43.141460822Z,2025-07-17T16:41:43.141295003Z,160,2,1108,A,A,15.770000000,100,0,375327877,130,165819,311182910,ARL
2025-07-17T16:41:43.142071494Z,2025-07-17T16:41:43.141905651Z,160,2,1108,C,A,14.790000000,100,0,370638797,0,165843,311182922,ARL
2025-07-17T16:41:43.142071494Z,2025-07-17T16:41:43.141905651Z,160,2,1108,A,A,15.090000000,100,0,375327909,130,165843,311182922,ARL
2025-07-17T16:41:43.142074383Z,2025-07-17T16:41:43.141908944Z,160,2,1108,C,A,17.070000000,100,0,370638817,0,165439,311182923,ARL
2025-07-17T16:41:43.142074383Z,2025-07-17T16:41:43.141908944Z,160,2,1108,A,A,17.420000000,100,0,375327913,130,165439,311182923,ARL
2025-07-17T16:41:43.143404021Z,2025-07-17T16:41:43.143238309Z,160,2,1108,C,A,14.390000000,100,0,370638997,0,165712,311182938,ARL
2025-07-17T16:41:43.143404021Z,2025-07-17T16:41:43.143238309Z,160,2,1108,A,A,14.670000000,100,0,375327925,130,165712,311182938,ARL
2025-07-17T16:41:43.144643219Z,2025-07-17T16:41:43.144477498Z,160,2,1108,C,A,14.230000000,100,0,370638833,0,165721,311182962,ARL
2025-07-17T16:41:43.144643219Z,2025-07-17T16:41:43.144477498Z,160,2,1108,A,A,14.500000000,100,0,375327933,130,165721,311182962,ARL
2025-07-17T16:41:43.156276827Z,2025-07-17T16:41:43.156111360Z,160,2,1108,C,A,13.710000000,100,0,370638829,130,165467,311183103,ARL
2025-07-17T16:41:43.156309203Z,2025-07-17T16:41:43.156143472Z,160,2,1108,C,A,14.400000000,700,0,375327817,130,165731,311183104,ARL
2025-07-17T16:41:43.156325543Z,2025-07-17T16:41:43.156160068Z,160,2,1108,A,A,13.980000000,100,0,375328129,130,165475,311183105,ARL
2025-07-17T16:41:43.156355688Z,2025-07-17T16:41:43.156190292Z,160,2,1108,A,A,15.930000000,100,0,375328137,130,165396,311183106,ARL
2025-07-17T16:41:43.156367888Z,2025-07-17T16:41:43.156202715Z,160,2,1108,C,A,15.630000000,100,0,375327821,130,165173,311183107,ARL
2025-07-17T16:41:43.157597824Z,2025-07-17T16:41:43.157432141Z,160,2,1108,C,A,15.770000000,100,0,375327877,0,165683,311183119,ARL
2025-07-17T16:41:43.157597824Z,2025-07-17T16:41:43.157432141Z,160,2,1108,A,A,16.020000000,100,0,375328149,130,165683,311183119,ARL
2025-07-17T16:41:43.157996803Z,2025-07-17T16:41:43.157830765Z,160,2,1108,C,A,17.420000000,100,0,375327913,0,166038,311183122,ARL
2025-07-17T16:41:43.157996803Z,2025-07-17T16:41:43.157830765Z,160,2,1108,A,A,17.750000000,100,0,375328161,130,166038,311183122,ARL
2025-07-17T16:41:43.158680871Z,2025-07-17T16:41:43.158515465Z,160,2,1108,C,A,14.670000000,100,0,375327849,0,165406,311183123,ARL
2025-07-17T16:41:43.158680871Z,2025-07-17T16:41:43.158515465Z,160,2,1108,A,A,14.950000000,100,0,375328181,130,165406,311183123,ARL
2025-07-17T16:41:43.162411987Z,2025-07-17T16:41:43.162246276Z,160,2,1108,C,A,13.640000000,2,0,374709161,0,165711,311183140,ARL
2025-07-17T16:41:43.162411987Z,2025-07-17T16:41:43.162246276Z,160,2,1108,A,A,13.970000000,2,0,375328205,130,165711,311183140,ARL
2025-07-17T16:41:43.170557359Z,2025-07-17T16:41:43.170391935Z,160,2,1108,C,A,14.670000000,100,0,375327925,0,165424,311183283,ARL
2025-07-17T16:41:43.170557359Z,2025-07-17T16:41:43.170391935Z,160,2,1108,A,A,14.950000000,100,0,375328333,130,165424,311183283,ARL
2025-07-17T16:41:43.171647677Z,2025-07-17T16:41:43.171482095Z,160,2,1108,C,A,13.980000000,100,0,375328129,130,165582,311183345,ARL
2025-07-17T16:41:43.171697072Z,2025-07-17T16:41:43.171531790Z,160,2,1108,A,A,14.210000000,100,0,375328497,130,165282,311183361,ARL
2025-07-17T16:41:43.189985367Z,2025-07-17T16:41:43.189819838Z,160,2,1108,C,A,14.540000000,100,0,375327841,0,165529,311183848,ARL
2025-07-17T16:41:43.189985367Z,2025-07-17T16:41:43.189819838Z,160,2,1108,A,A,15.050000000,100,0,375329021,130,165529,311183848,ARL
2025-07-17T16:41:43.209244405Z,2025-07-17T16:41:43.209078680Z,160,2,1108,C,A,13.970000000,100,0,370648729,130,165725,311184224,ARL
2025-07-17T16:41:43.209245171Z,2025-07-17T16:41:43.209079728Z,160,2,1108,A,A,14.260000000,100,0,375329381,130,165443,311184225,ARL
2025-07-17T16:41:43.209283014Z,2025-07-17T16:41:43.209117671Z,160,2,1108,A,A,14.670000000,700,0,375329385,130,165343,311184226,ARL
2025-07-17T16:41:43.210615597Z,2025-07-17T16:41:43.210450264Z,160,2,1108,C,A,15.090000000,100,0,375327909,0,165333,311184266,ARL
2025-07-17T16:41:43.210615597Z,2025-07-17T16:41:43.210450264Z,160,2,1108,A,A,15.380000000,100,0,375329405,130,165333,311184266,ARL
2025-07-17T16:41:43.224139305Z,2025-07-17T16:41:43.223973814Z,160,2,1108,C,A,15.090000000,100,0,375327873,0,165491,311184403,ARL
2025-07-17T16:41:43.224139305Z,2025-07-17T16:41:43.223973814Z,160,2,1108,A,A,15.380000000,100,0,375329581,130,165491,311184403,ARL
2025-07-17T16:41:43.490870911Z,2025-07-17T16:41:43.490705448Z,160,2,1108,A,A,14.810000000,100,0,375334157,130,165463,311188689,ARL
2025-07-17T16:41:43.490884111Z,2025-07-17T16:41:43.490718665Z,160,2,1108,C,A,14.240000000,100,0,370641493,130,165446,311188690,ARL
2025-07-17T16:41:43.752618225Z,2025-07-17T16:41:43.752453166Z,160,2,1108,C,A,14.320000000,100,0,375327857,130,165059,311195553,ARL
2025-07-17T16:41:43.752966124Z,2025-07-17T16:41:43.752800607Z,160,2,1108,A,A,14.600000000,100,0,375342121,130,165517,311195557,ARL
2025-07-17T16:41:43.860684286Z,2025-07-17T16:41:43.860518846Z,160,2,1108,A,A,13.980000000,100,0,375348505,130,165440,311202685,ARL
2025-07-17T16:41:44.146151701Z,2025-07-17T16:41:44.145986128Z,160,2,1108,C,A,14.500000000,100,0,375327933,130,165573,311210358,ARL
2025-07-17T16:41:44.146281685Z,2025-07-17T16:41:44.146116212Z,160,2,1108,A,A,14.770000000,100,0,375358061,130,165473,311210359,ARL
2025-07-17T16:41:53.592641426Z,2025-07-17T16:41:53.592475714Z,160,2,1108,C,B,12.910000000,2,0,369392197,0,165712,311376251,ARL
2025-07-17T16:41:53.592641426Z,2025-07-17T16:41:53.592475714Z,160,2,1108,A,B,12.990000000,2,0,375577225,130,165712,311376251,ARL
2025-07-17T16:42:04.386551221Z,2025-07-17T16:42:04.386385514Z,160,2,1108,C,B,12.990000000,2,0,375577225,0,165707,311568668,ARL
2025-07-17T16:42:04.386551221Z,2025-07-17T16:42:04.386385514Z,160,2,1108,A,B,13.060000000,2,0,375823217,130,165707,311568668,ARL
2025-07-17T16:42:36.878828609Z,2025-07-17T16:42:36.878663385Z,160,2,1108,A,A,13.450000000,15,0,376539701,130,165224,312149208,ARL
2025-07-17T16:42:37.986013005Z,2025-07-17T16:42:37.985847507Z,160,2,1108,C,B,13.060000000,2,0,375823217,0,165498,312159909,ARL
2025-07-17T16:42:37.986013005Z,2025-07-17T16:42:37.985847507Z,160,2,1108,A,B,13.110000000,2,0,376553221,130,165498,312159909,ARL
2025-07-17T16:42:38.270882414Z,2025-07-17T16:42:38.270716854Z,160,2,1108,C,A,13.980000000,100,0,375348505,0,165560,312165198,ARL
2025-07-17T16:42:38.270882414Z,2025-07-17T16:42:38.270716854Z,160,2,1108,A,A,13.460000000,100,0,376560477,130,165560,312165198,ARL
2025-07-17T16:42:38.271203497Z,2025-07-17T16:42:38.271038120Z,160,2,1108,C,B,13.110000000,2,0,376553221,0,165377,312165204,ARL
2025-07-17T16:42:38.271203497Z,2025-07-17T16:42:38.271038120Z,160,2,1108,A,B,13.000000000,2,0,376560493,130,165377,312165204,ARL
2025-07-17T16:42:38.271623092Z,2025-07-17T16:42:38.271457684Z,160,2,1108,C,A,15.050000000,100,0,375329021,0,165408,312165206,ARL
2025-07-17T16:42:38.271623092Z,2025-07-17T16:42:38.271457684Z,160,2,1108,A,A,14.500000000,100,0,376560501,130,165408,312165206,ARL
2025-07-17T16:42:38.271627330Z,2025-07-17T16:42:38.271462148Z,160,2,1108,C,A,14.600000000,100,0,375342121,130,165182,312165207,ARL
2025-07-17T16:42:38.271700751Z,2025-07-17T16:42:38.271535232Z,160,2,1108,C,A,16.020000000,100,0,375328149,0,165519,312165208,ARL
2025-07-17T16:42:38.271700751Z,2025-07-17T16:42:38.271535232Z,160,2,1108,A,A,15.480000000,100,0,376560505,130,165519,312165208,ARL
2025-07-17T16:42:38.271995019Z,2025-07-17T16:42:38.271829580Z,160,2,1108,A,A,14.060000000,100,0,376560525,130,165439,312165213,ARL
2025-07-17T16:42:38.273127483Z,2025-07-17T16:42:38.272961582Z,160,2,1108,C,A,17.750000000,100,0,375328161,0,165901,312165223,ARL
2025-07-17T16:42:38.273127483Z,2025-07-17T16:42:38.272961582Z,160,2,1108,A,A,17.100000000,100,0,376560545,130,165901,312165223,ARL
2025-07-17T16:42:38.273257076Z,2025-07-17T16:42:38.273091716Z,160,2,1108,C,A,14.950000000,100,0,375328181,0,165360,312165226,ARL
2025-07-17T16:42:38.273257076Z,2025-07-17T16:42:38.273091716Z,160,2,1108,A,A,14.410000000,100,0,376560553,130,165360,312165226,ARL
2025-07-17T16:42:38.274031520Z,2025-07-17T16:42:38.273865794Z,160,2,1108,C,A,15.380000000,100,0,375329405,0,165726,312165238,ARL
2025-07-17T16:42:38.274031520Z,2025-07-17T16:42:38.273865794Z,160,2,1108,A,A,14.810000000,100,0,376560573,130,165726,312165238,ARL
2025-07-17T16:42:38.274691227Z,2025-07-17T16:42:38.274525240Z,160,2,1108,C,A,14.770000000,100,0,375358061,0,165987,312165251,ARL
2025-07-17T16:42:38.274691227Z,2025-07-17T16:42:38.274525240Z,160,2,1108,A,A,14.250000000,100,0,376560581,130,165987,312165251,ARL
2025-07-17T16:42:38.278955044Z,2025-07-17T16:42:38.278789456Z,160,2,1108,C,A,14.950000000,100,0,375328333,0,165588,312165295,ARL
2025-07-17T16:42:38.278955044Z,2025-07-17T16:42:38.278789456Z,160,2,1108,A,A,14.410000000,100,0,376560685,130,165588,312165295,ARL
2025-07-17T16:42:38.283335826Z,2025-07-17T16:42:38.283170473Z,160,2,1108,C,A,14.210000000,100,0,375328497,130,165353,312165435,ARL
2025-07-17T16:42:38.283385507Z,2025-07-17T16:42:38.283220234Z,160,2,1108,A,A,13.730000000,100,0,376560813,130,165273,312165438,ARL
2025-07-17T16:42:38.286360751Z,2025-07-17T16:42:38.286195097Z,160,2,1108,C,A,15.380000000,100,0,375329581,0,165654,312165471,ARL
2025-07-17T16:42:38.286360751Z,2025-07-17T16:42:38.286195097Z,160,2,1108,A,A,14.810000000,100,0,376560829,130,165654,312165471,ARL
2025-07-17T16:42:38.312585522Z,2025-07-17T16:42:38.312420377Z,160,2,1108,A,A,15.350000000,100,0,376562017,130,165145,312166318,ARL
2025-07-17T16:42:38.312598967Z,2025-07-17T16:42:38.312433797Z,160,2,1108,C,A,15.930000000,100,0,375328137,130,165170,312166320,ARL
2025-07-17T16:42:38.873834209Z,2025-07-17T16:42:38.873668683Z,160,2,1108,A,A,14.260000000,100,0,376569293,130,165526,312171488,ARL
2025-07-17T16:42:38.873846810Z,2025-07-17T16:42:38.873681390Z,160,2,1108,C,A,14.810000000,100,0,375334157,130,165420,312171489,ARL
2025-07-17T16:42:40.989856036Z,2025-07-17T16:42:40.989690505Z,160,2,1108,C,A,13.970000000,2,0,375328205,0,165531,312198414,ARL
2025-07-17T16:42:40.989856036Z,2025-07-17T16:42:40.989690505Z,160,2,1108,A,A,13.870000000,2,0,376604133,130,165531,312198414,ARL
2025-07-17T16:42:46.433875144Z,2025-07-17T16:42:46.433709548Z,160,2,1108,A,A,14.180000000,700,0,376682393,130,165596,312255078,ARL
2025-07-17T16:42:46.433934580Z,2025-07-17T16:42:46.433769250Z,160,2,1108,C,A,14.670000000,700,0,375329385,130,165330,312255079,ARL
2025-07-17T16:42:48.190881685Z,2025-07-17T16:42:48.190716226Z,160,2,1108,C,A,13.870000000,2,0,376604133,0,165459,312275865,ARL
2025-07-17T16:42:48.190881685Z,2025-07-17T16:42:48.190716226Z,160,2,1108,A,A,13.790000000,2,0,376710049,130,165459,312275865,ARL
2025-07-17T16:42:53.414005762Z,2025-07-17T16:42:53.413840345Z,160,2,1108,C,A,13.450000000,15,0,376539701,130,165417,312346120,ARL
2025-07-17T16:42:53.419557632Z,2025-07-17T16:42:53.419392154Z,160,2,1108,A,A,13.450000000,15,0,376801517,130,165478,312346353,ARL
2025-07-17T16:43:01.389812641Z,2025-07-17T16:43:01.389646878Z,160,2,1108,C,A,13.790000000,2,0,376710049,0,165763,312450189,ARL
2025-07-17T16:43:01.389812641Z,2025-07-17T16:43:01.389646878Z,160,2,1108,A,A,13.720000000,2,0,376932045,130,165763,312450189,ARL
2025-07-17T16:44:05.066153300Z,2025-07-17T16:44:05.065987790Z,160,2,1108,C,A,13.450000000,15,0,376801517,130,165510,313334368,ARL
2025-07-17T16:44:10.386298578Z,2025-07-17T16:44:10.386132925Z,160,2,1108,C,A,13.720000000,2,0,376932045,0,165653,313428705,ARL
2025-07-17T16:44:10.386298578Z,2025-07-17T16:44:10.386132925Z,160,2,1108,A,A,13.660000000,2,0,378209833,130,165653,313428705,ARL
2025-07-17T16:44:28.874722110Z,2025-07-17T16:44:28.874556092Z,160,2,1108,A,A,13.450000000,15,0,378572841,130,166018,313679060,ARL
2025-07-17T16:44:33.445583879Z,2025-07-17T16:44:33.445416279Z,160,2,1108,C,A,13.450000000,15,0,378572841,128,167600,313731687,ARL
2025-07-17T16:44:43.947669248Z,2025-07-17T16:44:43.947504113Z,160,2,1108,C,A,13.460000000,100,0,376560477,130,165135,313928874,ARL
2025-07-17T16:44:43.947942946Z,2025-07-17T16:44:43.947777103Z,160,2,1108,C,A,14.180000000,700,0,376682393,130,165843,313928881,ARL
2025-07-17T16:44:43.947993530Z,2025-07-17T16:44:43.947828206Z,160,2,1108,A,A,14.420000000,700,0,378884161,130,165324,313928882,ARL
2025-07-17T16:44:43.948056072Z,2025-07-17T16:44:43.947890722Z,160,2,1108,A,A,15.660000000,100,0,378884173,130,165350,313928883,ARL
2025-07-17T16:44:43.948068794Z,2025-07-17T16:44:43.947903610Z,160,2,1108,C,A,15.350000000,100,0,376562017,130,165184,313928885,ARL
2025-07-17T16:44:43.948414576Z,2025-07-17T16:44:43.948249121Z,160,2,1108,C,A,14.060000000,100,0,376560525,130,165455,313928891,ARL
2025-07-17T16:44:43.948422718Z,2025-07-17T16:44:43.948256940Z,160,2,1108,C,A,14.500000000,100,0,376560501,0,165778,313928892,ARL
2025-07-17T16:44:43.948422718Z,2025-07-17T16:44:43.948256940Z,160,2,1108,A,A,14.560000000,100,0,378884201,130,165778,313928892,ARL
2025-07-17T16:44:43.948767247Z,2025-07-17T16:44:43.948601956Z,160,2,1108,A,A,14.340000000,100,0,378884205,130,165291,313928894,ARL
2025-07-17T16:44:43.949299210Z,2025-07-17T16:44:43.949133566Z,160,2,1108,C,A,14.410000000,100,0,376560553,0,165644,313928896,ARL
2025-07-17T16:44:43.949299210Z,2025-07-17T16:44:43.949133566Z,160,2,1108,A,A,14.700000000,100,0,378884209,130,165644,313928896,ARL
2025-07-17T16:44:43.949453661Z,2025-07-17T16:44:43.949288475Z,160,2,1108,C,A,17.100000000,100,0,376560545,0,165186,313928900,ARL
2025-07-17T16:44:43.949453661Z,2025-07-17T16:44:43.949288475Z,160,2,1108,A,A,17.440000000,100,0,378884213,130,165186,313928900,ARL
2025-07-17T16:44:43.949503974Z,2025-07-17T16:44:43.949338539Z,160,2,1108,C,A,14.810000000,100,0,376560829,0,165435,313928902,ARL
2025-07-17T16:44:43.949503974Z,2025-07-17T16:44:43.949338539Z,160,2,1108,A,A,15.110000000,100,0,378884221,130,165435,313928902,ARL
2025-07-17T16:44:43.949942472Z,2025-07-17T16:44:43.949777115Z,160,2,1108,C,A,14.810000000,100,0,376560573,0,165357,313928906,ARL
2025-07-17T16:44:43.949942472Z,2025-07-17T16:44:43.949777115Z,160,2,1108,A,A,15.110000000,100,0,378884229,130,165357,313928906,ARL
2025-07-17T16:44:43.950306016Z,2025-07-17T16:44:43.950140413Z,160,2,1108,C,A,15.480000000,100,0,376560505,0,165603,313928908,ARL
2025-07-17T16:44:43.950306016Z,2025-07-17T16:44:43.950140413Z,160,2,1108,A,A,15.790000000,100,0,378884237,130,165603,313928908,ARL
2025-07-17T16:44:43.950344278Z,2025-07-17T16:44:43.950178776Z,160,2,1108,C,A,14.410000000,100,0,376560685,0,165502,313928909,ARL
2025-07-17T16:44:43.950344278Z,2025-07-17T16:44:43.950178776Z,160,2,1108,A,A,14.700000000,100,0,378884245,130,165502,313928909,ARL
2025-07-17T16:44:43.960337599Z,2025-07-17T16:44:43.960172259Z,160,2,1108,C,A,14.250000000,100,0,376560581,130,165340,313928963,ARL
2025-07-17T16:44:43.960460247Z,2025-07-17T16:44:43.960295032Z,160,2,1108,A,A,14.520000000,100,0,378884345,130,165215,313928965,ARL
2025-07-17T16:44:43.965601475Z,2025-07-17T16:44:43.965436032Z,160,2,1108,C,A,13.730000000,100,0,376560813,130,165443,313928980,ARL
2025-07-17T16:44:43.965632719Z,2025-07-17T16:44:43.965467685Z,160,2,1108,C,A,14.420000000,700,0,378884161,130,165034,313928981,ARL
2025-07-17T16:44:43.965652705Z,2025-07-17T16:44:43.965487362Z,160,2,1108,A,A,14.000000000,100,0,378884369,130,165343,313928982,ARL
2025-07-17T16:44:43.966776104Z,2025-07-17T16:44:43.966610475Z,160,2,1108,C,A,14.700000000,100,0,378884209,0,165629,313928996,ARL
2025-07-17T16:44:43.966776104Z,2025-07-17T16:44:43.966610475Z,160,2,1108,A,A,14.930000000,100,0,378884389,130,165629,313928996,ARL
2025-07-17T16:44:43.966782543Z,2025-07-17T16:44:43.966617226Z,160,2,1108,C,A,15.790000000,100,0,378884237,0,165317,313928997,ARL
2025-07-17T16:44:43.966782543Z,2025-07-17T16:44:43.966617226Z,160,2,1108,A,A,16.050000000,100,0,378884393,130,165317,313928997,ARL
2025-07-17T16:44:43.966849035Z,2025-07-17T16:44:43.966683546Z,160,2,1108,C,A,17.440000000,100,0,378884213,0,165489,313928999,ARL
2025-07-17T16:44:43.966849035Z,2025-07-17T16:44:43.966683546Z,160,2,1108,A,A,17.720000000,100,0,378884397,130,165489,313928999,ARL
2025-07-17T16:44:43.967499949Z,2025-07-17T16:44:43.967334622Z,160,2,1108,C,B,13.000000000,2,0,376560493,0,165327,313929001,ARL
2025-07-17T16:44:43.967499949Z,2025-07-17T16:44:43.967334622Z,160,2,1108,A,B,12.880000000,2,0,378884417,130,165327,313929001,ARL
2025-07-17T16:44:43.967501575Z,2025-07-17T16:44:43.967336268Z,160,2,1108,C,A,13.660000000,2,0,378209833,0,165307,313929002,ARL
2025-07-17T16:44:43.967501575Z,2025-07-17T16:44:43.967336268Z,160,2,1108,A,A,13.980000000,2,0,378884421,130,165307,313929002,ARL
2025-07-17T16:44:43.968403415Z,2025-07-17T16:44:43.968238011Z,160,2,1108,C,A,14.700000000,100,0,378884245,0,165404,313929006,ARL
2025-07-17T16:44:43.968403415Z,2025-07-17T16:44:43.968238011Z,160,2,1108,A,A,14.960000000,100,0,378884425,130,165404,313929006,ARL
2025-07-17T16:44:43.998564091Z,2025-07-17T16:44:43.998398734Z,160,2,1108,C,A,14.560000000,100,0,378884201,0,165357,313929166,ARL
2025-07-17T16:44:43.998564091Z,2025-07-17T16:44:43.998398734Z,160,2,1108,A,A,15.030000000,100,0,378884749,130,165357,313929166,ARL
2025-07-17T16:44:43.998716453Z,2025-07-17T16:44:43.998551330Z,160,2,1108,C,A,14.000000000,100,0,378884369,130,165123,313929167,ARL
2025-07-17T16:44:43.998767406Z,2025-07-17T16:44:43.998602131Z,160,2,1108,A,A,14.230000000,100,0,378884757,130,165275,313929168,ARL
2025-07-17T16:44:44.034190479Z,2025-07-17T16:44:44.034024501Z,160,2,1108,A,A,14.680000000,700,0,378885133,130,165978,313929291,ARL
2025-07-17T16:44:44.140894361Z,2025-07-17T16:44:44.140729032Z,160,2,1108,A,A,14.810000000,100,0,378887673,130,165329,313931073,ARL
2025-07-17T16:44:44.140907933Z,2025-07-17T16:44:44.140742632Z,160,2,1108,C,A,14.260000000,100,0,376569293,130,165301,313931074,ARL
2025-07-17T16:44:44.228219658Z,2025-07-17T16:44:44.228054315Z,160,2,1108,A,A,13.990000000,100,0,378888877,130,165343,313931853,ARL
2025-07-17T16:44:44.523062538Z,2025-07-17T16:44:44.522897140Z,160,2,1108,A,A,13.450000000,15,0,378899025,130,165398,313938755,ARL
2025-07-17T16:44:44.570856266Z,2025-07-17T16:44:44.570690672Z,160,2,1108,C,A,14.340000000,100,0,378884205,130,165594,313939672,ARL
2025-07-17T16:44:44.571206054Z,2025-07-17T16:44:44.571040568Z,160,2,1108,A,A,14.600000000,100,0,378900061,130,165486,313939677,ARL
2025-07-17T16:44:44.961509837Z,2025-07-17T16:44:44.961344305Z,160,2,1108,C,A,14.520000000,100,0,378884345,0,165532,313943280,ARL
2025-07-17T16:44:44.961509837Z,2025-07-17T16:44:44.961344305Z,160,2,1108,A,A,14.770000000,100,0,378905145,130,165532,313943280,ARL
2025-07-17T16:44:46.881887593Z,2025-07-17T16:44:46.881722229Z,160,2,1108,C,A,13.450000000,15,0,378899025,130,165364,313964658,ARL
2025-07-17T16:44:49.387642544Z,2025-07-17T16:44:49.387476653Z,160,2,1108,C,B,12.880000000,2,0,378884417,0,165891,313994239,ARL
2025-07-17T16:44:49.387642544Z,2025-07-17T16:44:49.387476653Z,160,2,1108,A,B,12.970000000,2,0,378976465,130,165891,313994239,ARL
2025-07-17T16:44:54.883039800Z,2025-07-17T16:44:54.882874395Z,160,2,1108,A,A,13.450000000,15,0,379094717,130,165405,314081248,ARL
2025-07-17T16:44:54.909276584Z,2025-07-17T16:44:54.909111232Z,160,2,1108,C,A,13.990000000,100,0,378888877,0,165352,314082223,ARL
2025-07-17T16:44:54.909276584Z,2025-07-17T16:44:54.909111232Z,160,2,1108,A,A,13.460000000,100,0,379095909,130,165352,314082223,ARL
2025-07-17T16:44:54.909577600Z,2025-07-17T16:44:54.909412092Z,160,2,1108,C,A,13.980000000,2,0,378884421,0,165508,314082230,ARL
2025-07-17T16:44:54.909577600Z,2025-07-17T16:44:54.909412092Z,160,2,1108,A,A,13.790000000,2,0,379095929,130,165508,314082230,ARL
2025-07-17T16:44:54.910011788Z,2025-07-17T16:44:54.909846352Z,160,2,1108,C,A,15.030000000,100,0,378884749,0,165436,314082244,ARL
2025-07-17T16:44:54.910011788Z,2025-07-17T16:44:54.909846352Z,160,2,1108,A,A,14.500000000,100,0,379095949,130,165436,314082244,ARL
2025-07-17T16:44:54.910014084Z,2025-07-17T16:44:54.909848730Z,160,2,1108,C,A,14.600000000,100,0,378900061,130,165354,314082245,ARL
2025-07-17T16:44:54.910313561Z,2025-07-17T16:44:54.910148272Z,160,2,1108,C,A,14.930000000,100,0,378884389,0,165289,314082257,ARL
2025-07-17T16:44:54.910313561Z,2025-07-17T16:44:54.910148272Z,160,2,1108,A,A,14.410000000,100,0,379095977,130,165289,314082257,ARL
2025-07-17T16:44:54.910375306Z,2025-07-17T16:44:54.910209882Z,160,2,1108,A,A,14.060000000,100,0,379095981,130,165424,314082259,ARL
2025-07-17T16:44:54.910655006Z,2025-07-17T16:44:54.910489507Z,160,2,1108,C,A,15.110000000,100,0,378884229,0,165499,314082264,ARL
2025-07-17T16:44:54.910655006Z,2025-07-17T16:44:54.910489507Z,160,2,1108,A,A,14.810000000,100,0,379095997,130,165499,314082264,ARL
2025-07-17T16:44:54.914425010Z,2025-07-17T16:44:54.914259600Z,160,2,1108,C,A,17.720000000,100,0,378884397,0,165410,314082334,ARL
2025-07-17T16:44:54.914425010Z,2025-07-17T16:44:54.914259600Z,160,2,1108,A,A,17.100000000,100,0,379096089,130,165410,314082334,ARL
2025-07-17T16:44:54.915883302Z,2025-07-17T16:44:54.915718215Z,160,2,1108,C,A,14.230000000,100,0,378884757,130,165087,314082353,ARL
2025-07-17T16:44:54.915941482Z,2025-07-17T16:44:54.915775814Z,160,2,1108,A,A,13.730000000,100,0,379096113,130,165668,314082354,ARL
2025-07-17T16:44:54.917392645Z,2025-07-17T16:44:54.917226019Z,160,2,1108,C,A,16.050000000,100,0,378884393,0,166626,314082375,ARL
2025-07-17T16:44:54.917392645Z,2025-07-17T16:44:54.917226019Z,160,2,1108,A,A,15.480000000,100,0,379096145,128,166626,314082375,ARL
2025-07-17T16:44:54.943399816Z,2025-07-17T16:44:54.943234212Z,160,2,1108,A,A,15.350000000,100,0,379096757,130,165604,314082897,ARL
2025-07-17T16:44:54.943412752Z,2025-07-17T16:44:54.943247176Z,160,2,1108,C,A,15.660000000,100,0,378884173,130,165576,314082898,ARL
2025-07-17T16:44:54.946484373Z,2025-07-17T16:44:54.946318646Z,160,2,1108,C,A,14.770000000,100,0,378905145,130,165727,314082939,ARL
2025-07-17T16:44:54.946589307Z,2025-07-17T16:44:54.946424043Z,160,2,1108,A,A,14.250000000,100,0,379096805,130,165264,314082941,ARL
2025-07-17T16:44:54.966483966Z,2025-07-17T16:44:54.966318646Z,160,2,1108,C,A,15.110000000,100,0,378884221,0,165320,314083178,ARL
2025-07-17T16:44:54.966483966Z,2025-07-17T16:44:54.966318646Z,160,2,1108,A,A,14.810000000,100,0,379096977,130,165320,314083178,ARL
2025-07-17T16:44:54.966676722Z,2025-07-17T16:44:54.966510936Z,160,2,1108,C,A,14.960000000,100,0,378884425,0,165786,314083184,ARL
2025-07-17T16:44:54.966676722Z,2025-07-17T16:44:54.966510936Z,160,2,1108,A,A,14.410000000,100,0,379096981,130,165786,314083184,ARL
2025-07-17T16:44:55.300928207Z,2025-07-17T16:44:55.300763037Z,160,2,1108,A,A,14.260000000,100,0,379107445,130,165170,314089820,ARL
2025-07-17T16:44:55.300941959Z,2025-07-17T16:44:55.300776109Z,160,2,1108,C,A,14.810000000,100,0,378887673,130,165850,314089821,ARL
2025-07-17T16:44:59.834339138Z,2025-07-17T16:44:59.834173908Z,160,2,1108,A,A,14.180000000,700,0,379214721,130,165230,314166592,ARL
2025-07-17T16:44:59.834390830Z,2025-07-17T16:44:59.834225419Z,160,2,1108,C,A,14.680000000,700,0,378885133,130,165411,314166593,ARL
2025-07-17T16:45:03.007404835Z,2025-07-17T16:45:03.007238453Z,160,2,1108,C,A,13.790000000,2,0,379095929,0,166382,314215324,ARL
2025-07-17T16:45:03.007404835Z,2025-07-17T16:45:03.007238453Z,160,2,1108,A,A,13.710000000,2,0,379278349,130,166382,314215324,ARL
2025-07-17T16:45:27.018764451Z,2025-07-17T16:45:27.018599302Z,160,2,1108,A,A,13.490000000,100,0,379736825,130,165149,314585155,ARL
2025-07-17T16:45:30.186104539Z,2025-07-17T16:45:30.185938975Z,160,2,1108,C,A,13.710000000,2,0,379278349,0,165564,314635721,ARL
2025-07-17T16:45:30.186104539Z,2025-07-17T16:45:30.185938975Z,160,2,1108,A,A,13.650000000,2,0,379801189,130,165564,314635721,ARL
2025-07-17T16:46:28.859807513Z,2025-07-17T16:46:28.859642188Z,160,2,1108,A,B,13.110000000,10,0,381110009,130,165325,315728525,ARL
2025-07-17T16:46:36.884859958Z,2025-07-17T16:46:36.884693968Z,160,2,1108,C,B,13.110000000,10,0,381110009,130,165990,315927907,ARL
2025-07-17T16:46:37.794706042Z,2025-07-17T16:46:37.794540840Z,160,2,1108,A,A,13.470000000,100,0,381366917,130,165202,315954210,ARL
2025-07-17T16:46:37.802095880Z,2025-07-17T16:46:37.801930526Z,160,2,1108,C,A,13.490000000,100,0,379736825,130,165354,315954275,ARL
2025-07-17T16:46:38.884703690Z,2025-07-17T16:46:38.884538478Z,160,2,1108,A,A,13.430000000,15,0,381385565,130,165212,315968206,ARL
2025-07-17T16:46:39.214830278Z,2025-07-17T16:46:39.214664841Z,160,2,1108,C,A,13.460000000,100,0,379095909,0,165437,315973473,ARL
2025-07-17T16:46:39.214830278Z,2025-07-17T16:46:39.214664841Z,160,2,1108,A,A,13.440000000,100,0,381389921,130,165437,315973473,ARL
2025-07-17T16:46:39.495838136Z,2025-07-17T16:46:39.495672905Z,160,2,1108,A,A,13.970000000,100,0,381395205,130,165231,315977251,ARL
2025-07-17T16:46:39.495839277Z,2025-07-17T16:46:39.495673898Z,160,2,1108,C,A,14.260000000,100,0,375329381,130,165379,315977252,ARL
2025-07-17T16:47:10.014058218Z,2025-07-17T16:47:10.013892892Z,160,2,1108,C,A,13.440000000,100,0,381389921,130,165326,316423218,ARL
2025-07-17T16:47:10.015675562Z,2025-07-17T16:47:10.015510357Z,160,2,1108,C,A,13.450000000,15,0,379094717,130,165205,316423231,ARL
2025-07-17T16:47:11.017693401Z,2025-07-17T16:47:11.017528057Z,160,2,1108,A,A,13.400000000,15,0,381931621,130,165344,316439018,ARL
2025-07-17T16:47:11.276672234Z,2025-07-17T16:47:11.276507069Z,160,2,1108,A,A,13.440000000,100,0,381937585,130,165165,316442554,ARL
2025-07-17T16:47:20.734276459Z,2025-07-17T16:47:20.734111066Z,160,2,1108,C,A,13.400000000,15,0,381931621,130,165393,316605363,ARL
2025-07-17T16:47:20.735448515Z,2025-07-17T16:47:20.735283296Z,160,2,1108,C,A,13.430000000,15,0,381385565,130,165219,316605399,ARL
2025-07-17T16:47:39.209475918Z,2025-07-17T16:47:39.209310686Z,160,2,1108,A,A,13.390000000,15,0,382444445,130,165232,316885657,ARL
2025-07-17T16:47:46.798254633Z,2025-07-17T16:47:46.798089272Z,160,2,1108,C,A,13.470000000,100,0,381366917,130,165361,316999429,ARL
2025-07-17T16:47:46.799294977Z,2025-07-17T16:47:46.799129468Z,160,2,1108,A,A,13.370000000,15,0,382585849,130,165509,316999432,ARL
2025-07-17T16:47:56.799358992Z,2025-07-17T16:47:56.799193045Z,160,2,1108,C,A,13.390000000,15,0,382444445,130,165947,317127138,ARL
2025-07-17T16:48:45.976570510Z,2025-07-17T16:48:45.976405116Z,160,2,1108,A,A,13.350000000,15,0,383773141,130,165394,317969792,ARL
2025-07-17T16:49:41.077518286Z,2025-07-17T16:49:41.077352984Z,160,2,1108,C,A,13.370000000,15,0,382585849,130,165302,318962185,ARL
2025-07-17T16:49:42.081046319Z,2025-07-17T16:49:42.080880890Z,160,2,1108,A,A,13.330000000,15,0,384964609,130,165429,318972429,ARL
2025-07-17T16:49:42.081131683Z,2025-07-17T16:49:42.080966181Z,160,2,1108,C,A,14.350000000,100,0,360438973,0,165502,318972430,ARL
2025-07-17T16:49:42.081131683Z,2025-07-17T16:49:42.080966181Z,160,2,1108,A,A,14.230000000,100,0,384964613,130,165502,318972430,ARL
2025-07-17T16:49:42.081191778Z,2025-07-17T16:49:42.081026152Z,160,2,1108,C,A,14.350000000,100,0,360439617,0,165626,318972432,ARL
2025-07-17T16:49:42.081191778Z,2025-07-17T16:49:42.081026152Z,160,2,1108,A,A,14.230000000,100,0,384964617,130,165626,318972432,ARL
2025-07-17T16:50:35.555078054Z,2025-07-17T16:50:35.554910694Z,160,2,1108,C,A,13.330000000,15,0,384964609,130,167360,319771042,ARL
2025-07-17T16:50:35.568797086Z,2025-07-17T16:50:35.568627090Z,160,2,1108,C,A,13.350000000,15,0,383773141,130,169996,319772565,ARL
2025-07-17T16:50:37.518471839Z,2025-07-17T16:50:37.518305138Z,160,2,1108,A,A,13.330000000,15,0,386002397,130,166701,319815357,ARL
2025-07-17T16:50:50.893243130Z,2025-07-17T16:50:50.893077384Z,160,2,1108,A,A,13.310000000,15,0,386239877,130,165746,320022719,ARL
2025-07-17T16:51:49.203151913Z,2025-07-17T16:51:49.202985817Z,160,2,1108,T,A,13.110000000,100,0,0,130,166096,320804609,ARL
2025-07-17T16:51:49.203151913Z,2025-07-17T16:51:49.202985817Z,160,2,1108,F,B,13.110000000,100,0,326158877,130,166096,320804609,ARL
2025-07-17T16:51:49.203151913Z,2025-07-17T16:51:49.202985817Z,160,2,1108,C,B,13.110000000,100,0,326158877,130,166096,320804609,ARL
2025-07-17T16:51:49.203183079Z,2025-07-17T16:51:49.203017730Z,160,2,1108,A,A,13.270000000,12,0,387208141,130,165349,320804610,ARL
2025-07-17T16:51:49.203462720Z,2025-07-17T16:51:49.203297464Z,160,2,1108,A,A,14.180000000,700,0,387208149,130,165256,320804615,ARL
2025-07-17T16:51:49.203491307Z,2025-07-17T16:51:49.203325727Z,160,2,1108,C,B,12.980000000,100,0,328489377,130,165580,320804616,ARL
2025-07-17T16:51:49.203492455Z,2025-07-17T16:51:49.203327079Z,160,2,1108,C,B,12.980000000,100,0,328489385,130,165376,320804617,ARL
2025-07-17T16:51:49.203503585Z,2025-07-17T16:51:49.203337891Z,160,2,1108,C,A,14.540000000,700,0,338864169,130,165694,320804618,ARL
2025-07-17T16:51:49.203538049Z,2025-07-17T16:51:49.203372483Z,160,2,1108,C,B,12.370000000,700,0,45025165,130,165566,320804619,ARL
2025-07-17T16:51:49.203539070Z,2025-07-17T16:51:49.203373534Z,160,2,1108,C,B,12.430000000,700,0,47383873,130,165536,320804620,ARL
2025-07-17T16:51:49.203582920Z,2025-07-17T16:51:49.203417555Z,160,2,1108,A,B,12.210000000,700,0,387208153,130,165365,320804621,ARL
2025-07-17T16:51:49.203583860Z,2025-07-17T16:51:49.203418616Z,160,2,1108,A,B,12.150000000,700,0,387208157,130,165244,320804622,ARL
2025-07-17T16:51:49.203628732Z,2025-07-17T16:51:49.203463187Z,160,2,1108,A,B,11.050000000,100,0,387208161,130,165545,320804623,ARL
2025-07-17T16:51:49.203642142Z,2025-07-17T16:51:49.203476486Z,160,2,1108,C,B,11.400000000,100,0,43315905,130,165656,320804624,ARL
2025-07-17T16:51:49.203893770Z,2025-07-17T16:51:49.203728024Z,160,2,1108,C,B,12.710000000,100,0,285586093,130,165746,320804626,ARL
2025-07-17T16:51:49.203936007Z,2025-07-17T16:51:49.203770525Z,160,2,1108,C,B,12.100000000,100,0,327112289,0,165482,320804627,ARL
2025-07-17T16:51:49.203936007Z,2025-07-17T16:51:49.203770525Z,160,2,1108,A,B,11.970000000,100,0,387208165,130,165482,320804627,ARL
2025-07-17T16:51:49.204248005Z,2025-07-17T16:51:49.204082713Z,160,2,1108,A,B,12.290000000,100,0,387208173,130,165292,320804630,ARL
2025-07-17T16:51:49.204263290Z,2025-07-17T16:51:49.204097932Z,160,2,1108,C,B,12.420000000,700,0,44720357,130,165358,320804631,ARL
2025-07-17T16:51:49.204671217Z,2025-07-17T16:51:49.204505724Z,160,2,1108,A,B,12.180000000,700,0,387208181,130,165493,320804633,ARL
2025-07-17T16:51:49.204681497Z,2025-07-17T16:51:49.204515872Z,160,2,1108,C,B,11.930000000,100,0,43329953,0,165625,320804634,ARL
2025-07-17T16:51:49.204681497Z,2025-07-17T16:51:49.204515872Z,160,2,1108,A,B,11.570000000,100,0,387208185,130,165625,320804634,ARL
2025-07-17T16:51:49.205015653Z,2025-07-17T16:51:49.204850120Z,160,2,1108,C,B,12.200000000,100,0,327112385,0,165533,320804636,ARL
2025-07-17T16:51:49.205015653Z,2025-07-17T16:51:49.204850120Z,160,2,1108,A,B,11.950000000,100,0,387208189,130,165533,320804636,ARL
2025-07-17T16:51:49.205028204Z,2025-07-17T16:51:49.204862493Z,160,2,1108,C,B,11.270000000,100,0,285586145,0,165711,320804637,ARL
2025-07-17T16:51:49.205028204Z,2025-07-17T16:51:49.204862493Z,160,2,1108,A,B,10.930000000,100,0,387208193,130,165711,320804637,ARL
2025-07-17T16:51:49.205058473Z,2025-07-17T16:51:49.204893061Z,160,2,1108,C,B,12.200000000,100,0,327112393,0,165412,320804638,ARL
2025-07-17T16:51:49.205058473Z,2025-07-17T16:51:49.204893061Z,160,2,1108,A,B,11.950000000,100,0,387208197,130,165412,320804638,ARL
2025-07-17T16:51:49.205513341Z,2025-07-17T16:51:49.205347703Z,160,2,1108,C,B,12.330000000,100,0,327114465,0,165638,320804639,ARL
2025-07-17T16:51:49.205513341Z,2025-07-17T16:51:49.205347703Z,160,2,1108,A,B,12.080000000,100,0,387208201,130,165638,320804639,ARL
2025-07-17T16:51:49.205876283Z,2025-07-17T16:51:49.205710839Z,160,2,1108,C,B,9.680000000,100,0,285586157,0,165444,320804640,ARL
2025-07-17T16:51:49.205876283Z,2025-07-17T16:51:49.205710839Z,160,2,1108,A,B,9.380000000,100,0,387208209,130,165444,320804640,ARL
2025-07-17T16:51:49.205908116Z,2025-07-17T16:51:49.205742418Z,160,2,1108,C,B,11.930000000,100,0,43852121,0,165698,320804641,ARL
2025-07-17T16:51:49.205908116Z,2025-07-17T16:51:49.205742418Z,160,2,1108,A,B,11.570000000,100,0,387208213,130,165698,320804641,ARL
2025-07-17T16:51:49.208141937Z,2025-07-17T16:51:49.207976677Z,160,2,1108,C,A,13.330000000,15,0,386002397,130,165260,320804643,ARL
2025-07-17T16:51:49.209429801Z,2025-07-17T16:51:49.209264359Z,160,2,1108,C,B,12.970000000,2,0,378976465,0,165442,320804652,ARL
2025-07-17T16:51:49.209429801Z,2025-07-17T16:51:49.209264359Z,160,2,1108,A,B,12.860000000,2,0,387208221,130,165442,320804652,ARL
2025-07-17T16:51:49.228061514Z,2025-07-17T16:51:49.227895926Z,160,2,1108,C,B,12.860000000,100,0,327112577,130,165588,320804783,ARL
2025-07-17T16:51:49.228083393Z,2025-07-17T16:51:49.227918298Z,160,2,1108,C,A,13.270000000,12,0,387208141,130,165095,320804784,ARL
2025-07-17T16:51:49.228115834Z,2025-07-17T16:51:49.227950521Z,160,2,1108,A,B,12.720000000,100,0,387208393,130,165313,320804785,ARL
2025-07-17T16:51:49.228192290Z,2025-07-17T16:51:49.228027215Z,160,2,1108,A,A,13.350000000,100,0,387208401,130,165075,320804787,ARL
2025-07-17T16:51:49.228920022Z,2025-07-17T16:51:49.228754389Z,160,2,1108,C,A,14.500000000,100,0,379095949,0,165633,320804796,ARL
2025-07-17T16:51:49.228920022Z,2025-07-17T16:51:49.228754389Z,160,2,1108,A,A,14.390000000,100,0,387208437,130,165633,320804796,ARL
2025-07-17T16:51:49.228941361Z,2025-07-17T16:51:49.228776421Z,160,2,1108,C,B,12.720000000,100,0,387208393,130,164940,320804797,ARL
2025-07-17T16:51:49.228990151Z,2025-07-17T16:51:49.228824994Z,160,2,1108,A,B,12.600000000,100,0,387208445,130,165157,320804800,ARL
2025-07-17T16:51:49.229183103Z,2025-07-17T16:51:49.229017895Z,160,2,1108,C,B,12.500000000,700,0,216223005,130,165208,320804802,ARL
2025-07-17T16:51:49.229948151Z,2025-07-17T16:51:49.229782937Z,160,2,1108,A,B,11.900000000,700,0,387208453,130,165214,320804803,ARL
2025-07-17T16:51:49.231422801Z,2025-07-17T16:51:49.231256903Z,160,2,1108,C,A,17.100000000,100,0,379096089,0,165898,320804809,ARL
2025-07-17T16:51:49.231422801Z,2025-07-17T16:51:49.231256903Z,160,2,1108,A,A,16.960000000,100,0,387208465,130,165898,320804809,ARL
2025-07-17T16:51:49.248082452Z,2025-07-17T16:51:49.247917413Z,160,2,1108,C,B,12.600000000,100,0,387208445,130,165039,320804925,ARL
2025-07-17T16:51:49.248121701Z,2025-07-17T16:51:49.247956413Z,160,2,1108,C,A,13.730000000,100,0,379096113,130,165288,320804926,ARL
2025-07-17T16:51:49.248132021Z,2025-07-17T16:51:49.247966903Z,160,2,1108,A,B,12.480000000,100,0,387208693,130,165118,320804927,ARL
2025-07-17T16:51:49.248171077Z,2025-07-17T16:51:49.248005919Z,160,2,1108,A,A,13.620000000,100,0,387208697,130,165158,320804928,ARL
2025-07-17T16:51:49.253276576Z,2025-07-17T16:51:49.253111250Z,160,2,1108,C,B,11.970000000,100,0,387208165,0,165326,320804945,ARL
2025-07-17T16:51:49.253276576Z,2025-07-17T16:51:49.253111250Z,160,2,1108,A,B,11.740000000,100,0,387208725,130,165326,320804945,ARL
2025-07-17T16:51:49.486790140Z,2025-07-17T16:51:49.486625091Z,160,2,1108,A,B,11.970000000,100,0,387211505,130,165049,320807855,ARL
2025-07-17T16:51:49.486804184Z,2025-07-17T16:51:49.486638813Z,160,2,1108,C,B,12.460000000,100,0,43804025,130,165371,320807856,ARL
2025-07-17T16:51:49.800536067Z,2025-07-17T16:51:49.800370631Z,160,2,1108,C,B,12.730000000,100,0,44066409,130,165436,320817705,ARL
2025-07-17T16:51:49.800537373Z,2025-07-17T16:51:49.800372140Z,160,2,1108,A,B,12.220000000,100,0,387224049,130,165233,320817706,ARL
2025-07-17T16:51:49.800849744Z,2025-07-17T16:51:49.800684387Z,160,2,1108,C,B,12.210000000,700,0,387208153,130,165357,320817711,ARL
2025-07-17T16:51:49.800892151Z,2025-07-17T16:51:49.800726814Z,160,2,1108,A,B,12.040000000,700,0,387224057,130,165337,320817712,ARL
2025-07-17T16:51:49.802755391Z,2025-07-17T16:51:49.802589700Z,160,2,1108,C,B,10.930000000,100,0,387208193,0,165691,320817729,ARL
2025-07-17T16:51:49.802755391Z,2025-07-17T16:51:49.802589700Z,160,2,1108,A,B,10.770000000,100,0,387224101,130,165691,320817729,ARL
2025-07-17T16:51:49.803156570Z,2025-07-17T16:51:49.802991246Z,160,2,1108,C,B,11.950000000,100,0,387208189,0,165324,320817732,ARL
2025-07-17T16:51:49.803156570Z,2025-07-17T16:51:49.802991246Z,160,2,1108,A,B,11.790000000,100,0,387224105,130,165324,320817732,ARL
2025-07-17T16:51:49.859421495Z,2025-07-17T16:51:49.859256253Z,160,2,1108,C,B,11.950000000,100,0,387208197,0,165242,320818164,ARL
2025-07-17T16:51:49.859421495Z,2025-07-17T16:51:49.859256253Z,160,2,1108,A,B,11.790000000,100,0,387224437,130,165242,320818164,ARL
2025-07-17T16:51:49.859466704Z,2025-07-17T16:51:49.859301062Z,160,2,1108,C,B,12.150000000,700,0,387208157,0,165642,320818165,ARL
2025-07-17T16:51:49.859466704Z,2025-07-17T16:51:49.859301512Z,160,2,1108,C,B,12.040000000,700,0,387224057,130,165192,320818166,ARL
2025-07-17T16:51:49.859505956Z,2025-07-17T16:51:49.859340670Z,160,2,1108,A,B,11.850000000,700,0,387224445,130,165286,320818167,ARL
2025-07-17T16:51:49.859516630Z,2025-07-17T16:51:49.859351324Z,160,2,1108,A,B,11.790000000,700,0,387224449,130,165306,320818168,ARL
2025-07-17T16:51:49.859540088Z,2025-07-17T16:51:49.859374726Z,160,2,1108,A,B,10.730000000,100,0,387224453,130,165362,320818169,ARL
2025-07-17T16:51:49.859552342Z,2025-07-17T16:51:49.859387321Z,160,2,1108,C,B,11.050000000,100,0,387208161,130,165021,320818170,ARL
2025-07-17T16:51:49.859846672Z,2025-07-17T16:51:49.859680717Z,160,2,1108,C,B,12.860000000,2,0,387208221,0,165955,320818176,ARL
2025-07-17T16:51:49.859846672Z,2025-07-17T16:51:49.859680717Z,160,2,1108,A,B,12.480000000,2,0,387224461,130,165955,320818176,ARL
2025-07-17T16:51:49.859900876Z,2025-07-17T16:51:49.859735317Z,160,2,1108,C,B,11.740000000,100,0,387208725,0,165559,320818178,ARL
2025-07-17T16:51:49.859900876Z,2025-07-17T16:51:49.859735317Z,160,2,1108,A,B,11.690000000,100,0,387224465,130,165559,320818178,ARL
2025-07-17T16:51:49.859935005Z,2025-07-17T16:51:49.859769986Z,160,2,1108,C,B,12.290000000,100,0,387208173,130,165019,320818179,ARL
2025-07-17T16:51:49.859975262Z,2025-07-17T16:51:49.859810002Z,160,2,1108,C,B,12.180000000,700,0,387208181,130,165260,320818180,ARL
2025-07-17T16:51:49.860284456Z,2025-07-17T16:51:49.860119158Z,160,2,1108,A,B,11.920000000,100,0,387224477,130,165298,320818186,ARL
2025-07-17T16:51:49.860421400Z,2025-07-17T16:51:49.860256159Z,160,2,1108,A,B,11.820000000,700,0,387224481,130,165241,320818196,ARL
2025-07-17T16:51:49.860562759Z,2025-07-17T16:51:49.860397598Z,160,2,1108,C,B,10.770000000,100,0,387224101,0,165161,320818205,ARL
2025-07-17T16:51:49.860562759Z,2025-07-17T16:51:49.860397598Z,160,2,1108,A,B,10.600000000,100,0,387224485,130,165161,320818205,ARL
2025-07-17T16:51:49.861097298Z,2025-07-17T16:51:49.860931903Z,160,2,1108,C,B,9.380000000,100,0,387208209,0,165395,320818216,ARL
2025-07-17T16:51:49.861097298Z,2025-07-17T16:51:49.860931903Z,160,2,1108,A,B,9.110000000,100,0,387224489,130,165395,320818216,ARL
2025-07-17T16:51:49.861356980Z,2025-07-17T16:51:49.861191695Z,160,2,1108,C,B,11.790000000,100,0,387224105,0,165285,320818220,ARL
2025-07-17T16:51:49.861356980Z,2025-07-17T16:51:49.861191695Z,160,2,1108,A,B,11.600000000,100,0,387224493,130,165285,320818220,ARL
2025-07-17T16:51:49.861621072Z,2025-07-17T16:51:49.861455154Z,160,2,1108,C,B,11.570000000,100,0,387208185,0,165918,320818225,ARL
2025-07-17T16:51:49.861621072Z,2025-07-17T16:51:49.861455154Z,160,2,1108,A,B,11.230000000,100,0,387224501,130,165918,320818225,ARL
2025-07-17T16:51:49.864197480Z,2025-07-17T16:51:49.864031359Z,160,2,1108,C,B,11.570000000,100,0,387208213,0,166121,320818229,ARL
2025-07-17T16:51:49.864197480Z,2025-07-17T16:51:49.864031359Z,160,2,1108,A,B,11.230000000,100,0,387224517,128,166121,320818229,ARL
2025-07-17T16:51:49.866376519Z,2025-07-17T16:51:49.866210978Z,160,2,1108,C,B,12.480000000,100,0,387208693,130,165541,320818236,ARL
2025-07-17T16:51:49.866427192Z,2025-07-17T16:51:49.866261553Z,160,2,1108,A,B,12.230000000,100,0,387224537,130,165639,320818237,ARL
2025-07-17T16:51:49.884073963Z,2025-07-17T16:51:49.883908795Z,160,2,1108,C,B,11.790000000,100,0,387224437,0,165168,320818367,ARL
2025-07-17T16:51:49.884073963Z,2025-07-17T16:51:49.883908795Z,160,2,1108,A,B,11.600000000,100,0,387224957,130,165168,320818367,ARL
2025-07-17T16:51:49.910013623Z,2025-07-17T16:51:49.909848233Z,160,2,1108,C,B,11.690000000,100,0,387224465,0,165390,320818728,ARL
2025-07-17T16:51:49.910013623Z,2025-07-17T16:51:49.909848233Z,160,2,1108,A,B,11.510000000,100,0,387225161,130,165390,320818728,ARL
2025-07-17T16:51:50.208375347Z,2025-07-17T16:51:50.208210239Z,160,2,1108,C,B,12.080000000,100,0,387208201,130,165108,320822967,ARL
2025-07-17T16:51:50.208482454Z,2025-07-17T16:51:50.208317118Z,160,2,1108,A,B,11.720000000,100,0,387229905,130,165336,320822970,ARL
2025-07-17T16:51:50.699011166Z,2025-07-17T16:51:50.698845651Z,160,2,1108,A,A,13.290000000,15,0,387234697,130,165515,320827751,ARL
2025-07-17T16:51:51.701161133Z,2025-07-17T16:51:51.700995710Z,160,2,1108,A,A,13.330000000,100,0,387246049,130,165423,320835508,ARL
2025-07-17T16:51:51.702993642Z,2025-07-17T16:51:51.702827799Z,160,2,1108,C,A,14.410000000,100,0,379095977,0,165843,320835517,ARL
2025-07-17T16:51:51.702993642Z,2025-07-17T16:51:51.702827799Z,160,2,1108,A,A,14.270000000,100,0,387246077,130,165843,320835517,ARL
2025-07-17T16:51:51.703967249Z,2025-07-17T16:51:51.703801688Z,160,2,1108,C,A,15.480000000,100,0,379096145,0,165561,320835520,ARL
2025-07-17T16:51:51.703967249Z,2025-07-17T16:51:51.703801688Z,160,2,1108,A,A,15.330000000,100,0,387246085,130,165561,320835520,ARL
2025-07-17T16:51:51.713961526Z,2025-07-17T16:51:51.713795931Z,160,2,1108,C,A,14.250000000,100,0,379096805,0,165595,320835557,ARL
2025-07-17T16:51:51.713961526Z,2025-07-17T16:51:51.713795931Z,160,2,1108,A,A,14.110000000,100,0,387246169,130,165595,320835557,ARL
2025-07-17T16:51:51.715367568Z,2025-07-17T16:51:51.715202054Z,160,2,1108,C,A,14.410000000,100,0,379096981,0,165514,320835598,ARL
2025-07-17T16:51:51.715367568Z,2025-07-17T16:51:51.715202054Z,160,2,1108,A,A,14.270000000,100,0,387246189,130,165514,320835598,ARL
2025-07-17T16:51:51.725157788Z,2025-07-17T16:51:51.724992350Z,160,2,1108,C,A,13.350000000,100,0,387208401,130,165438,320835691,ARL
2025-07-17T16:51:54.352994981Z,2025-07-17T16:51:54.352829325Z,160,2,1108,A,A,14.060000000,700,0,387277657,130,165656,320864203,ARL
2025-07-17T16:51:54.353384868Z,2025-07-17T16:51:54.353219520Z,160,2,1108,C,A,14.480000000,700,0,347022749,130,165348,320864204,ARL
2025-07-17T16:51:57.166017979Z,2025-07-17T16:51:57.165852611Z,160,2,1108,A,A,14.200000000,700,0,387313797,130,165368,320905527,ARL
2025-07-17T16:51:57.166770222Z,2025-07-17T16:51:57.166604514Z,160,2,1108,C,A,14.480000000,700,0,331272997,130,165708,320905531,ARL
2025-07-17T16:52:09.189661940Z,2025-07-17T16:52:09.189496109Z,160,2,1108,C,A,13.650000000,2,0,379801189,0,165831,321054296,ARL
2025-07-17T16:52:09.189661940Z,2025-07-17T16:52:09.189496109Z,160,2,1108,A,A,13.400000000,2,0,387521285,130,165831,321054296,ARL
2025-07-17T16:52:25.385962483Z,2025-07-17T16:52:25.385796835Z,160,2,1108,C,A,13.400000000,2,0,387521285,0,165648,321280124,ARL
2025-07-17T16:52:25.385962483Z,2025-07-17T16:52:25.385796835Z,160,2,1108,A,A,13.340000000,2,0,387814377,130,165648,321280124,ARL
2025-07-17T16:52:44.599936486Z,2025-07-17T16:52:44.599769693Z,160,2,1108,C,A,13.310000000,15,0,386239877,130,166793,321507803,ARL
2025-07-17T16:52:45.910519022Z,2025-07-17T16:52:45.910353639Z,160,2,1108,A,A,13.270000000,15,0,388154969,130,165383,321528658,ARL
2025-07-17T16:52:45.913175484Z,2025-07-17T16:52:45.913010349Z,160,2,1108,A,A,13.310000000,100,0,388155109,130,165135,321528927,ARL
2025-07-17T16:52:45.913908188Z,2025-07-17T16:52:45.913742606Z,160,2,1108,C,A,14.390000000,100,0,387208437,0,165582,321528948,ARL
2025-07-17T16:52:45.913908188Z,2025-07-17T16:52:45.913742606Z,160,2,1108,A,A,14.340000000,100,0,388155141,130,165582,321528948,ARL
2025-07-17T16:52:45.915897968Z,2025-07-17T16:52:45.915732713Z,160,2,1108,C,A,13.330000000,100,0,387246049,130,165255,321528989,ARL
2025-07-17T16:53:02.591937954Z,2025-07-17T16:53:02.591772327Z,160,2,1108,C,A,13.340000000,2,0,387814377,0,165627,321769923,ARL
2025-07-17T16:53:02.591937954Z,2025-07-17T16:53:02.591772327Z,160,2,1108,A,A,13.310000000,2,0,388467165,130,165627,321769923,ARL
2025-07-17T16:53:04.319027498Z,2025-07-17T16:53:04.318857617Z,160,2,1108,C,A,13.270000000,15,0,388154969,128,169881,321820208,ARL
2025-07-17T16:53:04.327661725Z,2025-07-17T16:53:04.327496343Z,160,2,1108,C,A,13.290000000,15,0,387234697,130,165382,321823264,ARL
2025-07-17T16:53:05.349489709Z,2025-07-17T16:53:05.349324407Z,160,2,1108,A,A,13.270000000,15,0,388572113,130,165302,321852281,ARL
2025-07-17T16:53:06.896377351Z,2025-07-17T16:53:06.896211496Z,160,2,1108,C,A,13.270000000,15,0,388572113,130,165855,321876648,ARL
2025-07-17T16:53:26.171596597Z,2025-07-17T16:53:26.171430778Z,160,2,1108,C,A,13.310000000,100,0,388155109,130,165819,322130469,ARL
2025-07-17T16:53:26.172342788Z,2025-07-17T16:53:26.172176957Z,160,2,1108,C,A,14.340000000,100,0,388155141,0,165831,322130471,ARL
2025-07-17T16:53:26.172342788Z,2025-07-17T16:53:26.172176957Z,160,2,1108,A,A,14.480000000,100,0,388943405,130,165831,322130471,ARL
2025-07-17T16:53:26.190659558Z,2025-07-17T16:53:26.190494051Z,160,2,1108,C,A,13.620000000,100,0,387208697,130,165507,322130570,ARL
2025-07-17T16:53:26.190709400Z,2025-07-17T16:53:26.190544047Z,160,2,1108,A,A,13.710000000,100,0,388943785,130,165353,322130571,ARL
2025-07-17T16:53:30.899547028Z,2025-07-17T16:53:30.899381745Z,160,2,1108,A,A,13.250000000,15,0,389031981,130,165283,322188510,ARL
2025-07-17T16:53:40.523977051Z,2025-07-17T16:53:40.523811512Z,160,2,1108,A,A,13.290000000,100,0,389168405,130,165539,322295689,ARL
2025-07-17T16:53:40.524730169Z,2025-07-17T16:53:40.524564598Z,160,2,1108,C,A,14.480000000,100,0,388943405,0,165571,322295715,ARL
2025-07-17T16:53:40.524730169Z,2025-07-17T16:53:40.524564598Z,160,2,1108,A,A,14.320000000,100,0,389168425,130,165571,322295715,ARL
2025-07-17T16:53:40.543999964Z,2025-07-17T16:53:40.543834425Z,160,2,1108,C,A,13.710000000,100,0,388943785,130,165539,322295865,ARL
2025-07-17T16:53:40.544052304Z,2025-07-17T16:53:40.543887042Z,160,2,1108,A,A,13.560000000,100,0,389168529,130,165262,322295866,ARL
2025-07-17T16:53:58.389649544Z,2025-07-17T16:53:58.389483902Z,160,2,1108,C,A,13.310000000,2,0,388467165,0,165642,322603434,ARL
2025-07-17T16:53:58.389649544Z,2025-07-17T16:53:58.389483902Z,160,2,1108,A,A,13.290000000,2,0,389540593,130,165642,322603434,ARL
2025-07-17T16:54:21.082046733Z,2025-07-17T16:54:21.081881368Z,160,2,1108,A,A,13.270000000,100,0,389948353,130,165365,322944902,ARL
2025-07-17T16:54:21.084749633Z,2025-07-17T16:54:21.084582385Z,160,2,1108,C,A,13.290000000,100,0,389168405,128,167248,322945104,ARL
2025-07-17T16:54:22.887998509Z,2025-07-17T16:54:22.887832854Z,160,2,1108,C,A,14.230000000,100,0,384964617,0,165655,323001879,ARL
2025-07-17T16:54:22.887998509Z,2025-07-17T16:54:22.887832854Z,160,2,1108,A,A,14.110000000,100,0,390012165,130,165655,323001879,ARL
2025-07-17T16:54:22.888248718Z,2025-07-17T16:54:22.888082967Z,160,2,1108,C,A,14.230000000,100,0,384964613,0,165751,323001880,ARL
2025-07-17T16:54:22.888248718Z,2025-07-17T16:54:22.888082967Z,160,2,1108,A,A,14.110000000,100,0,390012177,130,165751,323001880,ARL
2025-07-17T16:54:22.890095705Z,2025-07-17T16:54:22.889930161Z,160,2,1108,A,A,13.230000000,15,0,390012185,130,165544,323001883,ARL
2025-07-17T16:54:25.387202430Z,2025-07-17T16:54:25.387036791Z,160,2,1108,C,A,13.290000000,2,0,389540593,0,165639,323044153,ARL
2025-07-17T16:54:25.387202430Z,2025-07-17T16:54:25.387036791Z,160,2,1108,A,A,13.270000000,2,0,390060109,130,165639,323044153,ARL
2025-07-17T16:54:29.752617295Z,2025-07-17T16:54:29.752451645Z,160,2,1108,A,A,13.250000000,100,0,390133645,130,165650,323103133,ARL
2025-07-17T16:54:29.752672363Z,2025-07-17T16:54:29.752502545Z,160,2,1108,T,B,13.230000000,15,0,0,0,169818,323103134,ARL
2025-07-17T16:54:29.752672363Z,2025-07-17T16:54:29.752502545Z,160,2,1108,F,A,13.230000000,15,0,390012185,0,169818,323103134,ARL
2025-07-17T16:54:29.752672363Z,2025-07-17T16:54:29.752502545Z,160,2,1108,C,A,13.230000000,15,0,390012185,0,169818,323103134,ARL
2025-07-17T16:54:29.752672363Z,2025-07-17T16:54:29.752502545Z,160,2,1108,T,N,13.240000000,50,0,0,0,169818,323103135,ARL
2025-07-17T16:54:29.752672363Z,2025-07-17T16:54:29.752502545Z,160,2,1108,T,B,13.250000000,15,0,0,0,169818,323103136,ARL
2025-07-17T16:54:29.752672363Z,2025-07-17T16:54:29.752502545Z,160,2,1108,F,A,13.250000000,15,0,389031981,0,169818,323103136,ARL
2025-07-17T16:54:29.752672363Z,2025-07-17T16:54:29.752502545Z,160,2,1108,C,A,13.250000000,15,0,389031981,0,169818,323103136,ARL
2025-07-17T16:54:29.752672363Z,2025-07-17T16:54:29.752502545Z,160,2,1108,T,B,13.250000000,50,0,0,130,169818,323103137,ARL
2025-07-17T16:54:29.752672363Z,2025-07-17T16:54:29.752502545Z,160,2,1108,F,A,13.250000000,50,0,390133645,130,169818,323103137,ARL
2025-07-17T16:54:29.752672363Z,2025-07-17T16:54:29.752502545Z,160,2,1108,C,A,13.250000000,50,0,390133645,130,169818,323103137,ARL
2025-07-17T16:54:29.752701698Z,2025-07-17T16:54:29.752536458Z,160,2,1108,A,B,12.860000000,5,0,390133657,130,165240,323103138,ARL
2025-07-17T16:54:29.752715670Z,2025-07-17T16:54:29.752550566Z,160,2,1108,A,B,12.860000000,1,0,390133665,130,165104,323103139,ARL
2025-07-17T16:54:29.752737909Z,2025-07-17T16:54:29.752572767Z,160,2,1108,A,B,12.630000000,3,0,390133673,130,165142,323103140,ARL
2025-07-17T16:54:29.752989375Z,2025-07-17T16:54:29.752820958Z,160,2,1108,A,B,13.120000000,1,0,390133713,128,168417,323103150,ARL
2025-07-17T16:54:29.753358690Z,2025-07-17T16:54:29.753192989Z,160,2,1108,C,A,14.060000000,100,0,379095981,130,165701,323103186,ARL
2025-07-17T16:54:29.753367493Z,2025-07-17T16:54:29.753201957Z,160,2,1108,C,A,14.320000000,100,0,389168425,0,165536,323103187,ARL
2025-07-17T16:54:29.753367493Z,2025-07-17T16:54:29.753201957Z,160,2,1108,A,A,14.280000000,100,0,390133865,130,165536,323103187,ARL
2025-07-17T16:54:29.753715748Z,2025-07-17T16:54:29.753550555Z,160,2,1108,A,A,13.860000000,100,0,390133893,130,165193,323103207,ARL
2025-07-17T16:54:29.753718240Z,2025-07-17T16:54:29.753552806Z,160,2,1108,C,B,12.860000000,5,0,390133657,130,165434,323103208,ARL
2025-07-17T16:54:29.753729022Z,2025-07-17T16:54:29.753564036Z,160,2,1108,C,B,12.860000000,1,0,390133665,130,164986,323103209,ARL
2025-07-17T16:54:29.754032980Z,2025-07-17T16:54:29.753868181Z,160,2,1108,C,B,13.120000000,1,0,390133713,130,164799,323103214,ARL
2025-07-17T16:54:29.755674164Z,2025-07-17T16:54:29.755508553Z,160,2,1108,C,A,13.270000000,100,0,389948353,130,165611,323103374,ARL
2025-07-17T16:54:29.765272943Z,2025-07-17T16:54:29.765107655Z,160,2,1108,C,A,13.560000000,100,0,389168529,130,165288,323103685,ARL
2025-07-17T16:54:29.765296367Z,2025-07-17T16:54:29.765130910Z,160,2,1108,C,B,12.630000000,3,0,390133673,130,165457,323103690,ARL
2025-07-17T16:54:29.765324253Z,2025-07-17T16:54:29.765159050Z,160,2,1108,A,A,13.710000000,100,0,390134597,130,165203,323103691,ARL
2025-07-17T16:54:29.803457455Z,2025-07-17T16:54:29.803292107Z,160,2,1108,C,A,14.280000000,100,0,390133865,0,165348,323104351,ARL
2025-07-17T16:54:29.803457455Z,2025-07-17T16:54:29.803292107Z,160,2,1108,A,A,14.480000000,100,0,390135069,130,165348,323104351,ARL
2025-07-17T16:54:29.902149909Z,2025-07-17T16:54:29.901984378Z,160,2,1108,C,A,13.250000000,50,0,390133645,130,165531,323105144,ARL
2025-07-17T16:54:29.902200064Z,2025-07-17T16:54:29.902034700Z,160,2,1108,C,A,13.440000000,100,0,381937585,130,165364,323105146,ARL
2025-07-17T16:54:29.902924290Z,2025-07-17T16:54:29.902759016Z,160,2,1108,C,A,14.480000000,100,0,390135069,0,165274,323105157,ARL
2025-07-17T16:54:29.902924290Z,2025-07-17T16:54:29.902759016Z,160,2,1108,A,A,14.540000000,100,0,390136225,130,165274,323105157,ARL
2025-07-17T16:54:29.903618942Z,2025-07-17T16:54:29.903453684Z,160,2,1108,C,A,14.180000000,700,0,387208149,130,165258,323105162,ARL
2025-07-17T16:54:29.903619827Z,2025-07-17T16:54:29.903454701Z,160,2,1108,C,A,14.180000000,700,0,379214721,130,165126,323105163,ARL
2025-07-17T16:54:29.903665995Z,2025-07-17T16:54:29.903499198Z,160,2,1108,A,A,14.400000000,700,0,390136249,0,166797,323105164,ARL
2025-07-17T16:54:29.903665995Z,2025-07-17T16:54:29.903499925Z,160,2,1108,A,A,14.470000000,700,0,390136253,130,166070,323105165,ARL
2025-07-17T16:54:29.903736121Z,2025-07-17T16:54:29.903569581Z,160,2,1108,A,A,15.630000000,100,0,390136261,130,166540,323105167,ARL
2025-07-17T16:54:29.903749150Z,2025-07-17T16:54:29.903583991Z,160,2,1108,C,A,15.350000000,100,0,379096757,130,165159,323105168,ARL
2025-07-17T16:54:29.904151511Z,2025-07-17T16:54:29.903986354Z,160,2,1108,C,A,14.060000000,700,0,387277657,130,165157,323105172,ARL
2025-07-17T16:54:29.904594600Z,2025-07-17T16:54:29.904429181Z,160,2,1108,A,A,14.430000000,700,0,390136281,130,165419,323105173,ARL
2025-07-17T16:54:29.904711701Z,2025-07-17T16:54:29.904545815Z,160,2,1108,C,A,14.270000000,100,0,387246077,0,165886,323105174,ARL
2025-07-17T16:54:29.904711701Z,2025-07-17T16:54:29.904545815Z,160,2,1108,A,A,14.670000000,100,0,390136285,130,165886,323105174,ARL
2025-07-17T16:54:29.904730712Z,2025-07-17T16:54:29.904565273Z,160,2,1108,C,A,15.330000000,100,0,387246085,0,165439,323105175,ARL
2025-07-17T16:54:29.904730712Z,2025-07-17T16:54:29.904565273Z,160,2,1108,A,A,15.770000000,100,0,390136289,130,165439,323105175,ARL
2025-07-17T16:54:29.905055107Z,2025-07-17T16:54:29.904889511Z,160,2,1108,C,A,16.960000000,100,0,387208465,0,165596,323105176,ARL
2025-07-17T16:54:29.905055107Z,2025-07-17T16:54:29.904889511Z,160,2,1108,A,A,17.420000000,100,0,390136293,130,165596,323105176,ARL
2025-07-17T16:54:29.906146981Z,2025-07-17T16:54:29.905981039Z,160,2,1108,C,A,14.110000000,100,0,387246169,130,165942,323105179,ARL
2025-07-17T16:54:29.906260629Z,2025-07-17T16:54:29.906095307Z,160,2,1108,A,A,14.490000000,100,0,390136305,130,165322,323105180,ARL
2025-07-17T16:54:29.913366029Z,2025-07-17T16:54:29.913200271Z,160,2,1108,C,A,14.270000000,100,0,387246189,0,165758,323105271,ARL
2025-07-17T16:54:29.913366029Z,2025-07-17T16:54:29.913200271Z,160,2,1108,A,A,14.670000000,100,0,390136577,130,165758,323105271,ARL
2025-07-17T16:54:29.941199602Z,2025-07-17T16:54:29.941034461Z,160,2,1108,C,A,13.710000000,100,0,390134597,130,165141,323105451,ARL
2025-07-17T16:54:29.941235857Z,2025-07-17T16:54:29.941070856Z,160,2,1108,C,A,14.400000000,700,0,390136249,130,165001,323105452,ARL
2025-07-17T16:54:29.941248976Z,2025-07-17T16:54:29.941083801Z,160,2,1108,A,A,13.980000000,100,0,390136733,130,165175,323105453,ARL
2025-07-17T16:54:29.941505876Z,2025-07-17T16:54:29.941340365Z,160,2,1108,C,B,12.480000000,2,0,387224461,130,165511,323105457,ARL
2025-07-17T16:54:29.941507781Z,2025-07-17T16:54:29.941342597Z,160,2,1108,C,A,13.270000000,2,0,390060109,130,165184,323105458,ARL
2025-07-17T16:54:29.941886876Z,2025-07-17T16:54:29.941721119Z,160,2,1108,C,B,12.220000000,100,0,342029561,0,165757,323105460,ARL
2025-07-17T16:54:29.941886876Z,2025-07-17T16:54:29.941721119Z,160,2,1108,A,B,11.580000000,100,0,390136757,130,165757,323105460,ARL
2025-07-17T16:54:29.941941025Z,2025-07-17T16:54:29.941775542Z,160,2,1108,C,A,14.110000000,100,0,390012177,0,165483,323105461,ARL
2025-07-17T16:54:29.941941025Z,2025-07-17T16:54:29.941775542Z,160,2,1108,A,A,14.330000000,100,0,390136761,130,165483,323105461,ARL
2025-07-17T16:54:29.942275798Z,2025-07-17T16:54:29.942110273Z,160,2,1108,C,B,12.220000000,100,0,342029581,0,165525,323105463,ARL
2025-07-17T16:54:29.942275798Z,2025-07-17T16:54:29.942110273Z,160,2,1108,A,B,11.580000000,100,0,390136769,130,165525,323105463,ARL
2025-07-17T16:54:29.942321132Z,2025-07-17T16:54:29.942155950Z,160,2,1108,C,A,17.420000000,100,0,390136293,0,165182,323105464,ARL
2025-07-17T16:54:29.942321132Z,2025-07-17T16:54:29.942155950Z,160,2,1108,A,A,17.610000000,100,0,390136773,130,165182,323105464,ARL
2025-07-17T16:54:29.942346690Z,2025-07-17T16:54:29.942181221Z,160,2,1108,C,A,14.110000000,100,0,390012165,0,165469,323105465,ARL
2025-07-17T16:54:29.942346690Z,2025-07-17T16:54:29.942181221Z,160,2,1108,A,A,14.330000000,100,0,390136777,130,165469,323105465,ARL
2025-07-17T16:54:29.943055746Z,2025-07-17T16:54:29.942890449Z,160,2,1108,C,A,14.670000000,100,0,390136285,0,165297,323105470,ARL
2025-07-17T16:54:29.943055746Z,2025-07-17T16:54:29.942890449Z,160,2,1108,A,A,14.840000000,100,0,390136789,130,165297,323105470,ARL
2025-07-17T16:54:29.943058973Z,2025-07-17T16:54:29.942893754Z,160,2,1108,C,A,15.770000000,100,0,390136289,0,165219,323105471,ARL
2025-07-17T16:54:29.943058973Z,2025-07-17T16:54:29.942893754Z,160,2,1108,A,A,15.940000000,100,0,390136793,130,165219,323105471,ARL
2025-07-17T16:54:29.943085767Z,2025-07-17T16:54:29.942920302Z,160,2,1108,C,A,14.670000000,100,0,390136577,0,165465,323105472,ARL
2025-07-17T16:54:29.943085767Z,2025-07-17T16:54:29.942920302Z,160,2,1108,A,A,14.840000000,100,0,390136797,130,165465,323105472,ARL
2025-07-17T16:54:29.943495528Z,2025-07-17T16:54:29.943330033Z,160,2,1108,C,A,14.810000000,100,0,379095997,0,165495,323105484,ARL
2025-07-17T16:54:29.943495528Z,2025-07-17T16:54:29.943330033Z,160,2,1108,A,A,15.250000000,100,0,390136825,130,165495,323105484,ARL
2025-07-17T16:54:29.943524689Z,2025-07-17T16:54:29.943358872Z,160,2,1108,C,A,14.810000000,100,0,379096977,0,165817,323105485,ARL
2025-07-17T16:54:29.943524689Z,2025-07-17T16:54:29.943358872Z,160,2,1108,A,A,15.250000000,100,0,390136829,130,165817,323105485,ARL
2025-07-17T16:54:29.949816648Z,2025-07-17T16:54:29.949651286Z,160,2,1108,C,A,13.980000000,100,0,390136733,130,165362,323105536,ARL
2025-07-17T16:54:29.949863878Z,2025-07-17T16:54:29.949698550Z,160,2,1108,A,A,14.140000000,100,0,390136953,130,165328,323105537,ARL
2025-07-17T16:54:29.953135260Z,2025-07-17T16:54:29.952969836Z,160,2,1108,C,A,14.540000000,100,0,390136225,0,165424,323105548,ARL
2025-07-17T16:54:29.953135260Z,2025-07-17T16:54:29.952969836Z,160,2,1108,A,A,14.930000000,100,0,390136969,130,165424,323105548,ARL
2025-07-17T16:54:29.958038073Z,2025-07-17T16:54:29.957872826Z,160,2,1108,A,A,14.560000000,700,0,390137005,130,165247,323105616,ARL
2025-07-17T16:54:29.980615341Z,2025-07-17T16:54:29.980450077Z,160,2,1108,A,A,13.870000000,100,0,390137561,130,165264,323106126,ARL
2025-07-17T16:54:30.291618577Z,2025-07-17T16:54:30.291453478Z,160,2,1108,C,A,13.860000000,100,0,390133893,130,165099,323111095,ARL
2025-07-17T16:54:30.291970609Z,2025-07-17T16:54:30.291805387Z,160,2,1108,A,A,14.480000000,100,0,390141957,130,165222,323111099,ARL
2025-07-17T16:54:30.389814249Z,2025-07-17T16:54:30.389648969Z,160,2,1108,A,A,14.690000000,100,0,390146033,130,165280,323116866,ARL
2025-07-17T16:54:30.389834142Z,2025-07-17T16:54:30.389668907Z,160,2,1108,C,A,14.260000000,100,0,379107445,130,165235,323116867,ARL
2025-07-17T16:54:30.880773993Z,2025-07-17T16:54:30.880608525Z,160,2,1108,C,A,13.970000000,100,0,381395205,130,165468,323122333,ARL
2025-07-17T16:54:30.880776478Z,2025-07-17T16:54:30.880610836Z,160,2,1108,A,A,14.420000000,100,0,390153597,130,165642,323122334,ARL
2025-07-17T16:54:30.908753326Z,2025-07-17T16:54:30.908587894Z,160,2,1108,C,A,14.490000000,100,0,390136305,0,165432,323122430,ARL
2025-07-17T16:54:30.908753326Z,2025-07-17T16:54:30.908587894Z,160,2,1108,A,A,14.650000000,100,0,390153953,130,165432,323122430,ARL
2025-07-17T16:54:30.982814000Z,2025-07-17T16:54:30.982648521Z,160,2,1108,C,B,11.580000000,100,0,390136769,0,165479,323123335,ARL
2025-07-17T16:54:30.982814000Z,2025-07-17T16:54:30.982648521Z,160,2,1108,A,B,12.220000000,100,0,390155937,130,165479,323123335,ARL
2025-07-17T16:54:30.989780924Z,2025-07-17T16:54:30.989615198Z,160,2,1108,C,B,11.580000000,100,0,390136757,0,165726,323123542,ARL
2025-07-17T16:54:30.989780924Z,2025-07-17T16:54:30.989615198Z,160,2,1108,A,B,12.220000000,100,0,390156205,130,165726,323123542,ARL
2025-07-17T16:54:33.001989064Z,2025-07-17T16:54:33.001823770Z,160,2,1108,A,B,13.100000000,10,0,390188869,130,165294,323145588,ARL
2025-07-17T16:54:36.495007453Z,2025-07-17T16:54:36.494842320Z,160,2,1108,A,A,13.450000000,10,0,390244445,130,165133,323190336,ARL
2025-07-17T16:54:39.639406363Z,2025-07-17T16:54:39.639240088Z,160,2,1108,C,B,13.100000000,10,0,390188869,128,166275,323229343,ARL
2025-07-17T16:54:39.640542054Z,2025-07-17T16:54:39.640376331Z,160,2,1108,C,B,12.220000000,100,0,390155937,0,165723,323229401,ARL
2025-07-17T16:54:39.640542054Z,2025-07-17T16:54:39.640376331Z,160,2,1108,A,B,11.630000000,100,0,390290997,130,165723,323229401,ARL
2025-07-17T16:54:39.641217887Z,2025-07-17T16:54:39.641052077Z,160,2,1108,C,B,12.220000000,100,0,390156205,0,165810,323229423,ARL
2025-07-17T16:54:39.641217887Z,2025-07-17T16:54:39.641052077Z,160,2,1108,A,B,11.630000000,100,0,390291089,130,165810,323229423,ARL
2025-07-17T16:54:39.742646883Z,2025-07-17T16:54:39.742481344Z,160,2,1108,C,A,13.870000000,100,0,390137561,0,165539,323233034,ARL
2025-07-17T16:54:39.742646883Z,2025-07-17T16:54:39.742481344Z,160,2,1108,A,A,13.460000000,100,0,390297413,130,165539,323233034,ARL
2025-07-17T16:54:39.743012285Z,2025-07-17T16:54:39.742847022Z,160,2,1108,A,A,15.940000000,100,0,390297493,130,165263,323233061,ARL
2025-07-17T16:54:39.743025349Z,2025-07-17T16:54:39.742860026Z,160,2,1108,C,A,15.630000000,100,0,390136261,130,165323,323233062,ARL
2025-07-17T16:54:39.743385774Z,2025-07-17T16:54:39.743220634Z,160,2,1108,C,A,14.480000000,100,0,390141957,130,165140,323233082,ARL
2025-07-17T16:54:39.743389705Z,2025-07-17T16:54:39.743224193Z,160,2,1108,C,A,14.930000000,100,0,390136969,0,165512,323233083,ARL
2025-07-17T16:54:39.743389705Z,2025-07-17T16:54:39.743224193Z,160,2,1108,A,A,14.500000000,100,0,390297517,130,165512,323233083,ARL
2025-07-17T16:54:39.743738072Z,2025-07-17T16:54:39.743571651Z,160,2,1108,A,A,14.060000000,100,0,390297545,128,166421,323233099,ARL
2025-07-17T16:54:39.744715135Z,2025-07-17T16:54:39.744549174Z,160,2,1108,C,A,15.250000000,100,0,390136825,0,165961,323233171,ARL
2025-07-17T16:54:39.744715135Z,2025-07-17T16:54:39.744549174Z,160,2,1108,A,A,14.810000000,100,0,390297569,130,165961,323233171,ARL
2025-07-17T16:54:39.745240987Z,2025-07-17T16:54:39.745075591Z,160,2,1108,C,A,14.840000000,100,0,390136789,0,165396,323233188,ARL
2025-07-17T16:54:39.745240987Z,2025-07-17T16:54:39.745075591Z,160,2,1108,A,A,14.410000000,100,0,390297581,130,165396,323233188,ARL
2025-07-17T16:54:39.746884273Z,2025-07-17T16:54:39.746718759Z,160,2,1108,C,A,14.140000000,100,0,390136953,130,165514,323233222,ARL
2025-07-17T16:54:39.746935980Z,2025-07-17T16:54:39.746770470Z,160,2,1108,A,A,13.730000000,100,0,390297625,130,165510,323233223,ARL
2025-07-17T16:54:39.749620468Z,2025-07-17T16:54:39.749455133Z,160,2,1108,A,B,12.490000000,2,0,390297773,130,165335,323233314,ARL
2025-07-17T16:54:39.749622469Z,2025-07-17T16:54:39.749457160Z,160,2,1108,A,A,13.460000000,2,0,390297777,130,165309,323233315,ARL
2025-07-17T16:54:39.754500422Z,2025-07-17T16:54:39.754335032Z,160,2,1108,C,A,14.650000000,100,0,390153953,130,165390,323233438,ARL
2025-07-17T16:54:39.754606898Z,2025-07-17T16:54:39.754439857Z,160,2,1108,C,A,17.610000000,100,0,390136773,0,167041,323233439,ARL
2025-07-17T16:54:39.754606898Z,2025-07-17T16:54:39.754439857Z,160,2,1108,A,A,17.100000000,100,0,390297945,128,167041,323233439,ARL
2025-07-17T16:54:39.754653581Z,2025-07-17T16:54:39.754488276Z,160,2,1108,A,A,14.240000000,100,0,390297949,130,165305,323233451,ARL
2025-07-17T16:54:39.759107859Z,2025-07-17T16:54:39.758942531Z,160,2,1108,C,A,15.940000000,100,0,390136793,0,165328,323233505,ARL
2025-07-17T16:54:39.759107859Z,2025-07-17T16:54:39.758942531Z,160,2,1108,A,A,15.480000000,100,0,390298037,130,165328,323233505,ARL
2025-07-17T16:54:39.784844144Z,2025-07-17T16:54:39.784678842Z,160,2,1108,A,A,15.350000000,100,0,390299429,130,165302,323234260,ARL
2025-07-17T16:54:39.784856295Z,2025-07-17T16:54:39.784691310Z,160,2,1108,C,A,15.940000000,100,0,390297493,130,164985,323234261,ARL
2025-07-17T16:54:39.813482651Z,2025-07-17T16:54:39.813316981Z,160,2,1108,C,A,15.250000000,100,0,390136829,0,165670,323234493,ARL
2025-07-17T16:54:39.813482651Z,2025-07-17T16:54:39.813316981Z,160,2,1108,A,A,14.810000000,100,0,390299625,130,165670,323234493,ARL
2025-07-17T16:54:39.856355410Z,2025-07-17T16:54:39.856189932Z,160,2,1108,C,A,14.840000000,100,0,390136797,0,165478,323234881,ARL
2025-07-17T16:54:39.856355410Z,2025-07-17T16:54:39.856189932Z,160,2,1108,A,A,14.410000000,100,0,390300213,130,165478,323234881,ARL
2025-07-17T16:54:39.925866692Z,2025-07-17T16:54:39.925701041Z,160,2,1108,A,A,14.260000000,100,0,390301509,130,165651,323235398,ARL
2025-07-17T16:54:39.925879693Z,2025-07-17T16:54:39.925713639Z,160,2,1108,C,A,14.690000000,100,0,390146033,130,166054,323235399,ARL
2025-07-17T16:54:40.360234631Z,2025-07-17T16:54:40.360069276Z,160,2,1108,A,A,13.990000000,100,0,390315289,130,165355,323249703,ARL
2025-07-17T16:54:40.360236874Z,2025-07-17T16:54:40.360071501Z,160,2,1108,C,A,14.420000000,100,0,390153597,130,165373,323249704,ARL
2025-07-17T16:54:40.658024243Z,2025-07-17T16:54:40.657858797Z,160,2,1108,C,B,11.630000000,100,0,390291089,0,165446,323252340,ARL
2025-07-17T16:54:40.658024243Z,2025-07-17T16:54:40.657858797Z,160,2,1108,A,B,12.220000000,100,0,390318665,130,165446,323252340,ARL
2025-07-17T16:54:40.672485315Z,2025-07-17T16:54:40.672319951Z,160,2,1108,C,B,11.630000000,100,0,390290997,0,165364,323252412,ARL
2025-07-17T16:54:40.672485315Z,2025-07-17T16:54:40.672319951Z,160,2,1108,A,B,12.220000000,100,0,390318917,130,165364,323252412,ARL
2025-07-17T16:54:48.636736618Z,2025-07-17T16:54:48.636571204Z,160,2,1108,A,A,14.140000000,700,0,390418545,130,165414,323339823,ARL
2025-07-17T16:54:48.636800010Z,2025-07-17T16:54:48.636634294Z,160,2,1108,C,A,14.560000000,700,0,390137005,130,165716,323339824,ARL
2025-07-17T16:55:18.860988102Z,2025-07-17T16:55:18.860820293Z,160,2,1108,C,A,13.450000000,10,0,390244445,128,167809,323792027,ARL
2025-07-17T17:10:10.001059089Z,2025-07-17T17:10:10.000893422Z,160,2,1108,C,A,13.460000000,2,0,390297777,0,165667,336433579,ARL
2025-07-17T17:10:10.001059089Z,2025-07-17T17:10:10.000893422Z,160,2,1108,A,A,13.440000000,2,0,407450073,130,165667,336433579,ARL
2025-07-17T17:10:10.361937776Z,2025-07-17T17:10:10.361772221Z,160,2,1108,C,A,13.460000000,100,0,390297413,0,165555,336439763,ARL
2025-07-17T17:10:10.361937776Z,2025-07-17T17:10:10.361772221Z,160,2,1108,A,A,13.450000000,100,0,407456589,130,165555,336439763,ARL
2025-07-17T17:10:43.029824820Z,2025-07-17T17:10:43.029659505Z,160,2,1108,C,A,13.450000000,100,0,407456589,130,165315,336947991,ARL
2025-07-17T17:10:43.031554443Z,2025-07-17T17:10:43.031388893Z,160,2,1108,A,A,13.740000000,100,0,408122037,130,165550,336948067,ARL
2025-07-17T17:14:42.264143177Z,2025-07-17T17:14:42.263977687Z,160,2,1108,A,A,13.440000000,4,0,412198129,130,165490,340033053,ARL
2025-07-17T17:24:42.260903989Z,2025-07-17T17:24:42.260738507Z,160,2,1108,C,A,13.440000000,4,0,412198129,130,165482,347925516,ARL
2025-07-17T17:24:42.261927302Z,2025-07-17T17:24:42.261761757Z,160,2,1108,C,A,13.740000000,100,0,408122037,0,165545,347925524,ARL
2025-07-17T17:24:42.261927302Z,2025-07-17T17:24:42.261761757Z,160,2,1108,A,A,13.450000000,100,0,422564177,130,165545,347925524,ARL
2025-07-17T17:24:42.262972478Z,2025-07-17T17:24:42.262806771Z,160,2,1108,C,B,12.220000000,100,0,390318917,0,165707,347925526,ARL
2025-07-17T17:24:42.262972478Z,2025-07-17T17:24:42.262806771Z,160,2,1108,A,B,11.620000000,100,0,422564185,130,165707,347925526,ARL
2025-07-17T17:24:42.262988045Z,2025-07-17T17:24:42.262822690Z,160,2,1108,C,B,12.220000000,100,0,390318665,0,165355,347925527,ARL
2025-07-17T17:24:42.262988045Z,2025-07-17T17:24:42.262822690Z,160,2,1108,A,B,11.620000000,100,0,422564189,130,165355,347925527,ARL
2025-07-17T17:24:42.548192960Z,2025-07-17T17:24:42.548027809Z,160,2,1108,C,A,13.450000000,100,0,422564177,130,165151,347929285,ARL
2025-07-17T17:24:42.549558183Z,2025-07-17T17:24:42.549392732Z,160,2,1108,A,A,13.740000000,100,0,422568905,130,165451,347929289,ARL
2025-07-17T17:56:30.441933915Z,2025-07-17T17:56:30.441768063Z,160,2,1108,A,A,13.430000000,10,0,457191725,130,165852,374792938,ARL
2025-07-17T17:56:30.636865513Z,2025-07-17T17:56:30.636700055Z,160,2,1108,C,A,13.740000000,100,0,422568905,0,165458,374794445,ARL
2025-07-17T17:56:30.636865513Z,2025-07-17T17:56:30.636700055Z,160,2,1108,A,A,13.450000000,100,0,457194033,130,165458,374794445,ARL
2025-07-17T17:57:00.747584752Z,2025-07-17T17:57:00.747417750Z,160,2,1108,C,B,11.620000000,100,0,422564189,0,167002,375114806,ARL
2025-07-17T17:57:00.747584752Z,2025-07-17T17:57:00.747417750Z,160,2,1108,A,B,12.050000000,100,0,457630209,130,167002,375114806,ARL
2025-07-17T17:57:00.748337392Z,2025-07-17T17:57:00.748171838Z,160,2,1108,C,B,11.620000000,100,0,422564185,0,165554,375114814,ARL
2025-07-17T17:57:00.748337392Z,2025-07-17T17:57:00.748171838Z,160,2,1108,A,B,12.050000000,100,0,457630269,130,165554,375114814,ARL
2025-07-17T18:02:45.504739085Z,2025-07-17T18:02:45.504573741Z,160,2,1108,A,A,13.370000000,1,0,464268809,130,165344,380174467,ARL
2025-07-17T18:02:45.511694258Z,2025-07-17T18:02:45.511528908Z,160,2,1108,A,A,13.370000000,10,0,464268845,130,165350,380174502,ARL
2025-07-17T18:02:45.604734847Z,2025-07-17T18:02:45.604569852Z,160,2,1108,C,A,13.370000000,1,0,464268809,130,164995,380175836,ARL
2025-07-17T18:02:45.758454022Z,2025-07-17T18:02:45.758288837Z,160,2,1108,A,B,12.480000000,19,0,464272409,130,165185,380177351,ARL
2025-07-17T18:03:28.675050388Z,2025-07-17T18:03:28.674884242Z,160,2,1108,C,A,13.370000000,10,0,464268845,130,166146,380875617,ARL
2025-07-17T18:03:28.675199309Z,2025-07-17T18:03:28.675033913Z,160,2,1108,C,A,13.430000000,10,0,457191725,130,165396,380875662,ARL
2025-07-17T18:03:37.156866249Z,2025-07-17T18:03:37.156700909Z,160,2,1108,A,A,13.430000000,10,0,465436101,130,165340,381033247,ARL
2025-07-17T18:03:39.024629946Z,2025-07-17T18:03:39.024464975Z,160,2,1108,C,A,13.430000000,10,0,465436101,130,164971,381055717,ARL
2025-07-17T18:03:45.510588660Z,2025-07-17T18:03:45.510423349Z,160,2,1108,A,A,13.430000000,10,0,465595785,130,165311,381155408,ARL
2025-07-17T18:03:55.373928938Z,2025-07-17T18:03:55.373753982Z,160,2,1108,C,A,13.430000000,10,0,465595785,128,174956,381294591,ARL
2025-07-17T18:04:03.102086582Z,2025-07-17T18:04:03.101919454Z,160,2,1108,A,A,13.430000000,10,0,465889901,128,167128,381395570,ARL
2025-07-17T18:04:45.575324272Z,2025-07-17T18:04:45.575158670Z,160,2,1108,A,A,13.430000000,10,0,466717245,130,165602,382020181,ARL
2025-07-17T18:08:14.760470941Z,2025-07-17T18:08:14.760305571Z,160,2,1108,C,B,12.480000000,19,0,464272409,130,165370,384965197,ARL
2025-07-17T18:19:43.054723566Z,2025-07-17T18:19:43.054558147Z,160,2,1108,C,A,13.430000000,10,0,465889901,130,165419,394283063,ARL
2025-07-17T18:19:47.055415026Z,2025-07-17T18:19:47.055249706Z,160,2,1108,A,A,13.430000000,10,0,482798553,130,165320,394326337,ARL
2025-07-17T18:19:50.478462852Z,2025-07-17T18:19:50.478297341Z,160,2,1108,C,B,12.050000000,100,0,457630209,0,165511,394363038,ARL
2025-07-17T18:19:50.478462852Z,2025-07-17T18:19:50.478297341Z,160,2,1108,A,B,11.630000000,100,0,482850641,130,165511,394363038,ARL
2025-07-17T18:19:50.478570601Z,2025-07-17T18:19:50.478404811Z,160,2,1108,C,B,12.050000000,100,0,457630269,0,165790,394363039,ARL
2025-07-17T18:19:50.478570601Z,2025-07-17T18:19:50.478404811Z,160,2,1108,A,B,11.630000000,100,0,482850645,130,165790,394363039,ARL
2025-07-17T18:19:50.488099752Z,2025-07-17T18:19:50.487934498Z,160,2,1108,C,A,13.450000000,100,0,457194033,130,165254,394363891,ARL
2025-07-17T18:19:50.492385521Z,2025-07-17T18:19:50.492220295Z,160,2,1108,A,A,13.740000000,100,0,482851573,130,165226,394364230,ARL
2025-07-17T18:19:50.980695881Z,2025-07-17T18:19:50.980530549Z,160,2,1108,C,A,13.740000000,100,0,482851573,0,165332,394370279,ARL
2025-07-17T18:19:50.980695881Z,2025-07-17T18:19:50.980530549Z,160,2,1108,A,A,13.450000000,100,0,482863949,130,165332,394370279,ARL
2025-07-17T18:20:07.054959298Z,2025-07-17T18:20:07.054794050Z,160,2,1108,C,A,13.430000000,10,0,482798553,130,165248,394619081,ARL
2025-07-17T18:20:13.055283148Z,2025-07-17T18:20:13.055117687Z,160,2,1108,A,A,13.430000000,10,0,483298361,130,165461,394709628,ARL
2025-07-17T18:20:18.734022977Z,2025-07-17T18:20:18.733857768Z,160,2,1108,C,A,13.430000000,10,0,483298361,130,165209,394792459,ARL
2025-07-17T18:20:31.890395248Z,2025-07-17T18:20:31.890228636Z,160,2,1108,A,A,13.430000000,10,0,483612169,130,166612,394964577,ARL
2025-07-17T18:21:34.342741611Z,2025-07-17T18:21:34.342574608Z,160,2,1108,C,B,12.490000000,2,0,390297773,0,167003,395825259,ARL
2025-07-17T18:21:34.342741611Z,2025-07-17T18:21:34.342574608Z,160,2,1108,A,B,12.370000000,2,0,484764453,130,167003,395825259,ARL
2025-07-17T18:21:41.375354733Z,2025-07-17T18:21:41.375189503Z,160,2,1108,C,A,13.430000000,10,0,483612169,130,165230,395912308,ARL
2025-07-17T18:21:42.510128472Z,2025-07-17T18:21:42.509963215Z,160,2,1108,A,A,13.430000000,10,0,484908201,130,165257,395938501,ARL
2025-07-17T18:21:43.021576447Z,2025-07-17T18:21:43.021411133Z,160,2,1108,C,A,13.430000000,10,0,484908201,130,165314,395964087,ARL
2025-07-17T18:21:52.394224735Z,2025-07-17T18:21:52.394059116Z,160,2,1108,C,A,13.440000000,2,0,407450073,0,165619,396204170,ARL
2025-07-17T18:21:52.394224735Z,2025-07-17T18:21:52.394059116Z,160,2,1108,A,A,13.560000000,2,0,485232841,130,165619,396204170,ARL
2025-07-17T18:21:55.669306871Z,2025-07-17T18:21:55.669141274Z,160,2,1108,C,A,13.450000000,100,0,482863949,0,165597,396249515,ARL
2025-07-17T18:21:55.669306871Z,2025-07-17T18:21:55.669141274Z,160,2,1108,A,A,13.440000000,100,0,485292661,130,165597,396249515,ARL
2025-07-17T18:21:55.669907127Z,2025-07-17T18:21:55.669742041Z,160,2,1108,A,A,13.740000000,4,0,485292677,130,165086,396249524,ARL
2025-07-17T18:22:01.058672261Z,2025-07-17T18:22:01.058506892Z,160,2,1108,A,A,13.430000000,10,0,485391097,130,165369,396320334,ARL
2025-07-17T18:22:13.436009303Z,2025-07-17T18:22:13.435844247Z,160,2,1108,C,A,13.430000000,10,0,485391097,130,165056,396492898,ARL
2025-07-17T18:22:39.061005340Z,2025-07-17T18:22:39.060839850Z,160,2,1108,A,A,13.430000000,10,0,486051129,130,165490,396801846,ARL
2025-07-17T18:24:02.569506205Z,2025-07-17T18:24:02.569341036Z,160,2,1108,C,A,13.430000000,10,0,486051129,130,165169,397768837,ARL
2025-07-17T18:24:05.242654617Z,2025-07-17T18:24:05.242489364Z,160,2,1108,A,A,13.430000000,10,0,487432113,130,165253,397805897,ARL
2025-07-17T18:24:20.247148147Z,2025-07-17T18:24:20.246982063Z,160,2,1108,C,A,13.430000000,10,0,487432113,130,166084,398013865,ARL
2025-07-17T18:25:00.146207682Z,2025-07-17T18:25:00.146030189Z,160,2,1108,A,A,13.430000000,10,0,488547681,128,177493,398730846,ARL
2025-07-17T18:25:04.834942456Z,2025-07-17T18:25:04.834777122Z,160,2,1108,C,A,13.430000000,10,0,488547681,130,165334,398832320,ARL
2025-07-17T18:25:13.234099945Z,2025-07-17T18:25:13.233934332Z,160,2,1108,A,A,13.430000000,10,0,488839225,130,165613,398973618,ARL
2025-07-17T18:25:32.715413506Z,2025-07-17T18:25:32.715248018Z,160,2,1108,C,B,11.630000000,100,0,482850641,0,165488,399247257,ARL
2025-07-17T18:25:32.715413506Z,2025-07-17T18:25:32.715248018Z,160,2,1108,A,B,11.760000000,100,0,489200865,130,165488,399247257,ARL
2025-07-17T18:25:32.715881242Z,2025-07-17T18:25:32.715715815Z,160,2,1108,C,B,11.630000000,100,0,482850645,0,165427,399247258,ARL
2025-07-17T18:25:32.715881242Z,2025-07-17T18:25:32.715715815Z,160,2,1108,A,B,11.760000000,100,0,489200877,130,165427,399247258,ARL
2025-07-17T18:28:52.016789656Z,2025-07-17T18:28:52.016623464Z,160,2,1108,C,A,13.430000000,10,0,488839225,130,166192,401929725,ARL
2025-07-17T18:28:53.050862274Z,2025-07-17T18:28:53.050696982Z,160,2,1108,A,A,13.430000000,10,0,492865077,130,165292,401946425,ARL
2025-07-17T18:29:05.900359009Z,2025-07-17T18:29:05.900193653Z,160,2,1108,A,A,13.300000000,10,0,493143705,130,165356,402134637,ARL
2025-07-17T18:29:05.901318308Z,2025-07-17T18:29:05.901152755Z,160,2,1108,C,A,14.330000000,100,0,390136777,0,165553,402134673,ARL
2025-07-17T18:29:05.901318308Z,2025-07-17T18:29:05.901152755Z,160,2,1108,A,A,14.170000000,100,0,493143725,130,165553,402134673,ARL
2025-07-17T18:29:05.901425622Z,2025-07-17T18:29:05.901260136Z,160,2,1108,C,A,14.330000000,100,0,390136761,0,165486,402134675,ARL
2025-07-17T18:29:05.901425622Z,2025-07-17T18:29:05.901260136Z,160,2,1108,A,A,14.170000000,100,0,493143729,130,165486,402134675,ARL
2025-07-17T18:29:07.048337783Z,2025-07-17T18:29:07.048172403Z,160,2,1108,C,A,13.440000000,100,0,485292661,0,165380,402152978,ARL
2025-07-17T18:29:07.048337783Z,2025-07-17T18:29:07.048172403Z,160,2,1108,A,A,13.310000000,100,0,493167357,130,165380,402152978,ARL
2025-07-17T18:29:07.048957249Z,2025-07-17T18:29:07.048789564Z,160,2,1108,C,A,13.740000000,4,0,485292677,128,167685,402153113,ARL
2025-07-17T18:29:07.049092359Z,2025-07-17T18:29:07.048926898Z,160,2,1108,C,A,14.500000000,100,0,390297517,0,165461,402153140,ARL
2025-07-17T18:29:07.049092359Z,2025-07-17T18:29:07.048926898Z,160,2,1108,A,A,14.340000000,100,0,493167417,130,165461,402153140,ARL
2025-07-17T18:29:07.050780257Z,2025-07-17T18:29:07.050614876Z,160,2,1108,C,A,14.410000000,100,0,390297581,0,165381,402153246,ARL
2025-07-17T18:29:07.050780257Z,2025-07-17T18:29:07.050614876Z,160,2,1108,A,A,14.250000000,100,0,493167485,130,165381,402153246,ARL
2025-07-17T18:29:07.052744488Z,2025-07-17T18:29:07.052579008Z,160,2,1108,C,A,14.240000000,100,0,390297949,0,165480,402153285,ARL
2025-07-17T18:29:07.052744488Z,2025-07-17T18:29:07.052579008Z,160,2,1108,A,A,14.080000000,100,0,493167537,130,165480,402153285,ARL
2025-07-17T18:29:07.052875300Z,2025-07-17T18:29:07.052710067Z,160,2,1108,C,A,13.730000000,100,0,390297625,130,165233,402153289,ARL
2025-07-17T18:29:07.052926505Z,2025-07-17T18:29:07.052761169Z,160,2,1108,A,A,13.580000000,100,0,493167549,130,165336,402153290,ARL
2025-07-17T18:29:07.058686154Z,2025-07-17T18:29:07.058520437Z,160,2,1108,C,A,17.100000000,100,0,390297945,0,165717,402153437,ARL
2025-07-17T18:29:07.058686154Z,2025-07-17T18:29:07.058520437Z,160,2,1108,A,A,16.910000000,100,0,493167733,130,165717,402153437,ARL
2025-07-17T18:29:07.062682712Z,2025-07-17T18:29:07.062517136Z,160,2,1108,C,A,15.480000000,100,0,390298037,0,165576,402153485,ARL
2025-07-17T18:29:07.062682712Z,2025-07-17T18:29:07.062517136Z,160,2,1108,A,A,15.310000000,100,0,493167781,130,165576,402153485,ARL
2025-07-17T18:29:07.106359697Z,2025-07-17T18:29:07.106194024Z,160,2,1108,C,A,14.410000000,100,0,390300213,0,165673,402153910,ARL
2025-07-17T18:29:07.106359697Z,2025-07-17T18:29:07.106194024Z,160,2,1108,A,A,14.250000000,100,0,493168277,130,165673,402153910,ARL
2025-07-17T18:29:14.583446623Z,2025-07-17T18:29:14.583281105Z,160,2,1108,A,A,14.050000000,700,0,493307877,130,165518,402256375,ARL
2025-07-17T18:29:14.583507908Z,2025-07-17T18:29:14.583342445Z,160,2,1108,C,A,14.470000000,700,0,390136253,130,165463,402256376,ARL
2025-07-17T18:29:16.360892047Z,2025-07-17T18:29:16.360726793Z,160,2,1108,A,A,14.010000000,700,0,493339833,130,165254,402282246,ARL
2025-07-17T18:29:16.361287920Z,2025-07-17T18:29:16.361122639Z,160,2,1108,C,A,14.430000000,700,0,390136281,130,165281,402282272,ARL
2025-07-17T18:29:25.628887304Z,2025-07-17T18:29:25.628721986Z,160,2,1108,C,A,13.430000000,10,0,492865077,130,165318,402397381,ARL
2025-07-17T18:29:37.071516765Z,2025-07-17T18:29:37.071351468Z,160,2,1108,A,A,13.200000000,10,0,493669961,130,165297,402520424,ARL
2025-07-17T18:29:46.924107233Z,2025-07-17T18:29:46.923941765Z,160,2,1108,C,A,13.560000000,2,0,485232841,0,165468,402615919,ARL
2025-07-17T18:29:46.924107233Z,2025-07-17T18:29:46.923941765Z,160,2,1108,A,A,13.460000000,2,0,493814817,130,165468,402615919,ARL
2025-07-17T18:30:00.004314404Z,2025-07-17T18:30:00.004148859Z,160,2,1108,C,A,13.310000000,100,0,493167357,0,165545,402798184,ARL
2025-07-17T18:30:00.004314404Z,2025-07-17T18:30:00.004148859Z,160,2,1108,A,A,13.210000000,100,0,494070601,130,165545,402798184,ARL
2025-07-17T18:30:00.004383969Z,2025-07-17T18:30:00.004218225Z,160,2,1108,C,A,17.150000000,100,0,43339133,0,165744,402798189,ARL
2025-07-17T18:30:00.004383969Z,2025-07-17T18:30:00.004218225Z,160,2,1108,A,A,16.900000000,100,0,494070617,130,165744,402798189,ARL
2025-07-17T18:30:00.004384822Z,2025-07-17T18:30:00.004219314Z,160,2,1108,C,A,17.150000000,100,0,43339165,0,165508,402798190,ARL
2025-07-17T18:30:00.004384822Z,2025-07-17T18:30:00.004219314Z,160,2,1108,A,A,16.900000000,100,0,494070621,130,165508,402798190,ARL
2025-07-17T18:30:00.004388046Z,2025-07-17T18:30:00.004220547Z,160,2,1108,C,A,17.150000000,100,0,43339333,0,167499,402798191,ARL
2025-07-17T18:30:00.004388046Z,2025-07-17T18:30:00.004220547Z,160,2,1108,A,A,16.900000000,100,0,494070625,0,167499,402798191,ARL
2025-07-17T18:30:00.004388046Z,2025-07-17T18:30:00.004220918Z,160,2,1108,C,A,17.150000000,100,0,43339337,0,167128,402798192,ARL
2025-07-17T18:30:00.004388046Z,2025-07-17T18:30:00.004220918Z,160,2,1108,A,A,16.900000000,100,0,494070629,128,167128,402798192,ARL
2025-07-17T18:30:00.004390361Z,2025-07-17T18:30:00.004222645Z,160,2,1108,C,A,17.150000000,100,0,43339341,0,167716,402798194,ARL
2025-07-17T18:30:00.004390361Z,2025-07-17T18:30:00.004222645Z,160,2,1108,A,A,16.900000000,100,0,494070633,0,167716,402798194,ARL
2025-07-17T18:30:00.004390361Z,2025-07-17T18:30:00.004223030Z,160,2,1108,C,A,17.150000000,100,0,43339377,0,167331,402798195,ARL
2025-07-17T18:30:00.004390361Z,2025-07-17T18:30:00.004223030Z,160,2,1108,A,A,16.900000000,100,0,494070637,0,167331,402798195,ARL
2025-07-17T18:30:00.004390361Z,2025-07-17T18:30:00.004223446Z,160,2,1108,C,A,17.150000000,100,0,43339381,0,166915,402798196,ARL
2025-07-17T18:30:00.004390361Z,2025-07-17T18:30:00.004223446Z,160,2,1108,A,A,16.900000000,100,0,494070641,130,166915,402798196,ARL
2025-07-17T18:30:00.004391009Z,2025-07-17T18:30:00.004224840Z,160,2,1108,C,A,17.150000000,100,0,43339385,0,166169,402798197,ARL
2025-07-17T18:30:00.004391009Z,2025-07-17T18:30:00.004224840Z,160,2,1108,A,A,16.900000000,100,0,494070645,130,166169,402798197,ARL
2025-07-17T18:30:00.004392464Z,2025-07-17T18:30:00.004225976Z,160,2,1108,C,A,17.150000000,100,0,43339565,0,166488,402798198,ARL
2025-07-17T18:30:00.004392464Z,2025-07-17T18:30:00.004225976Z,160,2,1108,A,A,16.900000000,100,0,494070649,0,166488,402798198,ARL
2025-07-17T18:30:00.004392464Z,2025-07-17T18:30:00.004226430Z,160,2,1108,C,A,17.150000000,100,0,43690825,0,166034,402798199,ARL
2025-07-17T18:30:00.004392464Z,2025-07-17T18:30:00.004226430Z,160,2,1108,A,A,16.900000000,100,0,494070653,130,166034,402798199,ARL
2025-07-17T18:30:00.004395186Z,2025-07-17T18:30:00.004227709Z,160,2,1108,C,A,17.150000000,100,0,43690829,0,167477,402798200,ARL
2025-07-17T18:30:00.004395186Z,2025-07-17T18:30:00.004227709Z,160,2,1108,A,A,16.900000000,100,0,494070657,0,167477,402798200,ARL
2025-07-17T18:30:00.004395186Z,2025-07-17T18:30:00.004228080Z,160,2,1108,C,A,17.150000000,100,0,43690833,0,167106,402798201,ARL
2025-07-17T18:30:00.004395186Z,2025-07-17T18:30:00.004228080Z,160,2,1108,A,A,16.900000000,100,0,494070661,0,167106,402798201,ARL
2025-07-17T18:30:00.004395186Z,2025-07-17T18:30:00.004228499Z,160,2,1108,C,A,17.150000000,100,0,43690837,0,166687,402798202,ARL
2025-07-17T18:30:00.004395186Z,2025-07-17T18:30:00.004228499Z,160,2,1108,A,A,16.900000000,100,0,494070665,130,166687,402798202,ARL
2025-07-17T18:30:00.004395999Z,2025-07-17T18:30:00.004229790Z,160,2,1108,C,A,17.150000000,100,0,43690841,0,166209,402798203,ARL
2025-07-17T18:30:00.004395999Z,2025-07-17T18:30:00.004229790Z,160,2,1108,A,A,16.900000000,100,0,494070669,130,166209,402798203,ARL
2025-07-17T18:30:00.004398034Z,2025-07-17T18:30:00.004231172Z,160,2,1108,C,A,17.150000000,100,0,43690845,0,166862,402798204,ARL
2025-07-17T18:30:00.004398034Z,2025-07-17T18:30:00.004231172Z,160,2,1108,A,A,16.900000000,100,0,494070673,0,166862,402798204,ARL
2025-07-17T18:30:00.004398034Z,2025-07-17T18:30:00.004231693Z,160,2,1108,C,A,17.150000000,100,0,43690849,0,166341,402798205,ARL
2025-07-17T18:30:00.004398034Z,2025-07-17T18:30:00.004231693Z,160,2,1108,A,A,16.900000000,100,0,494070677,130,166341,402798205,ARL
2025-07-17T18:30:00.004399744Z,2025-07-17T18:30:00.004233080Z,160,2,1108,C,A,17.150000000,100,0,44040361,0,166664,402798206,ARL
2025-07-17T18:30:00.004399744Z,2025-07-17T18:30:00.004233080Z,160,2,1108,A,A,16.900000000,100,0,494070681,130,166664,402798206,ARL
2025-07-17T18:30:00.005049199Z,2025-07-17T18:30:00.004883884Z,160,2,1108,A,A,13.560000000,4,0,494070737,130,165315,402798221,ARL
2025-07-17T18:30:00.005057480Z,2025-07-17T18:30:00.004892105Z,160,2,1108,C,A,14.340000000,100,0,493167417,0,165375,402798223,ARL
2025-07-17T18:30:00.005057480Z,2025-07-17T18:30:00.004892105Z,160,2,1108,A,A,14.240000000,100,0,494070741,130,165375,402798223,ARL
2025-07-17T18:30:00.005058719Z,2025-07-17T18:30:00.004893301Z,160,2,1108,C,A,14.060000000,100,0,390297545,130,165418,402798224,ARL
2025-07-17T18:30:00.005420940Z,2025-07-17T18:30:00.005255746Z,160,2,1108,A,A,13.800000000,100,0,494070769,130,165194,402798245,ARL
2025-07-17T18:30:00.015369605Z,2025-07-17T18:30:00.015204140Z,160,2,1108,C,A,14.810000000,100,0,390297569,0,165465,402798846,ARL
2025-07-17T18:30:00.015369605Z,2025-07-17T18:30:00.015204140Z,160,2,1108,A,A,14.540000000,100,0,494071325,130,165465,402798846,ARL
2025-07-17T18:30:00.016602712Z,2025-07-17T18:30:00.016437088Z,160,2,1108,C,A,13.580000000,100,0,493167549,130,165624,402798886,ARL
2025-07-17T18:30:00.038506062Z,2025-07-17T18:30:00.038340826Z,160,2,1108,A,A,13.470000000,100,0,494073757,130,165236,402800533,ARL
2025-07-17T18:30:00.038624416Z,2025-07-17T18:30:00.038459261Z,160,2,1108,A,A,15.060000000,100,0,494073769,130,165155,402800542,ARL
2025-07-17T18:30:00.038637498Z,2025-07-17T18:30:00.038472119Z,160,2,1108,C,A,15.350000000,100,0,390299429,130,165379,402800546,ARL
2025-07-17T18:30:00.090455227Z,2025-07-17T18:30:00.090289733Z,160,2,1108,C,A,14.810000000,100,0,390299625,0,165494,402804008,ARL
2025-07-17T18:30:00.090455227Z,2025-07-17T18:30:00.090289733Z,160,2,1108,A,A,14.540000000,100,0,494077585,130,165494,402804008,ARL
2025-07-17T18:30:03.400215422Z,2025-07-17T18:30:03.400049725Z,160,2,1108,C,B,9.550000000,100,0,43314177,130,165697,402859373,ARL
2025-07-17T18:30:03.400291717Z,2025-07-17T18:30:03.400126143Z,160,2,1108,C,A,16.900000000,100,0,494070649,130,165574,402859375,ARL
2025-07-17T18:30:03.401748751Z,2025-07-17T18:30:03.401583195Z,160,2,1108,A,B,8.990000000,100,0,494159689,130,165556,402859387,ARL
2025-07-17T18:30:03.401794522Z,2025-07-17T18:30:03.401629489Z,160,2,1108,A,A,16.900000000,100,0,494159697,130,165033,402859388,ARL
2025-07-17T18:30:47.524904943Z,2025-07-17T18:30:47.524738400Z,160,2,1108,C,A,13.200000000,10,0,493669961,130,166543,403534811,ARL
2025-07-17T18:30:59.074653918Z,2025-07-17T18:30:59.074488718Z,160,2,1108,A,A,13.200000000,10,0,495283297,130,165200,403703774,ARL
2025-07-17T18:31:15.693499146Z,2025-07-17T18:31:15.693333658Z,160,2,1108,C,A,13.210000000,100,0,494070601,130,165488,403953391,ARL
2025-07-17T18:31:15.694090868Z,2025-07-17T18:31:15.693925475Z,160,2,1108,A,A,13.430000000,300,0,495591097,130,165393,403953392,ARL
2025-07-17T18:31:15.694235510Z,2025-07-17T18:31:15.694069813Z,160,2,1108,C,A,14.240000000,100,0,494070741,0,165697,403953394,ARL
2025-07-17T18:31:15.694235510Z,2025-07-17T18:31:15.694069813Z,160,2,1108,A,A,14.290000000,100,0,495591101,130,165697,403953394,ARL
2025-07-17T18:31:15.694241952Z,2025-07-17T18:31:15.694076678Z,160,2,1108,C,A,13.800000000,100,0,494070769,130,165274,403953395,ARL
2025-07-17T18:31:15.694566895Z,2025-07-17T18:31:15.694401607Z,160,2,1108,C,A,13.560000000,4,0,494070737,130,165288,403953402,ARL
2025-07-17T18:31:15.694577814Z,2025-07-17T18:31:15.694412257Z,160,2,1108,A,A,13.440000000,100,0,495591105,130,165557,403953403,ARL
2025-07-17T18:31:15.694597207Z,2025-07-17T18:31:15.694432003Z,160,2,1108,A,A,14.030000000,100,0,495591109,130,165204,403953404,ARL
2025-07-17T18:31:15.694937938Z,2025-07-17T18:31:15.694772399Z,160,2,1108,C,A,15.310000000,100,0,493167781,0,165539,403953407,ARL
2025-07-17T18:31:15.694937938Z,2025-07-17T18:31:15.694772399Z,160,2,1108,A,A,15.450000000,100,0,495591113,130,165539,403953407,ARL
2025-07-17T18:31:15.694962777Z,2025-07-17T18:31:15.694796501Z,160,2,1108,C,A,16.910000000,100,0,493167733,0,166276,403953409,ARL
2025-07-17T18:31:15.694962777Z,2025-07-17T18:31:15.694796501Z,160,2,1108,A,A,17.060000000,100,0,495591117,130,166276,403953409,ARL
2025-07-17T18:31:15.699991540Z,2025-07-17T18:31:15.699826170Z,160,2,1108,C,A,13.470000000,100,0,494073757,130,165370,403953423,ARL
2025-07-17T18:31:15.700042490Z,2025-07-17T18:31:15.699877151Z,160,2,1108,A,A,13.700000000,100,0,495591161,130,165339,403953424,ARL
2025-07-17T18:31:15.744351727Z,2025-07-17T18:31:15.744186262Z,160,2,1108,C,A,14.290000000,100,0,495591101,0,165465,403953590,ARL
2025-07-17T18:31:15.744351727Z,2025-07-17T18:31:15.744186262Z,160,2,1108,A,A,14.470000000,100,0,495591413,130,165465,403953590,ARL
2025-07-17T18:31:15.744605625Z,2025-07-17T18:31:15.744440169Z,160,2,1108,C,A,13.440000000,100,0,495591105,0,165456,403953592,ARL
2025-07-17T18:31:15.744605625Z,2025-07-17T18:31:15.744440169Z,160,2,1108,A,A,13.310000000,100,0,495591421,130,165456,403953592,ARL
2025-07-17T18:31:15.747121051Z,2025-07-17T18:31:15.746955664Z,160,2,1108,C,A,15.450000000,100,0,495591113,0,165387,403953595,ARL
2025-07-17T18:31:15.747121051Z,2025-07-17T18:31:15.746955664Z,160,2,1108,A,A,15.310000000,100,0,495591449,130,165387,403953595,ARL
2025-07-17T18:31:15.747559043Z,2025-07-17T18:31:15.747393703Z,160,2,1108,C,A,17.060000000,100,0,495591117,0,165340,403953596,ARL
2025-07-17T18:31:15.747559043Z,2025-07-17T18:31:15.747393703Z,160,2,1108,A,A,16.910000000,100,0,495591453,130,165340,403953596,ARL
2025-07-17T18:31:15.762170180Z,2025-07-17T18:31:15.762005166Z,160,2,1108,C,A,13.700000000,100,0,495591161,130,165014,403953648,ARL
2025-07-17T18:31:15.762218148Z,2025-07-17T18:31:15.762052983Z,160,2,1108,A,A,13.580000000,100,0,495591557,130,165165,403953649,ARL
2025-07-17T18:31:15.794000859Z,2025-07-17T18:31:15.793835808Z,160,2,1108,C,A,13.430000000,300,0,495591097,130,165051,403953841,ARL
2025-07-17T18:31:15.794387146Z,2025-07-17T18:31:15.794221241Z,160,2,1108,C,A,14.470000000,100,0,495591413,0,165905,403953845,ARL
2025-07-17T18:31:15.794387146Z,2025-07-17T18:31:15.794221241Z,160,2,1108,A,A,14.340000000,100,0,495591797,130,165905,403953845,ARL
2025-07-17T18:31:38.260181170Z,2025-07-17T18:31:38.260015387Z,160,2,1108,C,A,13.310000000,100,0,495591421,0,165783,404322642,ARL
2025-07-17T18:31:38.260181170Z,2025-07-17T18:31:38.260015387Z,160,2,1108,A,A,13.210000000,100,0,496049113,130,165783,404322642,ARL
2025-07-17T18:31:38.260922373Z,2025-07-17T18:31:38.260756978Z,160,2,1108,C,A,14.030000000,100,0,495591109,130,165395,404322646,ARL
2025-07-17T18:31:38.260939675Z,2025-07-17T18:31:38.260773946Z,160,2,1108,C,A,14.340000000,100,0,495591797,0,165729,404322647,ARL
2025-07-17T18:31:38.260939675Z,2025-07-17T18:31:38.260773946Z,160,2,1108,A,A,14.240000000,100,0,496049141,130,165729,404322647,ARL
2025-07-17T18:31:38.261286335Z,2025-07-17T18:31:38.261120988Z,160,2,1108,A,A,13.800000000,100,0,496049157,130,165347,404322651,ARL
2025-07-17T18:31:38.282291461Z,2025-07-17T18:31:38.282126121Z,160,2,1108,C,A,13.580000000,100,0,495591557,130,165340,404323270,ARL
2025-07-17T18:31:38.282341585Z,2025-07-17T18:31:38.282176392Z,160,2,1108,A,A,13.470000000,100,0,496049717,130,165193,404323275,ARL
2025-07-17T18:33:10.293333589Z,2025-07-17T18:33:10.293168017Z,160,2,1108,C,A,13.460000000,2,0,493814817,0,165572,405729195,ARL
2025-07-17T18:33:10.293333589Z,2025-07-17T18:33:10.293168017Z,160,2,1108,A,A,13.360000000,2,0,497826957,130,165572,405729195,ARL
2025-07-17T18:42:38.188411696Z,2025-07-17T18:42:38.188245549Z,160,2,1108,C,A,13.200000000,10,0,495283297,130,166147,412912499,ARL
2025-07-17T18:42:51.095971497Z,2025-07-17T18:42:51.095805585Z,160,2,1108,A,A,13.200000000,10,0,507825893,130,165912,413090740,ARL
2025-07-17T18:47:44.409582857Z,2025-07-17T18:47:44.409417489Z,160,2,1108,C,A,13.210000000,100,0,496049113,130,165368,416595696,ARL
2025-07-17T18:47:44.410204684Z,2025-07-17T18:47:44.410039297Z,160,2,1108,A,A,13.430000000,300,0,512646381,130,165387,416595714,ARL
2025-07-17T18:47:44.410328844Z,2025-07-17T18:47:44.410163484Z,160,2,1108,C,A,13.800000000,100,0,496049157,130,165360,416595715,ARL
2025-07-17T18:47:44.410346205Z,2025-07-17T18:47:44.410180669Z,160,2,1108,C,A,14.240000000,100,0,496049141,0,165536,416595716,ARL
2025-07-17T18:47:44.410346205Z,2025-07-17T18:47:44.410180669Z,160,2,1108,A,A,14.290000000,100,0,512646389,130,165536,416595716,ARL
2025-07-17T18:47:44.410653145Z,2025-07-17T18:47:44.410487597Z,160,2,1108,A,A,13.370000000,100,0,512646401,130,165548,416595724,ARL
2025-07-17T18:47:44.410685592Z,2025-07-17T18:47:44.410520514Z,160,2,1108,A,A,14.030000000,100,0,512646409,130,165078,416595727,ARL
2025-07-17T18:47:44.411522301Z,2025-07-17T18:47:44.411356681Z,160,2,1108,C,A,16.910000000,100,0,495591453,0,165620,416595742,ARL
2025-07-17T18:47:44.411522301Z,2025-07-17T18:47:44.411356681Z,160,2,1108,A,A,17.060000000,100,0,512646445,130,165620,416595742,ARL
2025-07-17T18:47:44.415058824Z,2025-07-17T18:47:44.414893347Z,160,2,1108,C,A,13.470000000,100,0,496049717,130,165477,416595818,ARL
2025-07-17T18:47:44.415109917Z,2025-07-17T18:47:44.414944605Z,160,2,1108,A,A,13.700000000,100,0,512646529,130,165312,416595819,ARL
2025-07-17T18:47:44.460469362Z,2025-07-17T18:47:44.460303600Z,160,2,1108,C,A,14.290000000,100,0,512646389,0,165762,416596241,ARL
2025-07-17T18:47:44.460469362Z,2025-07-17T18:47:44.460303600Z,160,2,1108,A,A,14.410000000,100,0,512647193,130,165762,416596241,ARL
2025-07-17T18:47:44.460727003Z,2025-07-17T18:47:44.460561500Z,160,2,1108,C,A,13.370000000,100,0,512646401,0,165503,416596245,ARL
2025-07-17T18:47:44.460727003Z,2025-07-17T18:47:44.460561500Z,160,2,1108,A,A,13.310000000,100,0,512647197,130,165503,416596245,ARL
2025-07-17T18:47:44.461933027Z,2025-07-17T18:47:44.461767460Z,160,2,1108,C,A,17.060000000,100,0,512646445,0,165567,416596252,ARL
2025-07-17T18:47:44.461933027Z,2025-07-17T18:47:44.461767460Z,160,2,1108,A,A,16.910000000,100,0,512647217,130,165567,416596252,ARL
2025-07-17T18:47:44.473102240Z,2025-07-17T18:47:44.472937055Z,160,2,1108,C,A,13.700000000,100,0,512646529,130,165185,416596348,ARL
2025-07-17T18:47:44.473152616Z,2025-07-17T18:47:44.472987065Z,160,2,1108,A,A,13.580000000,100,0,512647317,130,165551,416596351,ARL
2025-07-17T18:47:44.510118477Z,2025-07-17T18:47:44.509953470Z,160,2,1108,C,A,13.430000000,300,0,512646381,130,165007,416597259,ARL
2025-07-17T18:47:44.510509007Z,2025-07-17T18:47:44.510343645Z,160,2,1108,C,A,14.410000000,100,0,512647193,0,165362,416597264,ARL
2025-07-17T18:47:44.510509007Z,2025-07-17T18:47:44.510343645Z,160,2,1108,A,A,14.340000000,100,0,512648081,130,165362,416597264,ARL
2025-07-17T18:47:46.003887443Z,2025-07-17T18:47:46.003722156Z,160,2,1108,C,A,13.200000000,10,0,507825893,130,165287,416619928,ARL
2025-07-17T18:48:18.518511578Z,2025-07-17T18:48:18.518346148Z,160,2,1108,A,A,13.200000000,10,0,513368973,130,165430,417114155,ARL
2025-07-17T18:48:22.752417429Z,2025-07-17T18:48:22.752250033Z,160,2,1108,C,A,13.310000000,100,0,512647197,0,167396,417170969,ARL
2025-07-17T18:48:22.752417429Z,2025-07-17T18:48:22.752250033Z,160,2,1108,A,A,13.210000000,100,0,513444357,128,167396,417170969,ARL
2025-07-17T18:48:22.753158699Z,2025-07-17T18:48:22.752993351Z,160,2,1108,C,A,14.030000000,100,0,512646409,130,165348,417170991,ARL
2025-07-17T18:48:22.753167918Z,2025-07-17T18:48:22.753002486Z,160,2,1108,C,A,14.340000000,100,0,512648081,0,165432,417170992,ARL
2025-07-17T18:48:22.753167918Z,2025-07-17T18:48:22.753002486Z,160,2,1108,A,A,14.240000000,100,0,513444417,130,165432,417170992,ARL
2025-07-17T18:48:22.753512614Z,2025-07-17T18:48:22.753347230Z,160,2,1108,A,A,13.800000000,100,0,513444445,130,165384,417170996,ARL
2025-07-17T18:48:22.760908654Z,2025-07-17T18:48:22.760743413Z,160,2,1108,C,A,13.580000000,100,0,512647317,130,165241,417171054,ARL
2025-07-17T18:48:22.760958801Z,2025-07-17T18:48:22.760792943Z,160,2,1108,A,A,13.470000000,100,0,513444541,130,165858,417171055,ARL
2025-07-17T18:48:32.006619874Z,2025-07-17T18:48:32.006449877Z,160,2,1108,C,A,13.200000000,10,0,513368973,128,169997,417302677,ARL
2025-07-17T18:48:33.040665584Z,2025-07-17T18:48:33.040500129Z,160,2,1108,A,A,13.200000000,10,0,513666941,130,165455,417334278,ARL
2025-07-17T18:54:52.580759012Z,2025-07-17T18:54:52.580591801Z,160,2,1108,C,A,13.200000000,10,0,513666941,130,167211,422382187,ARL
2025-07-17T18:54:52.599266356Z,2025-07-17T18:54:52.599100960Z,160,2,1108,C,A,13.300000000,10,0,493143705,130,165396,422384976,ARL
2025-07-17T18:55:23.117987032Z,2025-07-17T18:55:23.117820595Z,160,2,1108,A,A,13.200000000,10,0,521140661,130,166437,422794447,ARL
2025-07-17T18:55:27.117927800Z,2025-07-17T18:55:27.117762741Z,160,2,1108,C,A,13.200000000,10,0,521140661,130,165059,422859047,ARL
2025-07-17T18:55:33.117961853Z,2025-07-17T18:55:33.117796133Z,160,2,1108,A,A,13.200000000,10,0,521320541,130,165720,422923576,ARL
2025-07-17T18:56:11.119737796Z,2025-07-17T18:56:11.119572528Z,160,2,1108,C,A,13.200000000,10,0,521320541,130,165268,423716324,ARL
2025-07-17T18:56:22.613739715Z,2025-07-17T18:56:22.613573157Z,160,2,1108,A,A,13.200000000,10,0,522522877,128,166558,423872398,ARL
2025-07-17T18:57:24.765203181Z,2025-07-17T18:57:24.765037036Z,160,2,1108,C,A,13.200000000,10,0,522522877,128,166145,424631076,ARL
2025-07-17T18:57:26.699126081Z,2025-07-17T18:57:26.698960413Z,160,2,1108,A,A,13.200000000,10,0,523629125,130,165668,424654833,ARL
2025-07-17T18:57:29.121321130Z,2025-07-17T18:57:29.121156200Z,160,2,1108,C,A,13.200000000,10,0,523629125,130,164930,424685743,ARL
2025-07-17T18:57:37.122489958Z,2025-07-17T18:57:37.122322879Z,160,2,1108,A,A,13.200000000,10,0,523807409,130,167079,424777217,ARL
2025-07-17T18:57:51.122556353Z,2025-07-17T18:57:51.122390835Z,160,2,1108,C,A,13.200000000,10,0,523807409,130,165518,424936427,ARL
2025-07-17T18:58:19.123947091Z,2025-07-17T18:58:19.123780547Z,160,2,1108,A,A,13.200000000,10,0,524562765,130,166544,425305802,ARL
2025-07-17T19:00:11.127068758Z,2025-07-17T19:00:11.126903508Z,160,2,1108,C,A,13.200000000,10,0,524562765,130,165250,426882928,ARL
2025-07-17T19:00:15.127269145Z,2025-07-17T19:00:15.127103749Z,160,2,1108,A,A,13.200000000,10,0,526812109,130,165396,426940295,ARL
2025-07-17T19:00:41.126897519Z,2025-07-17T19:00:41.126732212Z,160,2,1108,C,A,13.200000000,10,0,526812109,130,165307,427390755,ARL
2025-07-17T19:00:45.127685234Z,2025-07-17T19:00:45.127520095Z,160,2,1108,A,A,13.200000000,15,0,527449669,130,165139,427449676,ARL
2025-07-17T19:01:15.127809761Z,2025-07-17T19:01:15.127644617Z,160,2,1108,C,A,13.200000000,15,0,527449669,130,165144,427952728,ARL
2025-07-17T19:01:25.128431402Z,2025-07-17T19:01:25.128266056Z,160,2,1108,A,A,13.200000000,15,0,528323525,130,165346,428129329,ARL
2025-07-17T19:01:29.127947553Z,2025-07-17T19:01:29.127781872Z,160,2,1108,C,A,13.200000000,15,0,528323525,130,165681,428202369,ARL
2025-07-17T19:01:41.129044513Z,2025-07-17T19:01:41.128877897Z,160,2,1108,A,A,13.200000000,15,0,528659397,130,166616,428387724,ARL
2025-07-17T19:02:20.273385873Z,2025-07-17T19:02:20.273220580Z,160,2,1108,C,A,13.200000000,15,0,528659397,130,165293,428975261,ARL
2025-07-17T19:02:47.131929826Z,2025-07-17T19:02:47.131763765Z,160,2,1108,A,A,13.200000000,20,0,529963793,130,166061,429403279,ARL
2025-07-17T19:03:07.231174636Z,2025-07-17T19:03:07.231009247Z,160,2,1108,C,A,13.210000000,100,0,513444357,130,165389,429695185,ARL
2025-07-17T19:03:07.231200759Z,2025-07-17T19:03:07.231035191Z,160,2,1108,C,A,13.200000000,20,0,529963793,130,165568,429695186,ARL
2025-07-17T19:03:07.231914680Z,2025-07-17T19:03:07.231749145Z,160,2,1108,C,A,13.800000000,100,0,513444445,130,165535,429695213,ARL
2025-07-17T19:03:07.231935082Z,2025-07-17T19:03:07.231769541Z,160,2,1108,C,A,14.240000000,100,0,513444417,0,165541,429695214,ARL
2025-07-17T19:03:07.231935082Z,2025-07-17T19:03:07.231769541Z,160,2,1108,A,A,14.290000000,100,0,530358565,130,165541,429695214,ARL
2025-07-17T19:03:07.232269781Z,2025-07-17T19:03:07.232104524Z,160,2,1108,A,A,14.030000000,100,0,530358577,130,165257,429695218,ARL
2025-07-17T19:03:07.232523664Z,2025-07-17T19:03:07.232358705Z,160,2,1108,A,A,13.370000000,100,0,530358593,130,164959,429695223,ARL
2025-07-17T19:03:07.233112380Z,2025-07-17T19:03:07.232947082Z,160,2,1108,A,A,13.670000000,4,0,530358621,130,165298,429695237,ARL
2025-07-17T19:03:07.235344283Z,2025-07-17T19:03:07.235178727Z,160,2,1108,C,A,13.470000000,100,0,513444541,130,165556,429695263,ARL
2025-07-17T19:03:07.235397241Z,2025-07-17T19:03:07.235232133Z,160,2,1108,A,A,13.700000000,100,0,530358641,130,165108,429695266,ARL
2025-07-17T19:03:07.282078868Z,2025-07-17T19:03:07.281913497Z,160,2,1108,C,A,14.290000000,100,0,530358565,0,165371,429695566,ARL
2025-07-17T19:03:07.282078868Z,2025-07-17T19:03:07.281913497Z,160,2,1108,A,A,14.410000000,100,0,530358997,130,165371,429695566,ARL
2025-07-17T19:03:08.232739283Z,2025-07-17T19:03:08.232573880Z,160,2,1108,A,A,13.200000000,20,0,530370329,130,165403,429707298,ARL
2025-07-17T19:03:23.022343604Z,2025-07-17T19:03:23.022174752Z,160,2,1108,C,A,13.200000000,20,0,530370329,128,168852,430007742,ARL
2025-07-17T19:03:24.035657950Z,2025-07-17T19:03:24.035491679Z,160,2,1108,A,A,13.200000000,20,0,530738113,128,166271,430039870,ARL
2025-07-17T19:03:33.073740113Z,2025-07-17T19:03:33.073574792Z,160,2,1108,C,A,13.200000000,20,0,530738113,130,165321,430200670,ARL
2025-07-17T19:03:35.132098334Z,2025-07-17T19:03:35.131933163Z,160,2,1108,A,A,13.200000000,20,0,530957373,130,165171,430223490,ARL
2025-07-17T19:03:50.939680746Z,2025-07-17T19:03:50.939515051Z,160,2,1108,C,A,13.370000000,100,0,530358593,0,165695,430428556,ARL
2025-07-17T19:03:50.939680746Z,2025-07-17T19:03:50.939515051Z,160,2,1108,A,A,13.210000000,100,0,531237357,130,165695,430428556,ARL
2025-07-17T19:03:50.940276496Z,2025-07-17T19:03:50.940111057Z,160,2,1108,C,A,13.670000000,4,0,530358621,130,165439,430428562,ARL
2025-07-17T19:03:50.940423310Z,2025-07-17T19:03:50.940257646Z,160,2,1108,C,A,14.410000000,100,0,530358997,0,165664,430428564,ARL
2025-07-17T19:03:50.940423310Z,2025-07-17T19:03:50.940257646Z,160,2,1108,A,A,14.240000000,100,0,531237397,130,165664,430428564,ARL
2025-07-17T19:03:50.940424372Z,2025-07-17T19:03:50.940258752Z,160,2,1108,C,A,14.030000000,100,0,530358577,130,165620,430428565,ARL
2025-07-17T19:03:50.940740403Z,2025-07-17T19:03:50.940574838Z,160,2,1108,A,A,13.560000000,4,0,531237401,130,165565,430428568,ARL
2025-07-17T19:03:50.940795719Z,2025-07-17T19:03:50.940630497Z,160,2,1108,A,A,13.800000000,100,0,531237405,130,165222,430428570,ARL
2025-07-17T19:03:50.958976162Z,2025-07-17T19:03:50.958810519Z,160,2,1108,C,A,13.700000000,100,0,530358641,130,165643,430428654,ARL
2025-07-17T19:03:50.959033578Z,2025-07-17T19:03:50.958868081Z,160,2,1108,A,A,13.470000000,100,0,531237541,130,165497,430428655,ARL
2025-07-17T19:05:00.005489933Z,2025-07-17T19:05:00.005324582Z,160,2,1108,C,A,13.210000000,100,0,531237357,130,165351,431494207,ARL
2025-07-17T19:05:00.006261507Z,2025-07-17T19:05:00.006092804Z,160,2,1108,C,A,14.240000000,100,0,531237397,0,168703,431494361,ARL
2025-07-17T19:05:00.006261507Z,2025-07-17T19:05:00.006092804Z,160,2,1108,A,A,14.290000000,100,0,532642717,128,168703,431494361,ARL
2025-07-17T19:05:00.006279306Z,2025-07-17T19:05:00.006114147Z,160,2,1108,C,A,13.800000000,100,0,531237405,130,165159,431494366,ARL
2025-07-17T19:05:00.006598992Z,2025-07-17T19:05:00.006430459Z,160,2,1108,A,A,13.370000000,100,0,532642849,130,168533,431494446,ARL
2025-07-17T19:05:00.006635058Z,2025-07-17T19:05:00.006469178Z,160,2,1108,A,A,14.030000000,100,0,532642873,130,165880,431494467,ARL
2025-07-17T19:05:00.020382587Z,2025-07-17T19:05:00.020216145Z,160,2,1108,C,A,13.470000000,100,0,531237541,128,166442,431496558,ARL
2025-07-17T19:05:00.033122308Z,2025-07-17T19:05:00.032957026Z,160,2,1108,A,A,13.700000000,100,0,532648605,130,165282,431499419,ARL
2025-07-17T19:05:00.056403412Z,2025-07-17T19:05:00.056237856Z,160,2,1108,C,A,14.290000000,100,0,532642717,0,165556,431500503,ARL
2025-07-17T19:05:00.056403412Z,2025-07-17T19:05:00.056237856Z,160,2,1108,A,A,14.410000000,100,0,532650157,130,165556,431500503,ARL
2025-07-17T19:06:17.158543851Z,2025-07-17T19:06:17.158374865Z,160,2,1108,C,A,13.200000000,20,0,530957373,128,168986,432681396,ARL
2025-07-17T19:06:19.729296427Z,2025-07-17T19:06:19.729130876Z,160,2,1108,A,A,13.200000000,20,0,534257581,130,165551,432714266,ARL
2025-07-17T19:06:21.135771224Z,2025-07-17T19:06:21.135605827Z,160,2,1108,C,A,13.200000000,20,0,534257581,130,165397,432732480,ARL
2025-07-17T19:06:29.624292153Z,2025-07-17T19:06:29.624126771Z,160,2,1108,A,B,12.900000000,6,0,534450577,130,165382,432852171,ARL
2025-07-17T19:06:29.624357993Z,2025-07-17T19:06:29.624192040Z,160,2,1108,T,N,12.925000000,6,0,0,130,165953,432852172,ARL
2025-07-17T19:06:29.624940376Z,2025-07-17T19:06:29.624774932Z,160,2,1108,C,A,13.430000000,10,0,466717245,130,165444,432852175,ARL
2025-07-17T19:06:29.626428061Z,2025-07-17T19:06:29.626262538Z,160,2,1108,A,A,13.360000000,10,0,534450593,130,165523,432852181,ARL
2025-07-17T19:06:43.240659845Z,2025-07-17T19:06:43.240494223Z,160,2,1108,C,B,12.370000000,2,0,484764453,0,165622,433017098,ARL
2025-07-17T19:06:43.240659845Z,2025-07-17T19:06:43.240494223Z,160,2,1108,A,B,12.460000000,2,0,534686481,130,165622,433017098,ARL
