ts_recv,ts_event,rtype,publisher_id,instrument_id,action,side,price,size,channel_id,order_id,flags,ts_in_delta,sequence,symbol
2025-07-17T07:05:09.035793433Z,2025-07-17T07:05:09.035627674Z,160,2,1108,R,N,,0,0,0,8,0,0,ARL
2025-07-17T08:05:03.360842448Z,2025-07-17T08:05:03.360677248Z,160,2,1108,A,B,5.510000000,100,0,817593,130,165200,851012,ARL
2025-07-17T08:05:03.360848793Z,2025-07-17T08:05:03.360683462Z,160,2,1108,A,A,21.330000000,100,0,817597,130,165331,851013,ARL
2025-07-17T08:05:03.361492517Z,2025-07-17T08:05:03.361327319Z,160,2,1108,A,B,5.900000000,100,0,817633,130,165198,851022,ARL
2025-07-17T08:05:03.361497823Z,2025-07-17T08:05:03.361332576Z,160,2,1108,A,A,20.940000000,100,0,817637,130,165247,851023,ARL
2025-07-17T08:09:48.860862095Z,2025-07-17T08:09:48.860696464Z,160,2,1108,C,B,5.510000000,100,0,817593,130,165631,1289631,ARL
2025-07-17T08:09:48.860870885Z,2025-07-17T08:09:48.860705588Z,160,2,1108,A,B,5.370000000,100,0,1263973,130,165297,1289632,ARL
2025-07-17T08:09:49.158061899Z,2025-07-17T08:09:49.157896784Z,160,2,1108,C,B,5.900000000,100,0,817633,130,165115,1290626,ARL
2025-07-17T08:09:49.158069452Z,2025-07-17T08:09:49.157903443Z,160,2,1108,A,B,5.400000000,100,0,1264721,0,166009,1290627,ARL
2025-07-17T08:09:49.158069452Z,2025-07-17T08:09:49.157903798Z,160,2,1108,C,A,20.940000000,100,0,817637,130,165654,1290628,ARL
2025-07-17T08:09:49.158074599Z,2025-07-17T08:09:49.157909054Z,160,2,1108,A,A,21.470000000,100,0,1264725,130,165545,1290629,ARL
2025-07-17T11:00:00.125340914Z,2025-07-17T11:00:00.125174985Z,160,2,1108,C,B,5.370000000,100,0,1263973,130,165929,10583317,ARL
2025-07-17T11:00:00.125347247Z,2025-07-17T11:00:00.125182048Z,160,2,1108,A,B,9.790000000,100,0,12852457,130,165199,10583320,ARL
2025-07-17T11:00:00.125619742Z,2025-07-17T11:00:00.125454029Z,160,2,1108,C,B,5.400000000,100,0,1264721,130,165713,10583363,ARL
2025-07-17T11:00:00.125626050Z,2025-07-17T11:00:00.125460962Z,160,2,1108,A,B,9.840000000,100,0,12852537,130,165088,10583364,ARL
2025-07-17T11:00:07.975990221Z,2025-07-17T11:00:07.975824831Z,160,2,1108,C,A,21.330000000,100,0,817597,130,165390,10674471,ARL
2025-07-17T11:00:07.976003383Z,2025-07-17T11:00:07.975837956Z,160,2,1108,A,A,17.440000000,100,0,12983425,130,165427,10674472,ARL
2025-07-17T11:00:07.976138102Z,2025-07-17T11:00:07.975972618Z,160,2,1108,C,A,21.470000000,100,0,1264725,130,165484,10674473,ARL
2025-07-17T11:00:07.976144724Z,2025-07-17T11:00:07.975979367Z,160,2,1108,A,A,17.360000000,100,0,12983429,130,165357,10674474,ARL
2025-07-17T11:00:08.255140498Z,2025-07-17T11:00:08.254975294Z,160,2,1108,C,A,17.440000000,100,0,12983425,130,165204,10676310,ARL
2025-07-17T11:00:08.255150459Z,2025-07-17T11:00:08.254985173Z,160,2,1108,A,A,18.920000000,100,0,12985397,130,165286,10676311,ARL
2025-07-17T11:00:08.255312226Z,2025-07-17T11:00:08.255147130Z,160,2,1108,C,A,17.360000000,100,0,12983429,130,165096,10676314,ARL
2025-07-17T11:00:08.255320414Z,2025-07-17T11:00:08.255155317Z,160,2,1108,A,A,18.840000000,100,0,12985401,130,165097,10676315,ARL
2025-07-17T11:00:08.256027692Z,2025-07-17T11:00:08.255862656Z,160,2,1108,C,A,18.920000000,100,0,12985397,130,165036,10676320,ARL
2025-07-17T11:00:08.256037075Z,2025-07-17T11:00:08.255871843Z,160,2,1108,A,A,20.620000000,100,0,12985405,130,165232,10676321,ARL
2025-07-17T11:00:08.256333906Z,2025-07-17T11:00:08.256168895Z,160,2,1108,C,A,18.840000000,100,0,12985401,130,165011,10676324,ARL
2025-07-17T11:00:08.256340615Z,2025-07-17T11:00:08.256175346Z,160,2,1108,A,A,20.530000000,100,0,12985413,130,165269,10676325,ARL
2025-07-17T11:00:08.257050282Z,2025-07-17T11:00:08.256885010Z,160,2,1108,C,A,20.620000000,100,0,12985405,130,165272,10676333,ARL
2025-07-17T11:00:08.257058070Z,2025-07-17T11:00:08.256892686Z,160,2,1108,A,A,21.470000000,100,0,12985417,130,165384,10676334,ARL
2025-07-17T11:00:08.257234812Z,2025-07-17T11:00:08.257069458Z,160,2,1108,C,A,20.530000000,100,0,12985413,130,165354,10676335,ARL
2025-07-17T11:00:08.257241334Z,2025-07-17T11:00:08.257076085Z,160,2,1108,A,A,21.470000000,100,0,12985421,130,165249,10676336,ARL
2025-07-17T11:01:05.260586668Z,2025-07-17T11:01:05.260421351Z,160,2,1108,C,A,21.470000000,100,0,12985417,130,165317,10824633,ARL
2025-07-17T11:01:05.260611137Z,2025-07-17T11:01:05.260445703Z,160,2,1108,A,A,17.440000000,100,0,13174157,130,165434,10824634,ARL
2025-07-17T11:01:05.260858436Z,2025-07-17T11:01:05.260693130Z,160,2,1108,C,A,21.470000000,100,0,12985421,130,165306,10824635,ARL
2025-07-17T11:01:05.260874630Z,2025-07-17T11:01:05.260709480Z,160,2,1108,A,A,17.360000000,100,0,13174161,130,165150,10824636,ARL
2025-07-17T11:56:26.691626843Z,2025-07-17T11:56:26.691461161Z,160,2,1108,C,B,9.790000000,100,0,12852457,130,165682,14213017,ARL
2025-07-17T11:56:26.691630539Z,2025-07-17T11:56:26.691465204Z,160,2,1108,C,A,17.440000000,100,0,13174157,130,165335,14213018,ARL
2025-07-17T11:56:26.694933250Z,2025-07-17T11:56:26.694767820Z,160,2,1108,A,B,9.790000000,100,0,19202569,130,165430,14213075,ARL
2025-07-17T11:56:26.694937361Z,2025-07-17T11:56:26.694772016Z,160,2,1108,A,A,17.440000000,100,0,19202573,130,165345,14213076,ARL
2025-07-17T11:56:30.446102409Z,2025-07-17T11:56:30.445937099Z,160,2,1108,C,A,17.440000000,100,0,19202573,130,165310,14219824,ARL
2025-07-17T11:56:30.446117449Z,2025-07-17T11:56:30.445951937Z,160,2,1108,A,A,17.930000000,100,0,19218909,130,165512,14219825,ARL
2025-07-17T11:56:30.446231965Z,2025-07-17T11:56:30.446066952Z,160,2,1108,C,A,17.930000000,100,0,19218909,130,165013,14219826,ARL
2025-07-17T11:56:30.446250148Z,2025-07-17T11:56:30.446084801Z,160,2,1108,A,A,17.440000000,100,0,19218913,130,165347,14219827,ARL
2025-07-17T11:56:30.446357192Z,2025-07-17T11:56:30.446191769Z,160,2,1108,C,A,17.360000000,100,0,13174161,130,165423,14219828,ARL
2025-07-17T11:56:30.446379036Z,2025-07-17T11:56:30.446213519Z,160,2,1108,A,A,17.850000000,100,0,19218917,130,165517,14219829,ARL
2025-07-17T11:56:30.446543637Z,2025-07-17T11:56:30.446378732Z,160,2,1108,C,A,17.850000000,100,0,19218917,130,164905,14219830,ARL
2025-07-17T11:56:30.446723646Z,2025-07-17T11:56:30.446558412Z,160,2,1108,A,A,17.360000000,100,0,19218921,130,165234,14219831,ARL
2025-07-17T11:57:30.222987797Z,2025-07-17T11:57:30.222822537Z,160,2,1108,C,B,9.840000000,100,0,12852537,130,165260,14325877,ARL
2025-07-17T11:57:30.222988778Z,2025-07-17T11:57:30.222823580Z,160,2,1108,C,A,17.360000000,100,0,19218921,130,165198,14325878,ARL
2025-07-17T11:57:30.224151967Z,2025-07-17T11:57:30.223986626Z,160,2,1108,A,B,9.840000000,100,0,19346173,130,165341,14325937,ARL
2025-07-17T11:57:30.224156146Z,2025-07-17T11:57:30.223991040Z,160,2,1108,A,A,17.360000000,100,0,19346177,130,165106,14325938,ARL
2025-07-17T12:30:01.318008785Z,2025-07-17T12:30:01.317842911Z,160,2,1108,A,A,20.480000000,100,0,23570297,130,165874,16864046,ARL
2025-07-17T12:30:03.426465857Z,2025-07-17T12:30:03.426300621Z,160,2,1108,A,B,7.740000000,100,0,23616197,130,165236,16882670,ARL
2025-07-17T12:30:03.426466862Z,2025-07-17T12:30:03.426301523Z,160,2,1108,A,A,20.480000000,100,0,23616201,130,165339,16882671,ARL
2025-07-17T12:30:03.604699168Z,2025-07-17T12:30:03.604533925Z,160,2,1108,A,B,7.740000000,100,0,23622101,130,165243,16886020,ARL
2025-07-17T12:30:51.178394233Z,2025-07-17T12:30:51.178228608Z,160,2,1108,A,A,20.480000000,100,0,24099409,130,165625,17120703,ARL
2025-07-17T12:30:51.643125167Z,2025-07-17T12:30:51.642959794Z,160,2,1108,A,B,7.740000000,100,0,24102329,130,165373,17122998,ARL
2025-07-17T13:15:00.032611736Z,2025-07-17T13:15:00.032446132Z,160,2,1108,C,A,17.440000000,100,0,19218913,130,165604,23080007,ARL
2025-07-17T13:15:00.032651211Z,2025-07-17T13:15:00.032483824Z,160,2,1108,C,B,9.790000000,100,0,19202569,128,167387,23080041,ARL
2025-07-17T13:15:00.058480238Z,2025-07-17T13:15:00.058314138Z,160,2,1108,C,A,17.360000000,100,0,19346177,128,166100,23101369,ARL
2025-07-17T13:15:00.058537384Z,2025-07-17T13:15:00.058371545Z,160,2,1108,C,B,9.840000000,100,0,19346173,130,165839,23101396,ARL
2025-07-17T13:15:01.925239044Z,2025-07-17T13:15:01.925073727Z,160,2,1108,A,B,7.740000000,100,0,31960841,130,165317,23123943,ARL
2025-07-17T13:15:02.042906947Z,2025-07-17T13:15:02.042741730Z,160,2,1108,A,A,20.480000000,100,0,31962113,130,165217,23124563,ARL
2025-07-17T13:17:49.831329888Z,2025-07-17T13:17:49.831164624Z,160,2,1108,A,B,7.740000000,100,0,33574717,130,165264,23465434,ARL
2025-07-17T13:17:49.831709365Z,2025-07-17T13:17:49.831544051Z,160,2,1108,A,A,20.480000000,100,0,33574725,130,165314,23465435,ARL
2025-07-17T13:19:57.597368321Z,2025-07-17T13:19:57.597203040Z,160,2,1108,A,B,8.740000000,100,0,34790041,130,165281,23710201,ARL
2025-07-17T13:19:57.597456270Z,2025-07-17T13:19:57.597291053Z,160,2,1108,A,A,18.350000000,100,0,34790045,130,165217,23710202,ARL
2025-07-17T13:19:58.492785060Z,2025-07-17T13:19:58.492619751Z,160,2,1108,A,A,18.240000000,100,0,34810233,130,165309,23728432,ARL
2025-07-17T13:19:58.492799826Z,2025-07-17T13:19:58.492634480Z,160,2,1108,A,B,9.240000000,100,0,34810241,130,165346,23728435,ARL
2025-07-17T13:20:00.525430361Z,2025-07-17T13:20:00.525263842Z,160,2,1108,C,A,18.240000000,100,0,34810233,0,166519,23765825,ARL
2025-07-17T13:20:00.525430361Z,2025-07-17T13:20:00.525264700Z,160,2,1108,C,B,9.240000000,100,0,34810241,130,165661,23765826,ARL
2025-07-17T13:25:00.157632223Z,2025-07-17T13:25:00.157467184Z,160,2,1108,C,B,8.740000000,100,0,34790041,130,165039,24448205,ARL
2025-07-17T13:25:00.157638512Z,2025-07-17T13:25:00.157473422Z,160,2,1108,C,A,18.350000000,100,0,34790045,130,165090,24448207,ARL
2025-07-17T13:25:01.732485386Z,2025-07-17T13:25:01.732320109Z,160,2,1108,A,B,7.740000000,100,0,38041417,130,165277,24478872,ARL
2025-07-17T13:25:01.819447960Z,2025-07-17T13:25:01.819282823Z,160,2,1108,A,A,20.480000000,100,0,38043741,130,165137,24480276,ARL
2025-07-17T13:28:08.192080463Z,2025-07-17T13:28:08.191915168Z,160,2,1108,A,B,7.740000000,100,0,40617777,130,165295,25597187,ARL
2025-07-17T13:28:08.192147601Z,2025-07-17T13:28:08.191982270Z,160,2,1108,A,A,20.480000000,100,0,40617785,130,165331,25597189,ARL
2025-07-17T13:28:21.011414592Z,2025-07-17T13:28:21.011249114Z,160,2,1108,A,A,18.320000000,700,0,40846101,130,165478,25907820,ARL
2025-07-17T13:28:21.029030365Z,2025-07-17T13:28:21.028865155Z,160,2,1108,A,B,9.290000000,700,0,40851989,130,165210,25917006,ARL
2025-07-17T13:28:30.048895468Z,2025-07-17T13:28:30.048730211Z,160,2,1108,A,B,9.670000000,100,0,40999441,130,165257,26140646,ARL
2025-07-17T13:28:30.048907452Z,2025-07-17T13:28:30.048741690Z,160,2,1108,A,A,17.600000000,100,0,40999449,130,165762,26140658,ARL
2025-07-17T13:28:30.052061798Z,2025-07-17T13:28:30.051894007Z,160,2,1108,A,B,9.990000000,100,0,41000165,130,167791,26142104,ARL
2025-07-17T13:28:30.052072568Z,2025-07-17T13:28:30.051907073Z,160,2,1108,A,A,17.120000000,100,0,41000173,130,165495,26142118,ARL
2025-07-17T13:28:30.257018844Z,2025-07-17T13:28:30.256853564Z,160,2,1108,A,B,9.670000000,100,0,41021369,130,165280,26170917,ARL
2025-07-17T13:28:30.257031156Z,2025-07-17T13:28:30.256865858Z,160,2,1108,A,A,17.600000000,100,0,41021373,130,165298,26170918,ARL
2025-07-17T13:28:30.277622346Z,2025-07-17T13:28:30.277457031Z,160,2,1108,A,B,9.990000000,100,0,41021837,130,165315,26171531,ARL
2025-07-17T13:28:30.277635645Z,2025-07-17T13:28:30.277470320Z,160,2,1108,A,A,17.120000000,100,0,41021841,130,165325,26171533,ARL
2025-07-17T13:28:30.613482667Z,2025-07-17T13:28:30.613317490Z,160,2,1108,A,B,9.130000000,100,0,41032049,130,165177,26182390,ARL
2025-07-17T13:28:30.613495057Z,2025-07-17T13:28:30.613329849Z,160,2,1108,A,A,18.400000000,100,0,41032057,130,165208,26182393,ARL
2025-07-17T13:28:41.476876547Z,2025-07-17T13:28:41.476711173Z,160,2,1108,A,B,7.840000000,100,0,41306441,130,165374,26518296,ARL
2025-07-17T13:28:41.476887975Z,2025-07-17T13:28:41.476722715Z,160,2,1108,A,A,20.320000000,100,0,41306445,130,165260,26518297,ARL
2025-07-17T13:28:46.014904874Z,2025-07-17T13:28:46.014739305Z,160,2,1108,A,A,15.300000000,100,0,41370837,130,165569,26613800,ARL
2025-07-17T13:28:46.014968000Z,2025-07-17T13:28:46.014802018Z,160,2,1108,C,A,20.480000000,100,0,23570297,0,165982,26613836,ARL
2025-07-17T13:28:46.014968000Z,2025-07-17T13:28:46.014802018Z,160,2,1108,A,A,19.580000000,100,0,41370945,130,165982,26613836,ARL
2025-07-17T13:28:46.014969135Z,2025-07-17T13:28:46.014803011Z,160,2,1108,C,A,20.480000000,100,0,23616201,0,166124,26613837,ARL
2025-07-17T13:28:46.014969135Z,2025-07-17T13:28:46.014803011Z,160,2,1108,A,A,19.580000000,100,0,41370949,130,166124,26613837,ARL
2025-07-17T13:28:46.014970699Z,2025-07-17T13:28:46.014804158Z,160,2,1108,C,A,20.480000000,100,0,24099409,0,166541,26613838,ARL
2025-07-17T13:28:46.014970699Z,2025-07-17T13:28:46.014804158Z,160,2,1108,A,A,19.580000000,100,0,41370953,0,166541,26613838,ARL
2025-07-17T13:28:46.014970699Z,2025-07-17T13:28:46.014804564Z,160,2,1108,C,A,20.480000000,100,0,31962113,0,166135,26613839,ARL
2025-07-17T13:28:46.014970699Z,2025-07-17T13:28:46.014804564Z,160,2,1108,A,A,19.580000000,100,0,41370957,130,166135,26613839,ARL
2025-07-17T13:28:46.014972151Z,2025-07-17T13:28:46.014805680Z,160,2,1108,C,A,20.480000000,100,0,33574725,0,166471,26613840,ARL
2025-07-17T13:28:46.014972151Z,2025-07-17T13:28:46.014805680Z,160,2,1108,A,A,19.580000000,100,0,41370961,0,166471,26613840,ARL
2025-07-17T13:28:46.014972151Z,2025-07-17T13:28:46.014805841Z,160,2,1108,C,A,20.480000000,100,0,38043741,0,166310,26613841,ARL
2025-07-17T13:28:46.014972151Z,2025-07-17T13:28:46.014805841Z,160,2,1108,A,A,19.580000000,100,0,41370965,130,166310,26613841,ARL
2025-07-17T13:28:46.014973343Z,2025-07-17T13:28:46.014807086Z,160,2,1108,C,A,20.480000000,100,0,40617785,0,166257,26613842,ARL
2025-07-17T13:28:46.014973343Z,2025-07-17T13:28:46.014807086Z,160,2,1108,A,A,19.580000000,100,0,41370969,130,166257,26613842,ARL
2025-07-17T13:28:46.015690361Z,2025-07-17T13:28:46.015523291Z,160,2,1108,A,B,10.180000000,700,0,41371221,130,167070,26614152,ARL
2025-07-17T13:28:46.015691617Z,2025-07-17T13:28:46.015525315Z,160,2,1108,A,A,16.110000000,700,0,41371225,130,166302,26614155,ARL
2025-07-17T13:28:46.017375168Z,2025-07-17T13:28:46.017209641Z,160,2,1108,C,A,17.120000000,100,0,41000173,0,165527,26614961,ARL
2025-07-17T13:28:46.017375168Z,2025-07-17T13:28:46.017209641Z,160,2,1108,A,A,16.380000000,100,0,41372085,130,165527,26614961,ARL
2025-07-17T13:28:46.017425627Z,2025-07-17T13:28:46.017260228Z,160,2,1108,C,A,17.600000000,100,0,40999449,0,165399,26614991,ARL
2025-07-17T13:28:46.017425627Z,2025-07-17T13:28:46.017260228Z,160,2,1108,A,A,16.830000000,100,0,41372125,130,165399,26614991,ARL
2025-07-17T13:28:46.017696573Z,2025-07-17T13:28:46.017531156Z,160,2,1108,C,A,17.120000000,100,0,41021841,0,165417,26615138,ARL
2025-07-17T13:28:46.017696573Z,2025-07-17T13:28:46.017531156Z,160,2,1108,A,A,16.380000000,100,0,41372369,130,165417,26615138,ARL
2025-07-17T13:28:46.017823073Z,2025-07-17T13:28:46.017657609Z,160,2,1108,C,A,17.600000000,100,0,41021373,0,165464,26615203,ARL
2025-07-17T13:28:46.017823073Z,2025-07-17T13:28:46.017657609Z,160,2,1108,A,A,16.830000000,100,0,41372469,130,165464,26615203,ARL
2025-07-17T13:28:46.017886428Z,2025-07-17T13:28:46.017721028Z,160,2,1108,C,A,18.400000000,100,0,41032057,0,165400,26615230,ARL
2025-07-17T13:28:46.017886428Z,2025-07-17T13:28:46.017721028Z,160,2,1108,A,A,17.600000000,100,0,41372493,130,165400,26615230,ARL
2025-07-17T13:28:46.018003119Z,2025-07-17T13:28:46.017837874Z,160,2,1108,C,A,20.320000000,100,0,41306445,0,165245,26615283,ARL
2025-07-17T13:28:46.018003119Z,2025-07-17T13:28:46.017837874Z,160,2,1108,A,A,19.440000000,100,0,41372549,130,165245,26615283,ARL
2025-07-17T13:28:46.022262428Z,2025-07-17T13:28:46.022095254Z,160,2,1108,A,B,10.050000000,700,0,41375793,128,167174,26616844,ARL
2025-07-17T13:28:46.022988063Z,2025-07-17T13:28:46.022822832Z,160,2,1108,A,A,16.300000000,700,0,41375973,130,165231,26617168,ARL
2025-07-17T13:28:46.025981579Z,2025-07-17T13:28:46.025816567Z,160,2,1108,A,B,11.760000000,100,0,41376297,130,165012,26618403,ARL
2025-07-17T13:28:46.026037162Z,2025-07-17T13:28:46.025870563Z,160,2,1108,C,B,7.740000000,100,0,23616197,0,166599,26618436,ARL
2025-07-17T13:28:46.026037162Z,2025-07-17T13:28:46.025870563Z,160,2,1108,A,B,8.470000000,100,0,41376333,130,166599,26618436,ARL
2025-07-17T13:28:46.026038058Z,2025-07-17T13:28:46.025872146Z,160,2,1108,C,B,7.740000000,100,0,23622101,0,165912,26618438,ARL
2025-07-17T13:28:46.026038058Z,2025-07-17T13:28:46.025872146Z,160,2,1108,A,B,8.470000000,100,0,41376337,130,165912,26618438,ARL
2025-07-17T13:28:46.026039687Z,2025-07-17T13:28:46.025873388Z,160,2,1108,C,B,7.740000000,100,0,24102329,0,166299,26618439,ARL
2025-07-17T13:28:46.026039687Z,2025-07-17T13:28:46.025873388Z,160,2,1108,A,B,8.470000000,100,0,41376341,128,166299,26618439,ARL
2025-07-17T13:28:46.026045679Z,2025-07-17T13:28:46.025874774Z,160,2,1108,C,B,7.740000000,100,0,31960841,0,170905,26618441,ARL
2025-07-17T13:28:46.026045679Z,2025-07-17T13:28:46.025874774Z,160,2,1108,A,B,8.470000000,100,0,41376345,0,170905,26618441,ARL
2025-07-17T13:28:46.026045679Z,2025-07-17T13:28:46.025875041Z,160,2,1108,C,B,7.740000000,100,0,33574717,0,170638,26618442,ARL
2025-07-17T13:28:46.026045679Z,2025-07-17T13:28:46.025875041Z,160,2,1108,A,B,8.470000000,100,0,41376349,0,170638,26618442,ARL
2025-07-17T13:28:46.026045679Z,2025-07-17T13:28:46.025875401Z,160,2,1108,C,B,7.740000000,100,0,38041417,0,170278,26618443,ARL
2025-07-17T13:28:46.026045679Z,2025-07-17T13:28:46.025875401Z,160,2,1108,A,B,8.470000000,100,0,41376353,0,170278,26618443,ARL
2025-07-17T13:28:46.026045679Z,2025-07-17T13:28:46.025877502Z,160,2,1108,C,B,7.740000000,100,0,40617777,0,168177,26618447,ARL
2025-07-17T13:28:46.026045679Z,2025-07-17T13:28:46.025877502Z,160,2,1108,A,B,8.470000000,100,0,41376357,130,168177,26618447,ARL
2025-07-17T13:28:46.027725683Z,2025-07-17T13:28:46.027560174Z,160,2,1108,C,B,9.990000000,100,0,41000165,0,165509,26619144,ARL
2025-07-17T13:28:46.027725683Z,2025-07-17T13:28:46.027560174Z,160,2,1108,A,B,10.930000000,100,0,41376501,130,165509,26619144,ARL
2025-07-17T13:28:46.029726785Z,2025-07-17T13:28:46.029556957Z,160,2,1108,C,B,9.670000000,100,0,40999441,0,169828,26619966,ARL
2025-07-17T13:28:46.029726785Z,2025-07-17T13:28:46.029556957Z,160,2,1108,A,B,10.580000000,100,0,41376725,128,169828,26619966,ARL
2025-07-17T13:28:46.029775250Z,2025-07-17T13:28:46.029609064Z,160,2,1108,C,B,7.840000000,100,0,41306441,0,166186,26619999,ARL
2025-07-17T13:28:46.029775250Z,2025-07-17T13:28:46.029609064Z,160,2,1108,A,B,8.580000000,100,0,41376733,130,166186,26619999,ARL
2025-07-17T13:28:46.031239452Z,2025-07-17T13:28:46.031073916Z,160,2,1108,C,B,9.130000000,100,0,41032049,0,165536,26620530,ARL
2025-07-17T13:28:46.031239452Z,2025-07-17T13:28:46.031073916Z,160,2,1108,A,B,9.990000000,100,0,41376769,130,165536,26620530,ARL
2025-07-17T13:28:46.038120992Z,2025-07-17T13:28:46.037954661Z,160,2,1108,C,B,9.670000000,100,0,41021369,0,166331,26623213,ARL
2025-07-17T13:28:46.038120992Z,2025-07-17T13:28:46.037954661Z,160,2,1108,A,B,10.580000000,100,0,41377117,128,166331,26623213,ARL
2025-07-17T13:28:46.043024422Z,2025-07-17T13:28:46.042858782Z,160,2,1108,C,B,9.990000000,100,0,41021837,0,165640,26625366,ARL
2025-07-17T13:28:46.043024422Z,2025-07-17T13:28:46.042858782Z,160,2,1108,A,B,10.930000000,100,0,41379985,130,165640,26625366,ARL
2025-07-17T13:28:52.312460374Z,2025-07-17T13:28:52.312295020Z,160,2,1108,A,B,10.750000000,700,0,41507073,130,165354,26806665,ARL
2025-07-17T13:28:52.312496032Z,2025-07-17T13:28:52.312330796Z,160,2,1108,C,B,10.050000000,700,0,41375793,130,165236,26806666,ARL
2025-07-17T13:28:52.512457909Z,2025-07-17T13:28:52.512292648Z,160,2,1108,A,B,10.990000000,700,0,41509393,130,165261,26808221,ARL
2025-07-17T13:28:52.513255552Z,2025-07-17T13:28:52.513090520Z,160,2,1108,C,B,10.750000000,700,0,41507073,130,165032,26808222,ARL
2025-07-17T13:28:53.957233148Z,2025-07-17T13:28:53.957067631Z,160,2,1108,A,A,16.150000000,700,0,41528029,130,165517,26835971,ARL
2025-07-17T13:28:53.957281517Z,2025-07-17T13:28:53.957116061Z,160,2,1108,C,A,18.320000000,700,0,40846101,130,165456,26835974,ARL
2025-07-17T13:28:54.128476219Z,2025-07-17T13:28:54.128310778Z,160,2,1108,A,B,9.990000000,700,0,41530665,130,165441,26850111,ARL
2025-07-17T13:28:54.128503934Z,2025-07-17T13:28:54.128338727Z,160,2,1108,C,B,9.290000000,700,0,40851989,130,165207,26850112,ARL
2025-07-17T13:28:54.328652337Z,2025-07-17T13:28:54.328487063Z,160,2,1108,A,B,10.260000000,700,0,41533513,130,165274,26851888,ARL
2025-07-17T13:28:54.328684086Z,2025-07-17T13:28:54.328519057Z,160,2,1108,C,B,9.990000000,700,0,41530665,130,165029,26851889,ARL
2025-07-17T13:28:54.477620754Z,2025-07-17T13:28:54.477455479Z,160,2,1108,A,B,11.140000000,700,0,41534785,130,165275,26853475,ARL
2025-07-17T13:28:54.478018001Z,2025-07-17T13:28:54.477852651Z,160,2,1108,C,B,10.180000000,700,0,41371221,130,165350,26853478,ARL
2025-07-17T13:28:54.528708243Z,2025-07-17T13:28:54.528542919Z,160,2,1108,A,B,10.530000000,700,0,41535173,130,165324,26853925,ARL
2025-07-17T13:28:54.528736554Z,2025-07-17T13:28:54.528571375Z,160,2,1108,C,B,10.260000000,700,0,41533513,130,165179,26853926,ARL
2025-07-17T13:28:54.728740313Z,2025-07-17T13:28:54.728575124Z,160,2,1108,A,B,10.800000000,700,0,41537525,130,165189,26856081,ARL
2025-07-17T13:28:54.728816275Z,2025-07-17T13:28:54.728651317Z,160,2,1108,C,B,10.530000000,700,0,41535173,130,164958,26856082,ARL
2025-07-17T13:28:54.928577406Z,2025-07-17T13:28:54.928412211Z,160,2,1108,A,B,11.070000000,700,0,41539477,130,165195,26858349,ARL
2025-07-17T13:28:54.928653303Z,2025-07-17T13:28:54.928488170Z,160,2,1108,C,B,10.800000000,700,0,41537525,130,165133,26858351,ARL
2025-07-17T13:29:00.583276463Z,2025-07-17T13:29:00.583110843Z,160,2,1108,A,B,10.840000000,100,0,41635065,130,165620,27000961,ARL
2025-07-17T13:29:00.583289800Z,2025-07-17T13:29:00.583124331Z,160,2,1108,A,A,16.490000000,100,0,41635069,130,165469,27000962,ARL
2025-07-17T13:29:31.666650984Z,2025-07-17T13:29:31.666485583Z,160,2,1108,A,B,11.050000000,100,0,42089321,130,165401,27592251,ARL
2025-07-17T13:29:31.666676040Z,2025-07-17T13:29:31.666510533Z,160,2,1108,A,A,16.220000000,100,0,42089325,130,165507,27592252,ARL
2025-07-17T13:29:32.011253336Z,2025-07-17T13:29:32.011088073Z,160,2,1108,A,B,11.290000000,100,0,42099317,130,165263,27599196,ARL
2025-07-17T13:29:32.011257301Z,2025-07-17T13:29:32.011092154Z,160,2,1108,A,A,15.910000000,100,0,42099321,130,165147,27599197,ARL
2025-07-17T13:29:39.840138413Z,2025-07-17T13:29:39.839973111Z,160,2,1108,A,B,8.470000000,100,0,42202297,130,165302,27759427,ARL
2025-07-17T13:29:40.000349567Z,2025-07-17T13:29:40.000183284Z,160,2,1108,A,A,19.580000000,100,0,42204681,130,166283,27760200,ARL
2025-07-17T13:29:55.529348997Z,2025-07-17T13:29:55.529183618Z,160,2,1108,A,B,11.520000000,100,0,42446497,130,165379,28123971,ARL
2025-07-17T13:29:55.529365902Z,2025-07-17T13:29:55.529200619Z,160,2,1108,A,A,15.610000000,100,0,42446501,130,165283,28123973,ARL
2025-07-17T13:29:59.677450683Z,2025-07-17T13:29:59.677285294Z,160,2,1108,A,B,10.110000000,100,0,42583289,130,165389,28321241,ARL
2025-07-17T13:29:59.677457187Z,2025-07-17T13:29:59.677290064Z,160,2,1108,A,A,17.450000000,100,0,42583293,128,167123,28321242,ARL
2025-07-17T13:30:00.093085479Z,2025-07-17T13:30:00.092900330Z,160,2,1108,A,B,11.010000000,100,0,42674817,128,185149,28409476,ARL
2025-07-17T13:30:00.093164566Z,2025-07-17T13:30:00.092988904Z,160,2,1108,A,A,16.100000000,100,0,42674989,128,175662,28409593,ARL
2025-07-17T13:30:00.412816741Z,2025-07-17T13:30:00.412637542Z,160,2,1108,A,A,19.580000000,100,0,42946053,128,179199,28676200,ARL
2025-07-17T13:30:00.422103919Z,2025-07-17T13:30:00.421937186Z,160,2,1108,A,B,8.470000000,100,0,42951397,128,166733,28680759,ARL
2025-07-17T13:30:00.675725361Z,2025-07-17T13:30:00.675553569Z,160,2,1108,A,B,10.920000000,100,0,43143317,128,171792,28833560,ARL
2025-07-17T13:30:00.675748539Z,2025-07-17T13:30:00.675570319Z,160,2,1108,A,A,16.200000000,100,0,43143333,128,178220,28833574,ARL
2025-07-17T13:30:00.730859228Z,2025-07-17T13:30:00.730688348Z,160,2,1108,A,B,10.920000000,100,0,43191333,130,170880,28858298,ARL
2025-07-17T13:30:00.730867405Z,2025-07-17T13:30:00.730693126Z,160,2,1108,A,A,16.200000000,100,0,43191369,128,174279,28858300,ARL
2025-07-17T13:30:00.869893365Z,2025-07-17T13:30:00.869714108Z,160,2,1108,A,B,9.410000000,100,0,43313553,0,179257,28963643,ARL
2025-07-17T13:30:00.869893365Z,2025-07-17T13:30:00.869715708Z,160,2,1108,A,A,18.360000000,100,0,43313565,128,177657,28963646,ARL
2025-07-17T13:30:00.869922678Z,2025-07-17T13:30:00.869746905Z,160,2,1108,A,A,18.360000000,100,0,43313633,128,175773,28963685,ARL
2025-07-17T13:30:00.869941215Z,2025-07-17T13:30:00.869768981Z,160,2,1108,A,B,9.410000000,100,0,43313681,130,172234,28963699,ARL
2025-07-17T13:30:00.870056916Z,2025-07-17T13:30:00.869883482Z,160,2,1108,A,B,11.240000000,100,0,43313941,128,173434,28963823,ARL
2025-07-17T13:30:00.870086307Z,2025-07-17T13:30:00.869917271Z,160,2,1108,A,A,15.980000000,100,0,43314009,130,169036,28963843,ARL
2025-07-17T13:30:00.870161301Z,2025-07-17T13:30:00.869979897Z,160,2,1108,C,B,8.470000000,100,0,41376333,0,181404,28963935,ARL
2025-07-17T13:30:00.870161301Z,2025-07-17T13:30:00.869979897Z,160,2,1108,A,B,9.550000000,100,0,43314145,0,181404,28963935,ARL
2025-07-17T13:30:00.870161301Z,2025-07-17T13:30:00.869983764Z,160,2,1108,C,B,8.470000000,100,0,41376337,0,177537,28963938,ARL
2025-07-17T13:30:00.870161301Z,2025-07-17T13:30:00.869983764Z,160,2,1108,A,B,9.550000000,100,0,43314149,128,177537,28963938,ARL
2025-07-17T13:30:00.870165319Z,2025-07-17T13:30:00.869988740Z,160,2,1108,C,B,8.470000000,100,0,41376341,0,176579,28963943,ARL
2025-07-17T13:30:00.870165319Z,2025-07-17T13:30:00.869988740Z,160,2,1108,A,B,9.550000000,100,0,43314153,0,176579,28963943,ARL
2025-07-17T13:30:00.870165319Z,2025-07-17T13:30:00.869989204Z,160,2,1108,C,B,8.470000000,100,0,41376345,0,176115,28963944,ARL
2025-07-17T13:30:00.870165319Z,2025-07-17T13:30:00.869989204Z,160,2,1108,A,B,9.550000000,100,0,43314157,128,176115,28963944,ARL
2025-07-17T13:30:00.870174640Z,2025-07-17T13:30:00.869996105Z,160,2,1108,C,B,8.470000000,100,0,41376349,0,178535,28963952,ARL
2025-07-17T13:30:00.870174640Z,2025-07-17T13:30:00.869996105Z,160,2,1108,A,B,9.550000000,100,0,43314161,0,178535,28963952,ARL
2025-07-17T13:30:00.870174640Z,2025-07-17T13:30:00.869996504Z,160,2,1108,C,B,8.470000000,100,0,41376353,0,178136,28963953,ARL
2025-07-17T13:30:00.870174640Z,2025-07-17T13:30:00.869996504Z,160,2,1108,A,B,9.550000000,100,0,43314165,0,178136,28963953,ARL
2025-07-17T13:30:00.870174640Z,2025-07-17T13:30:00.869997057Z,160,2,1108,C,B,8.470000000,100,0,41376357,0,177583,28963954,ARL
2025-07-17T13:30:00.870174640Z,2025-07-17T13:30:00.869997057Z,160,2,1108,A,B,9.550000000,100,0,43314169,128,177583,28963954,ARL
2025-07-17T13:30:00.870179751Z,2025-07-17T13:30:00.870003387Z,160,2,1108,C,B,8.470000000,100,0,42202297,0,176364,28963962,ARL
2025-07-17T13:30:00.870179751Z,2025-07-17T13:30:00.870003387Z,160,2,1108,A,B,9.550000000,100,0,43314173,0,176364,28963962,ARL
2025-07-17T13:30:00.870179751Z,2025-07-17T13:30:00.870004158Z,160,2,1108,C,B,8.470000000,100,0,42951397,0,175593,28963963,ARL
2025-07-17T13:30:00.870179751Z,2025-07-17T13:30:00.870004158Z,160,2,1108,A,B,9.550000000,100,0,43314177,128,175593,28963963,ARL
2025-07-17T13:30:00.870186428Z,2025-07-17T13:30:00.870009922Z,160,2,1108,C,A,19.580000000,100,0,41370945,0,176506,28963970,ARL
2025-07-17T13:30:00.870186428Z,2025-07-17T13:30:00.870009922Z,160,2,1108,A,A,18.380000000,100,0,43314181,0,176506,28963970,ARL
2025-07-17T13:30:00.870186428Z,2025-07-17T13:30:00.870010386Z,160,2,1108,C,A,19.580000000,100,0,41370949,0,176042,28963971,ARL
2025-07-17T13:30:00.870186428Z,2025-07-17T13:30:00.870010386Z,160,2,1108,A,A,18.380000000,100,0,43314185,128,176042,28963971,ARL
2025-07-17T13:30:00.870194394Z,2025-07-17T13:30:00.870017071Z,160,2,1108,C,A,19.580000000,100,0,41370953,0,177323,28963981,ARL
2025-07-17T13:30:00.870194394Z,2025-07-17T13:30:00.870017071Z,160,2,1108,A,A,18.380000000,100,0,43314189,0,177323,28963981,ARL
2025-07-17T13:30:00.870194394Z,2025-07-17T13:30:00.870022776Z,160,2,1108,C,A,19.580000000,100,0,41370957,0,171618,28963983,ARL
2025-07-17T13:30:00.870194394Z,2025-07-17T13:30:00.870022776Z,160,2,1108,A,A,18.380000000,100,0,43314233,0,171618,28963983,ARL
2025-07-17T13:30:00.870194394Z,2025-07-17T13:30:00.870023199Z,160,2,1108,C,A,19.580000000,100,0,41370961,0,171195,28963984,ARL
2025-07-17T13:30:00.870194394Z,2025-07-17T13:30:00.870023199Z,160,2,1108,A,A,18.380000000,100,0,43314237,0,171195,28963984,ARL
2025-07-17T13:30:00.870194394Z,2025-07-17T13:30:00.870023701Z,160,2,1108,C,A,19.580000000,100,0,41370965,0,170693,28963985,ARL
2025-07-17T13:30:00.870194394Z,2025-07-17T13:30:00.870023701Z,160,2,1108,A,A,18.380000000,100,0,43314241,130,170693,28963985,ARL
2025-07-17T13:30:00.870229401Z,2025-07-17T13:30:00.870053023Z,160,2,1108,C,A,19.580000000,100,0,41370969,0,176378,28964015,ARL
2025-07-17T13:30:00.870229401Z,2025-07-17T13:30:00.870053023Z,160,2,1108,A,A,18.380000000,100,0,43314245,0,176378,28964015,ARL
2025-07-17T13:30:00.870229401Z,2025-07-17T13:30:00.870053791Z,160,2,1108,C,A,19.580000000,100,0,42204681,0,175610,28964016,ARL
2025-07-17T13:30:00.870229401Z,2025-07-17T13:30:00.870053791Z,160,2,1108,A,A,18.380000000,100,0,43314253,0,175610,28964016,ARL
2025-07-17T13:30:00.870229401Z,2025-07-17T13:30:00.870054073Z,160,2,1108,C,A,19.580000000,100,0,42946053,0,175328,28964017,ARL
2025-07-17T13:30:00.870229401Z,2025-07-17T13:30:00.870054073Z,160,2,1108,A,A,18.380000000,100,0,43314257,128,175328,28964017,ARL
2025-07-17T13:30:00.870236146Z,2025-07-17T13:30:00.870063003Z,160,2,1108,C,A,18.360000000,100,0,43313633,0,173143,28964020,ARL
2025-07-17T13:30:00.870236146Z,2025-07-17T13:30:00.870063920Z,160,2,1108,C,B,9.410000000,100,0,43313681,128,172226,28964021,ARL
2025-07-17T13:30:00.870319397Z,2025-07-17T13:30:00.870151543Z,160,2,1108,A,B,10.610000000,100,0,43314465,128,167854,28964128,ARL
2025-07-17T13:30:00.870390228Z,2025-07-17T13:30:00.870209113Z,160,2,1108,A,A,17.230000000,100,0,43314561,128,181115,28964207,ARL
2025-07-17T13:30:00.870452050Z,2025-07-17T13:30:00.870273955Z,160,2,1108,C,B,11.240000000,100,0,43313941,0,178095,28964259,ARL
2025-07-17T13:30:00.870452050Z,2025-07-17T13:30:00.870278857Z,160,2,1108,C,A,15.980000000,100,0,43314009,128,173193,28964260,ARL
2025-07-17T13:30:00.870748921Z,2025-07-17T13:30:00.870579856Z,160,2,1108,C,B,9.410000000,100,0,43313553,0,169065,28964629,ARL
2025-07-17T13:30:00.870748921Z,2025-07-17T13:30:00.870580243Z,160,2,1108,C,A,18.360000000,100,0,43313565,128,168678,28964630,ARL
2025-07-17T13:30:00.871024910Z,2025-07-17T13:30:00.870848973Z,160,2,1108,A,B,11.400000000,100,0,43315905,128,175937,28964903,ARL
2025-07-17T13:30:00.871047347Z,2025-07-17T13:30:00.870874152Z,160,2,1108,C,B,10.110000000,100,0,42583289,128,173195,28964931,ARL
2025-07-17T13:30:00.871535485Z,2025-07-17T13:30:00.871359085Z,160,2,1108,A,A,16.380000000,100,0,43317137,128,176400,28965402,ARL
2025-07-17T13:30:00.871544335Z,2025-07-17T13:30:00.871371794Z,160,2,1108,A,B,10.610000000,100,0,43317177,128,172541,28965409,ARL
2025-07-17T13:30:00.871552017Z,2025-07-17T13:30:00.871379595Z,160,2,1108,A,A,17.230000000,100,0,43317185,0,172422,28965416,ARL
2025-07-17T13:30:00.871552017Z,2025-07-17T13:30:00.871381021Z,160,2,1108,C,A,17.450000000,100,0,42583293,128,170996,28965418,ARL
2025-07-17T13:30:00.871701004Z,2025-07-17T13:30:00.871520352Z,160,2,1108,C,B,10.840000000,100,0,41635065,0,180652,28965571,ARL
2025-07-17T13:30:00.871701004Z,2025-07-17T13:30:00.871520352Z,160,2,1108,A,B,12.230000000,100,0,43317473,128,180652,28965571,ARL
2025-07-17T13:30:00.871723283Z,2025-07-17T13:30:00.871548318Z,160,2,1108,C,A,16.490000000,100,0,41635069,0,174965,28965592,ARL
2025-07-17T13:30:00.871723283Z,2025-07-17T13:30:00.871548318Z,160,2,1108,A,A,15.470000000,100,0,43317561,128,174965,28965592,ARL
2025-07-17T13:30:00.911711427Z,2025-07-17T13:30:00.911486897Z,160,2,1108,A,B,11.690000000,2,0,43324133,128,224530,28973032,ARL
2025-07-17T13:30:00.914528735Z,2025-07-17T13:30:00.914351054Z,160,2,1108,A,A,15.310000000,2,0,43328313,128,177681,28975648,ARL
2025-07-17T13:30:00.915372008Z,2025-07-17T13:30:00.915197739Z,160,2,1108,C,B,10.580000000,100,0,41376725,0,174269,28976307,ARL
2025-07-17T13:30:00.915372008Z,2025-07-17T13:30:00.915197739Z,160,2,1108,A,B,11.930000000,100,0,43329953,130,174269,28976307,ARL
2025-07-17T13:30:00.916507980Z,2025-07-17T13:30:00.916332252Z,160,2,1108,C,A,16.830000000,100,0,41372125,0,175728,28977103,ARL
2025-07-17T13:30:00.916507980Z,2025-07-17T13:30:00.916332252Z,160,2,1108,A,A,15.800000000,100,0,43331877,128,175728,28977103,ARL
2025-07-17T13:30:00.920319545Z,2025-07-17T13:30:00.920144110Z,160,2,1108,C,A,18.380000000,100,0,43314181,0,175435,28979475,ARL
2025-07-17T13:30:00.920319545Z,2025-07-17T13:30:00.920144110Z,160,2,1108,A,A,17.150000000,100,0,43339133,0,175435,28979475,ARL
2025-07-17T13:30:00.920319545Z,2025-07-17T13:30:00.920147410Z,160,2,1108,C,A,18.380000000,100,0,43314185,0,172135,28979478,ARL
2025-07-17T13:30:00.920319545Z,2025-07-17T13:30:00.920147410Z,160,2,1108,A,A,17.150000000,100,0,43339165,130,172135,28979478,ARL
2025-07-17T13:30:00.920380241Z,2025-07-17T13:30:00.920208398Z,160,2,1108,C,A,18.380000000,100,0,43314189,0,171843,28979515,ARL
2025-07-17T13:30:00.920380241Z,2025-07-17T13:30:00.920208398Z,160,2,1108,A,A,17.150000000,100,0,43339333,0,171843,28979515,ARL
2025-07-17T13:30:00.920380241Z,2025-07-17T13:30:00.920208920Z,160,2,1108,C,A,18.380000000,100,0,43314233,0,171321,28979516,ARL
2025-07-17T13:30:00.920380241Z,2025-07-17T13:30:00.920208920Z,160,2,1108,A,A,17.150000000,100,0,43339337,130,171321,28979516,ARL
2025-07-17T13:30:00.920390005Z,2025-07-17T13:30:00.920209286Z,160,2,1108,C,A,18.380000000,100,0,43314237,0,180719,28979517,ARL
2025-07-17T13:30:00.920390005Z,2025-07-17T13:30:00.920209286Z,160,2,1108,A,A,17.150000000,100,0,43339341,0,180719,28979517,ARL
2025-07-17T13:30:00.920390005Z,2025-07-17T13:30:00.920216613Z,160,2,1108,C,A,18.380000000,100,0,43314241,0,173392,28979521,ARL
2025-07-17T13:30:00.920390005Z,2025-07-17T13:30:00.920216613Z,160,2,1108,A,A,17.150000000,100,0,43339377,0,173392,28979521,ARL
2025-07-17T13:30:00.920390005Z,2025-07-17T13:30:00.920217193Z,160,2,1108,C,A,18.380000000,100,0,43314245,0,172812,28979522,ARL
2025-07-17T13:30:00.920390005Z,2025-07-17T13:30:00.920217193Z,160,2,1108,A,A,17.150000000,100,0,43339381,0,172812,28979522,ARL
2025-07-17T13:30:00.920390005Z,2025-07-17T13:30:00.920217632Z,160,2,1108,C,A,18.380000000,100,0,43314253,0,172373,28979523,ARL
2025-07-17T13:30:00.920390005Z,2025-07-17T13:30:00.920217632Z,160,2,1108,A,A,17.150000000,100,0,43339385,130,172373,28979523,ARL
2025-07-17T13:30:00.920530105Z,2025-07-17T13:30:00.920351772Z,160,2,1108,C,A,18.380000000,100,0,43314257,0,178333,28979649,ARL
2025-07-17T13:30:00.920530105Z,2025-07-17T13:30:00.920351772Z,160,2,1108,A,A,17.150000000,100,0,43339565,128,178333,28979649,ARL
2025-07-17T13:30:00.931605690Z,2025-07-17T13:30:00.931432717Z,160,2,1108,C,A,15.800000000,100,0,43331877,0,172973,28991138,ARL
2025-07-17T13:30:00.931605690Z,2025-07-17T13:30:00.931432717Z,160,2,1108,A,A,14.740000000,100,0,43357029,128,172973,28991138,ARL
2025-07-17T13:30:00.941082601Z,2025-07-17T13:30:00.940916945Z,160,2,1108,C,A,15.470000000,100,0,43317561,0,165656,29000554,ARL
2025-07-17T13:30:00.941082601Z,2025-07-17T13:30:00.940916945Z,160,2,1108,A,A,14.440000000,100,0,43373009,130,165656,29000554,ARL
2025-07-17T13:30:00.941236862Z,2025-07-17T13:30:00.941071231Z,160,2,1108,A,A,15.280000000,100,0,43373085,130,165631,29000677,ARL
2025-07-17T13:30:00.941255157Z,2025-07-17T13:30:00.941085073Z,160,2,1108,C,A,16.380000000,100,0,43317137,128,170084,29000688,ARL
2025-07-17T13:30:01.086605950Z,2025-07-17T13:30:01.086438727Z,160,2,1108,C,B,11.010000000,100,0,42674817,0,167223,29116818,ARL
2025-07-17T13:30:01.086605950Z,2025-07-17T13:30:01.086438727Z,160,2,1108,A,B,12.470000000,100,0,43554133,130,167223,29116818,ARL
2025-07-17T13:30:01.086625226Z,2025-07-17T13:30:01.086456460Z,160,2,1108,C,A,16.100000000,100,0,42674989,0,168766,29116862,ARL
2025-07-17T13:30:01.086625226Z,2025-07-17T13:30:01.086456460Z,160,2,1108,A,A,14.200000000,100,0,43554141,128,168766,29116862,ARL
2025-07-17T13:30:01.214882922Z,2025-07-17T13:30:01.214703183Z,160,2,1108,A,B,12.670000000,100,0,43663229,0,179739,29196804,ARL
2025-07-17T13:30:01.214882922Z,2025-07-17T13:30:01.214704496Z,160,2,1108,A,A,14.000000000,100,0,43663233,128,178426,29196805,ARL
2025-07-17T13:30:01.252386379Z,2025-07-17T13:30:01.252206360Z,160,2,1108,A,B,7.740000000,100,0,27015957,0,180019,29221770,ARL
2025-07-17T13:30:01.252386379Z,2025-07-17T13:30:01.252206360Z,160,2,1108,A,A,20.480000000,100,0,27015965,0,180019,29221771,ARL
2025-07-17T13:30:01.252386379Z,2025-07-17T13:30:01.252206360Z,160,2,1108,A,B,7.740000000,100,0,38084501,0,180019,29221772,ARL
2025-07-17T13:30:01.252386379Z,2025-07-17T13:30:01.252206360Z,160,2,1108,A,A,20.480000000,100,0,38073517,0,180019,29221773,ARL
2025-07-17T13:30:01.252386379Z,2025-07-17T13:30:01.252206360Z,160,2,1108,A,B,7.740000000,100,0,38130589,0,180019,29221774,ARL
2025-07-17T13:30:01.252386379Z,2025-07-17T13:30:01.252206360Z,160,2,1108,A,A,20.480000000,100,0,38134973,0,180019,29221775,ARL
2025-07-17T13:30:01.252386379Z,2025-07-17T13:30:01.252206360Z,160,2,1108,A,B,7.740000000,100,0,38470185,0,180019,29221776,ARL
2025-07-17T13:30:01.252386379Z,2025-07-17T13:30:01.252206360Z,160,2,1108,A,A,20.480000000,100,0,38471493,0,180019,29221777,ARL
2025-07-17T13:30:01.252386379Z,2025-07-17T13:30:01.252206360Z,160,2,1108,A,B,7.740000000,100,0,38759997,0,180019,29221778,ARL
2025-07-17T13:30:01.252386379Z,2025-07-17T13:30:01.252206360Z,160,2,1108,A,A,20.480000000,100,0,38758965,0,180019,29221779,ARL
2025-07-17T13:30:01.252386379Z,2025-07-17T13:30:01.252206360Z,160,2,1108,A,B,7.740000000,100,0,38775373,0,180019,29221780,ARL
2025-07-17T13:30:01.252386379Z,2025-07-17T13:30:01.252206360Z,160,2,1108,A,A,20.480000000,100,0,38776877,0,180019,29221781,ARL
2025-07-17T13:30:01.252386379Z,2025-07-17T13:30:01.252206360Z,160,2,1108,A,B,7.740000000,100,0,38865193,0,180019,29221782,ARL
2025-07-17T13:30:01.252386379Z,2025-07-17T13:30:01.252206360Z,160,2,1108,A,A,20.480000000,100,0,38863877,128,180019,29221783,ARL
2025-07-17T13:30:01.252444419Z,2025-07-17T13:30:01.252269158Z,160,2,1108,C,B,7.740000000,100,0,27015957,0,175261,29221828,ARL
2025-07-17T13:30:01.252444419Z,2025-07-17T13:30:01.252269158Z,160,2,1108,A,B,9.550000000,100,0,43690797,0,175261,29221828,ARL
2025-07-17T13:30:01.252444419Z,2025-07-17T13:30:01.252269575Z,160,2,1108,C,B,7.740000000,100,0,38084501,0,174844,29221829,ARL
2025-07-17T13:30:01.252444419Z,2025-07-17T13:30:01.252269575Z,160,2,1108,A,B,9.550000000,100,0,43690801,0,174844,29221829,ARL
2025-07-17T13:30:01.252444419Z,2025-07-17T13:30:01.252269960Z,160,2,1108,C,B,7.740000000,100,0,38130589,0,174459,29221830,ARL
2025-07-17T13:30:01.252444419Z,2025-07-17T13:30:01.252269960Z,160,2,1108,A,B,9.550000000,100,0,43690805,0,174459,29221830,ARL
2025-07-17T13:30:01.252444419Z,2025-07-17T13:30:01.252270596Z,160,2,1108,C,B,7.740000000,100,0,38470185,0,173823,29221831,ARL
2025-07-17T13:30:01.252444419Z,2025-07-17T13:30:01.252270596Z,160,2,1108,A,B,9.550000000,100,0,43690809,0,173823,29221831,ARL
2025-07-17T13:30:01.252444419Z,2025-07-17T13:30:01.252270987Z,160,2,1108,C,B,7.740000000,100,0,38759997,0,173432,29221832,ARL
2025-07-17T13:30:01.252444419Z,2025-07-17T13:30:01.252270987Z,160,2,1108,A,B,9.550000000,100,0,43690813,0,173432,29221832,ARL
2025-07-17T13:30:01.252444419Z,2025-07-17T13:30:01.252271274Z,160,2,1108,C,B,7.740000000,100,0,38775373,0,173145,29221833,ARL
2025-07-17T13:30:01.252444419Z,2025-07-17T13:30:01.252271274Z,160,2,1108,A,B,9.550000000,100,0,43690817,0,173145,29221833,ARL
2025-07-17T13:30:01.252444419Z,2025-07-17T13:30:01.252272011Z,160,2,1108,C,B,7.740000000,100,0,38865193,0,172408,29221834,ARL
2025-07-17T13:30:01.252444419Z,2025-07-17T13:30:01.252272011Z,160,2,1108,A,B,9.550000000,100,0,43690821,128,172408,29221834,ARL
2025-07-17T13:30:01.252457898Z,2025-07-17T13:30:01.252279681Z,160,2,1108,C,A,20.480000000,100,0,27015965,0,178217,29221840,ARL
2025-07-17T13:30:01.252457898Z,2025-07-17T13:30:01.252279681Z,160,2,1108,A,A,17.150000000,100,0,43690825,0,178217,29221840,ARL
2025-07-17T13:30:01.252457898Z,2025-07-17T13:30:01.252280017Z,160,2,1108,C,A,20.480000000,100,0,38073517,0,177881,29221841,ARL
2025-07-17T13:30:01.252457898Z,2025-07-17T13:30:01.252280017Z,160,2,1108,A,A,17.150000000,100,0,43690829,0,177881,29221841,ARL
2025-07-17T13:30:01.252457898Z,2025-07-17T13:30:01.252280383Z,160,2,1108,C,A,20.480000000,100,0,38134973,0,177515,29221842,ARL
2025-07-17T13:30:01.252457898Z,2025-07-17T13:30:01.252280383Z,160,2,1108,A,A,17.150000000,100,0,43690833,0,177515,29221842,ARL
2025-07-17T13:30:01.252457898Z,2025-07-17T13:30:01.252280683Z,160,2,1108,C,A,20.480000000,100,0,38471493,0,177215,29221843,ARL
2025-07-17T13:30:01.252457898Z,2025-07-17T13:30:01.252280683Z,160,2,1108,A,A,17.150000000,100,0,43690837,0,177215,29221843,ARL
2025-07-17T13:30:01.252457898Z,2025-07-17T13:30:01.252281079Z,160,2,1108,C,A,20.480000000,100,0,38758965,0,176819,29221844,ARL
2025-07-17T13:30:01.252457898Z,2025-07-17T13:30:01.252281079Z,160,2,1108,A,A,17.150000000,100,0,43690841,0,176819,29221844,ARL
2025-07-17T13:30:01.252457898Z,2025-07-17T13:30:01.252281306Z,160,2,1108,C,A,20.480000000,100,0,38776877,0,176592,29221845,ARL
2025-07-17T13:30:01.252457898Z,2025-07-17T13:30:01.252281306Z,160,2,1108,A,A,17.150000000,100,0,43690845,0,176592,29221845,ARL
2025-07-17T13:30:01.252457898Z,2025-07-17T13:30:01.252281648Z,160,2,1108,C,A,20.480000000,100,0,38863877,0,176250,29221846,ARL
2025-07-17T13:30:01.252457898Z,2025-07-17T13:30:01.252281648Z,160,2,1108,A,A,17.150000000,100,0,43690849,130,176250,29221846,ARL
2025-07-17T13:30:01.255007539Z,2025-07-17T13:30:01.254829854Z,160,2,1108,C,B,11.690000000,2,0,43324133,0,177685,29223480,ARL
2025-07-17T13:30:01.255007539Z,2025-07-17T13:30:01.254829854Z,160,2,1108,A,B,12.330000000,2,0,43692153,128,177685,29223480,ARL
2025-07-17T13:30:01.255016966Z,2025-07-17T13:30:01.254836082Z,160,2,1108,C,A,15.310000000,2,0,43328313,0,180884,29223485,ARL
2025-07-17T13:30:01.255016966Z,2025-07-17T13:30:01.254836082Z,160,2,1108,A,A,14.650000000,2,0,43692157,128,180884,29223485,ARL
2025-07-17T13:30:01.327109477Z,2025-07-17T13:30:01.326934077Z,160,2,1108,C,B,11.520000000,100,0,42446497,130,175400,29250087,ARL
2025-07-17T13:30:01.327894898Z,2025-07-17T13:30:01.327714478Z,160,2,1108,C,A,15.610000000,100,0,42446501,128,180420,29250293,ARL
2025-07-17T13:30:01.367410233Z,2025-07-17T13:30:01.367244122Z,160,2,1108,C,B,10.930000000,100,0,41376501,0,166111,29262273,ARL
2025-07-17T13:30:01.367410233Z,2025-07-17T13:30:01.367244122Z,160,2,1108,A,B,12.330000000,100,0,43755813,130,166111,29262273,ARL
2025-07-17T13:30:01.367421844Z,2025-07-17T13:30:01.367256226Z,160,2,1108,C,A,16.380000000,100,0,41372085,0,165618,29262274,ARL
2025-07-17T13:30:01.367421844Z,2025-07-17T13:30:01.367256226Z,160,2,1108,A,A,14.340000000,100,0,43755821,130,165618,29262274,ARL
2025-07-17T13:30:01.456631847Z,2025-07-17T13:30:01.456460560Z,160,2,1108,C,B,10.920000000,100,0,43143317,0,171287,29285993,ARL
2025-07-17T13:30:01.456631847Z,2025-07-17T13:30:01.456460560Z,160,2,1108,A,B,12.360000000,100,0,43781537,130,171287,29285993,ARL
2025-07-17T13:30:01.456642950Z,2025-07-17T13:30:01.456476348Z,160,2,1108,C,A,16.200000000,100,0,43143333,0,166602,29285996,ARL
2025-07-17T13:30:01.456642950Z,2025-07-17T13:30:01.456476348Z,160,2,1108,A,A,14.900000000,100,0,43781545,130,166602,29285996,ARL
2025-07-17T13:30:01.488050182Z,2025-07-17T13:30:01.487884350Z,160,2,1108,C,B,10.920000000,100,0,43191333,0,165832,29297612,ARL
2025-07-17T13:30:01.488050182Z,2025-07-17T13:30:01.487884350Z,160,2,1108,A,B,12.360000000,100,0,43787977,130,165832,29297612,ARL
2025-07-17T13:30:01.488082852Z,2025-07-17T13:30:01.487905785Z,160,2,1108,C,A,16.200000000,100,0,43191369,0,177067,29297619,ARL
2025-07-17T13:30:01.488082852Z,2025-07-17T13:30:01.487905785Z,160,2,1108,A,A,14.900000000,100,0,43787985,128,177067,29297619,ARL
2025-07-17T13:30:01.488981292Z,2025-07-17T13:30:01.488809902Z,160,2,1108,C,A,17.230000000,100,0,43314561,128,171390,29298089,ARL
2025-07-17T13:30:01.489038112Z,2025-07-17T13:30:01.488866053Z,160,2,1108,A,A,16.080000000,100,0,43788313,128,172059,29298118,ARL
2025-07-17T13:30:01.532444998Z,2025-07-17T13:30:01.532274368Z,160,2,1108,A,B,12.460000000,100,0,43804025,128,170630,29318499,ARL
2025-07-17T13:30:01.532474492Z,2025-07-17T13:30:01.532293890Z,160,2,1108,C,B,11.050000000,100,0,42089321,128,180602,29318513,ARL
2025-07-17T13:30:01.532498294Z,2025-07-17T13:30:01.532324961Z,160,2,1108,A,A,14.200000000,100,0,43804081,128,173333,29318528,ARL
2025-07-17T13:30:01.532528215Z,2025-07-17T13:30:01.532347519Z,160,2,1108,C,A,16.220000000,100,0,42089325,128,180696,29318534,ARL
2025-07-17T13:30:01.537373659Z,2025-07-17T13:30:01.537195873Z,160,2,1108,A,B,12.990000000,100,0,43805737,128,177786,29320724,ARL
2025-07-17T13:30:01.537387032Z,2025-07-17T13:30:01.537219414Z,160,2,1108,A,A,14.650000000,100,0,43805773,128,167618,29320743,ARL
2025-07-17T13:30:01.571558801Z,2025-07-17T13:30:01.571375465Z,160,2,1108,A,B,13.200000000,28,0,43820541,130,183336,29336931,ARL
2025-07-17T13:30:01.589767581Z,2025-07-17T13:30:01.589592733Z,160,2,1108,C,A,17.230000000,100,0,43317185,128,174848,29345825,ARL
2025-07-17T13:30:01.590564534Z,2025-07-17T13:30:01.590381387Z,160,2,1108,A,A,16.080000000,100,0,43826261,128,183147,29346224,ARL
2025-07-17T13:30:01.592691520Z,2025-07-17T13:30:01.592507554Z,160,2,1108,C,B,9.990000000,100,0,41376769,0,183966,29347436,ARL
2025-07-17T13:30:01.592691520Z,2025-07-17T13:30:01.592507554Z,160,2,1108,A,B,11.270000000,100,0,43826785,128,183966,29347436,ARL
2025-07-17T13:30:01.592712062Z,2025-07-17T13:30:01.592539240Z,160,2,1108,C,A,17.600000000,100,0,41372493,0,172822,29347463,ARL
2025-07-17T13:30:01.592712062Z,2025-07-17T13:30:01.592539240Z,160,2,1108,A,A,15.410000000,100,0,43826805,128,172822,29347463,ARL
2025-07-17T13:30:01.662123703Z,2025-07-17T13:30:01.661958252Z,160,2,1108,C,B,10.580000000,100,0,41377117,0,165451,29378719,ARL
2025-07-17T13:30:01.662123703Z,2025-07-17T13:30:01.661958252Z,160,2,1108,A,B,11.930000000,100,0,43852121,130,165451,29378719,ARL
2025-07-17T13:30:01.662159610Z,2025-07-17T13:30:01.661989524Z,160,2,1108,C,A,16.830000000,100,0,41372469,0,170086,29378727,ARL
2025-07-17T13:30:01.662159610Z,2025-07-17T13:30:01.661989524Z,160,2,1108,A,A,14.740000000,100,0,43852129,128,170086,29378727,ARL
2025-07-17T13:30:01.929560509Z,2025-07-17T13:30:01.929395142Z,160,2,1108,C,A,14.650000000,100,0,43805773,130,165367,29480243,ARL
2025-07-17T13:30:01.930966377Z,2025-07-17T13:30:01.930800767Z,160,2,1108,A,A,13.670000000,100,0,43953649,130,165610,29480698,ARL
2025-07-17T13:30:02.209154979Z,2025-07-17T13:30:02.208989359Z,160,2,1108,A,A,17.150000000,100,0,44040361,130,165620,29556866,ARL
2025-07-17T13:30:02.209170665Z,2025-07-17T13:30:02.209004229Z,160,2,1108,A,B,9.550000000,100,0,44040369,128,166436,29556867,ARL
2025-07-17T13:30:02.378440054Z,2025-07-17T13:30:02.378274380Z,160,2,1108,A,B,12.730000000,100,0,44066409,130,165674,29585499,ARL
2025-07-17T13:30:02.378446229Z,2025-07-17T13:30:02.378280610Z,160,2,1108,A,A,13.930000000,100,0,44066417,130,165619,29585501,ARL
2025-07-17T13:30:02.378454598Z,2025-07-17T13:30:02.378286605Z,160,2,1108,C,B,11.290000000,100,0,42099317,128,167993,29585502,ARL
2025-07-17T13:30:02.378458883Z,2025-07-17T13:30:02.378293244Z,160,2,1108,C,A,15.910000000,100,0,42099321,130,165639,29585504,ARL
2025-07-17T13:30:02.476983806Z,2025-07-17T13:30:02.476818222Z,160,2,1108,C,A,14.900000000,100,0,43781545,0,165584,29601178,ARL
2025-07-17T13:30:02.476983806Z,2025-07-17T13:30:02.476818222Z,160,2,1108,A,A,14.570000000,100,0,44076709,130,165584,29601178,ARL
2025-07-17T13:30:02.483297761Z,2025-07-17T13:30:02.483131658Z,160,2,1108,C,A,14.900000000,100,0,43787985,0,166103,29601999,ARL
2025-07-17T13:30:02.483297761Z,2025-07-17T13:30:02.483131658Z,160,2,1108,A,A,14.570000000,100,0,44077497,130,166103,29601999,ARL
2025-07-17T13:30:02.524921786Z,2025-07-17T13:30:02.524755932Z,160,2,1108,C,B,8.580000000,100,0,41376733,0,165854,29608933,ARL
2025-07-17T13:30:02.524921786Z,2025-07-17T13:30:02.524755932Z,160,2,1108,A,B,9.670000000,100,0,44082961,130,165854,29608933,ARL
2025-07-17T13:30:02.524935181Z,2025-07-17T13:30:02.524769583Z,160,2,1108,C,A,19.440000000,100,0,41372549,0,165598,29608936,ARL
2025-07-17T13:30:02.524935181Z,2025-07-17T13:30:02.524769583Z,160,2,1108,A,A,17.020000000,100,0,44082969,130,165598,29608936,ARL
2025-07-17T13:30:02.573774313Z,2025-07-17T13:30:02.573606685Z,160,2,1108,C,B,10.930000000,100,0,41379985,0,167628,29618524,ARL
2025-07-17T13:30:02.573774313Z,2025-07-17T13:30:02.573606685Z,160,2,1108,A,B,12.330000000,100,0,44088633,128,167628,29618524,ARL
2025-07-17T13:30:02.573792046Z,2025-07-17T13:30:02.573623478Z,160,2,1108,C,A,16.380000000,100,0,41372369,0,168568,29618531,ARL
2025-07-17T13:30:02.573792046Z,2025-07-17T13:30:02.573623478Z,160,2,1108,A,A,14.340000000,100,0,44088637,128,168568,29618531,ARL
2025-07-17T13:30:06.757549069Z,2025-07-17T13:30:06.757383618Z,160,2,1108,A,A,14.270000000,700,0,44491681,130,165451,30107583,ARL
2025-07-17T13:30:06.757600916Z,2025-07-17T13:30:06.757435491Z,160,2,1108,C,A,16.150000000,700,0,41528029,130,165425,30107590,ARL
2025-07-17T13:30:07.195006880Z,2025-07-17T13:30:07.194841610Z,160,2,1108,A,A,15.300000000,700,0,44520965,130,165270,30150210,ARL
2025-07-17T13:30:07.195046929Z,2025-07-17T13:30:07.194880522Z,160,2,1108,C,A,16.300000000,700,0,41375973,128,166407,30150214,ARL
2025-07-17T13:30:07.395047633Z,2025-07-17T13:30:07.394882479Z,160,2,1108,A,A,15.000000000,700,0,44533061,130,165154,30169157,ARL
2025-07-17T13:30:07.395522844Z,2025-07-17T13:30:07.395357697Z,160,2,1108,C,A,15.300000000,700,0,44520965,130,165147,30169278,ARL
2025-07-17T13:30:07.594948559Z,2025-07-17T13:30:07.594772046Z,160,2,1108,A,A,14.700000000,700,0,44545381,128,176513,30189080,ARL
2025-07-17T13:30:07.594962236Z,2025-07-17T13:30:07.594797098Z,160,2,1108,C,A,15.000000000,700,0,44533061,130,165138,30189120,ARL
2025-07-17T13:30:07.663249150Z,2025-07-17T13:30:07.663083798Z,160,2,1108,A,A,14.460000000,700,0,44548325,130,165352,30194197,ARL
2025-07-17T13:30:07.663963574Z,2025-07-17T13:30:07.663798482Z,160,2,1108,C,A,14.700000000,700,0,44545381,130,165092,30194234,ARL
2025-07-17T13:30:07.914437226Z,2025-07-17T13:30:07.914271879Z,160,2,1108,A,B,11.760000000,700,0,44560257,130,165347,30213834,ARL
2025-07-17T13:30:07.915115414Z,2025-07-17T13:30:07.914949951Z,160,2,1108,C,B,10.990000000,700,0,41509393,130,165463,30213941,ARL
2025-07-17T13:30:08.025826192Z,2025-07-17T13:30:08.025660842Z,160,2,1108,A,B,12.020000000,700,0,44565617,130,165350,30224657,ARL
2025-07-17T13:30:08.025838588Z,2025-07-17T13:30:08.025673570Z,160,2,1108,C,B,11.760000000,700,0,44560257,130,165018,30224658,ARL
2025-07-17T13:30:08.114437837Z,2025-07-17T13:30:08.114272470Z,160,2,1108,A,B,12.260000000,700,0,44570585,130,165367,30233944,ARL
2025-07-17T13:30:08.115234484Z,2025-07-17T13:30:08.115068904Z,160,2,1108,C,B,12.020000000,700,0,44565617,130,165580,30234078,ARL
2025-07-17T13:30:08.394538665Z,2025-07-17T13:30:08.394373251Z,160,2,1108,A,B,13.250000000,11,0,44586753,130,165414,30258008,ARL
2025-07-17T13:30:08.402177882Z,2025-07-17T13:30:08.402012613Z,160,2,1108,C,B,13.200000000,28,0,43820541,130,165269,30259240,ARL
2025-07-17T13:30:08.512744920Z,2025-07-17T13:30:08.512579639Z,160,2,1108,A,A,14.260000000,700,0,44598153,130,165281,30276907,ARL
2025-07-17T13:30:08.513140882Z,2025-07-17T13:30:08.512974877Z,160,2,1108,C,A,16.110000000,700,0,41371225,130,166005,30276990,ARL
2025-07-17T13:30:09.129158268Z,2025-07-17T13:30:09.128991840Z,160,2,1108,A,B,11.760000000,700,0,44628617,128,166428,30336805,ARL
2025-07-17T13:30:09.129171567Z,2025-07-17T13:30:09.129006013Z,160,2,1108,C,B,11.070000000,700,0,41539477,130,165554,30336807,ARL
2025-07-17T13:30:09.329216559Z,2025-07-17T13:30:09.329050977Z,160,2,1108,A,B,12.020000000,700,0,44641397,130,165582,30353905,ARL
2025-07-17T13:30:09.329283504Z,2025-07-17T13:30:09.329118219Z,160,2,1108,C,B,11.760000000,700,0,44628617,130,165285,30353910,ARL
2025-07-17T13:30:10.081340519Z,2025-07-17T13:30:10.081175039Z,160,2,1108,A,A,13.400000000,10,0,44719917,130,165480,30441651,ARL
2025-07-17T13:30:10.082315658Z,2025-07-17T13:30:10.082150107Z,160,2,1108,C,A,14.570000000,100,0,44076709,0,165551,30441855,ARL
2025-07-17T13:30:10.082315658Z,2025-07-17T13:30:10.082150107Z,160,2,1108,A,A,14.290000000,100,0,44719985,130,165551,30441855,ARL
2025-07-17T13:30:10.082828352Z,2025-07-17T13:30:10.082662762Z,160,2,1108,C,A,14.570000000,100,0,44077497,0,165590,30441930,ARL
2025-07-17T13:30:10.082828352Z,2025-07-17T13:30:10.082662762Z,160,2,1108,A,A,14.290000000,100,0,44720033,130,165590,30441930,ARL
2025-07-17T13:30:10.085062201Z,2025-07-17T13:30:10.084896414Z,160,2,1108,A,B,12.420000000,700,0,44720357,130,165787,30442720,ARL
2025-07-17T13:30:10.085497770Z,2025-07-17T13:30:10.085332605Z,160,2,1108,C,B,11.140000000,700,0,41534785,130,165165,30442750,ARL
2025-07-17T13:30:12.194748173Z,2025-07-17T13:30:12.194582572Z,160,2,1108,C,A,14.650000000,2,0,43692157,0,165601,30681385,ARL
2025-07-17T13:30:12.194748173Z,2025-07-17T13:30:12.194582572Z,160,2,1108,A,A,14.430000000,2,0,44904733,130,165601,30681385,ARL
2025-07-17T13:30:14.129097570Z,2025-07-17T13:30:14.128932140Z,160,2,1108,A,B,12.370000000,700,0,45025165,130,165430,30851531,ARL
2025-07-17T13:30:14.129174026Z,2025-07-17T13:30:14.129008546Z,160,2,1108,C,B,12.020000000,700,0,44641397,130,165480,30851532,ARL
2025-07-17T13:30:23.695729484Z,2025-07-17T13:30:23.695564208Z,160,2,1108,A,A,13.400000000,12,0,45593201,130,165276,31649134,ARL
2025-07-17T13:30:25.512235443Z,2025-07-17T13:30:25.512069243Z,160,2,1108,C,A,13.400000000,10,0,44719917,128,166200,31806233,ARL
2025-07-17T13:30:26.553325979Z,2025-07-17T13:30:26.553160650Z,160,2,1108,A,A,13.400000000,10,0,45748261,130,165329,31897785,ARL
2025-07-17T13:30:35.240569990Z,2025-07-17T13:30:35.240400172Z,160,2,1108,C,A,13.400000000,10,0,45748261,130,169818,32725426,ARL
2025-07-17T13:30:43.953164386Z,2025-07-17T13:30:43.952999157Z,160,2,1108,C,A,13.400000000,12,0,45593201,130,165229,33659635,ARL
2025-07-17T13:30:43.953528491Z,2025-07-17T13:30:43.953363128Z,160,2,1108,A,A,13.400000000,24,0,46613073,130,165363,33659657,ARL
2025-07-17T13:30:47.814275253Z,2025-07-17T13:30:47.814108950Z,160,2,1108,A,A,13.400000000,10,0,46784085,130,166303,34075767,ARL
2025-07-17T13:30:48.271777831Z,2025-07-17T13:30:48.271611303Z,160,2,1108,C,A,13.400000000,10,0,46784085,130,166528,34129837,ARL
2025-07-17T13:30:56.518448581Z,2025-07-17T13:30:56.518283181Z,160,2,1108,A,A,13.400000000,10,0,47164169,130,165400,34951153,ARL
2025-07-17T13:31:01.011909405Z,2025-07-17T13:31:01.011743292Z,160,2,1108,A,A,14.200000000,700,0,47376925,128,166113,35180694,ARL
2025-07-17T13:31:01.029013770Z,2025-07-17T13:31:01.028848502Z,160,2,1108,A,B,12.430000000,700,0,47383873,130,165268,35188622,ARL
2025-07-17T13:31:01.131725810Z,2025-07-17T13:31:01.131557345Z,160,2,1108,C,A,13.400000000,10,0,47164169,128,168465,35203355,ARL
2025-07-17T13:31:08.376486633Z,2025-07-17T13:31:08.376321454Z,160,2,1108,C,A,13.400000000,24,0,46613073,130,165179,35703639,ARL
2025-07-17T13:31:08.376858048Z,2025-07-17T13:31:08.376692815Z,160,2,1108,A,A,13.400000000,18,0,47873813,130,165233,35703653,ARL
2025-07-17T13:31:08.377188468Z,2025-07-17T13:31:08.377022927Z,160,2,1108,C,A,14.290000000,100,0,44720033,0,165541,35703666,ARL
2025-07-17T13:31:08.377188468Z,2025-07-17T13:31:08.377022927Z,160,2,1108,A,A,14.560000000,100,0,47873821,130,165541,35703666,ARL
2025-07-17T13:31:09.400094773Z,2025-07-17T13:31:09.399928944Z,160,2,1108,C,A,14.560000000,100,0,47873821,0,165829,35758774,ARL
2025-07-17T13:31:09.400094773Z,2025-07-17T13:31:09.399928944Z,160,2,1108,A,A,14.290000000,100,0,47927629,130,165829,35758774,ARL
2025-07-17T13:31:16.539042057Z,2025-07-17T13:31:16.538876621Z,160,2,1108,A,A,13.400000000,10,0,48315949,130,165436,36186495,ARL
2025-07-17T13:31:17.448727976Z,2025-07-17T13:31:17.448559991Z,160,2,1108,C,A,13.400000000,10,0,48315949,128,167985,36232894,ARL
2025-07-17T13:31:34.836102962Z,2025-07-17T13:31:34.835937627Z,160,2,1108,C,A,13.400000000,18,0,47873813,130,165335,37177882,ARL
2025-07-17T13:31:34.836860858Z,2025-07-17T13:31:34.836694504Z,160,2,1108,C,A,14.290000000,100,0,44719985,0,166354,37177896,ARL
2025-07-17T13:31:34.836860858Z,2025-07-17T13:31:34.836694504Z,160,2,1108,A,A,14.560000000,100,0,49226081,130,166354,37177896,ARL
2025-07-17T13:31:34.837265065Z,2025-07-17T13:31:34.837099615Z,160,2,1108,C,A,14.290000000,100,0,47927629,0,165450,37177905,ARL
2025-07-17T13:31:34.837265065Z,2025-07-17T13:31:34.837099615Z,160,2,1108,A,A,14.560000000,100,0,49226101,130,165450,37177905,ARL
2025-07-17T13:35:00.187694195Z,2025-07-17T13:35:00.187526221Z,160,2,1108,C,B,12.330000000,2,0,43692153,0,167974,45447658,ARL
2025-07-17T13:35:00.187694195Z,2025-07-17T13:35:00.187526221Z,160,2,1108,A,B,12.880000000,2,0,58709193,128,167974,45447658,ARL
2025-07-17T13:35:00.187694720Z,2025-07-17T13:35:00.187528642Z,160,2,1108,C,A,14.430000000,2,0,44904733,0,166078,45447661,ARL
2025-07-17T13:35:00.187694720Z,2025-07-17T13:35:00.187528642Z,160,2,1108,A,A,13.780000000,2,0,58709197,130,166078,45447661,ARL
2025-07-17T13:37:31.076320046Z,2025-07-17T13:37:31.076154614Z,160,2,1108,C,A,14.560000000,100,0,49226101,0,165432,51978366,ARL
2025-07-17T13:37:31.076320046Z,2025-07-17T13:37:31.076154614Z,160,2,1108,A,A,14.290000000,100,0,65160189,130,165432,51978366,ARL
2025-07-17T13:37:31.076496403Z,2025-07-17T13:37:31.076330756Z,160,2,1108,C,A,14.560000000,100,0,49226081,0,165647,51978372,ARL
2025-07-17T13:37:31.076496403Z,2025-07-17T13:37:31.076330756Z,160,2,1108,A,A,14.290000000,100,0,65160193,130,165647,51978372,ARL
2025-07-17T13:38:08.679910189Z,2025-07-17T13:38:08.679744459Z,160,2,1108,C,A,14.290000000,100,0,65160189,0,165730,53264917,ARL
2025-07-17T13:38:08.679910189Z,2025-07-17T13:38:08.679744459Z,160,2,1108,A,A,14.560000000,100,0,66501333,130,165730,53264917,ARL
2025-07-17T13:38:08.679917832Z,2025-07-17T13:38:08.679752190Z,160,2,1108,C,A,14.290000000,100,0,65160193,0,165642,53264918,ARL
2025-07-17T13:38:08.679917832Z,2025-07-17T13:38:08.679752190Z,160,2,1108,A,A,14.560000000,100,0,66501341,130,165642,53264918,ARL
2025-07-17T13:38:09.687028970Z,2025-07-17T13:38:09.686863512Z,160,2,1108,C,A,14.560000000,100,0,66501333,0,165458,53302839,ARL
2025-07-17T13:38:09.687028970Z,2025-07-17T13:38:09.686863512Z,160,2,1108,A,A,14.290000000,100,0,66538149,130,165458,53302839,ARL
2025-07-17T13:38:09.708195003Z,2025-07-17T13:38:09.708029202Z,160,2,1108,C,A,14.560000000,100,0,66501341,0,165801,53303094,ARL
2025-07-17T13:38:09.708195003Z,2025-07-17T13:38:09.708029202Z,160,2,1108,A,A,14.290000000,100,0,66538573,130,165801,53303094,ARL
2025-07-17T13:38:44.679122862Z,2025-07-17T13:38:44.678957477Z,160,2,1108,A,A,13.400000000,15,0,67832461,130,165385,54485050,ARL
2025-07-17T13:38:44.679444346Z,2025-07-17T13:38:44.679278833Z,160,2,1108,C,A,14.290000000,100,0,66538149,0,165513,54485052,ARL
2025-07-17T13:38:44.679444346Z,2025-07-17T13:38:44.679278833Z,160,2,1108,A,A,14.560000000,100,0,67832465,130,165513,54485052,ARL
2025-07-17T13:38:45.695430520Z,2025-07-17T13:38:45.695265148Z,160,2,1108,C,A,14.560000000,100,0,67832465,0,165372,54508575,ARL
2025-07-17T13:38:45.695430520Z,2025-07-17T13:38:45.695265148Z,160,2,1108,A,A,14.290000000,100,0,67857641,130,165372,54508575,ARL
2025-07-17T13:39:08.714072882Z,2025-07-17T13:39:08.713907562Z,160,2,1108,C,A,13.400000000,15,0,67832461,130,165320,55204868,ARL
2025-07-17T13:39:08.714449550Z,2025-07-17T13:39:08.714284059Z,160,2,1108,A,A,13.400000000,24,0,68625181,130,165491,55204884,ARL
2025-07-17T13:39:39.996603180Z,2025-07-17T13:39:39.996436857Z,160,2,1108,T,B,13.400000000,1,0,0,130,166323,56150102,ARL
2025-07-17T13:39:39.996603180Z,2025-07-17T13:39:39.996436857Z,160,2,1108,F,A,13.400000000,1,0,68625181,130,166323,56150102,ARL
2025-07-17T13:39:39.996603180Z,2025-07-17T13:39:39.996436857Z,160,2,1108,C,A,13.400000000,1,0,68625181,130,166323,56150102,ARL
2025-07-17T13:39:39.996998334Z,2025-07-17T13:39:39.996833282Z,160,2,1108,C,A,13.400000000,23,0,68625181,130,165052,56150114,ARL
2025-07-17T13:39:39.997309515Z,2025-07-17T13:39:39.997144158Z,160,2,1108,C,A,14.290000000,100,0,66538573,0,165357,56150130,ARL
2025-07-17T13:39:39.997309515Z,2025-07-17T13:39:39.997144158Z,160,2,1108,A,A,14.570000000,100,0,69677517,130,165357,56150130,ARL
2025-07-17T13:39:39.997376873Z,2025-07-17T13:39:39.997211562Z,160,2,1108,A,A,13.400000000,24,0,69677521,130,165311,56150131,ARL
2025-07-17T13:39:41.018948933Z,2025-07-17T13:39:41.018783466Z,160,2,1108,C,A,14.570000000,100,0,69677517,0,165467,56183429,ARL
2025-07-17T13:39:41.018948933Z,2025-07-17T13:39:41.018783466Z,160,2,1108,A,A,14.300000000,100,0,69725541,130,165467,56183429,ARL
2025-07-17T13:40:08.782549047Z,2025-07-17T13:40:08.782383621Z,160,2,1108,C,A,13.400000000,24,0,69677521,130,165426,57235944,ARL
2025-07-17T13:40:08.782923978Z,2025-07-17T13:40:08.782758499Z,160,2,1108,A,A,13.400000000,18,0,70897053,130,165479,57235956,ARL
2025-07-17T13:41:08.818876572Z,2025-07-17T13:41:08.818711250Z,160,2,1108,C,A,13.400000000,18,0,70897053,130,165322,59313726,ARL
2025-07-17T13:41:08.819249545Z,2025-07-17T13:41:08.819083504Z,160,2,1108,A,A,13.400000000,24,0,73109413,130,166041,59313736,ARL
2025-07-17T13:41:08.819270512Z,2025-07-17T13:41:08.819104931Z,160,2,1108,C,A,14.300000000,100,0,69725541,0,165581,59313739,ARL
2025-07-17T13:41:08.819270512Z,2025-07-17T13:41:08.819104931Z,160,2,1108,A,A,14.570000000,100,0,73109417,130,165581,59313739,ARL
2025-07-17T13:41:09.881251193Z,2025-07-17T13:41:09.881085734Z,160,2,1108,C,A,14.570000000,100,0,73109417,0,165459,59383199,ARL
2025-07-17T13:41:09.881251193Z,2025-07-17T13:41:09.881085734Z,160,2,1108,A,A,14.300000000,100,0,73183421,130,165459,59383199,ARL
2025-07-17T13:41:44.348660105Z,2025-07-17T13:41:44.348494744Z,160,2,1108,C,A,13.400000000,24,0,73109413,130,165361,60614543,ARL
2025-07-17T13:41:44.349581977Z,2025-07-17T13:41:44.349416601Z,160,2,1108,C,A,14.300000000,100,0,73183421,0,165376,60614557,ARL
2025-07-17T13:41:44.349581977Z,2025-07-17T13:41:44.349416601Z,160,2,1108,A,A,14.570000000,100,0,74549681,130,165376,60614557,ARL
2025-07-17T13:41:45.405178844Z,2025-07-17T13:41:45.405013016Z,160,2,1108,C,A,14.570000000,100,0,74549681,0,165828,60651462,ARL
2025-07-17T13:41:45.405178844Z,2025-07-17T13:41:45.405013016Z,160,2,1108,A,A,14.300000000,100,0,74589605,130,165828,60651462,ARL
2025-07-17T13:42:08.821320823Z,2025-07-17T13:42:08.821155108Z,160,2,1108,C,A,14.290000000,100,0,67857641,0,165715,61488742,ARL
2025-07-17T13:42:08.821320823Z,2025-07-17T13:42:08.821155108Z,160,2,1108,A,A,14.570000000,100,0,75537553,130,165715,61488742,ARL
2025-07-17T13:42:09.827057338Z,2025-07-17T13:42:09.826891682Z,160,2,1108,C,A,14.570000000,100,0,75537553,0,165656,61523538,ARL
2025-07-17T13:42:09.827057338Z,2025-07-17T13:42:09.826891682Z,160,2,1108,A,A,14.300000000,100,0,75577257,130,165656,61523538,ARL
2025-07-17T13:43:08.826244125Z,2025-07-17T13:43:08.826078491Z,160,2,1108,C,A,14.300000000,100,0,75577257,0,165634,63579150,ARL
2025-07-17T13:43:08.826244125Z,2025-07-17T13:43:08.826078491Z,160,2,1108,A,A,14.570000000,100,0,77879933,130,165634,63579150,ARL
2025-07-17T13:43:09.832572415Z,2025-07-17T13:43:09.832406764Z,160,2,1108,C,A,14.570000000,100,0,77879933,0,165651,63604352,ARL
2025-07-17T13:43:09.832572415Z,2025-07-17T13:43:09.832406764Z,160,2,1108,A,A,14.300000000,100,0,77910357,130,165651,63604352,ARL
2025-07-17T13:46:09.541016899Z,2025-07-17T13:46:09.540851349Z,160,2,1108,C,A,14.200000000,700,0,47376925,130,165550,69578535,ARL
2025-07-17T13:46:09.541058233Z,2025-07-17T13:46:09.540892810Z,160,2,1108,A,A,14.360000000,700,0,84607761,130,165423,69578537,ARL
2025-07-17T13:46:09.541097538Z,2025-07-17T13:46:09.540932260Z,160,2,1108,A,A,15.590000000,100,0,84607765,130,165278,69578539,ARL
2025-07-17T13:46:09.541109881Z,2025-07-17T13:46:09.540944549Z,160,2,1108,C,A,15.280000000,100,0,43373085,130,165332,69578540,ARL
2025-07-17T13:46:09.541434576Z,2025-07-17T13:46:09.541269186Z,160,2,1108,C,A,14.440000000,100,0,43373009,0,165390,69578543,ARL
2025-07-17T13:46:09.541434576Z,2025-07-17T13:46:09.541269186Z,160,2,1108,A,A,14.490000000,100,0,84607785,130,165390,69578543,ARL
2025-07-17T13:46:09.541492629Z,2025-07-17T13:46:09.541327298Z,160,2,1108,C,A,14.000000000,100,0,43663233,130,165331,69578544,ARL
2025-07-17T13:46:09.541795256Z,2025-07-17T13:46:09.541629920Z,160,2,1108,C,A,14.340000000,100,0,43755821,0,165336,69578547,ARL
2025-07-17T13:46:09.541795256Z,2025-07-17T13:46:09.541629920Z,160,2,1108,A,A,14.630000000,100,0,84607801,130,165336,69578547,ARL
2025-07-17T13:46:09.541846554Z,2025-07-17T13:46:09.541680473Z,160,2,1108,C,A,14.740000000,100,0,43357029,0,166081,69578550,ARL
2025-07-17T13:46:09.541846554Z,2025-07-17T13:46:09.541680473Z,160,2,1108,A,A,15.040000000,100,0,84607805,130,166081,69578550,ARL
2025-07-17T13:46:09.541847519Z,2025-07-17T13:46:09.541682402Z,160,2,1108,A,A,14.280000000,100,0,84607809,130,165117,69578551,ARL
2025-07-17T13:46:09.542961756Z,2025-07-17T13:46:09.542796050Z,160,2,1108,C,A,15.410000000,100,0,43826805,0,165706,69578574,ARL
2025-07-17T13:46:09.542961756Z,2025-07-17T13:46:09.542796050Z,160,2,1108,A,A,15.730000000,100,0,84607837,130,165706,69578574,ARL
2025-07-17T13:46:09.543510155Z,2025-07-17T13:46:09.543344724Z,160,2,1108,C,A,17.020000000,100,0,44082969,0,165431,69578598,ARL
2025-07-17T13:46:09.543510155Z,2025-07-17T13:46:09.543344724Z,160,2,1108,A,A,17.370000000,100,0,84607861,130,165431,69578598,ARL
2025-07-17T13:46:09.546546482Z,2025-07-17T13:46:09.546381306Z,160,2,1108,C,A,14.200000000,100,0,43554141,130,165176,69578814,ARL
2025-07-17T13:46:09.546656996Z,2025-07-17T13:46:09.546491223Z,160,2,1108,A,A,14.470000000,100,0,84608321,130,165773,69578831,ARL
2025-07-17T13:46:09.560918620Z,2025-07-17T13:46:09.560753276Z,160,2,1108,C,A,13.670000000,100,0,43953649,130,165344,69579444,ARL
2025-07-17T13:46:09.560953850Z,2025-07-17T13:46:09.560789009Z,160,2,1108,C,A,14.360000000,700,0,84607761,130,164841,69579446,ARL
2025-07-17T13:46:09.560968819Z,2025-07-17T13:46:09.560803559Z,160,2,1108,A,A,13.940000000,100,0,84609305,130,165260,69579448,ARL
2025-07-17T13:46:09.560981020Z,2025-07-17T13:46:09.560815603Z,160,2,1108,C,A,14.270000000,700,0,44491681,130,165417,69579449,ARL
2025-07-17T13:46:09.560990769Z,2025-07-17T13:46:09.560825413Z,160,2,1108,A,A,15.890000000,100,0,84609309,130,165356,69579450,ARL
2025-07-17T13:46:09.561002700Z,2025-07-17T13:46:09.560837771Z,160,2,1108,C,A,15.590000000,100,0,84607765,130,164929,69579453,ARL
2025-07-17T13:46:09.561059021Z,2025-07-17T13:46:09.560893546Z,160,2,1108,A,A,14.700000000,700,0,84609321,130,165475,69579455,ARL
2025-07-17T13:46:09.561710911Z,2025-07-17T13:46:09.561543868Z,160,2,1108,C,A,14.260000000,700,0,44598153,128,167043,69579488,ARL
2025-07-17T13:46:09.561954989Z,2025-07-17T13:46:09.561788417Z,160,2,1108,C,A,15.040000000,100,0,84607805,0,166572,69579536,ARL
2025-07-17T13:46:09.561954989Z,2025-07-17T13:46:09.561788417Z,160,2,1108,A,A,15.330000000,100,0,84609385,0,166572,69579536,ARL
2025-07-17T13:46:09.561954989Z,2025-07-17T13:46:09.561788902Z,160,2,1108,C,A,14.630000000,100,0,84607801,0,166087,69579537,ARL
2025-07-17T13:46:09.561954989Z,2025-07-17T13:46:09.561788902Z,160,2,1108,A,A,14.910000000,100,0,84609389,130,166087,69579537,ARL
2025-07-17T13:46:09.562157451Z,2025-07-17T13:46:09.561992206Z,160,2,1108,A,A,14.670000000,700,0,84609409,130,165245,69579579,ARL
2025-07-17T13:46:09.563782397Z,2025-07-17T13:46:09.563617017Z,160,2,1108,C,A,17.370000000,100,0,84607861,0,165380,69579787,ARL
2025-07-17T13:46:09.563782397Z,2025-07-17T13:46:09.563617017Z,160,2,1108,A,A,17.700000000,100,0,84609557,130,165380,69579787,ARL
2025-07-17T13:46:09.565379544Z,2025-07-17T13:46:09.565213822Z,160,2,1108,C,A,13.780000000,2,0,58709197,0,165722,69579892,ARL
2025-07-17T13:46:09.565379544Z,2025-07-17T13:46:09.565213822Z,160,2,1108,A,A,13.930000000,2,0,84609637,130,165722,69579892,ARL
2025-07-17T13:46:09.565403598Z,2025-07-17T13:46:09.565237899Z,160,2,1108,C,A,15.730000000,100,0,84607837,0,165699,69579893,ARL
2025-07-17T13:46:09.565403598Z,2025-07-17T13:46:09.565237899Z,160,2,1108,A,A,16.020000000,100,0,84609645,130,165699,69579893,ARL
2025-07-17T13:46:09.566687064Z,2025-07-17T13:46:09.566522227Z,160,2,1108,C,A,13.940000000,100,0,84609305,130,164837,69579922,ARL
2025-07-17T13:46:09.566736503Z,2025-07-17T13:46:09.566571131Z,160,2,1108,A,A,14.210000000,100,0,84609733,130,165372,69579923,ARL
2025-07-17T13:46:09.583735074Z,2025-07-17T13:46:09.583569619Z,160,2,1108,C,A,14.740000000,100,0,43852129,0,165455,69580598,ARL
2025-07-17T13:46:09.583735074Z,2025-07-17T13:46:09.583569619Z,160,2,1108,A,A,15.330000000,100,0,84611025,130,165455,69580598,ARL
2025-07-17T13:46:09.591552337Z,2025-07-17T13:46:09.591386919Z,160,2,1108,C,A,14.490000000,100,0,84607785,0,165418,69581249,ARL
2025-07-17T13:46:09.591552337Z,2025-07-17T13:46:09.591386919Z,160,2,1108,A,A,15.010000000,100,0,84611613,130,165418,69581249,ARL
2025-07-17T13:46:09.595667047Z,2025-07-17T13:46:09.595500037Z,160,2,1108,A,A,14.630000000,700,0,84612081,128,167010,69582059,ARL
2025-07-17T13:46:09.610291566Z,2025-07-17T13:46:09.610126066Z,160,2,1108,C,A,14.340000000,100,0,44088637,0,165500,69582709,ARL
2025-07-17T13:46:09.610291566Z,2025-07-17T13:46:09.610126066Z,160,2,1108,A,A,14.910000000,100,0,84612773,130,165500,69582709,ARL
2025-07-17T13:46:09.812938843Z,2025-07-17T13:46:09.812773551Z,160,2,1108,A,A,14.760000000,100,0,84618189,130,165292,69586965,ARL
2025-07-17T13:46:09.812950020Z,2025-07-17T13:46:09.812784722Z,160,2,1108,C,A,14.200000000,100,0,43804081,130,165298,69586966,ARL
2025-07-17T13:46:09.936895839Z,2025-07-17T13:46:09.936730596Z,160,2,1108,C,A,13.930000000,100,0,44066417,130,165243,69592193,ARL
2025-07-17T13:46:09.936896832Z,2025-07-17T13:46:09.936731544Z,160,2,1108,A,A,14.480000000,100,0,84624129,130,165288,69592194,ARL
2025-07-17T13:46:09.937622396Z,2025-07-17T13:46:09.937457145Z,160,2,1108,C,A,15.010000000,100,0,84611613,0,165251,69592231,ARL
2025-07-17T13:46:09.937622396Z,2025-07-17T13:46:09.937457145Z,160,2,1108,A,A,15.060000000,100,0,84624201,130,165251,69592231,ARL
2025-07-17T13:46:10.046960966Z,2025-07-17T13:46:10.046795728Z,160,2,1108,C,A,14.700000000,700,0,84609321,130,165238,69596523,ARL
2025-07-17T13:46:10.046962793Z,2025-07-17T13:46:10.046796743Z,160,2,1108,C,A,14.630000000,700,0,84612081,130,166050,69596524,ARL
2025-07-17T13:46:10.047001176Z,2025-07-17T13:46:10.046834863Z,160,2,1108,A,A,14.990000000,700,0,84628757,0,166313,69596525,ARL
2025-07-17T13:46:10.047001176Z,2025-07-17T13:46:10.046835277Z,160,2,1108,A,A,14.910000000,700,0,84628761,130,165899,69596526,ARL
2025-07-17T13:46:10.047030471Z,2025-07-17T13:46:10.046864551Z,160,2,1108,A,A,16.200000000,100,0,84628765,130,165920,69596527,ARL
2025-07-17T13:46:10.047042954Z,2025-07-17T13:46:10.046877789Z,160,2,1108,C,A,15.890000000,100,0,84609309,130,165165,69596529,ARL
2025-07-17T13:46:10.047089640Z,2025-07-17T13:46:10.046924268Z,160,2,1108,C,A,13.930000000,2,0,84609637,0,165372,69596531,ARL
2025-07-17T13:46:10.047089640Z,2025-07-17T13:46:10.046924268Z,160,2,1108,A,A,14.200000000,2,0,84628773,130,165372,69596531,ARL
2025-07-17T13:46:10.047429477Z,2025-07-17T13:46:10.047264301Z,160,2,1108,C,A,14.280000000,100,0,84607809,130,165176,69596542,ARL
2025-07-17T13:46:10.047479201Z,2025-07-17T13:46:10.047313929Z,160,2,1108,C,A,14.670000000,700,0,84609409,130,165272,69596543,ARL
2025-07-17T13:46:10.047784342Z,2025-07-17T13:46:10.047618250Z,160,2,1108,A,A,14.830000000,100,0,84628793,128,166092,69596548,ARL
2025-07-17T13:46:10.047806230Z,2025-07-17T13:46:10.047640842Z,160,2,1108,C,A,14.460000000,700,0,44548325,130,165388,69596550,ARL
2025-07-17T13:46:10.047885265Z,2025-07-17T13:46:10.047719954Z,160,2,1108,A,A,14.950000000,700,0,84628797,130,165311,69596551,ARL
2025-07-17T13:46:10.047929072Z,2025-07-17T13:46:10.047763743Z,160,2,1108,C,A,14.910000000,100,0,84609389,0,165329,69596552,ARL
2025-07-17T13:46:10.047929072Z,2025-07-17T13:46:10.047763743Z,160,2,1108,A,A,15.200000000,100,0,84628801,130,165329,69596552,ARL
2025-07-17T13:46:10.047983286Z,2025-07-17T13:46:10.047817649Z,160,2,1108,C,A,15.060000000,100,0,84624201,0,165637,69596553,ARL
2025-07-17T13:46:10.047983286Z,2025-07-17T13:46:10.047817649Z,160,2,1108,A,A,15.300000000,100,0,84628813,130,165637,69596553,ARL
2025-07-17T13:46:10.048529147Z,2025-07-17T13:46:10.048363798Z,160,2,1108,A,A,15.140000000,700,0,84628829,130,165349,69596568,ARL
2025-07-17T13:46:10.048840949Z,2025-07-17T13:46:10.048674815Z,160,2,1108,C,A,15.330000000,100,0,84609385,0,166134,69596577,ARL
2025-07-17T13:46:10.048840949Z,2025-07-17T13:46:10.048674815Z,160,2,1108,A,A,15.640000000,100,0,84628833,130,166134,69596577,ARL
2025-07-17T13:46:10.051935025Z,2025-07-17T13:46:10.051769303Z,160,2,1108,C,A,17.700000000,100,0,84609557,0,165722,69596649,ARL
2025-07-17T13:46:10.051935025Z,2025-07-17T13:46:10.051769303Z,160,2,1108,A,A,18.050000000,100,0,84628913,130,165722,69596649,ARL
2025-07-17T13:46:10.054332558Z,2025-07-17T13:46:10.054167322Z,160,2,1108,C,A,16.020000000,100,0,84609645,0,165236,69596777,ARL
2025-07-17T13:46:10.054332558Z,2025-07-17T13:46:10.054167322Z,160,2,1108,A,A,16.350000000,100,0,84629065,130,165236,69596777,ARL
2025-07-17T13:46:10.055434148Z,2025-07-17T13:46:10.055269067Z,160,2,1108,C,A,14.210000000,100,0,84609733,130,165081,69596798,ARL
2025-07-17T13:46:10.055483249Z,2025-07-17T13:46:10.055317945Z,160,2,1108,A,A,14.480000000,100,0,84629093,130,165304,69596799,ARL
2025-07-17T13:46:10.061411059Z,2025-07-17T13:46:10.061246123Z,160,2,1108,C,A,14.480000000,100,0,84629093,130,164936,69596987,ARL
2025-07-17T13:46:10.061459915Z,2025-07-17T13:46:10.061294728Z,160,2,1108,A,A,14.590000000,100,0,84629329,130,165187,69596990,ARL
2025-07-17T13:46:10.087891846Z,2025-07-17T13:46:10.087725560Z,160,2,1108,C,A,15.330000000,100,0,84611025,0,166286,69597697,ARL
2025-07-17T13:46:10.087891846Z,2025-07-17T13:46:10.087725560Z,160,2,1108,A,A,15.730000000,100,0,84629953,128,166286,69597697,ARL
2025-07-17T13:46:10.098194757Z,2025-07-17T13:46:10.098029439Z,160,2,1108,C,A,15.300000000,100,0,84628813,0,165318,69597813,ARL
2025-07-17T13:46:10.098194757Z,2025-07-17T13:46:10.098029439Z,160,2,1108,A,A,15.410000000,100,0,84630217,130,165318,69597813,ARL
2025-07-17T13:46:10.109235050Z,2025-07-17T13:46:10.109069598Z,160,2,1108,C,A,14.910000000,100,0,84612773,0,165452,69598154,ARL
2025-07-17T13:46:10.109235050Z,2025-07-17T13:46:10.109069598Z,160,2,1108,A,A,15.310000000,100,0,84630849,130,165452,69598154,ARL
2025-07-17T13:46:10.551481906Z,2025-07-17T13:46:10.551316402Z,160,2,1108,C,A,14.470000000,100,0,84608321,0,165504,69614455,ARL
2025-07-17T13:46:10.551481906Z,2025-07-17T13:46:10.551316402Z,160,2,1108,A,A,15.090000000,100,0,84650629,130,165504,69614455,ARL
2025-07-17T13:46:10.904838107Z,2025-07-17T13:46:10.904672934Z,160,2,1108,A,A,15.160000000,100,0,84668677,130,165173,69628781,ARL
2025-07-17T13:46:10.904858553Z,2025-07-17T13:46:10.904693578Z,160,2,1108,C,A,14.760000000,100,0,84618189,130,164975,69628783,ARL
2025-07-17T13:46:11.840882444Z,2025-07-17T13:46:11.840717150Z,160,2,1108,A,A,14.870000000,100,0,84708037,130,165294,69663346,ARL
2025-07-17T13:46:11.840894787Z,2025-07-17T13:46:11.840729407Z,160,2,1108,C,A,14.480000000,100,0,84624129,130,165380,69663347,ARL
2025-07-17T13:46:23.920813185Z,2025-07-17T13:46:23.920647302Z,160,2,1108,C,B,12.880000000,2,0,58709193,0,165883,70104076,ARL
2025-07-17T13:46:23.920813185Z,2025-07-17T13:46:23.920647302Z,160,2,1108,A,B,13.120000000,2,0,85194077,130,165883,70104076,ARL
2025-07-17T13:46:45.786579604Z,2025-07-17T13:46:45.786413307Z,160,2,1108,C,B,13.120000000,2,0,85194077,0,166297,70834235,ARL
2025-07-17T13:46:45.786579604Z,2025-07-17T13:46:45.786413307Z,160,2,1108,A,B,13.200000000,2,0,86056033,130,166297,70834235,ARL
2025-07-17T13:47:34.987167177Z,2025-07-17T13:47:34.987001473Z,160,2,1108,C,B,13.200000000,2,0,86056033,0,165704,72269967,ARL
2025-07-17T13:47:34.987167177Z,2025-07-17T13:47:34.987001473Z,160,2,1108,A,B,13.260000000,2,0,87750309,130,165704,72269967,ARL
2025-07-17T13:49:46.533586484Z,2025-07-17T13:49:46.533420775Z,160,2,1108,C,A,14.300000000,100,0,77910357,0,165709,76393090,ARL
2025-07-17T13:49:46.533586484Z,2025-07-17T13:49:46.533420775Z,160,2,1108,A,A,15.260000000,100,0,92510725,130,165709,76393090,ARL
2025-07-17T13:49:46.533732414Z,2025-07-17T13:49:46.533566805Z,160,2,1108,C,A,14.300000000,100,0,74589605,0,165609,76393092,ARL
2025-07-17T13:49:46.533732414Z,2025-07-17T13:49:46.533566805Z,160,2,1108,A,A,15.260000000,100,0,92510729,130,165609,76393092,ARL
2025-07-17T13:49:46.533768662Z,2025-07-17T13:49:46.533603070Z,160,2,1108,C,A,14.910000000,700,0,84628761,130,165592,76393093,ARL
2025-07-17T13:49:46.533810238Z,2025-07-17T13:49:46.533644528Z,160,2,1108,A,A,15.070000000,700,0,92510741,130,165710,76393094,ARL
2025-07-17T13:49:46.534488891Z,2025-07-17T13:49:46.534323177Z,160,2,1108,C,A,15.410000000,100,0,84630217,0,165714,76393099,ARL
2025-07-17T13:49:46.534488891Z,2025-07-17T13:49:46.534323177Z,160,2,1108,A,A,15.460000000,100,0,92510753,130,165714,76393099,ARL
2025-07-17T13:49:46.534555834Z,2025-07-17T13:49:46.534390219Z,160,2,1108,C,A,15.200000000,100,0,84628801,0,165615,76393100,ARL
2025-07-17T13:49:46.534555834Z,2025-07-17T13:49:46.534390219Z,160,2,1108,A,A,15.360000000,100,0,92510761,130,165615,76393100,ARL
2025-07-17T13:49:46.535182699Z,2025-07-17T13:49:46.535017084Z,160,2,1108,C,A,16.350000000,100,0,84629065,0,165615,76393115,ARL
2025-07-17T13:49:46.535182699Z,2025-07-17T13:49:46.535017084Z,160,2,1108,A,A,16.510000000,100,0,92510813,130,165615,76393115,ARL
2025-07-17T13:49:46.535737854Z,2025-07-17T13:49:46.535572067Z,160,2,1108,C,A,18.050000000,100,0,84628913,0,165787,76393138,ARL
2025-07-17T13:49:46.535737854Z,2025-07-17T13:49:46.535572067Z,160,2,1108,A,A,18.230000000,100,0,92510841,130,165787,76393138,ARL
2025-07-17T13:56:11.001810226Z,2025-07-17T13:56:11.001642441Z,160,2,1108,A,B,13.280000000,1,0,107702381,128,167785,89819278,ARL
2025-07-17T13:56:11.005550129Z,2025-07-17T13:56:11.005384065Z,160,2,1108,A,B,13.280000000,10,0,107702861,130,166064,89819705,ARL
2025-07-17T13:56:11.005550669Z,2025-07-17T13:56:11.005385425Z,160,2,1108,A,A,13.940000000,10,0,107702865,130,165244,89819706,ARL
2025-07-17T13:56:11.013819857Z,2025-07-17T13:56:11.013654317Z,160,2,1108,C,A,15.260000000,100,0,92510729,0,165540,89820163,ARL
2025-07-17T13:56:11.013819857Z,2025-07-17T13:56:11.013654317Z,160,2,1108,A,A,14.840000000,100,0,107703205,130,165540,89820163,ARL
2025-07-17T13:56:11.026680779Z,2025-07-17T13:56:11.026515306Z,160,2,1108,C,A,15.260000000,100,0,92510725,0,165473,89820408,ARL
2025-07-17T13:56:11.026680779Z,2025-07-17T13:56:11.026515306Z,160,2,1108,A,A,14.840000000,100,0,107703433,130,165473,89820408,ARL
2025-07-17T13:56:11.101916770Z,2025-07-17T13:56:11.101751649Z,160,2,1108,C,B,13.280000000,1,0,107702381,130,165121,89823845,ARL
2025-07-17T13:56:19.511755342Z,2025-07-17T13:56:19.511590204Z,160,2,1108,C,B,13.280000000,10,0,107702861,130,165138,90148349,ARL
2025-07-17T13:56:22.512134723Z,2025-07-17T13:56:22.511968820Z,160,2,1108,C,A,13.940000000,10,0,107702865,130,165903,90281309,ARL
2025-07-17T13:56:22.517155918Z,2025-07-17T13:56:22.516990420Z,160,2,1108,C,A,14.840000000,100,0,107703205,0,165498,90281853,ARL
2025-07-17T13:56:22.517155918Z,2025-07-17T13:56:22.516990420Z,160,2,1108,A,A,15.260000000,100,0,108217045,130,165498,90281853,ARL
2025-07-17T13:56:22.517527654Z,2025-07-17T13:56:22.517362170Z,160,2,1108,C,A,14.840000000,100,0,107703433,0,165484,90281893,ARL
2025-07-17T13:56:22.517527654Z,2025-07-17T13:56:22.517362170Z,160,2,1108,A,A,15.260000000,100,0,108217173,130,165484,90281893,ARL
2025-07-17T13:56:40.757800894Z,2025-07-17T13:56:40.757635216Z,160,2,1108,C,A,14.200000000,2,0,84628773,0,165678,90866180,ARL
2025-07-17T13:56:40.757800894Z,2025-07-17T13:56:40.757635216Z,160,2,1108,A,A,14.360000000,2,0,108872153,130,165678,90866180,ARL
2025-07-17T13:57:40.142022323Z,2025-07-17T13:57:40.141855674Z,160,2,1108,C,B,13.260000000,2,0,87750309,0,166649,92821039,ARL
2025-07-17T13:57:40.142022323Z,2025-07-17T13:57:40.141855674Z,160,2,1108,A,B,13.120000000,2,0,111169049,128,166649,92821039,ARL
2025-07-17T13:57:44.947757237Z,2025-07-17T13:57:44.947591620Z,160,2,1108,C,A,14.360000000,2,0,108872153,0,165617,92961696,ARL
2025-07-17T13:57:44.947757237Z,2025-07-17T13:57:44.947591620Z,160,2,1108,A,A,14.500000000,2,0,111347121,130,165617,92961696,ARL
2025-07-17T13:59:50.477911158Z,2025-07-17T13:59:50.477745739Z,160,2,1108,C,B,13.250000000,11,0,44586753,130,165419,96389796,ARL
2025-07-17T13:59:50.479576984Z,2025-07-17T13:59:50.479411482Z,160,2,1108,C,B,12.360000000,100,0,43787977,0,165502,96389821,ARL
2025-07-17T13:59:50.479576984Z,2025-07-17T13:59:50.479411482Z,160,2,1108,A,B,12.510000000,100,0,115474337,130,165502,96389821,ARL
2025-07-17T13:59:50.480863637Z,2025-07-17T13:59:50.480698233Z,160,2,1108,C,B,12.360000000,100,0,43781537,0,165404,96389845,ARL
2025-07-17T13:59:50.480863637Z,2025-07-17T13:59:50.480698233Z,160,2,1108,A,B,12.510000000,100,0,115474357,130,165404,96389845,ARL
2025-07-17T14:00:00.063037446Z,2025-07-17T14:00:00.062872132Z,160,2,1108,A,B,13.110000000,100,0,115813253,130,165314,96673952,ARL
2025-07-17T14:00:00.063056200Z,2025-07-17T14:00:00.062890891Z,160,2,1108,A,A,14.510000000,100,0,115813261,130,165309,96673954,ARL
2025-07-17T14:02:01.157985602Z,2025-07-17T14:02:01.157819863Z,160,2,1108,C,B,13.120000000,2,0,111169049,0,165739,101310413,ARL
2025-07-17T14:02:01.157985602Z,2025-07-17T14:02:01.157819863Z,160,2,1108,A,B,13.260000000,2,0,121098337,130,165739,101310413,ARL
2025-07-17T14:02:01.157986499Z,2025-07-17T14:02:01.157820985Z,160,2,1108,C,A,14.500000000,2,0,111347121,0,165514,101310414,ARL
2025-07-17T14:02:01.157986499Z,2025-07-17T14:02:01.157820985Z,160,2,1108,A,A,14.360000000,2,0,121098341,130,165514,101310414,ARL
2025-07-17T14:02:01.283528838Z,2025-07-17T14:02:01.283363185Z,160,2,1108,C,B,13.110000000,100,0,115813253,0,165653,101317376,ARL
2025-07-17T14:02:01.283528838Z,2025-07-17T14:02:01.283363185Z,160,2,1108,A,B,13.250000000,100,0,121107957,130,165653,101317376,ARL
2025-07-17T14:02:01.283544588Z,2025-07-17T14:02:01.283378637Z,160,2,1108,C,A,14.510000000,100,0,115813261,0,165951,101317377,ARL
2025-07-17T14:02:01.283544588Z,2025-07-17T14:02:01.283378637Z,160,2,1108,A,A,14.370000000,100,0,121107961,130,165951,101317377,ARL
2025-07-17T14:04:21.248906318Z,2025-07-17T14:04:21.248740930Z,160,2,1108,A,A,14.350000000,1,0,126872197,130,165388,106336852,ARL
2025-07-17T14:04:21.250325900Z,2025-07-17T14:04:21.250160548Z,160,2,1108,C,B,12.510000000,100,0,115474357,0,165352,106336976,ARL
2025-07-17T14:04:21.250325900Z,2025-07-17T14:04:21.250160548Z,160,2,1108,A,B,12.360000000,100,0,126872345,130,165352,106336976,ARL
2025-07-17T14:04:21.250797741Z,2025-07-17T14:04:21.250632048Z,160,2,1108,C,B,12.510000000,100,0,115474337,0,165693,106337002,ARL
2025-07-17T14:04:21.250797741Z,2025-07-17T14:04:21.250632048Z,160,2,1108,A,B,12.360000000,100,0,126872361,130,165693,106337002,ARL
2025-07-17T14:04:21.350207939Z,2025-07-17T14:04:21.350041949Z,160,2,1108,C,A,14.350000000,1,0,126872197,128,165990,106339204,ARL
2025-07-17T14:04:54.699926747Z,2025-07-17T14:04:54.699761263Z,160,2,1108,C,A,15.460000000,100,0,92510753,0,165484,107313441,ARL
2025-07-17T14:04:54.699926747Z,2025-07-17T14:04:54.699761263Z,160,2,1108,A,A,15.340000000,100,0,127999501,130,165484,107313441,ARL
2025-07-17T14:05:10.258855609Z,2025-07-17T14:05:10.258689253Z,160,2,1108,A,A,14.080000000,1,0,128570149,130,166356,107833096,ARL
2025-07-17T14:05:10.259513876Z,2025-07-17T14:05:10.259348471Z,160,2,1108,C,A,15.260000000,100,0,108217173,0,165405,107833168,ARL
2025-07-17T14:05:10.259513876Z,2025-07-17T14:05:10.259348471Z,160,2,1108,A,A,14.980000000,100,0,128570229,130,165405,107833168,ARL
2025-07-17T14:05:10.259895236Z,2025-07-17T14:05:10.259729446Z,160,2,1108,C,A,15.260000000,100,0,108217045,0,165790,107833188,ARL
2025-07-17T14:05:10.259895236Z,2025-07-17T14:05:10.259729446Z,160,2,1108,A,A,14.980000000,100,0,128570237,130,165790,107833188,ARL
2025-07-17T14:05:10.262461863Z,2025-07-17T14:05:10.262295631Z,160,2,1108,C,A,14.370000000,100,0,121107961,0,166232,107833310,ARL
2025-07-17T14:05:10.262461863Z,2025-07-17T14:05:10.262295631Z,160,2,1108,A,A,14.090000000,100,0,128570317,130,166232,107833310,ARL
2025-07-17T14:05:10.262866527Z,2025-07-17T14:05:10.262701351Z,160,2,1108,C,A,14.080000000,1,0,128570149,130,165176,107833359,ARL
2025-07-17T14:05:10.263188035Z,2025-07-17T14:05:10.263022539Z,160,2,1108,C,A,15.340000000,100,0,127999501,0,165496,107833371,ARL
2025-07-17T14:05:10.263188035Z,2025-07-17T14:05:10.263022539Z,160,2,1108,A,A,15.180000000,100,0,128570417,130,165496,107833371,ARL
2025-07-17T14:05:10.264495078Z,2025-07-17T14:05:10.264329670Z,160,2,1108,C,A,15.360000000,100,0,92510761,0,165408,107833404,ARL
2025-07-17T14:05:10.264495078Z,2025-07-17T14:05:10.264329670Z,160,2,1108,A,A,15.080000000,100,0,128570449,130,165408,107833404,ARL
2025-07-17T14:05:10.264590318Z,2025-07-17T14:05:10.264425026Z,160,2,1108,C,A,15.090000000,100,0,84650629,130,165292,107833406,ARL
2025-07-17T14:05:10.264715723Z,2025-07-17T14:05:10.264550510Z,160,2,1108,A,A,14.890000000,100,0,128570453,130,165213,107833407,ARL
2025-07-17T14:05:10.269943051Z,2025-07-17T14:05:10.269777131Z,160,2,1108,C,A,14.590000000,100,0,84629329,128,165920,107833716,ARL
2025-07-17T14:05:10.269997960Z,2025-07-17T14:05:10.269832842Z,160,2,1108,A,A,14.370000000,100,0,128570621,130,165118,107833720,ARL
2025-07-17T14:05:10.271865423Z,2025-07-17T14:05:10.271699633Z,160,2,1108,C,A,18.230000000,100,0,92510841,0,165790,107833881,ARL
2025-07-17T14:05:10.271865423Z,2025-07-17T14:05:10.271699633Z,160,2,1108,A,A,17.900000000,100,0,128570685,130,165790,107833881,ARL
2025-07-17T14:05:10.276320920Z,2025-07-17T14:05:10.276155439Z,160,2,1108,C,A,16.510000000,100,0,92510813,0,165481,107834635,ARL
2025-07-17T14:05:10.276320920Z,2025-07-17T14:05:10.276155439Z,160,2,1108,A,A,16.210000000,100,0,128570977,130,165481,107834635,ARL
2025-07-17T14:05:10.342982797Z,2025-07-17T14:05:10.342817229Z,160,2,1108,C,A,15.310000000,100,0,84630849,0,165568,107837761,ARL
2025-07-17T14:05:10.342982797Z,2025-07-17T14:05:10.342817229Z,160,2,1108,A,A,15.080000000,100,0,128573957,130,165568,107837761,ARL
2025-07-17T14:05:31.418741362Z,2025-07-17T14:05:31.418575692Z,160,2,1108,C,A,14.360000000,2,0,121098341,0,165670,108664911,ARL
2025-07-17T14:05:31.418741362Z,2025-07-17T14:05:31.418575692Z,160,2,1108,A,A,14.260000000,2,0,129518753,130,165670,108664911,ARL
2025-07-17T14:06:01.386006059Z,2025-07-17T14:06:01.385840471Z,160,2,1108,C,B,13.260000000,2,0,121098337,0,165588,109685525,ARL
2025-07-17T14:06:01.386006059Z,2025-07-17T14:06:01.385840471Z,160,2,1108,A,B,13.150000000,2,0,130693973,130,165588,109685525,ARL
2025-07-17T14:13:11.346377890Z,2025-07-17T14:13:11.346212166Z,160,2,1108,C,A,15.180000000,100,0,128570417,0,165724,123937587,ARL
2025-07-17T14:13:11.346377890Z,2025-07-17T14:13:11.346212166Z,160,2,1108,A,A,15.090000000,100,0,146955361,130,165724,123937587,ARL
2025-07-17T14:13:11.358916626Z,2025-07-17T14:13:11.358751092Z,160,2,1108,C,A,14.370000000,100,0,128570621,130,165534,123938202,ARL
2025-07-17T14:13:11.358968656Z,2025-07-17T14:13:11.358802966Z,160,2,1108,A,A,14.280000000,100,0,146956357,130,165690,123938203,ARL
2025-07-17T14:13:11.393088913Z,2025-07-17T14:13:11.392923396Z,160,2,1108,C,A,15.730000000,100,0,84629953,0,165517,123939815,ARL
2025-07-17T14:13:11.393088913Z,2025-07-17T14:13:11.392923396Z,160,2,1108,A,A,15.400000000,100,0,146959177,130,165517,123939815,ARL
2025-07-17T14:13:11.423482323Z,2025-07-17T14:13:11.423316840Z,160,2,1108,A,A,14.560000000,100,0,146960005,130,165483,123940437,ARL
2025-07-17T14:13:11.423483431Z,2025-07-17T14:13:11.423317922Z,160,2,1108,C,A,14.870000000,100,0,84708037,130,165509,123940438,ARL
2025-07-17T14:13:11.555808541Z,2025-07-17T14:13:11.555642984Z,160,2,1108,A,A,14.840000000,100,0,146962993,130,165557,123942727,ARL
2025-07-17T14:13:11.555828856Z,2025-07-17T14:13:11.555663413Z,160,2,1108,C,A,15.160000000,100,0,84668677,130,165443,123942728,ARL
2025-07-17T14:13:19.230983072Z,2025-07-17T14:13:19.230817808Z,160,2,1108,A,A,14.910000000,700,0,147217629,130,165264,124169794,ARL
2025-07-17T14:13:19.231778755Z,2025-07-17T14:13:19.231613044Z,160,2,1108,C,A,15.140000000,700,0,84628829,130,165711,124169802,ARL
2025-07-17T14:22:28.338174848Z,2025-07-17T14:22:28.338009329Z,160,2,1108,A,A,14.000000000,1,0,168073025,130,165519,142657338,ARL
2025-07-17T14:22:29.994011311Z,2025-07-17T14:22:29.993845812Z,160,2,1108,C,A,14.090000000,100,0,128570317,0,165499,142715813,ARL
2025-07-17T14:22:29.994011311Z,2025-07-17T14:22:29.993845812Z,160,2,1108,A,A,14.010000000,100,0,168141389,130,165499,142715813,ARL
2025-07-17T14:32:58.233129156Z,2025-07-17T14:32:58.232963791Z,160,2,1108,C,B,13.250000000,100,0,121107957,130,165365,162140358,ARL
2025-07-17T14:32:58.714015555Z,2025-07-17T14:32:58.713850212Z,160,2,1108,A,B,13.140000000,100,0,190326921,130,165343,162149922,ARL
2025-07-17T14:34:48.346344959Z,2025-07-17T14:34:48.346179643Z,160,2,1108,C,A,14.000000000,1,0,168073025,130,165316,164925706,ARL
2025-07-17T14:47:30.548081358Z,2025-07-17T14:47:30.547915870Z,160,2,1108,A,B,13.380000000,33,0,215999733,130,165488,183466992,ARL
2025-07-17T14:47:30.548346701Z,2025-07-17T14:47:30.548180936Z,160,2,1108,C,B,13.140000000,100,0,190326921,0,165765,183466994,ARL
2025-07-17T14:47:30.548346701Z,2025-07-17T14:47:30.548180936Z,160,2,1108,A,B,13.370000000,100,0,215999737,130,165765,183466994,ARL
2025-07-17T14:47:30.548831608Z,2025-07-17T14:47:30.548666035Z,160,2,1108,C,B,12.360000000,100,0,126872345,0,165573,183467001,ARL
2025-07-17T14:47:30.548831608Z,2025-07-17T14:47:30.548666035Z,160,2,1108,A,B,12.480000000,100,0,215999741,130,165573,183467001,ARL
2025-07-17T14:47:30.549090785Z,2025-07-17T14:47:30.548925394Z,160,2,1108,C,B,12.230000000,100,0,43317473,0,165391,183467002,ARL
2025-07-17T14:47:30.549090785Z,2025-07-17T14:47:30.548925394Z,160,2,1108,A,B,12.330000000,100,0,215999753,130,165391,183467002,ARL
2025-07-17T14:47:30.549341156Z,2025-07-17T14:47:30.549175659Z,160,2,1108,C,B,12.360000000,100,0,126872361,0,165497,183467004,ARL
2025-07-17T14:47:30.549341156Z,2025-07-17T14:47:30.549175659Z,160,2,1108,A,B,12.480000000,100,0,215999761,130,165497,183467004,ARL
2025-07-17T14:47:30.571385383Z,2025-07-17T14:47:30.571220121Z,160,2,1108,C,B,12.990000000,100,0,43805737,130,165262,183468111,ARL
2025-07-17T14:47:30.571436944Z,2025-07-17T14:47:30.571271737Z,160,2,1108,A,B,13.100000000,100,0,216001413,130,165207,183468112,ARL
2025-07-17T14:47:37.384610677Z,2025-07-17T14:47:37.384441232Z,160,2,1108,A,B,12.500000000,700,0,216223005,130,169445,183649796,ARL
2025-07-17T14:47:37.385400265Z,2025-07-17T14:47:37.385234288Z,160,2,1108,C,B,12.260000000,700,0,44570585,130,165977,183649801,ARL
2025-07-17T14:52:02.610481877Z,2025-07-17T14:52:02.610315566Z,160,2,1108,T,N,13.410000000,1,0,0,130,166311,189559140,ARL
2025-07-17T14:52:02.610509102Z,2025-07-17T14:52:02.610343819Z,160,2,1108,A,A,13.710000000,1,0,223347833,130,165283,189559141,ARL
2025-07-17T14:52:02.611701408Z,2025-07-17T14:52:02.611536221Z,160,2,1108,C,A,13.710000000,1,0,223347833,130,165187,189559156,ARL
2025-07-17T15:00:11.560678862Z,2025-07-17T15:00:11.560513555Z,160,2,1108,C,B,13.380000000,33,0,215999733,130,165307,200140364,ARL
2025-07-17T15:00:11.563053782Z,2025-07-17T15:00:11.562887948Z,160,2,1108,C,B,12.480000000,100,0,215999761,0,165834,200140389,ARL
2025-07-17T15:00:11.563053782Z,2025-07-17T15:00:11.562887948Z,160,2,1108,A,B,12.650000000,100,0,236179089,130,165834,200140389,ARL
2025-07-17T15:00:12.536218524Z,2025-07-17T15:00:12.536052536Z,160,2,1108,C,B,12.480000000,100,0,215999741,0,165988,200161810,ARL
2025-07-17T15:00:12.536218524Z,2025-07-17T15:00:12.536052536Z,160,2,1108,A,B,12.650000000,100,0,236206261,130,165988,200161810,ARL
2025-07-17T15:01:11.658789910Z,2025-07-17T15:01:11.658624662Z,160,2,1108,A,A,13.980000000,10,0,237940713,130,165248,201616674,ARL
2025-07-17T15:01:12.948386121Z,2025-07-17T15:01:12.948220412Z,160,2,1108,C,A,14.010000000,100,0,168141389,0,165709,201642675,ARL
2025-07-17T15:01:12.948386121Z,2025-07-17T15:01:12.948220412Z,160,2,1108,A,A,13.990000000,100,0,237978541,130,165709,201642675,ARL
2025-07-17T15:01:12.949124493Z,2025-07-17T15:01:12.948959226Z,160,2,1108,C,A,14.830000000,100,0,84628793,130,165267,201642712,ARL
2025-07-17T15:01:12.949484115Z,2025-07-17T15:01:12.949317198Z,160,2,1108,A,A,14.610000000,100,0,237978629,130,166917,201642747,ARL
2025-07-17T15:01:26.963916368Z,2025-07-17T15:01:26.963746832Z,160,2,1108,C,A,13.980000000,10,0,237940713,128,169536,201984003,ARL
2025-07-17T15:01:37.513312432Z,2025-07-17T15:01:37.513147090Z,160,2,1108,A,A,13.980000000,10,0,238668633,130,165342,202186180,ARL
2025-07-17T15:05:36.047202557Z,2025-07-17T15:05:36.047029298Z,160,2,1108,C,A,13.980000000,10,0,238668633,128,173259,207097179,ARL
2025-07-17T15:10:34.469866273Z,2025-07-17T15:10:34.469700487Z,160,2,1108,C,A,14.260000000,2,0,129518753,0,165786,213735006,ARL
2025-07-17T15:10:34.469866273Z,2025-07-17T15:10:34.469700487Z,160,2,1108,A,A,14.170000000,2,0,252720897,130,165786,213735006,ARL
2025-07-17T15:12:52.735414592Z,2025-07-17T15:12:52.735249178Z,160,2,1108,A,A,14.030000000,100,0,256325129,130,165414,216651092,ARL
2025-07-17T15:13:06.511853457Z,2025-07-17T15:13:06.511687613Z,160,2,1108,A,A,13.980000000,10,0,256739841,130,165844,216995105,ARL
2025-07-17T15:13:08.654089411Z,2025-07-17T15:13:08.653923821Z,160,2,1108,A,A,14.010000000,100,0,256818881,130,165590,217058300,ARL
2025-07-17T15:13:08.661686458Z,2025-07-17T15:13:08.661521116Z,160,2,1108,C,A,14.030000000,100,0,256325129,130,165342,217058550,ARL
2025-07-17T15:14:00.440728359Z,2025-07-17T15:14:00.440563034Z,160,2,1108,C,A,13.980000000,10,0,256739841,130,165325,218096891,ARL
2025-07-17T15:14:52.382139830Z,2025-07-17T15:14:52.381974473Z,160,2,1108,A,A,13.980000000,10,0,259546169,130,165357,219204095,ARL
2025-07-17T15:14:56.683309707Z,2025-07-17T15:14:56.683144163Z,160,2,1108,C,A,14.010000000,100,0,256818881,130,165544,219317677,ARL
2025-07-17T15:15:11.661118778Z,2025-07-17T15:15:11.660953613Z,160,2,1108,A,A,14.020000000,100,0,260184621,130,165165,219726276,ARL
2025-07-17T15:15:32.408863263Z,2025-07-17T15:15:32.408694312Z,160,2,1108,C,A,13.980000000,10,0,259546169,128,168951,220152194,ARL
2025-07-17T15:16:31.607242914Z,2025-07-17T15:16:31.607077080Z,160,2,1108,A,A,14.000000000,100,0,262279553,130,165834,221423516,ARL
2025-07-17T15:16:31.614370696Z,2025-07-17T15:16:31.614205345Z,160,2,1108,C,A,14.020000000,100,0,260184621,130,165351,221423706,ARL
2025-07-17T15:16:39.373467449Z,2025-07-17T15:16:39.373301585Z,160,2,1108,A,A,13.980000000,10,0,262432821,130,165864,221549244,ARL
2025-07-17T15:17:50.916325497Z,2025-07-17T15:17:50.916157330Z,160,2,1108,C,A,13.980000000,10,0,262432821,130,168167,223060323,ARL
2025-07-17T15:17:51.938467389Z,2025-07-17T15:17:51.938301087Z,160,2,1108,C,A,14.000000000,100,0,262279553,130,166302,223092013,ARL
2025-07-17T15:17:55.957423821Z,2025-07-17T15:17:55.957258362Z,160,2,1108,A,A,14.010000000,100,0,264420961,130,165459,223181022,ARL
2025-07-17T15:19:23.618380576Z,2025-07-17T15:19:23.618215364Z,160,2,1108,C,A,14.010000000,100,0,264420961,130,165212,224925658,ARL
2025-07-17T15:19:27.663790911Z,2025-07-17T15:19:27.663625107Z,160,2,1108,A,A,14.030000000,100,0,266714557,130,165804,224999109,ARL
2025-07-17T15:20:46.705145876Z,2025-07-17T15:20:46.704980311Z,160,2,1108,A,A,14.010000000,100,0,269075833,130,165565,226851430,ARL
2025-07-17T15:20:46.716698477Z,2025-07-17T15:20:46.716532886Z,160,2,1108,C,A,14.030000000,100,0,266714557,130,165591,226851533,ARL
2025-07-17T15:23:00.249962772Z,2025-07-17T15:23:00.249796874Z,160,2,1108,C,B,13.150000000,2,0,130693973,0,165898,229397485,ARL
2025-07-17T15:23:00.249962772Z,2025-07-17T15:23:00.249796874Z,160,2,1108,A,B,13.230000000,2,0,272263853,130,165898,229397485,ARL
2025-07-17T15:26:04.666158860Z,2025-07-17T15:26:04.665993515Z,160,2,1108,C,A,14.170000000,2,0,252720897,0,165345,232977340,ARL
2025-07-17T15:26:04.666158860Z,2025-07-17T15:26:04.665993515Z,160,2,1108,A,A,14.090000000,2,0,276751517,130,165345,232977340,ARL
2025-07-17T15:28:38.882985923Z,2025-07-17T15:28:38.882820591Z,160,2,1108,A,A,13.990000000,100,0,280387693,130,165332,235874491,ARL
2025-07-17T15:28:38.890789214Z,2025-07-17T15:28:38.890623989Z,160,2,1108,C,A,14.010000000,100,0,269075833,130,165225,235874556,ARL
2025-07-17T15:28:44.820934614Z,2025-07-17T15:28:44.820769301Z,160,2,1108,C,A,13.990000000,100,0,280387693,130,165313,235961324,ARL
2025-07-17T15:28:48.918811203Z,2025-07-17T15:28:48.918645728Z,160,2,1108,A,A,14.010000000,100,0,280580873,130,165475,236028551,ARL
2025-07-17T15:30:23.573233259Z,2025-07-17T15:30:23.573067851Z,160,2,1108,A,A,13.820000000,10,0,282775557,130,165408,237754758,ARL
2025-07-17T15:30:23.573528359Z,2025-07-17T15:30:23.573362522Z,160,2,1108,C,A,14.980000000,100,0,128570237,0,165837,237754762,ARL
2025-07-17T15:30:23.573528359Z,2025-07-17T15:30:23.573362522Z,160,2,1108,A,A,14.720000000,100,0,282775561,130,165837,237754762,ARL
2025-07-17T15:30:23.574854165Z,2025-07-17T15:30:23.574688647Z,160,2,1108,C,A,14.980000000,100,0,128570229,0,165518,237754776,ARL
2025-07-17T15:30:23.574854165Z,2025-07-17T15:30:23.574688647Z,160,2,1108,A,A,14.720000000,100,0,282775577,130,165518,237754776,ARL
2025-07-17T15:30:23.585191081Z,2025-07-17T15:30:23.585025490Z,160,2,1108,A,A,13.840000000,100,0,282775973,130,165591,237755075,ARL
2025-07-17T15:30:23.585960886Z,2025-07-17T15:30:23.585795327Z,160,2,1108,C,A,15.090000000,100,0,146955361,0,165559,237755081,ARL
2025-07-17T15:30:23.585960886Z,2025-07-17T15:30:23.585795327Z,160,2,1108,A,A,14.910000000,100,0,282776009,130,165559,237755081,ARL
2025-07-17T15:30:23.586719371Z,2025-07-17T15:30:23.586553674Z,160,2,1108,C,A,14.890000000,100,0,128570453,0,165697,237755086,ARL
2025-07-17T15:30:23.586719371Z,2025-07-17T15:30:23.586553674Z,160,2,1108,A,A,14.650000000,100,0,282776013,130,165697,237755086,ARL
2025-07-17T15:30:23.586762105Z,2025-07-17T15:30:23.586596452Z,160,2,1108,C,A,15.640000000,100,0,84628833,0,165653,237755087,ARL
2025-07-17T15:30:23.586762105Z,2025-07-17T15:30:23.586596452Z,160,2,1108,A,A,15.230000000,100,0,282776017,130,165653,237755087,ARL
2025-07-17T15:30:23.587432517Z,2025-07-17T15:30:23.587267064Z,160,2,1108,C,A,17.900000000,100,0,128570685,0,165453,237755097,ARL
2025-07-17T15:30:23.587432517Z,2025-07-17T15:30:23.587267064Z,160,2,1108,A,A,17.580000000,100,0,282776025,130,165453,237755097,ARL
2025-07-17T15:30:23.587581881Z,2025-07-17T15:30:23.587416236Z,160,2,1108,C,A,15.080000000,100,0,128570449,0,165645,237755098,ARL
2025-07-17T15:30:23.587581881Z,2025-07-17T15:30:23.587416236Z,160,2,1108,A,A,14.810000000,100,0,282776029,130,165645,237755098,ARL
2025-07-17T15:30:23.587611440Z,2025-07-17T15:30:23.587445922Z,160,2,1108,C,A,16.210000000,100,0,128570977,0,165518,237755099,ARL
2025-07-17T15:30:23.587611440Z,2025-07-17T15:30:23.587445922Z,160,2,1108,A,A,15.920000000,100,0,282776033,130,165518,237755099,ARL
2025-07-17T15:30:23.590261792Z,2025-07-17T15:30:23.590096343Z,160,2,1108,C,A,15.080000000,100,0,128573957,0,165449,237755128,ARL
2025-07-17T15:30:23.590261792Z,2025-07-17T15:30:23.590096343Z,160,2,1108,A,A,14.810000000,100,0,282776089,130,165449,237755128,ARL
2025-07-17T15:30:23.591959120Z,2025-07-17T15:30:23.591793735Z,160,2,1108,C,A,14.010000000,100,0,280580873,130,165385,237755138,ARL
2025-07-17T15:30:23.602992439Z,2025-07-17T15:30:23.602827102Z,160,2,1108,C,A,14.280000000,100,0,146956357,130,165337,237755229,ARL
2025-07-17T15:30:23.603046460Z,2025-07-17T15:30:23.602881129Z,160,2,1108,A,A,14.120000000,100,0,282776285,130,165331,237755230,ARL
2025-07-17T15:30:23.628720816Z,2025-07-17T15:30:23.628555135Z,160,2,1108,A,A,15.780000000,100,0,282776733,130,165681,237755415,ARL
2025-07-17T15:30:23.628732597Z,2025-07-17T15:30:23.628567293Z,160,2,1108,C,A,16.200000000,100,0,84628765,130,165304,237755416,ARL
2025-07-17T15:30:23.952122580Z,2025-07-17T15:30:23.951957017Z,160,2,1108,C,A,13.990000000,100,0,237978541,0,165563,237759683,ARL
2025-07-17T15:30:23.952122580Z,2025-07-17T15:30:23.951957017Z,160,2,1108,A,A,13.830000000,100,0,282781741,130,165563,237759683,ARL
2025-07-17T15:30:24.769074814Z,2025-07-17T15:30:24.768909757Z,160,2,1108,C,A,13.820000000,10,0,282775557,130,165057,237771822,ARL
2025-07-17T15:30:28.617337198Z,2025-07-17T15:30:28.617171810Z,160,2,1108,A,A,14.530000000,700,0,282881853,130,165388,237840336,ARL
2025-07-17T15:30:28.617387294Z,2025-07-17T15:30:28.617221981Z,160,2,1108,C,A,15.070000000,700,0,92510741,130,165313,237840337,ARL
2025-07-17T15:30:30.767213907Z,2025-07-17T15:30:30.767048606Z,160,2,1108,A,A,14.600000000,700,0,282920685,130,165301,237873135,ARL
2025-07-17T15:30:30.767267001Z,2025-07-17T15:30:30.767101317Z,160,2,1108,C,A,14.990000000,700,0,84628757,130,165684,237873136,ARL
2025-07-17T15:30:33.016987097Z,2025-07-17T15:30:33.016821395Z,160,2,1108,A,A,14.560000000,700,0,282969973,130,165702,237915946,ARL
2025-07-17T15:30:33.017384279Z,2025-07-17T15:30:33.017218657Z,160,2,1108,C,A,14.950000000,700,0,84628797,130,165622,237915951,ARL
2025-07-17T15:30:49.985906754Z,2025-07-17T15:30:49.985741094Z,160,2,1108,C,A,14.090000000,2,0,276751517,0,165660,238230724,ARL
2025-07-17T15:30:49.985906754Z,2025-07-17T15:30:49.985741094Z,160,2,1108,A,A,14.020000000,2,0,283348193,130,165660,238230724,ARL
2025-07-17T15:30:59.996516554Z,2025-07-17T15:30:59.996351383Z,160,2,1108,C,A,13.830000000,100,0,282781741,130,165171,238442318,ARL
2025-07-17T15:31:00.002203922Z,2025-07-17T15:31:00.002038446Z,160,2,1108,C,A,13.840000000,100,0,282775973,130,165476,238442443,ARL
2025-07-17T15:31:00.002478393Z,2025-07-17T15:31:00.002313250Z,160,2,1108,C,A,14.530000000,700,0,282881853,130,165143,238442461,ARL
2025-07-17T15:31:00.002525213Z,2025-07-17T15:31:00.002359969Z,160,2,1108,A,A,14.680000000,700,0,283592941,130,165244,238442467,ARL
2025-07-17T15:31:00.002938332Z,2025-07-17T15:31:00.002772683Z,160,2,1108,C,A,14.720000000,100,0,282775577,0,165649,238442486,ARL
2025-07-17T15:31:00.002938332Z,2025-07-17T15:31:00.002772683Z,160,2,1108,A,A,14.970000000,100,0,283592993,130,165649,238442486,ARL
2025-07-17T15:31:00.002953704Z,2025-07-17T15:31:00.002788190Z,160,2,1108,C,A,14.910000000,100,0,282776009,0,165514,238442490,ARL
2025-07-17T15:31:00.002953704Z,2025-07-17T15:31:00.002788190Z,160,2,1108,A,A,14.960000000,100,0,283592997,130,165514,238442490,ARL
2025-07-17T15:31:00.003368272Z,2025-07-17T15:31:00.003202003Z,160,2,1108,C,A,14.720000000,100,0,282775561,0,166269,238442510,ARL
2025-07-17T15:31:00.003368272Z,2025-07-17T15:31:00.003202003Z,160,2,1108,A,A,14.970000000,100,0,283593041,130,166269,238442510,ARL
2025-07-17T15:31:00.006784947Z,2025-07-17T15:31:00.006618398Z,160,2,1108,C,A,14.650000000,100,0,282776013,130,166549,238442608,ARL
2025-07-17T15:31:00.006950491Z,2025-07-17T15:31:00.006784814Z,160,2,1108,A,A,14.790000000,100,0,283593313,130,165677,238442616,ARL
2025-07-17T15:31:00.017759891Z,2025-07-17T15:31:00.017594312Z,160,2,1108,C,A,17.580000000,100,0,282776025,0,165579,238443214,ARL
2025-07-17T15:31:00.017759891Z,2025-07-17T15:31:00.017594312Z,160,2,1108,A,A,17.760000000,100,0,283594173,130,165579,238443214,ARL
2025-07-17T15:31:00.028894478Z,2025-07-17T15:31:00.028729168Z,160,2,1108,C,A,14.120000000,100,0,282776285,130,165310,238443996,ARL
2025-07-17T15:31:00.028947312Z,2025-07-17T15:31:00.028782030Z,160,2,1108,A,A,14.260000000,100,0,283595181,130,165282,238443998,ARL
2025-07-17T15:31:00.053107210Z,2025-07-17T15:31:00.052941898Z,160,2,1108,C,A,14.960000000,100,0,283592997,0,165312,238444735,ARL
2025-07-17T15:31:00.053107210Z,2025-07-17T15:31:00.052941898Z,160,2,1108,A,A,15.060000000,100,0,283596673,130,165312,238444735,ARL
2025-07-17T15:31:00.054830847Z,2025-07-17T15:31:00.054665340Z,160,2,1108,C,A,14.810000000,100,0,282776089,0,165507,238444759,ARL
2025-07-17T15:31:00.054830847Z,2025-07-17T15:31:00.054665340Z,160,2,1108,A,A,14.960000000,100,0,283596721,130,165507,238444759,ARL
2025-07-17T15:31:00.071409275Z,2025-07-17T15:31:00.071243665Z,160,2,1108,C,A,14.810000000,100,0,282776029,0,165610,238444961,ARL
2025-07-17T15:31:00.071409275Z,2025-07-17T15:31:00.071243665Z,160,2,1108,A,A,14.960000000,100,0,283596945,130,165610,238444961,ARL
2025-07-17T15:31:00.243369582Z,2025-07-17T15:31:00.243203860Z,160,2,1108,C,A,15.920000000,100,0,282776033,0,165722,238447595,ARL
2025-07-17T15:31:00.243369582Z,2025-07-17T15:31:00.243203860Z,160,2,1108,A,A,16.080000000,100,0,283599609,130,165722,238447595,ARL
2025-07-17T15:31:00.347828545Z,2025-07-17T15:31:00.347663441Z,160,2,1108,A,A,14.030000000,100,0,283604173,130,165104,238450791,ARL
2025-07-17T15:31:04.014590575Z,2025-07-17T15:31:04.014425425Z,160,2,1108,A,A,14.000000000,100,0,283694233,130,165150,238529875,ARL
2025-07-17T15:31:04.124577845Z,2025-07-17T15:31:04.124411850Z,160,2,1108,C,A,14.030000000,100,0,283604173,0,165995,238531822,ARL
2025-07-17T15:31:04.124577845Z,2025-07-17T15:31:04.124411850Z,160,2,1108,A,A,14.010000000,100,0,283695933,130,165995,238531822,ARL
2025-07-17T15:32:28.644506279Z,2025-07-17T15:32:28.644335983Z,160,2,1108,A,B,13.550000000,10,0,285545121,128,170296,239938946,ARL
2025-07-17T15:32:28.653238729Z,2025-07-17T15:32:28.653073176Z,160,2,1108,C,B,13.370000000,100,0,215999737,0,165553,239940048,ARL
2025-07-17T15:32:28.653238729Z,2025-07-17T15:32:28.653073176Z,160,2,1108,A,B,13.540000000,100,0,285545885,130,165553,239940048,ARL
2025-07-17T15:32:28.653978501Z,2025-07-17T15:32:28.653812889Z,160,2,1108,C,B,12.330000000,100,0,215999753,0,165612,239940096,ARL
2025-07-17T15:32:28.653978501Z,2025-07-17T15:32:28.653812889Z,160,2,1108,A,B,12.490000000,100,0,285545945,130,165612,239940096,ARL
2025-07-17T15:32:28.653980648Z,2025-07-17T15:32:28.653815154Z,160,2,1108,C,B,12.670000000,100,0,43663229,130,165494,239940097,ARL
2025-07-17T15:32:28.654336987Z,2025-07-17T15:32:28.654171723Z,160,2,1108,A,B,12.940000000,100,0,285545953,130,165264,239940109,ARL
2025-07-17T15:32:28.657073743Z,2025-07-17T15:32:28.656908386Z,160,2,1108,C,B,12.470000000,100,0,43554133,130,165357,239940358,ARL
2025-07-17T15:32:28.657173856Z,2025-07-17T15:32:28.657008222Z,160,2,1108,A,B,12.730000000,100,0,285546061,130,165634,239940359,ARL
2025-07-17T15:32:28.667074437Z,2025-07-17T15:32:28.666909194Z,160,2,1108,C,B,13.100000000,100,0,216001413,130,165243,239940810,ARL
2025-07-17T15:32:28.667126637Z,2025-07-17T15:32:28.666961018Z,160,2,1108,A,B,13.270000000,100,0,285546673,130,165619,239940813,ARL
2025-07-17T15:32:28.674444711Z,2025-07-17T15:32:28.674279259Z,160,2,1108,C,B,12.330000000,100,0,43755813,0,165452,239941057,ARL
2025-07-17T15:32:28.674444711Z,2025-07-17T15:32:28.674279259Z,160,2,1108,A,B,12.590000000,100,0,285546893,130,165452,239941057,ARL
2025-07-17T15:32:28.691264796Z,2025-07-17T15:32:28.691099298Z,160,2,1108,C,B,9.670000000,100,0,44082961,0,165498,239941825,ARL
2025-07-17T15:32:28.691264796Z,2025-07-17T15:32:28.691099298Z,160,2,1108,A,B,9.880000000,100,0,285548137,130,165498,239941825,ARL
2025-07-17T15:32:28.711494526Z,2025-07-17T15:32:28.711329066Z,160,2,1108,C,B,11.270000000,100,0,43826785,0,165460,239942732,ARL
2025-07-17T15:32:28.711494526Z,2025-07-17T15:32:28.711329066Z,160,2,1108,A,B,11.500000000,100,0,285549537,130,165460,239942732,ARL
2025-07-17T15:32:28.771995987Z,2025-07-17T15:32:28.771830554Z,160,2,1108,C,B,13.550000000,10,0,285545121,128,165433,239945992,ARL
2025-07-17T15:32:28.806930722Z,2025-07-17T15:32:28.806765209Z,160,2,1108,C,B,12.330000000,100,0,44088633,0,165513,239948319,ARL
2025-07-17T15:32:28.806930722Z,2025-07-17T15:32:28.806765209Z,160,2,1108,A,B,12.590000000,100,0,285553901,130,165513,239948319,ARL
2025-07-17T15:32:28.850288215Z,2025-07-17T15:32:28.850122877Z,160,2,1108,A,A,13.980000000,100,0,285556869,130,165338,239950805,ARL
2025-07-17T15:32:28.857140107Z,2025-07-17T15:32:28.856973845Z,160,2,1108,C,A,14.000000000,100,0,283694233,130,166262,239951361,ARL
2025-07-17T15:32:29.573634202Z,2025-07-17T15:32:29.573469021Z,160,2,1108,C,B,13.540000000,100,0,285545885,130,165181,239975997,ARL
2025-07-17T15:32:29.574368326Z,2025-07-17T15:32:29.574202467Z,160,2,1108,C,B,12.490000000,100,0,285545945,0,165859,239976004,ARL
2025-07-17T15:32:29.574368326Z,2025-07-17T15:32:29.574202467Z,160,2,1108,A,B,12.270000000,100,0,285586089,130,165859,239976004,ARL
2025-07-17T15:32:29.574371866Z,2025-07-17T15:32:29.574206685Z,160,2,1108,C,B,12.940000000,100,0,285545953,130,165181,239976005,ARL
2025-07-17T15:32:29.574722141Z,2025-07-17T15:32:29.574556760Z,160,2,1108,A,B,12.710000000,100,0,285586093,130,165381,239976069,ARL
2025-07-17T15:32:29.575134655Z,2025-07-17T15:32:29.574968914Z,160,2,1108,C,B,12.590000000,100,0,285546893,0,165741,239976143,ARL
2025-07-17T15:32:29.575134655Z,2025-07-17T15:32:29.574968914Z,160,2,1108,A,B,12.340000000,100,0,285586113,130,165741,239976143,ARL
2025-07-17T15:32:29.575550333Z,2025-07-17T15:32:29.575384940Z,160,2,1108,C,B,11.500000000,100,0,285549537,0,165393,239976173,ARL
2025-07-17T15:32:29.575550333Z,2025-07-17T15:32:29.575384940Z,160,2,1108,A,B,11.270000000,100,0,285586145,130,165393,239976173,ARL
2025-07-17T15:32:29.575821091Z,2025-07-17T15:32:29.575655631Z,160,2,1108,C,B,9.880000000,100,0,285548137,0,165460,239976183,ARL
2025-07-17T15:32:29.575821091Z,2025-07-17T15:32:29.575655631Z,160,2,1108,A,B,9.680000000,100,0,285586157,130,165460,239976183,ARL
2025-07-17T15:32:29.578317238Z,2025-07-17T15:32:29.578151593Z,160,2,1108,C,B,12.590000000,100,0,285553901,0,165645,239976225,ARL
2025-07-17T15:32:29.578317238Z,2025-07-17T15:32:29.578151593Z,160,2,1108,A,B,12.340000000,100,0,285586189,130,165645,239976225,ARL
2025-07-17T15:32:29.580933155Z,2025-07-17T15:32:29.580767960Z,160,2,1108,A,B,13.260000000,100,0,285586221,130,165195,239976262,ARL
2025-07-17T15:32:29.580952045Z,2025-07-17T15:32:29.580786478Z,160,2,1108,C,A,14.010000000,100,0,283695933,0,165567,239976263,ARL
2025-07-17T15:32:29.580952045Z,2025-07-17T15:32:29.580786478Z,160,2,1108,A,A,13.990000000,100,0,285586225,130,165567,239976263,ARL
2025-07-17T15:32:29.587192852Z,2025-07-17T15:32:29.587027681Z,160,2,1108,C,B,13.270000000,100,0,285546673,130,165171,239976327,ARL
2025-07-17T15:32:29.587246470Z,2025-07-17T15:32:29.587081086Z,160,2,1108,A,B,13.030000000,100,0,285586293,130,165384,239976336,ARL
2025-07-17T15:32:29.659679280Z,2025-07-17T15:32:29.659513918Z,160,2,1108,C,B,12.730000000,100,0,285546061,0,165362,239977574,ARL
2025-07-17T15:32:29.659679280Z,2025-07-17T15:32:29.659513918Z,160,2,1108,A,B,12.460000000,100,0,285587281,130,165362,239977574,ARL
2025-07-17T15:33:04.248156868Z,2025-07-17T15:33:04.247990788Z,160,2,1108,C,A,14.970000000,100,0,283592993,0,166080,240885845,ARL
2025-07-17T15:33:04.248156868Z,2025-07-17T15:33:04.247990788Z,160,2,1108,A,A,14.720000000,100,0,286680573,130,166080,240885845,ARL
2025-07-17T15:33:04.248189408Z,2025-07-17T15:33:04.248023883Z,160,2,1108,C,A,14.970000000,100,0,283593041,0,165525,240885847,ARL
2025-07-17T15:33:04.248189408Z,2025-07-17T15:33:04.248023883Z,160,2,1108,A,A,14.720000000,100,0,286680577,130,165525,240885847,ARL
2025-07-17T15:33:04.255712050Z,2025-07-17T15:33:04.255546094Z,160,2,1108,A,A,13.840000000,100,0,286680685,130,165956,240886132,ARL
2025-07-17T15:33:04.255777981Z,2025-07-17T15:33:04.255612126Z,160,2,1108,C,B,12.270000000,100,0,285586089,0,165855,240886133,ARL
2025-07-17T15:33:04.255777981Z,2025-07-17T15:33:04.255612126Z,160,2,1108,A,B,12.230000000,100,0,286680693,130,165855,240886133,ARL
2025-07-17T15:33:04.256438228Z,2025-07-17T15:33:04.256272676Z,160,2,1108,C,A,15.060000000,100,0,283596673,0,165552,240886147,ARL
2025-07-17T15:33:04.256438228Z,2025-07-17T15:33:04.256272676Z,160,2,1108,A,A,14.910000000,100,0,286680721,130,165552,240886147,ARL
2025-07-17T15:33:04.258080504Z,2025-07-17T15:33:04.257914956Z,160,2,1108,C,A,14.960000000,100,0,283596945,0,165548,240886188,ARL
2025-07-17T15:33:04.258080504Z,2025-07-17T15:33:04.257914956Z,160,2,1108,A,A,14.810000000,100,0,286680741,130,165548,240886188,ARL
2025-07-17T15:33:04.261684319Z,2025-07-17T15:33:04.261518776Z,160,2,1108,C,A,14.790000000,100,0,283593313,0,165543,240886271,ARL
2025-07-17T15:33:04.261684319Z,2025-07-17T15:33:04.261518776Z,160,2,1108,A,A,14.650000000,100,0,286680905,130,165543,240886271,ARL
2025-07-17T15:33:04.263011314Z,2025-07-17T15:33:04.262845834Z,160,2,1108,C,A,14.260000000,100,0,283595181,130,165480,240886294,ARL
2025-07-17T15:33:04.263052660Z,2025-07-17T15:33:04.262887184Z,160,2,1108,C,A,13.980000000,100,0,285556869,130,165476,240886296,ARL
2025-07-17T15:33:04.263065252Z,2025-07-17T15:33:04.262899981Z,160,2,1108,A,A,14.120000000,100,0,286680917,130,165271,240886297,ARL
2025-07-17T15:33:04.271212113Z,2025-07-17T15:33:04.271046430Z,160,2,1108,C,A,17.760000000,100,0,283594173,0,165683,240886583,ARL
2025-07-17T15:33:04.271212113Z,2025-07-17T15:33:04.271046430Z,160,2,1108,A,A,17.580000000,100,0,286681057,130,165683,240886583,ARL
2025-07-17T15:33:04.277880725Z,2025-07-17T15:33:04.277715123Z,160,2,1108,C,A,16.080000000,100,0,283599609,0,165602,240886720,ARL
2025-07-17T15:33:04.277880725Z,2025-07-17T15:33:04.277715123Z,160,2,1108,A,A,15.920000000,100,0,286681229,130,165602,240886720,ARL
2025-07-17T15:33:04.418840148Z,2025-07-17T15:33:04.418674487Z,160,2,1108,C,A,14.960000000,100,0,283596721,0,165661,240888774,ARL
2025-07-17T15:33:04.418840148Z,2025-07-17T15:33:04.418674487Z,160,2,1108,A,A,14.810000000,100,0,286684005,130,165661,240888774,ARL
2025-07-17T15:33:05.330854217Z,2025-07-17T15:33:05.330688486Z,160,2,1108,C,A,13.990000000,100,0,285586225,0,165731,240911093,ARL
2025-07-17T15:33:05.330854217Z,2025-07-17T15:33:05.330688486Z,160,2,1108,A,A,13.850000000,100,0,286704785,130,165731,240911093,ARL
2025-07-17T15:33:06.455979270Z,2025-07-17T15:33:06.455814002Z,160,2,1108,C,A,13.840000000,100,0,286680685,130,165268,240936407,ARL
2025-07-17T15:33:10.468005342Z,2025-07-17T15:33:10.467840054Z,160,2,1108,A,A,13.870000000,100,0,286828253,130,165288,241000095,ARL
2025-07-17T15:33:40.986585803Z,2025-07-17T15:33:40.986420127Z,160,2,1108,C,A,14.020000000,2,0,283348193,0,165676,241593788,ARL
2025-07-17T15:33:40.986585803Z,2025-07-17T15:33:40.986420127Z,160,2,1108,A,A,13.950000000,2,0,287540393,130,165676,241593788,ARL
2025-07-17T15:33:41.766184571Z,2025-07-17T15:33:41.766018916Z,160,2,1108,A,A,13.820000000,10,0,287560109,130,165655,241612289,ARL
2025-07-17T15:33:41.766265703Z,2025-07-17T15:33:41.766100204Z,160,2,1108,C,A,13.850000000,100,0,286704785,0,165499,241612294,ARL
2025-07-17T15:33:41.766265703Z,2025-07-17T15:33:41.766100204Z,160,2,1108,A,A,13.830000000,100,0,287560121,130,165499,241612294,ARL
2025-07-17T15:33:41.777404666Z,2025-07-17T15:33:41.777239400Z,160,2,1108,A,A,13.850000000,100,0,287560333,130,165266,241612426,ARL
2025-07-17T15:33:41.784121031Z,2025-07-17T15:33:41.783955668Z,160,2,1108,C,A,13.870000000,100,0,286828253,130,165363,241612450,ARL
2025-07-17T15:33:42.773141775Z,2025-07-17T15:33:42.772976862Z,160,2,1108,C,A,13.820000000,10,0,287560109,130,164913,241630390,ARL
2025-07-17T15:34:28.155773560Z,2025-07-17T15:34:28.155608087Z,160,2,1108,A,A,14.200000000,50,0,288723725,130,165473,242513312,ARL
2025-07-17T15:34:28.156815057Z,2025-07-17T15:34:28.156649544Z,160,2,1108,C,B,12.650000000,100,0,236206261,0,165513,242513329,ARL
2025-07-17T15:34:28.156815057Z,2025-07-17T15:34:28.156649544Z,160,2,1108,A,B,12.360000000,100,0,288723813,130,165513,242513329,ARL
2025-07-17T15:34:28.156884900Z,2025-07-17T15:34:28.156719339Z,160,2,1108,C,B,12.650000000,100,0,236179089,0,165561,242513330,ARL
2025-07-17T15:34:28.156884900Z,2025-07-17T15:34:28.156719339Z,160,2,1108,A,B,12.360000000,100,0,288723817,130,165561,242513330,ARL
2025-07-17T15:34:28.164796058Z,2025-07-17T15:34:28.164629965Z,160,2,1108,T,N,13.410000000,43,0,0,130,166093,242513452,ARL
2025-07-17T15:34:28.165386986Z,2025-07-17T15:34:28.165221345Z,160,2,1108,T,N,13.410000000,100,0,0,130,165641,242513454,ARL
2025-07-17T15:34:28.166683461Z,2025-07-17T15:34:28.166516235Z,160,2,1108,T,N,13.410000000,56,0,0,0,167226,242513557,ARL
2025-07-17T15:34:28.166683461Z,2025-07-17T15:34:28.166516235Z,160,2,1108,T,N,13.410000000,28,0,0,130,167226,242513558,ARL
2025-07-17T15:34:28.170740864Z,2025-07-17T15:34:28.170575785Z,160,2,1108,A,A,13.810000000,50,0,288724173,130,165079,242513651,ARL
2025-07-17T15:34:28.170792211Z,2025-07-17T15:34:28.170626756Z,160,2,1108,C,B,13.260000000,100,0,285586221,130,165455,242513653,ARL
2025-07-17T15:34:28.171437442Z,2025-07-17T15:34:28.171272157Z,160,2,1108,A,A,13.780000000,2,0,288724201,130,165285,242513665,ARL
2025-07-17T15:34:28.171604993Z,2025-07-17T15:34:28.171439252Z,160,2,1108,T,N,13.410000000,13,0,0,130,165741,242513674,ARL
2025-07-17T15:34:28.172057926Z,2025-07-17T15:34:28.171892519Z,160,2,1108,A,B,13.310000000,10,0,288724225,130,165407,242513691,ARL
2025-07-17T15:34:28.172058708Z,2025-07-17T15:34:28.171893498Z,160,2,1108,A,A,13.820000000,10,0,288724229,130,165210,242513692,ARL
2025-07-17T15:34:28.175011712Z,2025-07-17T15:34:28.174846475Z,160,2,1108,A,B,13.300000000,100,0,288724429,130,165237,242513742,ARL
2025-07-17T15:34:28.175030125Z,2025-07-17T15:34:28.174864618Z,160,2,1108,C,A,13.830000000,100,0,287560121,0,165507,242513743,ARL
2025-07-17T15:34:28.175030125Z,2025-07-17T15:34:28.174864618Z,160,2,1108,A,A,13.790000000,100,0,288724433,130,165507,242513743,ARL
2025-07-17T15:34:28.175329569Z,2025-07-17T15:34:28.175164464Z,160,2,1108,C,A,13.780000000,2,0,288724201,130,165105,242513747,ARL
2025-07-17T15:34:28.175752130Z,2025-07-17T15:34:28.175586497Z,160,2,1108,C,B,12.230000000,100,0,286680693,0,165633,242513748,ARL
2025-07-17T15:34:28.175752130Z,2025-07-17T15:34:28.175586497Z,160,2,1108,A,B,12.270000000,100,0,288724485,130,165633,242513748,ARL
2025-07-17T15:34:28.175767666Z,2025-07-17T15:34:28.175602100Z,160,2,1108,C,A,14.910000000,100,0,286680721,0,165566,242513749,ARL
2025-07-17T15:34:28.175767666Z,2025-07-17T15:34:28.175602100Z,160,2,1108,A,A,14.860000000,100,0,288724489,130,165566,242513749,ARL
2025-07-17T15:34:28.180356536Z,2025-07-17T15:34:28.180191067Z,160,2,1108,A,A,13.800000000,100,0,288724565,130,165469,242513781,ARL
2025-07-17T15:34:28.187237384Z,2025-07-17T15:34:28.187072050Z,160,2,1108,C,A,13.850000000,100,0,287560333,130,165334,242513907,ARL
2025-07-17T15:34:28.192269421Z,2025-07-17T15:34:28.192104387Z,160,2,1108,C,A,13.790000000,100,0,288724433,130,165034,242513974,ARL
2025-07-17T15:34:28.231601320Z,2025-07-17T15:34:28.231436134Z,160,2,1108,A,A,13.830000000,100,0,288725173,130,165186,242514372,ARL
2025-07-17T15:34:28.256123809Z,2025-07-17T15:34:28.255958718Z,160,2,1108,C,A,14.200000000,50,0,288723725,130,165091,242514761,ARL
2025-07-17T15:34:28.271275449Z,2025-07-17T15:34:28.271110273Z,160,2,1108,C,A,13.810000000,50,0,288724173,130,165176,242515164,ARL
2025-07-17T15:34:28.281217370Z,2025-07-17T15:34:28.281052249Z,160,2,1108,C,A,13.800000000,100,0,288724565,130,165121,242515254,ARL
2025-07-17T15:34:28.281945481Z,2025-07-17T15:34:28.281780230Z,160,2,1108,C,A,14.860000000,100,0,288724489,0,165251,242515263,ARL
2025-07-17T15:34:28.281945481Z,2025-07-17T15:34:28.281780230Z,160,2,1108,A,A,14.900000000,100,0,288726085,130,165251,242515263,ARL
2025-07-17T15:34:32.289409612Z,2025-07-17T15:34:32.289244370Z,160,2,1108,A,A,13.840000000,100,0,288845417,130,165242,242598225,ARL
2025-07-17T15:34:39.864692027Z,2025-07-17T15:34:39.864526516Z,160,2,1108,A,A,13.800000000,15,0,289055901,130,165511,242774235,ARL
2025-07-17T15:34:39.865337932Z,2025-07-17T15:34:39.865171719Z,160,2,1108,C,A,13.830000000,100,0,288725173,0,166213,242774299,ARL
2025-07-17T15:34:39.865337932Z,2025-07-17T15:34:39.865171719Z,160,2,1108,A,A,13.810000000,100,0,289056097,130,166213,242774299,ARL
2025-07-17T15:34:39.869175972Z,2025-07-17T15:34:39.869009668Z,160,2,1108,T,N,13.410000000,1,0,0,130,166304,242774413,ARL
2025-07-17T15:34:39.871606986Z,2025-07-17T15:34:39.871441822Z,160,2,1108,A,A,13.810000000,100,0,289056353,130,165164,242774468,ARL
2025-07-17T15:34:39.878645012Z,2025-07-17T15:34:39.878479562Z,160,2,1108,C,A,13.840000000,100,0,288845417,130,165450,242774619,ARL
2025-07-17T15:34:42.774190041Z,2025-07-17T15:34:42.774024574Z,160,2,1108,C,B,13.310000000,10,0,288724225,130,165467,242816556,ARL
2025-07-17T15:34:42.775304741Z,2025-07-17T15:34:42.775139521Z,160,2,1108,C,A,13.810000000,100,0,289056353,130,165220,242816563,ARL
2025-07-17T15:34:46.774087945Z,2025-07-17T15:34:46.773922586Z,160,2,1108,C,A,13.800000000,15,0,289055901,130,165359,242893860,ARL
2025-07-17T15:34:46.800955057Z,2025-07-17T15:34:46.800789632Z,160,2,1108,A,A,13.830000000,100,0,289199221,130,165425,242894153,ARL
2025-07-17T15:34:53.545830704Z,2025-07-17T15:34:53.545665068Z,160,2,1108,C,A,13.820000000,10,0,288724229,130,165636,243011340,ARL
2025-07-17T15:35:05.620763928Z,2025-07-17T15:35:05.620598378Z,160,2,1108,A,A,13.770000000,15,0,289722397,130,165550,243344672,ARL
2025-07-17T15:35:05.712575243Z,2025-07-17T15:35:05.712409728Z,160,2,1108,C,A,13.810000000,100,0,289056097,0,165515,243347940,ARL
2025-07-17T15:35:05.712575243Z,2025-07-17T15:35:05.712409728Z,160,2,1108,A,A,13.780000000,100,0,289726281,130,165515,243347940,ARL
2025-07-17T15:35:05.713315450Z,2025-07-17T15:35:05.713150123Z,160,2,1108,C,A,14.610000000,100,0,237978629,130,165327,243347987,ARL
2025-07-17T15:35:05.713322577Z,2025-07-17T15:35:05.713157077Z,160,2,1108,C,A,14.900000000,100,0,288726085,0,165500,243347988,ARL
2025-07-17T15:35:05.713322577Z,2025-07-17T15:35:05.713157077Z,160,2,1108,A,A,14.850000000,100,0,289726349,130,165500,243347988,ARL
2025-07-17T15:35:05.713677091Z,2025-07-17T15:35:05.713508657Z,160,2,1108,A,A,14.400000000,100,0,289726421,128,168434,243348032,ARL
2025-07-17T15:35:05.729568877Z,2025-07-17T15:35:05.729398505Z,160,2,1108,A,A,13.800000000,100,0,289730309,128,170372,243351264,ARL
2025-07-17T15:35:05.737967956Z,2025-07-17T15:35:05.737802616Z,160,2,1108,C,A,13.830000000,100,0,289199221,130,165340,243352644,ARL
2025-07-17T15:35:06.286572335Z,2025-07-17T15:35:06.286407017Z,160,2,1108,C,A,13.770000000,15,0,289722397,130,165318,243362628,ARL
2025-07-17T15:35:09.788280931Z,2025-07-17T15:35:09.788115219Z,160,2,1108,C,B,13.230000000,2,0,272263853,0,165712,243432828,ARL
2025-07-17T15:35:09.788280931Z,2025-07-17T15:35:09.788115219Z,160,2,1108,A,B,13.140000000,2,0,289828293,130,165712,243432828,ARL
2025-07-17T15:35:11.891867009Z,2025-07-17T15:35:11.891701845Z,160,2,1108,C,A,13.800000000,100,0,289730309,130,165164,243482295,ARL
2025-07-17T15:35:14.301647013Z,2025-07-17T15:35:14.301481698Z,160,2,1108,A,A,14.680000000,700,0,289932801,130,165315,243521615,ARL
2025-07-17T15:35:14.302443648Z,2025-07-17T15:35:14.302278179Z,160,2,1108,C,A,14.910000000,700,0,147217629,130,165469,243521616,ARL
2025-07-17T15:35:15.940644416Z,2025-07-17T15:35:15.940479233Z,160,2,1108,A,A,13.820000000,100,0,289976125,130,165183,243557058,ARL
2025-07-17T15:35:23.746674314Z,2025-07-17T15:35:23.746509184Z,160,2,1108,A,A,13.800000000,100,0,290159301,130,165130,243692012,ARL
2025-07-17T15:35:23.754618546Z,2025-07-17T15:35:23.754453294Z,160,2,1108,C,A,13.820000000,100,0,289976125,130,165252,243692501,ARL
2025-07-17T15:35:39.056679600Z,2025-07-17T15:35:39.056513985Z,160,2,1108,C,A,13.800000000,100,0,290159301,130,165615,243992725,ARL
2025-07-17T15:35:43.128809717Z,2025-07-17T15:35:43.128644252Z,160,2,1108,A,A,13.820000000,100,0,290630573,130,165465,244078096,ARL
2025-07-17T15:36:30.044094509Z,2025-07-17T15:36:30.043928872Z,160,2,1108,A,A,13.800000000,100,0,291778909,130,165637,245013624,ARL
2025-07-17T15:36:30.051045453Z,2025-07-17T15:36:30.050880126Z,160,2,1108,C,A,13.820000000,100,0,290630573,130,165327,245013914,ARL
2025-07-17T15:36:34.298010005Z,2025-07-17T15:36:34.297844579Z,160,2,1108,C,B,13.300000000,100,0,288724429,130,165426,245144122,ARL
2025-07-17T15:36:35.381330809Z,2025-07-17T15:36:35.381165559Z,160,2,1108,A,B,13.130000000,100,0,291951937,130,165250,245161447,ARL
2025-07-17T15:36:35.532851032Z,2025-07-17T15:36:35.532685683Z,160,2,1108,A,B,13.270000000,10,0,291964737,130,165349,245174454,ARL
2025-07-17T15:36:35.532926951Z,2025-07-17T15:36:35.532761335Z,160,2,1108,C,B,12.270000000,100,0,288724485,0,165616,245174461,ARL
2025-07-17T15:36:35.532926951Z,2025-07-17T15:36:35.532761335Z,160,2,1108,A,B,12.230000000,100,0,291964745,130,165616,245174461,ARL
2025-07-17T15:36:36.152132527Z,2025-07-17T15:36:36.151966883Z,160,2,1108,C,B,13.130000000,100,0,291951937,0,165644,245183955,ARL
2025-07-17T15:36:36.152132527Z,2025-07-17T15:36:36.151966883Z,160,2,1108,A,B,13.260000000,100,0,291975017,130,165644,245183955,ARL
2025-07-17T15:36:46.889917278Z,2025-07-17T15:36:46.889749756Z,160,2,1108,C,B,13.270000000,10,0,291964737,128,167522,245499598,ARL
2025-07-17T15:36:46.986820391Z,2025-07-17T15:36:46.986655137Z,160,2,1108,C,A,13.800000000,100,0,291778909,130,165254,245503745,ARL
2025-07-17T15:36:50.997434689Z,2025-07-17T15:36:50.997269299Z,160,2,1108,A,A,13.820000000,100,0,292434813,130,165390,245564901,ARL
2025-07-17T15:37:40.389737573Z,2025-07-17T15:37:40.389572053Z,160,2,1108,C,B,13.140000000,2,0,289828293,0,165520,246491394,ARL
2025-07-17T15:37:40.389737573Z,2025-07-17T15:37:40.389572053Z,160,2,1108,A,B,13.040000000,2,0,293594281,130,165520,246491394,ARL
2025-07-17T15:39:27.070109669Z,2025-07-17T15:39:27.069942913Z,160,2,1108,A,A,13.800000000,100,0,296059685,128,166756,248436908,ARL
2025-07-17T15:39:27.077565902Z,2025-07-17T15:39:27.077400388Z,160,2,1108,C,A,13.820000000,100,0,292434813,130,165514,248437548,ARL
2025-07-17T15:39:30.509853083Z,2025-07-17T15:39:30.509687817Z,160,2,1108,A,A,13.760000000,15,0,296136617,130,165266,248491930,ARL
2025-07-17T15:39:30.573217843Z,2025-07-17T15:39:30.573052284Z,160,2,1108,C,A,13.780000000,100,0,289726281,0,165559,248492793,ARL
2025-07-17T15:39:30.573217843Z,2025-07-17T15:39:30.573052284Z,160,2,1108,A,A,13.770000000,100,0,296137537,130,165559,248492793,ARL
2025-07-17T15:39:30.589169820Z,2025-07-17T15:39:30.589004378Z,160,2,1108,C,A,14.120000000,100,0,286680917,130,165442,248493012,ARL
2025-07-17T15:39:30.589224596Z,2025-07-17T15:39:30.589059301Z,160,2,1108,A,A,14.050000000,100,0,296137769,130,165295,248493014,ARL
2025-07-17T15:39:31.092010369Z,2025-07-17T15:39:31.091844988Z,160,2,1108,A,A,13.780000000,100,0,296149845,130,165381,248502203,ARL
2025-07-17T15:39:31.098856641Z,2025-07-17T15:39:31.098691429Z,160,2,1108,C,A,13.800000000,100,0,296059685,130,165212,248502510,ARL
2025-07-17T15:39:40.691151435Z,2025-07-17T15:39:40.690971606Z,160,2,1108,A,A,13.730000000,15,0,296365029,128,179829,248666930,ARL
2025-07-17T15:39:40.696349429Z,2025-07-17T15:39:40.696182148Z,160,2,1108,C,A,13.770000000,100,0,296137537,0,167281,248669978,ARL
2025-07-17T15:39:40.696349429Z,2025-07-17T15:39:40.696182148Z,160,2,1108,A,A,13.740000000,100,0,296368281,130,167281,248669978,ARL
2025-07-17T15:39:40.697414147Z,2025-07-17T15:39:40.697247480Z,160,2,1108,C,A,14.850000000,100,0,289726349,0,166667,248670386,ARL
2025-07-17T15:39:40.697414147Z,2025-07-17T15:39:40.697247480Z,160,2,1108,A,A,14.810000000,100,0,296368709,128,166667,248670386,ARL
2025-07-17T15:39:40.708810377Z,2025-07-17T15:39:40.708645114Z,160,2,1108,A,A,13.760000000,100,0,296372577,130,165263,248674504,ARL
2025-07-17T15:39:40.731431547Z,2025-07-17T15:39:40.731266408Z,160,2,1108,C,A,13.780000000,100,0,296149845,130,165139,248676672,ARL
2025-07-17T15:39:40.908095999Z,2025-07-17T15:39:40.907929975Z,160,2,1108,C,A,15.400000000,100,0,146959177,0,166024,248685584,ARL
2025-07-17T15:39:40.908095999Z,2025-07-17T15:39:40.907929975Z,160,2,1108,A,A,15.120000000,100,0,296387089,130,166024,248685584,ARL
2025-07-17T15:39:41.085864728Z,2025-07-17T15:39:41.085699437Z,160,2,1108,A,A,14.560000000,100,0,296391881,130,165291,248688410,ARL
2025-07-17T15:39:41.085877317Z,2025-07-17T15:39:41.085711985Z,160,2,1108,C,A,14.840000000,100,0,146962993,130,165332,248688411,ARL
2025-07-17T15:39:43.773811774Z,2025-07-17T15:39:43.773645905Z,160,2,1108,C,A,14.720000000,100,0,286680577,0,165869,248737506,ARL
2025-07-17T15:39:43.773811774Z,2025-07-17T15:39:43.773645905Z,160,2,1108,A,A,14.610000000,100,0,296455037,130,165869,248737506,ARL
2025-07-17T15:39:43.773904473Z,2025-07-17T15:39:43.773738855Z,160,2,1108,C,A,14.720000000,100,0,286680573,0,165618,248737508,ARL
2025-07-17T15:39:43.773904473Z,2025-07-17T15:39:43.773738855Z,160,2,1108,A,A,14.610000000,100,0,296455041,130,165618,248737508,ARL
2025-07-17T15:39:44.428670900Z,2025-07-17T15:39:44.428505546Z,160,2,1108,C,A,13.760000000,15,0,296136617,130,165354,248751670,ARL
2025-07-17T15:39:44.433539292Z,2025-07-17T15:39:44.433372235Z,160,2,1108,C,A,13.730000000,15,0,296365029,128,167057,248752483,ARL
2025-07-17T15:39:44.436054885Z,2025-07-17T15:39:44.435889060Z,160,2,1108,C,A,13.740000000,100,0,296368281,130,165825,248752938,ARL
2025-07-17T15:39:44.450239090Z,2025-07-17T15:39:44.450073949Z,160,2,1108,C,A,13.760000000,100,0,296372577,130,165141,248753643,ARL
2025-07-17T15:39:44.450972330Z,2025-07-17T15:39:44.450806746Z,160,2,1108,C,A,14.810000000,100,0,296368709,0,165584,248753673,ARL
2025-07-17T15:39:44.450972330Z,2025-07-17T15:39:44.450806746Z,160,2,1108,A,A,15.060000000,100,0,296478965,130,165584,248753673,ARL
2025-07-17T15:39:44.451075992Z,2025-07-17T15:39:44.450910591Z,160,2,1108,C,A,13.950000000,2,0,287540393,0,165401,248753678,ARL
2025-07-17T15:39:44.451075992Z,2025-07-17T15:39:44.450910591Z,160,2,1108,A,A,14.070000000,2,0,296478973,130,165401,248753678,ARL
2025-07-17T15:39:44.455130297Z,2025-07-17T15:39:44.454964327Z,160,2,1108,C,A,14.810000000,100,0,286680741,0,165970,248753748,ARL
2025-07-17T15:39:44.455130297Z,2025-07-17T15:39:44.454964327Z,160,2,1108,A,A,14.960000000,100,0,296479053,130,165970,248753748,ARL
2025-07-17T15:39:44.456288062Z,2025-07-17T15:39:44.456122660Z,160,2,1108,C,A,14.650000000,100,0,286680905,130,165402,248753812,ARL
2025-07-17T15:39:44.456377500Z,2025-07-17T15:39:44.456211953Z,160,2,1108,A,A,14.780000000,100,0,296479285,130,165547,248753815,ARL
2025-07-17T15:39:44.462055094Z,2025-07-17T15:39:44.461889886Z,160,2,1108,C,A,14.050000000,100,0,296137769,130,165208,248753947,ARL
2025-07-17T15:39:44.462108809Z,2025-07-17T15:39:44.461943584Z,160,2,1108,A,A,14.260000000,100,0,296479425,130,165225,248753952,ARL
2025-07-17T15:39:44.478923366Z,2025-07-17T15:39:44.478757958Z,160,2,1108,C,A,17.580000000,100,0,286681057,0,165408,248754361,ARL
2025-07-17T15:39:44.478923366Z,2025-07-17T15:39:44.478757958Z,160,2,1108,A,A,17.760000000,100,0,296479893,130,165408,248754361,ARL
2025-07-17T15:39:44.491018431Z,2025-07-17T15:39:44.490852860Z,160,2,1108,C,A,15.920000000,100,0,286681229,0,165571,248754608,ARL
2025-07-17T15:39:44.491018431Z,2025-07-17T15:39:44.490852860Z,160,2,1108,A,A,16.080000000,100,0,296480097,130,165571,248754608,ARL
2025-07-17T15:39:44.593773213Z,2025-07-17T15:39:44.593607433Z,160,2,1108,C,A,14.810000000,100,0,286684005,0,165780,248756227,ARL
2025-07-17T15:39:44.593773213Z,2025-07-17T15:39:44.593607433Z,160,2,1108,A,A,14.960000000,100,0,296482509,130,165780,248756227,ARL
2025-07-17T15:39:44.859886562Z,2025-07-17T15:39:44.859720946Z,160,2,1108,C,A,14.610000000,100,0,296455041,0,165616,248760319,ARL
2025-07-17T15:39:44.859886562Z,2025-07-17T15:39:44.859720946Z,160,2,1108,A,A,15.100000000,100,0,296485621,130,165616,248760319,ARL
2025-07-17T15:39:44.860160096Z,2025-07-17T15:39:44.859994671Z,160,2,1108,A,A,14.080000000,100,0,296485629,130,165425,248760324,ARL
2025-07-17T15:39:44.863678795Z,2025-07-17T15:39:44.863513587Z,160,2,1108,C,A,14.610000000,100,0,296455037,0,165208,248760417,ARL
2025-07-17T15:39:44.863678795Z,2025-07-17T15:39:44.863513587Z,160,2,1108,A,A,15.100000000,100,0,296485649,130,165208,248760417,ARL
2025-07-17T15:39:54.187008224Z,2025-07-17T15:39:54.186842327Z,160,2,1108,C,A,15.100000000,100,0,296485649,0,165897,248915116,ARL
2025-07-17T15:39:54.187008224Z,2025-07-17T15:39:54.186842327Z,160,2,1108,A,A,14.880000000,100,0,296679277,130,165897,248915116,ARL
2025-07-17T15:39:54.187557412Z,2025-07-17T15:39:54.187391707Z,160,2,1108,C,A,15.100000000,100,0,296485621,0,165705,248915126,ARL
2025-07-17T15:39:54.187557412Z,2025-07-17T15:39:54.187391707Z,160,2,1108,A,A,14.880000000,100,0,296679285,130,165705,248915126,ARL
2025-07-17T15:42:06.780503054Z,2025-07-17T15:42:06.780337543Z,160,2,1108,A,A,13.900000000,15,0,299689753,130,165511,251407709,ARL
2025-07-17T15:42:06.780767761Z,2025-07-17T15:42:06.780602350Z,160,2,1108,C,A,14.080000000,100,0,296485629,0,165411,251407713,ARL
2025-07-17T15:42:06.780767761Z,2025-07-17T15:42:06.780602350Z,160,2,1108,A,A,13.910000000,100,0,299689769,130,165411,251407713,ARL
2025-07-17T15:42:06.781502831Z,2025-07-17T15:42:06.781336642Z,160,2,1108,C,A,15.060000000,100,0,296478965,0,166189,251407747,ARL
2025-07-17T15:42:06.781502831Z,2025-07-17T15:42:06.781336642Z,160,2,1108,A,A,14.990000000,100,0,299689857,130,166189,251407747,ARL
2025-07-17T15:42:06.795521307Z,2025-07-17T15:42:06.795355762Z,160,2,1108,C,A,14.260000000,100,0,296479425,130,165545,251408268,ARL
2025-07-17T15:42:06.795573392Z,2025-07-17T15:42:06.795408057Z,160,2,1108,A,A,14.190000000,100,0,299690593,130,165335,251408269,ARL
2025-07-17T15:42:16.264132159Z,2025-07-17T15:42:16.263966448Z,160,2,1108,C,A,14.880000000,100,0,296679285,0,165711,251574391,ARL
2025-07-17T15:42:16.264132159Z,2025-07-17T15:42:16.263966448Z,160,2,1108,A,A,14.760000000,100,0,299903169,130,165711,251574391,ARL
2025-07-17T15:42:17.356766715Z,2025-07-17T15:42:17.356601231Z,160,2,1108,A,A,13.830000000,15,0,299923773,130,165484,251593608,ARL
2025-07-17T15:42:17.577474246Z,2025-07-17T15:42:17.577308779Z,160,2,1108,C,A,13.910000000,100,0,299689769,0,165467,251595553,ARL
2025-07-17T15:42:17.577474246Z,2025-07-17T15:42:17.577308779Z,160,2,1108,A,A,13.840000000,100,0,299926781,130,165467,251595553,ARL
2025-07-17T15:42:17.578219175Z,2025-07-17T15:42:17.578053644Z,160,2,1108,C,A,14.990000000,100,0,299689857,0,165531,251595563,ARL
2025-07-17T15:42:17.578219175Z,2025-07-17T15:42:17.578053644Z,160,2,1108,A,A,14.910000000,100,0,299926801,130,165531,251595563,ARL
2025-07-17T15:42:17.579343189Z,2025-07-17T15:42:17.579177582Z,160,2,1108,C,A,14.780000000,100,0,296479285,0,165607,251595571,ARL
2025-07-17T15:42:17.579343189Z,2025-07-17T15:42:17.579177582Z,160,2,1108,A,A,14.640000000,100,0,299926813,130,165607,251595571,ARL
2025-07-17T15:42:17.580008869Z,2025-07-17T15:42:17.579843331Z,160,2,1108,C,A,14.960000000,100,0,296479053,0,165538,251595576,ARL
2025-07-17T15:42:17.580008869Z,2025-07-17T15:42:17.579843331Z,160,2,1108,A,A,14.810000000,100,0,299926849,130,165538,251595576,ARL
2025-07-17T15:42:17.580035793Z,2025-07-17T15:42:17.579870309Z,160,2,1108,C,A,16.080000000,100,0,296480097,0,165484,251595577,ARL
2025-07-17T15:42:17.580035793Z,2025-07-17T15:42:17.579870309Z,160,2,1108,A,A,15.920000000,100,0,299926853,130,165484,251595577,ARL
2025-07-17T15:42:17.580061097Z,2025-07-17T15:42:17.579895610Z,160,2,1108,C,A,14.960000000,100,0,296482509,0,165487,251595578,ARL
2025-07-17T15:42:17.580061097Z,2025-07-17T15:42:17.579895610Z,160,2,1108,A,A,14.810000000,100,0,299926857,130,165487,251595578,ARL
2025-07-17T15:42:17.580093535Z,2025-07-17T15:42:17.579928136Z,160,2,1108,C,A,17.760000000,100,0,296479893,0,165399,251595580,ARL
2025-07-17T15:42:17.580093535Z,2025-07-17T15:42:17.579928136Z,160,2,1108,A,A,17.580000000,100,0,299926861,130,165399,251595580,ARL
2025-07-17T15:42:17.589263550Z,2025-07-17T15:42:17.589098227Z,160,2,1108,C,A,14.190000000,100,0,299690593,130,165323,251595691,ARL
2025-07-17T15:42:17.589316911Z,2025-07-17T15:42:17.589151325Z,160,2,1108,A,A,14.120000000,100,0,299926965,130,165586,251595692,ARL
2025-07-17T15:42:18.398220000Z,2025-07-17T15:42:18.398054465Z,160,2,1108,C,A,14.880000000,100,0,296679277,0,165535,251612478,ARL
2025-07-17T15:42:18.398220000Z,2025-07-17T15:42:18.398054465Z,160,2,1108,A,A,14.730000000,100,0,299945073,130,165535,251612478,ARL
2025-07-17T15:42:21.517871714Z,2025-07-17T15:42:21.517706139Z,160,2,1108,C,A,13.900000000,15,0,299689753,130,165575,251668179,ARL
2025-07-17T15:42:22.522744242Z,2025-07-17T15:42:22.522578675Z,160,2,1108,A,A,13.790000000,15,0,300042293,130,165567,251690950,ARL
2025-07-17T15:42:22.533681479Z,2025-07-17T15:42:22.533515955Z,160,2,1108,A,A,13.820000000,100,0,300042385,130,165524,251691033,ARL
2025-07-17T15:42:23.490247121Z,2025-07-17T15:42:23.490079821Z,160,2,1108,C,A,13.840000000,100,0,299926781,0,167300,251710173,ARL
2025-07-17T15:42:23.490247121Z,2025-07-17T15:42:23.490079821Z,160,2,1108,A,A,13.800000000,100,0,300061581,128,167300,251710173,ARL
2025-07-17T15:42:23.491451368Z,2025-07-17T15:42:23.491285065Z,160,2,1108,C,A,14.910000000,100,0,299926801,0,166303,251710647,ARL
2025-07-17T15:42:23.491451368Z,2025-07-17T15:42:23.491285065Z,160,2,1108,A,A,14.870000000,100,0,300061989,128,166303,251710647,ARL
2025-07-17T15:42:23.589065154Z,2025-07-17T15:42:23.588899941Z,160,2,1108,C,A,13.790000000,15,0,300042293,130,165213,251718746,ARL
2025-07-17T15:42:23.589220778Z,2025-07-17T15:42:23.589055082Z,160,2,1108,C,A,13.830000000,15,0,299923773,130,165696,251718767,ARL
2025-07-17T15:42:34.003710081Z,2025-07-17T15:42:34.003544527Z,160,2,1108,C,A,13.800000000,100,0,300061581,130,165554,251901273,ARL
2025-07-17T15:42:34.003949340Z,2025-07-17T15:42:34.003783950Z,160,2,1108,C,A,13.820000000,100,0,300042385,130,165390,251901275,ARL
2025-07-17T15:42:34.004225180Z,2025-07-17T15:42:34.004059450Z,160,2,1108,C,A,14.730000000,100,0,299945073,0,165730,251901280,ARL
2025-07-17T15:42:34.004225180Z,2025-07-17T15:42:34.004059450Z,160,2,1108,A,A,14.880000000,100,0,300280745,130,165730,251901280,ARL
2025-07-17T15:42:34.004671652Z,2025-07-17T15:42:34.004506043Z,160,2,1108,C,A,14.870000000,100,0,300061989,0,165609,251901285,ARL
2025-07-17T15:42:34.004671652Z,2025-07-17T15:42:34.004506043Z,160,2,1108,A,A,15.060000000,100,0,300280757,130,165609,251901285,ARL
2025-07-17T15:42:34.004677786Z,2025-07-17T15:42:34.004512153Z,160,2,1108,C,A,14.760000000,100,0,299903169,0,165633,251901286,ARL
2025-07-17T15:42:34.004677786Z,2025-07-17T15:42:34.004512153Z,160,2,1108,A,A,14.880000000,100,0,300280761,130,165633,251901286,ARL
2025-07-17T15:42:34.005574760Z,2025-07-17T15:42:34.005409139Z,160,2,1108,C,A,15.920000000,100,0,299926853,0,165621,251901302,ARL
2025-07-17T15:42:34.005574760Z,2025-07-17T15:42:34.005409139Z,160,2,1108,A,A,16.080000000,100,0,300280773,130,165621,251901302,ARL
2025-07-17T15:42:34.005832926Z,2025-07-17T15:42:34.005667449Z,160,2,1108,C,A,14.810000000,100,0,299926849,0,165477,251901305,ARL
2025-07-17T15:42:34.005832926Z,2025-07-17T15:42:34.005667449Z,160,2,1108,A,A,14.960000000,100,0,300280777,130,165477,251901305,ARL
2025-07-17T15:42:34.006831024Z,2025-07-17T15:42:34.006665512Z,160,2,1108,C,A,17.580000000,100,0,299926861,0,165512,251901319,ARL
2025-07-17T15:42:34.006831024Z,2025-07-17T15:42:34.006665512Z,160,2,1108,A,A,17.760000000,100,0,300280797,130,165512,251901319,ARL
2025-07-17T15:42:34.007908678Z,2025-07-17T15:42:34.007743383Z,160,2,1108,C,A,14.640000000,100,0,299926813,130,165295,251901330,ARL
2025-07-17T15:42:34.008072663Z,2025-07-17T15:42:34.007907269Z,160,2,1108,A,A,14.780000000,100,0,300280825,130,165394,251901331,ARL
2025-07-17T15:42:34.010196831Z,2025-07-17T15:42:34.010031518Z,160,2,1108,C,A,14.120000000,100,0,299926965,130,165313,251901352,ARL
2025-07-17T15:42:34.010248842Z,2025-07-17T15:42:34.010083409Z,160,2,1108,A,A,14.260000000,100,0,300280857,130,165433,251901353,ARL
2025-07-17T15:42:34.010572370Z,2025-07-17T15:42:34.010406771Z,160,2,1108,C,A,14.810000000,100,0,299926857,0,165599,251901355,ARL
2025-07-17T15:42:34.010572370Z,2025-07-17T15:42:34.010406771Z,160,2,1108,A,A,14.960000000,100,0,300280873,130,165599,251901355,ARL
2025-07-17T15:42:34.952098027Z,2025-07-17T15:42:34.951932909Z,160,2,1108,A,A,14.080000000,100,0,300294885,130,165118,251912292,ARL
2025-07-17T15:43:21.513838949Z,2025-07-17T15:43:21.513673603Z,160,2,1108,A,A,13.920000000,15,0,301218889,130,165346,252622568,ARL
2025-07-17T15:43:24.878236760Z,2025-07-17T15:43:24.878071152Z,160,2,1108,C,A,14.080000000,100,0,300294885,0,165608,252681819,ARL
2025-07-17T15:43:24.878236760Z,2025-07-17T15:43:24.878071152Z,160,2,1108,A,A,13.930000000,100,0,301295841,130,165608,252681819,ARL
2025-07-17T15:43:24.879003443Z,2025-07-17T15:43:24.878837670Z,160,2,1108,C,A,15.060000000,100,0,300280757,0,165773,252681832,ARL
2025-07-17T15:43:24.879003443Z,2025-07-17T15:43:24.878837670Z,160,2,1108,A,A,15.010000000,100,0,301295873,130,165773,252681832,ARL
2025-07-17T15:43:32.780372412Z,2025-07-17T15:43:32.780206927Z,160,2,1108,A,A,13.880000000,15,0,301451057,130,165485,252800884,ARL
2025-07-17T15:43:32.780639619Z,2025-07-17T15:43:32.780474141Z,160,2,1108,C,A,13.930000000,100,0,301295841,0,165478,252800887,ARL
2025-07-17T15:43:32.780639619Z,2025-07-17T15:43:32.780474141Z,160,2,1108,A,A,13.890000000,100,0,301451061,130,165478,252800887,ARL
2025-07-17T15:43:32.781382162Z,2025-07-17T15:43:32.781216589Z,160,2,1108,C,A,15.010000000,100,0,301295873,0,165573,252800892,ARL
2025-07-17T15:43:32.781382162Z,2025-07-17T15:43:32.781216589Z,160,2,1108,A,A,14.970000000,100,0,301451077,130,165573,252800892,ARL
2025-07-17T15:43:32.792119698Z,2025-07-17T15:43:32.791954053Z,160,2,1108,C,A,14.260000000,100,0,300280857,130,165645,252801681,ARL
2025-07-17T15:43:32.792174617Z,2025-07-17T15:43:32.792008881Z,160,2,1108,A,A,14.170000000,100,0,301452785,130,165736,252801689,ARL
2025-07-17T15:43:44.004832641Z,2025-07-17T15:43:44.004667259Z,160,2,1108,C,A,13.920000000,15,0,301218889,130,165382,252977583,ARL
2025-07-17T15:43:44.005191111Z,2025-07-17T15:43:44.005025587Z,160,2,1108,C,A,14.880000000,100,0,300280761,0,165524,252977592,ARL
2025-07-17T15:43:44.005191111Z,2025-07-17T15:43:44.005025587Z,160,2,1108,A,A,14.770000000,100,0,301671709,130,165524,252977592,ARL
2025-07-17T15:43:44.005313071Z,2025-07-17T15:43:44.005147707Z,160,2,1108,C,A,14.880000000,100,0,300280745,0,165364,252977595,ARL
2025-07-17T15:43:44.005313071Z,2025-07-17T15:43:44.005147707Z,160,2,1108,A,A,14.770000000,100,0,301671713,130,165364,252977595,ARL
2025-07-17T15:43:48.787497664Z,2025-07-17T15:43:48.787332399Z,160,2,1108,A,A,13.830000000,15,0,301746941,130,165265,253027890,ARL
2025-07-17T15:43:48.787766907Z,2025-07-17T15:43:48.787601640Z,160,2,1108,C,A,13.890000000,100,0,301451061,0,165267,253027924,ARL
2025-07-17T15:43:48.787766907Z,2025-07-17T15:43:48.787601640Z,160,2,1108,A,A,13.840000000,100,0,301746949,130,165267,253027924,ARL
2025-07-17T15:43:48.788512022Z,2025-07-17T15:43:48.788345787Z,160,2,1108,C,A,14.970000000,100,0,301451077,0,166235,253027959,ARL
2025-07-17T15:43:48.788512022Z,2025-07-17T15:43:48.788345787Z,160,2,1108,A,A,14.910000000,100,0,301746969,128,166235,253027959,ARL
2025-07-17T15:43:48.790573820Z,2025-07-17T15:43:48.790408191Z,160,2,1108,C,A,14.960000000,100,0,300280777,0,165629,253028026,ARL
2025-07-17T15:43:48.790573820Z,2025-07-17T15:43:48.790408191Z,160,2,1108,A,A,14.810000000,100,0,301747001,130,165629,253028026,ARL
2025-07-17T15:43:48.790600546Z,2025-07-17T15:43:48.790434947Z,160,2,1108,C,A,14.780000000,100,0,300280825,0,165599,253028027,ARL
2025-07-17T15:43:48.790600546Z,2025-07-17T15:43:48.790434947Z,160,2,1108,A,A,14.640000000,100,0,301747005,130,165599,253028027,ARL
2025-07-17T15:43:48.800959598Z,2025-07-17T15:43:48.800794196Z,160,2,1108,C,A,17.760000000,100,0,300280797,0,165402,253028707,ARL
2025-07-17T15:43:48.800959598Z,2025-07-17T15:43:48.800794196Z,160,2,1108,A,A,17.580000000,100,0,301747261,130,165402,253028707,ARL
2025-07-17T15:43:48.806845249Z,2025-07-17T15:43:48.806679708Z,160,2,1108,C,A,16.080000000,100,0,300280773,0,165541,253028803,ARL
2025-07-17T15:43:48.806845249Z,2025-07-17T15:43:48.806679708Z,160,2,1108,A,A,15.920000000,100,0,301747301,130,165541,253028803,ARL
2025-07-17T15:43:48.852570853Z,2025-07-17T15:43:48.852405047Z,160,2,1108,C,A,14.960000000,100,0,300280873,0,165806,253029437,ARL
2025-07-17T15:43:48.852570853Z,2025-07-17T15:43:48.852405047Z,160,2,1108,A,A,14.810000000,100,0,301747957,130,165806,253029437,ARL
2025-07-17T15:43:53.123817759Z,2025-07-17T15:43:53.123652480Z,160,2,1108,C,A,13.880000000,15,0,301451057,130,165279,253100941,ARL
2025-07-17T15:43:54.126276976Z,2025-07-17T15:43:54.126111293Z,160,2,1108,A,A,13.810000000,15,0,301867541,130,165683,253121467,ARL
2025-07-17T15:43:54.998238933Z,2025-07-17T15:43:54.998073317Z,160,2,1108,C,A,13.840000000,100,0,301746949,0,165616,253137948,ARL
2025-07-17T15:43:54.998238933Z,2025-07-17T15:43:54.998073317Z,160,2,1108,A,A,13.820000000,100,0,301885353,130,165616,253137948,ARL
2025-07-17T15:43:55.019172741Z,2025-07-17T15:43:55.019007300Z,160,2,1108,C,A,14.170000000,100,0,301452785,130,165441,253138492,ARL
2025-07-17T15:43:55.019225935Z,2025-07-17T15:43:55.019060515Z,160,2,1108,A,A,14.100000000,100,0,301886057,130,165420,253138493,ARL
2025-07-17T15:44:01.698791467Z,2025-07-17T15:44:01.698626200Z,160,2,1108,C,A,13.830000000,15,0,301746941,130,165267,253246317,ARL
2025-07-17T15:44:04.014878156Z,2025-07-17T15:44:04.014712730Z,160,2,1108,A,A,13.830000000,100,0,302078553,130,165426,253292355,ARL
2025-07-17T15:44:05.055626948Z,2025-07-17T15:44:05.055461574Z,160,2,1108,A,A,13.810000000,100,0,302100649,130,165374,253307083,ARL
2025-07-17T15:44:05.062431949Z,2025-07-17T15:44:05.062266845Z,160,2,1108,C,A,13.830000000,100,0,302078553,130,165104,253307147,ARL
2025-07-17T15:44:09.389713730Z,2025-07-17T15:44:09.389548394Z,160,2,1108,A,A,13.760000000,15,0,302205249,130,165336,253384422,ARL
2025-07-17T15:44:09.390496140Z,2025-07-17T15:44:09.390329935Z,160,2,1108,C,A,14.770000000,100,0,301671709,0,166205,253384438,ARL
2025-07-17T15:44:09.390496140Z,2025-07-17T15:44:09.390329935Z,160,2,1108,A,A,14.660000000,100,0,302205289,128,166205,253384438,ARL
2025-07-17T15:44:09.391058486Z,2025-07-17T15:44:09.390893172Z,160,2,1108,C,A,14.770000000,100,0,301671713,0,165314,253384456,ARL
2025-07-17T15:44:09.391058486Z,2025-07-17T15:44:09.390893172Z,160,2,1108,A,A,14.660000000,100,0,302205309,130,165314,253384456,ARL
2025-07-17T15:44:09.395447612Z,2025-07-17T15:44:09.395281780Z,160,2,1108,C,A,13.820000000,100,0,301885353,0,165832,253384698,ARL
2025-07-17T15:44:09.395447612Z,2025-07-17T15:44:09.395281780Z,160,2,1108,A,A,13.770000000,100,0,302205493,130,165832,253384698,ARL
2025-07-17T15:44:09.396195647Z,2025-07-17T15:44:09.396030225Z,160,2,1108,C,A,14.910000000,100,0,301746969,0,165422,253384731,ARL
2025-07-17T15:44:09.396195647Z,2025-07-17T15:44:09.396030225Z,160,2,1108,A,A,14.840000000,100,0,302205537,130,165422,253384731,ARL
2025-07-17T15:44:09.398011186Z,2025-07-17T15:44:09.397845986Z,160,2,1108,A,A,13.790000000,100,0,302205561,130,165200,253384788,ARL
2025-07-17T15:44:09.404828956Z,2025-07-17T15:44:09.404663816Z,160,2,1108,C,A,13.810000000,100,0,302100649,130,165140,253385013,ARL
2025-07-17T15:44:20.402535831Z,2025-07-17T15:44:20.402370565Z,160,2,1108,C,A,13.810000000,15,0,301867541,130,165266,253562230,ARL
2025-07-17T15:44:21.405486122Z,2025-07-17T15:44:21.405320730Z,160,2,1108,A,A,13.740000000,15,0,302458113,130,165392,253582427,ARL
2025-07-17T15:44:21.843235911Z,2025-07-17T15:44:21.843070079Z,160,2,1108,C,A,13.770000000,100,0,302205493,0,165832,253590641,ARL
2025-07-17T15:44:21.843235911Z,2025-07-17T15:44:21.843070079Z,160,2,1108,A,A,13.750000000,100,0,302466045,130,165832,253590641,ARL
2025-07-17T15:44:21.855416093Z,2025-07-17T15:44:21.855250804Z,160,2,1108,C,A,14.100000000,100,0,301886057,130,165289,253590837,ARL
2025-07-17T15:44:21.855471158Z,2025-07-17T15:44:21.855305995Z,160,2,1108,A,A,14.030000000,100,0,302466157,130,165163,253590838,ARL
2025-07-17T15:44:24.447075532Z,2025-07-17T15:44:24.446910206Z,160,2,1108,A,A,13.770000000,100,0,302500469,130,165326,253614407,ARL
2025-07-17T15:44:24.465555818Z,2025-07-17T15:44:24.465390625Z,160,2,1108,C,A,13.790000000,100,0,302205561,130,165193,253614591,ARL
2025-07-17T15:44:30.846822983Z,2025-07-17T15:44:30.846657613Z,160,2,1108,C,A,13.760000000,15,0,302205249,130,165370,253704439,ARL
2025-07-17T15:44:31.849784693Z,2025-07-17T15:44:31.849618640Z,160,2,1108,A,A,13.720000000,15,0,302649021,130,166053,253721156,ARL
2025-07-17T15:44:31.849921857Z,2025-07-17T15:44:31.849756452Z,160,2,1108,A,A,13.750000000,100,0,302649029,130,165405,253721157,ARL
2025-07-17T15:44:31.910124978Z,2025-07-17T15:44:31.909959614Z,160,2,1108,C,A,13.770000000,100,0,302500469,130,165364,253722140,ARL
2025-07-17T15:44:32.484497230Z,2025-07-17T15:44:32.484331764Z,160,2,1108,C,A,13.750000000,100,0,302466045,0,165466,253730877,ARL
2025-07-17T15:44:32.484497230Z,2025-07-17T15:44:32.484331764Z,160,2,1108,A,A,13.730000000,100,0,302662769,130,165466,253730877,ARL
2025-07-17T15:44:32.485238209Z,2025-07-17T15:44:32.485072552Z,160,2,1108,C,A,14.840000000,100,0,302205537,0,165657,253730907,ARL
2025-07-17T15:44:32.485238209Z,2025-07-17T15:44:32.485072552Z,160,2,1108,A,A,14.790000000,100,0,302662821,130,165657,253730907,ARL
2025-07-17T15:44:33.389387814Z,2025-07-17T15:44:33.389222513Z,160,2,1108,A,A,14.280000000,100,0,302681357,130,165301,253745665,ARL
2025-07-17T15:44:33.389389030Z,2025-07-17T15:44:33.389223581Z,160,2,1108,C,A,14.560000000,100,0,146960005,130,165449,253745666,ARL
2025-07-17T15:44:36.362187673Z,2025-07-17T15:44:36.362022168Z,160,2,1108,C,A,13.740000000,15,0,302458113,130,165505,253783635,ARL
2025-07-17T15:44:37.364377419Z,2025-07-17T15:44:37.364212109Z,160,2,1108,A,A,13.700000000,15,0,302750929,130,165310,253797506,ARL
2025-07-17T15:44:37.364519067Z,2025-07-17T15:44:37.364353897Z,160,2,1108,A,A,13.730000000,100,0,302750937,130,165170,253797510,ARL
2025-07-17T15:44:37.458119494Z,2025-07-17T15:44:37.457954350Z,160,2,1108,C,A,13.750000000,100,0,302649029,130,165144,253798432,ARL
2025-07-17T15:44:38.432460509Z,2025-07-17T15:44:38.432294362Z,160,2,1108,C,A,13.730000000,100,0,302662769,0,166147,253807786,ARL
2025-07-17T15:44:38.432460509Z,2025-07-17T15:44:38.432294362Z,160,2,1108,A,A,13.710000000,100,0,302763889,130,166147,253807786,ARL
2025-07-17T15:44:38.439253975Z,2025-07-17T15:44:38.439088042Z,160,2,1108,C,A,15.920000000,100,0,301747301,0,165933,253808105,ARL
2025-07-17T15:44:38.439253975Z,2025-07-17T15:44:38.439088042Z,160,2,1108,A,A,15.770000000,100,0,302764121,130,165933,253808105,ARL
2025-07-17T15:44:38.440321697Z,2025-07-17T15:44:38.440156077Z,160,2,1108,C,A,17.580000000,100,0,301747261,0,165620,253808122,ARL
2025-07-17T15:44:38.440321697Z,2025-07-17T15:44:38.440156077Z,160,2,1108,A,A,17.420000000,100,0,302764137,130,165620,253808122,ARL
2025-07-17T15:44:43.019262217Z,2025-07-17T15:44:43.019083502Z,160,2,1108,C,A,13.700000000,15,0,302750929,128,178715,253875920,ARL
2025-07-17T15:44:43.019352658Z,2025-07-17T15:44:43.019184132Z,160,2,1108,C,A,13.720000000,15,0,302649021,128,168526,253876010,ARL
2025-07-17T15:44:44.076009999Z,2025-07-17T15:44:44.075843113Z,160,2,1108,A,A,13.700000000,15,0,302867209,128,166886,253892869,ARL
2025-07-17T15:44:44.781630732Z,2025-07-17T15:44:44.781464821Z,160,2,1108,C,A,13.700000000,15,0,302867209,130,165911,253901222,ARL
2025-07-17T15:44:53.143249270Z,2025-07-17T15:44:53.143083969Z,160,2,1108,C,A,13.730000000,100,0,302750937,130,165301,254011871,ARL
2025-07-17T15:44:57.191188470Z,2025-07-17T15:44:57.191023026Z,160,2,1108,A,A,13.750000000,100,0,303118785,130,165444,254079162,ARL
2025-07-17T15:45:07.065756574Z,2025-07-17T15:45:07.065587919Z,160,2,1108,C,A,13.710000000,100,0,302763889,128,168655,254244597,ARL
2025-07-17T15:45:07.080131505Z,2025-07-17T15:45:07.079966224Z,160,2,1108,C,A,13.750000000,100,0,303118785,130,165281,254245492,ARL
2025-07-17T15:45:07.080687215Z,2025-07-17T15:45:07.080521807Z,160,2,1108,C,A,14.660000000,100,0,302205289,0,165408,254245505,ARL
2025-07-17T15:45:07.080687215Z,2025-07-17T15:45:07.080521807Z,160,2,1108,A,A,14.890000000,100,0,303330477,130,165408,254245505,ARL
2025-07-17T15:45:07.080872245Z,2025-07-17T15:45:07.080706110Z,160,2,1108,C,A,14.790000000,100,0,302662821,0,166135,254245511,ARL
2025-07-17T15:45:07.080872245Z,2025-07-17T15:45:07.080706110Z,160,2,1108,A,A,15.060000000,100,0,303330485,130,166135,254245511,ARL
2025-07-17T15:45:07.081578064Z,2025-07-17T15:45:07.081407507Z,160,2,1108,C,A,14.810000000,100,0,301747001,0,170557,254245568,ARL
2025-07-17T15:45:07.081578064Z,2025-07-17T15:45:07.081407507Z,160,2,1108,A,A,14.960000000,100,0,303330509,128,170557,254245568,ARL
2025-07-17T15:45:07.081607970Z,2025-07-17T15:45:07.081441134Z,160,2,1108,C,A,14.660000000,100,0,302205309,0,166836,254245576,ARL
2025-07-17T15:45:07.081607970Z,2025-07-17T15:45:07.081441134Z,160,2,1108,A,A,14.890000000,100,0,303330521,130,166836,254245576,ARL
2025-07-17T15:45:07.083898999Z,2025-07-17T15:45:07.083732443Z,160,2,1108,C,A,17.420000000,100,0,302764137,0,166556,254246327,ARL
2025-07-17T15:45:07.083898999Z,2025-07-17T15:45:07.083732443Z,160,2,1108,A,A,17.760000000,100,0,303331309,130,166556,254246327,ARL
2025-07-17T15:45:07.085222525Z,2025-07-17T15:45:07.085057258Z,160,2,1108,C,A,14.030000000,100,0,302466157,130,165267,254246434,ARL
2025-07-17T15:45:07.085274852Z,2025-07-17T15:45:07.085109545Z,160,2,1108,A,A,14.260000000,100,0,303331401,130,165307,254246437,ARL
2025-07-17T15:45:07.086534700Z,2025-07-17T15:45:07.086368957Z,160,2,1108,C,A,14.640000000,100,0,301747005,130,165743,254246501,ARL
2025-07-17T15:45:07.086660325Z,2025-07-17T15:45:07.086494745Z,160,2,1108,A,A,14.780000000,100,0,303331425,130,165580,254246502,ARL
2025-07-17T15:45:07.087389466Z,2025-07-17T15:45:07.087223859Z,160,2,1108,C,A,15.770000000,100,0,302764121,0,165607,254246529,ARL
2025-07-17T15:45:07.087389466Z,2025-07-17T15:45:07.087223859Z,160,2,1108,A,A,16.080000000,100,0,303331429,130,165607,254246529,ARL
2025-07-17T15:45:07.133978488Z,2025-07-17T15:45:07.133812895Z,160,2,1108,C,A,14.810000000,100,0,301747957,0,165593,254250625,ARL
2025-07-17T15:45:07.133978488Z,2025-07-17T15:45:07.133812895Z,160,2,1108,A,A,14.960000000,100,0,303334253,130,165593,254250625,ARL
2025-07-17T15:45:07.469961302Z,2025-07-17T15:45:07.469796155Z,160,2,1108,A,A,14.080000000,100,0,303340405,130,165147,254258029,ARL
2025-07-17T15:45:08.094768552Z,2025-07-17T15:45:08.094603115Z,160,2,1108,C,A,14.890000000,100,0,303330521,0,165437,254266885,ARL
2025-07-17T15:45:08.094768552Z,2025-07-17T15:45:08.094603115Z,160,2,1108,A,A,15.100000000,100,0,303349309,130,165437,254266885,ARL
2025-07-17T15:45:08.103306644Z,2025-07-17T15:45:08.103141155Z,160,2,1108,C,A,14.890000000,100,0,303330477,0,165489,254266971,ARL
2025-07-17T15:45:08.103306644Z,2025-07-17T15:45:08.103141155Z,160,2,1108,A,A,15.100000000,100,0,303349377,130,165489,254266971,ARL
2025-07-17T15:45:24.187008278Z,2025-07-17T15:45:24.186842413Z,160,2,1108,C,A,15.100000000,100,0,303349309,0,165865,254547413,ARL
2025-07-17T15:45:24.187008278Z,2025-07-17T15:45:24.186842413Z,160,2,1108,A,A,14.880000000,100,0,303682385,130,165865,254547413,ARL
2025-07-17T15:45:24.187441892Z,2025-07-17T15:45:24.187276389Z,160,2,1108,C,A,15.100000000,100,0,303349377,0,165503,254547415,ARL
2025-07-17T15:45:24.187441892Z,2025-07-17T15:45:24.187276389Z,160,2,1108,A,A,14.880000000,100,0,303682389,130,165503,254547415,ARL
2025-07-17T15:45:37.509454888Z,2025-07-17T15:45:37.509289536Z,160,2,1108,A,A,13.940000000,15,0,304056997,130,165352,254851462,ARL
2025-07-17T15:45:37.998133497Z,2025-07-17T15:45:37.997967775Z,160,2,1108,C,A,14.080000000,100,0,303340405,0,165722,254864588,ARL
2025-07-17T15:45:37.998133497Z,2025-07-17T15:45:37.997967775Z,160,2,1108,A,A,13.950000000,100,0,304072245,130,165722,254864588,ARL
2025-07-17T15:45:44.700593408Z,2025-07-17T15:45:44.700428155Z,160,2,1108,A,A,13.890000000,15,0,304238913,130,165253,254999429,ARL
2025-07-17T15:45:45.262537122Z,2025-07-17T15:45:45.262371701Z,160,2,1108,C,A,13.950000000,100,0,304072245,0,165421,255010979,ARL
2025-07-17T15:45:45.262537122Z,2025-07-17T15:45:45.262371701Z,160,2,1108,A,A,13.900000000,100,0,304252313,130,165421,255010979,ARL
2025-07-17T15:45:45.263289023Z,2025-07-17T15:45:45.263123432Z,160,2,1108,C,A,15.060000000,100,0,303330485,0,165591,255010987,ARL
2025-07-17T15:45:45.263289023Z,2025-07-17T15:45:45.263123432Z,160,2,1108,A,A,14.980000000,100,0,304252333,130,165591,255010987,ARL
2025-07-17T15:45:45.274360382Z,2025-07-17T15:45:45.274194870Z,160,2,1108,C,A,14.260000000,100,0,303331401,130,165512,255011158,ARL
2025-07-17T15:45:45.274410721Z,2025-07-17T15:45:45.274245387Z,160,2,1108,A,A,14.180000000,100,0,304252469,130,165334,255011161,ARL
2025-07-17T15:45:58.419783333Z,2025-07-17T15:45:58.419617935Z,160,2,1108,C,A,13.940000000,15,0,304056997,130,165398,255183198,ARL
2025-07-17T15:45:58.420278691Z,2025-07-17T15:45:58.420113307Z,160,2,1108,C,A,14.880000000,100,0,303682389,0,165384,255183203,ARL
2025-07-17T15:45:58.420278691Z,2025-07-17T15:45:58.420113307Z,160,2,1108,A,A,14.770000000,100,0,304503585,130,165384,255183203,ARL
2025-07-17T15:45:58.420755889Z,2025-07-17T15:45:58.420590199Z,160,2,1108,C,A,14.880000000,100,0,303682385,0,165690,255183204,ARL
2025-07-17T15:45:58.420755889Z,2025-07-17T15:45:58.420590199Z,160,2,1108,A,A,14.770000000,100,0,304503593,130,165690,255183204,ARL
2025-07-17T15:45:58.782892109Z,2025-07-17T15:45:58.782726994Z,160,2,1108,C,A,13.890000000,15,0,304238913,130,165115,255189425,ARL
2025-07-17T15:46:16.783057616Z,2025-07-17T15:46:16.782892334Z,160,2,1108,A,A,13.880000000,15,0,304949689,130,165282,255552962,ARL
2025-07-17T15:46:16.783326241Z,2025-07-17T15:46:16.783160795Z,160,2,1108,C,A,13.900000000,100,0,304252313,0,165446,255552970,ARL
2025-07-17T15:46:16.783326241Z,2025-07-17T15:46:16.783160795Z,160,2,1108,A,A,13.890000000,100,0,304949697,130,165446,255552970,ARL
2025-07-17T15:46:18.782897570Z,2025-07-17T15:46:18.782732218Z,160,2,1108,C,A,13.880000000,15,0,304949689,130,165352,255587336,ARL
2025-07-17T15:46:28.474166897Z,2025-07-17T15:46:28.474001551Z,160,2,1108,C,A,13.890000000,100,0,304949697,130,165346,255746167,ARL
2025-07-17T15:46:28.474726594Z,2025-07-17T15:46:28.474561156Z,160,2,1108,C,A,14.770000000,100,0,304503593,0,165438,255746173,ARL
2025-07-17T15:46:28.474726594Z,2025-07-17T15:46:28.474561156Z,160,2,1108,A,A,14.880000000,100,0,305184937,130,165438,255746173,ARL
2025-07-17T15:46:28.474896460Z,2025-07-17T15:46:28.474730225Z,160,2,1108,C,A,14.770000000,100,0,304503585,0,166235,255746176,ARL
2025-07-17T15:46:28.474896460Z,2025-07-17T15:46:28.474730225Z,160,2,1108,A,A,14.880000000,100,0,305184953,130,166235,255746176,ARL
2025-07-17T15:46:28.474902154Z,2025-07-17T15:46:28.474736101Z,160,2,1108,C,A,14.980000000,100,0,304252333,0,166053,255746178,ARL
2025-07-17T15:46:28.474902154Z,2025-07-17T15:46:28.474736101Z,160,2,1108,A,A,15.030000000,100,0,305184957,128,166053,255746178,ARL
2025-07-17T15:46:28.492881980Z,2025-07-17T15:46:28.492716775Z,160,2,1108,C,A,14.180000000,100,0,304252469,130,165205,255746619,ARL
2025-07-17T15:46:28.492931279Z,2025-07-17T15:46:28.492765859Z,160,2,1108,A,A,14.260000000,100,0,305185529,130,165420,255746621,ARL
2025-07-17T15:46:28.646273467Z,2025-07-17T15:46:28.646108242Z,160,2,1108,A,A,14.080000000,100,0,305187077,130,165225,255748568,ARL
2025-07-17T15:46:57.524024658Z,2025-07-17T15:46:57.523859388Z,160,2,1108,A,A,13.920000000,15,0,305862145,130,165270,256268482,ARL
2025-07-17T15:46:57.932842994Z,2025-07-17T15:46:57.932677299Z,160,2,1108,C,A,14.080000000,100,0,305187077,0,165695,256280751,ARL
2025-07-17T15:46:57.932842994Z,2025-07-17T15:46:57.932677299Z,160,2,1108,A,A,13.930000000,100,0,305878881,130,165695,256280751,ARL
2025-07-17T15:47:06.609456251Z,2025-07-17T15:47:06.609290857Z,160,2,1108,A,A,13.880000000,15,0,306121113,130,165394,256488374,ARL
2025-07-17T15:47:08.787695144Z,2025-07-17T15:47:08.787529505Z,160,2,1108,C,A,13.930000000,100,0,305878881,0,165639,256532991,ARL
2025-07-17T15:47:08.787695144Z,2025-07-17T15:47:08.787529505Z,160,2,1108,A,A,13.890000000,100,0,306170837,130,165639,256532991,ARL
2025-07-17T15:47:08.788440762Z,2025-07-17T15:47:08.788275184Z,160,2,1108,C,A,15.030000000,100,0,305184957,0,165578,256533005,ARL
2025-07-17T15:47:08.788440762Z,2025-07-17T15:47:08.788275184Z,160,2,1108,A,A,14.970000000,100,0,306170869,130,165578,256533005,ARL
2025-07-17T15:47:08.805983406Z,2025-07-17T15:47:08.805818249Z,160,2,1108,C,A,14.260000000,100,0,305185529,130,165157,256533442,ARL
2025-07-17T15:47:08.806033773Z,2025-07-17T15:47:08.805868059Z,160,2,1108,A,A,14.170000000,100,0,306171457,130,165714,256533443,ARL
2025-07-17T15:47:13.121454355Z,2025-07-17T15:47:13.121288953Z,160,2,1108,C,A,13.880000000,15,0,306121113,130,165402,256612694,ARL
2025-07-17T15:47:13.122562533Z,2025-07-17T15:47:13.122396816Z,160,2,1108,C,A,13.920000000,15,0,305862145,130,165717,256612757,ARL
2025-07-17T15:47:24.786476266Z,2025-07-17T15:47:24.786310694Z,160,2,1108,A,A,13.870000000,15,0,306519385,130,165572,256812416,ARL
2025-07-17T15:47:24.786745657Z,2025-07-17T15:47:24.786580061Z,160,2,1108,C,A,13.890000000,100,0,306170837,0,165596,256812420,ARL
2025-07-17T15:47:24.786745657Z,2025-07-17T15:47:24.786580061Z,160,2,1108,A,A,13.880000000,100,0,306519397,130,165596,256812420,ARL
2025-07-17T15:47:24.786925729Z,2025-07-17T15:47:24.786759805Z,160,2,1108,C,A,14.880000000,100,0,305184937,0,165924,256812422,ARL
2025-07-17T15:47:24.786925729Z,2025-07-17T15:47:24.786759805Z,160,2,1108,A,A,14.770000000,100,0,306519409,130,165924,256812422,ARL
2025-07-17T15:47:24.800616004Z,2025-07-17T15:47:24.800449950Z,160,2,1108,C,A,14.880000000,100,0,305184953,0,166054,256812578,ARL
2025-07-17T15:47:24.800616004Z,2025-07-17T15:47:24.800449950Z,160,2,1108,A,A,14.750000000,100,0,306519741,130,166054,256812578,ARL
2025-07-17T15:47:27.860272892Z,2025-07-17T15:47:27.860107552Z,160,2,1108,A,A,13.830000000,15,0,306587393,130,165340,256866835,ARL
2025-07-17T15:47:31.407029312Z,2025-07-17T15:47:31.406863918Z,160,2,1108,C,A,13.880000000,100,0,306519397,0,165394,256910124,ARL
2025-07-17T15:47:31.407029312Z,2025-07-17T15:47:31.406863918Z,160,2,1108,A,A,13.840000000,100,0,306647425,130,165394,256910124,ARL
2025-07-17T15:47:31.407771110Z,2025-07-17T15:47:31.407605685Z,160,2,1108,C,A,14.970000000,100,0,306170869,0,165425,256910129,ARL
2025-07-17T15:47:31.407771110Z,2025-07-17T15:47:31.407605685Z,160,2,1108,A,A,14.910000000,100,0,306647445,130,165425,256910129,ARL
2025-07-17T15:47:31.413491477Z,2025-07-17T15:47:31.413325908Z,160,2,1108,C,A,14.780000000,100,0,303331425,0,165569,256910184,ARL
2025-07-17T15:47:31.413491477Z,2025-07-17T15:47:31.413325908Z,160,2,1108,A,A,14.640000000,100,0,306647521,130,165569,256910184,ARL
2025-07-17T15:47:31.433486283Z,2025-07-17T15:47:31.433320466Z,160,2,1108,C,A,14.960000000,100,0,303330509,0,165817,256910721,ARL
2025-07-17T15:47:31.433486283Z,2025-07-17T15:47:31.433320466Z,160,2,1108,A,A,14.810000000,100,0,306649913,130,165817,256910721,ARL
2025-07-17T15:47:31.574128504Z,2025-07-17T15:47:31.573963059Z,160,2,1108,C,A,16.080000000,100,0,303331429,0,165445,256912087,ARL
2025-07-17T15:47:31.574128504Z,2025-07-17T15:47:31.573963059Z,160,2,1108,A,A,15.920000000,100,0,306652001,130,165445,256912087,ARL
2025-07-17T15:47:31.575374481Z,2025-07-17T15:47:31.575209032Z,160,2,1108,C,A,17.760000000,100,0,303331309,0,165449,256912094,ARL
2025-07-17T15:47:31.575374481Z,2025-07-17T15:47:31.575209032Z,160,2,1108,A,A,17.580000000,100,0,306652017,130,165449,256912094,ARL
2025-07-17T15:47:31.740095714Z,2025-07-17T15:47:31.739930142Z,160,2,1108,C,A,14.960000000,100,0,303334253,0,165572,256914067,ARL
2025-07-17T15:47:31.740095714Z,2025-07-17T15:47:31.739930142Z,160,2,1108,A,A,14.810000000,100,0,306653713,130,165572,256914067,ARL
2025-07-17T15:47:37.159589804Z,2025-07-17T15:47:37.159424166Z,160,2,1108,C,A,13.870000000,15,0,306519385,130,165638,256983942,ARL
2025-07-17T15:47:37.172000440Z,2025-07-17T15:47:37.171834941Z,160,2,1108,A,A,13.850000000,100,0,306749753,130,165499,256984053,ARL
2025-07-17T15:47:38.161181283Z,2025-07-17T15:47:38.161015969Z,160,2,1108,A,A,13.790000000,15,0,306770041,130,165314,256998606,ARL
2025-07-17T15:47:38.794962245Z,2025-07-17T15:47:38.794795887Z,160,2,1108,C,A,13.840000000,100,0,306647425,0,166358,257010989,ARL
2025-07-17T15:47:38.794962245Z,2025-07-17T15:47:38.794795887Z,160,2,1108,A,A,13.800000000,100,0,306784133,128,166358,257010989,ARL
2025-07-17T15:47:38.795723570Z,2025-07-17T15:47:38.795557785Z,160,2,1108,C,A,14.910000000,100,0,306647445,0,165785,257011058,ARL
2025-07-17T15:47:38.795723570Z,2025-07-17T15:47:38.795557785Z,160,2,1108,A,A,14.870000000,100,0,306784201,130,165785,257011058,ARL
2025-07-17T15:47:38.804624258Z,2025-07-17T15:47:38.804458744Z,160,2,1108,C,A,14.170000000,100,0,306171457,130,165514,257011716,ARL
2025-07-17T15:47:38.804679592Z,2025-07-17T15:47:38.804513793Z,160,2,1108,A,A,14.080000000,100,0,306784853,130,165799,257011717,ARL
2025-07-17T15:47:39.092472059Z,2025-07-17T15:47:39.092305947Z,160,2,1108,C,A,13.790000000,15,0,306770041,130,166112,257018687,ARL
2025-07-17T15:47:39.095920859Z,2025-07-17T15:47:39.095755335Z,160,2,1108,C,A,13.830000000,15,0,306587393,130,165524,257018796,ARL
2025-07-17T15:48:08.909366905Z,2025-07-17T15:48:08.909201576Z,160,2,1108,A,A,13.830000000,100,0,307567929,130,165329,257603755,ARL
2025-07-17T15:48:08.916721098Z,2025-07-17T15:48:08.916555821Z,160,2,1108,C,A,13.850000000,100,0,306749753,130,165277,257604057,ARL
2025-07-17T15:48:09.653473465Z,2025-07-17T15:48:09.653308042Z,160,2,1108,A,A,13.780000000,15,0,307587873,130,165423,257621095,ARL
2025-07-17T15:48:11.166689254Z,2025-07-17T15:48:11.166517494Z,160,2,1108,C,A,13.780000000,15,0,307587873,128,171760,257644020,ARL
2025-07-17T15:48:13.509078553Z,2025-07-17T15:48:13.508913083Z,160,2,1108,A,A,13.780000000,15,0,307714769,130,165470,257727039,ARL
2025-07-17T15:48:13.525953545Z,2025-07-17T15:48:13.525788139Z,160,2,1108,A,A,13.810000000,100,0,307715101,130,165406,257727301,ARL
2025-07-17T15:48:13.532608874Z,2025-07-17T15:48:13.532443045Z,160,2,1108,C,A,13.830000000,100,0,307567929,130,165829,257727457,ARL
2025-07-17T15:48:15.568544154Z,2025-07-17T15:48:15.568378275Z,160,2,1108,C,A,13.800000000,100,0,306784133,0,165879,257757458,ARL
2025-07-17T15:48:15.568544154Z,2025-07-17T15:48:15.568378275Z,160,2,1108,A,A,13.790000000,100,0,307753241,130,165879,257757458,ARL
2025-07-17T15:48:24.009355346Z,2025-07-17T15:48:24.009190157Z,160,2,1108,A,A,13.750000000,15,0,307964605,130,165189,257928318,ARL
2025-07-17T15:48:24.009522633Z,2025-07-17T15:48:24.009357442Z,160,2,1108,A,A,13.790000000,100,0,307964609,130,165191,257928319,ARL
2025-07-17T15:48:24.009944381Z,2025-07-17T15:48:24.009778967Z,160,2,1108,C,A,13.790000000,100,0,307753241,0,165414,257928325,ARL
2025-07-17T15:48:24.009944381Z,2025-07-17T15:48:24.009778967Z,160,2,1108,A,A,13.760000000,100,0,307964621,130,165414,257928325,ARL
2025-07-17T15:48:24.009974166Z,2025-07-17T15:48:24.009808793Z,160,2,1108,C,A,13.810000000,100,0,307715101,130,165373,257928326,ARL
2025-07-17T15:48:24.010555416Z,2025-07-17T15:48:24.010390029Z,160,2,1108,C,A,14.770000000,100,0,306519409,0,165387,257928333,ARL
2025-07-17T15:48:24.010555416Z,2025-07-17T15:48:24.010390029Z,160,2,1108,A,A,14.650000000,100,0,307964661,130,165387,257928333,ARL
2025-07-17T15:48:24.010677522Z,2025-07-17T15:48:24.010512050Z,160,2,1108,C,A,14.870000000,100,0,306784201,0,165472,257928340,ARL
2025-07-17T15:48:24.010677522Z,2025-07-17T15:48:24.010512050Z,160,2,1108,A,A,14.830000000,100,0,307964665,130,165472,257928340,ARL
2025-07-17T15:48:42.009954046Z,2025-07-17T15:48:42.009788565Z,160,2,1108,C,A,13.780000000,15,0,307714769,130,165481,258199397,ARL
2025-07-17T15:48:42.011846392Z,2025-07-17T15:48:42.011680742Z,160,2,1108,C,A,14.750000000,100,0,306519741,0,165650,258199535,ARL
2025-07-17T15:48:42.011846392Z,2025-07-17T15:48:42.011680742Z,160,2,1108,A,A,14.640000000,100,0,308296381,130,165650,258199535,ARL
2025-07-17T15:48:42.016761374Z,2025-07-17T15:48:42.016595806Z,160,2,1108,A,A,13.770000000,100,0,308296741,130,165568,258199787,ARL
2025-07-17T15:48:42.023432407Z,2025-07-17T15:48:42.023266760Z,160,2,1108,C,A,13.790000000,100,0,307964609,130,165647,258199990,ARL
2025-07-17T15:48:46.750088490Z,2025-07-17T15:48:46.749922127Z,160,2,1108,A,A,13.730000000,15,0,308374537,128,166363,258260871,ARL
2025-07-17T15:48:46.758551033Z,2025-07-17T15:48:46.758385367Z,160,2,1108,C,A,13.760000000,100,0,307964621,0,165666,258261154,ARL
2025-07-17T15:48:46.758551033Z,2025-07-17T15:48:46.758385367Z,160,2,1108,A,A,13.740000000,100,0,308374881,130,165666,258261154,ARL
2025-07-17T15:48:46.773668988Z,2025-07-17T15:48:46.773503306Z,160,2,1108,C,A,14.080000000,100,0,306784853,130,165682,258261538,ARL
2025-07-17T15:48:46.773720726Z,2025-07-17T15:48:46.773555566Z,160,2,1108,A,A,14.010000000,100,0,308375185,130,165160,258261539,ARL
2025-07-17T15:49:02.010494480Z,2025-07-17T15:49:02.010329052Z,160,2,1108,A,A,13.750000000,100,0,308705489,130,165428,258502869,ARL
2025-07-17T15:49:02.019989567Z,2025-07-17T15:49:02.019824230Z,160,2,1108,C,A,13.770000000,100,0,308296741,130,165337,258502929,ARL
2025-07-17T15:49:03.406005590Z,2025-07-17T15:49:03.405840358Z,160,2,1108,C,A,13.750000000,15,0,307964605,130,165232,258527308,ARL
2025-07-17T15:49:04.713997925Z,2025-07-17T15:49:04.713831675Z,160,2,1108,A,A,13.710000000,15,0,308763065,128,166250,258547335,ARL
2025-07-17T15:49:06.013111941Z,2025-07-17T15:49:06.012946379Z,160,2,1108,A,A,13.730000000,100,0,308786185,130,165562,258567259,ARL
2025-07-17T15:49:06.023292147Z,2025-07-17T15:49:06.023126600Z,160,2,1108,C,A,13.750000000,100,0,308705489,130,165547,258567405,ARL
2025-07-17T15:49:06.344356890Z,2025-07-17T15:49:06.344191321Z,160,2,1108,C,A,13.740000000,100,0,308374881,0,165569,258574949,ARL
2025-07-17T15:49:06.344356890Z,2025-07-17T15:49:06.344191321Z,160,2,1108,A,A,13.720000000,100,0,308797069,130,165569,258574949,ARL
2025-07-17T15:49:06.345104491Z,2025-07-17T15:49:06.344938975Z,160,2,1108,C,A,14.830000000,100,0,307964665,0,165516,258575013,ARL
2025-07-17T15:49:06.345104491Z,2025-07-17T15:49:06.344938975Z,160,2,1108,A,A,14.780000000,100,0,308797245,130,165516,258575013,ARL
2025-07-17T15:49:06.362945410Z,2025-07-17T15:49:06.362779870Z,160,2,1108,C,A,17.580000000,100,0,306652017,0,165540,258575963,ARL
2025-07-17T15:49:06.362945410Z,2025-07-17T15:49:06.362779870Z,160,2,1108,A,A,17.430000000,100,0,308799373,130,165540,258575963,ARL
2025-07-17T15:49:10.459317885Z,2025-07-17T15:49:10.459152457Z,160,2,1108,C,A,13.730000000,15,0,308374537,130,165428,258636400,ARL
2025-07-17T15:49:11.460597600Z,2025-07-17T15:49:11.460432218Z,160,2,1108,A,A,13.690000000,15,0,308893737,130,165382,258650544,ARL
2025-07-17T15:49:11.891643099Z,2025-07-17T15:49:11.891477604Z,160,2,1108,C,A,13.720000000,100,0,308797069,0,165495,258658721,ARL
2025-07-17T15:49:11.891643099Z,2025-07-17T15:49:11.891477604Z,160,2,1108,A,A,13.700000000,100,0,308901793,130,165495,258658721,ARL
2025-07-17T15:49:11.893989071Z,2025-07-17T15:49:11.893823458Z,160,2,1108,C,A,14.810000000,100,0,306649913,0,165613,258658835,ARL
2025-07-17T15:49:11.893989071Z,2025-07-17T15:49:11.893823458Z,160,2,1108,A,A,14.660000000,100,0,308901981,130,165613,258658835,ARL
2025-07-17T15:49:11.904231149Z,2025-07-17T15:49:11.904065674Z,160,2,1108,C,A,15.920000000,100,0,306652001,0,165475,258659039,ARL
2025-07-17T15:49:11.904231149Z,2025-07-17T15:49:11.904065674Z,160,2,1108,A,A,15.760000000,100,0,308902229,130,165475,258659039,ARL
2025-07-17T15:49:11.935521687Z,2025-07-17T15:49:11.935356090Z,160,2,1108,C,A,14.810000000,100,0,306653713,0,165597,258659320,ARL
2025-07-17T15:49:11.935521687Z,2025-07-17T15:49:11.935356090Z,160,2,1108,A,A,14.660000000,100,0,308903001,130,165597,258659320,ARL
2025-07-17T15:49:11.948701049Z,2025-07-17T15:49:11.948535655Z,160,2,1108,C,A,14.640000000,100,0,306647521,130,165394,258659496,ARL
2025-07-17T15:49:11.948829112Z,2025-07-17T15:49:11.948663655Z,160,2,1108,A,A,14.500000000,100,0,308903349,130,165457,258659499,ARL
2025-07-17T15:49:12.221221367Z,2025-07-17T15:49:12.221056085Z,160,2,1108,A,A,13.710000000,100,0,308909249,130,165282,258663292,ARL
2025-07-17T15:49:12.227986905Z,2025-07-17T15:49:12.227821500Z,160,2,1108,C,A,13.730000000,100,0,308786185,130,165405,258663378,ARL
2025-07-17T15:49:14.463229121Z,2025-07-17T15:49:14.463063539Z,160,2,1108,C,A,13.710000000,15,0,308763065,130,165582,258702625,ARL
2025-07-17T15:49:15.466365122Z,2025-07-17T15:49:15.466199239Z,160,2,1108,A,A,13.670000000,15,0,308980305,130,165883,258716863,ARL
2025-07-17T15:49:16.351024588Z,2025-07-17T15:49:16.350859152Z,160,2,1108,C,A,13.700000000,100,0,308901793,0,165436,258727929,ARL
2025-07-17T15:49:16.351024588Z,2025-07-17T15:49:16.350859152Z,160,2,1108,A,A,13.680000000,100,0,308998225,130,165436,258727929,ARL
2025-07-17T15:49:16.351759618Z,2025-07-17T15:49:16.351594042Z,160,2,1108,C,A,14.780000000,100,0,308797245,0,165576,258727956,ARL
2025-07-17T15:49:16.351759618Z,2025-07-17T15:49:16.351594042Z,160,2,1108,A,A,14.740000000,100,0,308998341,130,165576,258727956,ARL
2025-07-17T15:49:16.494111490Z,2025-07-17T15:49:16.493946243Z,160,2,1108,A,A,13.690000000,100,0,309001525,130,165247,258729266,ARL
2025-07-17T15:49:16.557924863Z,2025-07-17T15:49:16.557759633Z,160,2,1108,C,A,13.710000000,100,0,308909249,130,165230,258730034,ARL
2025-07-17T15:49:21.186150487Z,2025-07-17T15:49:21.185984774Z,160,2,1108,C,A,14.070000000,2,0,296478973,0,165713,258786552,ARL
2025-07-17T15:49:21.186150487Z,2025-07-17T15:49:21.185984774Z,160,2,1108,A,A,13.980000000,2,0,309091513,130,165713,258786552,ARL
2025-07-17T15:49:24.283152112Z,2025-07-17T15:49:24.282985894Z,160,2,1108,C,A,13.690000000,15,0,308893737,130,166218,258838460,ARL
2025-07-17T15:49:34.570197134Z,2025-07-17T15:49:34.570031718Z,160,2,1108,C,A,13.670000000,15,0,308980305,130,165416,258980876,ARL
2025-07-17T15:49:34.591512915Z,2025-07-17T15:49:34.591347169Z,160,2,1108,C,A,13.690000000,100,0,309001525,130,165746,258983321,ARL
2025-07-17T15:49:38.610017394Z,2025-07-17T15:49:38.609851985Z,160,2,1108,A,A,13.720000000,100,0,309410565,130,165409,259031220,ARL
2025-07-17T15:49:38.610073334Z,2025-07-17T15:49:38.609907720Z,160,2,1108,C,B,13.260000000,100,0,291975017,130,165614,259031221,ARL
2025-07-17T15:49:39.068515005Z,2025-07-17T15:49:39.068349660Z,160,2,1108,A,B,13.020000000,100,0,309415429,130,165345,259035032,ARL
2025-07-17T15:49:44.788414401Z,2025-07-17T15:49:44.788249210Z,160,2,1108,A,A,13.670000000,15,0,309524921,130,165191,259105347,ARL
2025-07-17T15:49:44.789020757Z,2025-07-17T15:49:44.788855587Z,160,2,1108,A,A,13.700000000,100,0,309524933,130,165170,259105361,ARL
2025-07-17T15:49:44.789702916Z,2025-07-17T15:49:44.789537536Z,160,2,1108,C,A,13.720000000,100,0,309410565,130,165380,259105380,ARL
2025-07-17T15:49:54.788658841Z,2025-07-17T15:49:54.788493605Z,160,2,1108,A,A,13.650000000,15,0,309707269,130,165236,259253294,ARL
2025-07-17T15:49:54.799535744Z,2025-07-17T15:49:54.799370442Z,160,2,1108,A,A,13.680000000,100,0,309707413,130,165302,259253527,ARL
2025-07-17T15:49:54.820634917Z,2025-07-17T15:49:54.820469390Z,160,2,1108,C,A,13.700000000,100,0,309524933,130,165527,259253732,ARL
2025-07-17T15:49:59.512104064Z,2025-07-17T15:49:59.511938438Z,160,2,1108,C,A,13.680000000,100,0,308998225,0,165626,259313537,ARL
2025-07-17T15:49:59.512104064Z,2025-07-17T15:49:59.511938438Z,160,2,1108,A,A,13.660000000,100,0,309782481,130,165626,259313537,ARL
2025-07-17T15:49:59.534062634Z,2025-07-17T15:49:59.533897369Z,160,2,1108,C,A,14.010000000,100,0,308375185,130,165265,259314032,ARL
2025-07-17T15:49:59.534115275Z,2025-07-17T15:49:59.533948952Z,160,2,1108,A,A,13.930000000,100,0,309782973,130,166323,259314033,ARL
2025-07-17T15:50:00.547404972Z,2025-07-17T15:50:00.547239401Z,160,2,1108,C,A,13.670000000,15,0,309524921,130,165571,259349868,ARL
2025-07-17T15:50:00.555536688Z,2025-07-17T15:50:00.555363249Z,160,2,1108,C,A,14.650000000,100,0,307964661,0,173439,259353226,ARL
2025-07-17T15:50:00.555536688Z,2025-07-17T15:50:00.555363249Z,160,2,1108,A,A,14.540000000,100,0,309823025,128,173439,259353226,ARL
2025-07-17T15:50:03.412422880Z,2025-07-17T15:50:03.412257475Z,160,2,1108,A,A,13.630000000,15,0,309899025,130,165405,259413272,ARL
2025-07-17T15:50:03.415527372Z,2025-07-17T15:50:03.415361851Z,160,2,1108,C,A,14.640000000,100,0,308296381,0,165521,259413427,ARL
2025-07-17T15:50:03.415527372Z,2025-07-17T15:50:03.415361851Z,160,2,1108,A,A,14.530000000,100,0,309899141,130,165521,259413427,ARL
2025-07-17T15:50:03.824292152Z,2025-07-17T15:50:03.824126753Z,160,2,1108,C,A,13.660000000,100,0,309782481,0,165399,259418661,ARL
2025-07-17T15:50:03.824292152Z,2025-07-17T15:50:03.824126753Z,160,2,1108,A,A,13.640000000,100,0,309903973,130,165399,259418661,ARL
2025-07-17T15:50:03.825028460Z,2025-07-17T15:50:03.824863026Z,160,2,1108,C,A,14.740000000,100,0,308998341,0,165434,259418664,ARL
2025-07-17T15:50:03.825028460Z,2025-07-17T15:50:03.824863026Z,160,2,1108,A,A,14.700000000,100,0,309903993,130,165434,259418664,ARL
2025-07-17T15:50:04.484898759Z,2025-07-17T15:50:04.484733438Z,160,2,1108,A,A,13.660000000,100,0,309922345,130,165321,259433904,ARL
2025-07-17T15:50:04.524729039Z,2025-07-17T15:50:04.524563568Z,160,2,1108,C,A,13.680000000,100,0,309707413,130,165471,259434652,ARL
2025-07-17T15:50:06.787826975Z,2025-07-17T15:50:06.787661846Z,160,2,1108,C,A,13.630000000,15,0,309899025,130,165129,259472951,ARL
2025-07-17T15:50:09.185499367Z,2025-07-17T15:50:09.185334126Z,160,2,1108,A,A,13.610000000,15,0,310030465,130,165241,259516855,ARL
2025-07-17T15:50:09.198476437Z,2025-07-17T15:50:09.198311198Z,160,2,1108,A,A,13.640000000,100,0,310031625,130,165239,259517754,ARL
2025-07-17T15:50:09.205487416Z,2025-07-17T15:50:09.205322092Z,160,2,1108,C,A,13.660000000,100,0,309922345,130,165324,259517973,ARL
2025-07-17T15:50:09.330738153Z,2025-07-17T15:50:09.330572653Z,160,2,1108,C,A,13.640000000,100,0,309903973,0,165500,259522708,ARL
2025-07-17T15:50:09.330738153Z,2025-07-17T15:50:09.330572653Z,160,2,1108,A,A,13.620000000,100,0,310037965,130,165500,259522708,ARL
2025-07-17T15:50:20.204539185Z,2025-07-17T15:50:20.204373858Z,160,2,1108,C,A,13.650000000,15,0,309707269,130,165327,259737768,ARL
2025-07-17T15:50:25.935579034Z,2025-07-17T15:50:25.935412900Z,160,2,1108,A,A,13.590000000,15,0,310424077,128,166134,259828644,ARL
2025-07-17T15:50:26.954828150Z,2025-07-17T15:50:26.954662143Z,160,2,1108,C,A,13.620000000,100,0,310037965,0,166007,259847181,ARL
2025-07-17T15:50:26.954828150Z,2025-07-17T15:50:26.954662143Z,160,2,1108,A,A,13.600000000,100,0,310446249,130,166007,259847181,ARL
2025-07-17T15:50:26.955565904Z,2025-07-17T15:50:26.955400327Z,160,2,1108,C,A,14.700000000,100,0,309903993,0,165577,259847190,ARL
2025-07-17T15:50:26.955565904Z,2025-07-17T15:50:26.955400327Z,160,2,1108,A,A,14.650000000,100,0,310446269,130,165577,259847190,ARL
2025-07-17T15:50:26.956259508Z,2025-07-17T15:50:26.956094101Z,160,2,1108,C,A,17.430000000,100,0,308799373,0,165407,259847199,ARL
2025-07-17T15:50:26.956259508Z,2025-07-17T15:50:26.956094101Z,160,2,1108,A,A,17.280000000,100,0,310446293,130,165407,259847199,ARL
2025-07-17T15:50:26.983044736Z,2025-07-17T15:50:26.982879448Z,160,2,1108,A,A,15.510000000,100,0,310447441,130,165288,259847556,ARL
2025-07-17T15:50:26.983057675Z,2025-07-17T15:50:26.982892468Z,160,2,1108,C,A,15.780000000,100,0,282776733,130,165207,259847557,ARL
2025-07-17T15:50:30.046879569Z,2025-07-17T15:50:30.046714265Z,160,2,1108,C,A,13.590000000,15,0,310424077,130,165304,259916670,ARL
2025-07-17T15:50:30.047015114Z,2025-07-17T15:50:30.046849726Z,160,2,1108,C,A,13.610000000,15,0,310030465,130,165388,259916674,ARL
2025-07-17T15:51:37.986158330Z,2025-07-17T15:51:37.985992174Z,160,2,1108,C,A,13.980000000,2,0,309091513,0,166156,261130345,ARL
2025-07-17T15:51:37.986158330Z,2025-07-17T15:51:37.985992174Z,160,2,1108,A,A,13.890000000,2,0,311979125,130,166156,261130345,ARL
2025-07-17T15:52:16.371517839Z,2025-07-17T15:52:16.371351021Z,160,2,1108,T,N,13.410000000,58,0,0,0,166818,261713745,ARL
2025-07-17T15:52:16.371517839Z,2025-07-17T15:52:16.371351021Z,160,2,1108,T,N,13.280000000,12,0,0,130,166818,261713746,ARL
2025-07-17T15:52:16.372434625Z,2025-07-17T15:52:16.372269170Z,160,2,1108,C,A,13.600000000,100,0,310446249,130,165455,261713790,ARL
2025-07-17T15:52:16.373188791Z,2025-07-17T15:52:16.373023186Z,160,2,1108,C,A,14.650000000,100,0,310446269,0,165605,261713830,ARL
2025-07-17T15:52:16.373188791Z,2025-07-17T15:52:16.373023186Z,160,2,1108,A,A,14.700000000,100,0,312771573,130,165605,261713830,ARL
2025-07-17T15:52:16.374353159Z,2025-07-17T15:52:16.374186508Z,160,2,1108,C,A,13.640000000,100,0,310031625,130,166651,261713870,ARL
2025-07-17T15:52:16.374480183Z,2025-07-17T15:52:16.374312976Z,160,2,1108,A,A,15.860000000,100,0,312771645,128,167207,261713880,ARL
2025-07-17T15:52:16.374493650Z,2025-07-17T15:52:16.374327668Z,160,2,1108,C,A,15.510000000,100,0,310447441,130,165982,261713884,ARL
2025-07-17T15:52:16.375388285Z,2025-07-17T15:52:16.375222836Z,160,2,1108,C,A,14.540000000,100,0,309823025,0,165449,261713944,ARL
2025-07-17T15:52:16.375388285Z,2025-07-17T15:52:16.375222836Z,160,2,1108,A,A,14.810000000,100,0,312771781,130,165449,261713944,ARL
2025-07-17T15:52:16.375414247Z,2025-07-17T15:52:16.375248654Z,160,2,1108,C,A,14.660000000,100,0,308901981,0,165593,261713945,ARL
2025-07-17T15:52:16.375414247Z,2025-07-17T15:52:16.375248654Z,160,2,1108,A,A,14.890000000,100,0,312771785,130,165593,261713945,ARL
2025-07-17T15:52:16.375828154Z,2025-07-17T15:52:16.375662552Z,160,2,1108,C,A,14.530000000,100,0,309899141,0,165602,261713959,ARL
2025-07-17T15:52:16.375828154Z,2025-07-17T15:52:16.375662552Z,160,2,1108,A,A,14.760000000,100,0,312771829,130,165602,261713959,ARL
2025-07-17T15:52:16.377345053Z,2025-07-17T15:52:16.377179230Z,160,2,1108,C,A,17.280000000,100,0,310446293,0,165823,261714104,ARL
2025-07-17T15:52:16.377345053Z,2025-07-17T15:52:16.377179230Z,160,2,1108,A,A,17.700000000,100,0,312772009,130,165823,261714104,ARL
2025-07-17T15:52:16.378239114Z,2025-07-17T15:52:16.378073674Z,160,2,1108,C,A,15.760000000,100,0,308902229,0,165440,261714140,ARL
2025-07-17T15:52:16.378239114Z,2025-07-17T15:52:16.378073674Z,160,2,1108,A,A,16.020000000,100,0,312772057,130,165440,261714140,ARL
2025-07-17T15:52:16.378385943Z,2025-07-17T15:52:16.378220434Z,160,2,1108,C,A,14.500000000,100,0,308903349,0,165509,261714145,ARL
2025-07-17T15:52:16.378385943Z,2025-07-17T15:52:16.378220434Z,160,2,1108,A,A,14.720000000,100,0,312772061,130,165509,261714145,ARL
2025-07-17T15:52:16.378870638Z,2025-07-17T15:52:16.378705201Z,160,2,1108,A,B,13.270000000,10,0,312772069,130,165437,261714171,ARL
2025-07-17T15:52:16.378872385Z,2025-07-17T15:52:16.378707041Z,160,2,1108,A,A,13.860000000,15,0,312772073,130,165344,261714172,ARL
2025-07-17T15:52:16.379127782Z,2025-07-17T15:52:16.378962330Z,160,2,1108,C,B,13.020000000,100,0,309415429,0,165452,261714185,ARL
2025-07-17T15:52:16.379127782Z,2025-07-17T15:52:16.378962330Z,160,2,1108,A,B,13.260000000,100,0,312772077,130,165452,261714185,ARL
2025-07-17T15:52:16.389025469Z,2025-07-17T15:52:16.388859982Z,160,2,1108,C,A,13.930000000,100,0,309782973,130,165487,261714477,ARL
2025-07-17T15:52:16.389082451Z,2025-07-17T15:52:16.388917108Z,160,2,1108,A,A,14.190000000,100,0,312772501,130,165343,261714481,ARL
2025-07-17T15:52:16.396174502Z,2025-07-17T15:52:16.396008715Z,160,2,1108,C,A,14.660000000,100,0,308903001,0,165787,261714603,ARL
2025-07-17T15:52:16.396174502Z,2025-07-17T15:52:16.396008715Z,160,2,1108,A,A,14.960000000,100,0,312772869,130,165787,261714603,ARL
2025-07-17T15:52:16.397677681Z,2025-07-17T15:52:16.397512710Z,160,2,1108,C,A,14.190000000,100,0,312772501,130,164971,261714619,ARL
2025-07-17T15:52:16.397727042Z,2025-07-17T15:52:16.397561691Z,160,2,1108,A,A,14.260000000,100,0,312772901,130,165351,261714620,ARL
2025-07-17T15:52:16.424137423Z,2025-07-17T15:52:16.423972000Z,160,2,1108,C,A,14.700000000,100,0,312771573,0,165423,261714976,ARL
2025-07-17T15:52:16.424137423Z,2025-07-17T15:52:16.423972000Z,160,2,1108,A,A,15.060000000,100,0,312773353,130,165423,261714976,ARL
2025-07-17T15:52:16.464781343Z,2025-07-17T15:52:16.464616142Z,160,2,1108,A,A,13.870000000,100,0,312773881,130,165201,261715303,ARL
2025-07-17T15:52:16.473556948Z,2025-07-17T15:52:16.473391480Z,160,2,1108,C,A,15.060000000,100,0,312773353,0,165468,261715409,ARL
2025-07-17T15:52:16.473556948Z,2025-07-17T15:52:16.473391480Z,160,2,1108,A,A,14.950000000,100,0,312774001,130,165468,261715409,ARL
2025-07-17T15:52:16.480090894Z,2025-07-17T15:52:16.479925781Z,160,2,1108,C,A,14.260000000,100,0,312772901,130,165113,261715467,ARL
2025-07-17T15:52:16.480140131Z,2025-07-17T15:52:16.479974840Z,160,2,1108,A,A,14.150000000,100,0,312774033,130,165291,261715468,ARL
2025-07-17T15:52:28.787316865Z,2025-07-17T15:52:28.787151494Z,160,2,1108,C,B,13.270000000,10,0,312772069,130,165371,261883294,ARL
2025-07-17T15:52:28.787317827Z,2025-07-17T15:52:28.787152437Z,160,2,1108,C,A,13.860000000,15,0,312772073,130,165390,261883295,ARL
2025-07-17T15:52:43.128371033Z,2025-07-17T15:52:43.128203357Z,160,2,1108,C,A,13.890000000,2,0,311979125,0,167676,262115170,ARL
2025-07-17T15:52:43.128371033Z,2025-07-17T15:52:43.128203357Z,160,2,1108,A,A,13.990000000,2,0,313336713,128,167676,262115170,ARL
2025-07-17T15:54:24.908483782Z,2025-07-17T15:54:24.908318259Z,160,2,1108,A,B,13.290000000,10,0,315581981,130,165523,263863872,ARL
2025-07-17T15:54:26.792478456Z,2025-07-17T15:54:26.792313320Z,160,2,1108,C,B,13.290000000,10,0,315581981,130,165136,263895481,ARL
2025-07-17T15:54:52.986116083Z,2025-07-17T15:54:52.985950259Z,160,2,1108,C,A,13.990000000,2,0,313336713,0,165824,264262615,ARL
2025-07-17T15:54:52.986116083Z,2025-07-17T15:54:52.985950259Z,160,2,1108,A,A,14.100000000,2,0,316098525,130,165824,264262615,ARL
2025-07-17T15:55:33.673598252Z,2025-07-17T15:55:33.673432762Z,160,2,1108,A,B,13.290000000,10,0,316911465,130,165490,264905534,ARL
2025-07-17T15:55:34.257417204Z,2025-07-17T15:55:34.257251787Z,160,2,1108,C,B,13.260000000,100,0,312772077,0,165417,264919835,ARL
2025-07-17T15:55:34.257417204Z,2025-07-17T15:55:34.257251787Z,160,2,1108,A,B,13.280000000,100,0,316924721,130,165417,264919835,ARL
2025-07-17T15:55:40.197750400Z,2025-07-17T15:55:40.197584524Z,160,2,1108,C,B,13.290000000,10,0,316911465,130,165876,265015966,ARL
2025-07-17T15:57:51.111288955Z,2025-07-17T15:57:51.111121910Z,160,2,1108,T,N,13.600000000,1,0,0,0,167045,267268162,ARL
2025-07-17T15:57:51.111288955Z,2025-07-17T15:57:51.111121910Z,160,2,1108,T,N,13.575000000,99,0,0,130,167045,267268163,ARL
2025-07-17T15:57:51.111693755Z,2025-07-17T15:57:51.111527963Z,160,2,1108,T,N,13.575000000,100,0,0,130,165792,267268168,ARL
2025-07-17T15:57:51.112077532Z,2025-07-17T15:57:51.111911476Z,160,2,1108,T,N,13.575000000,1,0,0,130,166056,267268183,ARL
2025-07-17T15:57:51.328863560Z,2025-07-17T15:57:51.328698198Z,160,2,1108,C,A,13.870000000,100,0,312773881,130,165362,267272430,ARL
2025-07-17T15:57:51.329613584Z,2025-07-17T15:57:51.329447325Z,160,2,1108,C,A,14.950000000,100,0,312774001,0,166259,267272438,ARL
2025-07-17T15:57:51.329613584Z,2025-07-17T15:57:51.329447325Z,160,2,1108,A,A,15.000000000,100,0,319985021,130,166259,267272438,ARL
2025-07-17T15:57:51.329857672Z,2025-07-17T15:57:51.329692071Z,160,2,1108,C,A,14.760000000,100,0,312771829,0,165601,267272442,ARL
2025-07-17T15:57:51.329857672Z,2025-07-17T15:57:51.329692071Z,160,2,1108,A,A,14.890000000,100,0,319985025,130,165601,267272442,ARL
2025-07-17T15:57:51.339328219Z,2025-07-17T15:57:51.339162512Z,160,2,1108,C,A,14.150000000,100,0,312774033,130,165707,267272660,ARL
2025-07-17T15:57:51.339382098Z,2025-07-17T15:57:51.339216923Z,160,2,1108,A,A,14.260000000,100,0,319985165,130,165175,267272665,ARL
2025-07-17T15:57:51.379736852Z,2025-07-17T15:57:51.379570470Z,160,2,1108,C,A,15.000000000,100,0,319985021,0,166382,267273071,ARL
2025-07-17T15:57:51.379736852Z,2025-07-17T15:57:51.379570470Z,160,2,1108,A,A,15.060000000,100,0,319985497,128,166382,267273071,ARL
2025-07-17T15:57:52.378369524Z,2025-07-17T15:57:52.378204338Z,160,2,1108,A,A,14.110000000,100,0,320000233,130,165186,267283873,ARL
2025-07-17T15:58:14.483879079Z,2025-07-17T15:58:14.483712278Z,160,2,1108,T,N,13.410000000,44,0,0,130,166801,267657010,ARL
2025-07-17T15:58:14.483909354Z,2025-07-17T15:58:14.483743947Z,160,2,1108,A,A,13.760000000,4,0,320484625,130,165407,267657011,ARL
2025-07-17T15:58:14.484164551Z,2025-07-17T15:58:14.483999049Z,160,2,1108,C,A,14.110000000,100,0,320000233,0,165502,267657013,ARL
2025-07-17T15:58:14.484164551Z,2025-07-17T15:58:14.483999049Z,160,2,1108,A,A,13.770000000,100,0,320484637,130,165502,267657013,ARL
2025-07-17T15:58:14.484183413Z,2025-07-17T15:58:14.484017806Z,160,2,1108,C,B,13.280000000,100,0,316924721,130,165607,267657014,ARL
2025-07-17T15:58:14.484299450Z,2025-07-17T15:58:14.484133730Z,160,2,1108,T,N,13.410000000,8,0,0,130,165720,267657017,ARL
2025-07-17T15:58:14.484312532Z,2025-07-17T15:58:14.484147359Z,160,2,1108,A,A,13.790000000,100,0,320484661,130,165173,267657020,ARL
2025-07-17T15:58:14.484902175Z,2025-07-17T15:58:14.484736787Z,160,2,1108,C,A,15.060000000,100,0,319985497,0,165388,267657063,ARL
2025-07-17T15:58:14.484902175Z,2025-07-17T15:58:14.484736787Z,160,2,1108,A,A,14.840000000,100,0,320484709,130,165388,267657063,ARL
2025-07-17T15:58:14.484927848Z,2025-07-17T15:58:14.484761664Z,160,2,1108,C,A,13.760000000,4,0,320484625,128,166184,267657070,ARL
2025-07-17T15:58:14.484963870Z,2025-07-17T15:58:14.484798779Z,160,2,1108,C,A,13.770000000,100,0,320484637,130,165091,267657073,ARL
2025-07-17T15:58:14.485392903Z,2025-07-17T15:58:14.485227487Z,160,2,1108,C,A,14.810000000,100,0,312771781,0,165416,267657092,ARL
2025-07-17T15:58:14.485392903Z,2025-07-17T15:58:14.485227487Z,160,2,1108,A,A,14.680000000,100,0,320484781,130,165416,267657092,ARL
2025-07-17T15:58:14.485831602Z,2025-07-17T15:58:14.485666254Z,160,2,1108,C,A,16.020000000,100,0,312772057,0,165348,267657097,ARL
2025-07-17T15:58:14.485831602Z,2025-07-17T15:58:14.485666254Z,160,2,1108,A,A,15.860000000,100,0,320484817,130,165348,267657097,ARL
2025-07-17T15:58:14.485850874Z,2025-07-17T15:58:14.485685308Z,160,2,1108,C,A,14.960000000,100,0,312772869,0,165566,267657098,ARL
2025-07-17T15:58:14.485850874Z,2025-07-17T15:58:14.485685308Z,160,2,1108,A,A,14.760000000,100,0,320484821,130,165566,267657098,ARL
2025-07-17T15:58:14.485989643Z,2025-07-17T15:58:14.485824228Z,160,2,1108,C,A,14.890000000,100,0,319985025,0,165415,267657101,ARL
2025-07-17T15:58:14.485989643Z,2025-07-17T15:58:14.485824228Z,160,2,1108,A,A,14.690000000,100,0,320484825,130,165415,267657101,ARL
2025-07-17T15:58:14.486406355Z,2025-07-17T15:58:14.486240860Z,160,2,1108,C,A,17.700000000,100,0,312772009,0,165495,267657116,ARL
2025-07-17T15:58:14.486406355Z,2025-07-17T15:58:14.486240860Z,160,2,1108,A,A,17.520000000,100,0,320484837,130,165495,267657116,ARL
2025-07-17T15:58:14.508177256Z,2025-07-17T15:58:14.508012098Z,160,2,1108,C,A,14.260000000,100,0,319985165,130,165158,267657330,ARL
2025-07-17T15:58:14.508227890Z,2025-07-17T15:58:14.508062605Z,160,2,1108,A,A,14.050000000,100,0,320484985,130,165285,267657333,ARL
2025-07-17T15:58:14.529557108Z,2025-07-17T15:58:14.529391743Z,160,2,1108,A,B,13.020000000,100,0,320485385,130,165365,267657561,ARL
2025-07-17T15:58:14.529578291Z,2025-07-17T15:58:14.529413184Z,160,2,1108,A,A,13.800000000,100,0,320485389,130,165107,267657562,ARL
2025-07-17T15:58:14.659899426Z,2025-07-17T15:58:14.659734381Z,160,2,1108,C,A,13.790000000,100,0,320484661,130,165045,267658873,ARL
2025-07-17T15:58:14.659939230Z,2025-07-17T15:58:14.659773896Z,160,2,1108,C,A,13.800000000,100,0,320485389,130,165334,267658879,ARL
2025-07-17T15:58:14.660667636Z,2025-07-17T15:58:14.660502341Z,160,2,1108,C,A,14.840000000,100,0,320484709,0,165295,267658892,ARL
2025-07-17T15:58:14.660667636Z,2025-07-17T15:58:14.660502341Z,160,2,1108,A,A,14.910000000,100,0,320486925,130,165295,267658892,ARL
2025-07-17T15:58:14.664378962Z,2025-07-17T15:58:14.664213722Z,160,2,1108,C,A,17.520000000,100,0,320484837,0,165240,267658928,ARL
2025-07-17T15:58:14.664378962Z,2025-07-17T15:58:14.664213722Z,160,2,1108,A,A,17.760000000,100,0,320486937,130,165240,267658928,ARL
2025-07-17T15:58:14.664939310Z,2025-07-17T15:58:14.664774078Z,160,2,1108,C,A,15.860000000,100,0,320484817,0,165232,267658931,ARL
2025-07-17T15:58:14.664939310Z,2025-07-17T15:58:14.664774078Z,160,2,1108,A,A,16.080000000,100,0,320486945,130,165232,267658931,ARL
2025-07-17T15:58:14.672315806Z,2025-07-17T15:58:14.672150755Z,160,2,1108,C,A,14.050000000,100,0,320484985,130,165051,267658982,ARL
2025-07-17T15:58:14.672365974Z,2025-07-17T15:58:14.672200872Z,160,2,1108,A,A,14.120000000,100,0,320487017,130,165102,267658983,ARL
2025-07-17T15:58:14.673184116Z,2025-07-17T15:58:14.673019194Z,160,2,1108,C,A,14.120000000,100,0,320487017,130,164922,267658989,ARL
2025-07-17T15:58:14.673230480Z,2025-07-17T15:58:14.673065320Z,160,2,1108,A,A,14.260000000,100,0,320487025,130,165160,267658990,ARL
2025-07-17T15:58:14.682945541Z,2025-07-17T15:58:14.682780396Z,160,2,1108,C,A,14.760000000,100,0,320484821,0,165145,267659018,ARL
2025-07-17T15:58:14.682945541Z,2025-07-17T15:58:14.682780396Z,160,2,1108,A,A,14.960000000,100,0,320487105,130,165145,267659018,ARL
2025-07-17T15:58:14.710787891Z,2025-07-17T15:58:14.710622495Z,160,2,1108,C,A,14.910000000,100,0,320486925,0,165396,267659178,ARL
2025-07-17T15:58:14.710787891Z,2025-07-17T15:58:14.710622495Z,160,2,1108,A,A,15.060000000,100,0,320487357,130,165396,267659178,ARL
2025-07-17T15:58:15.564070256Z,2025-07-17T15:58:15.563904700Z,160,2,1108,C,A,14.680000000,100,0,320484781,0,165556,267672469,ARL
2025-07-17T15:58:15.564070256Z,2025-07-17T15:58:15.563904700Z,160,2,1108,A,A,14.870000000,100,0,320504473,130,165556,267672469,ARL
2025-07-17T15:58:15.577719796Z,2025-07-17T15:58:15.577554368Z,160,2,1108,C,A,14.690000000,100,0,320484825,0,165428,267672549,ARL
2025-07-17T15:58:15.577719796Z,2025-07-17T15:58:15.577554368Z,160,2,1108,A,A,14.880000000,100,0,320504609,130,165428,267672549,ARL
2025-07-17T15:58:16.502080515Z,2025-07-17T15:58:16.501915292Z,160,2,1108,A,A,14.110000000,100,0,320519893,130,165223,267685252,ARL
2025-07-17T15:58:19.965200980Z,2025-07-17T15:58:19.965034325Z,160,2,1108,A,A,13.940000000,15,0,320588689,130,166655,267738403,ARL
2025-07-17T15:58:20.237833402Z,2025-07-17T15:58:20.237668047Z,160,2,1108,C,A,14.110000000,100,0,320519893,0,165355,267745213,ARL
2025-07-17T15:58:20.237833402Z,2025-07-17T15:58:20.237668047Z,160,2,1108,A,A,13.950000000,100,0,320595817,130,165355,267745213,ARL
2025-07-17T15:58:20.705512171Z,2025-07-17T15:58:20.705344578Z,160,2,1108,C,A,13.940000000,15,0,320588689,128,167593,267754327,ARL
2025-07-17T15:58:30.800053062Z,2025-07-17T15:58:30.799887713Z,160,2,1108,A,A,13.890000000,15,0,320833897,130,165349,267913947,ARL
2025-07-17T15:58:30.905657319Z,2025-07-17T15:58:30.905491759Z,160,2,1108,C,A,13.950000000,100,0,320595817,0,165560,267919515,ARL
2025-07-17T15:58:30.905657319Z,2025-07-17T15:58:30.905491759Z,160,2,1108,A,A,13.900000000,100,0,320839125,130,165560,267919515,ARL
2025-07-17T15:58:30.906412286Z,2025-07-17T15:58:30.906246950Z,160,2,1108,C,A,15.060000000,100,0,320487357,0,165336,267919540,ARL
2025-07-17T15:58:30.906412286Z,2025-07-17T15:58:30.906246950Z,160,2,1108,A,A,14.980000000,100,0,320839149,130,165336,267919540,ARL
2025-07-17T15:58:30.916726353Z,2025-07-17T15:58:30.916561264Z,160,2,1108,C,A,14.260000000,100,0,320487025,130,165089,267919917,ARL
2025-07-17T15:58:30.916784278Z,2025-07-17T15:58:30.916619122Z,160,2,1108,A,A,14.180000000,100,0,320839577,130,165156,267919919,ARL
2025-07-17T15:58:31.124388717Z,2025-07-17T15:58:31.124222733Z,160,2,1108,C,A,14.870000000,100,0,320504473,0,165984,267925564,ARL
2025-07-17T15:58:31.124388717Z,2025-07-17T15:58:31.124222733Z,160,2,1108,A,A,14.760000000,100,0,320845893,130,165984,267925564,ARL
2025-07-17T15:58:31.136439248Z,2025-07-17T15:58:31.136273403Z,160,2,1108,C,A,14.880000000,100,0,320504609,0,165845,267925951,ARL
2025-07-17T15:58:31.136439248Z,2025-07-17T15:58:31.136273403Z,160,2,1108,A,A,14.770000000,100,0,320846429,130,165845,267925951,ARL
2025-07-17T15:58:40.799952243Z,2025-07-17T15:58:40.799787018Z,160,2,1108,A,A,13.830000000,15,0,321038033,130,165225,268074431,ARL
2025-07-17T15:58:43.690244473Z,2025-07-17T15:58:43.690078924Z,160,2,1108,C,A,13.900000000,100,0,320839125,0,165549,268115228,ARL
2025-07-17T15:58:43.690244473Z,2025-07-17T15:58:43.690078924Z,160,2,1108,A,A,13.840000000,100,0,321096769,130,165549,268115228,ARL
2025-07-17T15:58:43.690988921Z,2025-07-17T15:58:43.690823184Z,160,2,1108,C,A,14.980000000,100,0,320839149,0,165737,268115235,ARL
2025-07-17T15:58:43.690988921Z,2025-07-17T15:58:43.690823184Z,160,2,1108,A,A,14.910000000,100,0,321096793,130,165737,268115235,ARL
2025-07-17T15:58:43.693394500Z,2025-07-17T15:58:43.693228946Z,160,2,1108,C,A,17.760000000,100,0,320486937,0,165554,268115265,ARL
2025-07-17T15:58:43.693394500Z,2025-07-17T15:58:43.693228946Z,160,2,1108,A,A,17.580000000,100,0,321096825,130,165554,268115265,ARL
2025-07-17T15:58:43.695055785Z,2025-07-17T15:58:43.694890264Z,160,2,1108,C,A,16.080000000,100,0,320486945,0,165521,268115287,ARL
2025-07-17T15:58:43.695055785Z,2025-07-17T15:58:43.694890264Z,160,2,1108,A,A,15.920000000,100,0,321096889,130,165521,268115287,ARL
2025-07-17T15:58:43.716437124Z,2025-07-17T15:58:43.716271172Z,160,2,1108,C,A,14.960000000,100,0,320487105,0,165952,268115456,ARL
2025-07-17T15:58:43.716437124Z,2025-07-17T15:58:43.716271172Z,160,2,1108,A,A,14.810000000,100,0,321097197,130,165952,268115456,ARL
2025-07-17T15:58:44.903740109Z,2025-07-17T15:58:44.903574654Z,160,2,1108,A,A,13.830000000,100,0,321114473,130,165455,268129040,ARL
2025-07-17T15:58:44.924114268Z,2025-07-17T15:58:44.923948853Z,160,2,1108,C,A,14.180000000,100,0,320839577,130,165415,268129217,ARL
2025-07-17T15:58:44.924165875Z,2025-07-17T15:58:44.924000519Z,160,2,1108,A,A,14.110000000,100,0,321114729,130,165356,268129218,ARL
2025-07-17T15:58:51.241342265Z,2025-07-17T15:58:51.241176997Z,160,2,1108,C,A,13.890000000,15,0,320833897,130,165268,268212338,ARL
2025-07-17T15:58:51.254127339Z,2025-07-17T15:58:51.253961905Z,160,2,1108,A,A,13.800000000,100,0,321225725,130,165434,268212497,ARL
2025-07-17T15:58:51.254871890Z,2025-07-17T15:58:51.254706004Z,160,2,1108,C,A,14.910000000,100,0,321096793,0,165886,268212499,ARL
2025-07-17T15:58:51.254871890Z,2025-07-17T15:58:51.254706004Z,160,2,1108,A,A,14.870000000,100,0,321225745,130,165886,268212499,ARL
2025-07-17T15:58:51.260753179Z,2025-07-17T15:58:51.260587778Z,160,2,1108,C,A,13.830000000,100,0,321114473,130,165401,268212534,ARL
2025-07-17T15:58:53.579628288Z,2025-07-17T15:58:53.579462029Z,160,2,1108,C,A,13.830000000,15,0,321038033,130,166259,268250290,ARL
2025-07-17T15:58:53.580217445Z,2025-07-17T15:58:53.580052014Z,160,2,1108,C,A,13.840000000,100,0,321096769,0,165431,268250346,ARL
2025-07-17T15:58:53.580217445Z,2025-07-17T15:58:53.580052014Z,160,2,1108,A,A,13.810000000,100,0,321272581,130,165431,268250346,ARL
2025-07-17T15:58:54.584124215Z,2025-07-17T15:58:54.583958582Z,160,2,1108,C,A,14.770000000,100,0,320846429,0,165633,268265585,ARL
2025-07-17T15:58:54.584124215Z,2025-07-17T15:58:54.583958582Z,160,2,1108,A,A,14.650000000,100,0,321293737,130,165633,268265585,ARL
2025-07-17T15:58:54.584260712Z,2025-07-17T15:58:54.584094980Z,160,2,1108,C,A,14.760000000,100,0,320845893,0,165732,268265586,ARL
2025-07-17T15:58:54.584260712Z,2025-07-17T15:58:54.584094980Z,160,2,1108,A,A,14.640000000,100,0,321293741,130,165732,268265586,ARL
2025-07-17T15:58:55.305104029Z,2025-07-17T15:58:55.304938318Z,160,2,1108,A,A,13.780000000,100,0,321309865,130,165711,268277940,ARL
