ts_recv,ts_event,rtype,publisher_id,instrument_id,action,side,price,size,channel_id,order_id,flags,ts_in_delta,sequence,symbol
2025-07-17T15:58:55.307508305Z,2025-07-17T15:58:55.307342971Z,160,2,1108,C,A,14.720000000,100,0,312772061,130,165334,268277999,ARL
2025-07-17T15:58:55.307637209Z,2025-07-17T15:58:55.307472032Z,160,2,1108,A,A,14.580000000,100,0,321309941,130,165177,268278004,ARL
2025-07-17T15:58:55.311899965Z,2025-07-17T15:58:55.311734700Z,160,2,1108,C,A,13.800000000,100,0,321225725,130,165265,268278030,ARL
2025-07-17T15:58:58.668252306Z,2025-07-17T15:58:58.668086788Z,160,2,1108,C,A,13.810000000,100,0,321272581,0,165518,268321684,ARL
2025-07-17T15:58:58.668252306Z,2025-07-17T15:58:58.668086788Z,160,2,1108,A,A,13.790000000,100,0,321364281,130,165518,268321684,ARL
2025-07-17T15:59:03.613692913Z,2025-07-17T15:59:03.613527621Z,160,2,1108,A,A,13.720000000,15,0,321500117,130,165292,268437919,ARL
2025-07-17T15:59:03.626346616Z,2025-07-17T15:59:03.626181384Z,160,2,1108,A,A,13.760000000,100,0,321500317,130,165232,268438110,ARL
2025-07-17T15:59:03.627086888Z,2025-07-17T15:59:03.626920954Z,160,2,1108,C,A,14.870000000,100,0,321225745,0,165934,268438112,ARL
2025-07-17T15:59:03.627086888Z,2025-07-17T15:59:03.626920954Z,160,2,1108,A,A,14.830000000,100,0,321500333,130,165934,268438112,ARL
2025-07-17T15:59:03.628945278Z,2025-07-17T15:59:03.628779364Z,160,2,1108,C,A,14.890000000,100,0,312771785,0,165914,268438129,ARL
2025-07-17T15:59:03.628945278Z,2025-07-17T15:59:03.628779364Z,160,2,1108,A,A,14.730000000,100,0,321500349,130,165914,268438129,ARL
2025-07-17T15:59:03.633093258Z,2025-07-17T15:59:03.632928023Z,160,2,1108,C,A,13.780000000,100,0,321309865,130,165235,268438149,ARL
2025-07-17T15:59:03.649282063Z,2025-07-17T15:59:03.649116452Z,160,2,1108,C,A,14.110000000,100,0,321114729,130,165611,268438330,ARL
2025-07-17T15:59:03.649332873Z,2025-07-17T15:59:03.649167617Z,160,2,1108,A,A,14.040000000,100,0,321500957,130,165256,268438331,ARL
2025-07-17T15:59:04.224000805Z,2025-07-17T15:59:04.223835151Z,160,2,1108,C,A,13.790000000,100,0,321364281,0,165654,268447989,ARL
2025-07-17T15:59:04.224000805Z,2025-07-17T15:59:04.223835151Z,160,2,1108,A,A,13.730000000,100,0,321511377,130,165654,268447989,ARL
2025-07-17T15:59:04.224749333Z,2025-07-17T15:59:04.224583946Z,160,2,1108,C,A,14.830000000,100,0,321500333,0,165387,268448014,ARL
2025-07-17T15:59:04.224749333Z,2025-07-17T15:59:04.224583946Z,160,2,1108,A,A,14.790000000,100,0,321511477,130,165387,268448014,ARL
2025-07-17T15:59:04.799998642Z,2025-07-17T15:59:04.799833206Z,160,2,1108,C,A,13.720000000,15,0,321500117,130,165436,268457531,ARL
2025-07-17T16:00:13.989937414Z,2025-07-17T16:00:13.989771852Z,160,2,1108,C,A,14.100000000,2,0,316098525,0,165562,269514876,ARL
2025-07-17T16:00:13.989937414Z,2025-07-17T16:00:13.989771852Z,160,2,1108,A,A,14.010000000,2,0,322898193,130,165562,269514876,ARL
2025-07-17T16:00:28.803015930Z,2025-07-17T16:00:28.802849928Z,160,2,1108,A,A,13.720000000,15,0,323238809,130,166002,269765653,ARL
2025-07-17T16:00:32.549412616Z,2025-07-17T16:00:32.549247168Z,160,2,1108,A,A,13.740000000,100,0,323370569,130,165448,269878282,ARL
2025-07-17T16:00:32.560989093Z,2025-07-17T16:00:32.560823786Z,160,2,1108,C,A,13.760000000,100,0,321500317,130,165307,269878639,ARL
2025-07-17T16:00:35.513164458Z,2025-07-17T16:00:35.512999155Z,160,2,1108,A,A,13.690000000,15,0,323455221,130,165303,269940539,ARL
2025-07-17T16:00:42.614229184Z,2025-07-17T16:00:42.614063415Z,160,2,1108,C,A,13.730000000,100,0,321511377,0,165769,270051089,ARL
2025-07-17T16:00:42.614229184Z,2025-07-17T16:00:42.614063415Z,160,2,1108,A,A,13.700000000,100,0,323599605,130,165769,270051089,ARL
2025-07-17T16:00:42.614254199Z,2025-07-17T16:00:42.614088947Z,160,2,1108,A,A,13.720000000,100,0,323599609,130,165252,270051090,ARL
2025-07-17T16:00:42.614396214Z,2025-07-17T16:00:42.614231125Z,160,2,1108,C,A,13.740000000,100,0,323370569,130,165089,270051092,ARL
2025-07-17T16:00:42.616178962Z,2025-07-17T16:00:42.616013371Z,160,2,1108,C,A,14.810000000,100,0,321097197,0,165591,270051093,ARL
2025-07-17T16:00:42.616178962Z,2025-07-17T16:00:42.616013371Z,160,2,1108,A,A,14.660000000,100,0,323599625,130,165591,270051093,ARL
2025-07-17T16:00:42.616321879Z,2025-07-17T16:00:42.616156310Z,160,2,1108,C,A,15.920000000,100,0,321096889,0,165569,270051094,ARL
2025-07-17T16:00:42.616321879Z,2025-07-17T16:00:42.616156310Z,160,2,1108,A,A,15.760000000,100,0,323599629,130,165569,270051094,ARL
2025-07-17T16:00:42.616352247Z,2025-07-17T16:00:42.616186901Z,160,2,1108,C,A,17.580000000,100,0,321096825,0,165346,270051095,ARL
2025-07-17T16:00:42.616352247Z,2025-07-17T16:00:42.616186901Z,160,2,1108,A,A,17.400000000,100,0,323599633,130,165346,270051095,ARL
2025-07-17T16:00:42.636761176Z,2025-07-17T16:00:42.636595817Z,160,2,1108,C,A,14.040000000,100,0,321500957,130,165359,270051179,ARL
2025-07-17T16:00:42.636814704Z,2025-07-17T16:00:42.636649389Z,160,2,1108,A,A,13.970000000,100,0,323599765,130,165315,270051181,ARL
2025-07-17T16:00:46.803262460Z,2025-07-17T16:00:46.803097192Z,160,2,1108,C,A,13.720000000,15,0,323238809,130,165268,270102799,ARL
2025-07-17T16:00:49.255631264Z,2025-07-17T16:00:49.255465939Z,160,2,1108,A,A,13.660000000,15,0,323720189,130,165325,270140405,ARL
2025-07-17T16:00:49.739644604Z,2025-07-17T16:00:49.739479408Z,160,2,1108,A,A,13.700000000,100,0,323730309,130,165196,270146528,ARL
2025-07-17T16:00:49.745038261Z,2025-07-17T16:00:49.744872763Z,160,2,1108,C,A,13.700000000,100,0,323599605,0,165498,270146577,ARL
2025-07-17T16:00:49.745038261Z,2025-07-17T16:00:49.744872763Z,160,2,1108,A,A,13.670000000,100,0,323730353,130,165498,270146577,ARL
2025-07-17T16:00:49.745778725Z,2025-07-17T16:00:49.745613051Z,160,2,1108,C,A,14.790000000,100,0,321511477,0,165674,270146581,ARL
2025-07-17T16:00:49.745778725Z,2025-07-17T16:00:49.745613051Z,160,2,1108,A,A,14.730000000,100,0,323730369,130,165674,270146581,ARL
2025-07-17T16:00:49.746422142Z,2025-07-17T16:00:49.746256906Z,160,2,1108,C,A,13.720000000,100,0,323599609,130,165236,270146586,ARL
2025-07-17T16:00:49.772631967Z,2025-07-17T16:00:49.772466772Z,160,2,1108,A,A,15.590000000,100,0,323730697,130,165195,270146838,ARL
2025-07-17T16:00:49.772645303Z,2025-07-17T16:00:49.772479921Z,160,2,1108,C,A,15.860000000,100,0,312771645,130,165382,270146839,ARL
2025-07-17T16:00:51.624811889Z,2025-07-17T16:00:51.624646272Z,160,2,1108,C,A,14.650000000,100,0,321293737,0,165617,270181394,ARL
2025-07-17T16:00:51.624811889Z,2025-07-17T16:00:51.624646272Z,160,2,1108,A,A,14.540000000,100,0,323775433,130,165617,270181394,ARL
2025-07-17T16:00:51.625372516Z,2025-07-17T16:00:51.625206675Z,160,2,1108,C,A,14.640000000,100,0,321293741,0,165841,270181399,ARL
2025-07-17T16:00:51.625372516Z,2025-07-17T16:00:51.625206675Z,160,2,1108,A,A,14.530000000,100,0,323775457,130,165841,270181399,ARL
2025-07-17T16:00:53.749335010Z,2025-07-17T16:00:53.749169565Z,160,2,1108,A,A,13.670000000,100,0,323803301,130,165445,270204567,ARL
2025-07-17T16:00:53.755966680Z,2025-07-17T16:00:53.755801462Z,160,2,1108,C,A,13.700000000,100,0,323730309,130,165218,270204616,ARL
2025-07-17T16:01:00.801342739Z,2025-07-17T16:01:00.801177403Z,160,2,1108,C,A,13.690000000,15,0,323455221,130,165336,270319932,ARL
2025-07-17T16:01:10.802877570Z,2025-07-17T16:01:10.802712247Z,160,2,1108,A,A,13.620000000,15,0,324161541,130,165323,270493149,ARL
2025-07-17T16:01:11.418837472Z,2025-07-17T16:01:11.418671671Z,160,2,1108,A,A,13.650000000,100,0,324175569,130,165801,270503944,ARL
2025-07-17T16:01:11.425922184Z,2025-07-17T16:01:11.425757014Z,160,2,1108,C,A,13.670000000,100,0,323803301,130,165170,270504009,ARL
2025-07-17T16:01:11.820753616Z,2025-07-17T16:01:11.820588141Z,160,2,1108,C,A,13.670000000,100,0,323730353,0,165475,270509970,ARL
2025-07-17T16:01:11.820753616Z,2025-07-17T16:01:11.820588141Z,160,2,1108,A,A,13.630000000,100,0,324186213,130,165475,270509970,ARL
2025-07-17T16:01:11.821515043Z,2025-07-17T16:01:11.821349600Z,160,2,1108,C,A,14.730000000,100,0,323730369,0,165443,270509983,ARL
2025-07-17T16:01:11.821515043Z,2025-07-17T16:01:11.821349600Z,160,2,1108,A,A,14.690000000,100,0,324186233,130,165443,270509983,ARL
2025-07-17T16:01:11.826399871Z,2025-07-17T16:01:11.826234488Z,160,2,1108,C,A,13.970000000,100,0,323599765,130,165383,270510142,ARL
2025-07-17T16:01:11.826451447Z,2025-07-17T16:01:11.826286284Z,160,2,1108,A,A,13.900000000,100,0,324186721,130,165163,270510143,ARL
2025-07-17T16:01:11.828630414Z,2025-07-17T16:01:11.828464891Z,160,2,1108,C,A,14.580000000,100,0,321309941,0,165523,270510182,ARL
2025-07-17T16:01:11.828630414Z,2025-07-17T16:01:11.828464891Z,160,2,1108,A,A,14.430000000,100,0,324186781,130,165523,270510182,ARL
2025-07-17T16:01:22.802518536Z,2025-07-17T16:01:22.802353061Z,160,2,1108,C,A,13.660000000,15,0,323720189,130,165475,270674903,ARL
2025-07-17T16:01:32.804004639Z,2025-07-17T16:01:32.803839043Z,160,2,1108,A,A,13.600000000,15,0,324619361,130,165596,270824320,ARL
2025-07-17T16:01:32.804274168Z,2025-07-17T16:01:32.804108576Z,160,2,1108,C,A,13.630000000,100,0,324186213,0,165592,270824323,ARL
2025-07-17T16:01:32.804274168Z,2025-07-17T16:01:32.804108576Z,160,2,1108,A,A,13.610000000,100,0,324619369,130,165592,270824323,ARL
2025-07-17T16:01:32.806299464Z,2025-07-17T16:01:32.806134020Z,160,2,1108,C,A,14.730000000,100,0,321500349,0,165444,270824400,ARL
2025-07-17T16:01:32.806299464Z,2025-07-17T16:01:32.806134020Z,160,2,1108,A,A,14.570000000,100,0,324619409,130,165444,270824400,ARL
2025-07-17T16:01:32.815913520Z,2025-07-17T16:01:32.815748258Z,160,2,1108,A,A,13.630000000,100,0,324619837,130,165262,270824657,ARL
2025-07-17T16:01:32.822608966Z,2025-07-17T16:01:32.822443626Z,160,2,1108,C,A,13.650000000,100,0,324175569,130,165340,270824747,ARL
2025-07-17T16:01:37.242690420Z,2025-07-17T16:01:37.242525208Z,160,2,1108,C,A,13.620000000,15,0,324161541,130,165212,270889017,ARL
2025-07-17T16:01:40.605797765Z,2025-07-17T16:01:40.605632399Z,160,2,1108,A,A,13.610000000,100,0,324782841,130,165366,270946497,ARL
2025-07-17T16:01:40.653738176Z,2025-07-17T16:01:40.653572805Z,160,2,1108,C,A,13.630000000,100,0,324619837,130,165371,270946779,ARL
2025-07-17T16:01:47.565991684Z,2025-07-17T16:01:47.565825466Z,160,2,1108,A,A,13.570000000,15,0,324934601,128,166218,271062350,ARL
2025-07-17T16:01:47.902969773Z,2025-07-17T16:01:47.902804446Z,160,2,1108,C,A,13.610000000,100,0,324619369,0,165327,271068098,ARL
2025-07-17T16:01:47.902969773Z,2025-07-17T16:01:47.902804446Z,160,2,1108,A,A,13.580000000,100,0,324942229,130,165327,271068098,ARL
2025-07-17T16:01:47.903711757Z,2025-07-17T16:01:47.903546622Z,160,2,1108,C,A,14.400000000,100,0,289726421,130,165135,271068105,ARL
2025-07-17T16:01:47.903714323Z,2025-07-17T16:01:47.903548861Z,160,2,1108,C,A,14.690000000,100,0,324186233,0,165462,271068106,ARL
2025-07-17T16:01:47.903714323Z,2025-07-17T16:01:47.903548861Z,160,2,1108,A,A,14.630000000,100,0,324942257,130,165462,271068106,ARL
2025-07-17T16:01:47.904067686Z,2025-07-17T16:01:47.903902473Z,160,2,1108,A,A,14.190000000,100,0,324942273,130,165213,271068115,ARL
2025-07-17T16:01:47.905355779Z,2025-07-17T16:01:47.905189816Z,160,2,1108,C,A,15.230000000,100,0,282776017,0,165963,271068134,ARL
2025-07-17T16:01:47.905355779Z,2025-07-17T16:01:47.905189816Z,160,2,1108,A,A,14.940000000,100,0,324942277,130,165963,271068134,ARL
2025-07-17T16:01:47.909479724Z,2025-07-17T16:01:47.909314303Z,160,2,1108,C,A,17.400000000,100,0,323599633,0,165421,271068173,ARL
2025-07-17T16:01:47.909479724Z,2025-07-17T16:01:47.909314303Z,160,2,1108,A,A,17.250000000,100,0,324942361,130,165421,271068173,ARL
2025-07-17T16:01:50.799100504Z,2025-07-17T16:01:50.798934838Z,160,2,1108,A,A,13.590000000,100,0,325022101,130,165666,271131418,ARL
2025-07-17T16:01:50.805653961Z,2025-07-17T16:01:50.805488726Z,160,2,1108,C,A,13.610000000,100,0,324782841,130,165235,271131583,ARL
2025-07-17T16:01:52.133063761Z,2025-07-17T16:01:52.132898568Z,160,2,1108,C,A,13.600000000,15,0,324619361,130,165193,271153294,ARL
2025-07-17T16:01:53.137501962Z,2025-07-17T16:01:53.137336077Z,160,2,1108,A,A,13.550000000,15,0,325109165,130,165885,271200452,ARL
2025-07-17T16:01:56.264154095Z,2025-07-17T16:01:56.263988198Z,160,2,1108,C,A,13.580000000,100,0,324942229,0,165897,271251019,ARL
2025-07-17T16:01:56.264154095Z,2025-07-17T16:01:56.263988198Z,160,2,1108,A,A,13.560000000,100,0,325176181,130,165897,271251019,ARL
2025-07-17T16:01:56.269623788Z,2025-07-17T16:01:56.269458197Z,160,2,1108,C,A,13.900000000,100,0,324186721,130,165591,271251357,ARL
2025-07-17T16:01:56.269674232Z,2025-07-17T16:01:56.269508928Z,160,2,1108,A,A,13.830000000,100,0,325176373,130,165304,271251358,ARL
2025-07-17T16:01:56.272340730Z,2025-07-17T16:01:56.272175169Z,160,2,1108,C,A,15.760000000,100,0,323599629,0,165561,271251490,ARL
2025-07-17T16:01:56.272340730Z,2025-07-17T16:01:56.272175169Z,160,2,1108,A,A,15.600000000,100,0,325176677,130,165561,271251490,ARL
2025-07-17T16:01:56.300889378Z,2025-07-17T16:01:56.300723805Z,160,2,1108,C,A,14.660000000,100,0,323599625,0,165573,271252044,ARL
2025-07-17T16:01:56.300889378Z,2025-07-17T16:01:56.300723805Z,160,2,1108,A,A,14.510000000,100,0,325177757,130,165573,271252044,ARL
2025-07-17T16:01:56.776980244Z,2025-07-17T16:01:56.776814001Z,160,2,1108,T,N,13.410000000,16,0,0,130,166243,271255700,ARL
2025-07-17T16:01:56.777414332Z,2025-07-17T16:01:56.777248616Z,160,2,1108,T,N,13.410000000,16,0,0,130,165716,271255708,ARL
2025-07-17T16:01:56.777906069Z,2025-07-17T16:01:56.777739254Z,160,2,1108,T,N,13.410000000,4,0,0,130,166815,271255712,ARL
2025-07-17T16:02:01.992544607Z,2025-07-17T16:02:01.992379223Z,160,2,1108,C,A,14.010000000,2,0,322898193,0,165384,271343251,ARL
2025-07-17T16:02:01.992544607Z,2025-07-17T16:02:01.992379223Z,160,2,1108,A,A,13.920000000,2,0,325297093,130,165384,271343251,ARL
2025-07-17T16:02:03.207720826Z,2025-07-17T16:02:03.207555626Z,160,2,1108,C,A,13.570000000,15,0,324934601,130,165200,271367066,ARL
2025-07-17T16:02:04.212956339Z,2025-07-17T16:02:04.212791108Z,160,2,1108,A,A,13.530000000,15,0,325382429,130,165231,271415821,ARL
2025-07-17T16:02:04.214348814Z,2025-07-17T16:02:04.214183279Z,160,2,1108,C,A,14.540000000,100,0,323775433,0,165535,271415834,ARL
2025-07-17T16:02:04.214348814Z,2025-07-17T16:02:04.214183279Z,160,2,1108,A,A,14.430000000,100,0,325382437,130,165535,271415834,ARL
2025-07-17T16:02:04.840132668Z,2025-07-17T16:02:04.839967173Z,160,2,1108,C,A,13.560000000,100,0,325176181,0,165495,271432190,ARL
2025-07-17T16:02:04.840132668Z,2025-07-17T16:02:04.839967173Z,160,2,1108,A,A,13.540000000,100,0,325400045,130,165495,271432190,ARL
2025-07-17T16:02:04.840171240Z,2025-07-17T16:02:04.840006082Z,160,2,1108,A,A,14.270000000,700,0,325400053,130,165158,271432192,ARL
2025-07-17T16:02:04.840210880Z,2025-07-17T16:02:04.840045694Z,160,2,1108,C,A,14.680000000,700,0,283592941,130,165186,271432193,ARL
2025-07-17T16:02:04.840877603Z,2025-07-17T16:02:04.840711803Z,160,2,1108,C,A,14.630000000,100,0,324942257,0,165800,271432231,ARL
2025-07-17T16:02:04.840877603Z,2025-07-17T16:02:04.840711803Z,160,2,1108,A,A,14.590000000,100,0,325400105,130,165800,271432231,ARL
2025-07-17T16:02:11.249291142Z,2025-07-17T16:02:11.249125653Z,160,2,1108,C,A,14.530000000,100,0,323775457,0,165489,271526467,ARL
2025-07-17T16:02:11.249291142Z,2025-07-17T16:02:11.249125653Z,160,2,1108,A,A,14.420000000,100,0,325520705,130,165489,271526467,ARL
2025-07-17T16:02:15.062774661Z,2025-07-17T16:02:15.062605521Z,160,2,1108,C,A,13.530000000,15,0,325382429,128,169140,271576282,ARL
2025-07-17T16:02:15.068449048Z,2025-07-17T16:02:15.068283706Z,160,2,1108,C,A,13.550000000,15,0,325109165,130,165342,271577104,ARL
2025-07-17T16:02:20.635028489Z,2025-07-17T16:02:20.634863301Z,160,2,1108,C,A,13.540000000,100,0,325400045,130,165188,271675842,ARL
2025-07-17T16:02:20.635782472Z,2025-07-17T16:02:20.635616654Z,160,2,1108,C,A,14.590000000,100,0,325400105,0,165818,271675858,ARL
2025-07-17T16:02:20.635782472Z,2025-07-17T16:02:20.635616654Z,160,2,1108,A,A,14.640000000,100,0,325714169,130,165818,271675858,ARL
2025-07-17T16:02:20.650466751Z,2025-07-17T16:02:20.650301212Z,160,2,1108,C,A,13.590000000,100,0,325022101,130,165539,271676032,ARL
2025-07-17T16:02:20.650501448Z,2025-07-17T16:02:20.650335946Z,160,2,1108,C,A,14.270000000,700,0,325400053,130,165502,271676033,ARL
2025-07-17T16:02:20.650546483Z,2025-07-17T16:02:20.650381040Z,160,2,1108,A,A,14.530000000,700,0,325714545,130,165443,271676035,ARL
2025-07-17T16:02:20.651186537Z,2025-07-17T16:02:20.651020858Z,160,2,1108,C,A,14.420000000,100,0,325520705,0,165679,271676048,ARL
2025-07-17T16:02:20.651186537Z,2025-07-17T16:02:20.651020858Z,160,2,1108,A,A,14.730000000,100,0,325714577,130,165679,271676048,ARL
2025-07-17T16:02:20.651201182Z,2025-07-17T16:02:20.651035000Z,160,2,1108,C,A,14.190000000,100,0,324942273,130,166182,271676049,ARL
2025-07-17T16:02:20.651459317Z,2025-07-17T16:02:20.651293729Z,160,2,1108,C,A,17.250000000,100,0,324942361,0,165588,271676055,ARL
2025-07-17T16:02:20.651459317Z,2025-07-17T16:02:20.651293729Z,160,2,1108,A,A,17.570000000,100,0,325714589,130,165588,271676055,ARL
2025-07-17T16:02:20.651558948Z,2025-07-17T16:02:20.651393708Z,160,2,1108,A,A,14.450000000,100,0,325714601,130,165240,271676057,ARL
2025-07-17T16:02:20.651787813Z,2025-07-17T16:02:20.651618897Z,160,2,1108,C,A,14.430000000,100,0,325382437,0,168916,271676089,ARL
2025-07-17T16:02:20.651787813Z,2025-07-17T16:02:20.651618897Z,160,2,1108,A,A,14.730000000,100,0,325714613,128,168916,271676089,ARL
2025-07-17T16:02:20.652021618Z,2025-07-17T16:02:20.651854531Z,160,2,1108,C,A,14.570000000,100,0,324619409,0,167087,271676104,ARL
2025-07-17T16:02:20.652021618Z,2025-07-17T16:02:20.651854531Z,160,2,1108,A,A,14.800000000,100,0,325714629,130,167087,271676104,ARL
2025-07-17T16:02:20.652097288Z,2025-07-17T16:02:20.651932129Z,160,2,1108,C,A,14.430000000,100,0,324186781,130,165159,271676110,ARL
2025-07-17T16:02:20.652160470Z,2025-07-17T16:02:20.651994883Z,160,2,1108,C,A,15.600000000,100,0,325176677,0,165587,271676111,ARL
2025-07-17T16:02:20.652160470Z,2025-07-17T16:02:20.651994883Z,160,2,1108,A,A,15.910000000,100,0,325714633,130,165587,271676111,ARL
2025-07-17T16:02:20.652259931Z,2025-07-17T16:02:20.652094426Z,160,2,1108,A,A,14.630000000,100,0,325714653,130,165505,271676118,ARL
2025-07-17T16:02:20.653626391Z,2025-07-17T16:02:20.653460814Z,160,2,1108,A,B,13.270000000,10,0,325714717,130,165577,271676147,ARL
2025-07-17T16:02:20.653627232Z,2025-07-17T16:02:20.653461966Z,160,2,1108,A,A,13.830000000,15,0,325714721,130,165266,271676148,ARL
2025-07-17T16:02:20.653886896Z,2025-07-17T16:02:20.653721185Z,160,2,1108,C,B,13.020000000,100,0,320485385,0,165711,271676153,ARL
2025-07-17T16:02:20.653886896Z,2025-07-17T16:02:20.653721185Z,160,2,1108,A,B,13.260000000,100,0,325714729,130,165711,271676153,ARL
2025-07-17T16:02:20.655277066Z,2025-07-17T16:02:20.655111649Z,160,2,1108,C,B,13.040000000,2,0,293594281,0,165417,271676165,ARL
2025-07-17T16:02:20.655277066Z,2025-07-17T16:02:20.655111649Z,160,2,1108,A,B,12.910000000,2,0,325714741,130,165417,271676165,ARL
2025-07-17T16:02:20.663374576Z,2025-07-17T16:02:20.663209235Z,160,2,1108,C,A,13.830000000,100,0,325176373,130,165341,271676274,ARL
2025-07-17T16:02:20.663406861Z,2025-07-17T16:02:20.663241882Z,160,2,1108,C,A,14.530000000,700,0,325714545,130,164979,271676275,ARL
2025-07-17T16:02:20.663426974Z,2025-07-17T16:02:20.663261632Z,160,2,1108,A,A,14.110000000,100,0,325714905,130,165342,271676276,ARL
2025-07-17T16:02:20.663559466Z,2025-07-17T16:02:20.663394059Z,160,2,1108,A,A,15.940000000,100,0,325714909,130,165407,271676277,ARL
2025-07-17T16:02:20.663572634Z,2025-07-17T16:02:20.663407337Z,160,2,1108,C,A,15.590000000,100,0,323730697,130,165297,271676278,ARL
2025-07-17T16:02:20.664956400Z,2025-07-17T16:02:20.664790768Z,160,2,1108,C,A,17.570000000,100,0,325714589,0,165632,271676310,ARL
2025-07-17T16:02:20.664956400Z,2025-07-17T16:02:20.664790768Z,160,2,1108,A,A,17.760000000,100,0,325714949,130,165632,271676310,ARL
2025-07-17T16:02:20.665129279Z,2025-07-17T16:02:20.664963386Z,160,2,1108,C,A,14.800000000,100,0,325714629,0,165893,271676320,ARL
2025-07-17T16:02:20.665129279Z,2025-07-17T16:02:20.664963386Z,160,2,1108,A,A,14.960000000,100,0,325714953,130,165893,271676320,ARL
2025-07-17T16:02:20.665200392Z,2025-07-17T16:02:20.665034825Z,160,2,1108,C,A,15.910000000,100,0,325714633,0,165567,271676330,ARL
2025-07-17T16:02:20.665200392Z,2025-07-17T16:02:20.665034825Z,160,2,1108,A,A,16.080000000,100,0,325714957,130,165567,271676330,ARL
2025-07-17T16:02:20.665457595Z,2025-07-17T16:02:20.665292049Z,160,2,1108,C,A,14.940000000,100,0,324942277,0,165546,271676355,ARL
2025-07-17T16:02:20.665457595Z,2025-07-17T16:02:20.665292049Z,160,2,1108,A,A,15.380000000,100,0,325714965,130,165546,271676355,ARL
2025-07-17T16:02:20.669701452Z,2025-07-17T16:02:20.669536385Z,160,2,1108,C,A,14.110000000,100,0,325714905,130,165067,271676398,ARL
2025-07-17T16:02:20.669748954Z,2025-07-17T16:02:20.669583810Z,160,2,1108,A,A,14.260000000,100,0,325715045,130,165144,271676399,ARL
2025-07-17T16:02:20.669752979Z,2025-07-17T16:02:20.669587514Z,160,2,1108,C,A,14.510000000,100,0,325177757,0,165465,271676400,ARL
2025-07-17T16:02:20.669752979Z,2025-07-17T16:02:20.669587514Z,160,2,1108,A,A,14.960000000,100,0,325715053,130,165465,271676400,ARL
2025-07-17T16:02:20.685252049Z,2025-07-17T16:02:20.685086585Z,160,2,1108,C,A,14.640000000,100,0,325714169,0,165464,271676621,ARL
2025-07-17T16:02:20.685252049Z,2025-07-17T16:02:20.685086585Z,160,2,1108,A,A,15.060000000,100,0,325715113,130,165464,271676621,ARL
2025-07-17T16:02:20.832112637Z,2025-07-17T16:02:20.831947250Z,160,2,1108,A,A,14.680000000,700,0,325716945,130,165387,271678584,ARL
2025-07-17T16:02:20.936787418Z,2025-07-17T16:02:20.936622241Z,160,2,1108,C,B,13.260000000,100,0,325714729,130,165177,271679553,ARL
2025-07-17T16:02:20.936837611Z,2025-07-17T16:02:20.936672130Z,160,2,1108,A,A,13.910000000,5,0,325718477,130,165481,271679555,ARL
2025-07-17T16:02:20.936914901Z,2025-07-17T16:02:20.936748894Z,160,2,1108,T,N,13.280000000,11,0,0,130,166007,271679557,ARL
2025-07-17T16:02:20.936999211Z,2025-07-17T16:02:20.936833988Z,160,2,1108,A,A,13.840000000,100,0,325718485,130,165223,271679558,ARL
2025-07-17T16:02:20.937307935Z,2025-07-17T16:02:20.937142186Z,160,2,1108,T,N,13.280000000,11,0,0,130,165749,271679562,ARL
2025-07-17T16:02:20.937744264Z,2025-07-17T16:02:20.937578907Z,160,2,1108,C,A,15.060000000,100,0,325715113,0,165357,271679565,ARL
2025-07-17T16:02:20.937744264Z,2025-07-17T16:02:20.937578907Z,160,2,1108,A,A,14.910000000,100,0,325718509,130,165357,271679565,ARL
2025-07-17T16:02:20.937901293Z,2025-07-17T16:02:20.937736247Z,160,2,1108,C,A,13.910000000,5,0,325718477,130,165046,271679567,ARL
2025-07-17T16:02:20.938093286Z,2025-07-17T16:02:20.937927380Z,160,2,1108,C,A,14.960000000,100,0,325715053,0,165906,271679569,ARL
2025-07-17T16:02:20.938093286Z,2025-07-17T16:02:20.937927380Z,160,2,1108,A,A,14.810000000,100,0,325718517,130,165906,271679569,ARL
2025-07-17T16:02:20.938297839Z,2025-07-17T16:02:20.938132716Z,160,2,1108,C,A,16.080000000,100,0,325714957,0,165123,271679571,ARL
2025-07-17T16:02:20.938297839Z,2025-07-17T16:02:20.938132716Z,160,2,1108,A,A,15.920000000,100,0,325718525,130,165123,271679571,ARL
2025-07-17T16:02:20.938616654Z,2025-07-17T16:02:20.938451331Z,160,2,1108,C,A,14.960000000,100,0,325714953,0,165323,271679575,ARL
2025-07-17T16:02:20.938616654Z,2025-07-17T16:02:20.938451331Z,160,2,1108,A,A,14.810000000,100,0,325718549,130,165323,271679575,ARL
2025-07-17T16:02:20.938889819Z,2025-07-17T16:02:20.938724516Z,160,2,1108,C,A,17.760000000,100,0,325714949,0,165303,271679576,ARL
2025-07-17T16:02:20.938889819Z,2025-07-17T16:02:20.938724516Z,160,2,1108,A,A,17.580000000,100,0,325718557,130,165303,271679576,ARL
2025-07-17T16:02:20.939554686Z,2025-07-17T16:02:20.939389367Z,160,2,1108,A,B,13.020000000,100,0,325718561,130,165319,271679578,ARL
2025-07-17T16:02:20.946406202Z,2025-07-17T16:02:20.946240970Z,160,2,1108,C,A,14.260000000,100,0,325715045,130,165232,271679616,ARL
2025-07-17T16:02:20.946456786Z,2025-07-17T16:02:20.946291345Z,160,2,1108,A,A,14.120000000,100,0,325718637,130,165441,271679617,ARL
2025-07-17T16:02:20.957051613Z,2025-07-17T16:02:20.956886401Z,160,2,1108,C,B,13.020000000,100,0,325718561,0,165212,271679685,ARL
2025-07-17T16:02:20.957051613Z,2025-07-17T16:02:20.956886401Z,160,2,1108,A,B,13.260000000,100,0,325718821,130,165212,271679685,ARL
2025-07-17T16:02:20.957089143Z,2025-07-17T16:02:20.956923753Z,160,2,1108,A,B,13.120000000,100,0,325718833,130,165390,271679686,ARL
2025-07-17T16:02:20.957090484Z,2025-07-17T16:02:20.956925447Z,160,2,1108,A,B,13.120000000,100,0,325718837,130,165037,271679687,ARL
2025-07-17T16:02:20.988655870Z,2025-07-17T16:02:20.988490644Z,160,2,1108,A,A,13.980000000,100,0,325719353,130,165226,271679923,ARL
2025-07-17T16:02:20.988656944Z,2025-07-17T16:02:20.988491826Z,160,2,1108,A,A,13.980000000,100,0,325719357,130,165118,271679924,ARL
2025-07-17T16:02:30.805193695Z,2025-07-17T16:02:30.805028316Z,160,2,1108,C,B,13.270000000,10,0,325714717,130,165379,271818376,ARL
2025-07-17T16:02:34.987171397Z,2025-07-17T16:02:34.987005787Z,160,2,1108,C,B,12.910000000,2,0,325714741,0,165610,271871706,ARL
2025-07-17T16:02:34.987171397Z,2025-07-17T16:02:34.987005787Z,160,2,1108,A,B,13.000000000,2,0,325967705,130,165610,271871706,ARL
2025-07-17T16:02:39.809464961Z,2025-07-17T16:02:39.809299504Z,160,2,1108,A,A,13.790000000,15,0,326077141,130,165457,271952021,ARL
2025-07-17T16:02:40.007472020Z,2025-07-17T16:02:40.007306432Z,160,2,1108,C,A,13.840000000,100,0,325718485,0,165588,271957331,ARL
2025-07-17T16:02:40.007472020Z,2025-07-17T16:02:40.007306432Z,160,2,1108,A,A,13.800000000,100,0,326082329,130,165588,271957331,ARL
2025-07-17T16:02:40.008213654Z,2025-07-17T16:02:40.008048023Z,160,2,1108,C,A,14.910000000,100,0,325718509,0,165631,271957349,ARL
2025-07-17T16:02:40.008213654Z,2025-07-17T16:02:40.008048023Z,160,2,1108,A,A,14.870000000,100,0,326082353,130,165631,271957349,ARL
2025-07-17T16:02:40.795014471Z,2025-07-17T16:02:40.794847674Z,160,2,1108,C,A,13.790000000,15,0,326077141,130,166797,271972417,ARL
2025-07-17T16:02:40.806305895Z,2025-07-17T16:02:40.806140621Z,160,2,1108,C,A,13.830000000,15,0,325714721,130,165274,271973288,ARL
2025-07-17T16:02:43.834428162Z,2025-07-17T16:02:43.834262065Z,160,2,1108,T,N,13.280000000,100,0,0,130,166097,272014629,ARL
2025-07-17T16:02:43.841852430Z,2025-07-17T16:02:43.841686908Z,160,2,1108,C,B,13.260000000,100,0,325718821,130,165522,272014658,ARL
2025-07-17T16:02:43.841912053Z,2025-07-17T16:02:43.841746626Z,160,2,1108,A,A,13.900000000,4,0,326158809,130,165427,272014659,ARL
2025-07-17T16:02:43.842295427Z,2025-07-17T16:02:43.842130114Z,160,2,1108,C,A,13.800000000,100,0,326082329,130,165313,272014661,ARL
2025-07-17T16:02:43.843036936Z,2025-07-17T16:02:43.842871428Z,160,2,1108,C,A,14.870000000,100,0,326082353,0,165508,272014673,ARL
2025-07-17T16:02:43.843036936Z,2025-07-17T16:02:43.842871428Z,160,2,1108,A,A,14.920000000,100,0,326158869,130,165508,272014673,ARL
2025-07-17T16:02:43.843106749Z,2025-07-17T16:02:43.842941514Z,160,2,1108,A,B,13.110000000,100,0,326158877,130,165235,272014674,ARL
2025-07-17T16:02:43.843109026Z,2025-07-17T16:02:43.842943173Z,160,2,1108,C,A,14.810000000,100,0,325718549,0,165853,272014675,ARL
2025-07-17T16:02:43.843109026Z,2025-07-17T16:02:43.842943173Z,160,2,1108,A,A,14.960000000,100,0,326158881,130,165853,272014675,ARL
2025-07-17T16:02:43.843204692Z,2025-07-17T16:02:43.843039530Z,160,2,1108,C,A,13.900000000,4,0,326158809,130,165162,272014681,ARL
2025-07-17T16:02:43.843956820Z,2025-07-17T16:02:43.843791297Z,160,2,1108,C,A,17.580000000,100,0,325718557,0,165523,272014689,ARL
2025-07-17T16:02:43.843956820Z,2025-07-17T16:02:43.843791297Z,160,2,1108,A,A,17.760000000,100,0,326158953,130,165523,272014689,ARL
2025-07-17T16:02:43.844653014Z,2025-07-17T16:02:43.844487204Z,160,2,1108,C,A,15.920000000,100,0,325718525,0,165810,272014697,ARL
2025-07-17T16:02:43.844653014Z,2025-07-17T16:02:43.844487204Z,160,2,1108,A,A,16.080000000,100,0,326158989,130,165810,272014697,ARL
2025-07-17T16:02:43.844801951Z,2025-07-17T16:02:43.844636465Z,160,2,1108,C,A,14.810000000,100,0,325718517,0,165486,272014698,ARL
2025-07-17T16:02:43.844801951Z,2025-07-17T16:02:43.844636465Z,160,2,1108,A,A,14.960000000,100,0,326158997,130,165486,272014698,ARL
2025-07-17T16:02:43.847026795Z,2025-07-17T16:02:43.846861336Z,160,2,1108,C,A,13.920000000,2,0,325297093,0,165459,272014713,ARL
2025-07-17T16:02:43.847026795Z,2025-07-17T16:02:43.846861336Z,160,2,1108,A,A,14.030000000,2,0,326159041,130,165459,272014713,ARL
2025-07-17T16:02:43.847832258Z,2025-07-17T16:02:43.847666979Z,160,2,1108,C,A,14.730000000,100,0,325714613,0,165279,272014721,ARL
2025-07-17T16:02:43.847832258Z,2025-07-17T16:02:43.847666979Z,160,2,1108,A,A,14.870000000,100,0,326159049,130,165279,272014721,ARL
2025-07-17T16:02:43.848147198Z,2025-07-17T16:02:43.847981726Z,160,2,1108,C,A,14.730000000,100,0,325714577,0,165472,272014724,ARL
2025-07-17T16:02:43.848147198Z,2025-07-17T16:02:43.847981726Z,160,2,1108,A,A,14.870000000,100,0,326159061,130,165472,272014724,ARL
2025-07-17T16:02:43.860199647Z,2025-07-17T16:02:43.860034354Z,160,2,1108,C,A,14.120000000,100,0,325718637,130,165293,272014788,ARL
2025-07-17T16:02:43.860252446Z,2025-07-17T16:02:43.860087215Z,160,2,1108,A,A,14.260000000,100,0,326159201,130,165231,272014789,ARL
2025-07-17T16:02:43.893176312Z,2025-07-17T16:02:43.893011012Z,160,2,1108,C,A,14.920000000,100,0,326158869,0,165300,272014986,ARL
2025-07-17T16:02:43.893176312Z,2025-07-17T16:02:43.893011012Z,160,2,1108,A,A,15.060000000,100,0,326159425,130,165300,272014986,ARL
2025-07-17T16:02:43.946967137Z,2025-07-17T16:02:43.946801538Z,160,2,1108,C,A,14.630000000,100,0,325714653,0,165599,272015584,ARL
2025-07-17T16:02:43.946967137Z,2025-07-17T16:02:43.946801538Z,160,2,1108,A,A,14.770000000,100,0,326160141,130,165599,272015584,ARL
2025-07-17T16:02:44.664219784Z,2025-07-17T16:02:44.664054457Z,160,2,1108,A,A,13.990000000,100,0,326167529,130,165327,272021808,ARL
2025-07-17T16:03:02.985987598Z,2025-07-17T16:03:02.985818199Z,160,2,1108,C,A,14.870000000,100,0,326159049,0,169399,272331833,ARL
2025-07-17T16:03:02.985987598Z,2025-07-17T16:03:02.985818199Z,160,2,1108,A,A,14.700000000,100,0,326551237,128,169399,272331833,ARL
2025-07-17T16:03:02.987969729Z,2025-07-17T16:03:02.987797728Z,160,2,1108,C,A,14.870000000,100,0,326159061,0,172001,272332718,ARL
2025-07-17T16:03:02.987969729Z,2025-07-17T16:03:02.987797728Z,160,2,1108,A,A,14.700000000,100,0,326551829,128,172001,272332718,ARL
2025-07-17T16:03:10.807446975Z,2025-07-17T16:03:10.807281669Z,160,2,1108,A,A,13.720000000,15,0,326729677,130,165306,272474575,ARL
2025-07-17T16:03:10.807714421Z,2025-07-17T16:03:10.807548848Z,160,2,1108,C,A,13.990000000,100,0,326167529,0,165573,272474576,ARL
2025-07-17T16:03:10.807714421Z,2025-07-17T16:03:10.807548848Z,160,2,1108,A,A,13.730000000,100,0,326729685,130,165573,272474576,ARL
2025-07-17T16:03:10.808457278Z,2025-07-17T16:03:10.808290914Z,160,2,1108,C,A,15.060000000,100,0,326159425,0,166364,272474580,ARL
2025-07-17T16:03:10.808457278Z,2025-07-17T16:03:10.808290914Z,160,2,1108,A,A,14.790000000,100,0,326729705,128,166364,272474580,ARL
2025-07-17T16:03:10.809707274Z,2025-07-17T16:03:10.809541651Z,160,2,1108,C,A,14.960000000,100,0,326158881,0,165623,272474585,ARL
2025-07-17T16:03:10.809707274Z,2025-07-17T16:03:10.809541651Z,160,2,1108,A,A,14.700000000,100,0,326729721,130,165623,272474585,ARL
2025-07-17T16:03:10.809936821Z,2025-07-17T16:03:10.809771527Z,160,2,1108,C,A,14.770000000,100,0,326160141,130,165294,272474594,ARL
2025-07-17T16:03:10.809963577Z,2025-07-17T16:03:10.809798084Z,160,2,1108,C,A,17.760000000,100,0,326158953,0,165493,272474595,ARL
2025-07-17T16:03:10.809963577Z,2025-07-17T16:03:10.809798084Z,160,2,1108,A,A,17.440000000,100,0,326729725,130,165493,272474595,ARL
2025-07-17T16:03:10.810059442Z,2025-07-17T16:03:10.809894317Z,160,2,1108,A,A,14.520000000,100,0,326729729,130,165125,272474597,ARL
2025-07-17T16:03:10.810478524Z,2025-07-17T16:03:10.810312923Z,160,2,1108,C,A,16.080000000,100,0,326158989,0,165601,272474600,ARL
2025-07-17T16:03:10.810478524Z,2025-07-17T16:03:10.810312923Z,160,2,1108,A,A,15.790000000,100,0,326729733,130,165601,272474600,ARL
2025-07-17T16:03:10.814646270Z,2025-07-17T16:03:10.814480532Z,160,2,1108,C,A,14.960000000,100,0,326158997,0,165738,272474635,ARL
2025-07-17T16:03:10.814646270Z,2025-07-17T16:03:10.814480532Z,160,2,1108,A,A,14.700000000,100,0,326729821,130,165738,272474635,ARL
2025-07-17T16:03:10.817866066Z,2025-07-17T16:03:10.817700664Z,160,2,1108,C,A,14.260000000,100,0,326159201,130,165402,272474675,ARL
2025-07-17T16:03:10.817919970Z,2025-07-17T16:03:10.817754737Z,160,2,1108,A,A,14.000000000,100,0,326729929,130,165233,272474676,ARL
2025-07-17T16:03:10.843337845Z,2025-07-17T16:03:10.843172549Z,160,2,1108,A,A,15.660000000,100,0,326730513,130,165296,272474826,ARL
2025-07-17T16:03:10.843350160Z,2025-07-17T16:03:10.843184785Z,160,2,1108,C,A,15.940000000,100,0,325714909,130,165375,272474827,ARL
2025-07-17T16:03:10.843615537Z,2025-07-17T16:03:10.843448998Z,160,2,1108,C,A,13.980000000,100,0,325719357,0,166539,272474828,ARL
2025-07-17T16:03:10.843615537Z,2025-07-17T16:03:10.843449402Z,160,2,1108,C,A,13.980000000,100,0,325719353,130,166135,272474829,ARL
2025-07-17T16:03:10.843628246Z,2025-07-17T16:03:10.843462898Z,160,2,1108,A,A,13.870000000,100,0,326730517,130,165348,272474830,ARL
2025-07-17T16:03:10.843629633Z,2025-07-17T16:03:10.843464369Z,160,2,1108,A,A,13.870000000,100,0,326730521,130,165264,272474831,ARL
2025-07-17T16:03:16.348189077Z,2025-07-17T16:03:16.348023740Z,160,2,1108,A,A,13.690000000,15,0,326835877,130,165337,272557172,ARL
2025-07-17T16:03:16.348468824Z,2025-07-17T16:03:16.348302787Z,160,2,1108,C,A,14.700000000,100,0,326551829,0,166037,272557230,ARL
2025-07-17T16:03:16.348468824Z,2025-07-17T16:03:16.348302787Z,160,2,1108,A,A,14.580000000,100,0,326835885,130,166037,272557230,ARL
2025-07-17T16:03:16.349679949Z,2025-07-17T16:03:16.349513354Z,160,2,1108,C,A,14.700000000,100,0,326551237,0,166595,272557430,ARL
2025-07-17T16:03:16.349679949Z,2025-07-17T16:03:16.349513354Z,160,2,1108,A,A,14.580000000,100,0,326836085,130,166595,272557430,ARL
2025-07-17T16:03:16.352011831Z,2025-07-17T16:03:16.351845457Z,160,2,1108,C,A,13.730000000,100,0,326729685,0,166374,272557789,ARL
2025-07-17T16:03:16.352011831Z,2025-07-17T16:03:16.351845457Z,160,2,1108,A,A,13.700000000,100,0,326836533,130,166374,272557789,ARL
2025-07-17T16:03:16.365985162Z,2025-07-17T16:03:16.365819243Z,160,2,1108,C,A,15.380000000,100,0,325714965,0,165919,272559024,ARL
2025-07-17T16:03:16.365985162Z,2025-07-17T16:03:16.365819243Z,160,2,1108,A,A,15.070000000,100,0,326837501,130,165919,272559024,ARL
2025-07-17T16:03:18.804325078Z,2025-07-17T16:03:18.804159952Z,160,2,1108,C,A,13.690000000,15,0,326835877,130,165126,272609485,ARL
2025-07-17T16:03:18.804367560Z,2025-07-17T16:03:18.804202246Z,160,2,1108,C,A,13.700000000,100,0,326836533,130,165314,272609486,ARL
2025-07-17T16:03:18.805099118Z,2025-07-17T16:03:18.804933488Z,160,2,1108,C,A,14.790000000,100,0,326729705,0,165630,272609510,ARL
2025-07-17T16:03:18.805099118Z,2025-07-17T16:03:18.804933488Z,160,2,1108,A,A,14.950000000,100,0,326892717,130,165630,272609510,ARL
2025-07-17T16:03:18.805291629Z,2025-07-17T16:03:18.805126035Z,160,2,1108,C,A,14.700000000,100,0,326729721,0,165594,272609526,ARL
2025-07-17T16:03:18.805291629Z,2025-07-17T16:03:18.805126035Z,160,2,1108,A,A,14.850000000,100,0,326892721,130,165594,272609526,ARL
2025-07-17T16:03:18.805449089Z,2025-07-17T16:03:18.805283236Z,160,2,1108,C,A,13.720000000,15,0,326729677,130,165853,272609541,ARL
2025-07-17T16:03:18.806535903Z,2025-07-17T16:03:18.806370373Z,160,2,1108,C,A,14.580000000,100,0,326835885,0,165530,272609577,ARL
2025-07-17T16:03:18.806535903Z,2025-07-17T16:03:18.806370373Z,160,2,1108,A,A,14.760000000,100,0,326892817,130,165530,272609577,ARL
2025-07-17T16:03:18.806802589Z,2025-07-17T16:03:18.806637004Z,160,2,1108,C,A,14.580000000,100,0,326836085,0,165585,272609583,ARL
2025-07-17T16:03:18.806802589Z,2025-07-17T16:03:18.806637004Z,160,2,1108,A,A,14.760000000,100,0,326892825,130,165585,272609583,ARL
2025-07-17T16:03:18.809706334Z,2025-07-17T16:03:18.809540733Z,160,2,1108,C,A,14.520000000,100,0,326729729,0,165601,272609656,ARL
2025-07-17T16:03:18.809706334Z,2025-07-17T16:03:18.809540733Z,160,2,1108,A,A,14.660000000,100,0,326892885,130,165601,272609656,ARL
2025-07-17T16:03:18.809848665Z,2025-07-17T16:03:18.809683187Z,160,2,1108,C,A,15.790000000,100,0,326729733,0,165478,272609658,ARL
2025-07-17T16:03:18.809848665Z,2025-07-17T16:03:18.809683187Z,160,2,1108,A,A,15.960000000,100,0,326892889,130,165478,272609658,ARL
2025-07-17T16:03:18.812107206Z,2025-07-17T16:03:18.811941680Z,160,2,1108,C,A,17.440000000,100,0,326729725,0,165526,272609679,ARL
2025-07-17T16:03:18.812107206Z,2025-07-17T16:03:18.811941680Z,160,2,1108,A,A,17.620000000,100,0,326892921,130,165526,272609679,ARL
2025-07-17T16:03:18.818245629Z,2025-07-17T16:03:18.818080239Z,160,2,1108,C,A,14.000000000,100,0,326729929,130,165390,272609768,ARL
2025-07-17T16:03:18.818301143Z,2025-07-17T16:03:18.818135688Z,160,2,1108,A,A,14.150000000,100,0,326893213,130,165455,272609769,ARL
2025-07-17T16:03:18.868420503Z,2025-07-17T16:03:18.868254768Z,160,2,1108,C,A,14.700000000,100,0,326729821,0,165735,272610397,ARL
2025-07-17T16:03:18.868420503Z,2025-07-17T16:03:18.868254768Z,160,2,1108,A,A,14.850000000,100,0,326893961,130,165735,272610397,ARL
2025-07-17T16:03:19.191219507Z,2025-07-17T16:03:19.191054306Z,160,2,1108,A,A,13.880000000,100,0,326899125,130,165201,272614303,ARL
2025-07-17T16:03:27.433957932Z,2025-07-17T16:03:27.433791643Z,160,2,1108,T,N,13.280000000,40,0,0,130,166289,272788756,ARL
2025-07-17T16:03:27.436323951Z,2025-07-17T16:03:27.436158395Z,160,2,1108,A,A,14.250000000,53,0,327112281,130,165556,272788767,ARL
2025-07-17T16:03:27.436880768Z,2025-07-17T16:03:27.436715001Z,160,2,1108,C,B,12.230000000,100,0,291964745,0,165767,272788774,ARL
2025-07-17T16:03:27.436880768Z,2025-07-17T16:03:27.436715001Z,160,2,1108,A,B,12.100000000,100,0,327112289,130,165767,272788774,ARL
2025-07-17T16:03:27.438566971Z,2025-07-17T16:03:27.438400828Z,160,2,1108,C,B,12.340000000,100,0,285586113,0,166143,272788792,ARL
2025-07-17T16:03:27.438566971Z,2025-07-17T16:03:27.438400828Z,160,2,1108,A,B,12.200000000,100,0,327112385,130,166143,272788792,ARL
2025-07-17T16:03:27.438603564Z,2025-07-17T16:03:27.438437969Z,160,2,1108,C,B,12.340000000,100,0,285586189,0,165595,272788793,ARL
2025-07-17T16:03:27.438603564Z,2025-07-17T16:03:27.438437969Z,160,2,1108,A,B,12.200000000,100,0,327112393,130,165595,272788793,ARL
2025-07-17T16:03:27.454010355Z,2025-07-17T16:03:27.453845141Z,160,2,1108,C,B,13.030000000,100,0,285586293,130,165214,272788897,ARL
2025-07-17T16:03:27.454059719Z,2025-07-17T16:03:27.453894425Z,160,2,1108,A,B,12.950000000,100,0,327112565,130,165294,272788898,ARL
2025-07-17T16:03:27.454892321Z,2025-07-17T16:03:27.454726901Z,160,2,1108,C,B,12.950000000,100,0,327112565,130,165420,272788942,ARL
2025-07-17T16:03:27.454939600Z,2025-07-17T16:03:27.454773691Z,160,2,1108,A,B,12.860000000,100,0,327112577,130,165909,272788943,ARL
2025-07-17T16:03:27.517751270Z,2025-07-17T16:03:27.517585374Z,160,2,1108,C,B,12.460000000,100,0,285587281,130,165896,272790695,ARL
2025-07-17T16:03:27.517864675Z,2025-07-17T16:03:27.517699408Z,160,2,1108,A,B,12.330000000,100,0,327114465,130,165267,272790696,ARL
2025-07-17T16:03:27.536343943Z,2025-07-17T16:03:27.536178718Z,160,2,1108,C,A,14.250000000,53,0,327112281,130,165225,272791410,ARL
2025-07-17T16:03:56.548348047Z,2025-07-17T16:03:56.548182793Z,160,2,1108,A,A,13.800000000,15,0,327675057,130,165254,273208310,ARL
2025-07-17T16:03:56.548611716Z,2025-07-17T16:03:56.548446336Z,160,2,1108,C,A,13.880000000,100,0,326899125,0,165380,273208316,ARL
2025-07-17T16:03:56.548611716Z,2025-07-17T16:03:56.548446336Z,160,2,1108,A,A,13.810000000,100,0,327675065,130,165380,273208316,ARL
2025-07-17T16:03:56.549354405Z,2025-07-17T16:03:56.549188993Z,160,2,1108,C,A,14.950000000,100,0,326892717,0,165412,273208325,ARL
2025-07-17T16:03:56.549354405Z,2025-07-17T16:03:56.549188993Z,160,2,1108,A,A,14.880000000,100,0,327675093,130,165412,273208325,ARL
2025-07-17T16:04:06.233858611Z,2025-07-17T16:04:06.233692491Z,160,2,1108,C,A,14.760000000,100,0,326892825,0,166120,273345719,ARL
2025-07-17T16:04:06.233858611Z,2025-07-17T16:04:06.233692491Z,160,2,1108,A,A,14.640000000,100,0,327856297,130,166120,273345719,ARL
2025-07-17T16:04:06.234600198Z,2025-07-17T16:04:06.234433294Z,160,2,1108,C,A,14.760000000,100,0,326892817,0,166904,273345721,ARL
2025-07-17T16:04:06.234600198Z,2025-07-17T16:04:06.234433294Z,160,2,1108,A,A,14.640000000,100,0,327856309,130,166904,273345721,ARL
2025-07-17T16:04:06.510914101Z,2025-07-17T16:04:06.510748731Z,160,2,1108,A,A,13.720000000,15,0,327863853,130,165370,273352664,ARL
2025-07-17T16:04:06.512413102Z,2025-07-17T16:04:06.512244746Z,160,2,1108,C,A,13.810000000,100,0,327675065,0,168356,273352888,ARL
2025-07-17T16:04:06.512413102Z,2025-07-17T16:04:06.512244746Z,160,2,1108,A,A,13.730000000,100,0,327864137,128,168356,273352888,ARL
2025-07-17T16:04:06.513675299Z,2025-07-17T16:04:06.513497276Z,160,2,1108,C,A,14.880000000,100,0,327675093,0,178023,273353923,ARL
2025-07-17T16:04:06.513675299Z,2025-07-17T16:04:06.513497276Z,160,2,1108,A,A,14.790000000,100,0,327864893,128,178023,273353923,ARL
2025-07-17T16:04:06.522853161Z,2025-07-17T16:04:06.522687474Z,160,2,1108,C,A,14.850000000,100,0,326892721,0,165687,273357758,ARL
2025-07-17T16:04:06.522853161Z,2025-07-17T16:04:06.522687474Z,160,2,1108,A,A,14.700000000,100,0,327868421,130,165687,273357758,ARL
2025-07-17T16:04:06.525550815Z,2025-07-17T16:04:06.525385108Z,160,2,1108,C,A,14.150000000,100,0,326893213,130,165707,273358260,ARL
2025-07-17T16:04:06.525608746Z,2025-07-17T16:04:06.525442486Z,160,2,1108,A,A,14.000000000,100,0,327869193,128,166260,273358273,ARL
2025-07-17T16:04:06.528210755Z,2025-07-17T16:04:06.528043934Z,160,2,1108,C,A,14.660000000,100,0,326892885,130,166821,273358598,ARL
2025-07-17T16:04:06.528329048Z,2025-07-17T16:04:06.528161631Z,160,2,1108,A,A,14.520000000,100,0,327869529,128,167417,273358642,ARL
2025-07-17T16:04:06.543480312Z,2025-07-17T16:04:06.543314706Z,160,2,1108,C,A,17.620000000,100,0,326892921,0,165606,273359491,ARL
2025-07-17T16:04:06.543480312Z,2025-07-17T16:04:06.543314706Z,160,2,1108,A,A,17.440000000,100,0,327870217,130,165606,273359491,ARL
2025-07-17T16:04:06.548945239Z,2025-07-17T16:04:06.548778200Z,160,2,1108,C,A,15.960000000,100,0,326892889,0,167039,273359672,ARL
2025-07-17T16:04:06.548945239Z,2025-07-17T16:04:06.548778200Z,160,2,1108,A,A,15.790000000,100,0,327870361,130,167039,273359672,ARL
2025-07-17T16:04:06.648109829Z,2025-07-17T16:04:06.647944313Z,160,2,1108,C,A,14.850000000,100,0,326893961,0,165516,273361957,ARL
2025-07-17T16:04:06.648109829Z,2025-07-17T16:04:06.647944313Z,160,2,1108,A,A,14.700000000,100,0,327873009,130,165516,273361957,ARL
2025-07-17T16:04:06.805500523Z,2025-07-17T16:04:06.805335354Z,160,2,1108,C,A,13.720000000,15,0,327863853,130,165169,273364089,ARL
2025-07-17T16:04:06.806217584Z,2025-07-17T16:04:06.806052396Z,160,2,1108,C,A,13.800000000,15,0,327675057,130,165188,273364090,ARL
2025-07-17T16:04:21.277142662Z,2025-07-17T16:04:21.276976977Z,160,2,1108,A,A,13.770000000,100,0,328239293,130,165685,273687857,ARL
2025-07-17T16:04:27.791055146Z,2025-07-17T16:04:27.790889618Z,160,2,1108,C,A,14.030000000,2,0,326159041,0,165528,273775264,ARL
2025-07-17T16:04:27.791055146Z,2025-07-17T16:04:27.790889618Z,160,2,1108,A,A,13.940000000,2,0,328351217,130,165528,273775264,ARL
2025-07-17T16:04:31.232053154Z,2025-07-17T16:04:31.231887784Z,160,2,1108,A,A,13.680000000,15,0,328437797,130,165370,273846737,ARL
2025-07-17T16:04:31.232606440Z,2025-07-17T16:04:31.232440773Z,160,2,1108,A,A,13.720000000,100,0,328437805,130,165667,273846745,ARL
2025-07-17T16:04:31.246681162Z,2025-07-17T16:04:31.246515467Z,160,2,1108,C,A,13.770000000,100,0,328239293,130,165695,273847000,ARL
2025-07-17T16:04:32.836802111Z,2025-07-17T16:04:32.836635838Z,160,2,1108,C,A,13.730000000,100,0,327864137,0,166273,273882084,ARL
2025-07-17T16:04:32.836802111Z,2025-07-17T16:04:32.836635838Z,160,2,1108,A,A,13.690000000,100,0,328489153,130,166273,273882084,ARL
2025-07-17T16:04:32.837165431Z,2025-07-17T16:04:32.837000154Z,160,2,1108,C,B,13.120000000,100,0,325718833,130,165277,273882201,ARL
2025-07-17T16:04:32.837169083Z,2025-07-17T16:04:32.837002825Z,160,2,1108,C,B,13.120000000,100,0,325718837,128,166258,273882202,ARL
2025-07-17T16:04:32.837179568Z,2025-07-17T16:04:32.837013456Z,160,2,1108,A,B,12.980000000,100,0,328489377,130,166112,273882207,ARL
2025-07-17T16:04:32.837181582Z,2025-07-17T16:04:32.837016087Z,160,2,1108,A,B,12.980000000,100,0,328489385,130,165495,273882208,ARL
2025-07-17T16:04:32.837536434Z,2025-07-17T16:04:32.837369811Z,160,2,1108,C,A,14.790000000,100,0,327864893,0,166623,273882286,ARL
2025-07-17T16:04:32.837536434Z,2025-07-17T16:04:32.837369811Z,160,2,1108,A,A,14.750000000,100,0,328489481,128,166623,273882286,ARL
2025-07-17T16:04:36.810717146Z,2025-07-17T16:04:36.810551890Z,160,2,1108,A,A,13.650000000,15,0,328603377,130,165256,273963456,ARL
2025-07-17T16:04:37.026937493Z,2025-07-17T16:04:37.026771973Z,160,2,1108,A,A,13.690000000,100,0,328606289,130,165520,273965417,ARL
2025-07-17T16:04:37.033554557Z,2025-07-17T16:04:37.033389265Z,160,2,1108,C,A,13.720000000,100,0,328437805,130,165292,273965562,ARL
2025-07-17T16:04:37.542961161Z,2025-07-17T16:04:37.542795711Z,160,2,1108,C,A,13.690000000,100,0,328489153,0,165450,273971021,ARL
2025-07-17T16:04:37.542961161Z,2025-07-17T16:04:37.542795711Z,160,2,1108,A,A,13.660000000,100,0,328614509,130,165450,273971021,ARL
2025-07-17T16:04:37.543230680Z,2025-07-17T16:04:37.543063240Z,160,2,1108,C,A,13.870000000,100,0,326730517,0,167440,273971035,ARL
2025-07-17T16:04:37.543230680Z,2025-07-17T16:04:37.543064690Z,160,2,1108,C,A,13.870000000,100,0,326730521,130,165990,273971037,ARL
2025-07-17T16:04:37.543242390Z,2025-07-17T16:04:37.543077174Z,160,2,1108,A,A,13.800000000,100,0,328614525,130,165216,273971040,ARL
2025-07-17T16:04:37.543244193Z,2025-07-17T16:04:37.543078532Z,160,2,1108,A,A,13.800000000,100,0,328614529,130,165661,273971041,ARL
2025-07-17T16:04:37.549684713Z,2025-07-17T16:04:37.549519006Z,160,2,1108,C,A,14.000000000,100,0,327869193,130,165707,273973481,ARL
2025-07-17T16:04:37.549735824Z,2025-07-17T16:04:37.549570649Z,160,2,1108,A,A,13.930000000,100,0,328616925,130,165175,273973485,ARL
2025-07-17T16:04:44.524526545Z,2025-07-17T16:04:44.524360626Z,160,2,1108,C,A,13.680000000,15,0,328437797,130,165919,274066152,ARL
2025-07-17T16:04:45.528000143Z,2025-07-17T16:04:45.527835033Z,160,2,1108,A,A,13.630000000,15,0,328780565,130,165110,274088918,ARL
2025-07-17T16:04:45.528629613Z,2025-07-17T16:04:45.528464092Z,160,2,1108,C,A,14.640000000,100,0,327856309,0,165521,274088922,ARL
2025-07-17T16:04:45.528629613Z,2025-07-17T16:04:45.528464092Z,160,2,1108,A,A,14.520000000,100,0,328780577,130,165521,274088922,ARL
2025-07-17T16:04:45.530418278Z,2025-07-17T16:04:45.530252804Z,160,2,1108,C,A,14.640000000,100,0,327856297,0,165474,274088937,ARL
2025-07-17T16:04:45.530418278Z,2025-07-17T16:04:45.530252804Z,160,2,1108,A,A,14.520000000,100,0,328780597,130,165474,274088937,ARL
2025-07-17T16:04:45.533067029Z,2025-07-17T16:04:45.532901874Z,160,2,1108,C,A,13.660000000,100,0,328614509,0,165155,274088955,ARL
2025-07-17T16:04:45.533067029Z,2025-07-17T16:04:45.532901874Z,160,2,1108,A,A,13.640000000,100,0,328780669,130,165155,274088955,ARL
2025-07-17T16:04:45.533804768Z,2025-07-17T16:04:45.533639142Z,160,2,1108,C,A,14.750000000,100,0,328489481,0,165626,274088957,ARL
2025-07-17T16:04:45.533804768Z,2025-07-17T16:04:45.533639142Z,160,2,1108,A,A,14.700000000,100,0,328780685,130,165626,274088957,ARL
2025-07-17T16:04:45.533870711Z,2025-07-17T16:04:45.533705428Z,160,2,1108,A,A,13.670000000,100,0,328780689,130,165283,274088959,ARL
2025-07-17T16:04:45.563137443Z,2025-07-17T16:04:45.562972204Z,160,2,1108,C,A,13.690000000,100,0,328606289,130,165239,274089319,ARL
2025-07-17T16:04:56.809749973Z,2025-07-17T16:04:56.809584701Z,160,2,1108,C,A,13.650000000,15,0,328603377,130,165272,274293432,ARL
2025-07-17T16:04:57.827079009Z,2025-07-17T16:04:57.826913717Z,160,2,1108,A,A,13.610000000,15,0,329068341,130,165292,274310244,ARL
2025-07-17T16:04:57.970616610Z,2025-07-17T16:04:57.970451236Z,160,2,1108,C,A,13.640000000,100,0,328780669,0,165374,274316281,ARL
2025-07-17T16:04:57.970616610Z,2025-07-17T16:04:57.970451236Z,160,2,1108,A,A,13.620000000,100,0,329074609,130,165374,274316281,ARL
2025-07-17T16:04:57.971360344Z,2025-07-17T16:04:57.971193734Z,160,2,1108,C,A,14.450000000,100,0,325714601,128,166610,274316507,ARL
2025-07-17T16:04:57.971717511Z,2025-07-17T16:04:57.971552262Z,160,2,1108,A,A,14.230000000,100,0,329074833,130,165249,274316527,ARL
2025-07-17T16:04:57.992131878Z,2025-07-17T16:04:57.991966904Z,160,2,1108,C,A,13.610000000,15,0,329068341,130,164974,274318490,ARL
2025-07-17T16:04:57.993141438Z,2025-07-17T16:04:57.992976406Z,160,2,1108,C,A,13.620000000,100,0,329074609,130,165032,274318579,ARL
2025-07-17T16:04:57.993309561Z,2025-07-17T16:04:57.993143873Z,160,2,1108,C,A,13.630000000,15,0,328780565,130,165688,274318603,ARL
2025-07-17T16:04:58.002259715Z,2025-07-17T16:04:58.002094377Z,160,2,1108,C,A,13.670000000,100,0,328780689,130,165338,274319058,ARL
2025-07-17T16:04:58.002989430Z,2025-07-17T16:04:58.002823841Z,160,2,1108,C,A,14.700000000,100,0,328780685,0,165589,274319069,ARL
2025-07-17T16:04:58.002989430Z,2025-07-17T16:04:58.002823841Z,160,2,1108,A,A,14.870000000,100,0,329078553,130,165589,274319069,ARL
2025-07-17T16:04:58.013904697Z,2025-07-17T16:04:58.013739242Z,160,2,1108,C,A,13.930000000,100,0,328616925,130,165455,274319298,ARL
2025-07-17T16:04:58.013959233Z,2025-07-17T16:04:58.013793974Z,160,2,1108,A,A,14.080000000,100,0,329078953,130,165259,274319304,ARL
2025-07-17T16:04:58.536617917Z,2025-07-17T16:04:58.536452621Z,160,2,1108,A,A,13.810000000,100,0,329088265,130,165296,274326535,ARL
2025-07-17T16:05:46.594131664Z,2025-07-17T16:05:46.593966383Z,160,2,1108,A,A,13.760000000,100,0,330066537,130,165281,275083968,ARL
2025-07-17T16:05:46.594871336Z,2025-07-17T16:05:46.594705962Z,160,2,1108,C,A,14.870000000,100,0,329078553,0,165374,275083970,ARL
2025-07-17T16:05:46.594871336Z,2025-07-17T16:05:46.594705962Z,160,2,1108,A,A,14.830000000,100,0,330066553,130,165374,275083970,ARL
2025-07-17T16:05:46.996003552Z,2025-07-17T16:05:46.995837526Z,160,2,1108,C,A,13.810000000,100,0,329088265,0,166026,275092978,ARL
2025-07-17T16:05:46.996003552Z,2025-07-17T16:05:46.995837526Z,160,2,1108,A,A,13.770000000,100,0,330075425,130,166026,275092978,ARL
2025-07-17T16:05:50.680333151Z,2025-07-17T16:05:50.680167632Z,160,2,1108,A,A,13.680000000,15,0,330143813,130,165519,275152014,ARL
2025-07-17T16:05:50.697170320Z,2025-07-17T16:05:50.697005084Z,160,2,1108,A,A,13.720000000,100,0,330144301,130,165236,275152383,ARL
2025-07-17T16:05:50.697905372Z,2025-07-17T16:05:50.697739933Z,160,2,1108,C,A,14.830000000,100,0,330066553,0,165439,275152385,ARL
2025-07-17T16:05:50.697905372Z,2025-07-17T16:05:50.697739933Z,160,2,1108,A,A,14.780000000,100,0,330144321,130,165439,275152385,ARL
2025-07-17T16:05:50.704531748Z,2025-07-17T16:05:50.704366332Z,160,2,1108,C,A,13.760000000,100,0,330066537,130,165416,275152443,ARL
2025-07-17T16:05:50.708879311Z,2025-07-17T16:05:50.708714027Z,160,2,1108,C,A,14.080000000,100,0,329078953,130,165284,275152465,ARL
2025-07-17T16:05:50.708931189Z,2025-07-17T16:05:50.708766050Z,160,2,1108,A,A,13.990000000,100,0,330144513,130,165139,275152466,ARL
2025-07-17T16:05:50.913476268Z,2025-07-17T16:05:50.913310799Z,160,2,1108,C,A,13.770000000,100,0,330075425,0,165469,275159685,ARL
2025-07-17T16:05:50.913476268Z,2025-07-17T16:05:50.913310799Z,160,2,1108,A,A,13.690000000,100,0,330151389,130,165469,275159685,ARL
2025-07-17T16:05:59.704955970Z,2025-07-17T16:05:59.704790753Z,160,2,1108,A,A,13.640000000,15,0,330357473,130,165217,275325555,ARL
2025-07-17T16:05:59.715090662Z,2025-07-17T16:05:59.714925412Z,160,2,1108,A,A,13.680000000,100,0,330357633,130,165250,275325807,ARL
2025-07-17T16:05:59.722895750Z,2025-07-17T16:05:59.722730507Z,160,2,1108,C,A,13.720000000,100,0,330144301,130,165243,275325854,ARL
2025-07-17T16:05:59.802762087Z,2025-07-17T16:05:59.802596747Z,160,2,1108,C,A,13.690000000,100,0,330151389,0,165340,275327082,ARL
2025-07-17T16:05:59.802762087Z,2025-07-17T16:05:59.802596747Z,160,2,1108,A,A,13.650000000,100,0,330359197,130,165340,275327082,ARL
2025-07-17T16:05:59.803504658Z,2025-07-17T16:05:59.803338996Z,160,2,1108,C,A,14.780000000,100,0,330144321,0,165662,275327093,ARL
2025-07-17T16:05:59.803504658Z,2025-07-17T16:05:59.803338996Z,160,2,1108,A,A,14.710000000,100,0,330359225,130,165662,275327093,ARL
2025-07-17T16:05:59.827787837Z,2025-07-17T16:05:59.827622529Z,160,2,1108,C,A,13.990000000,100,0,330144513,130,165308,275327416,ARL
2025-07-17T16:05:59.827839802Z,2025-07-17T16:05:59.827674437Z,160,2,1108,A,A,13.920000000,100,0,330359625,130,165365,275327417,ARL
2025-07-17T16:06:02.724446337Z,2025-07-17T16:06:02.724280161Z,160,2,1108,C,A,13.680000000,15,0,330143813,128,166176,275430576,ARL
2025-07-17T16:06:03.729377770Z,2025-07-17T16:06:03.729212428Z,160,2,1108,A,A,13.620000000,15,0,330577045,130,165342,275517342,ARL
2025-07-17T16:06:03.738497645Z,2025-07-17T16:06:03.738332427Z,160,2,1108,A,A,13.650000000,100,0,330577773,130,165218,275517997,ARL
2025-07-17T16:06:03.747495669Z,2025-07-17T16:06:03.747330178Z,160,2,1108,C,A,13.680000000,100,0,330357633,130,165491,275518621,ARL
2025-07-17T16:06:03.887274670Z,2025-07-17T16:06:03.887107153Z,160,2,1108,C,A,13.650000000,100,0,330359197,0,167517,275532429,ARL
2025-07-17T16:06:03.887274670Z,2025-07-17T16:06:03.887107153Z,160,2,1108,A,A,13.630000000,100,0,330592465,130,167517,275532429,ARL
2025-07-17T16:06:07.510050758Z,2025-07-17T16:06:07.509885114Z,160,2,1108,C,A,13.640000000,15,0,330357473,130,165644,275647392,ARL
2025-07-17T16:06:09.885143909Z,2025-07-17T16:06:09.884978592Z,160,2,1108,A,A,13.600000000,15,0,330788421,130,165317,275699092,ARL
2025-07-17T16:06:09.967608061Z,2025-07-17T16:06:09.967442600Z,160,2,1108,C,A,13.630000000,100,0,330592465,0,165461,275700261,ARL
2025-07-17T16:06:09.967608061Z,2025-07-17T16:06:09.967442600Z,160,2,1108,A,A,13.610000000,100,0,330789481,130,165461,275700261,ARL
2025-07-17T16:06:09.968352066Z,2025-07-17T16:06:09.968186617Z,160,2,1108,C,A,14.710000000,100,0,330359225,0,165449,275700270,ARL
2025-07-17T16:06:09.968352066Z,2025-07-17T16:06:09.968186617Z,160,2,1108,A,A,14.670000000,100,0,330789501,130,165449,275700270,ARL
2025-07-17T16:06:09.970040686Z,2025-07-17T16:06:09.969875190Z,160,2,1108,C,A,17.440000000,100,0,327870217,0,165496,275700282,ARL
2025-07-17T16:06:09.970040686Z,2025-07-17T16:06:09.969875190Z,160,2,1108,A,A,17.290000000,100,0,330789509,130,165496,275700282,ARL
2025-07-17T16:06:20.470889851Z,2025-07-17T16:06:20.470724464Z,160,2,1108,A,A,13.630000000,100,0,331018065,130,165387,275896138,ARL
2025-07-17T16:06:20.477598578Z,2025-07-17T16:06:20.477432988Z,160,2,1108,C,A,13.650000000,100,0,330577773,130,165590,275896242,ARL
2025-07-17T16:06:20.811164178Z,2025-07-17T16:06:20.810998706Z,160,2,1108,C,A,13.620000000,15,0,330577045,130,165472,275900161,ARL
2025-07-17T16:06:22.151222819Z,2025-07-17T16:06:22.151057292Z,160,2,1108,A,A,13.580000000,15,0,331050981,130,165527,275926927,ARL
2025-07-17T16:06:22.151491832Z,2025-07-17T16:06:22.151326300Z,160,2,1108,C,A,13.610000000,100,0,330789481,0,165532,275926940,ARL
2025-07-17T16:06:22.151491832Z,2025-07-17T16:06:22.151326300Z,160,2,1108,A,A,13.590000000,100,0,331050989,130,165532,275926940,ARL
2025-07-17T16:06:22.151761329Z,2025-07-17T16:06:22.151595415Z,160,2,1108,C,A,13.800000000,100,0,328614525,0,165914,275926966,ARL
2025-07-17T16:06:22.151761329Z,2025-07-17T16:06:22.151595781Z,160,2,1108,C,A,13.800000000,100,0,328614529,130,165548,275926967,ARL
2025-07-17T16:06:22.153148893Z,2025-07-17T16:06:22.152983326Z,160,2,1108,C,A,15.790000000,100,0,327870361,0,165567,275927034,ARL
2025-07-17T16:06:22.153148893Z,2025-07-17T16:06:22.152983326Z,160,2,1108,A,A,15.630000000,100,0,331051145,130,165567,275927034,ARL
2025-07-17T16:06:22.153916169Z,2025-07-17T16:06:22.153749481Z,160,2,1108,C,A,14.700000000,100,0,327868421,0,166688,275927046,ARL
2025-07-17T16:06:22.153916169Z,2025-07-17T16:06:22.153749481Z,160,2,1108,A,A,14.550000000,100,0,331051173,130,166688,275927046,ARL
2025-07-17T16:06:22.156070698Z,2025-07-17T16:06:22.155905240Z,160,2,1108,C,A,14.520000000,100,0,327869529,0,165458,275927117,ARL
2025-07-17T16:06:22.156070698Z,2025-07-17T16:06:22.155905240Z,160,2,1108,A,A,14.380000000,100,0,331051369,130,165458,275927117,ARL
2025-07-17T16:06:22.178044675Z,2025-07-17T16:06:22.177879233Z,160,2,1108,C,A,14.700000000,100,0,327873009,0,165442,275927444,ARL
2025-07-17T16:06:22.178044675Z,2025-07-17T16:06:22.177879233Z,160,2,1108,A,A,14.550000000,100,0,331052197,130,165442,275927444,ARL
2025-07-17T16:06:24.519511128Z,2025-07-17T16:06:24.519345743Z,160,2,1108,A,A,13.600000000,100,0,331104725,130,165385,275968354,ARL
2025-07-17T16:06:24.526359716Z,2025-07-17T16:06:24.526194457Z,160,2,1108,C,A,13.630000000,100,0,331018065,130,165259,275968393,ARL
2025-07-17T16:06:26.610345800Z,2025-07-17T16:06:26.610180184Z,160,2,1108,C,A,13.940000000,2,0,328351217,0,165616,276013080,ARL
2025-07-17T16:06:26.610345800Z,2025-07-17T16:06:26.610180184Z,160,2,1108,A,A,13.850000000,2,0,331155889,130,165616,276013080,ARL
2025-07-17T16:06:30.625877214Z,2025-07-17T16:06:30.625711923Z,160,2,1108,A,A,14.270000000,700,0,331257169,130,165291,276103282,ARL
2025-07-17T16:06:30.625956307Z,2025-07-17T16:06:30.625790910Z,160,2,1108,C,A,14.680000000,700,0,325716945,130,165397,276103283,ARL
2025-07-17T16:06:31.127827805Z,2025-07-17T16:06:31.127662311Z,160,2,1108,A,A,14.480000000,700,0,331272997,130,165494,276118990,ARL
2025-07-17T16:06:31.128581831Z,2025-07-17T16:06:31.128416336Z,160,2,1108,C,A,14.680000000,700,0,289932801,130,165495,276119017,ARL
2025-07-17T16:06:31.990649229Z,2025-07-17T16:06:31.990483799Z,160,2,1108,C,A,13.600000000,15,0,330788421,130,165430,276135226,ARL
2025-07-17T16:06:42.812807096Z,2025-07-17T16:06:42.812641697Z,160,2,1108,A,A,13.560000000,15,0,331488089,130,165399,276276783,ARL
2025-07-17T16:06:43.012965957Z,2025-07-17T16:06:43.012799164Z,160,2,1108,C,A,13.590000000,100,0,331050989,0,166793,276279311,ARL
2025-07-17T16:06:43.012965957Z,2025-07-17T16:06:43.012799164Z,160,2,1108,A,A,13.570000000,100,0,331491049,128,166793,276279311,ARL
2025-07-17T16:06:43.013716205Z,2025-07-17T16:06:43.013550575Z,160,2,1108,C,A,14.670000000,100,0,330789501,0,165630,276279331,ARL
2025-07-17T16:06:43.013716205Z,2025-07-17T16:06:43.013550575Z,160,2,1108,A,A,14.620000000,100,0,331491077,130,165630,276279331,ARL
2025-07-17T16:06:43.024656023Z,2025-07-17T16:06:43.024490355Z,160,2,1108,C,A,13.920000000,100,0,330359625,130,165668,276279620,ARL
2025-07-17T16:06:43.024708304Z,2025-07-17T16:06:43.024543099Z,160,2,1108,A,A,13.840000000,100,0,331491269,130,165205,276279621,ARL
2025-07-17T16:06:49.613941821Z,2025-07-17T16:06:49.613776144Z,160,2,1108,C,A,13.580000000,15,0,331050981,130,165677,276382302,ARL
2025-07-17T16:06:50.618669843Z,2025-07-17T16:06:50.618504506Z,160,2,1108,A,A,13.540000000,15,0,331666961,130,165337,276408477,ARL
2025-07-17T16:06:50.626438205Z,2025-07-17T16:06:50.626272828Z,160,2,1108,A,A,13.580000000,100,0,331667121,130,165377,276408566,ARL
2025-07-17T16:06:50.633113557Z,2025-07-17T16:06:50.632947998Z,160,2,1108,C,A,13.600000000,100,0,331104725,130,165559,276408644,ARL
2025-07-17T16:06:51.754576322Z,2025-07-17T16:06:51.754410704Z,160,2,1108,C,A,13.570000000,100,0,331491049,0,165618,276428315,ARL
2025-07-17T16:06:51.754576322Z,2025-07-17T16:06:51.754410704Z,160,2,1108,A,A,13.550000000,100,0,331694265,130,165618,276428315,ARL
2025-07-17T16:06:51.757403109Z,2025-07-17T16:06:51.757237300Z,160,2,1108,C,B,13.000000000,2,0,325967705,0,165809,276428333,ARL
2025-07-17T16:06:51.757403109Z,2025-07-17T16:06:51.757237300Z,160,2,1108,A,B,12.900000000,2,0,331694297,130,165809,276428333,ARL
2025-07-17T16:06:55.056300861Z,2025-07-17T16:06:55.056135380Z,160,2,1108,C,A,13.540000000,15,0,331666961,130,165481,276516227,ARL
2025-07-17T16:06:55.056466231Z,2025-07-17T16:06:55.056301001Z,160,2,1108,C,A,13.560000000,15,0,331488089,130,165230,276516239,ARL
2025-07-17T16:07:00.010995558Z,2025-07-17T16:07:00.010829521Z,160,2,1108,C,A,13.550000000,100,0,331694265,130,166037,276611719,ARL
2025-07-17T16:07:00.023849180Z,2025-07-17T16:07:00.023683961Z,160,2,1108,C,A,13.580000000,100,0,331667121,130,165219,276613073,ARL
2025-07-17T16:07:00.023917543Z,2025-07-17T16:07:00.023752163Z,160,2,1108,C,A,14.270000000,700,0,331257169,130,165380,276613077,ARL
2025-07-17T16:07:00.023980805Z,2025-07-17T16:07:00.023815326Z,160,2,1108,A,A,14.510000000,700,0,331926981,130,165479,276613078,ARL
2025-07-17T16:07:00.024590283Z,2025-07-17T16:07:00.024424816Z,160,2,1108,C,A,14.620000000,100,0,331491077,0,165467,276613110,ARL
2025-07-17T16:07:00.024590283Z,2025-07-17T16:07:00.024424816Z,160,2,1108,A,A,14.880000000,100,0,331927017,130,165467,276613110,ARL
2025-07-17T16:07:00.025231164Z,2025-07-17T16:07:00.025064913Z,160,2,1108,C,A,14.230000000,100,0,329074833,130,166251,276613157,ARL
2025-07-17T16:07:00.025587549Z,2025-07-17T16:07:00.025422082Z,160,2,1108,A,A,14.460000000,100,0,331927161,130,165467,276613175,ARL
2025-07-17T16:07:00.025793260Z,2025-07-17T16:07:00.025628157Z,160,2,1108,A,A,13.590000000,100,0,331927177,130,165103,276613194,ARL
2025-07-17T16:07:00.026998695Z,2025-07-17T16:07:00.026833761Z,160,2,1108,C,A,13.590000000,100,0,331927177,130,164934,276613224,ARL
2025-07-17T16:07:00.032762182Z,2025-07-17T16:07:00.032596898Z,160,2,1108,C,A,14.380000000,100,0,331051369,130,165284,276613329,ARL
2025-07-17T16:07:00.032876947Z,2025-07-17T16:07:00.032711777Z,160,2,1108,A,A,14.630000000,100,0,331927477,130,165170,276613336,ARL
2025-07-17T16:07:00.045525047Z,2025-07-17T16:07:00.045359807Z,160,2,1108,C,A,13.840000000,100,0,331491269,130,165240,276613663,ARL
2025-07-17T16:07:00.045559272Z,2025-07-17T16:07:00.045394317Z,160,2,1108,C,A,14.510000000,700,0,331926981,130,164955,276613664,ARL
2025-07-17T16:07:00.045574786Z,2025-07-17T16:07:00.045409635Z,160,2,1108,A,A,14.090000000,100,0,331927857,130,165151,276613665,ARL
2025-07-17T16:07:00.046838602Z,2025-07-17T16:07:00.046672908Z,160,2,1108,C,A,14.090000000,100,0,331927857,130,165694,276613680,ARL
2025-07-17T16:07:00.046887005Z,2025-07-17T16:07:00.046721624Z,160,2,1108,A,A,13.860000000,100,0,331927877,130,165381,276613681,ARL
2025-07-17T16:07:00.047708936Z,2025-07-17T16:07:00.047544064Z,160,2,1108,C,A,13.860000000,100,0,331927877,130,164872,276613692,ARL
2025-07-17T16:07:00.047755498Z,2025-07-17T16:07:00.047590313Z,160,2,1108,A,A,14.120000000,100,0,331927921,130,165185,276613693,ARL
2025-07-17T16:07:00.053448670Z,2025-07-17T16:07:00.053283700Z,160,2,1108,C,A,14.120000000,100,0,331927921,130,164970,276613731,ARL
2025-07-17T16:07:00.053495095Z,2025-07-17T16:07:00.053329959Z,160,2,1108,A,A,14.260000000,100,0,331928009,130,165136,276613732,ARL
2025-07-17T16:07:00.057809857Z,2025-07-17T16:07:00.057644427Z,160,2,1108,C,A,14.550000000,100,0,331052197,0,165430,276613800,ARL
2025-07-17T16:07:00.057809857Z,2025-07-17T16:07:00.057644427Z,160,2,1108,A,A,14.960000000,100,0,331928129,130,165430,276613800,ARL
2025-07-17T16:07:00.070490835Z,2025-07-17T16:07:00.070325784Z,160,2,1108,C,A,14.260000000,100,0,331928009,130,165051,276614087,ARL
2025-07-17T16:07:00.070539222Z,2025-07-17T16:07:00.070373975Z,160,2,1108,A,A,14.140000000,100,0,331929033,130,165247,276614089,ARL
2025-07-17T16:07:00.071359350Z,2025-07-17T16:07:00.071194493Z,160,2,1108,C,A,14.140000000,100,0,331929033,130,164857,276614094,ARL
2025-07-17T16:07:00.071405105Z,2025-07-17T16:07:00.071239867Z,160,2,1108,A,A,14.260000000,100,0,331929041,130,165238,276614095,ARL
2025-07-17T16:07:00.074580946Z,2025-07-17T16:07:00.074415631Z,160,2,1108,C,A,14.880000000,100,0,331927017,0,165315,276614119,ARL
2025-07-17T16:07:00.074580946Z,2025-07-17T16:07:00.074415631Z,160,2,1108,A,A,15.060000000,100,0,331929065,130,165315,276614119,ARL
2025-07-17T16:07:00.085131263Z,2025-07-17T16:07:00.084965637Z,160,2,1108,C,A,15.070000000,100,0,326837501,0,165626,276614295,ARL
2025-07-17T16:07:00.085131263Z,2025-07-17T16:07:00.084965637Z,160,2,1108,A,A,15.380000000,100,0,331929445,130,165626,276614295,ARL
2025-07-17T16:07:00.090359757Z,2025-07-17T16:07:00.090194106Z,160,2,1108,C,A,14.550000000,100,0,331051173,0,165651,276614378,ARL
2025-07-17T16:07:00.090359757Z,2025-07-17T16:07:00.090194106Z,160,2,1108,A,A,14.960000000,100,0,331929633,130,165651,276614378,ARL
2025-07-17T16:07:00.102092147Z,2025-07-17T16:07:00.101927028Z,160,2,1108,A,A,14.680000000,700,0,331929977,130,165119,276614699,ARL
2025-07-17T16:07:00.287582448Z,2025-07-17T16:07:00.287416733Z,160,2,1108,C,A,17.290000000,100,0,330789509,0,165715,276617288,ARL
2025-07-17T16:07:00.287582448Z,2025-07-17T16:07:00.287416733Z,160,2,1108,A,A,17.760000000,100,0,331934277,130,165715,276617288,ARL
2025-07-17T16:07:00.293620434Z,2025-07-17T16:07:00.293454856Z,160,2,1108,C,A,15.630000000,100,0,331051145,0,165578,276617317,ARL
2025-07-17T16:07:00.293620434Z,2025-07-17T16:07:00.293454856Z,160,2,1108,A,A,16.080000000,100,0,331934377,130,165578,276617317,ARL
2025-07-17T16:07:00.494657495Z,2025-07-17T16:07:00.494492099Z,160,2,1108,A,A,13.860000000,100,0,331942821,130,165396,276622423,ARL
2025-07-17T16:07:00.495318245Z,2025-07-17T16:07:00.495152219Z,160,2,1108,C,B,12.360000000,100,0,288723817,0,166026,276622452,ARL
2025-07-17T16:07:00.495318245Z,2025-07-17T16:07:00.495152219Z,160,2,1108,A,B,12.490000000,100,0,331942901,130,166026,276622452,ARL
2025-07-17T16:07:00.495398644Z,2025-07-17T16:07:00.495233001Z,160,2,1108,C,A,15.060000000,100,0,331929065,0,165643,276622455,ARL
2025-07-17T16:07:00.495398644Z,2025-07-17T16:07:00.495233001Z,160,2,1108,A,A,14.930000000,100,0,331942913,130,165643,276622455,ARL
2025-07-17T16:07:00.495989598Z,2025-07-17T16:07:00.495823953Z,160,2,1108,C,B,12.360000000,100,0,288723813,0,165645,276622469,ARL
2025-07-17T16:07:00.495989598Z,2025-07-17T16:07:00.495823953Z,160,2,1108,A,B,12.490000000,100,0,331942945,130,165645,276622469,ARL
2025-07-17T16:07:00.496483460Z,2025-07-17T16:07:00.496317847Z,160,2,1108,C,A,17.760000000,100,0,331934277,0,165613,276622478,ARL
2025-07-17T16:07:00.496483460Z,2025-07-17T16:07:00.496317847Z,160,2,1108,A,A,17.610000000,100,0,331942981,130,165613,276622478,ARL
2025-07-17T16:07:00.499666149Z,2025-07-17T16:07:00.499501052Z,160,2,1108,C,A,14.260000000,100,0,331929041,130,165097,276622569,ARL
2025-07-17T16:07:00.499714918Z,2025-07-17T16:07:00.499549738Z,160,2,1108,A,A,14.140000000,100,0,331943133,130,165180,276622571,ARL
2025-07-17T16:07:22.814941809Z,2025-07-17T16:07:22.814776694Z,160,2,1108,A,A,13.690000000,15,0,332385317,130,165115,276946179,ARL
2025-07-17T16:07:22.815057507Z,2025-07-17T16:07:22.814891345Z,160,2,1108,C,A,13.860000000,100,0,331942821,0,166162,276946183,ARL
2025-07-17T16:07:22.815057507Z,2025-07-17T16:07:22.814891345Z,160,2,1108,A,A,13.700000000,100,0,332385325,130,166162,276946183,ARL
2025-07-17T16:07:22.815790890Z,2025-07-17T16:07:22.815625345Z,160,2,1108,C,A,14.930000000,100,0,331942913,0,165545,276946264,ARL
2025-07-17T16:07:22.815790890Z,2025-07-17T16:07:22.815625345Z,160,2,1108,A,A,14.760000000,100,0,332385501,130,165545,276946264,ARL
2025-07-17T16:07:22.817507809Z,2025-07-17T16:07:22.817341789Z,160,2,1108,C,A,14.960000000,100,0,331929633,0,166020,276946309,ARL
2025-07-17T16:07:22.817507809Z,2025-07-17T16:07:22.817341789Z,160,2,1108,A,A,14.660000000,100,0,332385565,130,166020,276946309,ARL
2025-07-17T16:07:22.817624699Z,2025-07-17T16:07:22.817459170Z,160,2,1108,C,A,15.380000000,100,0,331929445,0,165529,276946313,ARL
2025-07-17T16:07:22.817624699Z,2025-07-17T16:07:22.817459170Z,160,2,1108,A,A,15.070000000,100,0,332385569,130,165529,276946313,ARL
2025-07-17T16:07:22.818565766Z,2025-07-17T16:07:22.818400003Z,160,2,1108,C,A,16.080000000,100,0,331934377,0,165763,276946327,ARL
2025-07-17T16:07:22.818565766Z,2025-07-17T16:07:22.818400003Z,160,2,1108,A,A,15.760000000,100,0,332385585,130,165763,276946327,ARL
2025-07-17T16:07:22.819710983Z,2025-07-17T16:07:22.819545360Z,160,2,1108,C,A,17.610000000,100,0,331942981,0,165623,276946336,ARL
2025-07-17T16:07:22.819710983Z,2025-07-17T16:07:22.819545360Z,160,2,1108,A,A,17.400000000,100,0,332385593,130,165623,276946336,ARL
2025-07-17T16:07:22.819772408Z,2025-07-17T16:07:22.819606945Z,160,2,1108,C,A,14.630000000,100,0,331927477,0,165463,276946337,ARL
2025-07-17T16:07:22.819772408Z,2025-07-17T16:07:22.819606945Z,160,2,1108,A,A,14.490000000,100,0,332385597,130,165463,276946337,ARL
2025-07-17T16:07:22.821165451Z,2025-07-17T16:07:22.821000003Z,160,2,1108,C,A,14.140000000,100,0,331943133,130,165448,276946343,ARL
2025-07-17T16:07:22.821218207Z,2025-07-17T16:07:22.821052982Z,160,2,1108,A,A,13.970000000,100,0,332385613,130,165225,276946344,ARL
2025-07-17T16:07:22.832119220Z,2025-07-17T16:07:22.831949887Z,160,2,1108,C,A,14.960000000,100,0,331928129,0,169333,276946801,ARL
2025-07-17T16:07:22.832119220Z,2025-07-17T16:07:22.831949887Z,160,2,1108,A,A,14.660000000,100,0,332386121,128,169333,276946801,ARL
2025-07-17T16:07:28.273823608Z,2025-07-17T16:07:28.273658191Z,160,2,1108,C,A,13.690000000,15,0,332385317,130,165417,277012951,ARL
2025-07-17T16:07:28.700981149Z,2025-07-17T16:07:28.700815737Z,160,2,1108,C,A,13.700000000,100,0,332385325,130,165412,277019711,ARL
2025-07-17T16:07:28.701396669Z,2025-07-17T16:07:28.701230409Z,160,2,1108,C,B,12.900000000,2,0,331694297,0,166260,277019718,ARL
2025-07-17T16:07:28.701396669Z,2025-07-17T16:07:28.701230409Z,160,2,1108,A,B,13.010000000,2,0,332494213,130,166260,277019718,ARL
2025-07-17T16:07:28.701713232Z,2025-07-17T16:07:28.701547540Z,160,2,1108,C,A,14.760000000,100,0,332385501,0,165692,277019720,ARL
2025-07-17T16:07:28.701713232Z,2025-07-17T16:07:28.701547540Z,160,2,1108,A,A,14.820000000,100,0,332494229,130,165692,277019720,ARL
2025-07-17T16:07:28.702166297Z,2025-07-17T16:07:28.702000772Z,160,2,1108,C,A,15.760000000,100,0,332385585,0,165525,277019722,ARL
2025-07-17T16:07:28.702166297Z,2025-07-17T16:07:28.702000772Z,160,2,1108,A,A,16.010000000,100,0,332494245,130,165525,277019722,ARL
2025-07-17T16:07:28.702642020Z,2025-07-17T16:07:28.702476699Z,160,2,1108,C,A,14.660000000,100,0,332386121,0,165321,277019729,ARL
2025-07-17T16:07:28.702642020Z,2025-07-17T16:07:28.702476699Z,160,2,1108,A,A,14.950000000,100,0,332494281,130,165321,277019729,ARL
2025-07-17T16:07:28.703523092Z,2025-07-17T16:07:28.703357714Z,160,2,1108,C,A,14.660000000,100,0,332385565,0,165378,277019733,ARL
2025-07-17T16:07:28.703523092Z,2025-07-17T16:07:28.703357714Z,160,2,1108,A,A,14.950000000,100,0,332494285,130,165378,277019733,ARL
2025-07-17T16:07:28.703920336Z,2025-07-17T16:07:28.703754662Z,160,2,1108,C,A,15.070000000,100,0,332385569,0,165674,277019735,ARL
2025-07-17T16:07:28.703920336Z,2025-07-17T16:07:28.703754662Z,160,2,1108,A,A,15.370000000,100,0,332494289,130,165674,277019735,ARL
2025-07-17T16:07:28.704198103Z,2025-07-17T16:07:28.704032725Z,160,2,1108,C,A,17.400000000,100,0,332385593,0,165378,277019738,ARL
2025-07-17T16:07:28.704198103Z,2025-07-17T16:07:28.704032725Z,160,2,1108,A,A,17.750000000,100,0,332494297,130,165378,277019738,ARL
2025-07-17T16:07:28.724201840Z,2025-07-17T16:07:28.724036175Z,160,2,1108,C,A,13.970000000,100,0,332385613,130,165665,277019926,ARL
2025-07-17T16:07:28.724250835Z,2025-07-17T16:07:28.724085453Z,160,2,1108,A,A,14.200000000,100,0,332494893,130,165382,277019929,ARL
2025-07-17T16:07:28.751828120Z,2025-07-17T16:07:28.751662660Z,160,2,1108,C,A,14.820000000,100,0,332494229,0,165460,277020284,ARL
2025-07-17T16:07:28.751828120Z,2025-07-17T16:07:28.751662660Z,160,2,1108,A,A,15.050000000,100,0,332495781,130,165460,277020284,ARL
2025-07-17T16:07:28.831160987Z,2025-07-17T16:07:28.830995364Z,160,2,1108,C,A,14.490000000,100,0,332385597,130,165623,277021007,ARL
2025-07-17T16:07:28.831291377Z,2025-07-17T16:07:28.831125667Z,160,2,1108,A,A,14.770000000,100,0,332497653,130,165710,277021012,ARL
2025-07-17T16:07:29.214667270Z,2025-07-17T16:07:29.214500816Z,160,2,1108,A,A,13.860000000,100,0,332508813,128,166454,277029015,ARL
2025-07-17T16:07:29.215458844Z,2025-07-17T16:07:29.215292291Z,160,2,1108,C,A,15.050000000,100,0,332495781,0,166553,277029273,ARL
2025-07-17T16:07:29.215458844Z,2025-07-17T16:07:29.215292291Z,160,2,1108,A,A,14.930000000,100,0,332508997,128,166553,277029273,ARL
2025-07-17T16:08:20.816252850Z,2025-07-17T16:08:20.816087447Z,160,2,1108,A,A,13.680000000,15,0,333436357,130,165403,277732167,ARL
2025-07-17T16:08:20.816366205Z,2025-07-17T16:08:20.816200644Z,160,2,1108,C,A,13.860000000,100,0,332508813,0,165561,277732170,ARL
2025-07-17T16:08:20.816366205Z,2025-07-17T16:08:20.816200644Z,160,2,1108,A,A,13.690000000,100,0,333436361,130,165561,277732170,ARL
2025-07-17T16:08:20.817097587Z,2025-07-17T16:08:20.816932150Z,160,2,1108,C,A,14.930000000,100,0,332508997,0,165437,277732194,ARL
2025-07-17T16:08:20.817097587Z,2025-07-17T16:08:20.816932150Z,160,2,1108,A,A,14.750000000,100,0,333436397,130,165437,277732194,ARL
2025-07-17T16:08:20.818725102Z,2025-07-17T16:08:20.818559377Z,160,2,1108,C,A,15.370000000,100,0,332494289,0,165725,277732213,ARL
2025-07-17T16:08:20.818725102Z,2025-07-17T16:08:20.818559377Z,160,2,1108,A,A,15.060000000,100,0,333436421,130,165725,277732213,ARL
2025-07-17T16:08:20.819130820Z,2025-07-17T16:08:20.818965359Z,160,2,1108,C,A,14.950000000,100,0,332494285,0,165461,277732216,ARL
2025-07-17T16:08:20.819130820Z,2025-07-17T16:08:20.818965359Z,160,2,1108,A,A,14.650000000,100,0,333436425,130,165461,277732216,ARL
2025-07-17T16:08:20.819767091Z,2025-07-17T16:08:20.819601669Z,160,2,1108,C,A,17.750000000,100,0,332494297,0,165422,277732221,ARL
2025-07-17T16:08:20.819767091Z,2025-07-17T16:08:20.819601669Z,160,2,1108,A,A,17.390000000,100,0,333436441,130,165422,277732221,ARL
2025-07-17T16:08:20.820666169Z,2025-07-17T16:08:20.820500575Z,160,2,1108,C,A,16.010000000,100,0,332494245,0,165594,277732228,ARL
2025-07-17T16:08:20.820666169Z,2025-07-17T16:08:20.820500575Z,160,2,1108,A,A,15.750000000,100,0,333436449,130,165594,277732228,ARL
2025-07-17T16:08:20.822089544Z,2025-07-17T16:08:20.821924168Z,160,2,1108,C,A,14.200000000,100,0,332494893,130,165376,277732239,ARL
2025-07-17T16:08:20.822139541Z,2025-07-17T16:08:20.821974299Z,160,2,1108,A,A,13.960000000,100,0,333436473,130,165242,277732240,ARL
2025-07-17T16:08:20.830110499Z,2025-07-17T16:08:20.829945074Z,160,2,1108,C,A,14.950000000,100,0,332494281,0,165425,277732299,ARL
2025-07-17T16:08:20.830110499Z,2025-07-17T16:08:20.829945074Z,160,2,1108,A,A,14.650000000,100,0,333436589,130,165425,277732299,ARL
2025-07-17T16:08:20.966229266Z,2025-07-17T16:08:20.966063681Z,160,2,1108,C,A,14.770000000,100,0,332497653,0,165585,277733304,ARL
2025-07-17T16:08:20.966229266Z,2025-07-17T16:08:20.966063681Z,160,2,1108,A,A,14.480000000,100,0,333438545,130,165585,277733304,ARL
2025-07-17T16:08:22.998168186Z,2025-07-17T16:08:22.998002821Z,160,2,1108,C,A,13.680000000,15,0,333436357,130,165365,277766492,ARL
2025-07-17T16:08:27.482509684Z,2025-07-17T16:08:27.482344236Z,160,2,1108,C,A,13.690000000,100,0,333436361,130,165448,277841171,ARL
2025-07-17T16:08:27.483241007Z,2025-07-17T16:08:27.483075481Z,160,2,1108,C,A,14.750000000,100,0,333436397,0,165526,277841175,ARL
2025-07-17T16:08:27.483241007Z,2025-07-17T16:08:27.483075481Z,160,2,1108,A,A,14.990000000,100,0,333581389,130,165526,277841175,ARL
2025-07-17T16:08:27.483585892Z,2025-07-17T16:08:27.483420069Z,160,2,1108,C,A,14.520000000,100,0,328780577,0,165823,277841178,ARL
2025-07-17T16:08:27.483585892Z,2025-07-17T16:08:27.483420069Z,160,2,1108,A,A,14.740000000,100,0,333581393,130,165823,277841178,ARL
2025-07-17T16:08:27.484079224Z,2025-07-17T16:08:27.483913735Z,160,2,1108,C,A,14.650000000,100,0,333436589,0,165489,277841218,ARL
2025-07-17T16:08:27.484079224Z,2025-07-17T16:08:27.483913735Z,160,2,1108,A,A,14.940000000,100,0,333581409,130,165489,277841218,ARL
2025-07-17T16:08:27.484859188Z,2025-07-17T16:08:27.484693568Z,160,2,1108,C,A,17.390000000,100,0,333436441,0,165620,277841226,ARL
2025-07-17T16:08:27.484859188Z,2025-07-17T16:08:27.484693568Z,160,2,1108,A,A,17.730000000,100,0,333581425,130,165620,277841226,ARL
2025-07-17T16:08:27.484965957Z,2025-07-17T16:08:27.484800296Z,160,2,1108,C,A,14.650000000,100,0,333436425,0,165661,277841228,ARL
2025-07-17T16:08:27.484965957Z,2025-07-17T16:08:27.484800296Z,160,2,1108,A,A,14.940000000,100,0,333581429,130,165661,277841228,ARL
2025-07-17T16:08:27.484978859Z,2025-07-17T16:08:27.484813280Z,160,2,1108,C,A,15.750000000,100,0,333436449,0,165579,277841229,ARL
2025-07-17T16:08:27.484978859Z,2025-07-17T16:08:27.484813280Z,160,2,1108,A,A,16.060000000,100,0,333581433,130,165579,277841229,ARL
2025-07-17T16:08:27.485352204Z,2025-07-17T16:08:27.485186411Z,160,2,1108,C,A,15.060000000,100,0,333436421,0,165793,277841231,ARL
2025-07-17T16:08:27.485352204Z,2025-07-17T16:08:27.485186411Z,160,2,1108,A,A,15.360000000,100,0,333581441,130,165793,277841231,ARL
2025-07-17T16:08:27.487263276Z,2025-07-17T16:08:27.487097702Z,160,2,1108,C,A,14.520000000,100,0,328780597,0,165574,277841319,ARL
2025-07-17T16:08:27.487263276Z,2025-07-17T16:08:27.487097702Z,160,2,1108,A,A,14.740000000,100,0,333581481,130,165574,277841319,ARL
2025-07-17T16:08:27.492258906Z,2025-07-17T16:08:27.492093401Z,160,2,1108,C,A,14.480000000,100,0,333438545,130,165505,277841396,ARL
2025-07-17T16:08:27.492385750Z,2025-07-17T16:08:27.492220454Z,160,2,1108,A,A,14.750000000,100,0,333581569,130,165296,277841397,ARL
2025-07-17T16:08:27.496936122Z,2025-07-17T16:08:27.496770678Z,160,2,1108,C,A,13.960000000,100,0,333436473,130,165444,277841427,ARL
2025-07-17T16:08:27.496987832Z,2025-07-17T16:08:27.496822540Z,160,2,1108,A,A,14.190000000,100,0,333581625,130,165292,277841428,ARL
2025-07-17T16:08:27.501093618Z,2025-07-17T16:08:27.500928061Z,160,2,1108,C,A,13.850000000,2,0,331155889,0,165557,277841469,ARL
2025-07-17T16:08:27.501093618Z,2025-07-17T16:08:27.500928061Z,160,2,1108,A,A,13.980000000,2,0,333581677,130,165557,277841469,ARL
2025-07-17T16:08:27.516614373Z,2025-07-17T16:08:27.516449334Z,160,2,1108,C,A,14.190000000,100,0,333581625,130,165039,277841551,ARL
2025-07-17T16:08:27.516662099Z,2025-07-17T16:08:27.516496962Z,160,2,1108,A,A,14.260000000,100,0,333581765,130,165137,277841552,ARL
2025-07-17T16:08:27.533938450Z,2025-07-17T16:08:27.533773259Z,160,2,1108,C,A,14.990000000,100,0,333581389,0,165191,277841588,ARL
2025-07-17T16:08:27.533938450Z,2025-07-17T16:08:27.533773259Z,160,2,1108,A,A,15.040000000,100,0,333581845,130,165191,277841588,ARL
2025-07-17T16:08:27.987678739Z,2025-07-17T16:08:27.987513451Z,160,2,1108,A,A,13.990000000,100,0,333590057,130,165288,277846288,ARL
2025-07-17T16:08:58.024979382Z,2025-07-17T16:08:58.024814068Z,160,2,1108,A,A,13.810000000,15,0,334141429,130,165314,278261182,ARL
2025-07-17T16:09:00.222675234Z,2025-07-17T16:09:00.222509491Z,160,2,1108,C,A,13.990000000,100,0,333590057,0,165743,278295684,ARL
2025-07-17T16:09:00.222675234Z,2025-07-17T16:09:00.222509491Z,160,2,1108,A,A,13.820000000,100,0,334189729,130,165743,278295684,ARL
2025-07-17T16:09:00.223436757Z,2025-07-17T16:09:00.223269382Z,160,2,1108,C,A,15.040000000,100,0,333581845,0,167375,278295848,ARL
2025-07-17T16:09:00.223436757Z,2025-07-17T16:09:00.223269382Z,160,2,1108,A,A,14.890000000,100,0,334189777,128,167375,278295848,ARL
2025-07-17T16:09:00.226504346Z,2025-07-17T16:09:00.226338384Z,160,2,1108,C,A,14.750000000,100,0,333581569,0,165962,278296281,ARL
2025-07-17T16:09:00.226504346Z,2025-07-17T16:09:00.226338384Z,160,2,1108,A,A,14.610000000,100,0,334190189,130,165962,278296281,ARL
2025-07-17T16:09:00.227929061Z,2025-07-17T16:09:00.227763275Z,160,2,1108,C,A,14.260000000,100,0,333581765,130,165786,278296402,ARL
2025-07-17T16:09:00.227983483Z,2025-07-17T16:09:00.227818153Z,160,2,1108,A,A,14.100000000,100,0,334190225,130,165330,278296411,ARL
2025-07-17T16:09:00.232908882Z,2025-07-17T16:09:00.232743323Z,160,2,1108,C,A,14.940000000,100,0,333581429,0,165559,278296544,ARL
2025-07-17T16:09:00.232908882Z,2025-07-17T16:09:00.232743323Z,160,2,1108,A,A,14.790000000,100,0,334190353,130,165559,278296544,ARL
2025-07-17T16:09:00.326293286Z,2025-07-17T16:09:00.326127587Z,160,2,1108,C,A,17.730000000,100,0,333581425,0,165699,278298302,ARL
2025-07-17T16:09:00.326293286Z,2025-07-17T16:09:00.326127587Z,160,2,1108,A,A,17.560000000,100,0,334192253,130,165699,278298302,ARL
2025-07-17T16:09:00.335607827Z,2025-07-17T16:09:00.335442266Z,160,2,1108,C,A,16.060000000,100,0,333581433,0,165561,278298372,ARL
2025-07-17T16:09:00.335607827Z,2025-07-17T16:09:00.335442266Z,160,2,1108,A,A,15.900000000,100,0,334192405,130,165561,278298372,ARL
2025-07-17T16:09:00.695776010Z,2025-07-17T16:09:00.695610142Z,160,2,1108,C,A,14.940000000,100,0,333581409,0,165868,278304343,ARL
2025-07-17T16:09:00.695776010Z,2025-07-17T16:09:00.695610142Z,160,2,1108,A,A,14.790000000,100,0,334199009,130,165868,278304343,ARL
2025-07-17T16:09:08.719690693Z,2025-07-17T16:09:08.719524374Z,160,2,1108,A,A,13.750000000,15,0,334366613,130,166319,278436950,ARL
2025-07-17T16:09:08.719871410Z,2025-07-17T16:09:08.719706070Z,160,2,1108,C,A,13.820000000,100,0,334189729,0,165340,278436967,ARL
2025-07-17T16:09:08.719871410Z,2025-07-17T16:09:08.719706070Z,160,2,1108,A,A,13.760000000,100,0,334366617,130,165340,278436967,ARL
2025-07-17T16:09:08.720607932Z,2025-07-17T16:09:08.720442245Z,160,2,1108,C,A,14.890000000,100,0,334189777,0,165687,278436994,ARL
2025-07-17T16:09:08.720607932Z,2025-07-17T16:09:08.720442245Z,160,2,1108,A,A,14.830000000,100,0,334366645,130,165687,278436994,ARL
2025-07-17T16:09:18.819300735Z,2025-07-17T16:09:18.819135505Z,160,2,1108,C,A,13.810000000,15,0,334141429,130,165230,278596985,ARL
2025-07-17T16:09:19.927205023Z,2025-07-17T16:09:19.927039122Z,160,2,1108,A,A,13.730000000,15,0,334583329,130,165901,278621672,ARL
2025-07-17T16:09:19.927910703Z,2025-07-17T16:09:19.927745104Z,160,2,1108,C,A,14.740000000,100,0,333581393,0,165599,278621693,ARL
2025-07-17T16:09:19.927910703Z,2025-07-17T16:09:19.927745104Z,160,2,1108,A,A,14.620000000,100,0,334583349,130,165599,278621693,ARL
2025-07-17T16:09:19.928319369Z,2025-07-17T16:09:19.928153837Z,160,2,1108,C,A,14.740000000,100,0,333581481,0,165532,278621695,ARL
2025-07-17T16:09:19.928319369Z,2025-07-17T16:09:19.928153837Z,160,2,1108,A,A,14.620000000,100,0,334583361,130,165532,278621695,ARL
2025-07-17T16:09:20.284861075Z,2025-07-17T16:09:20.284695585Z,160,2,1108,C,A,13.760000000,100,0,334366617,0,165490,278629057,ARL
2025-07-17T16:09:20.284861075Z,2025-07-17T16:09:20.284695585Z,160,2,1108,A,A,13.740000000,100,0,334593569,130,165490,278629057,ARL
2025-07-17T16:09:20.293271620Z,2025-07-17T16:09:20.293106270Z,160,2,1108,C,A,14.100000000,100,0,334190225,130,165350,278629219,ARL
2025-07-17T16:09:20.293326641Z,2025-07-17T16:09:20.293161454Z,160,2,1108,A,A,14.010000000,100,0,334593753,130,165187,278629220,ARL
2025-07-17T16:09:20.818813935Z,2025-07-17T16:09:20.818648795Z,160,2,1108,C,A,13.730000000,15,0,334583329,130,165140,278640667,ARL
2025-07-17T16:09:20.818926356Z,2025-07-17T16:09:20.818761228Z,160,2,1108,C,A,13.750000000,15,0,334366613,130,165128,278640670,ARL
2025-07-17T16:09:28.986122432Z,2025-07-17T16:09:28.985956629Z,160,2,1108,C,A,13.980000000,2,0,333581677,0,165803,278784943,ARL
2025-07-17T16:09:28.986122432Z,2025-07-17T16:09:28.985956629Z,160,2,1108,A,A,13.900000000,2,0,334804177,130,165803,278784943,ARL
2025-07-17T16:09:40.821687905Z,2025-07-17T16:09:40.821522565Z,160,2,1108,A,A,13.700000000,15,0,335003269,130,165340,278938091,ARL
2025-07-17T16:09:40.853604577Z,2025-07-17T16:09:40.853439053Z,160,2,1108,C,A,13.740000000,100,0,334593569,0,165524,278938747,ARL
2025-07-17T16:09:40.853604577Z,2025-07-17T16:09:40.853439053Z,160,2,1108,A,A,13.710000000,100,0,335003813,130,165524,278938747,ARL
2025-07-17T16:09:40.854356022Z,2025-07-17T16:09:40.854190408Z,160,2,1108,C,A,14.830000000,100,0,334366645,0,165614,278938765,ARL
2025-07-17T16:09:40.854356022Z,2025-07-17T16:09:40.854190408Z,160,2,1108,A,A,14.770000000,100,0,335003845,130,165614,278938765,ARL
2025-07-17T16:09:40.855724422Z,2025-07-17T16:09:40.855558831Z,160,2,1108,C,A,17.560000000,100,0,334192253,0,165591,278938788,ARL
2025-07-17T16:09:40.855724422Z,2025-07-17T16:09:40.855558831Z,160,2,1108,A,A,17.420000000,100,0,335003849,130,165591,278938788,ARL
2025-07-17T16:09:50.820949131Z,2025-07-17T16:09:50.820783486Z,160,2,1108,A,A,13.670000000,15,0,335178437,130,165645,279081140,ARL
2025-07-17T16:09:52.678777358Z,2025-07-17T16:09:52.678611805Z,160,2,1108,C,A,13.710000000,100,0,335003813,0,165553,279109959,ARL
2025-07-17T16:09:52.678777358Z,2025-07-17T16:09:52.678611805Z,160,2,1108,A,A,13.680000000,100,0,335220349,130,165553,279109959,ARL
2025-07-17T16:09:52.679844338Z,2025-07-17T16:09:52.679678566Z,160,2,1108,C,A,15.900000000,100,0,334192405,0,165772,279109991,ARL
2025-07-17T16:09:52.679844338Z,2025-07-17T16:09:52.679678566Z,160,2,1108,A,A,15.740000000,100,0,335220497,130,165772,279109991,ARL
2025-07-17T16:09:52.679936826Z,2025-07-17T16:09:52.679769832Z,160,2,1108,C,A,14.790000000,100,0,334190353,0,166994,279109996,ARL
2025-07-17T16:09:52.679936826Z,2025-07-17T16:09:52.679769832Z,160,2,1108,A,A,14.640000000,100,0,335220525,130,166994,279109996,ARL
2025-07-17T16:09:52.680837736Z,2025-07-17T16:09:52.680672148Z,160,2,1108,C,A,15.360000000,100,0,333581441,0,165588,279110032,ARL
2025-07-17T16:09:52.680837736Z,2025-07-17T16:09:52.680672148Z,160,2,1108,A,A,15.050000000,100,0,335220549,130,165588,279110032,ARL
2025-07-17T16:09:52.682009938Z,2025-07-17T16:09:52.681844377Z,160,2,1108,C,A,14.610000000,100,0,334190189,130,165561,279110066,ARL
2025-07-17T16:09:52.682127530Z,2025-07-17T16:09:52.681961200Z,160,2,1108,A,A,14.470000000,100,0,335220561,130,166330,279110068,ARL
2025-07-17T16:09:52.683922707Z,2025-07-17T16:09:52.683757265Z,160,2,1108,C,A,14.790000000,100,0,334199009,0,165442,279110090,ARL
2025-07-17T16:09:52.683922707Z,2025-07-17T16:09:52.683757265Z,160,2,1108,A,A,14.640000000,100,0,335220629,130,165442,279110090,ARL
2025-07-17T16:10:04.521471804Z,2025-07-17T16:10:04.521306513Z,160,2,1108,C,A,13.670000000,15,0,335178437,130,165291,279306715,ARL
2025-07-17T16:10:04.561854856Z,2025-07-17T16:10:04.561688313Z,160,2,1108,C,A,13.700000000,15,0,335003269,128,166543,279312083,ARL
2025-07-17T16:10:32.822660498Z,2025-07-17T16:10:32.822495087Z,160,2,1108,A,A,13.650000000,15,0,335996705,130,165411,279705339,ARL
2025-07-17T16:10:32.822923138Z,2025-07-17T16:10:32.822757517Z,160,2,1108,C,A,13.680000000,100,0,335220349,0,165621,279705347,ARL
2025-07-17T16:10:32.822923138Z,2025-07-17T16:10:32.822757517Z,160,2,1108,A,A,13.660000000,100,0,335996709,130,165621,279705347,ARL
2025-07-17T16:10:32.823656903Z,2025-07-17T16:10:32.823491276Z,160,2,1108,C,A,14.770000000,100,0,335003845,0,165627,279705362,ARL
2025-07-17T16:10:32.823656903Z,2025-07-17T16:10:32.823491276Z,160,2,1108,A,A,14.720000000,100,0,335996725,130,165627,279705362,ARL
2025-07-17T16:10:32.830200844Z,2025-07-17T16:10:32.830032662Z,160,2,1108,C,A,14.010000000,100,0,334593753,130,168182,279705485,ARL
2025-07-17T16:10:32.830250720Z,2025-07-17T16:10:32.830085472Z,160,2,1108,A,A,13.930000000,100,0,335996777,130,165248,279705486,ARL
2025-07-17T16:10:42.822354869Z,2025-07-17T16:10:42.822189504Z,160,2,1108,A,A,13.630000000,15,0,336161333,130,165365,279834760,ARL
2025-07-17T16:10:42.822424663Z,2025-07-17T16:10:42.822258887Z,160,2,1108,C,A,13.660000000,100,0,335996709,0,165776,279834761,ARL
2025-07-17T16:10:42.822424663Z,2025-07-17T16:10:42.822258887Z,160,2,1108,A,A,13.640000000,100,0,336161337,130,165776,279834761,ARL
2025-07-17T16:10:42.823163929Z,2025-07-17T16:10:42.822998664Z,160,2,1108,C,A,14.460000000,100,0,331927161,130,165265,279834765,ARL
2025-07-17T16:10:42.823517444Z,2025-07-17T16:10:42.823352130Z,160,2,1108,A,A,14.250000000,100,0,336161365,130,165314,279834767,ARL
2025-07-17T16:10:46.534055942Z,2025-07-17T16:10:46.533890361Z,160,2,1108,C,A,14.620000000,100,0,334583349,0,165581,279921726,ARL
2025-07-17T16:10:46.534055942Z,2025-07-17T16:10:46.533890361Z,160,2,1108,A,A,14.510000000,100,0,336259225,130,165581,279921726,ARL
2025-07-17T16:10:46.538158874Z,2025-07-17T16:10:46.537992315Z,160,2,1108,C,A,13.650000000,15,0,335996705,128,166559,279921911,ARL
2025-07-17T16:10:46.561246030Z,2025-07-17T16:10:46.561080616Z,160,2,1108,C,A,14.620000000,100,0,334583361,0,165414,279924883,ARL
2025-07-17T16:10:46.561246030Z,2025-07-17T16:10:46.561080616Z,160,2,1108,A,A,14.510000000,100,0,336261905,130,165414,279924883,ARL
2025-07-17T16:10:47.543404001Z,2025-07-17T16:10:47.543238729Z,160,2,1108,A,A,13.610000000,15,0,336278197,130,165272,279938097,ARL
2025-07-17T16:10:48.657456395Z,2025-07-17T16:10:48.657290980Z,160,2,1108,C,A,13.640000000,100,0,336161337,0,165415,279952266,ARL
2025-07-17T16:10:48.657456395Z,2025-07-17T16:10:48.657290980Z,160,2,1108,A,A,13.620000000,100,0,336295769,130,165415,279952266,ARL
2025-07-17T16:10:48.658199425Z,2025-07-17T16:10:48.658033954Z,160,2,1108,C,A,14.720000000,100,0,335996725,0,165471,279952282,ARL
2025-07-17T16:10:48.658199425Z,2025-07-17T16:10:48.658033954Z,160,2,1108,A,A,14.680000000,100,0,336295845,130,165471,279952282,ARL
2025-07-17T16:10:51.059044292Z,2025-07-17T16:10:51.058878264Z,160,2,1108,C,A,13.610000000,15,0,336278197,128,166028,280001840,ARL
2025-07-17T16:10:51.059183923Z,2025-07-17T16:10:51.059016199Z,160,2,1108,C,A,13.630000000,15,0,336161333,128,167724,280001873,ARL
2025-07-17T16:10:51.059608753Z,2025-07-17T16:10:51.059443298Z,160,2,1108,C,A,13.620000000,100,0,336295769,130,165455,280001952,ARL
2025-07-17T16:10:51.170710609Z,2025-07-17T16:10:51.170545251Z,160,2,1108,A,A,13.910000000,100,0,336351081,130,165358,280003702,ARL
2025-07-17T16:10:52.958453641Z,2025-07-17T16:10:52.958288317Z,160,2,1108,A,A,13.600000000,15,0,336402845,130,165324,280050139,ARL
2025-07-17T16:10:53.102037173Z,2025-07-17T16:10:53.101871639Z,160,2,1108,C,A,13.910000000,100,0,336351081,0,165534,280057228,ARL
2025-07-17T16:10:53.102037173Z,2025-07-17T16:10:53.101871639Z,160,2,1108,A,A,13.610000000,100,0,336410125,130,165534,280057228,ARL
2025-07-17T16:10:54.959307592Z,2025-07-17T16:10:54.959141873Z,160,2,1108,C,A,13.900000000,2,0,334804177,0,165719,280084546,ARL
2025-07-17T16:10:54.959307592Z,2025-07-17T16:10:54.959141873Z,160,2,1108,A,A,13.820000000,2,0,336447325,130,165719,280084546,ARL
2025-07-17T16:10:59.518035805Z,2025-07-17T16:10:59.517870358Z,160,2,1108,A,A,13.580000000,15,0,336555153,130,165447,280173685,ARL
2025-07-17T16:11:00.215885294Z,2025-07-17T16:11:00.215719725Z,160,2,1108,C,A,13.610000000,100,0,336410125,0,165569,280184406,ARL
2025-07-17T16:11:00.215885294Z,2025-07-17T16:11:00.215719725Z,160,2,1108,A,A,13.590000000,100,0,336567189,130,165569,280184406,ARL
2025-07-17T16:11:00.216622121Z,2025-07-17T16:11:00.216456547Z,160,2,1108,C,A,14.680000000,100,0,336295845,0,165574,280184418,ARL
2025-07-17T16:11:00.216622121Z,2025-07-17T16:11:00.216456547Z,160,2,1108,A,A,14.640000000,100,0,336567213,130,165574,280184418,ARL
2025-07-17T16:11:00.228999377Z,2025-07-17T16:11:00.228833925Z,160,2,1108,C,A,13.930000000,100,0,335996777,130,165452,280184613,ARL
2025-07-17T16:11:00.229051124Z,2025-07-17T16:11:00.228885790Z,160,2,1108,A,A,13.860000000,100,0,336567333,130,165334,280184614,ARL
2025-07-17T16:11:00.313087129Z,2025-07-17T16:11:00.312921679Z,160,2,1108,C,A,17.420000000,100,0,335003849,0,165450,280188038,ARL
2025-07-17T16:11:00.313087129Z,2025-07-17T16:11:00.312921679Z,160,2,1108,A,A,17.260000000,100,0,336570921,130,165450,280188038,ARL
2025-07-17T16:11:00.366811541Z,2025-07-17T16:11:00.366645846Z,160,2,1108,A,A,13.620000000,1,0,336572049,130,165695,280189435,ARL
2025-07-17T16:11:00.367374773Z,2025-07-17T16:11:00.367209243Z,160,2,1108,C,B,12.490000000,100,0,331942945,0,165530,280189439,ARL
2025-07-17T16:11:00.367374773Z,2025-07-17T16:11:00.367209243Z,160,2,1108,A,B,12.360000000,100,0,336572057,130,165530,280189439,ARL
2025-07-17T16:11:00.367485094Z,2025-07-17T16:11:00.367319059Z,160,2,1108,C,B,12.490000000,100,0,331942901,0,166035,280189441,ARL
2025-07-17T16:11:00.367485094Z,2025-07-17T16:11:00.367319059Z,160,2,1108,A,B,12.360000000,100,0,336572069,130,166035,280189441,ARL
2025-07-17T16:11:00.466868624Z,2025-07-17T16:11:00.466703632Z,160,2,1108,C,A,13.620000000,1,0,336572049,130,164992,280191783,ARL
2025-07-17T16:11:06.626831799Z,2025-07-17T16:11:06.626666474Z,160,2,1108,A,A,14.270000000,700,0,336747457,130,165325,280342316,ARL
2025-07-17T16:11:06.626906700Z,2025-07-17T16:11:06.626741446Z,160,2,1108,C,A,14.680000000,700,0,331929977,130,165254,280342318,ARL
2025-07-17T16:11:08.308034538Z,2025-07-17T16:11:08.307868957Z,160,2,1108,C,A,13.600000000,15,0,336402845,130,165581,280374785,ARL
2025-07-17T16:11:09.568536292Z,2025-07-17T16:11:09.568370995Z,160,2,1108,A,A,13.560000000,15,0,336816813,130,165297,280401189,ARL
2025-07-17T16:11:10.341953971Z,2025-07-17T16:11:10.341788521Z,160,2,1108,C,A,13.590000000,100,0,336567189,0,165450,280411396,ARL
2025-07-17T16:11:10.341953971Z,2025-07-17T16:11:10.341788521Z,160,2,1108,A,A,13.570000000,100,0,336828765,130,165450,280411396,ARL
2025-07-17T16:11:14.610701450Z,2025-07-17T16:11:14.610535763Z,160,2,1108,C,A,13.580000000,15,0,336555153,130,165687,280482371,ARL
2025-07-17T16:11:16.025458231Z,2025-07-17T16:11:16.025292936Z,160,2,1108,C,A,13.560000000,15,0,336816813,130,165295,280514282,ARL
2025-07-17T16:11:50.026837358Z,2025-07-17T16:11:50.026672014Z,160,2,1108,A,A,13.550000000,15,0,337690189,130,165344,281078802,ARL
2025-07-17T16:11:50.027004977Z,2025-07-17T16:11:50.026839463Z,160,2,1108,C,A,13.570000000,100,0,336828765,0,165514,281078803,ARL
2025-07-17T16:11:50.027004977Z,2025-07-17T16:11:50.026839463Z,160,2,1108,A,A,13.560000000,100,0,337690193,130,165514,281078803,ARL
2025-07-17T16:11:50.033010798Z,2025-07-17T16:11:50.032845393Z,160,2,1108,C,A,15.740000000,100,0,335220497,0,165405,281078903,ARL
2025-07-17T16:11:50.033010798Z,2025-07-17T16:11:50.032845393Z,160,2,1108,A,A,15.600000000,100,0,337690641,130,165405,281078903,ARL
2025-07-17T16:11:53.859909462Z,2025-07-17T16:11:53.859743991Z,160,2,1108,A,A,13.530000000,15,0,337772837,130,165471,281142794,ARL
2025-07-17T16:11:54.662527332Z,2025-07-17T16:11:54.662361841Z,160,2,1108,C,A,13.560000000,100,0,337690193,0,165491,281156215,ARL
2025-07-17T16:11:54.662527332Z,2025-07-17T16:11:54.662361841Z,160,2,1108,A,A,13.540000000,100,0,337790717,130,165491,281156215,ARL
2025-07-17T16:11:54.663278200Z,2025-07-17T16:11:54.663112543Z,160,2,1108,C,A,14.640000000,100,0,336567213,0,165657,281156222,ARL
2025-07-17T16:11:54.663278200Z,2025-07-17T16:11:54.663112543Z,160,2,1108,A,A,14.590000000,100,0,337790737,130,165657,281156222,ARL
2025-07-17T16:11:54.664134026Z,2025-07-17T16:11:54.663968656Z,160,2,1108,C,A,14.640000000,100,0,335220525,0,165370,281156223,ARL
2025-07-17T16:11:54.664134026Z,2025-07-17T16:11:54.663968656Z,160,2,1108,A,A,14.490000000,100,0,337790745,130,165370,281156223,ARL
2025-07-17T16:11:54.666326600Z,2025-07-17T16:11:54.666160990Z,160,2,1108,C,A,14.470000000,100,0,335220561,0,165610,281156243,ARL
2025-07-17T16:11:54.666326600Z,2025-07-17T16:11:54.666160990Z,160,2,1108,A,A,14.330000000,100,0,337790761,130,165610,281156243,ARL
2025-07-17T16:11:54.667504546Z,2025-07-17T16:11:54.667339002Z,160,2,1108,C,A,14.640000000,100,0,335220629,0,165544,281156250,ARL
2025-07-17T16:11:54.667504546Z,2025-07-17T16:11:54.667339002Z,160,2,1108,A,A,14.490000000,100,0,337790777,130,165544,281156250,ARL
2025-07-17T16:11:59.382515678Z,2025-07-17T16:11:59.382350338Z,160,2,1108,C,A,13.550000000,15,0,337690189,130,165340,281270010,ARL
2025-07-17T16:12:02.982078719Z,2025-07-17T16:12:02.981913204Z,160,2,1108,A,A,13.510000000,15,0,338041605,130,165515,281348152,ARL
2025-07-17T16:12:03.064162605Z,2025-07-17T16:12:03.063997054Z,160,2,1108,C,A,13.540000000,100,0,337790717,0,165551,281351122,ARL
2025-07-17T16:12:03.064162605Z,2025-07-17T16:12:03.063997054Z,160,2,1108,A,A,13.520000000,100,0,338044041,130,165551,281351122,ARL
2025-07-17T16:12:03.068467146Z,2025-07-17T16:12:03.068301745Z,160,2,1108,C,B,13.010000000,2,0,332494213,0,165401,281351235,ARL
2025-07-17T16:12:03.068467146Z,2025-07-17T16:12:03.068301745Z,160,2,1108,A,B,12.920000000,2,0,338044113,130,165401,281351235,ARL
2025-07-17T16:12:03.075200038Z,2025-07-17T16:12:03.075034550Z,160,2,1108,C,A,13.860000000,100,0,336567333,130,165488,281351372,ARL
2025-07-17T16:12:03.075260529Z,2025-07-17T16:12:03.075095341Z,160,2,1108,A,A,13.790000000,100,0,338044233,130,165188,281351373,ARL
2025-07-17T16:12:06.775177637Z,2025-07-17T16:12:06.775011783Z,160,2,1108,C,A,14.510000000,100,0,336259225,0,165854,281422697,ARL
2025-07-17T16:12:06.775177637Z,2025-07-17T16:12:06.775011783Z,160,2,1108,A,A,14.400000000,100,0,338139585,130,165854,281422697,ARL
2025-07-17T16:12:06.775614536Z,2025-07-17T16:12:06.775449017Z,160,2,1108,C,A,14.510000000,100,0,336261905,0,165519,281422702,ARL
2025-07-17T16:12:06.775614536Z,2025-07-17T16:12:06.775449017Z,160,2,1108,A,A,14.400000000,100,0,338139601,130,165519,281422702,ARL
2025-07-17T16:12:06.779705717Z,2025-07-17T16:12:06.779540143Z,160,2,1108,C,A,13.530000000,15,0,337772837,130,165574,281422782,ARL
2025-07-17T16:12:07.784698893Z,2025-07-17T16:12:07.784533539Z,160,2,1108,A,A,13.490000000,15,0,338167057,130,165354,281443568,ARL
2025-07-17T16:12:08.585194585Z,2025-07-17T16:12:08.585029039Z,160,2,1108,C,A,13.520000000,100,0,338044041,0,165546,281451898,ARL
2025-07-17T16:12:08.585194585Z,2025-07-17T16:12:08.585029039Z,160,2,1108,A,A,13.500000000,100,0,338180793,130,165546,281451898,ARL
2025-07-17T16:12:08.585942049Z,2025-07-17T16:12:08.585776508Z,160,2,1108,C,A,14.590000000,100,0,337790737,0,165541,281451903,ARL
2025-07-17T16:12:08.585942049Z,2025-07-17T16:12:08.585776508Z,160,2,1108,A,A,14.550000000,100,0,338180841,130,165541,281451903,ARL
2025-07-17T16:12:18.789922022Z,2025-07-17T16:12:18.789756367Z,160,2,1108,C,A,13.820000000,2,0,336447325,0,165655,281613266,ARL
2025-07-17T16:12:18.789922022Z,2025-07-17T16:12:18.789756367Z,160,2,1108,A,A,13.740000000,2,0,338371797,130,165655,281613266,ARL
2025-07-17T16:12:19.370986404Z,2025-07-17T16:12:19.370820933Z,160,2,1108,A,A,14.270000000,700,0,338382329,130,165471,281622545,ARL
2025-07-17T16:12:19.371041049Z,2025-07-17T16:12:19.370875240Z,160,2,1108,C,A,14.600000000,700,0,282920685,130,165809,281622547,ARL
2025-07-17T16:12:19.696689718Z,2025-07-17T16:12:19.696521343Z,160,2,1108,C,A,13.490000000,15,0,338167057,128,168375,281630053,ARL
2025-07-17T16:12:19.711773364Z,2025-07-17T16:12:19.711591494Z,160,2,1108,C,A,13.510000000,15,0,338041605,128,181870,281634812,ARL
2025-07-17T16:12:32.761277424Z,2025-07-17T16:12:32.761112078Z,160,2,1108,A,A,13.480000000,15,0,338707945,130,165346,281880398,ARL
2025-07-17T16:12:32.761413202Z,2025-07-17T16:12:32.761246859Z,160,2,1108,C,A,13.500000000,100,0,338180793,0,166343,281880409,ARL
2025-07-17T16:12:32.761413202Z,2025-07-17T16:12:32.761246859Z,160,2,1108,A,A,13.490000000,100,0,338707949,130,166343,281880409,ARL
2025-07-17T16:12:32.779055996Z,2025-07-17T16:12:32.778890447Z,160,2,1108,C,A,15.120000000,100,0,296387089,0,165549,281880579,ARL
2025-07-17T16:12:32.779055996Z,2025-07-17T16:12:32.778890447Z,160,2,1108,A,A,14.840000000,100,0,338708241,130,165549,281880579,ARL
2025-07-17T16:12:32.804318005Z,2025-07-17T16:12:32.804152457Z,160,2,1108,A,A,15.380000000,100,0,338709513,130,165548,281880972,ARL
2025-07-17T16:12:32.804332586Z,2025-07-17T16:12:32.804166092Z,160,2,1108,C,A,15.660000000,100,0,326730513,130,166494,281880973,ARL
2025-07-17T16:12:40.993064296Z,2025-07-17T16:12:40.992898990Z,160,2,1108,C,A,13.490000000,100,0,338707949,130,165306,282007871,ARL
2025-07-17T16:12:40.993332664Z,2025-07-17T16:12:40.993167418Z,160,2,1108,C,A,14.270000000,700,0,338382329,130,165246,282007875,ARL
2025-07-17T16:12:40.993333790Z,2025-07-17T16:12:40.993168470Z,160,2,1108,C,A,14.270000000,700,0,336747457,130,165320,282007876,ARL
2025-07-17T16:12:40.993379626Z,2025-07-17T16:12:40.993214193Z,160,2,1108,A,A,14.540000000,700,0,338864169,130,165433,282007877,ARL
2025-07-17T16:12:40.993393440Z,2025-07-17T16:12:40.993227993Z,160,2,1108,A,A,14.470000000,700,0,338864173,130,165447,282007878,ARL
2025-07-17T16:12:40.993432115Z,2025-07-17T16:12:40.993266591Z,160,2,1108,A,A,15.710000000,100,0,338864177,130,165524,282007879,ARL
2025-07-17T16:12:40.993445042Z,2025-07-17T16:12:40.993279810Z,160,2,1108,C,A,15.380000000,100,0,338709513,130,165232,282007880,ARL
2025-07-17T16:12:40.993818130Z,2025-07-17T16:12:40.993652511Z,160,2,1108,C,A,14.550000000,100,0,338180841,0,165619,282007882,ARL
2025-07-17T16:12:40.993818130Z,2025-07-17T16:12:40.993652511Z,160,2,1108,A,A,14.850000000,100,0,338864189,130,165619,282007882,ARL
2025-07-17T16:12:40.994783297Z,2025-07-17T16:12:40.994617858Z,160,2,1108,C,A,14.490000000,100,0,337790745,0,165439,282007892,ARL
2025-07-17T16:12:40.994783297Z,2025-07-17T16:12:40.994617858Z,160,2,1108,A,A,14.760000000,100,0,338864217,130,165439,282007892,ARL
2025-07-17T16:12:40.995078856Z,2025-07-17T16:12:40.994913404Z,160,2,1108,C,A,14.840000000,100,0,338708241,0,165452,282007894,ARL
2025-07-17T16:12:40.995078856Z,2025-07-17T16:12:40.994913404Z,160,2,1108,A,A,15.170000000,100,0,338864221,130,165452,282007894,ARL
2025-07-17T16:12:40.995349303Z,2025-07-17T16:12:40.995183768Z,160,2,1108,C,A,15.600000000,100,0,337690641,0,165535,282007898,ARL
2025-07-17T16:12:40.995349303Z,2025-07-17T16:12:40.995183768Z,160,2,1108,A,A,15.860000000,100,0,338864245,130,165535,282007898,ARL
2025-07-17T16:12:40.996460080Z,2025-07-17T16:12:40.996294601Z,160,2,1108,C,A,17.260000000,100,0,336570921,0,165479,282007909,ARL
2025-07-17T16:12:40.996460080Z,2025-07-17T16:12:40.996294601Z,160,2,1108,A,A,17.520000000,100,0,338864289,130,165479,282007909,ARL
2025-07-17T16:12:40.997300700Z,2025-07-17T16:12:40.997135307Z,160,2,1108,C,A,14.330000000,100,0,337790761,130,165393,282007914,ARL
2025-07-17T16:12:40.997422356Z,2025-07-17T16:12:40.997257014Z,160,2,1108,A,A,14.580000000,100,0,338864317,130,165342,282007916,ARL
2025-07-17T16:12:41.004229622Z,2025-07-17T16:12:41.004063876Z,160,2,1108,C,A,14.490000000,100,0,337790777,0,165746,282007959,ARL
2025-07-17T16:12:41.004229622Z,2025-07-17T16:12:41.004063876Z,160,2,1108,A,A,14.760000000,100,0,338864405,130,165746,282007959,ARL
2025-07-17T16:12:41.005576053Z,2025-07-17T16:12:41.005406614Z,160,2,1108,A,A,13.490000000,100,0,338864581,128,169439,282008256,ARL
2025-07-17T16:12:41.010638351Z,2025-07-17T16:12:41.010473041Z,160,2,1108,C,A,14.760000000,100,0,338864405,0,165310,282008884,ARL
2025-07-17T16:12:41.010638351Z,2025-07-17T16:12:41.010473041Z,160,2,1108,A,A,14.440000000,100,0,338865133,130,165310,282008884,ARL
2025-07-17T16:12:41.011160341Z,2025-07-17T16:12:41.010994859Z,160,2,1108,C,A,13.790000000,100,0,338044233,130,165482,282008914,ARL
2025-07-17T16:12:41.011211986Z,2025-07-17T16:12:41.011046717Z,160,2,1108,A,A,14.060000000,100,0,338865141,130,165269,282008916,ARL
2025-07-17T16:12:41.011555342Z,2025-07-17T16:12:41.011390077Z,160,2,1108,C,A,14.760000000,100,0,338864217,0,165265,282008942,ARL
2025-07-17T16:12:41.011555342Z,2025-07-17T16:12:41.011390077Z,160,2,1108,A,A,14.440000000,100,0,338865165,130,165265,282008942,ARL
2025-07-17T16:12:41.012044919Z,2025-07-17T16:12:41.011879795Z,160,2,1108,C,A,14.060000000,100,0,338865141,130,165124,282008953,ARL
2025-07-17T16:12:41.012094494Z,2025-07-17T16:12:41.011929033Z,160,2,1108,A,A,13.760000000,100,0,338865177,130,165461,282008954,ARL
2025-07-17T16:12:41.014974491Z,2025-07-17T16:12:41.014809197Z,160,2,1108,C,A,17.520000000,100,0,338864289,0,165294,282008990,ARL
2025-07-17T16:12:41.014974491Z,2025-07-17T16:12:41.014809197Z,160,2,1108,A,A,17.140000000,100,0,338865253,130,165294,282008990,ARL
2025-07-17T16:12:41.017837378Z,2025-07-17T16:12:41.017672033Z,160,2,1108,C,A,15.860000000,100,0,338864245,0,165345,282009053,ARL
2025-07-17T16:12:41.017837378Z,2025-07-17T16:12:41.017672033Z,160,2,1108,A,A,15.520000000,100,0,338865301,130,165345,282009053,ARL
2025-07-17T16:12:41.032270817Z,2025-07-17T16:12:41.032105565Z,160,2,1108,C,A,15.170000000,100,0,338864221,0,165252,282009412,ARL
2025-07-17T16:12:41.032270817Z,2025-07-17T16:12:41.032105565Z,160,2,1108,A,A,14.840000000,100,0,338866081,130,165252,282009412,ARL
2025-07-17T16:12:41.032312420Z,2025-07-17T16:12:41.032147083Z,160,2,1108,A,A,15.380000000,100,0,338866089,130,165337,282009414,ARL
2025-07-17T16:12:41.032324438Z,2025-07-17T16:12:41.032159348Z,160,2,1108,C,A,15.710000000,100,0,338864177,130,165090,282009415,ARL
2025-07-17T16:12:41.043406383Z,2025-07-17T16:12:41.043241012Z,160,2,1108,C,A,14.850000000,100,0,338864189,0,165371,282009482,ARL
2025-07-17T16:12:41.043406383Z,2025-07-17T16:12:41.043241012Z,160,2,1108,A,A,14.540000000,100,0,338866245,130,165371,282009482,ARL
2025-07-17T16:12:42.001347844Z,2025-07-17T16:12:42.001182016Z,160,2,1108,C,A,14.580000000,100,0,338864317,0,165828,282033913,ARL
2025-07-17T16:12:42.001347844Z,2025-07-17T16:12:42.001182016Z,160,2,1108,A,A,14.280000000,100,0,338894329,130,165828,282033913,ARL
2025-07-17T16:12:42.762154469Z,2025-07-17T16:12:42.761989222Z,160,2,1108,A,A,13.460000000,15,0,338904977,130,165247,282042242,ARL
2025-07-17T16:12:43.022127902Z,2025-07-17T16:12:43.021951997Z,160,2,1108,C,A,13.490000000,100,0,338864581,0,175905,282057719,ARL
2025-07-17T16:12:43.022127902Z,2025-07-17T16:12:43.021951997Z,160,2,1108,A,A,13.470000000,100,0,338918217,128,175905,282057719,ARL
2025-07-17T16:12:43.022612177Z,2025-07-17T16:12:43.022444956Z,160,2,1108,A,A,15.690000000,100,0,338918553,128,167221,282058085,ARL
2025-07-17T16:12:43.022627592Z,2025-07-17T16:12:43.022461725Z,160,2,1108,C,A,15.380000000,100,0,338866089,130,165867,282058088,ARL
2025-07-17T16:12:43.049284355Z,2025-07-17T16:12:43.049119139Z,160,2,1108,A,A,15.360000000,100,0,338926929,130,165216,282065940,ARL
2025-07-17T16:12:43.049298989Z,2025-07-17T16:12:43.049132842Z,160,2,1108,C,A,15.690000000,100,0,338918553,128,166147,282065943,ARL
2025-07-17T16:12:43.154952375Z,2025-07-17T16:12:43.154787212Z,160,2,1108,A,A,14.270000000,100,0,338932853,130,165163,282073056,ARL
2025-07-17T16:12:43.154965183Z,2025-07-17T16:12:43.154800020Z,160,2,1108,C,A,14.560000000,100,0,296391881,130,165163,282073058,ARL
2025-07-17T16:12:43.915552526Z,2025-07-17T16:12:43.915387059Z,160,2,1108,C,A,14.280000000,100,0,302681357,130,165467,282085822,ARL
2025-07-17T16:12:43.915555340Z,2025-07-17T16:12:43.915389642Z,160,2,1108,A,A,14.000000000,100,0,338945933,130,165698,282085823,ARL
2025-07-17T16:12:50.729244449Z,2025-07-17T16:12:50.729079105Z,160,2,1108,C,A,13.460000000,15,0,338904977,130,165344,282168721,ARL
2025-07-17T16:12:50.729418237Z,2025-07-17T16:12:50.729252907Z,160,2,1108,C,A,13.480000000,15,0,338707945,130,165330,282168744,ARL
2025-07-17T16:12:50.729575741Z,2025-07-17T16:12:50.729409745Z,160,2,1108,A,A,13.470000000,96,0,339054149,130,165996,282168754,ARL
2025-07-17T16:12:53.021914652Z,2025-07-17T16:12:53.021749348Z,160,2,1108,A,A,13.460000000,15,0,339096733,130,165304,282194154,ARL
2025-07-17T16:12:53.021959141Z,2025-07-17T16:12:53.021793735Z,160,2,1108,C,A,13.470000000,100,0,338918217,130,165406,282194157,ARL
2025-07-17T16:12:53.022230122Z,2025-07-17T16:12:53.022064745Z,160,2,1108,C,A,13.470000000,96,0,339054149,130,165377,282194159,ARL
2025-07-17T16:12:53.022572023Z,2025-07-17T16:12:53.022406202Z,160,2,1108,A,A,15.690000000,100,0,339096757,130,165821,282194161,ARL
2025-07-17T16:12:53.022584264Z,2025-07-17T16:12:53.022418950Z,160,2,1108,C,A,15.360000000,100,0,338926929,130,165314,282194162,ARL
2025-07-17T16:12:53.022962940Z,2025-07-17T16:12:53.022797046Z,160,2,1108,C,A,14.540000000,100,0,338866245,0,165894,282194167,ARL
2025-07-17T16:12:53.022962940Z,2025-07-17T16:12:53.022797046Z,160,2,1108,A,A,14.830000000,100,0,339096773,130,165894,282194167,ARL
2025-07-17T16:12:53.023589530Z,2025-07-17T16:12:53.023423468Z,160,2,1108,C,A,14.440000000,100,0,338865165,0,166062,282194181,ARL
2025-07-17T16:12:53.023589530Z,2025-07-17T16:12:53.023423468Z,160,2,1108,A,A,14.730000000,100,0,339096797,130,166062,282194181,ARL
2025-07-17T16:12:53.024069153Z,2025-07-17T16:12:53.023903582Z,160,2,1108,C,A,17.140000000,100,0,338865253,0,165571,282194183,ARL
2025-07-17T16:12:53.024069153Z,2025-07-17T16:12:53.023903582Z,160,2,1108,A,A,17.480000000,100,0,339096809,130,165571,282194183,ARL
2025-07-17T16:12:53.025583784Z,2025-07-17T16:12:53.025418159Z,160,2,1108,C,A,14.840000000,100,0,338866081,0,165625,282194188,ARL
2025-07-17T16:12:53.025583784Z,2025-07-17T16:12:53.025418159Z,160,2,1108,A,A,15.140000000,100,0,339096813,130,165625,282194188,ARL
2025-07-17T16:12:53.025651983Z,2025-07-17T16:12:53.025486466Z,160,2,1108,C,A,14.440000000,100,0,338865133,0,165517,282194189,ARL
2025-07-17T16:12:53.025651983Z,2025-07-17T16:12:53.025486466Z,160,2,1108,A,A,14.730000000,100,0,339096817,130,165517,282194189,ARL
2025-07-17T16:12:53.027715026Z,2025-07-17T16:12:53.027549524Z,160,2,1108,C,A,14.280000000,100,0,338894329,130,165502,282194224,ARL
2025-07-17T16:12:53.027866777Z,2025-07-17T16:12:53.027701439Z,160,2,1108,A,A,14.550000000,100,0,339096833,130,165338,282194226,ARL
2025-07-17T16:12:53.027987030Z,2025-07-17T16:12:53.027821450Z,160,2,1108,C,A,15.520000000,100,0,338865301,0,165580,282194228,ARL
2025-07-17T16:12:53.027987030Z,2025-07-17T16:12:53.027821450Z,160,2,1108,A,A,15.830000000,100,0,339096837,130,165580,282194228,ARL
2025-07-17T16:12:53.033266537Z,2025-07-17T16:12:53.033101265Z,160,2,1108,C,A,13.760000000,100,0,338865177,130,165272,282194348,ARL
2025-07-17T16:12:53.033302848Z,2025-07-17T16:12:53.033137644Z,160,2,1108,C,A,14.470000000,700,0,338864173,130,165204,282194349,ARL
2025-07-17T16:12:53.033318818Z,2025-07-17T16:12:53.033153612Z,160,2,1108,A,A,14.040000000,100,0,339096893,130,165206,282194350,ARL
2025-07-17T16:12:53.033349323Z,2025-07-17T16:12:53.033183560Z,160,2,1108,A,A,14.680000000,700,0,339096897,130,165763,282194351,ARL
2025-07-17T16:12:53.033762072Z,2025-07-17T16:12:53.033596046Z,160,2,1108,C,A,13.740000000,2,0,338371797,0,166026,282194354,ARL
2025-07-17T16:12:53.033762072Z,2025-07-17T16:12:53.033596046Z,160,2,1108,A,A,13.980000000,2,0,339096909,130,166026,282194354,ARL
2025-07-17T16:12:53.034000646Z,2025-07-17T16:12:53.033835120Z,160,2,1108,C,A,14.250000000,100,0,336161365,130,165526,282194360,ARL
2025-07-17T16:12:53.034142471Z,2025-07-17T16:12:53.033977054Z,160,2,1108,C,A,14.730000000,100,0,339096797,0,165417,282194361,ARL
2025-07-17T16:12:53.034142471Z,2025-07-17T16:12:53.033977054Z,160,2,1108,A,A,14.960000000,100,0,339096917,130,165417,282194361,ARL
2025-07-17T16:12:53.034178176Z,2025-07-17T16:12:53.034012618Z,160,2,1108,C,A,15.830000000,100,0,339096837,0,165558,282194362,ARL
2025-07-17T16:12:53.034178176Z,2025-07-17T16:12:53.034012618Z,160,2,1108,A,A,16.080000000,100,0,339096921,130,165558,282194362,ARL
2025-07-17T16:12:53.034353140Z,2025-07-17T16:12:53.034187864Z,160,2,1108,A,A,14.600000000,100,0,339096925,130,165276,282194365,ARL
2025-07-17T16:12:53.035411748Z,2025-07-17T16:12:53.035246187Z,160,2,1108,C,A,15.050000000,100,0,335220549,0,165561,282194373,ARL
2025-07-17T16:12:53.035411748Z,2025-07-17T16:12:53.035246187Z,160,2,1108,A,A,15.380000000,100,0,339096929,130,165561,282194373,ARL
2025-07-17T16:12:53.036307382Z,2025-07-17T16:12:53.036142164Z,160,2,1108,C,A,17.480000000,100,0,339096809,0,165218,282194381,ARL
2025-07-17T16:12:53.036307382Z,2025-07-17T16:12:53.036142164Z,160,2,1108,A,A,17.760000000,100,0,339096949,130,165218,282194381,ARL
2025-07-17T16:12:53.040045217Z,2025-07-17T16:12:53.039879965Z,160,2,1108,C,A,14.730000000,100,0,339096817,0,165252,282194416,ARL
2025-07-17T16:12:53.040045217Z,2025-07-17T16:12:53.039879965Z,160,2,1108,A,A,14.960000000,100,0,339096977,130,165252,282194416,ARL
2025-07-17T16:12:53.043727225Z,2025-07-17T16:12:53.043562198Z,160,2,1108,C,A,14.040000000,100,0,339096893,130,165027,282194436,ARL
2025-07-17T16:12:53.043775299Z,2025-07-17T16:12:53.043610101Z,160,2,1108,A,A,14.260000000,100,0,339097005,130,165198,282194438,ARL
2025-07-17T16:12:53.073052597Z,2025-07-17T16:12:53.072887133Z,160,2,1108,C,A,14.830000000,100,0,339096773,0,165464,282194725,ARL
2025-07-17T16:12:53.073052597Z,2025-07-17T16:12:53.072887133Z,160,2,1108,A,A,15.060000000,100,0,339097245,130,165464,282194725,ARL
2025-07-17T16:12:53.332729487Z,2025-07-17T16:12:53.332564148Z,160,2,1108,C,A,14.000000000,100,0,338945933,130,165339,282196976,ARL
2025-07-17T16:12:53.332730508Z,2025-07-17T16:12:53.332565150Z,160,2,1108,A,A,14.530000000,100,0,339100477,130,165358,282196977,ARL
2025-07-17T16:12:53.587788615Z,2025-07-17T16:12:53.587623157Z,160,2,1108,A,A,14.810000000,100,0,339103269,130,165458,282200199,ARL
2025-07-17T16:12:53.587810242Z,2025-07-17T16:12:53.587644886Z,160,2,1108,C,A,14.270000000,100,0,338932853,130,165356,282200200,ARL
2025-07-17T16:12:54.015217279Z,2025-07-17T16:12:54.015051915Z,160,2,1108,A,A,13.470000000,100,0,339110853,130,165364,282207405,ARL
2025-07-17T16:12:54.015951319Z,2025-07-17T16:12:54.015785325Z,160,2,1108,C,A,14.600000000,100,0,339096925,130,165994,282207428,ARL
2025-07-17T16:12:54.015954059Z,2025-07-17T16:12:54.015788678Z,160,2,1108,C,A,15.060000000,100,0,339097245,0,165381,282207429,ARL
2025-07-17T16:12:54.015954059Z,2025-07-17T16:12:54.015788678Z,160,2,1108,A,A,14.520000000,100,0,339110897,130,165381,282207429,ARL
2025-07-17T16:12:54.016305036Z,2025-07-17T16:12:54.016139684Z,160,2,1108,A,A,14.070000000,100,0,339110909,130,165352,282207437,ARL
2025-07-17T16:12:54.017154493Z,2025-07-17T16:12:54.016988897Z,160,2,1108,C,A,14.960000000,100,0,339096917,0,165596,282207488,ARL
2025-07-17T16:12:54.017154493Z,2025-07-17T16:12:54.016988897Z,160,2,1108,A,A,14.420000000,100,0,339110981,130,165596,282207488,ARL
2025-07-17T16:12:54.017381126Z,2025-07-17T16:12:54.017215883Z,160,2,1108,C,A,13.980000000,2,0,339096909,0,165243,282207495,ARL
2025-07-17T16:12:54.017381126Z,2025-07-17T16:12:54.017215883Z,160,2,1108,A,A,13.730000000,2,0,339110993,130,165243,282207495,ARL
2025-07-17T16:12:54.017787766Z,2025-07-17T16:12:54.017622232Z,160,2,1108,C,A,15.380000000,100,0,339096929,0,165534,282207502,ARL
2025-07-17T16:12:54.017787766Z,2025-07-17T16:12:54.017622232Z,160,2,1108,A,A,14.820000000,100,0,339111005,130,165534,282207502,ARL
2025-07-17T16:12:54.020179178Z,2025-07-17T16:12:54.020013940Z,160,2,1108,C,A,14.260000000,100,0,339097005,130,165238,282207539,ARL
2025-07-17T16:12:54.020233019Z,2025-07-17T16:12:54.020067630Z,160,2,1108,A,A,13.740000000,100,0,339111029,130,165389,282207540,ARL
2025-07-17T16:12:54.023027943Z,2025-07-17T16:12:54.022862493Z,160,2,1108,C,A,17.760000000,100,0,339096949,0,165450,282207651,ARL
2025-07-17T16:12:54.023027943Z,2025-07-17T16:12:54.022862493Z,160,2,1108,A,A,17.110000000,100,0,339111097,130,165450,282207651,ARL
2025-07-17T16:12:54.026187354Z,2025-07-17T16:12:54.026021681Z,160,2,1108,C,A,16.080000000,100,0,339096921,0,165673,282207700,ARL
2025-07-17T16:12:54.026187354Z,2025-07-17T16:12:54.026021681Z,160,2,1108,A,A,15.500000000,100,0,339111149,130,165673,282207700,ARL
2025-07-17T16:12:54.029232379Z,2025-07-17T16:12:54.029066847Z,160,2,1108,C,A,14.550000000,100,0,339096833,0,165532,282207737,ARL
2025-07-17T16:12:54.029232379Z,2025-07-17T16:12:54.029066847Z,160,2,1108,A,A,14.260000000,100,0,339111189,130,165532,282207737,ARL
2025-07-17T16:12:54.055257401Z,2025-07-17T16:12:54.055092122Z,160,2,1108,A,A,15.360000000,100,0,339112469,130,165279,282209385,ARL
2025-07-17T16:12:54.055269406Z,2025-07-17T16:12:54.055104415Z,160,2,1108,C,A,15.690000000,100,0,339096757,130,164991,282209392,ARL
2025-07-17T16:12:54.069779810Z,2025-07-17T16:12:54.069614114Z,160,2,1108,C,A,14.960000000,100,0,339096977,0,165696,282210148,ARL
2025-07-17T16:12:54.069779810Z,2025-07-17T16:12:54.069614114Z,160,2,1108,A,A,14.420000000,100,0,339112945,130,165696,282210148,ARL
2025-07-17T16:12:54.072881596Z,2025-07-17T16:12:54.072716256Z,160,2,1108,C,A,15.140000000,100,0,339096813,0,165340,282210181,ARL
2025-07-17T16:12:54.072881596Z,2025-07-17T16:12:54.072716256Z,160,2,1108,A,A,14.820000000,100,0,339112981,130,165340,282210181,ARL
2025-07-17T16:12:54.694796063Z,2025-07-17T16:12:54.694630780Z,160,2,1108,A,A,14.270000000,100,0,339126221,130,165283,282224916,ARL
2025-07-17T16:12:54.694809520Z,2025-07-17T16:12:54.694644316Z,160,2,1108,C,A,14.810000000,100,0,339103269,130,165204,282224917,ARL
2025-07-17T16:12:55.255327586Z,2025-07-17T16:12:55.255162003Z,160,2,1108,A,A,14.000000000,100,0,339133353,130,165583,282231441,ARL
2025-07-17T16:12:55.255328269Z,2025-07-17T16:12:55.255163083Z,160,2,1108,C,A,14.530000000,100,0,339100477,130,165186,282231442,ARL
2025-07-17T16:12:58.302183447Z,2025-07-17T16:12:58.302017238Z,160,2,1108,C,A,13.460000000,15,0,339096733,128,166209,282279351,ARL
2025-07-17T16:12:58.420887746Z,2025-07-17T16:12:58.420710579Z,160,2,1108,C,A,13.470000000,100,0,339110853,128,177167,282288716,ARL
2025-07-17T16:12:58.420950587Z,2025-07-17T16:12:58.420776003Z,160,2,1108,A,A,13.470000000,96,0,339201549,128,174584,282288757,ARL
2025-07-17T16:12:58.421338553Z,2025-07-17T16:12:58.421165414Z,160,2,1108,C,A,13.470000000,96,0,339201549,130,173139,282289082,ARL
2025-07-17T16:12:58.421379924Z,2025-07-17T16:12:58.421205027Z,160,2,1108,A,A,15.670000000,100,0,339202065,128,174897,282289111,ARL
2025-07-17T16:12:58.421423275Z,2025-07-17T16:12:58.421248082Z,160,2,1108,C,A,15.360000000,100,0,339112469,128,175193,282289154,ARL
2025-07-17T16:12:58.421756726Z,2025-07-17T16:12:58.421581692Z,160,2,1108,C,A,14.070000000,100,0,339110909,130,175034,282289338,ARL
2025-07-17T16:12:58.422145785Z,2025-07-17T16:12:58.421969675Z,160,2,1108,A,A,14.350000000,100,0,339202733,128,176110,282289650,ARL
2025-07-17T16:12:58.422247877Z,2025-07-17T16:12:58.422073305Z,160,2,1108,C,A,14.520000000,100,0,339110897,0,174572,282289747,ARL
2025-07-17T16:12:58.422247877Z,2025-07-17T16:12:58.422073305Z,160,2,1108,A,A,14.810000000,100,0,339202805,128,174572,282289747,ARL
2025-07-17T16:12:58.424958370Z,2025-07-17T16:12:58.424789366Z,160,2,1108,C,A,14.400000000,100,0,338139585,0,169004,282290622,ARL
2025-07-17T16:12:58.424958370Z,2025-07-17T16:12:58.424789366Z,160,2,1108,A,A,14.570000000,100,0,339203693,128,169004,282290622,ARL
2025-07-17T16:12:58.425450176Z,2025-07-17T16:12:58.425283932Z,160,2,1108,C,A,14.400000000,100,0,338139601,0,166244,282290769,ARL
2025-07-17T16:12:58.425450176Z,2025-07-17T16:12:58.425283932Z,160,2,1108,A,A,14.570000000,100,0,339203897,128,166244,282290769,ARL
2025-07-17T16:12:58.426423622Z,2025-07-17T16:12:58.426258092Z,160,2,1108,C,A,14.260000000,100,0,339111189,130,165530,282290946,ARL
2025-07-17T16:12:58.426544477Z,2025-07-17T16:12:58.426378483Z,160,2,1108,A,A,14.530000000,100,0,339204077,130,165994,282290959,ARL
2025-07-17T16:12:58.430830694Z,2025-07-17T16:12:58.430665639Z,160,2,1108,C,A,13.740000000,100,0,339111029,130,165055,282291933,ARL
2025-07-17T16:12:58.430888526Z,2025-07-17T16:12:58.430720526Z,160,2,1108,A,A,14.010000000,100,0,339205213,128,168000,282291946,ARL
2025-07-17T16:12:58.432901795Z,2025-07-17T16:12:58.432736189Z,160,2,1108,C,A,14.820000000,100,0,339111005,0,165606,282292390,ARL
2025-07-17T16:12:58.432901795Z,2025-07-17T16:12:58.432736189Z,160,2,1108,A,A,15.380000000,100,0,339206141,130,165606,282292390,ARL
2025-07-17T16:12:58.438073339Z,2025-07-17T16:12:58.437907652Z,160,2,1108,C,B,12.920000000,2,0,338044113,0,165687,282292938,ARL
2025-07-17T16:12:58.438073339Z,2025-07-17T16:12:58.437907652Z,160,2,1108,A,B,13.020000000,2,0,339207125,130,165687,282292938,ARL
2025-07-17T16:12:58.438076762Z,2025-07-17T16:12:58.437911392Z,160,2,1108,C,A,13.730000000,2,0,339110993,0,165370,282292939,ARL
2025-07-17T16:12:58.438076762Z,2025-07-17T16:12:58.437911392Z,160,2,1108,A,A,13.980000000,2,0,339207129,130,165370,282292939,ARL
2025-07-17T16:12:58.438843944Z,2025-07-17T16:12:58.438678961Z,160,2,1108,C,A,14.010000000,100,0,339205213,130,164983,282293023,ARL
2025-07-17T16:12:58.438894336Z,2025-07-17T16:12:58.438728994Z,160,2,1108,A,A,14.240000000,100,0,339207197,130,165342,282293026,ARL
2025-07-17T16:12:58.441834497Z,2025-07-17T16:12:58.441669159Z,160,2,1108,C,A,14.420000000,100,0,339110981,0,165338,282293191,ARL
2025-07-17T16:12:58.441834497Z,2025-07-17T16:12:58.441669159Z,160,2,1108,A,A,14.960000000,100,0,339207505,130,165338,282293191,ARL
2025-07-17T16:12:58.454376675Z,2025-07-17T16:12:58.454211242Z,160,2,1108,C,A,17.110000000,100,0,339111097,0,165433,282293811,ARL
2025-07-17T16:12:58.454376675Z,2025-07-17T16:12:58.454211242Z,160,2,1108,A,A,17.760000000,100,0,339208377,130,165433,282293811,ARL
2025-07-17T16:12:58.472292476Z,2025-07-17T16:12:58.472126777Z,160,2,1108,C,A,15.500000000,100,0,339111149,0,165699,282294411,ARL
2025-07-17T16:12:58.472292476Z,2025-07-17T16:12:58.472126777Z,160,2,1108,A,A,16.080000000,100,0,339209241,130,165699,282294411,ARL
2025-07-17T16:12:58.472624779Z,2025-07-17T16:12:58.472458830Z,160,2,1108,C,A,14.810000000,100,0,339202805,0,165949,282294423,ARL
2025-07-17T16:12:58.472624779Z,2025-07-17T16:12:58.472458830Z,160,2,1108,A,A,15.040000000,100,0,339209257,130,165949,282294423,ARL
2025-07-17T16:12:58.571845708Z,2025-07-17T16:12:58.571679985Z,160,2,1108,C,A,14.820000000,100,0,339112981,0,165723,282298942,ARL
2025-07-17T16:12:58.571845708Z,2025-07-17T16:12:58.571679985Z,160,2,1108,A,A,15.380000000,100,0,339215205,130,165723,282298942,ARL
2025-07-17T16:12:58.619404102Z,2025-07-17T16:12:58.619238614Z,160,2,1108,C,A,14.420000000,100,0,339112945,0,165488,282299781,ARL
2025-07-17T16:12:58.619404102Z,2025-07-17T16:12:58.619238614Z,160,2,1108,A,A,14.960000000,100,0,339216161,130,165488,282299781,ARL
2025-07-17T16:12:58.986093948Z,2025-07-17T16:12:58.985928594Z,160,2,1108,C,B,13.020000000,2,0,339207125,0,165354,282305386,ARL
2025-07-17T16:12:58.986093948Z,2025-07-17T16:12:58.985928594Z,160,2,1108,A,B,12.860000000,2,0,339222617,130,165354,282305386,ARL
2025-07-17T16:12:59.063108412Z,2025-07-17T16:12:59.062943193Z,160,2,1108,A,A,13.990000000,100,0,339224109,130,165219,282306400,ARL
2025-07-17T16:12:59.082855570Z,2025-07-17T16:12:59.082690430Z,160,2,1108,C,A,14.000000000,100,0,339133353,130,165140,282307908,ARL
2025-07-17T16:12:59.082856640Z,2025-07-17T16:12:59.082691385Z,160,2,1108,A,A,14.530000000,100,0,339225769,130,165255,282307909,ARL
2025-07-17T16:12:59.088794570Z,2025-07-17T16:12:59.088629294Z,160,2,1108,A,A,14.810000000,100,0,339225885,130,165276,282308093,ARL
2025-07-17T16:12:59.088808117Z,2025-07-17T16:12:59.088642718Z,160,2,1108,C,A,14.270000000,100,0,339126221,130,165399,282308094,ARL
2025-07-17T16:12:59.092927842Z,2025-07-17T16:12:59.092762564Z,160,2,1108,C,A,14.350000000,100,0,339202733,130,165278,282308154,ARL
2025-07-17T16:12:59.093278915Z,2025-07-17T16:12:59.093113488Z,160,2,1108,A,A,14.600000000,100,0,339226021,130,165427,282308163,ARL
2025-07-17T16:12:59.430486012Z,2025-07-17T16:12:59.430320610Z,160,2,1108,C,A,14.530000000,100,0,339204077,0,165402,282313368,ARL
2025-07-17T16:12:59.430486012Z,2025-07-17T16:12:59.430320610Z,160,2,1108,A,A,14.770000000,100,0,339232213,130,165402,282313368,ARL
2025-07-17T16:13:04.825902166Z,2025-07-17T16:13:04.825736034Z,160,2,1108,A,A,13.660000000,15,0,339332865,128,166132,282392593,ARL
2025-07-17T16:13:06.189275812Z,2025-07-17T16:13:06.189110140Z,160,2,1108,C,B,12.860000000,2,0,339222617,0,165672,282411935,ARL
2025-07-17T16:13:06.189275812Z,2025-07-17T16:13:06.189110140Z,160,2,1108,A,B,12.960000000,2,0,339356397,130,165672,282411935,ARL
2025-07-17T16:13:06.224898389Z,2025-07-17T16:13:06.224732787Z,160,2,1108,C,A,13.990000000,100,0,339224109,0,165602,282413599,ARL
2025-07-17T16:13:06.224898389Z,2025-07-17T16:13:06.224732787Z,160,2,1108,A,A,13.670000000,100,0,339358233,130,165602,282413599,ARL
2025-07-17T16:13:06.225642781Z,2025-07-17T16:13:06.225475518Z,160,2,1108,C,A,15.040000000,100,0,339209257,0,167263,282413677,ARL
2025-07-17T16:13:06.225642781Z,2025-07-17T16:13:06.225475518Z,160,2,1108,A,A,14.730000000,100,0,339358293,0,167263,282413677,ARL
2025-07-17T16:13:06.225642781Z,2025-07-17T16:13:06.225475906Z,160,2,1108,C,A,14.600000000,100,0,339226021,128,166875,282413678,ARL
2025-07-17T16:13:06.225995297Z,2025-07-17T16:13:06.225829921Z,160,2,1108,A,A,14.280000000,100,0,339358333,130,165376,282413699,ARL
2025-07-17T16:13:06.226789913Z,2025-07-17T16:13:06.226624084Z,160,2,1108,C,A,15.380000000,100,0,339206141,0,165829,282413738,ARL
2025-07-17T16:13:06.226789913Z,2025-07-17T16:13:06.226624084Z,160,2,1108,A,A,15.040000000,100,0,339358349,130,165829,282413738,ARL
2025-07-17T16:13:06.226882302Z,2025-07-17T16:13:06.226716697Z,160,2,1108,C,A,14.960000000,100,0,339207505,0,165605,282413745,ARL
2025-07-17T16:13:06.226882302Z,2025-07-17T16:13:06.226716697Z,160,2,1108,A,A,14.630000000,100,0,339358353,130,165605,282413745,ARL
2025-07-17T16:13:06.229858538Z,2025-07-17T16:13:06.229693020Z,160,2,1108,C,A,13.980000000,2,0,339207129,0,165518,282413801,ARL
2025-07-17T16:13:06.229858538Z,2025-07-17T16:13:06.229693020Z,160,2,1108,A,A,13.810000000,2,0,339358409,130,165518,282413801,ARL
2025-07-17T16:13:06.235594115Z,2025-07-17T16:13:06.235428434Z,160,2,1108,C,A,17.760000000,100,0,339208377,0,165681,282414050,ARL
2025-07-17T16:13:06.235594115Z,2025-07-17T16:13:06.235428434Z,160,2,1108,A,A,17.370000000,100,0,339358609,130,165681,282414050,ARL
2025-07-17T16:13:06.236567790Z,2025-07-17T16:13:06.236401579Z,160,2,1108,C,A,14.240000000,100,0,339207197,130,166211,282414131,ARL
2025-07-17T16:13:06.236621535Z,2025-07-17T16:13:06.236456489Z,160,2,1108,A,A,13.940000000,100,0,339358741,130,165046,282414141,ARL
2025-07-17T16:13:06.243909112Z,2025-07-17T16:13:06.243743642Z,160,2,1108,C,A,16.080000000,100,0,339209241,0,165470,282414340,ARL
2025-07-17T16:13:06.243909112Z,2025-07-17T16:13:06.243743642Z,160,2,1108,A,A,15.730000000,100,0,339359077,130,165470,282414340,ARL
2025-07-17T16:13:06.268052093Z,2025-07-17T16:13:06.267886189Z,160,2,1108,C,A,15.380000000,100,0,339215205,0,165904,282414570,ARL
2025-07-17T16:13:06.268052093Z,2025-07-17T16:13:06.267886189Z,160,2,1108,A,A,15.040000000,100,0,339359357,130,165904,282414570,ARL
2025-07-17T16:13:06.275886461Z,2025-07-17T16:13:06.275720866Z,160,2,1108,C,A,14.960000000,100,0,339216161,0,165595,282414642,ARL
2025-07-17T16:13:06.275886461Z,2025-07-17T16:13:06.275720866Z,160,2,1108,A,A,14.630000000,100,0,339359401,130,165595,282414642,ARL
2025-07-17T16:13:06.277048260Z,2025-07-17T16:13:06.276882863Z,160,2,1108,C,A,14.770000000,100,0,339232213,130,165397,282414659,ARL
2025-07-17T16:13:06.277178914Z,2025-07-17T16:13:06.277013512Z,160,2,1108,A,A,14.460000000,100,0,339359421,130,165402,282414660,ARL
2025-07-17T16:13:06.622659102Z,2025-07-17T16:13:06.622493734Z,160,2,1108,A,A,14.220000000,100,0,339365193,130,165368,282418746,ARL
2025-07-17T16:13:06.663836744Z,2025-07-17T16:13:06.663671305Z,160,2,1108,C,A,14.530000000,100,0,339225769,130,165439,282418921,ARL
2025-07-17T16:13:06.759791103Z,2025-07-17T16:13:06.759625628Z,160,2,1108,A,A,14.490000000,100,0,339366385,130,165475,282419471,ARL
2025-07-17T16:13:06.759804641Z,2025-07-17T16:13:06.759638890Z,160,2,1108,C,A,14.810000000,100,0,339225885,130,165751,282419472,ARL
2025-07-17T16:13:09.354048740Z,2025-07-17T16:13:09.353883614Z,160,2,1108,A,A,13.640000000,15,0,339425837,130,165126,282469242,ARL
2025-07-17T16:13:09.368197659Z,2025-07-17T16:13:09.368030843Z,160,2,1108,C,A,13.670000000,100,0,339358233,0,166816,282470466,ARL
2025-07-17T16:13:09.368197659Z,2025-07-17T16:13:09.368030843Z,160,2,1108,A,A,13.650000000,100,0,339427217,128,166816,282470466,ARL
2025-07-17T16:13:14.046267875Z,2025-07-17T16:13:14.046102556Z,160,2,1108,C,A,13.660000000,15,0,339332865,130,165319,282563502,ARL
2025-07-17T16:13:17.775210916Z,2025-07-17T16:13:17.775045316Z,160,2,1108,A,A,13.570000000,15,0,339610637,130,165600,282616566,ARL
2025-07-17T16:13:19.781143691Z,2025-07-17T16:13:19.780978185Z,160,2,1108,C,A,13.650000000,100,0,339427217,0,165506,282644181,ARL
2025-07-17T16:13:19.781143691Z,2025-07-17T16:13:19.780978185Z,160,2,1108,A,A,13.580000000,100,0,339641813,130,165506,282644181,ARL
2025-07-17T16:13:19.781889805Z,2025-07-17T16:13:19.781723964Z,160,2,1108,C,A,14.730000000,100,0,339358293,0,165841,282644189,ARL
2025-07-17T16:13:19.781889805Z,2025-07-17T16:13:19.781723964Z,160,2,1108,A,A,14.630000000,100,0,339641865,130,165841,282644189,ARL
2025-07-17T16:13:19.789771458Z,2025-07-17T16:13:19.789606057Z,160,2,1108,C,A,13.940000000,100,0,339358741,130,165401,282644321,ARL
2025-07-17T16:13:19.789822010Z,2025-07-17T16:13:19.789656689Z,160,2,1108,A,A,13.850000000,100,0,339642033,130,165321,282644322,ARL
2025-07-17T16:13:19.863618706Z,2025-07-17T16:13:19.863452537Z,160,2,1108,C,A,13.570000000,15,0,339610637,130,166169,282645966,ARL
2025-07-17T16:13:19.863790083Z,2025-07-17T16:13:19.863624798Z,160,2,1108,C,A,13.640000000,15,0,339425837,130,165285,282646001,ARL
2025-07-17T16:13:19.863968792Z,2025-07-17T16:13:19.863803503Z,160,2,1108,A,A,13.580000000,96,0,339643285,130,165289,282646014,ARL
2025-07-17T16:13:24.182625011Z,2025-07-17T16:13:24.182459676Z,160,2,1108,A,A,13.570000000,15,0,339710089,130,165335,282694909,ARL
2025-07-17T16:13:24.182918202Z,2025-07-17T16:13:24.182753004Z,160,2,1108,C,A,13.580000000,96,0,339643285,130,165198,282694924,ARL
2025-07-17T16:13:24.627374514Z,2025-07-17T16:13:24.627209125Z,160,2,1108,A,A,14.260000000,700,0,339716321,130,165389,282700118,ARL
2025-07-17T16:13:24.627430447Z,2025-07-17T16:13:24.627265040Z,160,2,1108,C,A,14.680000000,700,0,339096897,130,165407,282700120,ARL
2025-07-17T16:13:25.962717944Z,2025-07-17T16:13:25.962552288Z,160,2,1108,C,A,14.570000000,100,0,339203693,0,165656,282719507,ARL
2025-07-17T16:13:25.962717944Z,2025-07-17T16:13:25.962552288Z,160,2,1108,A,A,14.460000000,100,0,339739285,130,165656,282719507,ARL
2025-07-17T16:13:25.963209328Z,2025-07-17T16:13:25.963043858Z,160,2,1108,C,A,14.570000000,100,0,339203897,0,165470,282719515,ARL
2025-07-17T16:13:25.963209328Z,2025-07-17T16:13:25.963043858Z,160,2,1108,A,A,14.460000000,100,0,339739297,130,165470,282719515,ARL
2025-07-17T16:13:34.825229037Z,2025-07-17T16:13:34.825063658Z,160,2,1108,A,A,13.550000000,15,0,339897885,130,165379,282849136,ARL
2025-07-17T16:13:36.525450545Z,2025-07-17T16:13:36.525285006Z,160,2,1108,C,A,13.580000000,100,0,339641813,0,165539,282880671,ARL
2025-07-17T16:13:36.525450545Z,2025-07-17T16:13:36.525285006Z,160,2,1108,A,A,13.560000000,100,0,339937253,130,165539,282880671,ARL
2025-07-17T16:13:36.528326337Z,2025-07-17T16:13:36.528160728Z,160,2,1108,C,A,17.370000000,100,0,339358609,0,165609,282880690,ARL
2025-07-17T16:13:36.528326337Z,2025-07-17T16:13:36.528160728Z,160,2,1108,A,A,17.230000000,100,0,339937293,130,165609,282880690,ARL
2025-07-17T16:13:40.166698198Z,2025-07-17T16:13:40.166532673Z,160,2,1108,C,A,13.570000000,15,0,339710089,130,165525,282934517,ARL
2025-07-17T16:13:41.168681977Z,2025-07-17T16:13:41.168516592Z,160,2,1108,A,A,13.530000000,15,0,340027925,130,165385,282947373,ARL
2025-07-17T16:13:41.810648775Z,2025-07-17T16:13:41.810482971Z,160,2,1108,C,A,13.560000000,100,0,339937253,0,165804,282959674,ARL
2025-07-17T16:13:41.810648775Z,2025-07-17T16:13:41.810482971Z,160,2,1108,A,A,13.540000000,100,0,340046965,130,165804,282959674,ARL
2025-07-17T16:13:41.811397213Z,2025-07-17T16:13:41.811231743Z,160,2,1108,C,A,14.630000000,100,0,339641865,0,165470,282959705,ARL
2025-07-17T16:13:41.811397213Z,2025-07-17T16:13:41.811231743Z,160,2,1108,A,A,14.590000000,100,0,340047001,130,165470,282959705,ARL
2025-07-17T16:13:41.846549822Z,2025-07-17T16:13:41.846384162Z,160,2,1108,C,A,15.730000000,100,0,339359077,0,165660,282960440,ARL
2025-07-17T16:13:41.846549822Z,2025-07-17T16:13:41.846384162Z,160,2,1108,A,A,15.580000000,100,0,340047805,130,165660,282960440,ARL
2025-07-17T16:13:53.138391930Z,2025-07-17T16:13:53.138226660Z,160,2,1108,C,A,13.530000000,15,0,340027925,130,165270,283090735,ARL
2025-07-17T16:13:53.784302227Z,2025-07-17T16:13:53.784124590Z,160,2,1108,C,A,13.550000000,15,0,339897885,128,177637,283098338,ARL
2025-07-17T16:14:06.190866982Z,2025-07-17T16:14:06.190701389Z,160,2,1108,C,A,13.810000000,2,0,339358409,0,165593,283262191,ARL
2025-07-17T16:14:06.190866982Z,2025-07-17T16:14:06.190701389Z,160,2,1108,A,A,13.740000000,2,0,340449865,130,165593,283262191,ARL
2025-07-17T16:14:10.827419207Z,2025-07-17T16:14:10.827253317Z,160,2,1108,A,A,13.510000000,15,0,340526285,130,165890,283315922,ARL
2025-07-17T16:14:10.876894854Z,2025-07-17T16:14:10.876729278Z,160,2,1108,C,A,13.540000000,100,0,340046965,0,165576,283317356,ARL
2025-07-17T16:14:10.876894854Z,2025-07-17T16:14:10.876729278Z,160,2,1108,A,A,13.520000000,100,0,340527921,130,165576,283317356,ARL
2025-07-17T16:14:10.878601199Z,2025-07-17T16:14:10.878435316Z,160,2,1108,C,A,14.630000000,100,0,339358353,0,165883,283317367,ARL
2025-07-17T16:14:10.878601199Z,2025-07-17T16:14:10.878435316Z,160,2,1108,A,A,14.470000000,100,0,340527969,130,165883,283317367,ARL
2025-07-17T16:14:10.892679514Z,2025-07-17T16:14:10.892513823Z,160,2,1108,C,A,14.630000000,100,0,339359401,0,165691,283317451,ARL
2025-07-17T16:14:10.892679514Z,2025-07-17T16:14:10.892513823Z,160,2,1108,A,A,14.470000000,100,0,340528121,130,165691,283317451,ARL
2025-07-17T16:14:10.985507716Z,2025-07-17T16:14:10.985342000Z,160,2,1108,C,A,14.460000000,100,0,339359421,0,165716,283318181,ARL
2025-07-17T16:14:10.985507716Z,2025-07-17T16:14:10.985342000Z,160,2,1108,A,A,14.310000000,100,0,340529021,130,165716,283318181,ARL
2025-07-17T16:14:19.528488233Z,2025-07-17T16:14:19.528322793Z,160,2,1108,A,A,13.490000000,15,0,340664453,130,165440,283419160,ARL
2025-07-17T16:14:21.306764970Z,2025-07-17T16:14:21.306599291Z,160,2,1108,C,A,13.520000000,100,0,340527921,0,165679,283454179,ARL
2025-07-17T16:14:21.306764970Z,2025-07-17T16:14:21.306599291Z,160,2,1108,A,A,13.500000000,100,0,340704401,130,165679,283454179,ARL
2025-07-17T16:14:21.307512009Z,2025-07-17T16:14:21.307346403Z,160,2,1108,C,A,14.590000000,100,0,340047001,0,165606,283454259,ARL
2025-07-17T16:14:21.307512009Z,2025-07-17T16:14:21.307346403Z,160,2,1108,A,A,14.550000000,100,0,340704465,130,165606,283454259,ARL
2025-07-17T16:14:21.317261991Z,2025-07-17T16:14:21.317096752Z,160,2,1108,C,A,13.850000000,100,0,339642033,130,165239,283454878,ARL
2025-07-17T16:14:21.317314136Z,2025-07-17T16:14:21.317148983Z,160,2,1108,A,A,13.770000000,100,0,340705133,130,165153,283454882,ARL
2025-07-17T16:14:21.343294261Z,2025-07-17T16:14:21.343129166Z,160,2,1108,A,A,15.390000000,100,0,340706373,130,165095,283455758,ARL
2025-07-17T16:14:21.343307836Z,2025-07-17T16:14:21.343142096Z,160,2,1108,C,A,15.670000000,100,0,339202065,130,165740,283455759,ARL
2025-07-17T16:14:36.523553349Z,2025-07-17T16:14:36.523382949Z,160,2,1108,C,A,13.490000000,15,0,340664453,128,170400,283655411,ARL
2025-07-17T16:14:36.523730500Z,2025-07-17T16:14:36.523564373Z,160,2,1108,C,A,13.510000000,15,0,340526285,128,166127,283655455,ARL
2025-07-17T16:14:36.523862340Z,2025-07-17T16:14:36.523696080Z,160,2,1108,A,A,13.500000000,99,0,340971661,128,166260,283655477,ARL
2025-07-17T16:14:52.280593678Z,2025-07-17T16:14:52.280428336Z,160,2,1108,C,A,13.500000000,99,0,340971661,130,165342,283870929,ARL
2025-07-17T16:14:52.297037125Z,2025-07-17T16:14:52.296871817Z,160,2,1108,A,A,13.480000000,15,0,341248825,130,165308,283871393,ARL
2025-07-17T16:14:52.828721867Z,2025-07-17T16:14:52.828556785Z,160,2,1108,C,A,13.480000000,15,0,341248825,130,165082,283875146,ARL
2025-07-17T16:14:52.829033713Z,2025-07-17T16:14:52.828868258Z,160,2,1108,A,A,13.500000000,99,0,341253573,130,165455,283875150,ARL
2025-07-17T16:15:16.987369971Z,2025-07-17T16:15:16.987204735Z,160,2,1108,C,A,13.500000000,99,0,341253573,130,165236,284194889,ARL
2025-07-17T16:15:16.987414675Z,2025-07-17T16:15:16.987249289Z,160,2,1108,C,A,13.500000000,100,0,340704401,130,165386,284194891,ARL
2025-07-17T16:15:16.987689493Z,2025-07-17T16:15:16.987524101Z,160,2,1108,C,A,14.260000000,700,0,339716321,130,165392,284194901,ARL
2025-07-17T16:15:16.987744468Z,2025-07-17T16:15:16.987579177Z,160,2,1108,A,A,14.460000000,700,0,341661841,130,165291,284194908,ARL
2025-07-17T16:15:16.987772549Z,2025-07-17T16:15:16.987607468Z,160,2,1108,A,A,15.700000000,100,0,341661849,130,165081,284194910,ARL
2025-07-17T16:15:16.987786087Z,2025-07-17T16:15:16.987620573Z,160,2,1108,C,A,15.390000000,100,0,340706373,130,165514,284194911,ARL
2025-07-17T16:15:16.988145770Z,2025-07-17T16:15:16.987980299Z,160,2,1108,C,A,14.550000000,100,0,340704465,0,165471,284194935,ARL
2025-07-17T16:15:16.988145770Z,2025-07-17T16:15:16.987980299Z,160,2,1108,A,A,14.600000000,100,0,341661869,130,165471,284194935,ARL
2025-07-17T16:15:16.988410269Z,2025-07-17T16:15:16.988244795Z,160,2,1108,C,A,14.470000000,100,0,340527969,0,165474,284194952,ARL
2025-07-17T16:15:16.988410269Z,2025-07-17T16:15:16.988244795Z,160,2,1108,A,A,14.740000000,100,0,341661877,130,165474,284194952,ARL
2025-07-17T16:15:16.989313102Z,2025-07-17T16:15:16.989147294Z,160,2,1108,C,A,15.580000000,100,0,340047805,0,165808,284195117,ARL
2025-07-17T16:15:16.989313102Z,2025-07-17T16:15:16.989147294Z,160,2,1108,A,A,15.840000000,100,0,341661893,130,165808,284195117,ARL
2025-07-17T16:15:16.989763697Z,2025-07-17T16:15:16.989598095Z,160,2,1108,C,A,17.230000000,100,0,339937293,0,165602,284195176,ARL
2025-07-17T16:15:16.989763697Z,2025-07-17T16:15:16.989598095Z,160,2,1108,A,A,17.490000000,100,0,341661901,130,165602,284195176,ARL
2025-07-17T16:15:16.989886697Z,2025-07-17T16:15:16.989720957Z,160,2,1108,C,A,14.470000000,100,0,340528121,0,165740,284195185,ARL
2025-07-17T16:15:16.989886697Z,2025-07-17T16:15:16.989720957Z,160,2,1108,A,A,14.740000000,100,0,341661905,130,165740,284195185,ARL
2025-07-17T16:15:16.992804347Z,2025-07-17T16:15:16.992638952Z,160,2,1108,C,A,14.310000000,100,0,340529021,130,165395,284195309,ARL
2025-07-17T16:15:16.992941967Z,2025-07-17T16:15:16.992776612Z,160,2,1108,A,A,14.560000000,100,0,341661985,130,165355,284195310,ARL
2025-07-17T16:15:17.000588174Z,2025-07-17T16:15:17.000422944Z,160,2,1108,C,A,13.770000000,100,0,340705133,130,165230,284195454,ARL
2025-07-17T16:15:17.000621056Z,2025-07-17T16:15:17.000456046Z,160,2,1108,C,A,14.460000000,700,0,341661841,130,165010,284195456,ARL
2025-07-17T16:15:17.000640033Z,2025-07-17T16:15:17.000474862Z,160,2,1108,A,A,14.050000000,100,0,341662085,130,165171,284195458,ARL
2025-07-17T16:15:17.001323406Z,2025-07-17T16:15:17.001158038Z,160,2,1108,C,A,14.280000000,100,0,339358333,130,165368,284195476,ARL
2025-07-17T16:15:17.001687312Z,2025-07-17T16:15:17.001522171Z,160,2,1108,A,A,14.600000000,100,0,341662113,130,165141,284195477,ARL
2025-07-17T16:15:17.002229963Z,2025-07-17T16:15:17.002064284Z,160,2,1108,C,A,14.740000000,100,0,341661905,0,165679,284195479,ARL
2025-07-17T16:15:17.002229963Z,2025-07-17T16:15:17.002064284Z,160,2,1108,A,A,14.960000000,100,0,341662117,130,165679,284195479,ARL
2025-07-17T16:15:17.002790290Z,2025-07-17T16:15:17.002625119Z,160,2,1108,C,A,17.490000000,100,0,341661901,0,165171,284195482,ARL
2025-07-17T16:15:17.002790290Z,2025-07-17T16:15:17.002625119Z,160,2,1108,A,A,17.760000000,100,0,341662125,130,165171,284195482,ARL
2025-07-17T16:15:17.003246802Z,2025-07-17T16:15:17.003081581Z,160,2,1108,C,A,14.740000000,100,0,341661877,0,165221,284195486,ARL
2025-07-17T16:15:17.003246802Z,2025-07-17T16:15:17.003081581Z,160,2,1108,A,A,14.960000000,100,0,341662133,130,165221,284195486,ARL
2025-07-17T16:15:17.003381863Z,2025-07-17T16:15:17.003216492Z,160,2,1108,C,A,15.840000000,100,0,341661893,0,165371,284195487,ARL
2025-07-17T16:15:17.003381863Z,2025-07-17T16:15:17.003216492Z,160,2,1108,A,A,16.080000000,100,0,341662137,130,165371,284195487,ARL
2025-07-17T16:15:17.003874553Z,2025-07-17T16:15:17.003708485Z,160,2,1108,C,A,15.040000000,100,0,339358349,0,166068,284195498,ARL
2025-07-17T16:15:17.003874553Z,2025-07-17T16:15:17.003708485Z,160,2,1108,A,A,15.380000000,100,0,341662145,130,166068,284195498,ARL
2025-07-17T16:15:17.003883470Z,2025-07-17T16:15:17.003717832Z,160,2,1108,C,A,15.040000000,100,0,339359357,0,165638,284195499,ARL
2025-07-17T16:15:17.003883470Z,2025-07-17T16:15:17.003717832Z,160,2,1108,A,A,15.380000000,100,0,341662149,130,165638,284195499,ARL
2025-07-17T16:15:17.019567564Z,2025-07-17T16:15:17.019402521Z,160,2,1108,C,A,14.050000000,100,0,341662085,130,165043,284195602,ARL
2025-07-17T16:15:17.019617602Z,2025-07-17T16:15:17.019452245Z,160,2,1108,A,A,14.260000000,100,0,341662313,130,165357,284195603,ARL
2025-07-17T16:15:17.037261626Z,2025-07-17T16:15:17.037096157Z,160,2,1108,C,A,14.600000000,100,0,341661869,0,165469,284195665,ARL
2025-07-17T16:15:17.037261626Z,2025-07-17T16:15:17.037096157Z,160,2,1108,A,A,15.060000000,100,0,341662429,130,165469,284195665,ARL
2025-07-17T16:15:17.049066370Z,2025-07-17T16:15:17.048901142Z,160,2,1108,A,A,13.750000000,100,0,341663101,130,165228,284196195,ARL
2025-07-17T16:15:17.049108554Z,2025-07-17T16:15:17.048943087Z,160,2,1108,A,A,14.680000000,700,0,341663105,130,165467,284196196,ARL
2025-07-17T16:15:17.050812161Z,2025-07-17T16:15:17.050646751Z,160,2,1108,C,A,14.960000000,100,0,341662133,0,165410,284196235,ARL
2025-07-17T16:15:17.050812161Z,2025-07-17T16:15:17.050646751Z,160,2,1108,A,A,14.720000000,100,0,341663261,130,165410,284196235,ARL
2025-07-17T16:15:17.051644859Z,2025-07-17T16:15:17.051479522Z,160,2,1108,C,A,17.760000000,100,0,341662125,0,165337,284196242,ARL
2025-07-17T16:15:17.051644859Z,2025-07-17T16:15:17.051479522Z,160,2,1108,A,A,17.470000000,100,0,341663289,130,165337,284196242,ARL
2025-07-17T16:15:17.054159307Z,2025-07-17T16:15:17.053993491Z,160,2,1108,C,A,16.080000000,100,0,341662137,0,165816,284196273,ARL
2025-07-17T16:15:17.054159307Z,2025-07-17T16:15:17.053993491Z,160,2,1108,A,A,15.820000000,100,0,341663317,130,165816,284196273,ARL
2025-07-17T16:15:17.059504149Z,2025-07-17T16:15:17.059338704Z,160,2,1108,C,A,14.260000000,100,0,341662313,130,165445,284196314,ARL
2025-07-17T16:15:17.059552653Z,2025-07-17T16:15:17.059387360Z,160,2,1108,A,A,14.030000000,100,0,341663401,130,165293,284196315,ARL
2025-07-17T16:15:17.084101480Z,2025-07-17T16:15:17.083936164Z,160,2,1108,C,A,14.960000000,100,0,341662117,0,165316,284196410,ARL
2025-07-17T16:15:17.084101480Z,2025-07-17T16:15:17.083936164Z,160,2,1108,A,A,14.720000000,100,0,341663737,130,165316,284196410,ARL
2025-07-17T16:15:17.087853488Z,2025-07-17T16:15:17.087688271Z,160,2,1108,C,A,15.060000000,100,0,341662429,0,165217,284196429,ARL
2025-07-17T16:15:17.087853488Z,2025-07-17T16:15:17.087688271Z,160,2,1108,A,A,14.820000000,100,0,341663749,130,165217,284196429,ARL
2025-07-17T16:15:17.643818240Z,2025-07-17T16:15:17.643653020Z,160,2,1108,C,A,14.600000000,100,0,341662113,130,165220,284202090,ARL
2025-07-17T16:15:17.644168944Z,2025-07-17T16:15:17.644003726Z,160,2,1108,A,A,14.360000000,100,0,341671053,130,165218,284202091,ARL
2025-07-17T16:15:35.998576859Z,2025-07-17T16:15:35.998410310Z,160,2,1108,T,N,13.280000000,26,0,0,130,166549,284480470,ARL
2025-07-17T16:15:35.999140348Z,2025-07-17T16:15:35.998974923Z,160,2,1108,C,B,12.360000000,100,0,336572057,0,165425,284480502,ARL
2025-07-17T16:15:35.999140348Z,2025-07-17T16:15:35.998974923Z,160,2,1108,A,B,12.220000000,100,0,342029561,130,165425,284480502,ARL
2025-07-17T16:15:35.999762137Z,2025-07-17T16:15:35.999596382Z,160,2,1108,C,B,12.360000000,100,0,336572069,0,165755,284480519,ARL
2025-07-17T16:15:35.999762137Z,2025-07-17T16:15:35.999596382Z,160,2,1108,A,B,12.220000000,100,0,342029581,130,165755,284480519,ARL
2025-07-17T16:16:30.787448429Z,2025-07-17T16:16:30.787282866Z,160,2,1108,C,B,12.960000000,2,0,339356397,0,165563,285308466,ARL
2025-07-17T16:16:30.787448429Z,2025-07-17T16:16:30.787282866Z,160,2,1108,A,B,13.030000000,2,0,343084165,130,165563,285308466,ARL
2025-07-17T16:17:22.832948558Z,2025-07-17T16:17:22.832783132Z,160,2,1108,A,A,13.470000000,15,0,344211173,130,165426,286207282,ARL
2025-07-17T16:17:23.620456421Z,2025-07-17T16:17:23.620290881Z,160,2,1108,C,A,13.750000000,100,0,341663101,0,165540,286219821,ARL
2025-07-17T16:17:23.620456421Z,2025-07-17T16:17:23.620290881Z,160,2,1108,A,A,13.480000000,100,0,344225341,130,165540,286219821,ARL
2025-07-17T16:17:23.621199578Z,2025-07-17T16:17:23.621034171Z,160,2,1108,C,A,14.360000000,100,0,341671053,130,165407,286219868,ARL
2025-07-17T16:17:23.621205573Z,2025-07-17T16:17:23.621040069Z,160,2,1108,C,A,14.820000000,100,0,341663749,0,165504,286219869,ARL
2025-07-17T16:17:23.621205573Z,2025-07-17T16:17:23.621040069Z,160,2,1108,A,A,14.530000000,100,0,344225385,130,165504,286219869,ARL
2025-07-17T16:17:23.621387062Z,2025-07-17T16:17:23.621221535Z,160,2,1108,C,A,15.820000000,100,0,341663317,0,165527,286219879,ARL
2025-07-17T16:17:23.621387062Z,2025-07-17T16:17:23.621221535Z,160,2,1108,A,A,15.510000000,100,0,344225393,130,165527,286219879,ARL
2025-07-17T16:17:23.621555609Z,2025-07-17T16:17:23.621389325Z,160,2,1108,A,A,14.080000000,100,0,344225397,130,166284,286219881,ARL
2025-07-17T16:17:23.621978089Z,2025-07-17T16:17:23.621812403Z,160,2,1108,C,A,15.380000000,100,0,341662145,0,165686,286219887,ARL
2025-07-17T16:17:23.621978089Z,2025-07-17T16:17:23.621812403Z,160,2,1108,A,A,14.830000000,100,0,344225405,130,165686,286219887,ARL
2025-07-17T16:17:23.622834183Z,2025-07-17T16:17:23.622668656Z,160,2,1108,C,A,14.720000000,100,0,341663261,0,165527,286219894,ARL
2025-07-17T16:17:23.622834183Z,2025-07-17T16:17:23.622668656Z,160,2,1108,A,A,14.430000000,100,0,344225449,130,165527,286219894,ARL
2025-07-17T16:17:23.623011421Z,2025-07-17T16:17:23.622845856Z,160,2,1108,C,A,14.560000000,100,0,341661985,0,165565,286219895,ARL
2025-07-17T16:17:23.623011421Z,2025-07-17T16:17:23.622845856Z,160,2,1108,A,A,14.270000000,100,0,344225453,130,165565,286219895,ARL
2025-07-17T16:17:23.623052802Z,2025-07-17T16:17:23.622887237Z,160,2,1108,C,A,17.470000000,100,0,341663289,0,165565,286219896,ARL
2025-07-17T16:17:23.623052802Z,2025-07-17T16:17:23.622887237Z,160,2,1108,A,A,17.120000000,100,0,344225457,130,165565,286219896,ARL
2025-07-17T16:17:23.624578699Z,2025-07-17T16:17:23.624413295Z,160,2,1108,C,A,15.380000000,100,0,341662149,0,165404,286219909,ARL
2025-07-17T16:17:23.624578699Z,2025-07-17T16:17:23.624413295Z,160,2,1108,A,A,14.830000000,100,0,344225485,130,165404,286219909,ARL
2025-07-17T16:17:23.624638111Z,2025-07-17T16:17:23.624472504Z,160,2,1108,C,A,14.720000000,100,0,341663737,0,165607,286219911,ARL
2025-07-17T16:17:23.624638111Z,2025-07-17T16:17:23.624472504Z,160,2,1108,A,A,14.430000000,100,0,344225489,130,165607,286219911,ARL
2025-07-17T16:17:23.627653611Z,2025-07-17T16:17:23.627488304Z,160,2,1108,C,A,14.030000000,100,0,341663401,130,165307,286219940,ARL
2025-07-17T16:17:23.627704598Z,2025-07-17T16:17:23.627539425Z,160,2,1108,A,A,13.750000000,100,0,344225533,130,165173,286219941,ARL
2025-07-17T16:17:23.653807815Z,2025-07-17T16:17:23.653641816Z,160,2,1108,A,A,15.370000000,100,0,344225829,130,165999,286220138,ARL
2025-07-17T16:17:23.653821034Z,2025-07-17T16:17:23.653655443Z,160,2,1108,C,A,15.700000000,100,0,341661849,130,165591,286220139,ARL
2025-07-17T16:17:24.832340976Z,2025-07-17T16:17:24.832175508Z,160,2,1108,C,A,13.470000000,15,0,344211173,130,165468,286237340,ARL
2025-07-17T16:17:26.823562625Z,2025-07-17T16:17:26.823396428Z,160,2,1108,C,A,13.480000000,100,0,344225341,130,166197,286261717,ARL
2025-07-17T16:17:26.823923686Z,2025-07-17T16:17:26.823758552Z,160,2,1108,A,A,15.680000000,100,0,344280537,130,165134,286261727,ARL
2025-07-17T16:17:26.823937553Z,2025-07-17T16:17:26.823771696Z,160,2,1108,C,A,15.370000000,100,0,344225829,130,165857,286261728,ARL
2025-07-17T16:17:26.824304510Z,2025-07-17T16:17:26.824137854Z,160,2,1108,C,A,14.530000000,100,0,344225385,0,166656,286261743,ARL
2025-07-17T16:17:26.824304510Z,2025-07-17T16:17:26.824137854Z,160,2,1108,A,A,14.580000000,100,0,344280577,0,166656,286261743,ARL
2025-07-17T16:17:26.824304510Z,2025-07-17T16:17:26.824138799Z,160,2,1108,C,A,14.080000000,100,0,344225397,130,165711,286261744,ARL
2025-07-17T16:17:26.824657956Z,2025-07-17T16:17:26.824492765Z,160,2,1108,A,A,14.360000000,100,0,344280617,130,165191,286261759,ARL
2025-07-17T16:17:26.825988253Z,2025-07-17T16:17:26.825823014Z,160,2,1108,C,A,14.270000000,100,0,344225453,130,165239,286261769,ARL
2025-07-17T16:17:26.826051208Z,2025-07-17T16:17:26.825885765Z,160,2,1108,C,A,14.430000000,100,0,344225449,0,165443,286261770,ARL
2025-07-17T16:17:26.826051208Z,2025-07-17T16:17:26.825885765Z,160,2,1108,A,A,14.720000000,100,0,344280641,130,165443,286261770,ARL
2025-07-17T16:17:26.826159189Z,2025-07-17T16:17:26.825993909Z,160,2,1108,A,A,14.540000000,100,0,344280645,130,165280,286261771,ARL
2025-07-17T16:17:26.826294122Z,2025-07-17T16:17:26.826128663Z,160,2,1108,C,A,14.830000000,100,0,344225405,0,165459,286261775,ARL
2025-07-17T16:17:26.826294122Z,2025-07-17T16:17:26.826128663Z,160,2,1108,A,A,15.130000000,100,0,344280653,130,165459,286261775,ARL
2025-07-17T16:17:26.828538841Z,2025-07-17T16:17:26.828373551Z,160,2,1108,C,A,13.750000000,100,0,344225533,130,165290,286261785,ARL
2025-07-17T16:17:26.828589142Z,2025-07-17T16:17:26.828423432Z,160,2,1108,A,A,14.030000000,100,0,344280689,130,165710,286261786,ARL
2025-07-17T16:17:26.828846606Z,2025-07-17T16:17:26.828681062Z,160,2,1108,C,A,13.740000000,2,0,340449865,0,165544,286261788,ARL
2025-07-17T16:17:26.828846606Z,2025-07-17T16:17:26.828681062Z,160,2,1108,A,A,13.970000000,2,0,344280721,130,165544,286261788,ARL
2025-07-17T16:17:26.830066702Z,2025-07-17T16:17:26.829901530Z,160,2,1108,C,A,14.720000000,100,0,344280641,0,165172,286262023,ARL
2025-07-17T16:17:26.830066702Z,2025-07-17T16:17:26.829901530Z,160,2,1108,A,A,14.960000000,100,0,344280825,130,165172,286262023,ARL
2025-07-17T16:17:26.832026257Z,2025-07-17T16:17:26.831860798Z,160,2,1108,C,A,17.120000000,100,0,344225457,0,165459,286262118,ARL
2025-07-17T16:17:26.832026257Z,2025-07-17T16:17:26.831860798Z,160,2,1108,A,A,17.760000000,100,0,344280917,130,165459,286262118,ARL
2025-07-17T16:17:26.833194882Z,2025-07-17T16:17:26.833029512Z,160,2,1108,C,A,15.510000000,100,0,344225393,0,165370,286262137,ARL
2025-07-17T16:17:26.833194882Z,2025-07-17T16:17:26.833029512Z,160,2,1108,A,A,16.080000000,100,0,344280941,130,165370,286262137,ARL
2025-07-17T16:17:26.834911649Z,2025-07-17T16:17:26.834746475Z,160,2,1108,C,A,14.030000000,100,0,344280689,130,165174,286262165,ARL
2025-07-17T16:17:26.834961494Z,2025-07-17T16:17:26.834796238Z,160,2,1108,A,A,14.250000000,100,0,344280953,130,165256,286262166,ARL
2025-07-17T16:17:26.846567340Z,2025-07-17T16:17:26.846401696Z,160,2,1108,C,A,14.830000000,100,0,344225485,0,165644,286262231,ARL
2025-07-17T16:17:26.846567340Z,2025-07-17T16:17:26.846401696Z,160,2,1108,A,A,15.380000000,100,0,344281229,130,165644,286262231,ARL
2025-07-17T16:17:26.849670659Z,2025-07-17T16:17:26.849505109Z,160,2,1108,C,A,14.430000000,100,0,344225489,0,165550,286262262,ARL
2025-07-17T16:17:26.849670659Z,2025-07-17T16:17:26.849505109Z,160,2,1108,A,A,14.960000000,100,0,344281257,130,165550,286262262,ARL
2025-07-17T16:17:26.874430238Z,2025-07-17T16:17:26.874264677Z,160,2,1108,C,A,14.580000000,100,0,344280577,0,165561,286262413,ARL
2025-07-17T16:17:26.874430238Z,2025-07-17T16:17:26.874264677Z,160,2,1108,A,A,15.050000000,100,0,344281457,130,165561,286262413,ARL
2025-07-17T16:17:27.000782790Z,2025-07-17T16:17:27.000617575Z,160,2,1108,A,A,13.980000000,100,0,344283633,130,165215,286264622,ARL
2025-07-17T16:17:27.204893988Z,2025-07-17T16:17:27.204728176Z,160,2,1108,C,A,14.220000000,100,0,339365193,130,165812,286267644,ARL
2025-07-17T16:17:27.204895267Z,2025-07-17T16:17:27.204730160Z,160,2,1108,A,A,14.530000000,100,0,344288585,130,165107,286267645,ARL
2025-07-17T16:17:27.381792167Z,2025-07-17T16:17:27.381626601Z,160,2,1108,A,A,14.810000000,100,0,344292849,130,165566,286271009,ARL
2025-07-17T16:17:27.381809823Z,2025-07-17T16:17:27.381644366Z,160,2,1108,C,A,14.490000000,100,0,339366385,130,165457,286271010,ARL
2025-07-17T16:17:27.443162448Z,2025-07-17T16:17:27.442997426Z,160,2,1108,C,A,14.360000000,100,0,344280617,130,165022,286271749,ARL
2025-07-17T16:17:27.443512590Z,2025-07-17T16:17:27.443347265Z,160,2,1108,A,A,14.600000000,100,0,344294245,130,165325,286271751,ARL
2025-07-17T16:17:27.829055288Z,2025-07-17T16:17:27.828890080Z,160,2,1108,C,A,14.540000000,100,0,344280645,0,165208,286275353,ARL
2025-07-17T16:17:27.829055288Z,2025-07-17T16:17:27.828890080Z,160,2,1108,A,A,14.770000000,100,0,344300085,130,165208,286275353,ARL
2025-07-17T16:17:39.514690751Z,2025-07-17T16:17:39.514525397Z,160,2,1108,A,A,13.470000000,15,0,344587533,130,165354,286508705,ARL
2025-07-17T16:17:39.829017289Z,2025-07-17T16:17:39.828851797Z,160,2,1108,C,A,14.460000000,100,0,339739285,0,165492,286513833,ARL
2025-07-17T16:17:39.829017289Z,2025-07-17T16:17:39.828851797Z,160,2,1108,A,A,14.350000000,100,0,344593405,130,165492,286513833,ARL
2025-07-17T16:17:39.829247357Z,2025-07-17T16:17:39.829081898Z,160,2,1108,C,A,14.460000000,100,0,339739297,0,165459,286513835,ARL
2025-07-17T16:17:39.829247357Z,2025-07-17T16:17:39.829081898Z,160,2,1108,A,A,14.350000000,100,0,344593409,130,165459,286513835,ARL
2025-07-17T16:17:40.321326768Z,2025-07-17T16:17:40.321161439Z,160,2,1108,C,A,13.980000000,100,0,344283633,0,165329,286524785,ARL
2025-07-17T16:17:40.321326768Z,2025-07-17T16:17:40.321161439Z,160,2,1108,A,A,13.480000000,100,0,344607833,130,165329,286524785,ARL
2025-07-17T16:17:40.322064038Z,2025-07-17T16:17:40.321898765Z,160,2,1108,C,A,14.600000000,100,0,344294245,130,165273,286524815,ARL
2025-07-17T16:17:40.322069742Z,2025-07-17T16:17:40.321903984Z,160,2,1108,C,A,15.050000000,100,0,344281457,0,165758,286524817,ARL
2025-07-17T16:17:40.322069742Z,2025-07-17T16:17:40.321903984Z,160,2,1108,A,A,14.530000000,100,0,344607889,130,165758,286524817,ARL
2025-07-17T16:17:40.322416015Z,2025-07-17T16:17:40.322250847Z,160,2,1108,A,A,14.080000000,100,0,344607893,130,165168,286524822,ARL
2025-07-17T16:17:40.329180897Z,2025-07-17T16:17:40.329015669Z,160,2,1108,C,A,14.250000000,100,0,344280953,130,165228,286524967,ARL
2025-07-17T16:17:40.329233157Z,2025-07-17T16:17:40.329067996Z,160,2,1108,A,A,13.750000000,100,0,344608193,130,165161,286524969,ARL
2025-07-17T16:17:40.330448099Z,2025-07-17T16:17:40.330282519Z,160,2,1108,C,A,15.130000000,100,0,344280653,0,165580,286524982,ARL
2025-07-17T16:17:40.330448099Z,2025-07-17T16:17:40.330282519Z,160,2,1108,A,A,14.830000000,100,0,344608205,130,165580,286524982,ARL
2025-07-17T16:17:40.331429414Z,2025-07-17T16:17:40.331264268Z,160,2,1108,C,A,14.770000000,100,0,344300085,130,165146,286524998,ARL
2025-07-17T16:17:40.331551656Z,2025-07-17T16:17:40.331386492Z,160,2,1108,A,A,14.270000000,100,0,344608225,130,165164,286525005,ARL
2025-07-17T16:17:40.333679181Z,2025-07-17T16:17:40.333513866Z,160,2,1108,C,A,14.960000000,100,0,344280825,0,165315,286525029,ARL
2025-07-17T16:17:40.333679181Z,2025-07-17T16:17:40.333513866Z,160,2,1108,A,A,14.430000000,100,0,344608253,130,165315,286525029,ARL
2025-07-17T16:17:40.348996221Z,2025-07-17T16:17:40.348830748Z,160,2,1108,C,A,17.760000000,100,0,344280917,0,165473,286525170,ARL
2025-07-17T16:17:40.348996221Z,2025-07-17T16:17:40.348830748Z,160,2,1108,A,A,17.120000000,100,0,344608637,130,165473,286525170,ARL
2025-07-17T16:17:40.349081921Z,2025-07-17T16:17:40.348916703Z,160,2,1108,A,A,15.370000000,100,0,344608641,130,165218,286525175,ARL
2025-07-17T16:17:40.349095477Z,2025-07-17T16:17:40.348930117Z,160,2,1108,C,A,15.680000000,100,0,344280537,130,165360,286525177,ARL
2025-07-17T16:17:40.357367234Z,2025-07-17T16:17:40.357201846Z,160,2,1108,C,A,16.080000000,100,0,344280941,0,165388,286525428,ARL
2025-07-17T16:17:40.357367234Z,2025-07-17T16:17:40.357201846Z,160,2,1108,A,A,15.510000000,100,0,344608797,130,165388,286525428,ARL
2025-07-17T16:17:40.403239477Z,2025-07-17T16:17:40.403073956Z,160,2,1108,C,A,15.380000000,100,0,344281229,0,165521,286526316,ARL
2025-07-17T16:17:40.403239477Z,2025-07-17T16:17:40.403073956Z,160,2,1108,A,A,14.830000000,100,0,344609897,130,165521,286526316,ARL
2025-07-17T16:17:40.426590567Z,2025-07-17T16:17:40.426425205Z,160,2,1108,C,A,14.960000000,100,0,344281257,0,165362,286526540,ARL
2025-07-17T16:17:40.426590567Z,2025-07-17T16:17:40.426425205Z,160,2,1108,A,A,14.430000000,100,0,344610073,130,165362,286526540,ARL
2025-07-17T16:17:40.474841118Z,2025-07-17T16:17:40.474675991Z,160,2,1108,A,A,14.010000000,100,0,344612049,130,165127,286527611,ARL
2025-07-17T16:17:40.474842468Z,2025-07-17T16:17:40.474677082Z,160,2,1108,C,A,14.530000000,100,0,344288585,130,165386,286527612,ARL
2025-07-17T16:17:40.697721205Z,2025-07-17T16:17:40.697555911Z,160,2,1108,A,A,14.280000000,100,0,344615393,130,165294,286530329,ARL
2025-07-17T16:17:40.697733924Z,2025-07-17T16:17:40.697568713Z,160,2,1108,C,A,14.810000000,100,0,344292849,130,165211,286530330,ARL
2025-07-17T16:17:41.586151161Z,2025-07-17T16:17:41.585985709Z,160,2,1108,C,A,13.970000000,2,0,344280721,0,165452,286543225,ARL
2025-07-17T16:17:41.586151161Z,2025-07-17T16:17:41.585985709Z,160,2,1108,A,A,13.870000000,2,0,344631921,130,165452,286543225,ARL
2025-07-17T16:17:42.553133650Z,2025-07-17T16:17:42.552968542Z,160,2,1108,A,A,13.450000000,15,0,344653009,130,165108,286561347,ARL
2025-07-17T16:17:44.014614049Z,2025-07-17T16:17:44.014448587Z,160,2,1108,C,A,13.480000000,100,0,344607833,0,165462,286577648,ARL
2025-07-17T16:17:44.014614049Z,2025-07-17T16:17:44.014448587Z,160,2,1108,A,A,13.460000000,100,0,344673481,130,165462,286577648,ARL
2025-07-17T16:17:44.014977545Z,2025-07-17T16:17:44.014812396Z,160,2,1108,A,A,15.680000000,100,0,344673501,130,165149,286577651,ARL
2025-07-17T16:17:44.014991037Z,2025-07-17T16:17:44.014825581Z,160,2,1108,C,A,15.370000000,100,0,344608641,130,165456,286577652,ARL
2025-07-17T16:17:44.042976984Z,2025-07-17T16:17:44.042811526Z,160,2,1108,A,A,15.350000000,100,0,344674517,130,165458,286578356,ARL
2025-07-17T16:17:44.042989197Z,2025-07-17T16:17:44.042824242Z,160,2,1108,C,A,15.680000000,100,0,344673501,130,164955,286578357,ARL
2025-07-17T16:17:46.828260391Z,2025-07-17T16:17:46.828095134Z,160,2,1108,A,A,14.180000000,700,0,344724301,130,165257,286618024,ARL
2025-07-17T16:17:46.828325564Z,2025-07-17T16:17:46.828160338Z,160,2,1108,C,A,14.680000000,700,0,341663105,130,165226,286618025,ARL
2025-07-17T16:17:49.387530942Z,2025-07-17T16:17:49.387365405Z,160,2,1108,C,A,13.870000000,2,0,344631921,0,165537,286651544,ARL
2025-07-17T16:17:49.387530942Z,2025-07-17T16:17:49.387365405Z,160,2,1108,A,A,13.790000000,2,0,344765077,130,165537,286651544,ARL
2025-07-17T16:17:52.834173973Z,2025-07-17T16:17:52.834008196Z,160,2,1108,C,A,13.470000000,15,0,344587533,130,165777,286689853,ARL
2025-07-17T16:17:58.033327053Z,2025-07-17T16:17:58.033161898Z,160,2,1108,C,A,13.450000000,15,0,344653009,130,165155,286753046,ARL
2025-07-17T16:17:58.036588469Z,2025-07-17T16:17:58.036423237Z,160,2,1108,C,A,13.460000000,100,0,344673481,130,165232,286753126,ARL
2025-07-17T16:17:58.036861922Z,2025-07-17T16:17:58.036696806Z,160,2,1108,C,A,14.180000000,700,0,344724301,130,165116,286753127,ARL
2025-07-17T16:17:58.036914002Z,2025-07-17T16:17:58.036748831Z,160,2,1108,A,A,14.440000000,700,0,344897921,130,165171,286753128,ARL
2025-07-17T16:17:58.036971455Z,2025-07-17T16:17:58.036806229Z,160,2,1108,A,A,15.680000000,100,0,344897933,130,165226,286753129,ARL
2025-07-17T16:17:58.036983460Z,2025-07-17T16:17:58.036818196Z,160,2,1108,C,A,15.350000000,100,0,344674517,130,165264,286753132,ARL
2025-07-17T16:17:58.037325671Z,2025-07-17T16:17:58.037160197Z,160,2,1108,C,A,14.530000000,100,0,344607889,0,165474,286753136,ARL
2025-07-17T16:17:58.037325671Z,2025-07-17T16:17:58.037160197Z,160,2,1108,A,A,14.820000000,100,0,344897945,130,165474,286753136,ARL
2025-07-17T16:17:58.037330946Z,2025-07-17T16:17:58.037165870Z,160,2,1108,C,A,14.080000000,100,0,344607893,130,165076,286753137,ARL
2025-07-17T16:17:58.037686676Z,2025-07-17T16:17:58.037521442Z,160,2,1108,A,A,14.360000000,100,0,344897953,130,165234,286753149,ARL
2025-07-17T16:17:58.038759735Z,2025-07-17T16:17:58.038594284Z,160,2,1108,C,A,14.430000000,100,0,344608253,0,165451,286753168,ARL
2025-07-17T16:17:58.038759735Z,2025-07-17T16:17:58.038594284Z,160,2,1108,A,A,14.720000000,100,0,344897989,130,165451,286753168,ARL
2025-07-17T16:17:58.039381900Z,2025-07-17T16:17:58.039215838Z,160,2,1108,C,A,14.830000000,100,0,344608205,0,166062,286753172,ARL
2025-07-17T16:17:58.039381900Z,2025-07-17T16:17:58.039215838Z,160,2,1108,A,A,15.130000000,100,0,344897997,130,166062,286753172,ARL
2025-07-17T16:17:58.047862207Z,2025-07-17T16:17:58.047696769Z,160,2,1108,C,A,17.120000000,100,0,344608637,0,165438,286753519,ARL
2025-07-17T16:17:58.047862207Z,2025-07-17T16:17:58.047696769Z,160,2,1108,A,A,17.470000000,100,0,344898485,130,165438,286753519,ARL
2025-07-17T16:17:58.051632876Z,2025-07-17T16:17:58.051466948Z,160,2,1108,C,A,15.510000000,100,0,344608797,0,165928,286753581,ARL
2025-07-17T16:17:58.051632876Z,2025-07-17T16:17:58.051466948Z,160,2,1108,A,A,15.820000000,100,0,344898677,130,165928,286753581,ARL
2025-07-17T16:17:58.054049362Z,2025-07-17T16:17:58.053883828Z,160,2,1108,C,A,13.750000000,100,0,344608193,130,165534,286753747,ARL
2025-07-17T16:17:58.054100805Z,2025-07-17T16:17:58.053934652Z,160,2,1108,C,A,14.440000000,700,0,344897921,130,166153,286753751,ARL
2025-07-17T16:17:58.054101429Z,2025-07-17T16:17:58.053935872Z,160,2,1108,A,A,14.030000000,100,0,344898949,130,165557,286753752,ARL
2025-07-17T16:17:58.056965001Z,2025-07-17T16:17:58.056799769Z,160,2,1108,C,A,14.720000000,100,0,344897989,0,165232,286753926,ARL
2025-07-17T16:17:58.056965001Z,2025-07-17T16:17:58.056799769Z,160,2,1108,A,A,14.960000000,100,0,344899081,130,165232,286753926,ARL
2025-07-17T16:17:58.057809322Z,2025-07-17T16:17:58.057644161Z,160,2,1108,C,A,15.820000000,100,0,344898677,0,165161,286753935,ARL
2025-07-17T16:17:58.057809322Z,2025-07-17T16:17:58.057644161Z,160,2,1108,A,A,16.080000000,100,0,344899093,130,165161,286753935,ARL
2025-07-17T16:17:58.061670860Z,2025-07-17T16:17:58.061505885Z,160,2,1108,C,A,14.030000000,100,0,344898949,130,164975,286754272,ARL
2025-07-17T16:17:58.061730836Z,2025-07-17T16:17:58.061563628Z,160,2,1108,A,A,14.250000000,100,0,344899417,130,167208,286754286,ARL
2025-07-17T16:17:58.062137122Z,2025-07-17T16:17:58.061971960Z,160,2,1108,C,A,17.470000000,100,0,344898485,0,165162,286754339,ARL
2025-07-17T16:17:58.062137122Z,2025-07-17T16:17:58.061971960Z,160,2,1108,A,A,17.760000000,100,0,344899449,130,165162,286754339,ARL
2025-07-17T16:17:58.086582033Z,2025-07-17T16:17:58.086415950Z,160,2,1108,C,A,14.270000000,100,0,344608225,0,166083,286754819,ARL
2025-07-17T16:17:58.086582033Z,2025-07-17T16:17:58.086415950Z,160,2,1108,A,A,14.540000000,100,0,344899913,130,166083,286754819,ARL
2025-07-17T16:17:58.087829372Z,2025-07-17T16:17:58.087663773Z,160,2,1108,C,A,14.820000000,100,0,344897945,0,165599,286754826,ARL
2025-07-17T16:17:58.087829372Z,2025-07-17T16:17:58.087663773Z,160,2,1108,A,A,15.050000000,100,0,344899937,130,165599,286754826,ARL
2025-07-17T16:17:58.113382320Z,2025-07-17T16:17:58.113216665Z,160,2,1108,C,A,14.830000000,100,0,344609897,0,165655,286755076,ARL
2025-07-17T16:17:58.113382320Z,2025-07-17T16:17:58.113216665Z,160,2,1108,A,A,15.380000000,100,0,344900289,130,165655,286755076,ARL
2025-07-17T16:17:58.145548497Z,2025-07-17T16:17:58.145382853Z,160,2,1108,C,A,14.430000000,100,0,344610073,0,165644,286755340,ARL
2025-07-17T16:17:58.145548497Z,2025-07-17T16:17:58.145382853Z,160,2,1108,A,A,14.960000000,100,0,344900597,130,165644,286755340,ARL
2025-07-17T16:17:58.173831273Z,2025-07-17T16:17:58.173665745Z,160,2,1108,A,A,14.810000000,100,0,344900925,130,165528,286755602,ARL
2025-07-17T16:17:58.173852767Z,2025-07-17T16:17:58.173687330Z,160,2,1108,C,A,14.280000000,100,0,344615393,130,165437,286755603,ARL
2025-07-17T16:17:58.235788576Z,2025-07-17T16:17:58.235623452Z,160,2,1108,A,A,14.680000000,700,0,344902153,130,165124,286756143,ARL
2025-07-17T16:17:58.502856372Z,2025-07-17T16:17:58.502691073Z,160,2,1108,A,A,14.530000000,100,0,344905321,130,165299,286758830,ARL
2025-07-17T16:17:58.502858100Z,2025-07-17T16:17:58.502692641Z,160,2,1108,C,A,14.010000000,100,0,344612049,130,165459,286758831,ARL
2025-07-17T16:17:58.704865076Z,2025-07-17T16:17:58.704699676Z,160,2,1108,C,A,14.360000000,100,0,344897953,130,165400,286760091,ARL
2025-07-17T16:17:58.705216838Z,2025-07-17T16:17:58.705051532Z,160,2,1108,A,A,14.600000000,100,0,344906945,130,165306,286760096,ARL
2025-07-17T16:17:59.086439158Z,2025-07-17T16:17:59.086273873Z,160,2,1108,C,A,14.540000000,100,0,344899913,130,165285,286766349,ARL
2025-07-17T16:17:59.086561438Z,2025-07-17T16:17:59.086395964Z,160,2,1108,A,A,14.770000000,100,0,344914361,130,165474,286766355,ARL
2025-07-17T16:18:02.178629167Z,2025-07-17T16:18:02.178463984Z,160,2,1108,A,A,13.800000000,100,0,344989393,130,165183,286829047,ARL
2025-07-17T16:18:02.179379565Z,2025-07-17T16:18:02.179214149Z,160,2,1108,C,A,15.050000000,100,0,344899937,0,165416,286829057,ARL
2025-07-17T16:18:02.179379565Z,2025-07-17T16:18:02.179214149Z,160,2,1108,A,A,14.870000000,100,0,344989421,130,165416,286829057,ARL
2025-07-17T16:18:02.181473898Z,2025-07-17T16:18:02.181307241Z,160,2,1108,C,A,14.960000000,100,0,344899081,0,166657,286829106,ARL
2025-07-17T16:18:02.181473898Z,2025-07-17T16:18:02.181307241Z,160,2,1108,A,A,14.770000000,100,0,344989525,128,166657,286829106,ARL
2025-07-17T16:18:02.182474498Z,2025-07-17T16:18:02.182309015Z,160,2,1108,C,A,17.760000000,100,0,344899449,0,165483,286829137,ARL
2025-07-17T16:18:02.182474498Z,2025-07-17T16:18:02.182309015Z,160,2,1108,A,A,17.530000000,100,0,344989557,130,165483,286829137,ARL
2025-07-17T16:18:02.184788371Z,2025-07-17T16:18:02.184622698Z,160,2,1108,C,A,14.250000000,100,0,344899417,130,165673,286829173,ARL
2025-07-17T16:18:02.184840010Z,2025-07-17T16:18:02.184674810Z,160,2,1108,A,A,14.080000000,100,0,344989601,130,165200,286829174,ARL
2025-07-17T16:18:02.186910586Z,2025-07-17T16:18:02.186745185Z,160,2,1108,C,A,14.770000000,100,0,344914361,0,165401,286829206,ARL
2025-07-17T16:18:02.186910586Z,2025-07-17T16:18:02.186745185Z,160,2,1108,A,A,14.590000000,100,0,344989661,130,165401,286829206,ARL
2025-07-17T16:18:02.189536873Z,2025-07-17T16:18:02.189371317Z,160,2,1108,C,A,16.080000000,100,0,344899093,0,165556,286829251,ARL
2025-07-17T16:18:02.189536873Z,2025-07-17T16:18:02.189371317Z,160,2,1108,A,A,15.870000000,100,0,344989713,130,165556,286829251,ARL
2025-07-17T16:18:02.271602472Z,2025-07-17T16:18:02.271437003Z,160,2,1108,C,A,14.960000000,100,0,344900597,0,165469,286830984,ARL
2025-07-17T16:18:02.271602472Z,2025-07-17T16:18:02.271437003Z,160,2,1108,A,A,14.770000000,100,0,344990837,130,165469,286830984,ARL
2025-07-17T16:18:44.836233374Z,2025-07-17T16:18:44.836067409Z,160,2,1108,A,A,13.470000000,15,0,345869437,130,165965,287534438,ARL
2025-07-17T16:18:45.977564112Z,2025-07-17T16:18:45.977398557Z,160,2,1108,C,A,13.800000000,100,0,344989393,0,165555,287547865,ARL
2025-07-17T16:18:45.977564112Z,2025-07-17T16:18:45.977398557Z,160,2,1108,A,A,13.480000000,100,0,345889137,130,165555,287547865,ARL
2025-07-17T16:18:45.978304784Z,2025-07-17T16:18:45.978139497Z,160,2,1108,C,A,14.600000000,100,0,344906945,130,165287,287547870,ARL
2025-07-17T16:18:45.978307201Z,2025-07-17T16:18:45.978141738Z,160,2,1108,C,A,14.870000000,100,0,344989421,0,165463,287547871,ARL
2025-07-17T16:18:45.978307201Z,2025-07-17T16:18:45.978141738Z,160,2,1108,A,A,14.530000000,100,0,345889161,130,165463,287547871,ARL
2025-07-17T16:18:45.978659056Z,2025-07-17T16:18:45.978493799Z,160,2,1108,A,A,14.080000000,100,0,345889165,130,165257,287547872,ARL
2025-07-17T16:18:45.979197330Z,2025-07-17T16:18:45.979031886Z,160,2,1108,C,A,15.130000000,100,0,344897997,0,165444,287547882,ARL
2025-07-17T16:18:45.979197330Z,2025-07-17T16:18:45.979031886Z,160,2,1108,A,A,14.830000000,100,0,345889185,130,165444,287547882,ARL
2025-07-17T16:18:45.979453023Z,2025-07-17T16:18:45.979287575Z,160,2,1108,C,A,14.770000000,100,0,344990837,0,165448,287547885,ARL
2025-07-17T16:18:45.979453023Z,2025-07-17T16:18:45.979287575Z,160,2,1108,A,A,14.430000000,100,0,345889189,130,165448,287547885,ARL
2025-07-17T16:18:45.979897527Z,2025-07-17T16:18:45.979732081Z,160,2,1108,C,A,15.870000000,100,0,344989713,0,165446,287547887,ARL
2025-07-17T16:18:45.979897527Z,2025-07-17T16:18:45.979732081Z,160,2,1108,A,A,15.510000000,100,0,345889193,130,165446,287547887,ARL
2025-07-17T16:18:45.980137835Z,2025-07-17T16:18:45.979972220Z,160,2,1108,C,A,14.770000000,100,0,344989525,0,165615,287547890,ARL
2025-07-17T16:18:45.980137835Z,2025-07-17T16:18:45.979972220Z,160,2,1108,A,A,14.430000000,100,0,345889201,130,165615,287547890,ARL
2025-07-17T16:18:45.980197213Z,2025-07-17T16:18:45.980031732Z,160,2,1108,C,A,17.530000000,100,0,344989557,0,165481,287547891,ARL
2025-07-17T16:18:45.980197213Z,2025-07-17T16:18:45.980031732Z,160,2,1108,A,A,17.120000000,100,0,345889205,130,165481,287547891,ARL
2025-07-17T16:18:45.980205832Z,2025-07-17T16:18:45.980040000Z,160,2,1108,C,A,15.380000000,100,0,344900289,0,165832,287547892,ARL
2025-07-17T16:18:45.980205832Z,2025-07-17T16:18:45.980040000Z,160,2,1108,A,A,14.830000000,100,0,345889209,130,165832,287547892,ARL
2025-07-17T16:18:45.982963696Z,2025-07-17T16:18:45.982798406Z,160,2,1108,C,A,14.590000000,100,0,344989661,130,165290,287547919,ARL
2025-07-17T16:18:45.983098604Z,2025-07-17T16:18:45.982933040Z,160,2,1108,A,A,14.270000000,100,0,345889277,130,165564,287547921,ARL
2025-07-17T16:18:45.994306597Z,2025-07-17T16:18:45.994141218Z,160,2,1108,C,A,14.080000000,100,0,344989601,130,165379,287548000,ARL
2025-07-17T16:18:45.994356983Z,2025-07-17T16:18:45.994191684Z,160,2,1108,A,A,13.750000000,100,0,345889457,130,165299,287548002,ARL
2025-07-17T16:18:46.020770846Z,2025-07-17T16:18:46.020605332Z,160,2,1108,A,A,15.370000000,100,0,345889897,130,165514,287548308,ARL
2025-07-17T16:18:46.020783162Z,2025-07-17T16:18:46.020617704Z,160,2,1108,C,A,15.680000000,100,0,344897933,130,165458,287548309,ARL
2025-07-17T16:18:46.583802176Z,2025-07-17T16:18:46.583636828Z,160,2,1108,A,A,14.280000000,100,0,345903265,130,165348,287559115,ARL
2025-07-17T16:18:46.583815469Z,2025-07-17T16:18:46.583649620Z,160,2,1108,C,A,14.810000000,100,0,344900925,128,165849,287559119,ARL
2025-07-17T16:18:46.972854044Z,2025-07-17T16:18:46.972688613Z,160,2,1108,C,A,14.530000000,100,0,344905321,130,165431,287565224,ARL
2025-07-17T16:18:46.972855248Z,2025-07-17T16:18:46.972689989Z,160,2,1108,A,A,14.010000000,100,0,345911213,130,165259,287565225,ARL
2025-07-17T16:18:47.836167832Z,2025-07-17T16:18:47.836002486Z,160,2,1108,A,A,13.450000000,15,0,345924181,130,165346,287577128,ARL
2025-07-17T16:18:47.956236479Z,2025-07-17T16:18:47.956070064Z,160,2,1108,C,A,13.480000000,100,0,345889137,0,166415,287579474,ARL
2025-07-17T16:18:47.956236479Z,2025-07-17T16:18:47.956070064Z,160,2,1108,A,A,13.460000000,100,0,345926413,130,166415,287579474,ARL
2025-07-17T16:18:47.956614041Z,2025-07-17T16:18:47.956448830Z,160,2,1108,A,A,15.680000000,100,0,345926449,130,165211,287579583,ARL
2025-07-17T16:18:47.956628879Z,2025-07-17T16:18:47.956462726Z,160,2,1108,C,A,15.370000000,100,0,345889897,130,166153,287579592,ARL
2025-07-17T16:18:47.983287076Z,2025-07-17T16:18:47.983119698Z,160,2,1108,A,A,15.350000000,100,0,345930785,128,167378,287583059,ARL
2025-07-17T16:18:47.983312942Z,2025-07-17T16:18:47.983140841Z,160,2,1108,C,A,15.680000000,100,0,345926449,128,172101,287583076,ARL
2025-07-17T16:18:51.228439638Z,2025-07-17T16:18:51.228274415Z,160,2,1108,A,A,14.180000000,700,0,345998433,130,165223,287639434,ARL
2025-07-17T16:18:51.228516429Z,2025-07-17T16:18:51.228351310Z,160,2,1108,C,A,14.680000000,700,0,344902153,130,165119,287639437,ARL
2025-07-17T16:18:57.882365457Z,2025-07-17T16:18:57.882196648Z,160,2,1108,C,A,13.470000000,15,0,345869437,128,168809,287807679,ARL
2025-07-17T16:19:04.990890102Z,2025-07-17T16:19:04.990724544Z,160,2,1108,C,A,13.790000000,2,0,344765077,0,165558,288025773,ARL
2025-07-17T16:19:04.990890102Z,2025-07-17T16:19:04.990724544Z,160,2,1108,A,A,13.720000000,2,0,346423105,130,165558,288025773,ARL
2025-07-17T16:19:08.837286193Z,2025-07-17T16:19:08.837120837Z,160,2,1108,A,A,13.430000000,15,0,346492493,130,165356,288088546,ARL
2025-07-17T16:19:11.008353202Z,2025-07-17T16:19:11.008187551Z,160,2,1108,C,A,13.460000000,100,0,345926413,0,165651,288143215,ARL
2025-07-17T16:19:11.008353202Z,2025-07-17T16:19:11.008187551Z,160,2,1108,A,A,13.440000000,100,0,346562289,130,165651,288143215,ARL
2025-07-17T16:19:11.008765986Z,2025-07-17T16:19:11.008600601Z,160,2,1108,A,A,15.680000000,100,0,346562317,130,165385,288143223,ARL
2025-07-17T16:19:11.008779449Z,2025-07-17T16:19:11.008613992Z,160,2,1108,C,A,15.350000000,100,0,345930785,130,165457,288143225,ARL
2025-07-17T16:19:11.009089771Z,2025-07-17T16:19:11.008923390Z,160,2,1108,C,A,14.530000000,100,0,345889161,0,166381,288143233,ARL
2025-07-17T16:19:11.009089771Z,2025-07-17T16:19:11.008923390Z,160,2,1108,A,A,14.480000000,100,0,346562329,130,166381,288143233,ARL
2025-07-17T16:19:11.035380853Z,2025-07-17T16:19:11.035215637Z,160,2,1108,A,A,15.330000000,100,0,346563437,130,165216,288143789,ARL
2025-07-17T16:19:11.035392933Z,2025-07-17T16:19:11.035227814Z,160,2,1108,C,A,15.680000000,100,0,346562317,130,165119,288143791,ARL
2025-07-17T16:19:20.837507906Z,2025-07-17T16:19:20.837342130Z,160,2,1108,C,A,13.450000000,15,0,345924181,130,165776,288310746,ARL
2025-07-17T16:19:26.654075072Z,2025-07-17T16:19:26.653909048Z,160,2,1108,A,A,13.410000000,15,0,346891037,128,166024,288411319,ARL
2025-07-17T16:19:27.200595996Z,2025-07-17T16:19:27.200430092Z,160,2,1108,C,A,13.440000000,100,0,346562289,0,165904,288424564,ARL
2025-07-17T16:19:27.200595996Z,2025-07-17T16:19:27.200430092Z,160,2,1108,A,A,13.420000000,100,0,346904153,130,165904,288424564,ARL
2025-07-17T16:19:27.200986286Z,2025-07-17T16:19:27.200820552Z,160,2,1108,A,A,15.680000000,100,0,346904169,130,165734,288424568,ARL
2025-07-17T16:19:27.201000330Z,2025-07-17T16:19:27.200833294Z,160,2,1108,C,A,15.330000000,100,0,346563437,128,167036,288424570,ARL
2025-07-17T16:19:27.201378249Z,2025-07-17T16:19:27.201212584Z,160,2,1108,A,A,14.190000000,700,0,346904221,130,165665,288424582,ARL
2025-07-17T16:19:27.201777312Z,2025-07-17T16:19:27.201611743Z,160,2,1108,C,A,14.560000000,700,0,282969973,130,165569,288424585,ARL
2025-07-17T16:19:27.228463152Z,2025-07-17T16:19:27.228297629Z,160,2,1108,A,A,15.300000000,100,0,346904561,130,165523,288425148,ARL
2025-07-17T16:19:27.228473898Z,2025-07-17T16:19:27.228308764Z,160,2,1108,C,A,15.680000000,100,0,346904169,130,165134,288425149,ARL
2025-07-17T16:19:28.991308227Z,2025-07-17T16:19:28.991142567Z,160,2,1108,C,B,13.030000000,2,0,343084165,0,165660,288452523,ARL
2025-07-17T16:19:28.991308227Z,2025-07-17T16:19:28.991142567Z,160,2,1108,A,B,12.950000000,2,0,346942181,130,165660,288452523,ARL
2025-07-17T16:19:30.834459284Z,2025-07-17T16:19:30.834293908Z,160,2,1108,C,A,13.410000000,15,0,346891037,130,165376,288478995,ARL
2025-07-17T16:19:30.835008022Z,2025-07-17T16:19:30.834842536Z,160,2,1108,C,A,13.420000000,100,0,346904153,130,165486,288479015,ARL
2025-07-17T16:19:30.835569072Z,2025-07-17T16:19:30.835403659Z,160,2,1108,C,A,13.430000000,15,0,346492493,130,165413,288479032,ARL
2025-07-17T16:19:32.547487183Z,2025-07-17T16:19:32.547320695Z,160,2,1108,C,A,14.180000000,700,0,345998433,130,166488,288512762,ARL
2025-07-17T16:19:32.547527626Z,2025-07-17T16:19:32.547362298Z,160,2,1108,A,A,14.440000000,700,0,347022701,130,165328,288512763,ARL
2025-07-17T16:19:32.547597224Z,2025-07-17T16:19:32.547432031Z,160,2,1108,A,A,15.680000000,100,0,347022705,130,165193,288512765,ARL
2025-07-17T16:19:32.547609689Z,2025-07-17T16:19:32.547444392Z,160,2,1108,C,A,15.300000000,100,0,346904561,130,165297,288512766,ARL
2025-07-17T16:19:32.548069205Z,2025-07-17T16:19:32.547904024Z,160,2,1108,C,A,14.080000000,100,0,345889165,130,165181,288512768,ARL
2025-07-17T16:19:32.548096238Z,2025-07-17T16:19:32.547930966Z,160,2,1108,C,A,14.190000000,700,0,346904221,130,165272,288512769,ARL
2025-07-17T16:19:32.548113549Z,2025-07-17T16:19:32.547947865Z,160,2,1108,C,A,14.480000000,100,0,346562329,0,165684,288512770,ARL
2025-07-17T16:19:32.548113549Z,2025-07-17T16:19:32.547947865Z,160,2,1108,A,A,14.820000000,100,0,347022737,130,165684,288512770,ARL
2025-07-17T16:19:32.548423905Z,2025-07-17T16:19:32.548258519Z,160,2,1108,A,A,14.360000000,100,0,347022741,130,165386,288512772,ARL
2025-07-17T16:19:32.548503722Z,2025-07-17T16:19:32.548338068Z,160,2,1108,A,A,14.480000000,700,0,347022749,130,165654,288512773,ARL
2025-07-17T16:19:32.548575405Z,2025-07-17T16:19:32.548409803Z,160,2,1108,C,A,14.830000000,100,0,345889185,0,165602,288512774,ARL
2025-07-17T16:19:32.548575405Z,2025-07-17T16:19:32.548409803Z,160,2,1108,A,A,15.130000000,100,0,347022753,130,165602,288512774,ARL
2025-07-17T16:19:32.548583352Z,2025-07-17T16:19:32.548417853Z,160,2,1108,C,A,17.120000000,100,0,345889205,0,165499,288512775,ARL
2025-07-17T16:19:32.548583352Z,2025-07-17T16:19:32.548417853Z,160,2,1108,A,A,17.470000000,100,0,347022757,130,165499,288512775,ARL
2025-07-17T16:19:32.549166752Z,2025-07-17T16:19:32.549001387Z,160,2,1108,C,A,14.270000000,100,0,345889277,0,165365,288512787,ARL
2025-07-17T16:19:32.549166752Z,2025-07-17T16:19:32.549001387Z,160,2,1108,A,A,14.540000000,100,0,347022789,130,165365,288512787,ARL
2025-07-17T16:19:32.549433234Z,2025-07-17T16:19:32.549267465Z,160,2,1108,C,A,14.430000000,100,0,345889201,0,165769,288512789,ARL
2025-07-17T16:19:32.549433234Z,2025-07-17T16:19:32.549267465Z,160,2,1108,A,A,14.720000000,100,0,347022797,130,165769,288512789,ARL
2025-07-17T16:19:32.550149522Z,2025-07-17T16:19:32.549983550Z,160,2,1108,C,A,15.510000000,100,0,345889193,0,165972,288512792,ARL
2025-07-17T16:19:32.550149522Z,2025-07-17T16:19:32.549983550Z,160,2,1108,A,A,15.820000000,100,0,347022817,130,165972,288512792,ARL
2025-07-17T16:19:32.551870451Z,2025-07-17T16:19:32.551704711Z,160,2,1108,C,A,14.830000000,100,0,345889209,0,165740,288512835,ARL
2025-07-17T16:19:32.551870451Z,2025-07-17T16:19:32.551704711Z,160,2,1108,A,A,15.130000000,100,0,347022865,130,165740,288512835,ARL
2025-07-17T16:19:32.554564549Z,2025-07-17T16:19:32.554398971Z,160,2,1108,C,A,14.430000000,100,0,345889189,0,165578,288512857,ARL
2025-07-17T16:19:32.554564549Z,2025-07-17T16:19:32.554398971Z,160,2,1108,A,A,14.720000000,100,0,347022893,130,165578,288512857,ARL
2025-07-17T16:19:32.566140694Z,2025-07-17T16:19:32.565975313Z,160,2,1108,C,A,13.750000000,100,0,345889457,130,165381,288512959,ARL
2025-07-17T16:19:32.566174380Z,2025-07-17T16:19:32.566009468Z,160,2,1108,C,A,14.440000000,700,0,347022701,130,164912,288512961,ARL
2025-07-17T16:19:32.566193866Z,2025-07-17T16:19:32.566028302Z,160,2,1108,A,A,14.030000000,100,0,347023005,130,165564,288512962,ARL
2025-07-17T16:19:32.567048160Z,2025-07-17T16:19:32.566882768Z,160,2,1108,C,A,14.720000000,100,0,347022893,0,165392,288512963,ARL
2025-07-17T16:19:32.567048160Z,2025-07-17T16:19:32.566882768Z,160,2,1108,A,A,14.950000000,100,0,347023021,130,165392,288512963,ARL
2025-07-17T16:19:32.567810828Z,2025-07-17T16:19:32.567645036Z,160,2,1108,C,A,17.470000000,100,0,347022757,0,165792,288512966,ARL
2025-07-17T16:19:32.567810828Z,2025-07-17T16:19:32.567645036Z,160,2,1108,A,A,17.750000000,100,0,347023037,130,165792,288512966,ARL
2025-07-17T16:19:32.567981668Z,2025-07-17T16:19:32.567816385Z,160,2,1108,C,A,14.720000000,100,0,347022797,0,165283,288512969,ARL
2025-07-17T16:19:32.567981668Z,2025-07-17T16:19:32.567816385Z,160,2,1108,A,A,14.960000000,100,0,347023045,130,165283,288512969,ARL
2025-07-17T16:19:32.568776675Z,2025-07-17T16:19:32.568611131Z,160,2,1108,C,A,13.720000000,2,0,346423105,0,165544,288512974,ARL
2025-07-17T16:19:32.568776675Z,2025-07-17T16:19:32.568611131Z,160,2,1108,A,A,13.980000000,2,0,347023061,130,165544,288512974,ARL
2025-07-17T16:19:32.568800112Z,2025-07-17T16:19:32.568634829Z,160,2,1108,C,A,15.820000000,100,0,347022817,0,165283,288512975,ARL
2025-07-17T16:19:32.568800112Z,2025-07-17T16:19:32.568634829Z,160,2,1108,A,A,16.080000000,100,0,347023065,130,165283,288512975,ARL
2025-07-17T16:19:32.586782162Z,2025-07-17T16:19:32.586617069Z,160,2,1108,C,A,14.030000000,100,0,347023005,130,165093,288513024,ARL
2025-07-17T16:19:32.586832073Z,2025-07-17T16:19:32.586666869Z,160,2,1108,A,A,14.250000000,100,0,347023197,130,165204,288513026,ARL
2025-07-17T16:19:32.597958839Z,2025-07-17T16:19:32.597793442Z,160,2,1108,C,A,14.820000000,100,0,347022737,0,165397,288513278,ARL
2025-07-17T16:19:32.597958839Z,2025-07-17T16:19:32.597793442Z,160,2,1108,A,A,15.050000000,100,0,347023333,130,165397,288513278,ARL
2025-07-17T16:19:32.602447841Z,2025-07-17T16:19:32.602282571Z,160,2,1108,A,A,14.680000000,700,0,347023357,130,165270,288513328,ARL
2025-07-17T16:19:32.706223822Z,2025-07-17T16:19:32.706057444Z,160,2,1108,A,A,14.530000000,100,0,347025333,0,166378,288514904,ARL
2025-07-17T16:19:32.706223822Z,2025-07-17T16:19:32.706057831Z,160,2,1108,C,A,14.010000000,100,0,345911213,130,165991,288514905,ARL
2025-07-17T16:19:32.857787299Z,2025-07-17T16:19:32.857621837Z,160,2,1108,A,A,14.810000000,100,0,347027121,130,165462,288516573,ARL
2025-07-17T16:19:32.857804235Z,2025-07-17T16:19:32.857638959Z,160,2,1108,C,A,14.280000000,100,0,345903265,130,165276,288516574,ARL
2025-07-17T16:19:32.887058748Z,2025-07-17T16:19:32.886893433Z,160,2,1108,A,A,13.990000000,100,0,347030085,130,165315,288519618,ARL
2025-07-17T16:19:33.241360545Z,2025-07-17T16:19:33.241195095Z,160,2,1108,C,A,14.360000000,100,0,347022741,130,165450,288533108,ARL
2025-07-17T16:19:33.241714286Z,2025-07-17T16:19:33.241548838Z,160,2,1108,A,A,14.600000000,100,0,347045237,130,165448,288533114,ARL
2025-07-17T16:19:33.550443222Z,2025-07-17T16:19:33.550277249Z,160,2,1108,C,A,14.540000000,100,0,347022789,130,165973,288537856,ARL
2025-07-17T16:19:33.550630659Z,2025-07-17T16:19:33.550465490Z,160,2,1108,A,A,14.770000000,100,0,347052337,130,165169,288537857,ARL
2025-07-17T16:19:42.789662492Z,2025-07-17T16:19:42.789496729Z,160,2,1108,C,B,12.950000000,2,0,346942181,0,165763,288669878,ARL
2025-07-17T16:19:42.789662492Z,2025-07-17T16:19:42.789496729Z,160,2,1108,A,B,13.030000000,2,0,347220093,130,165763,288669878,ARL
2025-07-17T16:19:50.837886219Z,2025-07-17T16:19:50.837720648Z,160,2,1108,A,A,13.440000000,15,0,347377693,130,165571,288783555,ARL
2025-07-17T16:19:51.986999699Z,2025-07-17T16:19:51.986834012Z,160,2,1108,C,A,13.990000000,100,0,347030085,0,165687,288797308,ARL
2025-07-17T16:19:51.986999699Z,2025-07-17T16:19:51.986834012Z,160,2,1108,A,A,13.450000000,100,0,347396033,130,165687,288797308,ARL
2025-07-17T16:19:51.987738024Z,2025-07-17T16:19:51.987571652Z,160,2,1108,C,A,14.600000000,100,0,347045237,128,166372,288797316,ARL
2025-07-17T16:19:51.987743715Z,2025-07-17T16:19:51.987578278Z,160,2,1108,C,A,15.050000000,100,0,347023333,0,165437,288797318,ARL
2025-07-17T16:19:51.987743715Z,2025-07-17T16:19:51.987578278Z,160,2,1108,A,A,14.490000000,100,0,347396065,130,165437,288797318,ARL
2025-07-17T16:19:51.988088818Z,2025-07-17T16:19:51.987923621Z,160,2,1108,A,A,14.050000000,100,0,347396069,130,165197,288797336,ARL
2025-07-17T16:19:51.988346300Z,2025-07-17T16:19:51.988180539Z,160,2,1108,C,A,15.130000000,100,0,347022753,0,165761,288797337,ARL
2025-07-17T16:19:51.988346300Z,2025-07-17T16:19:51.988180539Z,160,2,1108,A,A,14.800000000,100,0,347396073,130,165761,288797337,ARL
2025-07-17T16:19:51.989180674Z,2025-07-17T16:19:51.989015100Z,160,2,1108,C,A,14.960000000,100,0,347023045,0,165574,288797340,ARL
2025-07-17T16:19:51.989180674Z,2025-07-17T16:19:51.989015100Z,160,2,1108,A,A,14.400000000,100,0,347396085,130,165574,288797340,ARL
2025-07-17T16:19:51.990397633Z,2025-07-17T16:19:51.990232192Z,160,2,1108,C,A,17.750000000,100,0,347023037,0,165441,288797376,ARL
2025-07-17T16:19:51.990397633Z,2025-07-17T16:19:51.990232192Z,160,2,1108,A,A,17.090000000,100,0,347396125,130,165441,288797376,ARL
2025-07-17T16:19:51.990483745Z,2025-07-17T16:19:51.990318196Z,160,2,1108,C,A,16.080000000,100,0,347023065,0,165549,288797381,ARL
2025-07-17T16:19:51.990483745Z,2025-07-17T16:19:51.990318196Z,160,2,1108,A,A,15.470000000,100,0,347396129,130,165549,288797381,ARL
2025-07-17T16:19:51.990825106Z,2025-07-17T16:19:51.990659712Z,160,2,1108,C,A,13.980000000,2,0,347023061,0,165394,288797388,ARL
2025-07-17T16:19:51.990825106Z,2025-07-17T16:19:51.990659712Z,160,2,1108,A,A,13.860000000,2,0,347396177,130,165394,288797388,ARL
2025-07-17T16:19:52.000587632Z,2025-07-17T16:19:52.000421983Z,160,2,1108,C,A,14.250000000,100,0,347023197,130,165649,288797576,ARL
2025-07-17T16:19:52.000639640Z,2025-07-17T16:19:52.000474403Z,160,2,1108,A,A,13.720000000,100,0,347396369,130,165237,288797577,ARL
2025-07-17T16:19:52.002454838Z,2025-07-17T16:19:52.002289289Z,160,2,1108,C,A,15.130000000,100,0,347022865,0,165549,288797618,ARL
2025-07-17T16:19:52.002454838Z,2025-07-17T16:19:52.002289289Z,160,2,1108,A,A,14.800000000,100,0,347396405,130,165549,288797618,ARL
2025-07-17T16:19:52.007405432Z,2025-07-17T16:19:52.007240010Z,160,2,1108,C,A,14.950000000,100,0,347023021,0,165422,288797725,ARL
2025-07-17T16:19:52.007405432Z,2025-07-17T16:19:52.007240010Z,160,2,1108,A,A,14.400000000,100,0,347396549,130,165422,288797725,ARL
2025-07-17T16:19:52.033682506Z,2025-07-17T16:19:52.033517230Z,160,2,1108,A,A,15.340000000,100,0,347396797,130,165276,288797909,ARL
2025-07-17T16:19:52.033694906Z,2025-07-17T16:19:52.033529658Z,160,2,1108,C,A,15.680000000,100,0,347022705,130,165248,288797910,ARL
2025-07-17T16:19:52.051786264Z,2025-07-17T16:19:52.051620731Z,160,2,1108,C,A,14.770000000,100,0,347052337,0,165533,288798183,ARL
2025-07-17T16:19:52.051786264Z,2025-07-17T16:19:52.051620731Z,160,2,1108,A,A,14.240000000,100,0,347397201,130,165533,288798183,ARL
2025-07-17T16:19:52.565796243Z,2025-07-17T16:19:52.565630623Z,160,2,1108,A,A,14.250000000,100,0,347404325,130,165620,288804470,ARL
2025-07-17T16:19:52.565810193Z,2025-07-17T16:19:52.565644711Z,160,2,1108,C,A,14.810000000,100,0,347027121,130,165482,288804471,ARL
2025-07-17T16:19:52.662889593Z,2025-07-17T16:19:52.662723196Z,160,2,1108,A,A,13.980000000,100,0,347406169,0,166397,288807539,ARL
2025-07-17T16:19:52.662889593Z,2025-07-17T16:19:52.662723667Z,160,2,1108,C,A,14.530000000,100,0,347025333,130,165926,288807540,ARL
2025-07-17T16:19:53.670698618Z,2025-07-17T16:19:53.670533326Z,160,2,1108,C,A,13.450000000,100,0,347396033,130,165292,288824717,ARL
2025-07-17T16:19:53.671091071Z,2025-07-17T16:19:53.670925923Z,160,2,1108,A,A,15.650000000,100,0,347422209,130,165148,288824743,ARL
2025-07-17T16:19:53.671121526Z,2025-07-17T16:19:53.670956346Z,160,2,1108,C,A,15.340000000,100,0,347396797,130,165180,288824744,ARL
2025-07-17T16:19:53.671439851Z,2025-07-17T16:19:53.671274370Z,160,2,1108,C,A,14.490000000,100,0,347396065,0,165481,288824750,ARL
2025-07-17T16:19:53.671439851Z,2025-07-17T16:19:53.671274370Z,160,2,1108,A,A,14.550000000,100,0,347422221,130,165481,288824750,ARL
2025-07-17T16:19:53.671446392Z,2025-07-17T16:19:53.671281229Z,160,2,1108,C,A,14.050000000,100,0,347396069,130,165163,288824751,ARL
2025-07-17T16:19:53.671794970Z,2025-07-17T16:19:53.671629711Z,160,2,1108,A,A,14.330000000,100,0,347422225,130,165259,288824753,ARL
2025-07-17T16:19:53.672102714Z,2025-07-17T16:19:53.671937159Z,160,2,1108,C,A,14.800000000,100,0,347396073,0,165555,288824759,ARL
2025-07-17T16:19:53.672102714Z,2025-07-17T16:19:53.671937159Z,160,2,1108,A,A,15.100000000,100,0,347422237,130,165555,288824759,ARL
2025-07-17T16:19:53.672212827Z,2025-07-17T16:19:53.672047366Z,160,2,1108,C,A,15.470000000,100,0,347396129,0,165461,288824760,ARL
2025-07-17T16:19:53.672212827Z,2025-07-17T16:19:53.672047366Z,160,2,1108,A,A,15.780000000,100,0,347422241,130,165461,288824760,ARL
2025-07-17T16:19:53.673048826Z,2025-07-17T16:19:53.672883433Z,160,2,1108,C,A,14.400000000,100,0,347396085,0,165393,288824777,ARL
2025-07-17T16:19:53.673048826Z,2025-07-17T16:19:53.672883433Z,160,2,1108,A,A,14.690000000,100,0,347422245,130,165393,288824777,ARL
2025-07-17T16:19:53.673442999Z,2025-07-17T16:19:53.673277621Z,160,2,1108,C,A,14.240000000,100,0,347397201,130,165378,288824780,ARL
2025-07-17T16:19:53.673563265Z,2025-07-17T16:19:53.673398019Z,160,2,1108,A,A,14.510000000,100,0,347422249,130,165246,288824781,ARL
2025-07-17T16:19:53.673762180Z,2025-07-17T16:19:53.673596490Z,160,2,1108,C,A,17.090000000,100,0,347396125,0,165690,288824783,ARL
2025-07-17T16:19:53.673762180Z,2025-07-17T16:19:53.673596490Z,160,2,1108,A,A,17.430000000,100,0,347422253,130,165690,288824783,ARL
2025-07-17T16:19:53.675414447Z,2025-07-17T16:19:53.675249213Z,160,2,1108,C,A,13.720000000,100,0,347396369,130,165234,288824805,ARL
2025-07-17T16:19:53.675466833Z,2025-07-17T16:19:53.675301684Z,160,2,1108,A,A,13.990000000,100,0,347422265,130,165149,288824807,ARL
2025-07-17T16:19:53.675513622Z,2025-07-17T16:19:53.675348484Z,160,2,1108,A,A,15.940000000,100,0,347422273,130,165138,288824808,ARL
2025-07-17T16:19:53.675525392Z,2025-07-17T16:19:53.675360245Z,160,2,1108,C,A,15.650000000,100,0,347422209,130,165147,288824809,ARL
2025-07-17T16:19:53.676268880Z,2025-07-17T16:19:53.676103642Z,160,2,1108,C,A,15.780000000,100,0,347422241,0,165238,288824817,ARL
2025-07-17T16:19:53.676268880Z,2025-07-17T16:19:53.676103642Z,160,2,1108,A,A,16.040000000,100,0,347422301,130,165238,288824817,ARL
2025-07-17T16:19:53.677094265Z,2025-07-17T16:19:53.676928854Z,160,2,1108,C,A,14.690000000,100,0,347422245,0,165411,288824819,ARL
2025-07-17T16:19:53.677094265Z,2025-07-17T16:19:53.676928854Z,160,2,1108,A,A,14.960000000,100,0,347422321,130,165411,288824819,ARL
2025-07-17T16:19:53.677815834Z,2025-07-17T16:19:53.677650753Z,160,2,1108,C,A,17.430000000,100,0,347422253,0,165081,288824868,ARL
2025-07-17T16:19:53.677815834Z,2025-07-17T16:19:53.677650753Z,160,2,1108,A,A,17.760000000,100,0,347422329,130,165081,288824868,ARL
2025-07-17T16:19:53.679633024Z,2025-07-17T16:19:53.679468070Z,160,2,1108,C,A,13.990000000,100,0,347422265,130,164954,288824919,ARL
2025-07-17T16:19:53.679682575Z,2025-07-17T16:19:53.679517110Z,160,2,1108,A,A,14.220000000,100,0,347422365,130,165465,288824921,ARL
2025-07-17T16:19:53.693584804Z,2025-07-17T16:19:53.693419327Z,160,2,1108,C,A,14.800000000,100,0,347396405,0,165477,288825303,ARL
2025-07-17T16:19:53.693584804Z,2025-07-17T16:19:53.693419327Z,160,2,1108,A,A,15.380000000,100,0,347422849,130,165477,288825303,ARL
2025-07-17T16:19:53.718084751Z,2025-07-17T16:19:53.717918994Z,160,2,1108,C,A,14.400000000,100,0,347396549,0,165757,288827326,ARL
2025-07-17T16:19:53.718084751Z,2025-07-17T16:19:53.717918994Z,160,2,1108,A,A,14.960000000,100,0,347425145,130,165757,288827326,ARL
2025-07-17T16:19:53.721565807Z,2025-07-17T16:19:53.721400029Z,160,2,1108,C,A,14.550000000,100,0,347422221,0,165778,288827785,ARL
2025-07-17T16:19:53.721565807Z,2025-07-17T16:19:53.721400029Z,160,2,1108,A,A,15.060000000,100,0,347426113,130,165778,288827785,ARL
2025-07-17T16:19:54.211864515Z,2025-07-17T16:19:54.211699263Z,160,2,1108,A,A,14.810000000,100,0,347437117,130,165252,288836874,ARL
2025-07-17T16:19:54.211876077Z,2025-07-17T16:19:54.211710788Z,160,2,1108,C,A,14.250000000,100,0,347404325,130,165289,288836876,ARL
2025-07-17T16:19:54.248985468Z,2025-07-17T16:19:54.248820201Z,160,2,1108,C,A,14.330000000,100,0,347422225,130,165267,288837261,ARL
2025-07-17T16:19:54.249335716Z,2025-07-17T16:19:54.249170165Z,160,2,1108,A,A,14.600000000,100,0,347437857,130,165551,288837262,ARL
2025-07-17T16:19:54.601852935Z,2025-07-17T16:19:54.601687713Z,160,2,1108,C,A,13.980000000,100,0,347406169,130,165222,288841783,ARL
2025-07-17T16:19:54.601853940Z,2025-07-17T16:19:54.601688695Z,160,2,1108,A,A,14.530000000,100,0,347443097,130,165245,288841784,ARL
2025-07-17T16:19:54.677250454Z,2025-07-17T16:19:54.677084975Z,160,2,1108,C,A,14.510000000,100,0,347422249,0,165479,288842530,ARL
2025-07-17T16:19:54.677250454Z,2025-07-17T16:19:54.677084975Z,160,2,1108,A,A,14.770000000,100,0,347444385,130,165479,288842530,ARL
2025-07-17T16:19:54.919087937Z,2025-07-17T16:19:54.918922624Z,160,2,1108,A,A,13.870000000,100,0,347449521,130,165313,288846635,ARL
2025-07-17T16:19:54.919821816Z,2025-07-17T16:19:54.919656438Z,160,2,1108,C,A,15.060000000,100,0,347426113,0,165378,288846645,ARL
2025-07-17T16:19:54.919821816Z,2025-07-17T16:19:54.919656438Z,160,2,1108,A,A,14.950000000,100,0,347449549,130,165378,288846645,ARL
2025-07-17T16:19:54.942941458Z,2025-07-17T16:19:54.942776198Z,160,2,1108,C,A,14.220000000,100,0,347422365,130,165260,288847105,ARL
2025-07-17T16:19:54.942998015Z,2025-07-17T16:19:54.942832705Z,160,2,1108,A,A,14.150000000,100,0,347449893,130,165310,288847115,ARL
2025-07-17T16:20:02.838461207Z,2025-07-17T16:20:02.838295810Z,160,2,1108,A,A,13.400000000,15,0,347592441,130,165397,288958120,ARL
2025-07-17T16:20:03.544957156Z,2025-07-17T16:20:03.544791773Z,160,2,1108,C,A,13.870000000,100,0,347449521,0,165383,288969245,ARL
2025-07-17T16:20:03.544957156Z,2025-07-17T16:20:03.544791773Z,160,2,1108,A,A,13.450000000,100,0,347605041,130,165383,288969245,ARL
2025-07-17T16:20:03.545692221Z,2025-07-17T16:20:03.545526427Z,160,2,1108,C,A,14.950000000,100,0,347449549,0,165794,288969257,ARL
2025-07-17T16:20:03.545692221Z,2025-07-17T16:20:03.545526427Z,160,2,1108,A,A,14.490000000,100,0,347605073,130,165794,288969257,ARL
2025-07-17T16:20:03.545693843Z,2025-07-17T16:20:03.545528318Z,160,2,1108,C,A,14.600000000,100,0,347437857,130,165525,288969258,ARL
2025-07-17T16:20:03.546047231Z,2025-07-17T16:20:03.545881983Z,160,2,1108,A,A,14.050000000,100,0,347605081,130,165248,288969265,ARL
2025-07-17T16:20:03.546381253Z,2025-07-17T16:20:03.546215424Z,160,2,1108,C,A,15.100000000,100,0,347422237,0,165829,288969267,ARL
2025-07-17T16:20:03.546381253Z,2025-07-17T16:20:03.546215424Z,160,2,1108,A,A,14.800000000,100,0,347605085,130,165829,288969267,ARL
2025-07-17T16:20:03.547098908Z,2025-07-17T16:20:03.546933285Z,160,2,1108,C,A,17.760000000,100,0,347422329,0,165623,288969279,ARL
2025-07-17T16:20:03.547098908Z,2025-07-17T16:20:03.546933285Z,160,2,1108,A,A,17.090000000,100,0,347605101,130,165623,288969279,ARL
2025-07-17T16:20:03.547495212Z,2025-07-17T16:20:03.547329771Z,160,2,1108,C,A,16.040000000,100,0,347422301,0,165441,288969284,ARL
2025-07-17T16:20:03.547495212Z,2025-07-17T16:20:03.547329771Z,160,2,1108,A,A,15.470000000,100,0,347605105,130,165441,288969284,ARL
2025-07-17T16:20:03.547722218Z,2025-07-17T16:20:03.547556902Z,160,2,1108,C,A,14.960000000,100,0,347422321,0,165316,288969290,ARL
2025-07-17T16:20:03.547722218Z,2025-07-17T16:20:03.547556902Z,160,2,1108,A,A,14.400000000,100,0,347605109,130,165316,288969290,ARL
2025-07-17T16:20:03.551397729Z,2025-07-17T16:20:03.551232289Z,160,2,1108,C,A,15.380000000,100,0,347422849,0,165440,288969331,ARL
2025-07-17T16:20:03.551397729Z,2025-07-17T16:20:03.551232289Z,160,2,1108,A,A,14.800000000,100,0,347605169,130,165440,288969331,ARL
2025-07-17T16:20:03.558022065Z,2025-07-17T16:20:03.557856817Z,160,2,1108,C,A,14.150000000,100,0,347449893,130,165248,288969562,ARL
2025-07-17T16:20:03.558074886Z,2025-07-17T16:20:03.557909645Z,160,2,1108,A,A,13.720000000,100,0,347605397,130,165241,288969565,ARL
2025-07-17T16:20:03.569904581Z,2025-07-17T16:20:03.569738711Z,160,2,1108,C,A,14.960000000,100,0,347425145,0,165870,288969738,ARL
2025-07-17T16:20:03.569904581Z,2025-07-17T16:20:03.569738711Z,160,2,1108,A,A,14.400000000,100,0,347605617,130,165870,288969738,ARL
2025-07-17T16:20:03.592801539Z,2025-07-17T16:20:03.592636279Z,160,2,1108,C,A,14.770000000,100,0,347444385,130,165260,288970208,ARL
2025-07-17T16:20:03.592903833Z,2025-07-17T16:20:03.592738507Z,160,2,1108,A,A,14.240000000,100,0,347605969,130,165326,288970211,ARL
2025-07-17T16:20:03.592933652Z,2025-07-17T16:20:03.592768402Z,160,2,1108,A,A,15.340000000,100,0,347605973,130,165250,288970212,ARL
2025-07-17T16:20:03.592946817Z,2025-07-17T16:20:03.592781399Z,160,2,1108,C,A,15.940000000,100,0,347422273,130,165418,288970213,ARL
2025-07-17T16:20:04.069659336Z,2025-07-17T16:20:04.069494130Z,160,2,1108,C,A,14.530000000,100,0,347443097,130,165206,288977268,ARL
2025-07-17T16:20:04.069661713Z,2025-07-17T16:20:04.069496437Z,160,2,1108,A,A,13.980000000,100,0,347613877,130,165276,288977269,ARL
2025-07-17T16:20:04.111795639Z,2025-07-17T16:20:04.111630484Z,160,2,1108,A,A,14.250000000,100,0,347615553,130,165155,288978560,ARL
2025-07-17T16:20:04.111808972Z,2025-07-17T16:20:04.111643490Z,160,2,1108,C,A,14.810000000,100,0,347437117,130,165482,288978561,ARL
2025-07-17T16:20:07.945427285Z,2025-07-17T16:20:07.945262120Z,160,2,1108,C,A,13.440000000,15,0,347377693,130,165165,289031160,ARL
2025-07-17T16:20:08.949407416Z,2025-07-17T16:20:08.949241997Z,160,2,1108,A,A,13.360000000,15,0,347710393,130,165419,289046760,ARL
2025-07-17T16:20:09.428817232Z,2025-07-17T16:20:09.428650758Z,160,2,1108,A,A,14.170000000,700,0,347717317,130,166474,289052533,ARL
2025-07-17T16:20:09.428874375Z,2025-07-17T16:20:09.428709003Z,160,2,1108,C,A,14.680000000,700,0,347023357,130,165372,289052534,ARL
2025-07-17T16:20:09.704859787Z,2025-07-17T16:20:09.704693450Z,160,2,1108,C,A,13.860000000,2,0,347396177,0,166337,289057887,ARL
2025-07-17T16:20:09.704859787Z,2025-07-17T16:20:09.704693450Z,160,2,1108,A,A,13.780000000,2,0,347722857,128,166337,289057887,ARL
2025-07-17T16:20:11.608367693Z,2025-07-17T16:20:11.608202073Z,160,2,1108,C,A,14.350000000,100,0,344593405,0,165620,289085339,ARL
2025-07-17T16:20:11.608367693Z,2025-07-17T16:20:11.608202073Z,160,2,1108,A,A,14.240000000,100,0,347760469,130,165620,289085339,ARL
2025-07-17T16:20:11.608472767Z,2025-07-17T16:20:11.608307409Z,160,2,1108,C,A,14.350000000,100,0,344593409,0,165358,289085342,ARL
2025-07-17T16:20:11.608472767Z,2025-07-17T16:20:11.608307409Z,160,2,1108,A,A,14.240000000,100,0,347760485,130,165358,289085342,ARL
2025-07-17T16:20:20.588044932Z,2025-07-17T16:20:20.587879078Z,160,2,1108,C,A,13.780000000,2,0,347722857,0,165854,289232518,ARL
2025-07-17T16:20:20.588044932Z,2025-07-17T16:20:20.587879078Z,160,2,1108,A,A,13.710000000,2,0,347935421,130,165854,289232518,ARL
2025-07-17T16:20:20.839245229Z,2025-07-17T16:20:20.839080003Z,160,2,1108,C,A,13.400000000,15,0,347592441,130,165226,289235324,ARL
2025-07-17T16:20:21.839565900Z,2025-07-17T16:20:21.839400050Z,160,2,1108,A,A,13.330000000,15,0,347961173,130,165850,289253047,ARL
2025-07-17T16:20:27.448533855Z,2025-07-17T16:20:27.448368575Z,160,2,1108,C,A,13.360000000,15,0,347710393,130,165280,289339972,ARL
2025-07-17T16:20:28.452553412Z,2025-07-17T16:20:28.452388023Z,160,2,1108,A,A,13.310000000,15,0,348099617,130,165389,289367352,ARL
2025-07-17T16:20:31.453437816Z,2025-07-17T16:20:31.453272244Z,160,2,1108,C,A,13.330000000,15,0,347961173,130,165572,289452005,ARL
2025-07-17T16:20:42.838073701Z,2025-07-17T16:20:42.837908349Z,160,2,1108,A,A,13.290000000,15,0,348428649,130,165352,289627630,ARL
2025-07-17T16:20:56.875524789Z,2025-07-17T16:20:56.875359282Z,160,2,1108,C,B,13.030000000,2,0,347220093,0,165507,289958017,ARL
2025-07-17T16:20:56.875524789Z,2025-07-17T16:20:56.875359282Z,160,2,1108,A,B,12.960000000,2,0,348838809,130,165507,289958017,ARL
2025-07-17T16:21:03.027643943Z,2025-07-17T16:21:03.027478065Z,160,2,1108,C,A,13.310000000,15,0,348099617,130,165878,290149718,ARL
2025-07-17T16:21:03.786334915Z,2025-07-17T16:21:03.786169333Z,160,2,1108,C,A,13.710000000,2,0,347935421,0,165582,290172493,ARL
2025-07-17T16:21:03.786334915Z,2025-07-17T16:21:03.786169333Z,160,2,1108,A,A,13.650000000,2,0,349094877,130,165582,290172493,ARL
2025-07-17T16:21:04.031563260Z,2025-07-17T16:21:04.031397539Z,160,2,1108,A,A,13.270000000,15,0,349100269,130,165721,290175495,ARL
2025-07-17T16:21:04.035799229Z,2025-07-17T16:21:04.035632459Z,160,2,1108,T,B,13.270000000,15,0,0,128,166770,290175561,ARL
2025-07-17T16:21:04.035799229Z,2025-07-17T16:21:04.035632459Z,160,2,1108,F,A,13.270000000,15,0,349100269,128,166770,290175561,ARL
2025-07-17T16:21:04.035799229Z,2025-07-17T16:21:04.035632459Z,160,2,1108,C,A,13.270000000,15,0,349100269,128,166770,290175561,ARL
2025-07-17T16:21:04.035825836Z,2025-07-17T16:21:04.035660519Z,160,2,1108,A,B,13.140000000,11,0,349100461,130,165317,290175563,ARL
