,ts_recv,ts_event,rtype,publisher_id,instrument_id,action,side,depth,price,size,flags,ts_in_delta,sequence,bid_px_00,bid_sz_00,bid_ct_00,ask_px_00,ask_sz_00,ask_ct_00,bid_px_01,bid_sz_01,bid_ct_01,ask_px_01,ask_sz_01,ask_ct_01,bid_px_02,bid_sz_02,bid_ct_02,ask_px_02,ask_sz_02,ask_ct_02,bid_px_03,bid_sz_03,bid_ct_03,ask_px_03,ask_sz_03,ask_ct_03,bid_px_04,bid_sz_04,bid_ct_04,ask_px_04,ask_sz_04,ask_ct_04,bid_px_05,bid_sz_05,bid_ct_05,ask_px_05,ask_sz_05,ask_ct_05,bid_px_06,bid_sz_06,bid_ct_06,ask_px_06,ask_sz_06,ask_ct_06,bid_px_07,bid_sz_07,bid_ct_07,ask_px_07,ask_sz_07,ask_ct_07,bid_px_08,bid_sz_08,bid_ct_08,ask_px_08,ask_sz_08,ask_ct_08,bid_px_09,bid_sz_09,bid_ct_09,ask_px_09,ask_sz_09,ask_ct_09,symbol,order_id
1522,2025-07-17T15:58:51.241176997Z,2025-07-17T15:58:51.241176997Z,10,2,1108,C,A,0,13.8900,15,130,165268,268212338,13.0399,2,1,13.8300,115,2,13.0299,100,1,13.8399,100,1,13.0199,100,1,14.0999,2,1,12.7300,100,1,14.1099,100,1,12.7100,100,1,14.2799,100,1,12.5000,700,1,14.4000,100,1,12.4600,200,2,14.5600,800,2,12.4299,700,1,14.5999,700,1,12.4199,700,1,14.6799,1400,2,12.3699,700,1,14.7200,100,1,ARL,320833897
1523,2025-07-17T15:58:51.253961905Z,2025-07-17T15:58:51.253961905Z,10,2,1108,A,A,0,13.8000,100,130,165434,268212497,13.0399,2,1,13.8000,100,1,13.0299,100,1,13.8300,115,2,13.0199,100,1,13.8399,100,1,12.7300,100,1,14.0999,2,1,12.7100,100,1,14.1099,100,1,12.5000,700,1,14.2799,100,1,12.4600,200,2,14.4000,100,1,12.4299,700,1,14.5600,800,2,12.4199,700,1,14.5999,700,1,12.3699,700,1,14.6799,1400,2,ARL,321225725
1524,2025-07-17T15:58:51.254706004Z,2025-07-17T15:58:51.254706004Z,10,2,1108,C,A,0,14.9100,100,0,165886,268212499,13.0399,2,1,13.8000,100,1,13.0299,100,1,13.8300,115,2,13.0199,100,1,13.8399,100,1,12.7300,100,1,14.0999,2,1,12.7100,100,1,14.1099,100,1,12.5000,700,1,14.2799,100,1,12.4600,200,2,14.4000,100,1,12.4299,700,1,14.5600,800,2,12.4199,700,1,14.5999,700,1,12.3699,700,1,14.6799,1400,2,ARL,321096793
1525,2025-07-17T15:58:51.254706004Z,2025-07-17T15:58:51.254706004Z,10,2,1108,A,A,0,14.8699,100,130,165886,268212499,13.0399,2,1,13.8000,100,1,13.0299,100,1,13.8300,115,2,13.0199,100,1,13.8399,100,1,12.7300,100,1,14.0999,2,1,12.7100,100,1,14.1099,100,1,12.5000,700,1,14.2799,100,1,12.4600,200,2,14.4000,100,1,12.4299,700,1,14.5600,800,2,12.4199,700,1,14.5999,700,1,12.3699,700,1,14.6799,1400,2,ARL,321225745
1526,2025-07-17T15:58:51.260587778Z,2025-07-17T15:58:51.260587778Z,10,2,1108,C,A,0,13.8300,100,130,165401,268212534,13.0399,2,1,13.8000,100,1,13.0299,100,1,13.8300,15,1,13.0199,100,1,13.8399,100,1,12.7300,100,1,14.0999,2,1,12.7100,100,1,14.1099,100,1,12.5000,700,1,14.2799,100,1,12.4600,200,2,14.4000,100,1,12.4299,700,1,14.5600,800,2,12.4199,700,1,14.5999,700,1,12.3699,700,1,14.6799,1400,2,ARL,321114473
1527,2025-07-17T15:58:53.579462029Z,2025-07-17T15:58:53.579462029Z,10,2,1108,C,A,0,13.8300,15,130,166259,268250290,13.0399,2,1,13.8000,100,1,13.0299,100,1,13.8399,100,1,13.0199,100,1,14.0999,2,1,12.7300,100,1,14.1099,100,1,12.7100,100,1,14.2799,100,1,12.5000,700,1,14.4000,100,1,12.4600,200,2,14.5600,800,2,12.4299,700,1,14.5999,700,1,12.4199,700,1,14.6799,1400,2,12.3699,700,1,14.7200,100,1,ARL,321038033
1528,2025-07-17T15:58:53.580052014Z,2025-07-17T15:58:53.580052014Z,10,2,1108,C,A,0,13.8399,100,0,165431,268250346,13.0399,2,1,13.8000,100,1,13.0299,100,1,14.0999,2,1,13.0199,100,1,14.1099,100,1,12.7300,100,1,14.2799,100,1,12.7100,100,1,14.4000,100,1,12.5000,700,1,14.5600,800,2,12.4600,200,2,14.5999,700,1,12.4299,700,1,14.6799,1400,2,12.4199,700,1,14.7200,100,1,12.3699,700,1,14.7599,100,1,ARL,321096769
1529,2025-07-17T15:58:53.580052014Z,2025-07-17T15:58:53.580052014Z,10,2,1108,A,A,0,13.8100,100,130,165431,268250346,13.0399,2,1,13.8000,100,1,13.0299,100,1,13.8100,100,1,13.0199,100,1,14.0999,2,1,12.7300,100,1,14.1099,100,1,12.7100,100,1,14.2799,100,1,12.5000,700,1,14.4000,100,1,12.4600,200,2,14.5600,800,2,12.4299,700,1,14.5999,700,1,12.4199,700,1,14.6799,1400,2,12.3699,700,1,14.7200,100,1,ARL,321272581
1530,2025-07-17T15:58:54.583958582Z,2025-07-17T15:58:54.583958582Z,10,2,1108,C,A,0,14.7699,100,0,165633,268265585,13.0399,2,1,13.8000,100,1,13.0299,100,1,13.8100,100,1,13.0199,100,1,14.0999,2,1,12.7300,100,1,14.1099,100,1,12.7100,100,1,14.2799,100,1,12.5000,700,1,14.4000,100,1,12.4600,200,2,14.5600,800,2,12.4299,700,1,14.5999,700,1,12.4199,700,1,14.6799,1400,2,12.3699,700,1,14.7200,100,1,ARL,320846429
1531,2025-07-17T15:58:54.583958582Z,2025-07-17T15:58:54.583958582Z,10,2,1108,A,A,0,14.6500,100,130,165633,268265585,13.0399,2,1,13.8000,100,1,13.0299,100,1,13.8100,100,1,13.0199,100,1,14.0999,2,1,12.7300,100,1,14.1099,100,1,12.7100,100,1,14.2799,100,1,12.5000,700,1,14.4000,100,1,12.4600,200,2,14.5600,800,2,12.4299,700,1,14.5999,700,1,12.4199,700,1,14.6500,100,1,12.3699,700,1,14.6799,1400,2,ARL,321293737
1532,2025-07-17T15:58:54.584094980Z,2025-07-17T15:58:54.584094980Z,10,2,1108,C,A,0,14.7599,100,0,165732,268265586,13.0399,2,1,13.8000,100,1,13.0299,100,1,13.8100,100,1,13.0199,100,1,14.0999,2,1,12.7300,100,1,14.1099,100,1,12.7100,100,1,14.2799,100,1,12.5000,700,1,14.4000,100,1,12.4600,200,2,14.5600,800,2,12.4299,700,1,14.5999,700,1,12.4199,700,1,14.6500,100,1,12.3699,700,1,14.6799,1400,2,ARL,320845893
1533,2025-07-17T15:58:54.584094980Z,2025-07-17T15:58:54.584094980Z,10,2,1108,A,A,0,14.6400,100,130,165732,268265586,13.0399,2,1,13.8000,100,1,13.0299,100,1,13.8100,100,1,13.0199,100,1,14.0999,2,1,12.7300,100,1,14.1099,100,1,12.7100,100,1,14.2799,100,1,12.5000,700,1,14.4000,100,1,12.4600,200,2,14.5600,800,2,12.4299,700,1,14.5999,700,1,12.4199,700,1,14.6400,100,1,12.3699,700,1,14.6500,100,1,ARL,321293741
1534,2025-07-17T15:58:55.304938318Z,2025-07-17T15:58:55.304938318Z,10,2,1108,A,A,0,13.7799,100,130,165711,268277940,13.0399,2,1,13.7799,100,1,13.0299,100,1,13.8000,100,1,13.0199,100,1,13.8100,100,1,12.7300,100,1,14.0999,2,1,12.7100,100,1,14.1099,100,1,12.5000,700,1,14.2799,100,1,12.4600,200,2,14.4000,100,1,12.4299,700,1,14.5600,800,2,12.4199,700,1,14.5999,700,1,12.3699,700,1,14.6400,100,1,ARL,321309865
1535,2025-07-17T15:58:55.307342971Z,2025-07-17T15:58:55.307342971Z,10,2,1108,C,A,0,14.7200,100,130,165334,268277999,13.0399,2,1,13.7799,100,1,13.0299,100,1,13.8000,100,1,13.0199,100,1,13.8100,100,1,12.7300,100,1,14.0999,2,1,12.7100,100,1,14.1099,100,1,12.5000,700,1,14.2799,100,1,12.4600,200,2,14.4000,100,1,12.4299,700,1,14.5600,800,2,12.4199,700,1,14.5999,700,1,12.3699,700,1,14.6400,100,1,ARL,312772061
1536,2025-07-17T15:58:55.307472032Z,2025-07-17T15:58:55.307472032Z,10,2,1108,A,A,0,14.5800,100,130,165177,268278004,13.0399,2,1,13.7799,100,1,13.0299,100,1,13.8000,100,1,13.0199,100,1,13.8100,100,1,12.7300,100,1,14.0999,2,1,12.7100,100,1,14.1099,100,1,12.5000,700,1,14.2799,100,1,12.4600,200,2,14.4000,100,1,12.4299,700,1,14.5600,800,2,12.4199,700,1,14.5800,100,1,12.3699,700,1,14.5999,700,1,ARL,321309941
1537,2025-07-17T15:58:55.311734700Z,2025-07-17T15:58:55.311734700Z,10,2,1108,C,A,0,13.8000,100,130,165265,268278030,13.0399,2,1,13.7799,100,1,13.0299,100,1,13.8100,100,1,13.0199,100,1,14.0999,2,1,12.7300,100,1,14.1099,100,1,12.7100,100,1,14.2799,100,1,12.5000,700,1,14.4000,100,1,12.4600,200,2,14.5600,800,2,12.4299,700,1,14.5800,100,1,12.4199,700,1,14.5999,700,1,12.3699,700,1,14.6400,100,1,ARL,321225725
1538,2025-07-17T15:58:58.668086788Z,2025-07-17T15:58:58.668086788Z,10,2,1108,C,A,0,13.8100,100,0,165518,268321684,13.0399,2,1,13.7799,100,1,13.0299,100,1,14.0999,2,1,13.0199,100,1,14.1099,100,1,12.7300,100,1,14.2799,100,1,12.7100,100,1,14.4000,100,1,12.5000,700,1,14.5600,800,2,12.4600,200,2,14.5800,100,1,12.4299,700,1,14.5999,700,1,12.4199,700,1,14.6400,100,1,12.3699,700,1,14.6500,100,1,ARL,321272581
1539,2025-07-17T15:58:58.668086788Z,2025-07-17T15:58:58.668086788Z,10,2,1108,A,A,0,13.7899,100,130,165518,268321684,13.0399,2,1,13.7799,100,1,13.0299,100,1,13.7899,100,1,13.0199,100,1,14.0999,2,1,12.7300,100,1,14.1099,100,1,12.7100,100,1,14.2799,100,1,12.5000,700,1,14.4000,100,1,12.4600,200,2,14.5600,800,2,12.4299,700,1,14.5800,100,1,12.4199,700,1,14.5999,700,1,12.3699,700,1,14.6400,100,1,ARL,321364281
1540,2025-07-17T15:59:03.613527621Z,2025-07-17T15:59:03.613527621Z,10,2,1108,A,A,0,13.7200,15,130,165292,268437919,13.0399,2,1,13.7200,15,1,13.0299,100,1,13.7799,100,1,13.0199,100,1,13.7899,100,1,12.7300,100,1,14.0999,2,1,12.7100,100,1,14.1099,100,1,12.5000,700,1,14.2799,100,1,12.4600,200,2,14.4000,100,1,12.4299,700,1,14.5600,800,2,12.4199,700,1,14.5800,100,1,12.3699,700,1,14.5999,700,1,ARL,321500117
1541,2025-07-17T15:59:03.626181384Z,2025-07-17T15:59:03.626181384Z,10,2,1108,A,A,0,13.7599,100,130,165232,268438110,13.0399,2,1,13.7200,15,1,13.0299,100,1,13.7599,100,1,13.0199,100,1,13.7799,100,1,12.7300,100,1,13.7899,100,1,12.7100,100,1,14.0999,2,1,12.5000,700,1,14.1099,100,1,12.4600,200,2,14.2799,100,1,12.4299,700,1,14.4000,100,1,12.4199,700,1,14.5600,800,2,12.3699,700,1,14.5800,100,1,ARL,321500317
1542,2025-07-17T15:59:03.626920954Z,2025-07-17T15:59:03.626920954Z,10,2,1108,C,A,0,14.8699,100,0,165934,268438112,13.0399,2,1,13.7200,15,1,13.0299,100,1,13.7599,100,1,13.0199,100,1,13.7799,100,1,12.7300,100,1,13.7899,100,1,12.7100,100,1,14.0999,2,1,12.5000,700,1,14.1099,100,1,12.4600,200,2,14.2799,100,1,12.4299,700,1,14.4000,100,1,12.4199,700,1,14.5600,800,2,12.3699,700,1,14.5800,100,1,ARL,321225745
1543,2025-07-17T15:59:03.626920954Z,2025-07-17T15:59:03.626920954Z,10,2,1108,A,A,0,14.8300,100,130,165934,268438112,13.0399,2,1,13.7200,15,1,13.0299,100,1,13.7599,100,1,13.0199,100,1,13.7799,100,1,12.7300,100,1,13.7899,100,1,12.7100,100,1,14.0999,2,1,12.5000,700,1,14.1099,100,1,12.4600,200,2,14.2799,100,1,12.4299,700,1,14.4000,100,1,12.4199,700,1,14.5600,800,2,12.3699,700,1,14.5800,100,1,ARL,321500333
1544,2025-07-17T15:59:03.628779364Z,2025-07-17T15:59:03.628779364Z,10,2,1108,C,A,0,14.8900,100,0,165914,268438129,13.0399,2,1,13.7200,15,1,13.0299,100,1,13.7599,100,1,13.0199,100,1,13.7799,100,1,12.7300,100,1,13.7899,100,1,12.7100,100,1,14.0999,2,1,12.5000,700,1,14.1099,100,1,12.4600,200,2,14.2799,100,1,12.4299,700,1,14.4000,100,1,12.4199,700,1,14.5600,800,2,12.3699,700,1,14.5800,100,1,ARL,312771785
1545,2025-07-17T15:59:03.628779364Z,2025-07-17T15:59:03.628779364Z,10,2,1108,A,A,0,14.7300,100,130,165914,268438129,13.0399,2,1,13.7200,15,1,13.0299,100,1,13.7599,100,1,13.0199,100,1,13.7799,100,1,12.7300,100,1,13.7899,100,1,12.7100,100,1,14.0999,2,1,12.5000,700,1,14.1099,100,1,12.4600,200,2,14.2799,100,1,12.4299,700,1,14.4000,100,1,12.4199,700,1,14.5600,800,2,12.3699,700,1,14.5800,100,1,ARL,321500349
1546,2025-07-17T15:59:03.632928023Z,2025-07-17T15:59:03.632928023Z,10,2,1108,C,A,0,13.7799,100,130,165235,268438149,13.0399,2,1,13.7200,15,1,13.0299,100,1,13.7599,100,1,13.0199,100,1,13.7899,100,1,12.7300,100,1,14.0999,2,1,12.7100,100,1,14.1099,100,1,12.5000,700,1,14.2799,100,1,12.4600,200,2,14.4000,100,1,12.4299,700,1,14.5600,800,2,12.4199,700,1,14.5800,100,1,12.3699,700,1,14.5999,700,1,ARL,321309865
1547,2025-07-17T15:59:03.649116452Z,2025-07-17T15:59:03.649116452Z,10,2,1108,C,A,0,14.1099,100,130,165611,268438330,13.0399,2,1,13.7200,15,1,13.0299,100,1,13.7599,100,1,13.0199,100,1,13.7899,100,1,12.7300,100,1,14.0999,2,1,12.7100,100,1,14.2799,100,1,12.5000,700,1,14.4000,100,1,12.4600,200,2,14.5600,800,2,12.4299,700,1,14.5800,100,1,12.4199,700,1,14.5999,700,1,12.3699,700,1,14.6400,100,1,ARL,321114729
1548,2025-07-17T15:59:03.649167617Z,2025-07-17T15:59:03.649167617Z,10,2,1108,A,A,0,14.0399,100,130,165256,268438331,13.0399,2,1,13.7200,15,1,13.0299,100,1,13.7599,100,1,13.0199,100,1,13.7899,100,1,12.7300,100,1,14.0399,100,1,12.7100,100,1,14.0999,2,1,12.5000,700,1,14.2799,100,1,12.4600,200,2,14.4000,100,1,12.4299,700,1,14.5600,800,2,12.4199,700,1,14.5800,100,1,12.3699,700,1,14.5999,700,1,ARL,321500957
1549,2025-07-17T15:59:04.223835151Z,2025-07-17T15:59:04.223835151Z,10,2,1108,C,A,0,13.7899,100,0,165654,268447989,13.0399,2,1,13.7200,15,1,13.0299,100,1,13.7599,100,1,13.0199,100,1,14.0399,100,1,12.7300,100,1,14.0999,2,1,12.7100,100,1,14.2799,100,1,12.5000,700,1,14.4000,100,1,12.4600,200,2,14.5600,800,2,12.4299,700,1,14.5800,100,1,12.4199,700,1,14.5999,700,1,12.3699,700,1,14.6400,100,1,ARL,321364281
1550,2025-07-17T15:59:04.223835151Z,2025-07-17T15:59:04.223835151Z,10,2,1108,A,A,0,13.7300,100,130,165654,268447989,13.0399,2,1,13.7200,15,1,13.0299,100,1,13.7300,100,1,13.0199,100,1,13.7599,100,1,12.7300,100,1,14.0399,100,1,12.7100,100,1,14.0999,2,1,12.5000,700,1,14.2799,100,1,12.4600,200,2,14.4000,100,1,12.4299,700,1,14.5600,800,2,12.4199,700,1,14.5800,100,1,12.3699,700,1,14.5999,700,1,ARL,321511377
1551,2025-07-17T15:59:04.224583946Z,2025-07-17T15:59:04.224583946Z,10,2,1108,C,A,0,14.8300,100,0,165387,268448014,13.0399,2,1,13.7200,15,1,13.0299,100,1,13.7300,100,1,13.0199,100,1,13.7599,100,1,12.7300,100,1,14.0399,100,1,12.7100,100,1,14.0999,2,1,12.5000,700,1,14.2799,100,1,12.4600,200,2,14.4000,100,1,12.4299,700,1,14.5600,800,2,12.4199,700,1,14.5800,100,1,12.3699,700,1,14.5999,700,1,ARL,321500333
1552,2025-07-17T15:59:04.224583946Z,2025-07-17T15:59:04.224583946Z,10,2,1108,A,A,0,14.7899,100,130,165387,268448014,13.0399,2,1,13.7200,15,1,13.0299,100,1,13.7300,100,1,13.0199,100,1,13.7599,100,1,12.7300,100,1,14.0399,100,1,12.7100,100,1,14.0999,2,1,12.5000,700,1,14.2799,100,1,12.4600,200,2,14.4000,100,1,12.4299,700,1,14.5600,800,2,12.4199,700,1,14.5800,100,1,12.3699,700,1,14.5999,700,1,ARL,321511477
1553,2025-07-17T15:59:04.799833206Z,2025-07-17T15:59:04.799833206Z,10,2,1108,C,A,0,13.7200,15,130,165436,268457531,13.0399,2,1,13.7300,100,1,13.0299,100,1,13.7599,100,1,13.0199,100,1,14.0399,100,1,12.7300,100,1,14.0999,2,1,12.7100,100,1,14.2799,100,1,12.5000,700,1,14.4000,100,1,12.4600,200,2,14.5600,800,2,12.4299,700,1,14.5800,100,1,12.4199,700,1,14.5999,700,1,12.3699,700,1,14.6400,100,1,ARL,321500117
1554,2025-07-17T16:00:13.989771852Z,2025-07-17T16:00:13.989771852Z,10,2,1108,C,A,0,14.0999,2,0,165562,269514876,13.0399,2,1,13.7300,100,1,13.0299,100,1,13.7599,100,1,13.0199,100,1,14.0399,100,1,12.7300,100,1,14.2799,100,1,12.7100,100,1,14.4000,100,1,12.5000,700,1,14.5600,800,2,12.4600,200,2,14.5800,100,1,12.4299,700,1,14.5999,700,1,12.4199,700,1,14.6400,100,1,12.3699,700,1,14.6500,100,1,ARL,316098525
1555,2025-07-17T16:00:13.989771852Z,2025-07-17T16:00:13.989771852Z,10,2,1108,A,A,0,14.0099,2,130,165562,269514876,13.0399,2,1,13.7300,100,1,13.0299,100,1,13.7599,100,1,13.0199,100,1,14.0099,2,1,12.7300,100,1,14.0399,100,1,12.7100,100,1,14.2799,100,1,12.5000,700,1,14.4000,100,1,12.4600,200,2,14.5600,800,2,12.4299,700,1,14.5800,100,1,12.4199,700,1,14.5999,700,1,12.3699,700,1,14.6400,100,1,ARL,322898193
1556,2025-07-17T16:00:28.802849928Z,2025-07-17T16:00:28.802849928Z,10,2,1108,A,A,0,13.7200,15,130,166002,269765653,13.0399,2,1,13.7200,15,1,13.0299,100,1,13.7300,100,1,13.0199,100,1,13.7599,100,1,12.7300,100,1,14.0099,2,1,12.7100,100,1,14.0399,100,1,12.5000,700,1,14.2799,100,1,12.4600,200,2,14.4000,100,1,12.4299,700,1,14.5600,800,2,12.4199,700,1,14.5800,100,1,12.3699,700,1,14.5999,700,1,ARL,323238809
1557,2025-07-17T16:00:32.549247168Z,2025-07-17T16:00:32.549247168Z,10,2,1108,A,A,0,13.7400,100,130,165448,269878282,13.0399,2,1,13.7200,15,1,13.0299,100,1,13.7300,100,1,13.0199,100,1,13.7400,100,1,12.7300,100,1,13.7599,100,1,12.7100,100,1,14.0099,2,1,12.5000,700,1,14.0399,100,1,12.4600,200,2,14.2799,100,1,12.4299,700,1,14.4000,100,1,12.4199,700,1,14.5600,800,2,12.3699,700,1,14.5800,100,1,ARL,323370569
1558,2025-07-17T16:00:32.560823786Z,2025-07-17T16:00:32.560823786Z,10,2,1108,C,A,0,13.7599,100,130,165307,269878639,13.0399,2,1,13.7200,15,1,13.0299,100,1,13.7300,100,1,13.0199,100,1,13.7400,100,1,12.7300,100,1,14.0099,2,1,12.7100,100,1,14.0399,100,1,12.5000,700,1,14.2799,100,1,12.4600,200,2,14.4000,100,1,12.4299,700,1,14.5600,800,2,12.4199,700,1,14.5800,100,1,12.3699,700,1,14.5999,700,1,ARL,321500317
1559,2025-07-17T16:00:35.512999155Z,2025-07-17T16:00:35.512999155Z,10,2,1108,A,A,0,13.6899,15,130,165303,269940539,13.0399,2,1,13.6899,15,1,13.0299,100,1,13.7200,15,1,13.0199,100,1,13.7300,100,1,12.7300,100,1,13.7400,100,1,12.7100,100,1,14.0099,2,1,12.5000,700,1,14.0399,100,1,12.4600,200,2,14.2799,100,1,12.4299,700,1,14.4000,100,1,12.4199,700,1,14.5600,800,2,12.3699,700,1,14.5800,100,1,ARL,323455221
1560,2025-07-17T16:00:42.614063415Z,2025-07-17T16:00:42.614063415Z,10,2,1108,C,A,0,13.7300,100,0,165769,270051089,13.0399,2,1,13.6899,15,1,13.0299,100,1,13.7200,15,1,13.0199,100,1,13.7400,100,1,12.7300,100,1,14.0099,2,1,12.7100,100,1,14.0399,100,1,12.5000,700,1,14.2799,100,1,12.4600,200,2,14.4000,100,1,12.4299,700,1,14.5600,800,2,12.4199,700,1,14.5800,100,1,12.3699,700,1,14.5999,700,1,ARL,321511377
1561,2025-07-17T16:00:42.614063415Z,2025-07-17T16:00:42.614063415Z,10,2,1108,A,A,0,13.6999,100,130,165769,270051089,13.0399,2,1,13.6899,15,1,13.0299,100,1,13.6999,100,1,13.0199,100,1,13.7200,15,1,12.7300,100,1,13.7400,100,1,12.7100,100,1,14.0099,2,1,12.5000,700,1,14.0399,100,1,12.4600,200,2,14.2799,100,1,12.4299,700,1,14.4000,100,1,12.4199,700,1,14.5600,800,2,12.3699,700,1,14.5800,100,1,ARL,323599605
1562,2025-07-17T16:00:42.614088947Z,2025-07-17T16:00:42.614088947Z,10,2,1108,A,A,0,13.7200,100,130,165252,270051090,13.0399,2,1,13.6899,15,1,13.0299,100,1,13.6999,100,1,13.0199,100,1,13.7200,115,2,12.7300,100,1,13.7400,100,1,12.7100,100,1,14.0099,2,1,12.5000,700,1,14.0399,100,1,12.4600,200,2,14.2799,100,1,12.4299,700,1,14.4000,100,1,12.4199,700,1,14.5600,800,2,12.3699,700,1,14.5800,100,1,ARL,323599609
1563,2025-07-17T16:00:42.614231125Z,2025-07-17T16:00:42.614231125Z,10,2,1108,C,A,0,13.7400,100,130,165089,270051092,13.0399,2,1,13.6899,15,1,13.0299,100,1,13.6999,100,1,13.0199,100,1,13.7200,115,2,12.7300,100,1,14.0099,2,1,12.7100,100,1,14.0399,100,1,12.5000,700,1,14.2799,100,1,12.4600,200,2,14.4000,100,1,12.4299,700,1,14.5600,800,2,12.4199,700,1,14.5800,100,1,12.3699,700,1,14.5999,700,1,ARL,323370569
1564,2025-07-17T16:00:42.616013371Z,2025-07-17T16:00:42.616013371Z,10,2,1108,C,A,0,14.8100,100,0,165591,270051093,13.0399,2,1,13.6899,15,1,13.0299,100,1,13.6999,100,1,13.0199,100,1,13.7200,115,2,12.7300,100,1,14.0099,2,1,12.7100,100,1,14.0399,100,1,12.5000,700,1,14.2799,100,1,12.4600,200,2,14.4000,100,1,12.4299,700,1,14.5600,800,2,12.4199,700,1,14.5800,100,1,12.3699,700,1,14.5999,700,1,ARL,321097197
1565,2025-07-17T16:00:42.616013371Z,2025-07-17T16:00:42.616013371Z,10,2,1108,A,A,0,14.6600,100,130,165591,270051093,13.0399,2,1,13.6899,15,1,13.0299,100,1,13.6999,100,1,13.0199,100,1,13.7200,115,2,12.7300,100,1,14.0099,2,1,12.7100,100,1,14.0399,100,1,12.5000,700,1,14.2799,100,1,12.4600,200,2,14.4000,100,1,12.4299,700,1,14.5600,800,2,12.4199,700,1,14.5800,100,1,12.3699,700,1,14.5999,700,1,ARL,323599625
1566,2025-07-17T16:00:42.616156310Z,2025-07-17T16:00:42.616156310Z,10,2,1108,C,A,0,15.9199,100,0,165569,270051094,13.0399,2,1,13.6899,15,1,13.0299,100,1,13.6999,100,1,13.0199,100,1,13.7200,115,2,12.7300,100,1,14.0099,2,1,12.7100,100,1,14.0399,100,1,12.5000,700,1,14.2799,100,1,12.4600,200,2,14.4000,100,1,12.4299,700,1,14.5600,800,2,12.4199,700,1,14.5800,100,1,12.3699,700,1,14.5999,700,1,ARL,321096889
1567,2025-07-17T16:00:42.616156310Z,2025-07-17T16:00:42.616156310Z,10,2,1108,A,A,0,15.7599,100,130,165569,270051094,13.0399,2,1,13.6899,15,1,13.0299,100,1,13.6999,100,1,13.0199,100,1,13.7200,115,2,12.7300,100,1,14.0099,2,1,12.7100,100,1,14.0399,100,1,12.5000,700,1,14.2799,100,1,12.4600,200,2,14.4000,100,1,12.4299,700,1,14.5600,800,2,12.4199,700,1,14.5800,100,1,12.3699,700,1,14.5999,700,1,ARL,323599629
1568,2025-07-17T16:00:42.616186901Z,2025-07-17T16:00:42.616186901Z,10,2,1108,C,A,0,17.5799,100,0,165346,270051095,13.0399,2,1,13.6899,15,1,13.0299,100,1,13.6999,100,1,13.0199,100,1,13.7200,115,2,12.7300,100,1,14.0099,2,1,12.7100,100,1,14.0399,100,1,12.5000,700,1,14.2799,100,1,12.4600,200,2,14.4000,100,1,12.4299,700,1,14.5600,800,2,12.4199,700,1,14.5800,100,1,12.3699,700,1,14.5999,700,1,ARL,321096825
1569,2025-07-17T16:00:42.616186901Z,2025-07-17T16:00:42.616186901Z,10,2,1108,A,A,0,17.3999,100,130,165346,270051095,13.0399,2,1,13.6899,15,1,13.0299,100,1,13.6999,100,1,13.0199,100,1,13.7200,115,2,12.7300,100,1,14.0099,2,1,12.7100,100,1,14.0399,100,1,12.5000,700,1,14.2799,100,1,12.4600,200,2,14.4000,100,1,12.4299,700,1,14.5600,800,2,12.4199,700,1,14.5800,100,1,12.3699,700,1,14.5999,700,1,ARL,323599633
1570,2025-07-17T16:00:42.636595817Z,2025-07-17T16:00:42.636595817Z,10,2,1108,C,A,0,14.0399,100,130,165359,270051179,13.0399,2,1,13.6899,15,1,13.0299,100,1,13.6999,100,1,13.0199,100,1,13.7200,115,2,12.7300,100,1,14.0099,2,1,12.7100,100,1,14.2799,100,1,12.5000,700,1,14.4000,100,1,12.4600,200,2,14.5600,800,2,12.4299,700,1,14.5800,100,1,12.4199,700,1,14.5999,700,1,12.3699,700,1,14.6400,100,1,ARL,321500957
1571,2025-07-17T16:00:42.636649389Z,2025-07-17T16:00:42.636649389Z,10,2,1108,A,A,0,13.9700,100,130,165315,270051181,13.0399,2,1,13.6899,15,1,13.0299,100,1,13.6999,100,1,13.0199,100,1,13.7200,115,2,12.7300,100,1,13.9700,100,1,12.7100,100,1,14.0099,2,1,12.5000,700,1,14.2799,100,1,12.4600,200,2,14.4000,100,1,12.4299,700,1,14.5600,800,2,12.4199,700,1,14.5800,100,1,12.3699,700,1,14.5999,700,1,ARL,323599765
1572,2025-07-17T16:00:46.803097192Z,2025-07-17T16:00:46.803097192Z,10,2,1108,C,A,0,13.7200,15,130,165268,270102799,13.0399,2,1,13.6899,15,1,13.0299,100,1,13.6999,100,1,13.0199,100,1,13.7200,100,1,12.7300,100,1,13.9700,100,1,12.7100,100,1,14.0099,2,1,12.5000,700,1,14.2799,100,1,12.4600,200,2,14.4000,100,1,12.4299,700,1,14.5600,800,2,12.4199,700,1,14.5800,100,1,12.3699,700,1,14.5999,700,1,ARL,323238809
1573,2025-07-17T16:00:49.255465939Z,2025-07-17T16:00:49.255465939Z,10,2,1108,A,A,0,13.6600,15,130,165325,270140405,13.0399,2,1,13.6600,15,1,13.0299,100,1,13.6899,15,1,13.0199,100,1,13.6999,100,1,12.7300,100,1,13.7200,100,1,12.7100,100,1,13.9700,100,1,12.5000,700,1,14.0099,2,1,12.4600,200,2,14.2799,100,1,12.4299,700,1,14.4000,100,1,12.4199,700,1,14.5600,800,2,12.3699,700,1,14.5800,100,1,ARL,323720189
1574,2025-07-17T16:00:49.739479408Z,2025-07-17T16:00:49.739479408Z,10,2,1108,A,A,0,13.6999,100,130,165196,270146528,13.0399,2,1,13.6600,15,1,13.0299,100,1,13.6899,15,1,13.0199,100,1,13.6999,200,2,12.7300,100,1,13.7200,100,1,12.7100,100,1,13.9700,100,1,12.5000,700,1,14.0099,2,1,12.4600,200,2,14.2799,100,1,12.4299,700,1,14.4000,100,1,12.4199,700,1,14.5600,800,2,12.3699,700,1,14.5800,100,1,ARL,323730309
1575,2025-07-17T16:00:49.744872763Z,2025-07-17T16:00:49.744872763Z,10,2,1108,C,A,0,13.6999,100,0,165498,270146577,13.0399,2,1,13.6600,15,1,13.0299,100,1,13.6899,15,1,13.0199,100,1,13.6999,100,1,12.7300,100,1,13.7200,100,1,12.7100,100,1,13.9700,100,1,12.5000,700,1,14.0099,2,1,12.4600,200,2,14.2799,100,1,12.4299,700,1,14.4000,100,1,12.4199,700,1,14.5600,800,2,12.3699,700,1,14.5800,100,1,ARL,323599605
1576,2025-07-17T16:00:49.744872763Z,2025-07-17T16:00:49.744872763Z,10,2,1108,A,A,0,13.6699,100,130,165498,270146577,13.0399,2,1,13.6600,15,1,13.0299,100,1,13.6699,100,1,13.0199,100,1,13.6899,15,1,12.7300,100,1,13.6999,100,1,12.7100,100,1,13.7200,100,1,12.5000,700,1,13.9700,100,1,12.4600,200,2,14.0099,2,1,12.4299,700,1,14.2799,100,1,12.4199,700,1,14.4000,100,1,12.3699,700,1,14.5600,800,2,ARL,323730353
1577,2025-07-17T16:00:49.745613051Z,2025-07-17T16:00:49.745613051Z,10,2,1108,C,A,0,14.7899,100,0,165674,270146581,13.0399,2,1,13.6600,15,1,13.0299,100,1,13.6699,100,1,13.0199,100,1,13.6899,15,1,12.7300,100,1,13.6999,100,1,12.7100,100,1,13.7200,100,1,12.5000,700,1,13.9700,100,1,12.4600,200,2,14.0099,2,1,12.4299,700,1,14.2799,100,1,12.4199,700,1,14.4000,100,1,12.3699,700,1,14.5600,800,2,ARL,321511477
1578,2025-07-17T16:00:49.745613051Z,2025-07-17T16:00:49.745613051Z,10,2,1108,A,A,0,14.7300,100,130,165674,270146581,13.0399,2,1,13.6600,15,1,13.0299,100,1,13.6699,100,1,13.0199,100,1,13.6899,15,1,12.7300,100,1,13.6999,100,1,12.7100,100,1,13.7200,100,1,12.5000,700,1,13.9700,100,1,12.4600,200,2,14.0099,2,1,12.4299,700,1,14.2799,100,1,12.4199,700,1,14.4000,100,1,12.3699,700,1,14.5600,800,2,ARL,323730369
1579,2025-07-17T16:00:49.746256906Z,2025-07-17T16:00:49.746256906Z,10,2,1108,C,A,0,13.7200,100,130,165236,270146586,13.0399,2,1,13.6600,15,1,13.0299,100,1,13.6699,100,1,13.0199,100,1,13.6899,15,1,12.7300,100,1,13.6999,100,1,12.7100,100,1,13.9700,100,1,12.5000,700,1,14.0099,2,1,12.4600,200,2,14.2799,100,1,12.4299,700,1,14.4000,100,1,12.4199,700,1,14.5600,800,2,12.3699,700,1,14.5800,100,1,ARL,323599609
1580,2025-07-17T16:00:49.772466772Z,2025-07-17T16:00:49.772466772Z,10,2,1108,A,A,0,15.5899,100,130,165195,270146838,13.0399,2,1,13.6600,15,1,13.0299,100,1,13.6699,100,1,13.0199,100,1,13.6899,15,1,12.7300,100,1,13.6999,100,1,12.7100,100,1,13.9700,100,1,12.5000,700,1,14.0099,2,1,12.4600,200,2,14.2799,100,1,12.4299,700,1,14.4000,100,1,12.4199,700,1,14.5600,800,2,12.3699,700,1,14.5800,100,1,ARL,323730697
1581,2025-07-17T16:00:49.772479921Z,2025-07-17T16:00:49.772479921Z,10,2,1108,C,A,0,15.8599,100,130,165382,270146839,13.0399,2,1,13.6600,15,1,13.0299,100,1,13.6699,100,1,13.0199,100,1,13.6899,15,1,12.7300,100,1,13.6999,100,1,12.7100,100,1,13.9700,100,1,12.5000,700,1,14.0099,2,1,12.4600,200,2,14.2799,100,1,12.4299,700,1,14.4000,100,1,12.4199,700,1,14.5600,800,2,12.3699,700,1,14.5800,100,1,ARL,312771645
1582,2025-07-17T16:00:51.624646272Z,2025-07-17T16:00:51.624646272Z,10,2,1108,C,A,0,14.6500,100,0,165617,270181394,13.0399,2,1,13.6600,15,1,13.0299,100,1,13.6699,100,1,13.0199,100,1,13.6899,15,1,12.7300,100,1,13.6999,100,1,12.7100,100,1,13.9700,100,1,12.5000,700,1,14.0099,2,1,12.4600,200,2,14.2799,100,1,12.4299,700,1,14.4000,100,1,12.4199,700,1,14.5600,800,2,12.3699,700,1,14.5800,100,1,ARL,321293737
1583,2025-07-17T16:00:51.624646272Z,2025-07-17T16:00:51.624646272Z,10,2,1108,A,A,0,14.5399,100,130,165617,270181394,13.0399,2,1,13.6600,15,1,13.0299,100,1,13.6699,100,1,13.0199,100,1,13.6899,15,1,12.7300,100,1,13.6999,100,1,12.7100,100,1,13.9700,100,1,12.5000,700,1,14.0099,2,1,12.4600,200,2,14.2799,100,1,12.4299,700,1,14.4000,100,1,12.4199,700,1,14.5399,100,1,12.3699,700,1,14.5600,800,2,ARL,323775433
1584,2025-07-17T16:00:51.625206675Z,2025-07-17T16:00:51.625206675Z,10,2,1108,C,A,0,14.6400,100,0,165841,270181399,13.0399,2,1,13.6600,15,1,13.0299,100,1,13.6699,100,1,13.0199,100,1,13.6899,15,1,12.7300,100,1,13.6999,100,1,12.7100,100,1,13.9700,100,1,12.5000,700,1,14.0099,2,1,12.4600,200,2,14.2799,100,1,12.4299,700,1,14.4000,100,1,12.4199,700,1,14.5399,100,1,12.3699,700,1,14.5600,800,2,ARL,321293741
1585,2025-07-17T16:00:51.625206675Z,2025-07-17T16:00:51.625206675Z,10,2,1108,A,A,0,14.5299,100,130,165841,270181399,13.0399,2,1,13.6600,15,1,13.0299,100,1,13.6699,100,1,13.0199,100,1,13.6899,15,1,12.7300,100,1,13.6999,100,1,12.7100,100,1,13.9700,100,1,12.5000,700,1,14.0099,2,1,12.4600,200,2,14.2799,100,1,12.4299,700,1,14.4000,100,1,12.4199,700,1,14.5299,100,1,12.3699,700,1,14.5399,100,1,ARL,323775457
1586,2025-07-17T16:00:53.749169565Z,2025-07-17T16:00:53.749169565Z,10,2,1108,A,A,0,13.6699,100,130,165445,270204567,13.0399,2,1,13.6600,15,1,13.0299,100,1,13.6699,200,2,13.0199,100,1,13.6899,15,1,12.7300,100,1,13.6999,100,1,12.7100,100,1,13.9700,100,1,12.5000,700,1,14.0099,2,1,12.4600,200,2,14.2799,100,1,12.4299,700,1,14.4000,100,1,12.4199,700,1,14.5299,100,1,12.3699,700,1,14.5399,100,1,ARL,323803301
1587,2025-07-17T16:00:53.755801462Z,2025-07-17T16:00:53.755801462Z,10,2,1108,C,A,0,13.6999,100,130,165218,270204616,13.0399,2,1,13.6600,15,1,13.0299,100,1,13.6699,200,2,13.0199,100,1,13.6899,15,1,12.7300,100,1,13.9700,100,1,12.7100,100,1,14.0099,2,1,12.5000,700,1,14.2799,100,1,12.4600,200,2,14.4000,100,1,12.4299,700,1,14.5299,100,1,12.4199,700,1,14.5399,100,1,12.3699,700,1,14.5600,800,2,ARL,323730309
1588,2025-07-17T16:01:00.801177403Z,2025-07-17T16:01:00.801177403Z,10,2,1108,C,A,0,13.6899,15,130,165336,270319932,13.0399,2,1,13.6600,15,1,13.0299,100,1,13.6699,200,2,13.0199,100,1,13.9700,100,1,12.7300,100,1,14.0099,2,1,12.7100,100,1,14.2799,100,1,12.5000,700,1,14.4000,100,1,12.4600,200,2,14.5299,100,1,12.4299,700,1,14.5399,100,1,12.4199,700,1,14.5600,800,2,12.3699,700,1,14.5800,100,1,ARL,323455221
1589,2025-07-17T16:01:10.802712247Z,2025-07-17T16:01:10.802712247Z,10,2,1108,A,A,0,13.6199,15,130,165323,270493149,13.0399,2,1,13.6199,15,1,13.0299,100,1,13.6600,15,1,13.0199,100,1,13.6699,200,2,12.7300,100,1,13.9700,100,1,12.7100,100,1,14.0099,2,1,12.5000,700,1,14.2799,100,1,12.4600,200,2,14.4000,100,1,12.4299,700,1,14.5299,100,1,12.4199,700,1,14.5399,100,1,12.3699,700,1,14.5600,800,2,ARL,324161541
1590,2025-07-17T16:01:11.418671671Z,2025-07-17T16:01:11.418671671Z,10,2,1108,A,A,0,13.6500,100,130,165801,270503944,13.0399,2,1,13.6199,15,1,13.0299,100,1,13.6500,100,1,13.0199,100,1,13.6600,15,1,12.7300,100,1,13.6699,200,2,12.7100,100,1,13.9700,100,1,12.5000,700,1,14.0099,2,1,12.4600,200,2,14.2799,100,1,12.4299,700,1,14.4000,100,1,12.4199,700,1,14.5299,100,1,12.3699,700,1,14.5399,100,1,ARL,324175569
1591,2025-07-17T16:01:11.425757014Z,2025-07-17T16:01:11.425757014Z,10,2,1108,C,A,0,13.6699,100,130,165170,270504009,13.0399,2,1,13.6199,15,1,13.0299,100,1,13.6500,100,1,13.0199,100,1,13.6600,15,1,12.7300,100,1,13.6699,100,1,12.7100,100,1,13.9700,100,1,12.5000,700,1,14.0099,2,1,12.4600,200,2,14.2799,100,1,12.4299,700,1,14.4000,100,1,12.4199,700,1,14.5299,100,1,12.3699,700,1,14.5399,100,1,ARL,323803301
1592,2025-07-17T16:01:11.820588141Z,2025-07-17T16:01:11.820588141Z,10,2,1108,C,A,0,13.6699,100,0,165475,270509970,13.0399,2,1,13.6199,15,1,13.0299,100,1,13.6500,100,1,13.0199,100,1,13.6600,15,1,12.7300,100,1,13.9700,100,1,12.7100,100,1,14.0099,2,1,12.5000,700,1,14.2799,100,1,12.4600,200,2,14.4000,100,1,12.4299,700,1,14.5299,100,1,12.4199,700,1,14.5399,100,1,12.3699,700,1,14.5600,800,2,ARL,323730353
1593,2025-07-17T16:01:11.820588141Z,2025-07-17T16:01:11.820588141Z,10,2,1108,A,A,0,13.6300,100,130,165475,270509970,13.0399,2,1,13.6199,15,1,13.0299,100,1,13.6300,100,1,13.0199,100,1,13.6500,100,1,12.7300,100,1,13.6600,15,1,12.7100,100,1,13.9700,100,1,12.5000,700,1,14.0099,2,1,12.4600,200,2,14.2799,100,1,12.4299,700,1,14.4000,100,1,12.4199,700,1,14.5299,100,1,12.3699,700,1,14.5399,100,1,ARL,324186213
1594,2025-07-17T16:01:11.821349600Z,2025-07-17T16:01:11.821349600Z,10,2,1108,C,A,0,14.7300,100,0,165443,270509983,13.0399,2,1,13.6199,15,1,13.0299,100,1,13.6300,100,1,13.0199,100,1,13.6500,100,1,12.7300,100,1,13.6600,15,1,12.7100,100,1,13.9700,100,1,12.5000,700,1,14.0099,2,1,12.4600,200,2,14.2799,100,1,12.4299,700,1,14.4000,100,1,12.4199,700,1,14.5299,100,1,12.3699,700,1,14.5399,100,1,ARL,323730369
1595,2025-07-17T16:01:11.821349600Z,2025-07-17T16:01:11.821349600Z,10,2,1108,A,A,0,14.6899,100,130,165443,270509983,13.0399,2,1,13.6199,15,1,13.0299,100,1,13.6300,100,1,13.0199,100,1,13.6500,100,1,12.7300,100,1,13.6600,15,1,12.7100,100,1,13.9700,100,1,12.5000,700,1,14.0099,2,1,12.4600,200,2,14.2799,100,1,12.4299,700,1,14.4000,100,1,12.4199,700,1,14.5299,100,1,12.3699,700,1,14.5399,100,1,ARL,324186233
1596,2025-07-17T16:01:11.826234488Z,2025-07-17T16:01:11.826234488Z,10,2,1108,C,A,0,13.9700,100,130,165383,270510142,13.0399,2,1,13.6199,15,1,13.0299,100,1,13.6300,100,1,13.0199,100,1,13.6500,100,1,12.7300,100,1,13.6600,15,1,12.7100,100,1,14.0099,2,1,12.5000,700,1,14.2799,100,1,12.4600,200,2,14.4000,100,1,12.4299,700,1,14.5299,100,1,12.4199,700,1,14.5399,100,1,12.3699,700,1,14.5600,800,2,ARL,323599765
1597,2025-07-17T16:01:11.826286284Z,2025-07-17T16:01:11.826286284Z,10,2,1108,A,A,0,13.9000,100,130,165163,270510143,13.0399,2,1,13.6199,15,1,13.0299,100,1,13.6300,100,1,13.0199,100,1,13.6500,100,1,12.7300,100,1,13.6600,15,1,12.7100,100,1,13.9000,100,1,12.5000,700,1,14.0099,2,1,12.4600,200,2,14.2799,100,1,12.4299,700,1,14.4000,100,1,12.4199,700,1,14.5299,100,1,12.3699,700,1,14.5399,100,1,ARL,324186721
1598,2025-07-17T16:01:11.828464891Z,2025-07-17T16:01:11.828464891Z,10,2,1108,C,A,0,14.5800,100,0,165523,270510182,13.0399,2,1,13.6199,15,1,13.0299,100,1,13.6300,100,1,13.0199,100,1,13.6500,100,1,12.7300,100,1,13.6600,15,1,12.7100,100,1,13.9000,100,1,12.5000,700,1,14.0099,2,1,12.4600,200,2,14.2799,100,1,12.4299,700,1,14.4000,100,1,12.4199,700,1,14.5299,100,1,12.3699,700,1,14.5399,100,1,ARL,321309941
1599,2025-07-17T16:01:11.828464891Z,2025-07-17T16:01:11.828464891Z,10,2,1108,A,A,0,14.4299,100,130,165523,270510182,13.0399,2,1,13.6199,15,1,13.0299,100,1,13.6300,100,1,13.0199,100,1,13.6500,100,1,12.7300,100,1,13.6600,15,1,12.7100,100,1,13.9000,100,1,12.5000,700,1,14.0099,2,1,12.4600,200,2,14.2799,100,1,12.4299,700,1,14.4000,100,1,12.4199,700,1,14.4299,100,1,12.3699,700,1,14.5299,100,1,ARL,324186781
1600,2025-07-17T16:01:22.802353061Z,2025-07-17T16:01:22.802353061Z,10,2,1108,C,A,0,13.6600,15,130,165475,270674903,13.0399,2,1,13.6199,15,1,13.0299,100,1,13.6300,100,1,13.0199,100,1,13.6500,100,1,12.7300,100,1,13.9000,100,1,12.7100,100,1,14.0099,2,1,12.5000,700,1,14.2799,100,1,12.4600,200,2,14.4000,100,1,12.4299,700,1,14.4299,100,1,12.4199,700,1,14.5299,100,1,12.3699,700,1,14.5399,100,1,ARL,323720189
1601,2025-07-17T16:01:32.803839043Z,2025-07-17T16:01:32.803839043Z,10,2,1108,A,A,0,13.5999,15,130,165596,270824320,13.0399,2,1,13.5999,15,1,13.0299,100,1,13.6199,15,1,13.0199,100,1,13.6300,100,1,12.7300,100,1,13.6500,100,1,12.7100,100,1,13.9000,100,1,12.5000,700,1,14.0099,2,1,12.4600,200,2,14.2799,100,1,12.4299,700,1,14.4000,100,1,12.4199,700,1,14.4299,100,1,12.3699,700,1,14.5299,100,1,ARL,324619361
1602,2025-07-17T16:01:32.804108576Z,2025-07-17T16:01:32.804108576Z,10,2,1108,C,A,0,13.6300,100,0,165592,270824323,13.0399,2,1,13.5999,15,1,13.0299,100,1,13.6199,15,1,13.0199,100,1,13.6500,100,1,12.7300,100,1,13.9000,100,1,12.7100,100,1,14.0099,2,1,12.5000,700,1,14.2799,100,1,12.4600,200,2,14.4000,100,1,12.4299,700,1,14.4299,100,1,12.4199,700,1,14.5299,100,1,12.3699,700,1,14.5399,100,1,ARL,324186213
1603,2025-07-17T16:01:32.804108576Z,2025-07-17T16:01:32.804108576Z,10,2,1108,A,A,0,13.6099,100,130,165592,270824323,13.0399,2,1,13.5999,15,1,13.0299,100,1,13.6099,100,1,13.0199,100,1,13.6199,15,1,12.7300,100,1,13.6500,100,1,12.7100,100,1,13.9000,100,1,12.5000,700,1,14.0099,2,1,12.4600,200,2,14.2799,100,1,12.4299,700,1,14.4000,100,1,12.4199,700,1,14.4299,100,1,12.3699,700,1,14.5299,100,1,ARL,324619369
1604,2025-07-17T16:01:32.806134020Z,2025-07-17T16:01:32.806134020Z,10,2,1108,C,A,0,14.7300,100,0,165444,270824400,13.0399,2,1,13.5999,15,1,13.0299,100,1,13.6099,100,1,13.0199,100,1,13.6199,15,1,12.7300,100,1,13.6500,100,1,12.7100,100,1,13.9000,100,1,12.5000,700,1,14.0099,2,1,12.4600,200,2,14.2799,100,1,12.4299,700,1,14.4000,100,1,12.4199,700,1,14.4299,100,1,12.3699,700,1,14.5299,100,1,ARL,321500349
1605,2025-07-17T16:01:32.806134020Z,2025-07-17T16:01:32.806134020Z,10,2,1108,A,A,0,14.5700,100,130,165444,270824400,13.0399,2,1,13.5999,15,1,13.0299,100,1,13.6099,100,1,13.0199,100,1,13.6199,15,1,12.7300,100,1,13.6500,100,1,12.7100,100,1,13.9000,100,1,12.5000,700,1,14.0099,2,1,12.4600,200,2,14.2799,100,1,12.4299,700,1,14.4000,100,1,12.4199,700,1,14.4299,100,1,12.3699,700,1,14.5299,100,1,ARL,324619409
1606,2025-07-17T16:01:32.815748258Z,2025-07-17T16:01:32.815748258Z,10,2,1108,A,A,0,13.6300,100,130,165262,270824657,13.0399,2,1,13.5999,15,1,13.0299,100,1,13.6099,100,1,13.0199,100,1,13.6199,15,1,12.7300,100,1,13.6300,100,1,12.7100,100,1,13.6500,100,1,12.5000,700,1,13.9000,100,1,12.4600,200,2,14.0099,2,1,12.4299,700,1,14.2799,100,1,12.4199,700,1,14.4000,100,1,12.3699,700,1,14.4299,100,1,ARL,324619837
1607,2025-07-17T16:01:32.822443626Z,2025-07-17T16:01:32.822443626Z,10,2,1108,C,A,0,13.6500,100,130,165340,270824747,13.0399,2,1,13.5999,15,1,13.0299,100,1,13.6099,100,1,13.0199,100,1,13.6199,15,1,12.7300,100,1,13.6300,100,1,12.7100,100,1,13.9000,100,1,12.5000,700,1,14.0099,2,1,12.4600,200,2,14.2799,100,1,12.4299,700,1,14.4000,100,1,12.4199,700,1,14.4299,100,1,12.3699,700,1,14.5299,100,1,ARL,324175569
1608,2025-07-17T16:01:37.242525208Z,2025-07-17T16:01:37.242525208Z,10,2,1108,C,A,0,13.6199,15,130,165212,270889017,13.0399,2,1,13.5999,15,1,13.0299,100,1,13.6099,100,1,13.0199,100,1,13.6300,100,1,12.7300,100,1,13.9000,100,1,12.7100,100,1,14.0099,2,1,12.5000,700,1,14.2799,100,1,12.4600,200,2,14.4000,100,1,12.4299,700,1,14.4299,100,1,12.4199,700,1,14.5299,100,1,12.3699,700,1,14.5399,100,1,ARL,324161541
1609,2025-07-17T16:01:40.605632399Z,2025-07-17T16:01:40.605632399Z,10,2,1108,A,A,0,13.6099,100,130,165366,270946497,13.0399,2,1,13.5999,15,1,13.0299,100,1,13.6099,200,2,13.0199,100,1,13.6300,100,1,12.7300,100,1,13.9000,100,1,12.7100,100,1,14.0099,2,1,12.5000,700,1,14.2799,100,1,12.4600,200,2,14.4000,100,1,12.4299,700,1,14.4299,100,1,12.4199,700,1,14.5299,100,1,12.3699,700,1,14.5399,100,1,ARL,324782841
1610,2025-07-17T16:01:40.653572805Z,2025-07-17T16:01:40.653572805Z,10,2,1108,C,A,0,13.6300,100,130,165371,270946779,13.0399,2,1,13.5999,15,1,13.0299,100,1,13.6099,200,2,13.0199,100,1,13.9000,100,1,12.7300,100,1,14.0099,2,1,12.7100,100,1,14.2799,100,1,12.5000,700,1,14.4000,100,1,12.4600,200,2,14.4299,100,1,12.4299,700,1,14.5299,100,1,12.4199,700,1,14.5399,100,1,12.3699,700,1,14.5600,800,2,ARL,324619837
1611,2025-07-17T16:01:47.565825466Z,2025-07-17T16:01:47.565825466Z,10,2,1108,A,A,0,13.5700,15,128,166218,271062350,13.0399,2,1,13.5700,15,1,13.0299,100,1,13.5999,15,1,13.0199,100,1,13.6099,200,2,12.7300,100,1,13.9000,100,1,12.7100,100,1,14.0099,2,1,12.5000,700,1,14.2799,100,1,12.4600,200,2,14.4000,100,1,12.4299,700,1,14.4299,100,1,12.4199,700,1,14.5299,100,1,12.3699,700,1,14.5399,100,1,ARL,324934601
1612,2025-07-17T16:01:47.902804446Z,2025-07-17T16:01:47.902804446Z,10,2,1108,C,A,0,13.6099,100,0,165327,271068098,13.0399,2,1,13.5700,15,1,13.0299,100,1,13.5999,15,1,13.0199,100,1,13.6099,100,1,12.7300,100,1,13.9000,100,1,12.7100,100,1,14.0099,2,1,12.5000,700,1,14.2799,100,1,12.4600,200,2,14.4000,100,1,12.4299,700,1,14.4299,100,1,12.4199,700,1,14.5299,100,1,12.3699,700,1,14.5399,100,1,ARL,324619369
1613,2025-07-17T16:01:47.902804446Z,2025-07-17T16:01:47.902804446Z,10,2,1108,A,A,0,13.5800,100,130,165327,271068098,13.0399,2,1,13.5700,15,1,13.0299,100,1,13.5800,100,1,13.0199,100,1,13.5999,15,1,12.7300,100,1,13.6099,100,1,12.7100,100,1,13.9000,100,1,12.5000,700,1,14.0099,2,1,12.4600,200,2,14.2799,100,1,12.4299,700,1,14.4000,100,1,12.4199,700,1,14.4299,100,1,12.3699,700,1,14.5299,100,1,ARL,324942229
1614,2025-07-17T16:01:47.903546622Z,2025-07-17T16:01:47.903546622Z,10,2,1108,C,A,0,14.4000,100,130,165135,271068105,13.0399,2,1,13.5700,15,1,13.0299,100,1,13.5800,100,1,13.0199,100,1,13.5999,15,1,12.7300,100,1,13.6099,100,1,12.7100,100,1,13.9000,100,1,12.5000,700,1,14.0099,2,1,12.4600,200,2,14.2799,100,1,12.4299,700,1,14.4299,100,1,12.4199,700,1,14.5299,100,1,12.3699,700,1,14.5399,100,1,ARL,289726421
1615,2025-07-17T16:01:47.903548861Z,2025-07-17T16:01:47.903548861Z,10,2,1108,C,A,0,14.6899,100,0,165462,271068106,13.0399,2,1,13.5700,15,1,13.0299,100,1,13.5800,100,1,13.0199,100,1,13.5999,15,1,12.7300,100,1,13.6099,100,1,12.7100,100,1,13.9000,100,1,12.5000,700,1,14.0099,2,1,12.4600,200,2,14.2799,100,1,12.4299,700,1,14.4299,100,1,12.4199,700,1,14.5299,100,1,12.3699,700,1,14.5399,100,1,ARL,324186233
1616,2025-07-17T16:01:47.903548861Z,2025-07-17T16:01:47.903548861Z,10,2,1108,A,A,0,14.6300,100,130,165462,271068106,13.0399,2,1,13.5700,15,1,13.0299,100,1,13.5800,100,1,13.0199,100,1,13.5999,15,1,12.7300,100,1,13.6099,100,1,12.7100,100,1,13.9000,100,1,12.5000,700,1,14.0099,2,1,12.4600,200,2,14.2799,100,1,12.4299,700,1,14.4299,100,1,12.4199,700,1,14.5299,100,1,12.3699,700,1,14.5399,100,1,ARL,324942257
1617,2025-07-17T16:01:47.903902473Z,2025-07-17T16:01:47.903902473Z,10,2,1108,A,A,0,14.1899,100,130,165213,271068115,13.0399,2,1,13.5700,15,1,13.0299,100,1,13.5800,100,1,13.0199,100,1,13.5999,15,1,12.7300,100,1,13.6099,100,1,12.7100,100,1,13.9000,100,1,12.5000,700,1,14.0099,2,1,12.4600,200,2,14.1899,100,1,12.4299,700,1,14.2799,100,1,12.4199,700,1,14.4299,100,1,12.3699,700,1,14.5299,100,1,ARL,324942273
1618,2025-07-17T16:01:47.905189816Z,2025-07-17T16:01:47.905189816Z,10,2,1108,C,A,0,15.2300,100,0,165963,271068134,13.0399,2,1,13.5700,15,1,13.0299,100,1,13.5800,100,1,13.0199,100,1,13.5999,15,1,12.7300,100,1,13.6099,100,1,12.7100,100,1,13.9000,100,1,12.5000,700,1,14.0099,2,1,12.4600,200,2,14.1899,100,1,12.4299,700,1,14.2799,100,1,12.4199,700,1,14.4299,100,1,12.3699,700,1,14.5299,100,1,ARL,282776017
1619,2025-07-17T16:01:47.905189816Z,2025-07-17T16:01:47.905189816Z,10,2,1108,A,A,0,14.9399,100,130,165963,271068134,13.0399,2,1,13.5700,15,1,13.0299,100,1,13.5800,100,1,13.0199,100,1,13.5999,15,1,12.7300,100,1,13.6099,100,1,12.7100,100,1,13.9000,100,1,12.5000,700,1,14.0099,2,1,12.4600,200,2,14.1899,100,1,12.4299,700,1,14.2799,100,1,12.4199,700,1,14.4299,100,1,12.3699,700,1,14.5299,100,1,ARL,324942277
1620,2025-07-17T16:01:47.909314303Z,2025-07-17T16:01:47.909314303Z,10,2,1108,C,A,0,17.3999,100,0,165421,271068173,13.0399,2,1,13.5700,15,1,13.0299,100,1,13.5800,100,1,13.0199,100,1,13.5999,15,1,12.7300,100,1,13.6099,100,1,12.7100,100,1,13.9000,100,1,12.5000,700,1,14.0099,2,1,12.4600,200,2,14.1899,100,1,12.4299,700,1,14.2799,100,1,12.4199,700,1,14.4299,100,1,12.3699,700,1,14.5299,100,1,ARL,323599633
1621,2025-07-17T16:01:47.909314303Z,2025-07-17T16:01:47.909314303Z,10,2,1108,A,A,0,17.2500,100,130,165421,271068173,13.0399,2,1,13.5700,15,1,13.0299,100,1,13.5800,100,1,13.0199,100,1,13.5999,15,1,12.7300,100,1,13.6099,100,1,12.7100,100,1,13.9000,100,1,12.5000,700,1,14.0099,2,1,12.4600,200,2,14.1899,100,1,12.4299,700,1,14.2799,100,1,12.4199,700,1,14.4299,100,1,12.3699,700,1,14.5299,100,1,ARL,324942361
1622,2025-07-17T16:01:50.798934838Z,2025-07-17T16:01:50.798934838Z,10,2,1108,A,A,0,13.5899,100,130,165666,271131418,13.0399,2,1,13.5700,15,1,13.0299,100,1,13.5800,100,1,13.0199,100,1,13.5899,100,1,12.7300,100,1,13.5999,15,1,12.7100,100,1,13.6099,100,1,12.5000,700,1,13.9000,100,1,12.4600,200,2,14.0099,2,1,12.4299,700,1,14.1899,100,1,12.4199,700,1,14.2799,100,1,12.3699,700,1,14.4299,100,1,ARL,325022101
1623,2025-07-17T16:01:50.805488726Z,2025-07-17T16:01:50.805488726Z,10,2,1108,C,A,0,13.6099,100,130,165235,271131583,13.0399,2,1,13.5700,15,1,13.0299,100,1,13.5800,100,1,13.0199,100,1,13.5899,100,1,12.7300,100,1,13.5999,15,1,12.7100,100,1,13.9000,100,1,12.5000,700,1,14.0099,2,1,12.4600,200,2,14.1899,100,1,12.4299,700,1,14.2799,100,1,12.4199,700,1,14.4299,100,1,12.3699,700,1,14.5299,100,1,ARL,324782841
1624,2025-07-17T16:01:52.132898568Z,2025-07-17T16:01:52.132898568Z,10,2,1108,C,A,0,13.5999,15,130,165193,271153294,13.0399,2,1,13.5700,15,1,13.0299,100,1,13.5800,100,1,13.0199,100,1,13.5899,100,1,12.7300,100,1,13.9000,100,1,12.7100,100,1,14.0099,2,1,12.5000,700,1,14.1899,100,1,12.4600,200,2,14.2799,100,1,12.4299,700,1,14.4299,100,1,12.4199,700,1,14.5299,100,1,12.3699,700,1,14.5399,100,1,ARL,324619361
1625,2025-07-17T16:01:53.137336077Z,2025-07-17T16:01:53.137336077Z,10,2,1108,A,A,0,13.5500,15,130,165885,271200452,13.0399,2,1,13.5500,15,1,13.0299,100,1,13.5700,15,1,13.0199,100,1,13.5800,100,1,12.7300,100,1,13.5899,100,1,12.7100,100,1,13.9000,100,1,12.5000,700,1,14.0099,2,1,12.4600,200,2,14.1899,100,1,12.4299,700,1,14.2799,100,1,12.4199,700,1,14.4299,100,1,12.3699,700,1,14.5299,100,1,ARL,325109165
1626,2025-07-17T16:01:56.263988198Z,2025-07-17T16:01:56.263988198Z,10,2,1108,C,A,0,13.5800,100,0,165897,271251019,13.0399,2,1,13.5500,15,1,13.0299,100,1,13.5700,15,1,13.0199,100,1,13.5899,100,1,12.7300,100,1,13.9000,100,1,12.7100,100,1,14.0099,2,1,12.5000,700,1,14.1899,100,1,12.4600,200,2,14.2799,100,1,12.4299,700,1,14.4299,100,1,12.4199,700,1,14.5299,100,1,12.3699,700,1,14.5399,100,1,ARL,324942229
1627,2025-07-17T16:01:56.263988198Z,2025-07-17T16:01:56.263988198Z,10,2,1108,A,A,0,13.5600,100,130,165897,271251019,13.0399,2,1,13.5500,15,1,13.0299,100,1,13.5600,100,1,13.0199,100,1,13.5700,15,1,12.7300,100,1,13.5899,100,1,12.7100,100,1,13.9000,100,1,12.5000,700,1,14.0099,2,1,12.4600,200,2,14.1899,100,1,12.4299,700,1,14.2799,100,1,12.4199,700,1,14.4299,100,1,12.3699,700,1,14.5299,100,1,ARL,325176181
1628,2025-07-17T16:01:56.269458197Z,2025-07-17T16:01:56.269458197Z,10,2,1108,C,A,0,13.9000,100,130,165591,271251357,13.0399,2,1,13.5500,15,1,13.0299,100,1,13.5600,100,1,13.0199,100,1,13.5700,15,1,12.7300,100,1,13.5899,100,1,12.7100,100,1,14.0099,2,1,12.5000,700,1,14.1899,100,1,12.4600,200,2,14.2799,100,1,12.4299,700,1,14.4299,100,1,12.4199,700,1,14.5299,100,1,12.3699,700,1,14.5399,100,1,ARL,324186721
1629,2025-07-17T16:01:56.269508928Z,2025-07-17T16:01:56.269508928Z,10,2,1108,A,A,0,13.8300,100,130,165304,271251358,13.0399,2,1,13.5500,15,1,13.0299,100,1,13.5600,100,1,13.0199,100,1,13.5700,15,1,12.7300,100,1,13.5899,100,1,12.7100,100,1,13.8300,100,1,12.5000,700,1,14.0099,2,1,12.4600,200,2,14.1899,100,1,12.4299,700,1,14.2799,100,1,12.4199,700,1,14.4299,100,1,12.3699,700,1,14.5299,100,1,ARL,325176373
1630,2025-07-17T16:01:56.272175169Z,2025-07-17T16:01:56.272175169Z,10,2,1108,C,A,0,15.7599,100,0,165561,271251490,13.0399,2,1,13.5500,15,1,13.0299,100,1,13.5600,100,1,13.0199,100,1,13.5700,15,1,12.7300,100,1,13.5899,100,1,12.7100,100,1,13.8300,100,1,12.5000,700,1,14.0099,2,1,12.4600,200,2,14.1899,100,1,12.4299,700,1,14.2799,100,1,12.4199,700,1,14.4299,100,1,12.3699,700,1,14.5299,100,1,ARL,323599629
1631,2025-07-17T16:01:56.272175169Z,2025-07-17T16:01:56.272175169Z,10,2,1108,A,A,0,15.5999,100,130,165561,271251490,13.0399,2,1,13.5500,15,1,13.0299,100,1,13.5600,100,1,13.0199,100,1,13.5700,15,1,12.7300,100,1,13.5899,100,1,12.7100,100,1,13.8300,100,1,12.5000,700,1,14.0099,2,1,12.4600,200,2,14.1899,100,1,12.4299,700,1,14.2799,100,1,12.4199,700,1,14.4299,100,1,12.3699,700,1,14.5299,100,1,ARL,325176677
1632,2025-07-17T16:01:56.300723805Z,2025-07-17T16:01:56.300723805Z,10,2,1108,C,A,0,14.6600,100,0,165573,271252044,13.0399,2,1,13.5500,15,1,13.0299,100,1,13.5600,100,1,13.0199,100,1,13.5700,15,1,12.7300,100,1,13.5899,100,1,12.7100,100,1,13.8300,100,1,12.5000,700,1,14.0099,2,1,12.4600,200,2,14.1899,100,1,12.4299,700,1,14.2799,100,1,12.4199,700,1,14.4299,100,1,12.3699,700,1,14.5299,100,1,ARL,323599625
1633,2025-07-17T16:01:56.300723805Z,2025-07-17T16:01:56.300723805Z,10,2,1108,A,A,0,14.5099,100,130,165573,271252044,13.0399,2,1,13.5500,15,1,13.0299,100,1,13.5600,100,1,13.0199,100,1,13.5700,15,1,12.7300,100,1,13.5899,100,1,12.7100,100,1,13.8300,100,1,12.5000,700,1,14.0099,2,1,12.4600,200,2,14.1899,100,1,12.4299,700,1,14.2799,100,1,12.4199,700,1,14.4299,100,1,12.3699,700,1,14.5099,100,1,ARL,325177757
1634,2025-07-17T16:01:56.776814001Z,2025-07-17T16:01:56.776814001Z,10,2,1108,T,N,0,13.4100,16,130,166243,271255700,13.0399,2,1,13.5500,15,1,13.0299,100,1,13.5600,100,1,13.0199,100,1,13.5700,15,1,12.7300,100,1,13.5899,100,1,12.7100,100,1,13.8300,100,1,12.5000,700,1,14.0099,2,1,12.4600,200,2,14.1899,100,1,12.4299,700,1,14.2799,100,1,12.4199,700,1,14.4299,100,1,12.3699,700,1,14.5099,100,1,ARL,0
1635,2025-07-17T16:01:56.777248616Z,2025-07-17T16:01:56.777248616Z,10,2,1108,T,N,0,13.4100,16,130,165716,271255708,13.0399,2,1,13.5500,15,1,13.0299,100,1,13.5600,100,1,13.0199,100,1,13.5700,15,1,12.7300,100,1,13.5899,100,1,12.7100,100,1,13.8300,100,1,12.5000,700,1,14.0099,2,1,12.4600,200,2,14.1899,100,1,12.4299,700,1,14.2799,100,1,12.4199,700,1,14.4299,100,1,12.3699,700,1,14.5099,100,1,ARL,0
1636,2025-07-17T16:01:56.777739254Z,2025-07-17T16:01:56.777739254Z,10,2,1108,T,N,0,13.4100,4,130,166815,271255712,13.0399,2,1,13.5500,15,1,13.0299,100,1,13.5600,100,1,13.0199,100,1,13.5700,15,1,12.7300,100,1,13.5899,100,1,12.7100,100,1,13.8300,100,1,12.5000,700,1,14.0099,2,1,12.4600,200,2,14.1899,100,1,12.4299,700,1,14.2799,100,1,12.4199,700,1,14.4299,100,1,12.3699,700,1,14.5099,100,1,ARL,0
1637,2025-07-17T16:02:01.992379223Z,2025-07-17T16:02:01.992379223Z,10,2,1108,C,A,0,14.0099,2,0,165384,271343251,13.0399,2,1,13.5500,15,1,13.0299,100,1,13.5600,100,1,13.0199,100,1,13.5700,15,1,12.7300,100,1,13.5899,100,1,12.7100,100,1,13.8300,100,1,12.5000,700,1,14.1899,100,1,12.4600,200,2,14.2799,100,1,12.4299,700,1,14.4299,100,1,12.4199,700,1,14.5099,100,1,12.3699,700,1,14.5299,100,1,ARL,322898193
1638,2025-07-17T16:02:01.992379223Z,2025-07-17T16:02:01.992379223Z,10,2,1108,A,A,0,13.9199,2,130,165384,271343251,13.0399,2,1,13.5500,15,1,13.0299,100,1,13.5600,100,1,13.0199,100,1,13.5700,15,1,12.7300,100,1,13.5899,100,1,12.7100,100,1,13.8300,100,1,12.5000,700,1,13.9199,2,1,12.4600,200,2,14.1899,100,1,12.4299,700,1,14.2799,100,1,12.4199,700,1,14.4299,100,1,12.3699,700,1,14.5099,100,1,ARL,325297093
1639,2025-07-17T16:02:03.207555626Z,2025-07-17T16:02:03.207555626Z,10,2,1108,C,A,0,13.5700,15,130,165200,271367066,13.0399,2,1,13.5500,15,1,13.0299,100,1,13.5600,100,1,13.0199,100,1,13.5899,100,1,12.7300,100,1,13.8300,100,1,12.7100,100,1,13.9199,2,1,12.5000,700,1,14.1899,100,1,12.4600,200,2,14.2799,100,1,12.4299,700,1,14.4299,100,1,12.4199,700,1,14.5099,100,1,12.3699,700,1,14.5299,100,1,ARL,324934601
1640,2025-07-17T16:02:04.212791108Z,2025-07-17T16:02:04.212791108Z,10,2,1108,A,A,0,13.5299,15,130,165231,271415821,13.0399,2,1,13.5299,15,1,13.0299,100,1,13.5500,15,1,13.0199,100,1,13.5600,100,1,12.7300,100,1,13.5899,100,1,12.7100,100,1,13.8300,100,1,12.5000,700,1,13.9199,2,1,12.4600,200,2,14.1899,100,1,12.4299,700,1,14.2799,100,1,12.4199,700,1,14.4299,100,1,12.3699,700,1,14.5099,100,1,ARL,325382429
1641,2025-07-17T16:02:04.214183279Z,2025-07-17T16:02:04.214183279Z,10,2,1108,C,A,0,14.5399,100,0,165535,271415834,13.0399,2,1,13.5299,15,1,13.0299,100,1,13.5500,15,1,13.0199,100,1,13.5600,100,1,12.7300,100,1,13.5899,100,1,12.7100,100,1,13.8300,100,1,12.5000,700,1,13.9199,2,1,12.4600,200,2,14.1899,100,1,12.4299,700,1,14.2799,100,1,12.4199,700,1,14.4299,100,1,12.3699,700,1,14.5099,100,1,ARL,323775433
1642,2025-07-17T16:02:04.214183279Z,2025-07-17T16:02:04.214183279Z,10,2,1108,A,A,0,14.4299,100,130,165535,271415834,13.0399,2,1,13.5299,15,1,13.0299,100,1,13.5500,15,1,13.0199,100,1,13.5600,100,1,12.7300,100,1,13.5899,100,1,12.7100,100,1,13.8300,100,1,12.5000,700,1,13.9199,2,1,12.4600,200,2,14.1899,100,1,12.4299,700,1,14.2799,100,1,12.4199,700,1,14.4299,200,2,12.3699,700,1,14.5099,100,1,ARL,325382437
1643,2025-07-17T16:02:04.839967173Z,2025-07-17T16:02:04.839967173Z,10,2,1108,C,A,0,13.5600,100,0,165495,271432190,13.0399,2,1,13.5299,15,1,13.0299,100,1,13.5500,15,1,13.0199,100,1,13.5899,100,1,12.7300,100,1,13.8300,100,1,12.7100,100,1,13.9199,2,1,12.5000,700,1,14.1899,100,1,12.4600,200,2,14.2799,100,1,12.4299,700,1,14.4299,200,2,12.4199,700,1,14.5099,100,1,12.3699,700,1,14.5299,100,1,ARL,325176181
1644,2025-07-17T16:02:04.839967173Z,2025-07-17T16:02:04.839967173Z,10,2,1108,A,A,0,13.5399,100,130,165495,271432190,13.0399,2,1,13.5299,15,1,13.0299,100,1,13.5399,100,1,13.0199,100,1,13.5500,15,1,12.7300,100,1,13.5899,100,1,12.7100,100,1,13.8300,100,1,12.5000,700,1,13.9199,2,1,12.4600,200,2,14.1899,100,1,12.4299,700,1,14.2799,100,1,12.4199,700,1,14.4299,200,2,12.3699,700,1,14.5099,100,1,ARL,325400045
1645,2025-07-17T16:02:04.840006082Z,2025-07-17T16:02:04.840006082Z,10,2,1108,A,A,0,14.2699,700,130,165158,271432192,13.0399,2,1,13.5299,15,1,13.0299,100,1,13.5399,100,1,13.0199,100,1,13.5500,15,1,12.7300,100,1,13.5899,100,1,12.7100,100,1,13.8300,100,1,12.5000,700,1,13.9199,2,1,12.4600,200,2,14.1899,100,1,12.4299,700,1,14.2699,700,1,12.4199,700,1,14.2799,100,1,12.3699,700,1,14.4299,200,2,ARL,325400053
1646,2025-07-17T16:02:04.840045694Z,2025-07-17T16:02:04.840045694Z,10,2,1108,C,A,0,14.6799,700,130,165186,271432193,13.0399,2,1,13.5299,15,1,13.0299,100,1,13.5399,100,1,13.0199,100,1,13.5500,15,1,12.7300,100,1,13.5899,100,1,12.7100,100,1,13.8300,100,1,12.5000,700,1,13.9199,2,1,12.4600,200,2,14.1899,100,1,12.4299,700,1,14.2699,700,1,12.4199,700,1,14.2799,100,1,12.3699,700,1,14.4299,200,2,ARL,283592941
1647,2025-07-17T16:02:04.840711803Z,2025-07-17T16:02:04.840711803Z,10,2,1108,C,A,0,14.6300,100,0,165800,271432231,13.0399,2,1,13.5299,15,1,13.0299,100,1,13.5399,100,1,13.0199,100,1,13.5500,15,1,12.7300,100,1,13.5899,100,1,12.7100,100,1,13.8300,100,1,12.5000,700,1,13.9199,2,1,12.4600,200,2,14.1899,100,1,12.4299,700,1,14.2699,700,1,12.4199,700,1,14.2799,100,1,12.3699,700,1,14.4299,200,2,ARL,324942257
1648,2025-07-17T16:02:04.840711803Z,2025-07-17T16:02:04.840711803Z,10,2,1108,A,A,0,14.5899,100,130,165800,271432231,13.0399,2,1,13.5299,15,1,13.0299,100,1,13.5399,100,1,13.0199,100,1,13.5500,15,1,12.7300,100,1,13.5899,100,1,12.7100,100,1,13.8300,100,1,12.5000,700,1,13.9199,2,1,12.4600,200,2,14.1899,100,1,12.4299,700,1,14.2699,700,1,12.4199,700,1,14.2799,100,1,12.3699,700,1,14.4299,200,2,ARL,325400105
1649,2025-07-17T16:02:11.249125653Z,2025-07-17T16:02:11.249125653Z,10,2,1108,C,A,0,14.5299,100,0,165489,271526467,13.0399,2,1,13.5299,15,1,13.0299,100,1,13.5399,100,1,13.0199,100,1,13.5500,15,1,12.7300,100,1,13.5899,100,1,12.7100,100,1,13.8300,100,1,12.5000,700,1,13.9199,2,1,12.4600,200,2,14.1899,100,1,12.4299,700,1,14.2699,700,1,12.4199,700,1,14.2799,100,1,12.3699,700,1,14.4299,200,2,ARL,323775457
1650,2025-07-17T16:02:11.249125653Z,2025-07-17T16:02:11.249125653Z,10,2,1108,A,A,0,14.4199,100,130,165489,271526467,13.0399,2,1,13.5299,15,1,13.0299,100,1,13.5399,100,1,13.0199,100,1,13.5500,15,1,12.7300,100,1,13.5899,100,1,12.7100,100,1,13.8300,100,1,12.5000,700,1,13.9199,2,1,12.4600,200,2,14.1899,100,1,12.4299,700,1,14.2699,700,1,12.4199,700,1,14.2799,100,1,12.3699,700,1,14.4199,100,1,ARL,325520705
1651,2025-07-17T16:02:15.062605521Z,2025-07-17T16:02:15.062605521Z,10,2,1108,C,A,0,13.5299,15,128,169140,271576282,13.0399,2,1,13.5399,100,1,13.0299,100,1,13.5500,15,1,13.0199,100,1,13.5899,100,1,12.7300,100,1,13.8300,100,1,12.7100,100,1,13.9199,2,1,12.5000,700,1,14.1899,100,1,12.4600,200,2,14.2699,700,1,12.4299,700,1,14.2799,100,1,12.4199,700,1,14.4199,100,1,12.3699,700,1,14.4299,200,2,ARL,325382429
1652,2025-07-17T16:02:15.068283706Z,2025-07-17T16:02:15.068283706Z,10,2,1108,C,A,0,13.5500,15,130,165342,271577104,13.0399,2,1,13.5399,100,1,13.0299,100,1,13.5899,100,1,13.0199,100,1,13.8300,100,1,12.7300,100,1,13.9199,2,1,12.7100,100,1,14.1899,100,1,12.5000,700,1,14.2699,700,1,12.4600,200,2,14.2799,100,1,12.4299,700,1,14.4199,100,1,12.4199,700,1,14.4299,200,2,12.3699,700,1,14.5099,100,1,ARL,325109165
1653,2025-07-17T16:02:20.634863301Z,2025-07-17T16:02:20.634863301Z,10,2,1108,C,A,0,13.5399,100,130,165188,271675842,13.0399,2,1,13.5899,100,1,13.0299,100,1,13.8300,100,1,13.0199,100,1,13.9199,2,1,12.7300,100,1,14.1899,100,1,12.7100,100,1,14.2699,700,1,12.5000,700,1,14.2799,100,1,12.4600,200,2,14.4199,100,1,12.4299,700,1,14.4299,200,2,12.4199,700,1,14.5099,100,1,12.3699,700,1,14.5600,800,2,ARL,325400045
1654,2025-07-17T16:02:20.635616654Z,2025-07-17T16:02:20.635616654Z,10,2,1108,C,A,0,14.5899,100,0,165818,271675858,13.0399,2,1,13.5899,100,1,13.0299,100,1,13.8300,100,1,13.0199,100,1,13.9199,2,1,12.7300,100,1,14.1899,100,1,12.7100,100,1,14.2699,700,1,12.5000,700,1,14.2799,100,1,12.4600,200,2,14.4199,100,1,12.4299,700,1,14.4299,200,2,12.4199,700,1,14.5099,100,1,12.3699,700,1,14.5600,800,2,ARL,325400105
1655,2025-07-17T16:02:20.635616654Z,2025-07-17T16:02:20.635616654Z,10,2,1108,A,A,0,14.6400,100,130,165818,271675858,13.0399,2,1,13.5899,100,1,13.0299,100,1,13.8300,100,1,13.0199,100,1,13.9199,2,1,12.7300,100,1,14.1899,100,1,12.7100,100,1,14.2699,700,1,12.5000,700,1,14.2799,100,1,12.4600,200,2,14.4199,100,1,12.4299,700,1,14.4299,200,2,12.4199,700,1,14.5099,100,1,12.3699,700,1,14.5600,800,2,ARL,325714169
1656,2025-07-17T16:02:20.650301212Z,2025-07-17T16:02:20.650301212Z,10,2,1108,C,A,0,13.5899,100,130,165539,271676032,13.0399,2,1,13.8300,100,1,13.0299,100,1,13.9199,2,1,13.0199,100,1,14.1899,100,1,12.7300,100,1,14.2699,700,1,12.7100,100,1,14.2799,100,1,12.5000,700,1,14.4199,100,1,12.4600,200,2,14.4299,200,2,12.4299,700,1,14.5099,100,1,12.4199,700,1,14.5600,800,2,12.3699,700,1,14.5700,100,1,ARL,325022101
1657,2025-07-17T16:02:20.650335946Z,2025-07-17T16:02:20.650335946Z,10,2,1108,C,A,0,14.2699,700,130,165502,271676033,13.0399,2,1,13.8300,100,1,13.0299,100,1,13.9199,2,1,13.0199,100,1,14.1899,100,1,12.7300,100,1,14.2799,100,1,12.7100,100,1,14.4199,100,1,12.5000,700,1,14.4299,200,2,12.4600,200,2,14.5099,100,1,12.4299,700,1,14.5600,800,2,12.4199,700,1,14.5700,100,1,12.3699,700,1,14.5999,700,1,ARL,325400053
1658,2025-07-17T16:02:20.650381040Z,2025-07-17T16:02:20.650381040Z,10,2,1108,A,A,0,14.5299,700,130,165443,271676035,13.0399,2,1,13.8300,100,1,13.0299,100,1,13.9199,2,1,13.0199,100,1,14.1899,100,1,12.7300,100,1,14.2799,100,1,12.7100,100,1,14.4199,100,1,12.5000,700,1,14.4299,200,2,12.4600,200,2,14.5099,100,1,12.4299,700,1,14.5299,700,1,12.4199,700,1,14.5600,800,2,12.3699,700,1,14.5700,100,1,ARL,325714545
1659,2025-07-17T16:02:20.651020858Z,2025-07-17T16:02:20.651020858Z,10,2,1108,C,A,0,14.4199,100,0,165679,271676048,13.0399,2,1,13.8300,100,1,13.0299,100,1,13.9199,2,1,13.0199,100,1,14.1899,100,1,12.7300,100,1,14.2799,100,1,12.7100,100,1,14.4299,200,2,12.5000,700,1,14.5099,100,1,12.4600,200,2,14.5299,700,1,12.4299,700,1,14.5600,800,2,12.4199,700,1,14.5700,100,1,12.3699,700,1,14.5999,700,1,ARL,325520705
1660,2025-07-17T16:02:20.651020858Z,2025-07-17T16:02:20.651020858Z,10,2,1108,A,A,0,14.7300,100,130,165679,271676048,13.0399,2,1,13.8300,100,1,13.0299,100,1,13.9199,2,1,13.0199,100,1,14.1899,100,1,12.7300,100,1,14.2799,100,1,12.7100,100,1,14.4299,200,2,12.5000,700,1,14.5099,100,1,12.4600,200,2,14.5299,700,1,12.4299,700,1,14.5600,800,2,12.4199,700,1,14.5700,100,1,12.3699,700,1,14.5999,700,1,ARL,325714577
1661,2025-07-17T16:02:20.651035000Z,2025-07-17T16:02:20.651035000Z,10,2,1108,C,A,0,14.1899,100,130,166182,271676049,13.0399,2,1,13.8300,100,1,13.0299,100,1,13.9199,2,1,13.0199,100,1,14.2799,100,1,12.7300,100,1,14.4299,200,2,12.7100,100,1,14.5099,100,1,12.5000,700,1,14.5299,700,1,12.4600,200,2,14.5600,800,2,12.4299,700,1,14.5700,100,1,12.4199,700,1,14.5999,700,1,12.3699,700,1,14.6400,100,1,ARL,324942273
1662,2025-07-17T16:02:20.651293729Z,2025-07-17T16:02:20.651293729Z,10,2,1108,C,A,0,17.2500,100,0,165588,271676055,13.0399,2,1,13.8300,100,1,13.0299,100,1,13.9199,2,1,13.0199,100,1,14.2799,100,1,12.7300,100,1,14.4299,200,2,12.7100,100,1,14.5099,100,1,12.5000,700,1,14.5299,700,1,12.4600,200,2,14.5600,800,2,12.4299,700,1,14.5700,100,1,12.4199,700,1,14.5999,700,1,12.3699,700,1,14.6400,100,1,ARL,324942361
1663,2025-07-17T16:02:20.651293729Z,2025-07-17T16:02:20.651293729Z,10,2,1108,A,A,0,17.5700,100,130,165588,271676055,13.0399,2,1,13.8300,100,1,13.0299,100,1,13.9199,2,1,13.0199,100,1,14.2799,100,1,12.7300,100,1,14.4299,200,2,12.7100,100,1,14.5099,100,1,12.5000,700,1,14.5299,700,1,12.4600,200,2,14.5600,800,2,12.4299,700,1,14.5700,100,1,12.4199,700,1,14.5999,700,1,12.3699,700,1,14.6400,100,1,ARL,325714589
1664,2025-07-17T16:02:20.651393708Z,2025-07-17T16:02:20.651393708Z,10,2,1108,A,A,0,14.4499,100,130,165240,271676057,13.0399,2,1,13.8300,100,1,13.0299,100,1,13.9199,2,1,13.0199,100,1,14.2799,100,1,12.7300,100,1,14.4299,200,2,12.7100,100,1,14.4499,100,1,12.5000,700,1,14.5099,100,1,12.4600,200,2,14.5299,700,1,12.4299,700,1,14.5600,800,2,12.4199,700,1,14.5700,100,1,12.3699,700,1,14.5999,700,1,ARL,325714601
1665,2025-07-17T16:02:20.651618897Z,2025-07-17T16:02:20.651618897Z,10,2,1108,C,A,0,14.4299,100,0,168916,271676089,13.0399,2,1,13.8300,100,1,13.0299,100,1,13.9199,2,1,13.0199,100,1,14.2799,100,1,12.7300,100,1,14.4299,100,1,12.7100,100,1,14.4499,100,1,12.5000,700,1,14.5099,100,1,12.4600,200,2,14.5299,700,1,12.4299,700,1,14.5600,800,2,12.4199,700,1,14.5700,100,1,12.3699,700,1,14.5999,700,1,ARL,325382437
1666,2025-07-17T16:02:20.651618897Z,2025-07-17T16:02:20.651618897Z,10,2,1108,A,A,0,14.7300,100,128,168916,271676089,13.0399,2,1,13.8300,100,1,13.0299,100,1,13.9199,2,1,13.0199,100,1,14.2799,100,1,12.7300,100,1,14.4299,100,1,12.7100,100,1,14.4499,100,1,12.5000,700,1,14.5099,100,1,12.4600,200,2,14.5299,700,1,12.4299,700,1,14.5600,800,2,12.4199,700,1,14.5700,100,1,12.3699,700,1,14.5999,700,1,ARL,325714613
1667,2025-07-17T16:02:20.651854531Z,2025-07-17T16:02:20.651854531Z,10,2,1108,C,A,0,14.5700,100,0,167087,271676104,13.0399,2,1,13.8300,100,1,13.0299,100,1,13.9199,2,1,13.0199,100,1,14.2799,100,1,12.7300,100,1,14.4299,100,1,12.7100,100,1,14.4499,100,1,12.5000,700,1,14.5099,100,1,12.4600,200,2,14.5299,700,1,12.4299,700,1,14.5600,800,2,12.4199,700,1,14.5999,700,1,12.3699,700,1,14.6400,100,1,ARL,324619409
1668,2025-07-17T16:02:20.651854531Z,2025-07-17T16:02:20.651854531Z,10,2,1108,A,A,0,14.8000,100,130,167087,271676104,13.0399,2,1,13.8300,100,1,13.0299,100,1,13.9199,2,1,13.0199,100,1,14.2799,100,1,12.7300,100,1,14.4299,100,1,12.7100,100,1,14.4499,100,1,12.5000,700,1,14.5099,100,1,12.4600,200,2,14.5299,700,1,12.4299,700,1,14.5600,800,2,12.4199,700,1,14.5999,700,1,12.3699,700,1,14.6400,100,1,ARL,325714629
1669,2025-07-17T16:02:20.651932129Z,2025-07-17T16:02:20.651932129Z,10,2,1108,C,A,0,14.4299,100,130,165159,271676110,13.0399,2,1,13.8300,100,1,13.0299,100,1,13.9199,2,1,13.0199,100,1,14.2799,100,1,12.7300,100,1,14.4499,100,1,12.7100,100,1,14.5099,100,1,12.5000,700,1,14.5299,700,1,12.4600,200,2,14.5600,800,2,12.4299,700,1,14.5999,700,1,12.4199,700,1,14.6400,100,1,12.3699,700,1,14.6799,700,1,ARL,324186781
1670,2025-07-17T16:02:20.651994883Z,2025-07-17T16:02:20.651994883Z,10,2,1108,C,A,0,15.5999,100,0,165587,271676111,13.0399,2,1,13.8300,100,1,13.0299,100,1,13.9199,2,1,13.0199,100,1,14.2799,100,1,12.7300,100,1,14.4499,100,1,12.7100,100,1,14.5099,100,1,12.5000,700,1,14.5299,700,1,12.4600,200,2,14.5600,800,2,12.4299,700,1,14.5999,700,1,12.4199,700,1,14.6400,100,1,12.3699,700,1,14.6799,700,1,ARL,325176677
1671,2025-07-17T16:02:20.651994883Z,2025-07-17T16:02:20.651994883Z,10,2,1108,A,A,0,15.9100,100,130,165587,271676111,13.0399,2,1,13.8300,100,1,13.0299,100,1,13.9199,2,1,13.0199,100,1,14.2799,100,1,12.7300,100,1,14.4499,100,1,12.7100,100,1,14.5099,100,1,12.5000,700,1,14.5299,700,1,12.4600,200,2,14.5600,800,2,12.4299,700,1,14.5999,700,1,12.4199,700,1,14.6400,100,1,12.3699,700,1,14.6799,700,1,ARL,325714633
1672,2025-07-17T16:02:20.652094426Z,2025-07-17T16:02:20.652094426Z,10,2,1108,A,A,0,14.6300,100,130,165505,271676118,13.0399,2,1,13.8300,100,1,13.0299,100,1,13.9199,2,1,13.0199,100,1,14.2799,100,1,12.7300,100,1,14.4499,100,1,12.7100,100,1,14.5099,100,1,12.5000,700,1,14.5299,700,1,12.4600,200,2,14.5600,800,2,12.4299,700,1,14.5999,700,1,12.4199,700,1,14.6300,100,1,12.3699,700,1,14.6400,100,1,ARL,325714653
1673,2025-07-17T16:02:20.653460814Z,2025-07-17T16:02:20.653460814Z,10,2,1108,A,B,0,13.2699,10,130,165577,271676147,13.2699,10,1,13.8300,100,1,13.0399,2,1,13.9199,2,1,13.0299,100,1,14.2799,100,1,13.0199,100,1,14.4499,100,1,12.7300,100,1,14.5099,100,1,12.7100,100,1,14.5299,700,1,12.5000,700,1,14.5600,800,2,12.4600,200,2,14.5999,700,1,12.4299,700,1,14.6300,100,1,12.4199,700,1,14.6400,100,1,ARL,325714717
1674,2025-07-17T16:02:20.653461966Z,2025-07-17T16:02:20.653461966Z,10,2,1108,A,A,0,13.8300,15,130,165266,271676148,13.2699,10,1,13.8300,115,2,13.0399,2,1,13.9199,2,1,13.0299,100,1,14.2799,100,1,13.0199,100,1,14.4499,100,1,12.7300,100,1,14.5099,100,1,12.7100,100,1,14.5299,700,1,12.5000,700,1,14.5600,800,2,12.4600,200,2,14.5999,700,1,12.4299,700,1,14.6300,100,1,12.4199,700,1,14.6400,100,1,ARL,325714721
1675,2025-07-17T16:02:20.653721185Z,2025-07-17T16:02:20.653721185Z,10,2,1108,C,B,0,13.0199,100,0,165711,271676153,13.2699,10,1,13.8300,115,2,13.0399,2,1,13.9199,2,1,13.0299,100,1,14.2799,100,1,12.7300,100,1,14.4499,100,1,12.7100,100,1,14.5099,100,1,12.5000,700,1,14.5299,700,1,12.4600,200,2,14.5600,800,2,12.4299,700,1,14.5999,700,1,12.4199,700,1,14.6300,100,1,12.3699,700,1,14.6400,100,1,ARL,320485385
1676,2025-07-17T16:02:20.653721185Z,2025-07-17T16:02:20.653721185Z,10,2,1108,A,B,0,13.2599,100,130,165711,271676153,13.2699,10,1,13.8300,115,2,13.2599,100,1,13.9199,2,1,13.0399,2,1,14.2799,100,1,13.0299,100,1,14.4499,100,1,12.7300,100,1,14.5099,100,1,12.7100,100,1,14.5299,700,1,12.5000,700,1,14.5600,800,2,12.4600,200,2,14.5999,700,1,12.4299,700,1,14.6300,100,1,12.4199,700,1,14.6400,100,1,ARL,325714729
1677,2025-07-17T16:02:20.655111649Z,2025-07-17T16:02:20.655111649Z,10,2,1108,C,B,0,13.0399,2,0,165417,271676165,13.2699,10,1,13.8300,115,2,13.2599,100,1,13.9199,2,1,13.0299,100,1,14.2799,100,1,12.7300,100,1,14.4499,100,1,12.7100,100,1,14.5099,100,1,12.5000,700,1,14.5299,700,1,12.4600,200,2,14.5600,800,2,12.4299,700,1,14.5999,700,1,12.4199,700,1,14.6300,100,1,12.3699,700,1,14.6400,100,1,ARL,293594281
1678,2025-07-17T16:02:20.655111649Z,2025-07-17T16:02:20.655111649Z,10,2,1108,A,B,0,12.9100,2,130,165417,271676165,13.2699,10,1,13.8300,115,2,13.2599,100,1,13.9199,2,1,13.0299,100,1,14.2799,100,1,12.9100,2,1,14.4499,100,1,12.7300,100,1,14.5099,100,1,12.7100,100,1,14.5299,700,1,12.5000,700,1,14.5600,800,2,12.4600,200,2,14.5999,700,1,12.4299,700,1,14.6300,100,1,12.4199,700,1,14.6400,100,1,ARL,325714741
1679,2025-07-17T16:02:20.663209235Z,2025-07-17T16:02:20.663209235Z,10,2,1108,C,A,0,13.8300,100,130,165341,271676274,13.2699,10,1,13.8300,15,1,13.2599,100,1,13.9199,2,1,13.0299,100,1,14.2799,100,1,12.9100,2,1,14.4499,100,1,12.7300,100,1,14.5099,100,1,12.7100,100,1,14.5299,700,1,12.5000,700,1,14.5600,800,2,12.4600,200,2,14.5999,700,1,12.4299,700,1,14.6300,100,1,12.4199,700,1,14.6400,100,1,ARL,325176373
1680,2025-07-17T16:02:20.663241882Z,2025-07-17T16:02:20.663241882Z,10,2,1108,C,A,0,14.5299,700,130,164979,271676275,13.2699,10,1,13.8300,15,1,13.2599,100,1,13.9199,2,1,13.0299,100,1,14.2799,100,1,12.9100,2,1,14.4499,100,1,12.7300,100,1,14.5099,100,1,12.7100,100,1,14.5600,800,2,12.5000,700,1,14.5999,700,1,12.4600,200,2,14.6300,100,1,12.4299,700,1,14.6400,100,1,12.4199,700,1,14.6799,700,1,ARL,325714545
1681,2025-07-17T16:02:20.663261632Z,2025-07-17T16:02:20.663261632Z,10,2,1108,A,A,0,14.1099,100,130,165342,271676276,13.2699,10,1,13.8300,15,1,13.2599,100,1,13.9199,2,1,13.0299,100,1,14.1099,100,1,12.9100,2,1,14.2799,100,1,12.7300,100,1,14.4499,100,1,12.7100,100,1,14.5099,100,1,12.5000,700,1,14.5600,800,2,12.4600,200,2,14.5999,700,1,12.4299,700,1,14.6300,100,1,12.4199,700,1,14.6400,100,1,ARL,325714905
1682,2025-07-17T16:02:20.663394059Z,2025-07-17T16:02:20.663394059Z,10,2,1108,A,A,0,15.9399,100,130,165407,271676277,13.2699,10,1,13.8300,15,1,13.2599,100,1,13.9199,2,1,13.0299,100,1,14.1099,100,1,12.9100,2,1,14.2799,100,1,12.7300,100,1,14.4499,100,1,12.7100,100,1,14.5099,100,1,12.5000,700,1,14.5600,800,2,12.4600,200,2,14.5999,700,1,12.4299,700,1,14.6300,100,1,12.4199,700,1,14.6400,100,1,ARL,325714909
1683,2025-07-17T16:02:20.663407337Z,2025-07-17T16:02:20.663407337Z,10,2,1108,C,A,0,15.5899,100,130,165297,271676278,13.2699,10,1,13.8300,15,1,13.2599,100,1,13.9199,2,1,13.0299,100,1,14.1099,100,1,12.9100,2,1,14.2799,100,1,12.7300,100,1,14.4499,100,1,12.7100,100,1,14.5099,100,1,12.5000,700,1,14.5600,800,2,12.4600,200,2,14.5999,700,1,12.4299,700,1,14.6300,100,1,12.4199,700,1,14.6400,100,1,ARL,323730697
1684,2025-07-17T16:02:20.664790768Z,2025-07-17T16:02:20.664790768Z,10,2,1108,C,A,0,17.5700,100,0,165632,271676310,13.2699,10,1,13.8300,15,1,13.2599,100,1,13.9199,2,1,13.0299,100,1,14.1099,100,1,12.9100,2,1,14.2799,100,1,12.7300,100,1,14.4499,100,1,12.7100,100,1,14.5099,100,1,12.5000,700,1,14.5600,800,2,12.4600,200,2,14.5999,700,1,12.4299,700,1,14.6300,100,1,12.4199,700,1,14.6400,100,1,ARL,325714589
1685,2025-07-17T16:02:20.664790768Z,2025-07-17T16:02:20.664790768Z,10,2,1108,A,A,0,17.7600,100,130,165632,271676310,13.2699,10,1,13.8300,15,1,13.2599,100,1,13.9199,2,1,13.0299,100,1,14.1099,100,1,12.9100,2,1,14.2799,100,1,12.7300,100,1,14.4499,100,1,12.7100,100,1,14.5099,100,1,12.5000,700,1,14.5600,800,2,12.4600,200,2,14.5999,700,1,12.4299,700,1,14.6300,100,1,12.4199,700,1,14.6400,100,1,ARL,325714949
1686,2025-07-17T16:02:20.664963386Z,2025-07-17T16:02:20.664963386Z,10,2,1108,C,A,0,14.8000,100,0,165893,271676320,13.2699,10,1,13.8300,15,1,13.2599,100,1,13.9199,2,1,13.0299,100,1,14.1099,100,1,12.9100,2,1,14.2799,100,1,12.7300,100,1,14.4499,100,1,12.7100,100,1,14.5099,100,1,12.5000,700,1,14.5600,800,2,12.4600,200,2,14.5999,700,1,12.4299,700,1,14.6300,100,1,12.4199,700,1,14.6400,100,1,ARL,325714629
1687,2025-07-17T16:02:20.664963386Z,2025-07-17T16:02:20.664963386Z,10,2,1108,A,A,0,14.9600,100,130,165893,271676320,13.2699,10,1,13.8300,15,1,13.2599,100,1,13.9199,2,1,13.0299,100,1,14.1099,100,1,12.9100,2,1,14.2799,100,1,12.7300,100,1,14.4499,100,1,12.7100,100,1,14.5099,100,1,12.5000,700,1,14.5600,800,2,12.4600,200,2,14.5999,700,1,12.4299,700,1,14.6300,100,1,12.4199,700,1,14.6400,100,1,ARL,325714953
1688,2025-07-17T16:02:20.665034825Z,2025-07-17T16:02:20.665034825Z,10,2,1108,C,A,0,15.9100,100,0,165567,271676330,13.2699,10,1,13.8300,15,1,13.2599,100,1,13.9199,2,1,13.0299,100,1,14.1099,100,1,12.9100,2,1,14.2799,100,1,12.7300,100,1,14.4499,100,1,12.7100,100,1,14.5099,100,1,12.5000,700,1,14.5600,800,2,12.4600,200,2,14.5999,700,1,12.4299,700,1,14.6300,100,1,12.4199,700,1,14.6400,100,1,ARL,325714633
1689,2025-07-17T16:02:20.665034825Z,2025-07-17T16:02:20.665034825Z,10,2,1108,A,A,0,16.0799,100,130,165567,271676330,13.2699,10,1,13.8300,15,1,13.2599,100,1,13.9199,2,1,13.0299,100,1,14.1099,100,1,12.9100,2,1,14.2799,100,1,12.7300,100,1,14.4499,100,1,12.7100,100,1,14.5099,100,1,12.5000,700,1,14.5600,800,2,12.4600,200,2,14.5999,700,1,12.4299,700,1,14.6300,100,1,12.4199,700,1,14.6400,100,1,ARL,325714957
1690,2025-07-17T16:02:20.665292049Z,2025-07-17T16:02:20.665292049Z,10,2,1108,C,A,0,14.9399,100,0,165546,271676355,13.2699,10,1,13.8300,15,1,13.2599,100,1,13.9199,2,1,13.0299,100,1,14.1099,100,1,12.9100,2,1,14.2799,100,1,12.7300,100,1,14.4499,100,1,12.7100,100,1,14.5099,100,1,12.5000,700,1,14.5600,800,2,12.4600,200,2,14.5999,700,1,12.4299,700,1,14.6300,100,1,12.4199,700,1,14.6400,100,1,ARL,324942277
1691,2025-07-17T16:02:20.665292049Z,2025-07-17T16:02:20.665292049Z,10,2,1108,A,A,0,15.3800,100,130,165546,271676355,13.2699,10,1,13.8300,15,1,13.2599,100,1,13.9199,2,1,13.0299,100,1,14.1099,100,1,12.9100,2,1,14.2799,100,1,12.7300,100,1,14.4499,100,1,12.7100,100,1,14.5099,100,1,12.5000,700,1,14.5600,800,2,12.4600,200,2,14.5999,700,1,12.4299,700,1,14.6300,100,1,12.4199,700,1,14.6400,100,1,ARL,325714965
1692,2025-07-17T16:02:20.669536385Z,2025-07-17T16:02:20.669536385Z,10,2,1108,C,A,0,14.1099,100,130,165067,271676398,13.2699,10,1,13.8300,15,1,13.2599,100,1,13.9199,2,1,13.0299,100,1,14.2799,100,1,12.9100,2,1,14.4499,100,1,12.7300,100,1,14.5099,100,1,12.7100,100,1,14.5600,800,2,12.5000,700,1,14.5999,700,1,12.4600,200,2,14.6300,100,1,12.4299,700,1,14.6400,100,1,12.4199,700,1,14.6799,700,1,ARL,325714905
1693,2025-07-17T16:02:20.669583810Z,2025-07-17T16:02:20.669583810Z,10,2,1108,A,A,0,14.2599,100,130,165144,271676399,13.2699,10,1,13.8300,15,1,13.2599,100,1,13.9199,2,1,13.0299,100,1,14.2599,100,1,12.9100,2,1,14.2799,100,1,12.7300,100,1,14.4499,100,1,12.7100,100,1,14.5099,100,1,12.5000,700,1,14.5600,800,2,12.4600,200,2,14.5999,700,1,12.4299,700,1,14.6300,100,1,12.4199,700,1,14.6400,100,1,ARL,325715045
1694,2025-07-17T16:02:20.669587514Z,2025-07-17T16:02:20.669587514Z,10,2,1108,C,A,0,14.5099,100,0,165465,271676400,13.2699,10,1,13.8300,15,1,13.2599,100,1,13.9199,2,1,13.0299,100,1,14.2599,100,1,12.9100,2,1,14.2799,100,1,12.7300,100,1,14.4499,100,1,12.7100,100,1,14.5600,800,2,12.5000,700,1,14.5999,700,1,12.4600,200,2,14.6300,100,1,12.4299,700,1,14.6400,100,1,12.4199,700,1,14.6799,700,1,ARL,325177757
1695,2025-07-17T16:02:20.669587514Z,2025-07-17T16:02:20.669587514Z,10,2,1108,A,A,0,14.9600,100,130,165465,271676400,13.2699,10,1,13.8300,15,1,13.2599,100,1,13.9199,2,1,13.0299,100,1,14.2599,100,1,12.9100,2,1,14.2799,100,1,12.7300,100,1,14.4499,100,1,12.7100,100,1,14.5600,800,2,12.5000,700,1,14.5999,700,1,12.4600,200,2,14.6300,100,1,12.4299,700,1,14.6400,100,1,12.4199,700,1,14.6799,700,1,ARL,325715053
1696,2025-07-17T16:02:20.685086585Z,2025-07-17T16:02:20.685086585Z,10,2,1108,C,A,0,14.6400,100,0,165464,271676621,13.2699,10,1,13.8300,15,1,13.2599,100,1,13.9199,2,1,13.0299,100,1,14.2599,100,1,12.9100,2,1,14.2799,100,1,12.7300,100,1,14.4499,100,1,12.7100,100,1,14.5600,800,2,12.5000,700,1,14.5999,700,1,12.4600,200,2,14.6300,100,1,12.4299,700,1,14.6799,700,1,12.4199,700,1,14.7300,200,2,ARL,325714169
1697,2025-07-17T16:02:20.685086585Z,2025-07-17T16:02:20.685086585Z,10,2,1108,A,A,0,15.0600,100,130,165464,271676621,13.2699,10,1,13.8300,15,1,13.2599,100,1,13.9199,2,1,13.0299,100,1,14.2599,100,1,12.9100,2,1,14.2799,100,1,12.7300,100,1,14.4499,100,1,12.7100,100,1,14.5600,800,2,12.5000,700,1,14.5999,700,1,12.4600,200,2,14.6300,100,1,12.4299,700,1,14.6799,700,1,12.4199,700,1,14.7300,200,2,ARL,325715113
1698,2025-07-17T16:02:20.831947250Z,2025-07-17T16:02:20.831947250Z,10,2,1108,A,A,0,14.6799,700,130,165387,271678584,13.2699,10,1,13.8300,15,1,13.2599,100,1,13.9199,2,1,13.0299,100,1,14.2599,100,1,12.9100,2,1,14.2799,100,1,12.7300,100,1,14.4499,100,1,12.7100,100,1,14.5600,800,2,12.5000,700,1,14.5999,700,1,12.4600,200,2,14.6300,100,1,12.4299,700,1,14.6799,1400,2,12.4199,700,1,14.7300,200,2,ARL,325716945
1699,2025-07-17T16:02:20.936622241Z,2025-07-17T16:02:20.936622241Z,10,2,1108,C,B,0,13.2599,100,130,165177,271679553,13.2699,10,1,13.8300,15,1,13.0299,100,1,13.9199,2,1,12.9100,2,1,14.2599,100,1,12.7300,100,1,14.2799,100,1,12.7100,100,1,14.4499,100,1,12.5000,700,1,14.5600,800,2,12.4600,200,2,14.5999,700,1,12.4299,700,1,14.6300,100,1,12.4199,700,1,14.6799,1400,2,12.3699,700,1,14.7300,200,2,ARL,325714729
1700,2025-07-17T16:02:20.936672130Z,2025-07-17T16:02:20.936672130Z,10,2,1108,A,A,0,13.9100,5,130,165481,271679555,13.2699,10,1,13.8300,15,1,13.0299,100,1,13.9100,5,1,12.9100,2,1,13.9199,2,1,12.7300,100,1,14.2599,100,1,12.7100,100,1,14.2799,100,1,12.5000,700,1,14.4499,100,1,12.4600,200,2,14.5600,800,2,12.4299,700,1,14.5999,700,1,12.4199,700,1,14.6300,100,1,12.3699,700,1,14.6799,1400,2,ARL,325718477
1701,2025-07-17T16:02:20.936748894Z,2025-07-17T16:02:20.936748894Z,10,2,1108,T,N,0,13.2799,11,130,166007,271679557,13.2699,10,1,13.8300,15,1,13.0299,100,1,13.9100,5,1,12.9100,2,1,13.9199,2,1,12.7300,100,1,14.2599,100,1,12.7100,100,1,14.2799,100,1,12.5000,700,1,14.4499,100,1,12.4600,200,2,14.5600,800,2,12.4299,700,1,14.5999,700,1,12.4199,700,1,14.6300,100,1,12.3699,700,1,14.6799,1400,2,ARL,0
1702,2025-07-17T16:02:20.936833988Z,2025-07-17T16:02:20.936833988Z,10,2,1108,A,A,0,13.8399,100,130,165223,271679558,13.2699,10,1,13.8300,15,1,13.0299,100,1,13.8399,100,1,12.9100,2,1,13.9100,5,1,12.7300,100,1,13.9199,2,1,12.7100,100,1,14.2599,100,1,12.5000,700,1,14.2799,100,1,12.4600,200,2,14.4499,100,1,12.4299,700,1,14.5600,800,2,12.4199,700,1,14.5999,700,1,12.3699,700,1,14.6300,100,1,ARL,325718485
1703,2025-07-17T16:02:20.937142186Z,2025-07-17T16:02:20.937142186Z,10,2,1108,T,N,0,13.2799,11,130,165749,271679562,13.2699,10,1,13.8300,15,1,13.0299,100,1,13.8399,100,1,12.9100,2,1,13.9100,5,1,12.7300,100,1,13.9199,2,1,12.7100,100,1,14.2599,100,1,12.5000,700,1,14.2799,100,1,12.4600,200,2,14.4499,100,1,12.4299,700,1,14.5600,800,2,12.4199,700,1,14.5999,700,1,12.3699,700,1,14.6300,100,1,ARL,0
1704,2025-07-17T16:02:20.937578907Z,2025-07-17T16:02:20.937578907Z,10,2,1108,C,A,0,15.0600,100,0,165357,271679565,13.2699,10,1,13.8300,15,1,13.0299,100,1,13.8399,100,1,12.9100,2,1,13.9100,5,1,12.7300,100,1,13.9199,2,1,12.7100,100,1,14.2599,100,1,12.5000,700,1,14.2799,100,1,12.4600,200,2,14.4499,100,1,12.4299,700,1,14.5600,800,2,12.4199,700,1,14.5999,700,1,12.3699,700,1,14.6300,100,1,ARL,325715113
1705,2025-07-17T16:02:20.937578907Z,2025-07-17T16:02:20.937578907Z,10,2,1108,A,A,0,14.9100,100,130,165357,271679565,13.2699,10,1,13.8300,15,1,13.0299,100,1,13.8399,100,1,12.9100,2,1,13.9100,5,1,12.7300,100,1,13.9199,2,1,12.7100,100,1,14.2599,100,1,12.5000,700,1,14.2799,100,1,12.4600,200,2,14.4499,100,1,12.4299,700,1,14.5600,800,2,12.4199,700,1,14.5999,700,1,12.3699,700,1,14.6300,100,1,ARL,325718509
1706,2025-07-17T16:02:20.937736247Z,2025-07-17T16:02:20.937736247Z,10,2,1108,C,A,0,13.9100,5,130,165046,271679567,13.2699,10,1,13.8300,15,1,13.0299,100,1,13.8399,100,1,12.9100,2,1,13.9199,2,1,12.7300,100,1,14.2599,100,1,12.7100,100,1,14.2799,100,1,12.5000,700,1,14.4499,100,1,12.4600,200,2,14.5600,800,2,12.4299,700,1,14.5999,700,1,12.4199,700,1,14.6300,100,1,12.3699,700,1,14.6799,1400,2,ARL,325718477
1707,2025-07-17T16:02:20.937927380Z,2025-07-17T16:02:20.937927380Z,10,2,1108,C,A,0,14.9600,100,0,165906,271679569,13.2699,10,1,13.8300,15,1,13.0299,100,1,13.8399,100,1,12.9100,2,1,13.9199,2,1,12.7300,100,1,14.2599,100,1,12.7100,100,1,14.2799,100,1,12.5000,700,1,14.4499,100,1,12.4600,200,2,14.5600,800,2,12.4299,700,1,14.5999,700,1,12.4199,700,1,14.6300,100,1,12.3699,700,1,14.6799,1400,2,ARL,325715053
1708,2025-07-17T16:02:20.937927380Z,2025-07-17T16:02:20.937927380Z,10,2,1108,A,A,0,14.8100,100,130,165906,271679569,13.2699,10,1,13.8300,15,1,13.0299,100,1,13.8399,100,1,12.9100,2,1,13.9199,2,1,12.7300,100,1,14.2599,100,1,12.7100,100,1,14.2799,100,1,12.5000,700,1,14.4499,100,1,12.4600,200,2,14.5600,800,2,12.4299,700,1,14.5999,700,1,12.4199,700,1,14.6300,100,1,12.3699,700,1,14.6799,1400,2,ARL,325718517
1709,2025-07-17T16:02:20.938132716Z,2025-07-17T16:02:20.938132716Z,10,2,1108,C,A,0,16.0799,100,0,165123,271679571,13.2699,10,1,13.8300,15,1,13.0299,100,1,13.8399,100,1,12.9100,2,1,13.9199,2,1,12.7300,100,1,14.2599,100,1,12.7100,100,1,14.2799,100,1,12.5000,700,1,14.4499,100,1,12.4600,200,2,14.5600,800,2,12.4299,700,1,14.5999,700,1,12.4199,700,1,14.6300,100,1,12.3699,700,1,14.6799,1400,2,ARL,325714957
1710,2025-07-17T16:02:20.938132716Z,2025-07-17T16:02:20.938132716Z,10,2,1108,A,A,0,15.9199,100,130,165123,271679571,13.2699,10,1,13.8300,15,1,13.0299,100,1,13.8399,100,1,12.9100,2,1,13.9199,2,1,12.7300,100,1,14.2599,100,1,12.7100,100,1,14.2799,100,1,12.5000,700,1,14.4499,100,1,12.4600,200,2,14.5600,800,2,12.4299,700,1,14.5999,700,1,12.4199,700,1,14.6300,100,1,12.3699,700,1,14.6799,1400,2,ARL,325718525
1711,2025-07-17T16:02:20.938451331Z,2025-07-17T16:02:20.938451331Z,10,2,1108,C,A,0,14.9600,100,0,165323,271679575,13.2699,10,1,13.8300,15,1,13.0299,100,1,13.8399,100,1,12.9100,2,1,13.9199,2,1,12.7300,100,1,14.2599,100,1,12.7100,100,1,14.2799,100,1,12.5000,700,1,14.4499,100,1,12.4600,200,2,14.5600,800,2,12.4299,700,1,14.5999,700,1,12.4199,700,1,14.6300,100,1,12.3699,700,1,14.6799,1400,2,ARL,325714953
1712,2025-07-17T16:02:20.938451331Z,2025-07-17T16:02:20.938451331Z,10,2,1108,A,A,0,14.8100,100,130,165323,271679575,13.2699,10,1,13.8300,15,1,13.0299,100,1,13.8399,100,1,12.9100,2,1,13.9199,2,1,12.7300,100,1,14.2599,100,1,12.7100,100,1,14.2799,100,1,12.5000,700,1,14.4499,100,1,12.4600,200,2,14.5600,800,2,12.4299,700,1,14.5999,700,1,12.4199,700,1,14.6300,100,1,12.3699,700,1,14.6799,1400,2,ARL,325718549
1713,2025-07-17T16:02:20.938724516Z,2025-07-17T16:02:20.938724516Z,10,2,1108,C,A,0,17.7600,100,0,165303,271679576,13.2699,10,1,13.8300,15,1,13.0299,100,1,13.8399,100,1,12.9100,2,1,13.9199,2,1,12.7300,100,1,14.2599,100,1,12.7100,100,1,14.2799,100,1,12.5000,700,1,14.4499,100,1,12.4600,200,2,14.5600,800,2,12.4299,700,1,14.5999,700,1,12.4199,700,1,14.6300,100,1,12.3699,700,1,14.6799,1400,2,ARL,325714949
1714,2025-07-17T16:02:20.938724516Z,2025-07-17T16:02:20.938724516Z,10,2,1108,A,A,0,17.5799,100,130,165303,271679576,13.2699,10,1,13.8300,15,1,13.0299,100,1,13.8399,100,1,12.9100,2,1,13.9199,2,1,12.7300,100,1,14.2599,100,1,12.7100,100,1,14.2799,100,1,12.5000,700,1,14.4499,100,1,12.4600,200,2,14.5600,800,2,12.4299,700,1,14.5999,700,1,12.4199,700,1,14.6300,100,1,12.3699,700,1,14.6799,1400,2,ARL,325718557
1715,2025-07-17T16:02:20.939389367Z,2025-07-17T16:02:20.939389367Z,10,2,1108,A,B,0,13.0199,100,130,165319,271679578,13.2699,10,1,13.8300,15,1,13.0299,100,1,13.8399,100,1,13.0199,100,1,13.9199,2,1,12.9100,2,1,14.2599,100,1,12.7300,100,1,14.2799,100,1,12.7100,100,1,14.4499,100,1,12.5000,700,1,14.5600,800,2,12.4600,200,2,14.5999,700,1,12.4299,700,1,14.6300,100,1,12.4199,700,1,14.6799,1400,2,ARL,325718561
1716,2025-07-17T16:02:20.946240970Z,2025-07-17T16:02:20.946240970Z,10,2,1108,C,A,0,14.2599,100,130,165232,271679616,13.2699,10,1,13.8300,15,1,13.0299,100,1,13.8399,100,1,13.0199,100,1,13.9199,2,1,12.9100,2,1,14.2799,100,1,12.7300,100,1,14.4499,100,1,12.7100,100,1,14.5600,800,2,12.5000,700,1,14.5999,700,1,12.4600,200,2,14.6300,100,1,12.4299,700,1,14.6799,1400,2,12.4199,700,1,14.7300,200,2,ARL,325715045
1717,2025-07-17T16:02:20.946291345Z,2025-07-17T16:02:20.946291345Z,10,2,1108,A,A,0,14.1199,100,130,165441,271679617,13.2699,10,1,13.8300,15,1,13.0299,100,1,13.8399,100,1,13.0199,100,1,13.9199,2,1,12.9100,2,1,14.1199,100,1,12.7300,100,1,14.2799,100,1,12.7100,100,1,14.4499,100,1,12.5000,700,1,14.5600,800,2,12.4600,200,2,14.5999,700,1,12.4299,700,1,14.6300,100,1,12.4199,700,1,14.6799,1400,2,ARL,325718637
1718,2025-07-17T16:02:20.956886401Z,2025-07-17T16:02:20.956886401Z,10,2,1108,C,B,0,13.0199,100,0,165212,271679685,13.2699,10,1,13.8300,15,1,13.0299,100,1,13.8399,100,1,12.9100,2,1,13.9199,2,1,12.7300,100,1,14.1199,100,1,12.7100,100,1,14.2799,100,1,12.5000,700,1,14.4499,100,1,12.4600,200,2,14.5600,800,2,12.4299,700,1,14.5999,700,1,12.4199,700,1,14.6300,100,1,12.3699,700,1,14.6799,1400,2,ARL,325718561
1719,2025-07-17T16:02:20.956886401Z,2025-07-17T16:02:20.956886401Z,10,2,1108,A,B,0,13.2599,100,130,165212,271679685,13.2699,10,1,13.8300,15,1,13.2599,100,1,13.8399,100,1,13.0299,100,1,13.9199,2,1,12.9100,2,1,14.1199,100,1,12.7300,100,1,14.2799,100,1,12.7100,100,1,14.4499,100,1,12.5000,700,1,14.5600,800,2,12.4600,200,2,14.5999,700,1,12.4299,700,1,14.6300,100,1,12.4199,700,1,14.6799,1400,2,ARL,325718821
1720,2025-07-17T16:02:20.956923753Z,2025-07-17T16:02:20.956923753Z,10,2,1108,A,B,0,13.1199,100,130,165390,271679686,13.2699,10,1,13.8300,15,1,13.2599,100,1,13.8399,100,1,13.1199,100,1,13.9199,2,1,13.0299,100,1,14.1199,100,1,12.9100,2,1,14.2799,100,1,12.7300,100,1,14.4499,100,1,12.7100,100,1,14.5600,800,2,12.5000,700,1,14.5999,700,1,12.4600,200,2,14.6300,100,1,12.4299,700,1,14.6799,1400,2,ARL,325718833
1721,2025-07-17T16:02:20.956925447Z,2025-07-17T16:02:20.956925447Z,10,2,1108,A,B,0,13.1199,100,130,165037,271679687,13.2699,10,1,13.8300,15,1,13.2599,100,1,13.8399,100,1,13.1199,200,2,13.9199,2,1,13.0299,100,1,14.1199,100,1,12.9100,2,1,14.2799,100,1,12.7300,100,1,14.4499,100,1,12.7100,100,1,14.5600,800,2,12.5000,700,1,14.5999,700,1,12.4600,200,2,14.6300,100,1,12.4299,700,1,14.6799,1400,2,ARL,325718837
1722,2025-07-17T16:02:20.988490644Z,2025-07-17T16:02:20.988490644Z,10,2,1108,A,A,0,13.9800,100,130,165226,271679923,13.2699,10,1,13.8300,15,1,13.2599,100,1,13.8399,100,1,13.1199,200,2,13.9199,2,1,13.0299,100,1,13.9800,100,1,12.9100,2,1,14.1199,100,1,12.7300,100,1,14.2799,100,1,12.7100,100,1,14.4499,100,1,12.5000,700,1,14.5600,800,2,12.4600,200,2,14.5999,700,1,12.4299,700,1,14.6300,100,1,ARL,325719353
1723,2025-07-17T16:02:20.988491826Z,2025-07-17T16:02:20.988491826Z,10,2,1108,A,A,0,13.9800,100,130,165118,271679924,13.2699,10,1,13.8300,15,1,13.2599,100,1,13.8399,100,1,13.1199,200,2,13.9199,2,1,13.0299,100,1,13.9800,200,2,12.9100,2,1,14.1199,100,1,12.7300,100,1,14.2799,100,1,12.7100,100,1,14.4499,100,1,12.5000,700,1,14.5600,800,2,12.4600,200,2,14.5999,700,1,12.4299,700,1,14.6300,100,1,ARL,325719357
1724,2025-07-17T16:02:30.805028316Z,2025-07-17T16:02:30.805028316Z,10,2,1108,C,B,0,13.2699,10,130,165379,271818376,13.2599,100,1,13.8300,15,1,13.1199,200,2,13.8399,100,1,13.0299,100,1,13.9199,2,1,12.9100,2,1,13.9800,200,2,12.7300,100,1,14.1199,100,1,12.7100,100,1,14.2799,100,1,12.5000,700,1,14.4499,100,1,12.4600,200,2,14.5600,800,2,12.4299,700,1,14.5999,700,1,12.4199,700,1,14.6300,100,1,ARL,325714717
1725,2025-07-17T16:02:34.987005787Z,2025-07-17T16:02:34.987005787Z,10,2,1108,C,B,0,12.9100,2,0,165610,271871706,13.2599,100,1,13.8300,15,1,13.1199,200,2,13.8399,100,1,13.0299,100,1,13.9199,2,1,12.7300,100,1,13.9800,200,2,12.7100,100,1,14.1199,100,1,12.5000,700,1,14.2799,100,1,12.4600,200,2,14.4499,100,1,12.4299,700,1,14.5600,800,2,12.4199,700,1,14.5999,700,1,12.3699,700,1,14.6300,100,1,ARL,325714741
1726,2025-07-17T16:02:34.987005787Z,2025-07-17T16:02:34.987005787Z,10,2,1108,A,B,0,13.0000,2,130,165610,271871706,13.2599,100,1,13.8300,15,1,13.1199,200,2,13.8399,100,1,13.0299,100,1,13.9199,2,1,13.0000,2,1,13.9800,200,2,12.7300,100,1,14.1199,100,1,12.7100,100,1,14.2799,100,1,12.5000,700,1,14.4499,100,1,12.4600,200,2,14.5600,800,2,12.4299,700,1,14.5999,700,1,12.4199,700,1,14.6300,100,1,ARL,325967705
1727,2025-07-17T16:02:39.809299504Z,2025-07-17T16:02:39.809299504Z,10,2,1108,A,A,0,13.7899,15,130,165457,271952021,13.2599,100,1,13.7899,15,1,13.1199,200,2,13.8300,15,1,13.0299,100,1,13.8399,100,1,13.0000,2,1,13.9199,2,1,12.7300,100,1,13.9800,200,2,12.7100,100,1,14.1199,100,1,12.5000,700,1,14.2799,100,1,12.4600,200,2,14.4499,100,1,12.4299,700,1,14.5600,800,2,12.4199,700,1,14.5999,700,1,ARL,326077141
1728,2025-07-17T16:02:40.007306432Z,2025-07-17T16:02:40.007306432Z,10,2,1108,C,A,0,13.8399,100,0,165588,271957331,13.2599,100,1,13.7899,15,1,13.1199,200,2,13.8300,15,1,13.0299,100,1,13.9199,2,1,13.0000,2,1,13.9800,200,2,12.7300,100,1,14.1199,100,1,12.7100,100,1,14.2799,100,1,12.5000,700,1,14.4499,100,1,12.4600,200,2,14.5600,800,2,12.4299,700,1,14.5999,700,1,12.4199,700,1,14.6300,100,1,ARL,325718485
1729,2025-07-17T16:02:40.007306432Z,2025-07-17T16:02:40.007306432Z,10,2,1108,A,A,0,13.8000,100,130,165588,271957331,13.2599,100,1,13.7899,15,1,13.1199,200,2,13.8000,100,1,13.0299,100,1,13.8300,15,1,13.0000,2,1,13.9199,2,1,12.7300,100,1,13.9800,200,2,12.7100,100,1,14.1199,100,1,12.5000,700,1,14.2799,100,1,12.4600,200,2,14.4499,100,1,12.4299,700,1,14.5600,800,2,12.4199,700,1,14.5999,700,1,ARL,326082329
1730,2025-07-17T16:02:40.008048023Z,2025-07-17T16:02:40.008048023Z,10,2,1108,C,A,0,14.9100,100,0,165631,271957349,13.2599,100,1,13.7899,15,1,13.1199,200,2,13.8000,100,1,13.0299,100,1,13.8300,15,1,13.0000,2,1,13.9199,2,1,12.7300,100,1,13.9800,200,2,12.7100,100,1,14.1199,100,1,12.5000,700,1,14.2799,100,1,12.4600,200,2,14.4499,100,1,12.4299,700,1,14.5600,800,2,12.4199,700,1,14.5999,700,1,ARL,325718509
1731,2025-07-17T16:02:40.008048023Z,2025-07-17T16:02:40.008048023Z,10,2,1108,A,A,0,14.8699,100,130,165631,271957349,13.2599,100,1,13.7899,15,1,13.1199,200,2,13.8000,100,1,13.0299,100,1,13.8300,15,1,13.0000,2,1,13.9199,2,1,12.7300,100,1,13.9800,200,2,12.7100,100,1,14.1199,100,1,12.5000,700,1,14.2799,100,1,12.4600,200,2,14.4499,100,1,12.4299,700,1,14.5600,800,2,12.4199,700,1,14.5999,700,1,ARL,326082353
1732,2025-07-17T16:02:40.794847674Z,2025-07-17T16:02:40.794847674Z,10,2,1108,C,A,0,13.7899,15,130,166797,271972417,13.2599,100,1,13.8000,100,1,13.1199,200,2,13.8300,15,1,13.0299,100,1,13.9199,2,1,13.0000,2,1,13.9800,200,2,12.7300,100,1,14.1199,100,1,12.7100,100,1,14.2799,100,1,12.5000,700,1,14.4499,100,1,12.4600,200,2,14.5600,800,2,12.4299,700,1,14.5999,700,1,12.4199,700,1,14.6300,100,1,ARL,326077141
1733,2025-07-17T16:02:40.806140621Z,2025-07-17T16:02:40.806140621Z,10,2,1108,C,A,0,13.8300,15,130,165274,271973288,13.2599,100,1,13.8000,100,1,13.1199,200,2,13.9199,2,1,13.0299,100,1,13.9800,200,2,13.0000,2,1,14.1199,100,1,12.7300,100,1,14.2799,100,1,12.7100,100,1,14.4499,100,1,12.5000,700,1,14.5600,800,2,12.4600,200,2,14.5999,700,1,12.4299,700,1,14.6300,100,1,12.4199,700,1,14.6799,1400,2,ARL,325714721
1734,2025-07-17T16:02:43.834262065Z,2025-07-17T16:02:43.834262065Z,10,2,1108,T,N,0,13.2799,100,130,166097,272014629,13.2599,100,1,13.8000,100,1,13.1199,200,2,13.9199,2,1,13.0299,100,1,13.9800,200,2,13.0000,2,1,14.1199,100,1,12.7300,100,1,14.2799,100,1,12.7100,100,1,14.4499,100,1,12.5000,700,1,14.5600,800,2,12.4600,200,2,14.5999,700,1,12.4299,700,1,14.6300,100,1,12.4199,700,1,14.6799,1400,2,ARL,0
1735,2025-07-17T16:02:43.841686908Z,2025-07-17T16:02:43.841686908Z,10,2,1108,C,B,0,13.2599,100,130,165522,272014658,13.1199,200,2,13.8000,100,1,13.0299,100,1,13.9199,2,1,13.0000,2,1,13.9800,200,2,12.7300,100,1,14.1199,100,1,12.7100,100,1,14.2799,100,1,12.5000,700,1,14.4499,100,1,12.4600,200,2,14.5600,800,2,12.4299,700,1,14.5999,700,1,12.4199,700,1,14.6300,100,1,12.3699,700,1,14.6799,1400,2,ARL,325718821
1736,2025-07-17T16:02:43.841746626Z,2025-07-17T16:02:43.841746626Z,10,2,1108,A,A,0,13.9000,4,130,165427,272014659,13.1199,200,2,13.8000,100,1,13.0299,100,1,13.9000,4,1,13.0000,2,1,13.9199,2,1,12.7300,100,1,13.9800,200,2,12.7100,100,1,14.1199,100,1,12.5000,700,1,14.2799,100,1,12.4600,200,2,14.4499,100,1,12.4299,700,1,14.5600,800,2,12.4199,700,1,14.5999,700,1,12.3699,700,1,14.6300,100,1,ARL,326158809
1737,2025-07-17T16:02:43.842130114Z,2025-07-17T16:02:43.842130114Z,10,2,1108,C,A,0,13.8000,100,130,165313,272014661,13.1199,200,2,13.9000,4,1,13.0299,100,1,13.9199,2,1,13.0000,2,1,13.9800,200,2,12.7300,100,1,14.1199,100,1,12.7100,100,1,14.2799,100,1,12.5000,700,1,14.4499,100,1,12.4600,200,2,14.5600,800,2,12.4299,700,1,14.5999,700,1,12.4199,700,1,14.6300,100,1,12.3699,700,1,14.6799,1400,2,ARL,326082329
1738,2025-07-17T16:02:43.842871428Z,2025-07-17T16:02:43.842871428Z,10,2,1108,C,A,0,14.8699,100,0,165508,272014673,13.1199,200,2,13.9000,4,1,13.0299,100,1,13.9199,2,1,13.0000,2,1,13.9800,200,2,12.7300,100,1,14.1199,100,1,12.7100,100,1,14.2799,100,1,12.5000,700,1,14.4499,100,1,12.4600,200,2,14.5600,800,2,12.4299,700,1,14.5999,700,1,12.4199,700,1,14.6300,100,1,12.3699,700,1,14.6799,1400,2,ARL,326082353
1739,2025-07-17T16:02:43.842871428Z,2025-07-17T16:02:43.842871428Z,10,2,1108,A,A,0,14.9199,100,130,165508,272014673,13.1199,200,2,13.9000,4,1,13.0299,100,1,13.9199,2,1,13.0000,2,1,13.9800,200,2,12.7300,100,1,14.1199,100,1,12.7100,100,1,14.2799,100,1,12.5000,700,1,14.4499,100,1,12.4600,200,2,14.5600,800,2,12.4299,700,1,14.5999,700,1,12.4199,700,1,14.6300,100,1,12.3699,700,1,14.6799,1400,2,ARL,326158869
1740,2025-07-17T16:02:43.842941514Z,2025-07-17T16:02:43.842941514Z,10,2,1108,A,B,0,13.1099,100,130,165235,272014674,13.1199,200,2,13.9000,4,1,13.1099,100,1,13.9199,2,1,13.0299,100,1,13.9800,200,2,13.0000,2,1,14.1199,100,1,12.7300,100,1,14.2799,100,1,12.7100,100,1,14.4499,100,1,12.5000,700,1,14.5600,800,2,12.4600,200,2,14.5999,700,1,12.4299,700,1,14.6300,100,1,12.4199,700,1,14.6799,1400,2,ARL,326158877
1741,2025-07-17T16:02:43.842943173Z,2025-07-17T16:02:43.842943173Z,10,2,1108,C,A,0,14.8100,100,0,165853,272014675,13.1199,200,2,13.9000,4,1,13.1099,100,1,13.9199,2,1,13.0299,100,1,13.9800,200,2,13.0000,2,1,14.1199,100,1,12.7300,100,1,14.2799,100,1,12.7100,100,1,14.4499,100,1,12.5000,700,1,14.5600,800,2,12.4600,200,2,14.5999,700,1,12.4299,700,1,14.6300,100,1,12.4199,700,1,14.6799,1400,2,ARL,325718549
1742,2025-07-17T16:02:43.842943173Z,2025-07-17T16:02:43.842943173Z,10,2,1108,A,A,0,14.9600,100,130,165853,272014675,13.1199,200,2,13.9000,4,1,13.1099,100,1,13.9199,2,1,13.0299,100,1,13.9800,200,2,13.0000,2,1,14.1199,100,1,12.7300,100,1,14.2799,100,1,12.7100,100,1,14.4499,100,1,12.5000,700,1,14.5600,800,2,12.4600,200,2,14.5999,700,1,12.4299,700,1,14.6300,100,1,12.4199,700,1,14.6799,1400,2,ARL,326158881
1743,2025-07-17T16:02:43.843039530Z,2025-07-17T16:02:43.843039530Z,10,2,1108,C,A,0,13.9000,4,130,165162,272014681,13.1199,200,2,13.9199,2,1,13.1099,100,1,13.9800,200,2,13.0299,100,1,14.1199,100,1,13.0000,2,1,14.2799,100,1,12.7300,100,1,14.4499,100,1,12.7100,100,1,14.5600,800,2,12.5000,700,1,14.5999,700,1,12.4600,200,2,14.6300,100,1,12.4299,700,1,14.6799,1400,2,12.4199,700,1,14.7300,200,2,ARL,326158809
1744,2025-07-17T16:02:43.843791297Z,2025-07-17T16:02:43.843791297Z,10,2,1108,C,A,0,17.5799,100,0,165523,272014689,13.1199,200,2,13.9199,2,1,13.1099,100,1,13.9800,200,2,13.0299,100,1,14.1199,100,1,13.0000,2,1,14.2799,100,1,12.7300,100,1,14.4499,100,1,12.7100,100,1,14.5600,800,2,12.5000,700,1,14.5999,700,1,12.4600,200,2,14.6300,100,1,12.4299,700,1,14.6799,1400,2,12.4199,700,1,14.7300,200,2,ARL,325718557
1745,2025-07-17T16:02:43.843791297Z,2025-07-17T16:02:43.843791297Z,10,2,1108,A,A,0,17.7600,100,130,165523,272014689,13.1199,200,2,13.9199,2,1,13.1099,100,1,13.9800,200,2,13.0299,100,1,14.1199,100,1,13.0000,2,1,14.2799,100,1,12.7300,100,1,14.4499,100,1,12.7100,100,1,14.5600,800,2,12.5000,700,1,14.5999,700,1,12.4600,200,2,14.6300,100,1,12.4299,700,1,14.6799,1400,2,12.4199,700,1,14.7300,200,2,ARL,326158953
1746,2025-07-17T16:02:43.844487204Z,2025-07-17T16:02:43.844487204Z,10,2,1108,C,A,0,15.9199,100,0,165810,272014697,13.1199,200,2,13.9199,2,1,13.1099,100,1,13.9800,200,2,13.0299,100,1,14.1199,100,1,13.0000,2,1,14.2799,100,1,12.7300,100,1,14.4499,100,1,12.7100,100,1,14.5600,800,2,12.5000,700,1,14.5999,700,1,12.4600,200,2,14.6300,100,1,12.4299,700,1,14.6799,1400,2,12.4199,700,1,14.7300,200,2,ARL,325718525
1747,2025-07-17T16:02:43.844487204Z,2025-07-17T16:02:43.844487204Z,10,2,1108,A,A,0,16.0799,100,130,165810,272014697,13.1199,200,2,13.9199,2,1,13.1099,100,1,13.9800,200,2,13.0299,100,1,14.1199,100,1,13.0000,2,1,14.2799,100,1,12.7300,100,1,14.4499,100,1,12.7100,100,1,14.5600,800,2,12.5000,700,1,14.5999,700,1,12.4600,200,2,14.6300,100,1,12.4299,700,1,14.6799,1400,2,12.4199,700,1,14.7300,200,2,ARL,326158989
1748,2025-07-17T16:02:43.844636465Z,2025-07-17T16:02:43.844636465Z,10,2,1108,C,A,0,14.8100,100,0,165486,272014698,13.1199,200,2,13.9199,2,1,13.1099,100,1,13.9800,200,2,13.0299,100,1,14.1199,100,1,13.0000,2,1,14.2799,100,1,12.7300,100,1,14.4499,100,1,12.7100,100,1,14.5600,800,2,12.5000,700,1,14.5999,700,1,12.4600,200,2,14.6300,100,1,12.4299,700,1,14.6799,1400,2,12.4199,700,1,14.7300,200,2,ARL,325718517
1749,2025-07-17T16:02:43.844636465Z,2025-07-17T16:02:43.844636465Z,10,2,1108,A,A,0,14.9600,100,130,165486,272014698,13.1199,200,2,13.9199,2,1,13.1099,100,1,13.9800,200,2,13.0299,100,1,14.1199,100,1,13.0000,2,1,14.2799,100,1,12.7300,100,1,14.4499,100,1,12.7100,100,1,14.5600,800,2,12.5000,700,1,14.5999,700,1,12.4600,200,2,14.6300,100,1,12.4299,700,1,14.6799,1400,2,12.4199,700,1,14.7300,200,2,ARL,326158997
1750,2025-07-17T16:02:43.846861336Z,2025-07-17T16:02:43.846861336Z,10,2,1108,C,A,0,13.9199,2,0,165459,272014713,13.1199,200,2,13.9800,200,2,13.1099,100,1,14.1199,100,1,13.0299,100,1,14.2799,100,1,13.0000,2,1,14.4499,100,1,12.7300,100,1,14.5600,800,2,12.7100,100,1,14.5999,700,1,12.5000,700,1,14.6300,100,1,12.4600,200,2,14.6799,1400,2,12.4299,700,1,14.7300,200,2,12.4199,700,1,14.9199,100,1,ARL,325297093
1751,2025-07-17T16:02:43.846861336Z,2025-07-17T16:02:43.846861336Z,10,2,1108,A,A,0,14.0299,2,130,165459,272014713,13.1199,200,2,13.9800,200,2,13.1099,100,1,14.0299,2,1,13.0299,100,1,14.1199,100,1,13.0000,2,1,14.2799,100,1,12.7300,100,1,14.4499,100,1,12.7100,100,1,14.5600,800,2,12.5000,700,1,14.5999,700,1,12.4600,200,2,14.6300,100,1,12.4299,700,1,14.6799,1400,2,12.4199,700,1,14.7300,200,2,ARL,326159041
1752,2025-07-17T16:02:43.847666979Z,2025-07-17T16:02:43.847666979Z,10,2,1108,C,A,0,14.7300,100,0,165279,272014721,13.1199,200,2,13.9800,200,2,13.1099,100,1,14.0299,2,1,13.0299,100,1,14.1199,100,1,13.0000,2,1,14.2799,100,1,12.7300,100,1,14.4499,100,1,12.7100,100,1,14.5600,800,2,12.5000,700,1,14.5999,700,1,12.4600,200,2,14.6300,100,1,12.4299,700,1,14.6799,1400,2,12.4199,700,1,14.7300,100,1,ARL,325714613
1753,2025-07-17T16:02:43.847666979Z,2025-07-17T16:02:43.847666979Z,10,2,1108,A,A,0,14.8699,100,130,165279,272014721,13.1199,200,2,13.9800,200,2,13.1099,100,1,14.0299,2,1,13.0299,100,1,14.1199,100,1,13.0000,2,1,14.2799,100,1,12.7300,100,1,14.4499,100,1,12.7100,100,1,14.5600,800,2,12.5000,700,1,14.5999,700,1,12.4600,200,2,14.6300,100,1,12.4299,700,1,14.6799,1400,2,12.4199,700,1,14.7300,100,1,ARL,326159049
1754,2025-07-17T16:02:43.847981726Z,2025-07-17T16:02:43.847981726Z,10,2,1108,C,A,0,14.7300,100,0,165472,272014724,13.1199,200,2,13.9800,200,2,13.1099,100,1,14.0299,2,1,13.0299,100,1,14.1199,100,1,13.0000,2,1,14.2799,100,1,12.7300,100,1,14.4499,100,1,12.7100,100,1,14.5600,800,2,12.5000,700,1,14.5999,700,1,12.4600,200,2,14.6300,100,1,12.4299,700,1,14.6799,1400,2,12.4199,700,1,14.8699,100,1,ARL,325714577
1755,2025-07-17T16:02:43.847981726Z,2025-07-17T16:02:43.847981726Z,10,2,1108,A,A,0,14.8699,100,130,165472,272014724,13.1199,200,2,13.9800,200,2,13.1099,100,1,14.0299,2,1,13.0299,100,1,14.1199,100,1,13.0000,2,1,14.2799,100,1,12.7300,100,1,14.4499,100,1,12.7100,100,1,14.5600,800,2,12.5000,700,1,14.5999,700,1,12.4600,200,2,14.6300,100,1,12.4299,700,1,14.6799,1400,2,12.4199,700,1,14.8699,200,2,ARL,326159061
1756,2025-07-17T16:02:43.860034354Z,2025-07-17T16:02:43.860034354Z,10,2,1108,C,A,0,14.1199,100,130,165293,272014788,13.1199,200,2,13.9800,200,2,13.1099,100,1,14.0299,2,1,13.0299,100,1,14.2799,100,1,13.0000,2,1,14.4499,100,1,12.7300,100,1,14.5600,800,2,12.7100,100,1,14.5999,700,1,12.5000,700,1,14.6300,100,1,12.4600,200,2,14.6799,1400,2,12.4299,700,1,14.8699,200,2,12.4199,700,1,14.9199,100,1,ARL,325718637
1757,2025-07-17T16:02:43.860087215Z,2025-07-17T16:02:43.860087215Z,10,2,1108,A,A,0,14.2599,100,130,165231,272014789,13.1199,200,2,13.9800,200,2,13.1099,100,1,14.0299,2,1,13.0299,100,1,14.2599,100,1,13.0000,2,1,14.2799,100,1,12.7300,100,1,14.4499,100,1,12.7100,100,1,14.5600,800,2,12.5000,700,1,14.5999,700,1,12.4600,200,2,14.6300,100,1,12.4299,700,1,14.6799,1400,2,12.4199,700,1,14.8699,200,2,ARL,326159201
1758,2025-07-17T16:02:43.893011012Z,2025-07-17T16:02:43.893011012Z,10,2,1108,C,A,0,14.9199,100,0,165300,272014986,13.1199,200,2,13.9800,200,2,13.1099,100,1,14.0299,2,1,13.0299,100,1,14.2599,100,1,13.0000,2,1,14.2799,100,1,12.7300,100,1,14.4499,100,1,12.7100,100,1,14.5600,800,2,12.5000,700,1,14.5999,700,1,12.4600,200,2,14.6300,100,1,12.4299,700,1,14.6799,1400,2,12.4199,700,1,14.8699,200,2,ARL,326158869
1759,2025-07-17T16:02:43.893011012Z,2025-07-17T16:02:43.893011012Z,10,2,1108,A,A,0,15.0600,100,130,165300,272014986,13.1199,200,2,13.9800,200,2,13.1099,100,1,14.0299,2,1,13.0299,100,1,14.2599,100,1,13.0000,2,1,14.2799,100,1,12.7300,100,1,14.4499,100,1,12.7100,100,1,14.5600,800,2,12.5000,700,1,14.5999,700,1,12.4600,200,2,14.6300,100,1,12.4299,700,1,14.6799,1400,2,12.4199,700,1,14.8699,200,2,ARL,326159425
1760,2025-07-17T16:02:43.946801538Z,2025-07-17T16:02:43.946801538Z,10,2,1108,C,A,0,14.6300,100,0,165599,272015584,13.1199,200,2,13.9800,200,2,13.1099,100,1,14.0299,2,1,13.0299,100,1,14.2599,100,1,13.0000,2,1,14.2799,100,1,12.7300,100,1,14.4499,100,1,12.7100,100,1,14.5600,800,2,12.5000,700,1,14.5999,700,1,12.4600,200,2,14.6799,1400,2,12.4299,700,1,14.8699,200,2,12.4199,700,1,14.9600,200,2,ARL,325714653
1761,2025-07-17T16:02:43.946801538Z,2025-07-17T16:02:43.946801538Z,10,2,1108,A,A,0,14.7699,100,130,165599,272015584,13.1199,200,2,13.9800,200,2,13.1099,100,1,14.0299,2,1,13.0299,100,1,14.2599,100,1,13.0000,2,1,14.2799,100,1,12.7300,100,1,14.4499,100,1,12.7100,100,1,14.5600,800,2,12.5000,700,1,14.5999,700,1,12.4600,200,2,14.6799,1400,2,12.4299,700,1,14.7699,100,1,12.4199,700,1,14.8699,200,2,ARL,326160141
1762,2025-07-17T16:02:44.664054457Z,2025-07-17T16:02:44.664054457Z,10,2,1108,A,A,0,13.9900,100,130,165327,272021808,13.1199,200,2,13.9800,200,2,13.1099,100,1,13.9900,100,1,13.0299,100,1,14.0299,2,1,13.0000,2,1,14.2599,100,1,12.7300,100,1,14.2799,100,1,12.7100,100,1,14.4499,100,1,12.5000,700,1,14.5600,800,2,12.4600,200,2,14.5999,700,1,12.4299,700,1,14.6799,1400,2,12.4199,700,1,14.7699,100,1,ARL,326167529
1763,2025-07-17T16:03:02.985818199Z,2025-07-17T16:03:02.985818199Z,10,2,1108,C,A,0,14.8699,100,0,169399,272331833,13.1199,200,2,13.9800,200,2,13.1099,100,1,13.9900,100,1,13.0299,100,1,14.0299,2,1,13.0000,2,1,14.2599,100,1,12.7300,100,1,14.2799,100,1,12.7100,100,1,14.4499,100,1,12.5000,700,1,14.5600,800,2,12.4600,200,2,14.5999,700,1,12.4299,700,1,14.6799,1400,2,12.4199,700,1,14.7699,100,1,ARL,326159049
1764,2025-07-17T16:03:02.985818199Z,2025-07-17T16:03:02.985818199Z,10,2,1108,A,A,0,14.6999,100,128,169399,272331833,13.1199,200,2,13.9800,200,2,13.1099,100,1,13.9900,100,1,13.0299,100,1,14.0299,2,1,13.0000,2,1,14.2599,100,1,12.7300,100,1,14.2799,100,1,12.7100,100,1,14.4499,100,1,12.5000,700,1,14.5600,800,2,12.4600,200,2,14.5999,700,1,12.4299,700,1,14.6799,1400,2,12.4199,700,1,14.6999,100,1,ARL,326551237
1765,2025-07-17T16:03:02.987797728Z,2025-07-17T16:03:02.987797728Z,10,2,1108,C,A,0,14.8699,100,0,172001,272332718,13.1199,200,2,13.9800,200,2,13.1099,100,1,13.9900,100,1,13.0299,100,1,14.0299,2,1,13.0000,2,1,14.2599,100,1,12.7300,100,1,14.2799,100,1,12.7100,100,1,14.4499,100,1,12.5000,700,1,14.5600,800,2,12.4600,200,2,14.5999,700,1,12.4299,700,1,14.6799,1400,2,12.4199,700,1,14.6999,100,1,ARL,326159061
1766,2025-07-17T16:03:02.987797728Z,2025-07-17T16:03:02.987797728Z,10,2,1108,A,A,0,14.6999,100,128,172001,272332718,13.1199,200,2,13.9800,200,2,13.1099,100,1,13.9900,100,1,13.0299,100,1,14.0299,2,1,13.0000,2,1,14.2599,100,1,12.7300,100,1,14.2799,100,1,12.7100,100,1,14.4499,100,1,12.5000,700,1,14.5600,800,2,12.4600,200,2,14.5999,700,1,12.4299,700,1,14.6799,1400,2,12.4199,700,1,14.6999,200,2,ARL,326551829
1767,2025-07-17T16:03:10.807281669Z,2025-07-17T16:03:10.807281669Z,10,2,1108,A,A,0,13.7200,15,130,165306,272474575,13.1199,200,2,13.7200,15,1,13.1099,100,1,13.9800,200,2,13.0299,100,1,13.9900,100,1,13.0000,2,1,14.0299,2,1,12.7300,100,1,14.2599,100,1,12.7100,100,1,14.2799,100,1,12.5000,700,1,14.4499,100,1,12.4600,200,2,14.5600,800,2,12.4299,700,1,14.5999,700,1,12.4199,700,1,14.6799,1400,2,ARL,326729677
1768,2025-07-17T16:03:10.807548848Z,2025-07-17T16:03:10.807548848Z,10,2,1108,C,A,0,13.9900,100,0,165573,272474576,13.1199,200,2,13.7200,15,1,13.1099,100,1,13.9800,200,2,13.0299,100,1,14.0299,2,1,13.0000,2,1,14.2599,100,1,12.7300,100,1,14.2799,100,1,12.7100,100,1,14.4499,100,1,12.5000,700,1,14.5600,800,2,12.4600,200,2,14.5999,700,1,12.4299,700,1,14.6799,1400,2,12.4199,700,1,14.6999,200,2,ARL,326167529
1769,2025-07-17T16:03:10.807548848Z,2025-07-17T16:03:10.807548848Z,10,2,1108,A,A,0,13.7300,100,130,165573,272474576,13.1199,200,2,13.7200,15,1,13.1099,100,1,13.7300,100,1,13.0299,100,1,13.9800,200,2,13.0000,2,1,14.0299,2,1,12.7300,100,1,14.2599,100,1,12.7100,100,1,14.2799,100,1,12.5000,700,1,14.4499,100,1,12.4600,200,2,14.5600,800,2,12.4299,700,1,14.5999,700,1,12.4199,700,1,14.6799,1400,2,ARL,326729685
1770,2025-07-17T16:03:10.808290914Z,2025-07-17T16:03:10.808290914Z,10,2,1108,C,A,0,15.0600,100,0,166364,272474580,13.1199,200,2,13.7200,15,1,13.1099,100,1,13.7300,100,1,13.0299,100,1,13.9800,200,2,13.0000,2,1,14.0299,2,1,12.7300,100,1,14.2599,100,1,12.7100,100,1,14.2799,100,1,12.5000,700,1,14.4499,100,1,12.4600,200,2,14.5600,800,2,12.4299,700,1,14.5999,700,1,12.4199,700,1,14.6799,1400,2,ARL,326159425
1771,2025-07-17T16:03:10.808290914Z,2025-07-17T16:03:10.808290914Z,10,2,1108,A,A,0,14.7899,100,128,166364,272474580,13.1199,200,2,13.7200,15,1,13.1099,100,1,13.7300,100,1,13.0299,100,1,13.9800,200,2,13.0000,2,1,14.0299,2,1,12.7300,100,1,14.2599,100,1,12.7100,100,1,14.2799,100,1,12.5000,700,1,14.4499,100,1,12.4600,200,2,14.5600,800,2,12.4299,700,1,14.5999,700,1,12.4199,700,1,14.6799,1400,2,ARL,326729705
1772,2025-07-17T16:03:10.809541651Z,2025-07-17T16:03:10.809541651Z,10,2,1108,C,A,0,14.9600,100,0,165623,272474585,13.1199,200,2,13.7200,15,1,13.1099,100,1,13.7300,100,1,13.0299,100,1,13.9800,200,2,13.0000,2,1,14.0299,2,1,12.7300,100,1,14.2599,100,1,12.7100,100,1,14.2799,100,1,12.5000,700,1,14.4499,100,1,12.4600,200,2,14.5600,800,2,12.4299,700,1,14.5999,700,1,12.4199,700,1,14.6799,1400,2,ARL,326158881
1773,2025-07-17T16:03:10.809541651Z,2025-07-17T16:03:10.809541651Z,10,2,1108,A,A,0,14.6999,100,130,165623,272474585,13.1199,200,2,13.7200,15,1,13.1099,100,1,13.7300,100,1,13.0299,100,1,13.9800,200,2,13.0000,2,1,14.0299,2,1,12.7300,100,1,14.2599,100,1,12.7100,100,1,14.2799,100,1,12.5000,700,1,14.4499,100,1,12.4600,200,2,14.5600,800,2,12.4299,700,1,14.5999,700,1,12.4199,700,1,14.6799,1400,2,ARL,326729721
1774,2025-07-17T16:03:10.809771527Z,2025-07-17T16:03:10.809771527Z,10,2,1108,C,A,0,14.7699,100,130,165294,272474594,13.1199,200,2,13.7200,15,1,13.1099,100,1,13.7300,100,1,13.0299,100,1,13.9800,200,2,13.0000,2,1,14.0299,2,1,12.7300,100,1,14.2599,100,1,12.7100,100,1,14.2799,100,1,12.5000,700,1,14.4499,100,1,12.4600,200,2,14.5600,800,2,12.4299,700,1,14.5999,700,1,12.4199,700,1,14.6799,1400,2,ARL,326160141
1775,2025-07-17T16:03:10.809798084Z,2025-07-17T16:03:10.809798084Z,10,2,1108,C,A,0,17.7600,100,0,165493,272474595,13.1199,200,2,13.7200,15,1,13.1099,100,1,13.7300,100,1,13.0299,100,1,13.9800,200,2,13.0000,2,1,14.0299,2,1,12.7300,100,1,14.2599,100,1,12.7100,100,1,14.2799,100,1,12.5000,700,1,14.4499,100,1,12.4600,200,2,14.5600,800,2,12.4299,700,1,14.5999,700,1,12.4199,700,1,14.6799,1400,2,ARL,326158953
1776,2025-07-17T16:03:10.809798084Z,2025-07-17T16:03:10.809798084Z,10,2,1108,A,A,0,17.4400,100,130,165493,272474595,13.1199,200,2,13.7200,15,1,13.1099,100,1,13.7300,100,1,13.0299,100,1,13.9800,200,2,13.0000,2,1,14.0299,2,1,12.7300,100,1,14.2599,100,1,12.7100,100,1,14.2799,100,1,12.5000,700,1,14.4499,100,1,12.4600,200,2,14.5600,800,2,12.4299,700,1,14.5999,700,1,12.4199,700,1,14.6799,1400,2,ARL,326729725
1777,2025-07-17T16:03:10.809894317Z,2025-07-17T16:03:10.809894317Z,10,2,1108,A,A,0,14.5199,100,130,165125,272474597,13.1199,200,2,13.7200,15,1,13.1099,100,1,13.7300,100,1,13.0299,100,1,13.9800,200,2,13.0000,2,1,14.0299,2,1,12.7300,100,1,14.2599,100,1,12.7100,100,1,14.2799,100,1,12.5000,700,1,14.4499,100,1,12.4600,200,2,14.5199,100,1,12.4299,700,1,14.5600,800,2,12.4199,700,1,14.5999,700,1,ARL,326729729
1778,2025-07-17T16:03:10.810312923Z,2025-07-17T16:03:10.810312923Z,10,2,1108,C,A,0,16.0799,100,0,165601,272474600,13.1199,200,2,13.7200,15,1,13.1099,100,1,13.7300,100,1,13.0299,100,1,13.9800,200,2,13.0000,2,1,14.0299,2,1,12.7300,100,1,14.2599,100,1,12.7100,100,1,14.2799,100,1,12.5000,700,1,14.4499,100,1,12.4600,200,2,14.5199,100,1,12.4299,700,1,14.5600,800,2,12.4199,700,1,14.5999,700,1,ARL,326158989
1779,2025-07-17T16:03:10.810312923Z,2025-07-17T16:03:10.810312923Z,10,2,1108,A,A,0,15.7899,100,130,165601,272474600,13.1199,200,2,13.7200,15,1,13.1099,100,1,13.7300,100,1,13.0299,100,1,13.9800,200,2,13.0000,2,1,14.0299,2,1,12.7300,100,1,14.2599,100,1,12.7100,100,1,14.2799,100,1,12.5000,700,1,14.4499,100,1,12.4600,200,2,14.5199,100,1,12.4299,700,1,14.5600,800,2,12.4199,700,1,14.5999,700,1,ARL,326729733
1780,2025-07-17T16:03:10.814480532Z,2025-07-17T16:03:10.814480532Z,10,2,1108,C,A,0,14.9600,100,0,165738,272474635,13.1199,200,2,13.7200,15,1,13.1099,100,1,13.7300,100,1,13.0299,100,1,13.9800,200,2,13.0000,2,1,14.0299,2,1,12.7300,100,1,14.2599,100,1,12.7100,100,1,14.2799,100,1,12.5000,700,1,14.4499,100,1,12.4600,200,2,14.5199,100,1,12.4299,700,1,14.5600,800,2,12.4199,700,1,14.5999,700,1,ARL,326158997
1781,2025-07-17T16:03:10.814480532Z,2025-07-17T16:03:10.814480532Z,10,2,1108,A,A,0,14.6999,100,130,165738,272474635,13.1199,200,2,13.7200,15,1,13.1099,100,1,13.7300,100,1,13.0299,100,1,13.9800,200,2,13.0000,2,1,14.0299,2,1,12.7300,100,1,14.2599,100,1,12.7100,100,1,14.2799,100,1,12.5000,700,1,14.4499,100,1,12.4600,200,2,14.5199,100,1,12.4299,700,1,14.5600,800,2,12.4199,700,1,14.5999,700,1,ARL,326729821
1782,2025-07-17T16:03:10.817700664Z,2025-07-17T16:03:10.817700664Z,10,2,1108,C,A,0,14.2599,100,130,165402,272474675,13.1199,200,2,13.7200,15,1,13.1099,100,1,13.7300,100,1,13.0299,100,1,13.9800,200,2,13.0000,2,1,14.0299,2,1,12.7300,100,1,14.2799,100,1,12.7100,100,1,14.4499,100,1,12.5000,700,1,14.5199,100,1,12.4600,200,2,14.5600,800,2,12.4299,700,1,14.5999,700,1,12.4199,700,1,14.6799,1400,2,ARL,326159201
1783,2025-07-17T16:03:10.817754737Z,2025-07-17T16:03:10.817754737Z,10,2,1108,A,A,0,14.0000,100,130,165233,272474676,13.1199,200,2,13.7200,15,1,13.1099,100,1,13.7300,100,1,13.0299,100,1,13.9800,200,2,13.0000,2,1,14.0000,100,1,12.7300,100,1,14.0299,2,1,12.7100,100,1,14.2799,100,1,12.5000,700,1,14.4499,100,1,12.4600,200,2,14.5199,100,1,12.4299,700,1,14.5600,800,2,12.4199,700,1,14.5999,700,1,ARL,326729929
1784,2025-07-17T16:03:10.843172549Z,2025-07-17T16:03:10.843172549Z,10,2,1108,A,A,0,15.6600,100,130,165296,272474826,13.1199,200,2,13.7200,15,1,13.1099,100,1,13.7300,100,1,13.0299,100,1,13.9800,200,2,13.0000,2,1,14.0000,100,1,12.7300,100,1,14.0299,2,1,12.7100,100,1,14.2799,100,1,12.5000,700,1,14.4499,100,1,12.4600,200,2,14.5199,100,1,12.4299,700,1,14.5600,800,2,12.4199,700,1,14.5999,700,1,ARL,326730513
1785,2025-07-17T16:03:10.843184785Z,2025-07-17T16:03:10.843184785Z,10,2,1108,C,A,0,15.9399,100,130,165375,272474827,13.1199,200,2,13.7200,15,1,13.1099,100,1,13.7300,100,1,13.0299,100,1,13.9800,200,2,13.0000,2,1,14.0000,100,1,12.7300,100,1,14.0299,2,1,12.7100,100,1,14.2799,100,1,12.5000,700,1,14.4499,100,1,12.4600,200,2,14.5199,100,1,12.4299,700,1,14.5600,800,2,12.4199,700,1,14.5999,700,1,ARL,325714909
1786,2025-07-17T16:03:10.843448998Z,2025-07-17T16:03:10.843448998Z,10,2,1108,C,A,0,13.9800,100,0,166539,272474828,13.1199,200,2,13.7200,15,1,13.1099,100,1,13.7300,100,1,13.0299,100,1,13.9800,100,1,13.0000,2,1,14.0000,100,1,12.7300,100,1,14.0299,2,1,12.7100,100,1,14.2799,100,1,12.5000,700,1,14.4499,100,1,12.4600,200,2,14.5199,100,1,12.4299,700,1,14.5600,800,2,12.4199,700,1,14.5999,700,1,ARL,325719357
1787,2025-07-17T16:03:10.843449402Z,2025-07-17T16:03:10.843449402Z,10,2,1108,C,A,0,13.9800,100,130,166135,272474829,13.1199,200,2,13.7200,15,1,13.1099,100,1,13.7300,100,1,13.0299,100,1,14.0000,100,1,13.0000,2,1,14.0299,2,1,12.7300,100,1,14.2799,100,1,12.7100,100,1,14.4499,100,1,12.5000,700,1,14.5199,100,1,12.4600,200,2,14.5600,800,2,12.4299,700,1,14.5999,700,1,12.4199,700,1,14.6799,1400,2,ARL,325719353
1788,2025-07-17T16:03:10.843462898Z,2025-07-17T16:03:10.843462898Z,10,2,1108,A,A,0,13.8699,100,130,165348,272474830,13.1199,200,2,13.7200,15,1,13.1099,100,1,13.7300,100,1,13.0299,100,1,13.8699,100,1,13.0000,2,1,14.0000,100,1,12.7300,100,1,14.0299,2,1,12.7100,100,1,14.2799,100,1,12.5000,700,1,14.4499,100,1,12.4600,200,2,14.5199,100,1,12.4299,700,1,14.5600,800,2,12.4199,700,1,14.5999,700,1,ARL,326730517
1789,2025-07-17T16:03:10.843464369Z,2025-07-17T16:03:10.843464369Z,10,2,1108,A,A,0,13.8699,100,130,165264,272474831,13.1199,200,2,13.7200,15,1,13.1099,100,1,13.7300,100,1,13.0299,100,1,13.8699,200,2,13.0000,2,1,14.0000,100,1,12.7300,100,1,14.0299,2,1,12.7100,100,1,14.2799,100,1,12.5000,700,1,14.4499,100,1,12.4600,200,2,14.5199,100,1,12.4299,700,1,14.5600,800,2,12.4199,700,1,14.5999,700,1,ARL,326730521
1790,2025-07-17T16:03:16.348023740Z,2025-07-17T16:03:16.348023740Z,10,2,1108,A,A,0,13.6899,15,130,165337,272557172,13.1199,200,2,13.6899,15,1,13.1099,100,1,13.7200,15,1,13.0299,100,1,13.7300,100,1,13.0000,2,1,13.8699,200,2,12.7300,100,1,14.0000,100,1,12.7100,100,1,14.0299,2,1,12.5000,700,1,14.2799,100,1,12.4600,200,2,14.4499,100,1,12.4299,700,1,14.5199,100,1,12.4199,700,1,14.5600,800,2,ARL,326835877
1791,2025-07-17T16:03:16.348302787Z,2025-07-17T16:03:16.348302787Z,10,2,1108,C,A,0,14.6999,100,0,166037,272557230,13.1199,200,2,13.6899,15,1,13.1099,100,1,13.7200,15,1,13.0299,100,1,13.7300,100,1,13.0000,2,1,13.8699,200,2,12.7300,100,1,14.0000,100,1,12.7100,100,1,14.0299,2,1,12.5000,700,1,14.2799,100,1,12.4600,200,2,14.4499,100,1,12.4299,700,1,14.5199,100,1,12.4199,700,1,14.5600,800,2,ARL,326551829
1792,2025-07-17T16:03:16.348302787Z,2025-07-17T16:03:16.348302787Z,10,2,1108,A,A,0,14.5800,100,130,166037,272557230,13.1199,200,2,13.6899,15,1,13.1099,100,1,13.7200,15,1,13.0299,100,1,13.7300,100,1,13.0000,2,1,13.8699,200,2,12.7300,100,1,14.0000,100,1,12.7100,100,1,14.0299,2,1,12.5000,700,1,14.2799,100,1,12.4600,200,2,14.4499,100,1,12.4299,700,1,14.5199,100,1,12.4199,700,1,14.5600,800,2,ARL,326835885
1793,2025-07-17T16:03:16.349513354Z,2025-07-17T16:03:16.349513354Z,10,2,1108,C,A,0,14.6999,100,0,166595,272557430,13.1199,200,2,13.6899,15,1,13.1099,100,1,13.7200,15,1,13.0299,100,1,13.7300,100,1,13.0000,2,1,13.8699,200,2,12.7300,100,1,14.0000,100,1,12.7100,100,1,14.0299,2,1,12.5000,700,1,14.2799,100,1,12.4600,200,2,14.4499,100,1,12.4299,700,1,14.5199,100,1,12.4199,700,1,14.5600,800,2,ARL,326551237
1794,2025-07-17T16:03:16.349513354Z,2025-07-17T16:03:16.349513354Z,10,2,1108,A,A,0,14.5800,100,130,166595,272557430,13.1199,200,2,13.6899,15,1,13.1099,100,1,13.7200,15,1,13.0299,100,1,13.7300,100,1,13.0000,2,1,13.8699,200,2,12.7300,100,1,14.0000,100,1,12.7100,100,1,14.0299,2,1,12.5000,700,1,14.2799,100,1,12.4600,200,2,14.4499,100,1,12.4299,700,1,14.5199,100,1,12.4199,700,1,14.5600,800,2,ARL,326836085
1795,2025-07-17T16:03:16.351845457Z,2025-07-17T16:03:16.351845457Z,10,2,1108,C,A,0,13.7300,100,0,166374,272557789,13.1199,200,2,13.6899,15,1,13.1099,100,1,13.7200,15,1,13.0299,100,1,13.8699,200,2,13.0000,2,1,14.0000,100,1,12.7300,100,1,14.0299,2,1,12.7100,100,1,14.2799,100,1,12.5000,700,1,14.4499,100,1,12.4600,200,2,14.5199,100,1,12.4299,700,1,14.5600,800,2,12.4199,700,1,14.5800,200,2,ARL,326729685
1796,2025-07-17T16:03:16.351845457Z,2025-07-17T16:03:16.351845457Z,10,2,1108,A,A,0,13.6999,100,130,166374,272557789,13.1199,200,2,13.6899,15,1,13.1099,100,1,13.6999,100,1,13.0299,100,1,13.7200,15,1,13.0000,2,1,13.8699,200,2,12.7300,100,1,14.0000,100,1,12.7100,100,1,14.0299,2,1,12.5000,700,1,14.2799,100,1,12.4600,200,2,14.4499,100,1,12.4299,700,1,14.5199,100,1,12.4199,700,1,14.5600,800,2,ARL,326836533
1797,2025-07-17T16:03:16.365819243Z,2025-07-17T16:03:16.365819243Z,10,2,1108,C,A,0,15.3800,100,0,165919,272559024,13.1199,200,2,13.6899,15,1,13.1099,100,1,13.6999,100,1,13.0299,100,1,13.7200,15,1,13.0000,2,1,13.8699,200,2,12.7300,100,1,14.0000,100,1,12.7100,100,1,14.0299,2,1,12.5000,700,1,14.2799,100,1,12.4600,200,2,14.4499,100,1,12.4299,700,1,14.5199,100,1,12.4199,700,1,14.5600,800,2,ARL,325714965
1798,2025-07-17T16:03:16.365819243Z,2025-07-17T16:03:16.365819243Z,10,2,1108,A,A,0,15.0700,100,130,165919,272559024,13.1199,200,2,13.6899,15,1,13.1099,100,1,13.6999,100,1,13.0299,100,1,13.7200,15,1,13.0000,2,1,13.8699,200,2,12.7300,100,1,14.0000,100,1,12.7100,100,1,14.0299,2,1,12.5000,700,1,14.2799,100,1,12.4600,200,2,14.4499,100,1,12.4299,700,1,14.5199,100,1,12.4199,700,1,14.5600,800,2,ARL,326837501
1799,2025-07-17T16:03:18.804159952Z,2025-07-17T16:03:18.804159952Z,10,2,1108,C,A,0,13.6899,15,130,165126,272609485,13.1199,200,2,13.6999,100,1,13.1099,100,1,13.7200,15,1,13.0299,100,1,13.8699,200,2,13.0000,2,1,14.0000,100,1,12.7300,100,1,14.0299,2,1,12.7100,100,1,14.2799,100,1,12.5000,700,1,14.4499,100,1,12.4600,200,2,14.5199,100,1,12.4299,700,1,14.5600,800,2,12.4199,700,1,14.5800,200,2,ARL,326835877
1800,2025-07-17T16:03:18.804202246Z,2025-07-17T16:03:18.804202246Z,10,2,1108,C,A,0,13.6999,100,130,165314,272609486,13.1199,200,2,13.7200,15,1,13.1099,100,1,13.8699,200,2,13.0299,100,1,14.0000,100,1,13.0000,2,1,14.0299,2,1,12.7300,100,1,14.2799,100,1,12.7100,100,1,14.4499,100,1,12.5000,700,1,14.5199,100,1,12.4600,200,2,14.5600,800,2,12.4299,700,1,14.5800,200,2,12.4199,700,1,14.5999,700,1,ARL,326836533
1801,2025-07-17T16:03:18.804933488Z,2025-07-17T16:03:18.804933488Z,10,2,1108,C,A,0,14.7899,100,0,165630,272609510,13.1199,200,2,13.7200,15,1,13.1099,100,1,13.8699,200,2,13.0299,100,1,14.0000,100,1,13.0000,2,1,14.0299,2,1,12.7300,100,1,14.2799,100,1,12.7100,100,1,14.4499,100,1,12.5000,700,1,14.5199,100,1,12.4600,200,2,14.5600,800,2,12.4299,700,1,14.5800,200,2,12.4199,700,1,14.5999,700,1,ARL,326729705
1802,2025-07-17T16:03:18.804933488Z,2025-07-17T16:03:18.804933488Z,10,2,1108,A,A,0,14.9499,100,130,165630,272609510,13.1199,200,2,13.7200,15,1,13.1099,100,1,13.8699,200,2,13.0299,100,1,14.0000,100,1,13.0000,2,1,14.0299,2,1,12.7300,100,1,14.2799,100,1,12.7100,100,1,14.4499,100,1,12.5000,700,1,14.5199,100,1,12.4600,200,2,14.5600,800,2,12.4299,700,1,14.5800,200,2,12.4199,700,1,14.5999,700,1,ARL,326892717
1803,2025-07-17T16:03:18.805126035Z,2025-07-17T16:03:18.805126035Z,10,2,1108,C,A,0,14.6999,100,0,165594,272609526,13.1199,200,2,13.7200,15,1,13.1099,100,1,13.8699,200,2,13.0299,100,1,14.0000,100,1,13.0000,2,1,14.0299,2,1,12.7300,100,1,14.2799,100,1,12.7100,100,1,14.4499,100,1,12.5000,700,1,14.5199,100,1,12.4600,200,2,14.5600,800,2,12.4299,700,1,14.5800,200,2,12.4199,700,1,14.5999,700,1,ARL,326729721
1804,2025-07-17T16:03:18.805126035Z,2025-07-17T16:03:18.805126035Z,10,2,1108,A,A,0,14.8499,100,130,165594,272609526,13.1199,200,2,13.7200,15,1,13.1099,100,1,13.8699,200,2,13.0299,100,1,14.0000,100,1,13.0000,2,1,14.0299,2,1,12.7300,100,1,14.2799,100,1,12.7100,100,1,14.4499,100,1,12.5000,700,1,14.5199,100,1,12.4600,200,2,14.5600,800,2,12.4299,700,1,14.5800,200,2,12.4199,700,1,14.5999,700,1,ARL,326892721
1805,2025-07-17T16:03:18.805283236Z,2025-07-17T16:03:18.805283236Z,10,2,1108,C,A,0,13.7200,15,130,165853,272609541,13.1199,200,2,13.8699,200,2,13.1099,100,1,14.0000,100,1,13.0299,100,1,14.0299,2,1,13.0000,2,1,14.2799,100,1,12.7300,100,1,14.4499,100,1,12.7100,100,1,14.5199,100,1,12.5000,700,1,14.5600,800,2,12.4600,200,2,14.5800,200,2,12.4299,700,1,14.5999,700,1,12.4199,700,1,14.6799,1400,2,ARL,326729677
1806,2025-07-17T16:03:18.806370373Z,2025-07-17T16:03:18.806370373Z,10,2,1108,C,A,0,14.5800,100,0,165530,272609577,13.1199,200,2,13.8699,200,2,13.1099,100,1,14.0000,100,1,13.0299,100,1,14.0299,2,1,13.0000,2,1,14.2799,100,1,12.7300,100,1,14.4499,100,1,12.7100,100,1,14.5199,100,1,12.5000,700,1,14.5600,800,2,12.4600,200,2,14.5800,100,1,12.4299,700,1,14.5999,700,1,12.4199,700,1,14.6799,1400,2,ARL,326835885
1807,2025-07-17T16:03:18.806370373Z,2025-07-17T16:03:18.806370373Z,10,2,1108,A,A,0,14.7599,100,130,165530,272609577,13.1199,200,2,13.8699,200,2,13.1099,100,1,14.0000,100,1,13.0299,100,1,14.0299,2,1,13.0000,2,1,14.2799,100,1,12.7300,100,1,14.4499,100,1,12.7100,100,1,14.5199,100,1,12.5000,700,1,14.5600,800,2,12.4600,200,2,14.5800,100,1,12.4299,700,1,14.5999,700,1,12.4199,700,1,14.6799,1400,2,ARL,326892817
1808,2025-07-17T16:03:18.806637004Z,2025-07-17T16:03:18.806637004Z,10,2,1108,C,A,0,14.5800,100,0,165585,272609583,13.1199,200,2,13.8699,200,2,13.1099,100,1,14.0000,100,1,13.0299,100,1,14.0299,2,1,13.0000,2,1,14.2799,100,1,12.7300,100,1,14.4499,100,1,12.7100,100,1,14.5199,100,1,12.5000,700,1,14.5600,800,2,12.4600,200,2,14.5999,700,1,12.4299,700,1,14.6799,1400,2,12.4199,700,1,14.6999,100,1,ARL,326836085
1809,2025-07-17T16:03:18.806637004Z,2025-07-17T16:03:18.806637004Z,10,2,1108,A,A,0,14.7599,100,130,165585,272609583,13.1199,200,2,13.8699,200,2,13.1099,100,1,14.0000,100,1,13.0299,100,1,14.0299,2,1,13.0000,2,1,14.2799,100,1,12.7300,100,1,14.4499,100,1,12.7100,100,1,14.5199,100,1,12.5000,700,1,14.5600,800,2,12.4600,200,2,14.5999,700,1,12.4299,700,1,14.6799,1400,2,12.4199,700,1,14.6999,100,1,ARL,326892825
1810,2025-07-17T16:03:18.809540733Z,2025-07-17T16:03:18.809540733Z,10,2,1108,C,A,0,14.5199,100,0,165601,272609656,13.1199,200,2,13.8699,200,2,13.1099,100,1,14.0000,100,1,13.0299,100,1,14.0299,2,1,13.0000,2,1,14.2799,100,1,12.7300,100,1,14.4499,100,1,12.7100,100,1,14.5600,800,2,12.5000,700,1,14.5999,700,1,12.4600,200,2,14.6799,1400,2,12.4299,700,1,14.6999,100,1,12.4199,700,1,14.7599,200,2,ARL,326729729
1811,2025-07-17T16:03:18.809540733Z,2025-07-17T16:03:18.809540733Z,10,2,1108,A,A,0,14.6600,100,130,165601,272609656,13.1199,200,2,13.8699,200,2,13.1099,100,1,14.0000,100,1,13.0299,100,1,14.0299,2,1,13.0000,2,1,14.2799,100,1,12.7300,100,1,14.4499,100,1,12.7100,100,1,14.5600,800,2,12.5000,700,1,14.5999,700,1,12.4600,200,2,14.6600,100,1,12.4299,700,1,14.6799,1400,2,12.4199,700,1,14.6999,100,1,ARL,326892885
1812,2025-07-17T16:03:18.809683187Z,2025-07-17T16:03:18.809683187Z,10,2,1108,C,A,0,15.7899,100,0,165478,272609658,13.1199,200,2,13.8699,200,2,13.1099,100,1,14.0000,100,1,13.0299,100,1,14.0299,2,1,13.0000,2,1,14.2799,100,1,12.7300,100,1,14.4499,100,1,12.7100,100,1,14.5600,800,2,12.5000,700,1,14.5999,700,1,12.4600,200,2,14.6600,100,1,12.4299,700,1,14.6799,1400,2,12.4199,700,1,14.6999,100,1,ARL,326729733
1813,2025-07-17T16:03:18.809683187Z,2025-07-17T16:03:18.809683187Z,10,2,1108,A,A,0,15.9600,100,130,165478,272609658,13.1199,200,2,13.8699,200,2,13.1099,100,1,14.0000,100,1,13.0299,100,1,14.0299,2,1,13.0000,2,1,14.2799,100,1,12.7300,100,1,14.4499,100,1,12.7100,100,1,14.5600,800,2,12.5000,700,1,14.5999,700,1,12.4600,200,2,14.6600,100,1,12.4299,700,1,14.6799,1400,2,12.4199,700,1,14.6999,100,1,ARL,326892889
1814,2025-07-17T16:03:18.811941680Z,2025-07-17T16:03:18.811941680Z,10,2,1108,C,A,0,17.4400,100,0,165526,272609679,13.1199,200,2,13.8699,200,2,13.1099,100,1,14.0000,100,1,13.0299,100,1,14.0299,2,1,13.0000,2,1,14.2799,100,1,12.7300,100,1,14.4499,100,1,12.7100,100,1,14.5600,800,2,12.5000,700,1,14.5999,700,1,12.4600,200,2,14.6600,100,1,12.4299,700,1,14.6799,1400,2,12.4199,700,1,14.6999,100,1,ARL,326729725
1815,2025-07-17T16:03:18.811941680Z,2025-07-17T16:03:18.811941680Z,10,2,1108,A,A,0,17.6200,100,130,165526,272609679,13.1199,200,2,13.8699,200,2,13.1099,100,1,14.0000,100,1,13.0299,100,1,14.0299,2,1,13.0000,2,1,14.2799,100,1,12.7300,100,1,14.4499,100,1,12.7100,100,1,14.5600,800,2,12.5000,700,1,14.5999,700,1,12.4600,200,2,14.6600,100,1,12.4299,700,1,14.6799,1400,2,12.4199,700,1,14.6999,100,1,ARL,326892921
1816,2025-07-17T16:03:18.818080239Z,2025-07-17T16:03:18.818080239Z,10,2,1108,C,A,0,14.0000,100,130,165390,272609768,13.1199,200,2,13.8699,200,2,13.1099,100,1,14.0299,2,1,13.0299,100,1,14.2799,100,1,13.0000,2,1,14.4499,100,1,12.7300,100,1,14.5600,800,2,12.7100,100,1,14.5999,700,1,12.5000,700,1,14.6600,100,1,12.4600,200,2,14.6799,1400,2,12.4299,700,1,14.6999,100,1,12.4199,700,1,14.7599,200,2,ARL,326729929
1817,2025-07-17T16:03:18.818135688Z,2025-07-17T16:03:18.818135688Z,10,2,1108,A,A,0,14.1500,100,130,165455,272609769,13.1199,200,2,13.8699,200,2,13.1099,100,1,14.0299,2,1,13.0299,100,1,14.1500,100,1,13.0000,2,1,14.2799,100,1,12.7300,100,1,14.4499,100,1,12.7100,100,1,14.5600,800,2,12.5000,700,1,14.5999,700,1,12.4600,200,2,14.6600,100,1,12.4299,700,1,14.6799,1400,2,12.4199,700,1,14.6999,100,1,ARL,326893213
1818,2025-07-17T16:03:18.868254768Z,2025-07-17T16:03:18.868254768Z,10,2,1108,C,A,0,14.6999,100,0,165735,272610397,13.1199,200,2,13.8699,200,2,13.1099,100,1,14.0299,2,1,13.0299,100,1,14.1500,100,1,13.0000,2,1,14.2799,100,1,12.7300,100,1,14.4499,100,1,12.7100,100,1,14.5600,800,2,12.5000,700,1,14.5999,700,1,12.4600,200,2,14.6600,100,1,12.4299,700,1,14.6799,1400,2,12.4199,700,1,14.7599,200,2,ARL,326729821
1819,2025-07-17T16:03:18.868254768Z,2025-07-17T16:03:18.868254768Z,10,2,1108,A,A,0,14.8499,100,130,165735,272610397,13.1199,200,2,13.8699,200,2,13.1099,100,1,14.0299,2,1,13.0299,100,1,14.1500,100,1,13.0000,2,1,14.2799,100,1,12.7300,100,1,14.4499,100,1,12.7100,100,1,14.5600,800,2,12.5000,700,1,14.5999,700,1,12.4600,200,2,14.6600,100,1,12.4299,700,1,14.6799,1400,2,12.4199,700,1,14.7599,200,2,ARL,326893961
1820,2025-07-17T16:03:19.191054306Z,2025-07-17T16:03:19.191054306Z,10,2,1108,A,A,0,13.8800,100,130,165201,272614303,13.1199,200,2,13.8699,200,2,13.1099,100,1,13.8800,100,1,13.0299,100,1,14.0299,2,1,13.0000,2,1,14.1500,100,1,12.7300,100,1,14.2799,100,1,12.7100,100,1,14.4499,100,1,12.5000,700,1,14.5600,800,2,12.4600,200,2,14.5999,700,1,12.4299,700,1,14.6600,100,1,12.4199,700,1,14.6799,1400,2,ARL,326899125
1821,2025-07-17T16:03:27.433791643Z,2025-07-17T16:03:27.433791643Z,10,2,1108,T,N,0,13.2799,40,130,166289,272788756,13.1199,200,2,13.8699,200,2,13.1099,100,1,13.8800,100,1,13.0299,100,1,14.0299,2,1,13.0000,2,1,14.1500,100,1,12.7300,100,1,14.2799,100,1,12.7100,100,1,14.4499,100,1,12.5000,700,1,14.5600,800,2,12.4600,200,2,14.5999,700,1,12.4299,700,1,14.6600,100,1,12.4199,700,1,14.6799,1400,2,ARL,0
1822,2025-07-17T16:03:27.436158395Z,2025-07-17T16:03:27.436158395Z,10,2,1108,A,A,0,14.2500,53,130,165556,272788767,13.1199,200,2,13.8699,200,2,13.1099,100,1,13.8800,100,1,13.0299,100,1,14.0299,2,1,13.0000,2,1,14.1500,100,1,12.7300,100,1,14.2500,53,1,12.7100,100,1,14.2799,100,1,12.5000,700,1,14.4499,100,1,12.4600,200,2,14.5600,800,2,12.4299,700,1,14.5999,700,1,12.4199,700,1,14.6600,100,1,ARL,327112281
1823,2025-07-17T16:03:27.436715001Z,2025-07-17T16:03:27.436715001Z,10,2,1108,C,B,0,12.2300,100,0,165767,272788774,13.1199,200,2,13.8699,200,2,13.1099,100,1,13.8800,100,1,13.0299,100,1,14.0299,2,1,13.0000,2,1,14.1500,100,1,12.7300,100,1,14.2500,53,1,12.7100,100,1,14.2799,100,1,12.5000,700,1,14.4499,100,1,12.4600,200,2,14.5600,800,2,12.4299,700,1,14.5999,700,1,12.4199,700,1,14.6600,100,1,ARL,291964745
1824,2025-07-17T16:03:27.436715001Z,2025-07-17T16:03:27.436715001Z,10,2,1108,A,B,0,12.0999,100,130,165767,272788774,13.1199,200,2,13.8699,200,2,13.1099,100,1,13.8800,100,1,13.0299,100,1,14.0299,2,1,13.0000,2,1,14.1500,100,1,12.7300,100,1,14.2500,53,1,12.7100,100,1,14.2799,100,1,12.5000,700,1,14.4499,100,1,12.4600,200,2,14.5600,800,2,12.4299,700,1,14.5999,700,1,12.4199,700,1,14.6600,100,1,ARL,327112289
1825,2025-07-17T16:03:27.438400828Z,2025-07-17T16:03:27.438400828Z,10,2,1108,C,B,0,12.3399,100,0,166143,272788792,13.1199,200,2,13.8699,200,2,13.1099,100,1,13.8800,100,1,13.0299,100,1,14.0299,2,1,13.0000,2,1,14.1500,100,1,12.7300,100,1,14.2500,53,1,12.7100,100,1,14.2799,100,1,12.5000,700,1,14.4499,100,1,12.4600,200,2,14.5600,800,2,12.4299,700,1,14.5999,700,1,12.4199,700,1,14.6600,100,1,ARL,285586113
1826,2025-07-17T16:03:27.438400828Z,2025-07-17T16:03:27.438400828Z,10,2,1108,A,B,0,12.1999,100,130,166143,272788792,13.1199,200,2,13.8699,200,2,13.1099,100,1,13.8800,100,1,13.0299,100,1,14.0299,2,1,13.0000,2,1,14.1500,100,1,12.7300,100,1,14.2500,53,1,12.7100,100,1,14.2799,100,1,12.5000,700,1,14.4499,100,1,12.4600,200,2,14.5600,800,2,12.4299,700,1,14.5999,700,1,12.4199,700,1,14.6600,100,1,ARL,327112385
1827,2025-07-17T16:03:27.438437969Z,2025-07-17T16:03:27.438437969Z,10,2,1108,C,B,0,12.3399,100,0,165595,272788793,13.1199,200,2,13.8699,200,2,13.1099,100,1,13.8800,100,1,13.0299,100,1,14.0299,2,1,13.0000,2,1,14.1500,100,1,12.7300,100,1,14.2500,53,1,12.7100,100,1,14.2799,100,1,12.5000,700,1,14.4499,100,1,12.4600,200,2,14.5600,800,2,12.4299,700,1,14.5999,700,1,12.4199,700,1,14.6600,100,1,ARL,285586189
1828,2025-07-17T16:03:27.438437969Z,2025-07-17T16:03:27.438437969Z,10,2,1108,A,B,0,12.1999,100,130,165595,272788793,13.1199,200,2,13.8699,200,2,13.1099,100,1,13.8800,100,1,13.0299,100,1,14.0299,2,1,13.0000,2,1,14.1500,100,1,12.7300,100,1,14.2500,53,1,12.7100,100,1,14.2799,100,1,12.5000,700,1,14.4499,100,1,12.4600,200,2,14.5600,800,2,12.4299,700,1,14.5999,700,1,12.4199,700,1,14.6600,100,1,ARL,327112393
1829,2025-07-17T16:03:27.453845141Z,2025-07-17T16:03:27.453845141Z,10,2,1108,C,B,0,13.0299,100,130,165214,272788897,13.1199,200,2,13.8699,200,2,13.1099,100,1,13.8800,100,1,13.0000,2,1,14.0299,2,1,12.7300,100,1,14.1500,100,1,12.7100,100,1,14.2500,53,1,12.5000,700,1,14.2799,100,1,12.4600,200,2,14.4499,100,1,12.4299,700,1,14.5600,800,2,12.4199,700,1,14.5999,700,1,12.3699,700,1,14.6600,100,1,ARL,285586293
1830,2025-07-17T16:03:27.453894425Z,2025-07-17T16:03:27.453894425Z,10,2,1108,A,B,0,12.9499,100,130,165294,272788898,13.1199,200,2,13.8699,200,2,13.1099,100,1,13.8800,100,1,13.0000,2,1,14.0299,2,1,12.9499,100,1,14.1500,100,1,12.7300,100,1,14.2500,53,1,12.7100,100,1,14.2799,100,1,12.5000,700,1,14.4499,100,1,12.4600,200,2,14.5600,800,2,12.4299,700,1,14.5999,700,1,12.4199,700,1,14.6600,100,1,ARL,327112565
1831,2025-07-17T16:03:27.454726901Z,2025-07-17T16:03:27.454726901Z,10,2,1108,C,B,0,12.9499,100,130,165420,272788942,13.1199,200,2,13.8699,200,2,13.1099,100,1,13.8800,100,1,13.0000,2,1,14.0299,2,1,12.7300,100,1,14.1500,100,1,12.7100,100,1,14.2500,53,1,12.5000,700,1,14.2799,100,1,12.4600,200,2,14.4499,100,1,12.4299,700,1,14.5600,800,2,12.4199,700,1,14.5999,700,1,12.3699,700,1,14.6600,100,1,ARL,327112565
1832,2025-07-17T16:03:27.454773691Z,2025-07-17T16:03:27.454773691Z,10,2,1108,A,B,0,12.8599,100,130,165909,272788943,13.1199,200,2,13.8699,200,2,13.1099,100,1,13.8800,100,1,13.0000,2,1,14.0299,2,1,12.8599,100,1,14.1500,100,1,12.7300,100,1,14.2500,53,1,12.7100,100,1,14.2799,100,1,12.5000,700,1,14.4499,100,1,12.4600,200,2,14.5600,800,2,12.4299,700,1,14.5999,700,1,12.4199,700,1,14.6600,100,1,ARL,327112577
1833,2025-07-17T16:03:27.517585374Z,2025-07-17T16:03:27.517585374Z,10,2,1108,C,B,0,12.4600,100,130,165896,272790695,13.1199,200,2,13.8699,200,2,13.1099,100,1,13.8800,100,1,13.0000,2,1,14.0299,2,1,12.8599,100,1,14.1500,100,1,12.7300,100,1,14.2500,53,1,12.7100,100,1,14.2799,100,1,12.5000,700,1,14.4499,100,1,12.4600,100,1,14.5600,800,2,12.4299,700,1,14.5999,700,1,12.4199,700,1,14.6600,100,1,ARL,285587281
1834,2025-07-17T16:03:27.517699408Z,2025-07-17T16:03:27.517699408Z,10,2,1108,A,B,0,12.3300,100,130,165267,272790696,13.1199,200,2,13.8699,200,2,13.1099,100,1,13.8800,100,1,13.0000,2,1,14.0299,2,1,12.8599,100,1,14.1500,100,1,12.7300,100,1,14.2500,53,1,12.7100,100,1,14.2799,100,1,12.5000,700,1,14.4499,100,1,12.4600,100,1,14.5600,800,2,12.4299,700,1,14.5999,700,1,12.4199,700,1,14.6600,100,1,ARL,327114465
1835,2025-07-17T16:03:27.536178718Z,2025-07-17T16:03:27.536178718Z,10,2,1108,C,A,0,14.2500,53,130,165225,272791410,13.1199,200,2,13.8699,200,2,13.1099,100,1,13.8800,100,1,13.0000,2,1,14.0299,2,1,12.8599,100,1,14.1500,100,1,12.7300,100,1,14.2799,100,1,12.7100,100,1,14.4499,100,1,12.5000,700,1,14.5600,800,2,12.4600,100,1,14.5999,700,1,12.4299,700,1,14.6600,100,1,12.4199,700,1,14.6799,1400,2,ARL,327112281
1836,2025-07-17T16:03:56.548182793Z,2025-07-17T16:03:56.548182793Z,10,2,1108,A,A,0,13.8000,15,130,165254,273208310,13.1199,200,2,13.8000,15,1,13.1099,100,1,13.8699,200,2,13.0000,2,1,13.8800,100,1,12.8599,100,1,14.0299,2,1,12.7300,100,1,14.1500,100,1,12.7100,100,1,14.2799,100,1,12.5000,700,1,14.4499,100,1,12.4600,100,1,14.5600,800,2,12.4299,700,1,14.5999,700,1,12.4199,700,1,14.6600,100,1,ARL,327675057
1837,2025-07-17T16:03:56.548446336Z,2025-07-17T16:03:56.548446336Z,10,2,1108,C,A,0,13.8800,100,0,165380,273208316,13.1199,200,2,13.8000,15,1,13.1099,100,1,13.8699,200,2,13.0000,2,1,14.0299,2,1,12.8599,100,1,14.1500,100,1,12.7300,100,1,14.2799,100,1,12.7100,100,1,14.4499,100,1,12.5000,700,1,14.5600,800,2,12.4600,100,1,14.5999,700,1,12.4299,700,1,14.6600,100,1,12.4199,700,1,14.6799,1400,2,ARL,326899125
1838,2025-07-17T16:03:56.548446336Z,2025-07-17T16:03:56.548446336Z,10,2,1108,A,A,0,13.8100,100,130,165380,273208316,13.1199,200,2,13.8000,15,1,13.1099,100,1,13.8100,100,1,13.0000,2,1,13.8699,200,2,12.8599,100,1,14.0299,2,1,12.7300,100,1,14.1500,100,1,12.7100,100,1,14.2799,100,1,12.5000,700,1,14.4499,100,1,12.4600,100,1,14.5600,800,2,12.4299,700,1,14.5999,700,1,12.4199,700,1,14.6600,100,1,ARL,327675065
1839,2025-07-17T16:03:56.549188993Z,2025-07-17T16:03:56.549188993Z,10,2,1108,C,A,0,14.9499,100,0,165412,273208325,13.1199,200,2,13.8000,15,1,13.1099,100,1,13.8100,100,1,13.0000,2,1,13.8699,200,2,12.8599,100,1,14.0299,2,1,12.7300,100,1,14.1500,100,1,12.7100,100,1,14.2799,100,1,12.5000,700,1,14.4499,100,1,12.4600,100,1,14.5600,800,2,12.4299,700,1,14.5999,700,1,12.4199,700,1,14.6600,100,1,ARL,326892717
1840,2025-07-17T16:03:56.549188993Z,2025-07-17T16:03:56.549188993Z,10,2,1108,A,A,0,14.8800,100,130,165412,273208325,13.1199,200,2,13.8000,15,1,13.1099,100,1,13.8100,100,1,13.0000,2,1,13.8699,200,2,12.8599,100,1,14.0299,2,1,12.7300,100,1,14.1500,100,1,12.7100,100,1,14.2799,100,1,12.5000,700,1,14.4499,100,1,12.4600,100,1,14.5600,800,2,12.4299,700,1,14.5999,700,1,12.4199,700,1,14.6600,100,1,ARL,327675093
1841,2025-07-17T16:04:06.233692491Z,2025-07-17T16:04:06.233692491Z,10,2,1108,C,A,0,14.7599,100,0,166120,273345719,13.1199,200,2,13.8000,15,1,13.1099,100,1,13.8100,100,1,13.0000,2,1,13.8699,200,2,12.8599,100,1,14.0299,2,1,12.7300,100,1,14.1500,100,1,12.7100,100,1,14.2799,100,1,12.5000,700,1,14.4499,100,1,12.4600,100,1,14.5600,800,2,12.4299,700,1,14.5999,700,1,12.4199,700,1,14.6600,100,1,ARL,326892825
1842,2025-07-17T16:04:06.233692491Z,2025-07-17T16:04:06.233692491Z,10,2,1108,A,A,0,14.6400,100,130,166120,273345719,13.1199,200,2,13.8000,15,1,13.1099,100,1,13.8100,100,1,13.0000,2,1,13.8699,200,2,12.8599,100,1,14.0299,2,1,12.7300,100,1,14.1500,100,1,12.7100,100,1,14.2799,100,1,12.5000,700,1,14.4499,100,1,12.4600,100,1,14.5600,800,2,12.4299,700,1,14.5999,700,1,12.4199,700,1,14.6400,100,1,ARL,327856297
1843,2025-07-17T16:04:06.234433294Z,2025-07-17T16:04:06.234433294Z,10,2,1108,C,A,0,14.7599,100,0,166904,273345721,13.1199,200,2,13.8000,15,1,13.1099,100,1,13.8100,100,1,13.0000,2,1,13.8699,200,2,12.8599,100,1,14.0299,2,1,12.7300,100,1,14.1500,100,1,12.7100,100,1,14.2799,100,1,12.5000,700,1,14.4499,100,1,12.4600,100,1,14.5600,800,2,12.4299,700,1,14.5999,700,1,12.4199,700,1,14.6400,100,1,ARL,326892817
1844,2025-07-17T16:04:06.234433294Z,2025-07-17T16:04:06.234433294Z,10,2,1108,A,A,0,14.6400,100,130,166904,273345721,13.1199,200,2,13.8000,15,1,13.1099,100,1,13.8100,100,1,13.0000,2,1,13.8699,200,2,12.8599,100,1,14.0299,2,1,12.7300,100,1,14.1500,100,1,12.7100,100,1,14.2799,100,1,12.5000,700,1,14.4499,100,1,12.4600,100,1,14.5600,800,2,12.4299,700,1,14.5999,700,1,12.4199,700,1,14.6400,200,2,ARL,327856309
1845,2025-07-17T16:04:06.510748731Z,2025-07-17T16:04:06.510748731Z,10,2,1108,A,A,0,13.7200,15,130,165370,273352664,13.1199,200,2,13.7200,15,1,13.1099,100,1,13.8000,15,1,13.0000,2,1,13.8100,100,1,12.8599,100,1,13.8699,200,2,12.7300,100,1,14.0299,2,1,12.7100,100,1,14.1500,100,1,12.5000,700,1,14.2799,100,1,12.4600,100,1,14.4499,100,1,12.4299,700,1,14.5600,800,2,12.4199,700,1,14.5999,700,1,ARL,327863853
1846,2025-07-17T16:04:06.512244746Z,2025-07-17T16:04:06.512244746Z,10,2,1108,C,A,0,13.8100,100,0,168356,273352888,13.1199,200,2,13.7200,15,1,13.1099,100,1,13.8000,15,1,13.0000,2,1,13.8699,200,2,12.8599,100,1,14.0299,2,1,12.7300,100,1,14.1500,100,1,12.7100,100,1,14.2799,100,1,12.5000,700,1,14.4499,100,1,12.4600,100,1,14.5600,800,2,12.4299,700,1,14.5999,700,1,12.4199,700,1,14.6400,200,2,ARL,327675065
1847,2025-07-17T16:04:06.512244746Z,2025-07-17T16:04:06.512244746Z,10,2,1108,A,A,0,13.7300,100,128,168356,273352888,13.1199,200,2,13.7200,15,1,13.1099,100,1,13.7300,100,1,13.0000,2,1,13.8000,15,1,12.8599,100,1,13.8699,200,2,12.7300,100,1,14.0299,2,1,12.7100,100,1,14.1500,100,1,12.5000,700,1,14.2799,100,1,12.4600,100,1,14.4499,100,1,12.4299,700,1,14.5600,800,2,12.4199,700,1,14.5999,700,1,ARL,327864137
1848,2025-07-17T16:04:06.513497276Z,2025-07-17T16:04:06.513497276Z,10,2,1108,C,A,0,14.8800,100,0,178023,273353923,13.1199,200,2,13.7200,15,1,13.1099,100,1,13.7300,100,1,13.0000,2,1,13.8000,15,1,12.8599,100,1,13.8699,200,2,12.7300,100,1,14.0299,2,1,12.7100,100,1,14.1500,100,1,12.5000,700,1,14.2799,100,1,12.4600,100,1,14.4499,100,1,12.4299,700,1,14.5600,800,2,12.4199,700,1,14.5999,700,1,ARL,327675093
1849,2025-07-17T16:04:06.513497276Z,2025-07-17T16:04:06.513497276Z,10,2,1108,A,A,0,14.7899,100,128,178023,273353923,13.1199,200,2,13.7200,15,1,13.1099,100,1,13.7300,100,1,13.0000,2,1,13.8000,15,1,12.8599,100,1,13.8699,200,2,12.7300,100,1,14.0299,2,1,12.7100,100,1,14.1500,100,1,12.5000,700,1,14.2799,100,1,12.4600,100,1,14.4499,100,1,12.4299,700,1,14.5600,800,2,12.4199,700,1,14.5999,700,1,ARL,327864893
1850,2025-07-17T16:04:06.522687474Z,2025-07-17T16:04:06.522687474Z,10,2,1108,C,A,0,14.8499,100,0,165687,273357758,13.1199,200,2,13.7200,15,1,13.1099,100,1,13.7300,100,1,13.0000,2,1,13.8000,15,1,12.8599,100,1,13.8699,200,2,12.7300,100,1,14.0299,2,1,12.7100,100,1,14.1500,100,1,12.5000,700,1,14.2799,100,1,12.4600,100,1,14.4499,100,1,12.4299,700,1,14.5600,800,2,12.4199,700,1,14.5999,700,1,ARL,326892721
1851,2025-07-17T16:04:06.522687474Z,2025-07-17T16:04:06.522687474Z,10,2,1108,A,A,0,14.6999,100,130,165687,273357758,13.1199,200,2,13.7200,15,1,13.1099,100,1,13.7300,100,1,13.0000,2,1,13.8000,15,1,12.8599,100,1,13.8699,200,2,12.7300,100,1,14.0299,2,1,12.7100,100,1,14.1500,100,1,12.5000,700,1,14.2799,100,1,12.4600,100,1,14.4499,100,1,12.4299,700,1,14.5600,800,2,12.4199,700,1,14.5999,700,1,ARL,327868421
1852,2025-07-17T16:04:06.525385108Z,2025-07-17T16:04:06.525385108Z,10,2,1108,C,A,0,14.1500,100,130,165707,273358260,13.1199,200,2,13.7200,15,1,13.1099,100,1,13.7300,100,1,13.0000,2,1,13.8000,15,1,12.8599,100,1,13.8699,200,2,12.7300,100,1,14.0299,2,1,12.7100,100,1,14.2799,100,1,12.5000,700,1,14.4499,100,1,12.4600,100,1,14.5600,800,2,12.4299,700,1,14.5999,700,1,12.4199,700,1,14.6400,200,2,ARL,326893213
1853,2025-07-17T16:04:06.525442486Z,2025-07-17T16:04:06.525442486Z,10,2,1108,A,A,0,14.0000,100,128,166260,273358273,13.1199,200,2,13.7200,15,1,13.1099,100,1,13.7300,100,1,13.0000,2,1,13.8000,15,1,12.8599,100,1,13.8699,200,2,12.7300,100,1,14.0000,100,1,12.7100,100,1,14.0299,2,1,12.5000,700,1,14.2799,100,1,12.4600,100,1,14.4499,100,1,12.4299,700,1,14.5600,800,2,12.4199,700,1,14.5999,700,1,ARL,327869193
1854,2025-07-17T16:04:06.528043934Z,2025-07-17T16:04:06.528043934Z,10,2,1108,C,A,0,14.6600,100,130,166821,273358598,13.1199,200,2,13.7200,15,1,13.1099,100,1,13.7300,100,1,13.0000,2,1,13.8000,15,1,12.8599,100,1,13.8699,200,2,12.7300,100,1,14.0000,100,1,12.7100,100,1,14.0299,2,1,12.5000,700,1,14.2799,100,1,12.4600,100,1,14.4499,100,1,12.4299,700,1,14.5600,800,2,12.4199,700,1,14.5999,700,1,ARL,326892885
1855,2025-07-17T16:04:06.528161631Z,2025-07-17T16:04:06.528161631Z,10,2,1108,A,A,0,14.5199,100,128,167417,273358642,13.1199,200,2,13.7200,15,1,13.1099,100,1,13.7300,100,1,13.0000,2,1,13.8000,15,1,12.8599,100,1,13.8699,200,2,12.7300,100,1,14.0000,100,1,12.7100,100,1,14.0299,2,1,12.5000,700,1,14.2799,100,1,12.4600,100,1,14.4499,100,1,12.4299,700,1,14.5199,100,1,12.4199,700,1,14.5600,800,2,ARL,327869529
1856,2025-07-17T16:04:06.543314706Z,2025-07-17T16:04:06.543314706Z,10,2,1108,C,A,0,17.6200,100,0,165606,273359491,13.1199,200,2,13.7200,15,1,13.1099,100,1,13.7300,100,1,13.0000,2,1,13.8000,15,1,12.8599,100,1,13.8699,200,2,12.7300,100,1,14.0000,100,1,12.7100,100,1,14.0299,2,1,12.5000,700,1,14.2799,100,1,12.4600,100,1,14.4499,100,1,12.4299,700,1,14.5199,100,1,12.4199,700,1,14.5600,800,2,ARL,326892921
1857,2025-07-17T16:04:06.543314706Z,2025-07-17T16:04:06.543314706Z,10,2,1108,A,A,0,17.4400,100,130,165606,273359491,13.1199,200,2,13.7200,15,1,13.1099,100,1,13.7300,100,1,13.0000,2,1,13.8000,15,1,12.8599,100,1,13.8699,200,2,12.7300,100,1,14.0000,100,1,12.7100,100,1,14.0299,2,1,12.5000,700,1,14.2799,100,1,12.4600,100,1,14.4499,100,1,12.4299,700,1,14.5199,100,1,12.4199,700,1,14.5600,800,2,ARL,327870217
1858,2025-07-17T16:04:06.548778200Z,2025-07-17T16:04:06.548778200Z,10,2,1108,C,A,0,15.9600,100,0,167039,273359672,13.1199,200,2,13.7200,15,1,13.1099,100,1,13.7300,100,1,13.0000,2,1,13.8000,15,1,12.8599,100,1,13.8699,200,2,12.7300,100,1,14.0000,100,1,12.7100,100,1,14.0299,2,1,12.5000,700,1,14.2799,100,1,12.4600,100,1,14.4499,100,1,12.4299,700,1,14.5199,100,1,12.4199,700,1,14.5600,800,2,ARL,326892889
1859,2025-07-17T16:04:06.548778200Z,2025-07-17T16:04:06.548778200Z,10,2,1108,A,A,0,15.7899,100,130,167039,273359672,13.1199,200,2,13.7200,15,1,13.1099,100,1,13.7300,100,1,13.0000,2,1,13.8000,15,1,12.8599,100,1,13.8699,200,2,12.7300,100,1,14.0000,100,1,12.7100,100,1,14.0299,2,1,12.5000,700,1,14.2799,100,1,12.4600,100,1,14.4499,100,1,12.4299,700,1,14.5199,100,1,12.4199,700,1,14.5600,800,2,ARL,327870361
1860,2025-07-17T16:04:06.647944313Z,2025-07-17T16:04:06.647944313Z,10,2,1108,C,A,0,14.8499,100,0,165516,273361957,13.1199,200,2,13.7200,15,1,13.1099,100,1,13.7300,100,1,13.0000,2,1,13.8000,15,1,12.8599,100,1,13.8699,200,2,12.7300,100,1,14.0000,100,1,12.7100,100,1,14.0299,2,1,12.5000,700,1,14.2799,100,1,12.4600,100,1,14.4499,100,1,12.4299,700,1,14.5199,100,1,12.4199,700,1,14.5600,800,2,ARL,326893961
1861,2025-07-17T16:04:06.647944313Z,2025-07-17T16:04:06.647944313Z,10,2,1108,A,A,0,14.6999,100,130,165516,273361957,13.1199,200,2,13.7200,15,1,13.1099,100,1,13.7300,100,1,13.0000,2,1,13.8000,15,1,12.8599,100,1,13.8699,200,2,12.7300,100,1,14.0000,100,1,12.7100,100,1,14.0299,2,1,12.5000,700,1,14.2799,100,1,12.4600,100,1,14.4499,100,1,12.4299,700,1,14.5199,100,1,12.4199,700,1,14.5600,800,2,ARL,327873009
1862,2025-07-17T16:04:06.805335354Z,2025-07-17T16:04:06.805335354Z,10,2,1108,C,A,0,13.7200,15,130,165169,273364089,13.1199,200,2,13.7300,100,1,13.1099,100,1,13.8000,15,1,13.0000,2,1,13.8699,200,2,12.8599,100,1,14.0000,100,1,12.7300,100,1,14.0299,2,1,12.7100,100,1,14.2799,100,1,12.5000,700,1,14.4499,100,1,12.4600,100,1,14.5199,100,1,12.4299,700,1,14.5600,800,2,12.4199,700,1,14.5999,700,1,ARL,327863853
1863,2025-07-17T16:04:06.806052396Z,2025-07-17T16:04:06.806052396Z,10,2,1108,C,A,0,13.8000,15,130,165188,273364090,13.1199,200,2,13.7300,100,1,13.1099,100,1,13.8699,200,2,13.0000,2,1,14.0000,100,1,12.8599,100,1,14.0299,2,1,12.7300,100,1,14.2799,100,1,12.7100,100,1,14.4499,100,1,12.5000,700,1,14.5199,100,1,12.4600,100,1,14.5600,800,2,12.4299,700,1,14.5999,700,1,12.4199,700,1,14.6400,200,2,ARL,327675057
1864,2025-07-17T16:04:21.276976977Z,2025-07-17T16:04:21.276976977Z,10,2,1108,A,A,0,13.7699,100,130,165685,273687857,13.1199,200,2,13.7300,100,1,13.1099,100,1,13.7699,100,1,13.0000,2,1,13.8699,200,2,12.8599,100,1,14.0000,100,1,12.7300,100,1,14.0299,2,1,12.7100,100,1,14.2799,100,1,12.5000,700,1,14.4499,100,1,12.4600,100,1,14.5199,100,1,12.4299,700,1,14.5600,800,2,12.4199,700,1,14.5999,700,1,ARL,328239293
1865,2025-07-17T16:04:27.790889618Z,2025-07-17T16:04:27.790889618Z,10,2,1108,C,A,0,14.0299,2,0,165528,273775264,13.1199,200,2,13.7300,100,1,13.1099,100,1,13.7699,100,1,13.0000,2,1,13.8699,200,2,12.8599,100,1,14.0000,100,1,12.7300,100,1,14.2799,100,1,12.7100,100,1,14.4499,100,1,12.5000,700,1,14.5199,100,1,12.4600,100,1,14.5600,800,2,12.4299,700,1,14.5999,700,1,12.4199,700,1,14.6400,200,2,ARL,326159041
1866,2025-07-17T16:04:27.790889618Z,2025-07-17T16:04:27.790889618Z,10,2,1108,A,A,0,13.9399,2,130,165528,273775264,13.1199,200,2,13.7300,100,1,13.1099,100,1,13.7699,100,1,13.0000,2,1,13.8699,200,2,12.8599,100,1,13.9399,2,1,12.7300,100,1,14.0000,100,1,12.7100,100,1,14.2799,100,1,12.5000,700,1,14.4499,100,1,12.4600,100,1,14.5199,100,1,12.4299,700,1,14.5600,800,2,12.4199,700,1,14.5999,700,1,ARL,328351217
1867,2025-07-17T16:04:31.231887784Z,2025-07-17T16:04:31.231887784Z,10,2,1108,A,A,0,13.6799,15,130,165370,273846737,13.1199,200,2,13.6799,15,1,13.1099,100,1,13.7300,100,1,13.0000,2,1,13.7699,100,1,12.8599,100,1,13.8699,200,2,12.7300,100,1,13.9399,2,1,12.7100,100,1,14.0000,100,1,12.5000,700,1,14.2799,100,1,12.4600,100,1,14.4499,100,1,12.4299,700,1,14.5199,100,1,12.4199,700,1,14.5600,800,2,ARL,328437797
1868,2025-07-17T16:04:31.232440773Z,2025-07-17T16:04:31.232440773Z,10,2,1108,A,A,0,13.7200,100,130,165667,273846745,13.1199,200,2,13.6799,15,1,13.1099,100,1,13.7200,100,1,13.0000,2,1,13.7300,100,1,12.8599,100,1,13.7699,100,1,12.7300,100,1,13.8699,200,2,12.7100,100,1,13.9399,2,1,12.5000,700,1,14.0000,100,1,12.4600,100,1,14.2799,100,1,12.4299,700,1,14.4499,100,1,12.4199,700,1,14.5199,100,1,ARL,328437805
1869,2025-07-17T16:04:31.246515467Z,2025-07-17T16:04:31.246515467Z,10,2,1108,C,A,0,13.7699,100,130,165695,273847000,13.1199,200,2,13.6799,15,1,13.1099,100,1,13.7200,100,1,13.0000,2,1,13.7300,100,1,12.8599,100,1,13.8699,200,2,12.7300,100,1,13.9399,2,1,12.7100,100,1,14.0000,100,1,12.5000,700,1,14.2799,100,1,12.4600,100,1,14.4499,100,1,12.4299,700,1,14.5199,100,1,12.4199,700,1,14.5600,800,2,ARL,328239293
1870,2025-07-17T16:04:32.836635838Z,2025-07-17T16:04:32.836635838Z,10,2,1108,C,A,0,13.7300,100,0,166273,273882084,13.1199,200,2,13.6799,15,1,13.1099,100,1,13.7200,100,1,13.0000,2,1,13.8699,200,2,12.8599,100,1,13.9399,2,1,12.7300,100,1,14.0000,100,1,12.7100,100,1,14.2799,100,1,12.5000,700,1,14.4499,100,1,12.4600,100,1,14.5199,100,1,12.4299,700,1,14.5600,800,2,12.4199,700,1,14.5999,700,1,ARL,327864137
1871,2025-07-17T16:04:32.836635838Z,2025-07-17T16:04:32.836635838Z,10,2,1108,A,A,0,13.6899,100,130,166273,273882084,13.1199,200,2,13.6799,15,1,13.1099,100,1,13.6899,100,1,13.0000,2,1,13.7200,100,1,12.8599,100,1,13.8699,200,2,12.7300,100,1,13.9399,2,1,12.7100,100,1,14.0000,100,1,12.5000,700,1,14.2799,100,1,12.4600,100,1,14.4499,100,1,12.4299,700,1,14.5199,100,1,12.4199,700,1,14.5600,800,2,ARL,328489153
1872,2025-07-17T16:04:32.837000154Z,2025-07-17T16:04:32.837000154Z,10,2,1108,C,B,0,13.1199,100,130,165277,273882201,13.1199,100,1,13.6799,15,1,13.1099,100,1,13.6899,100,1,13.0000,2,1,13.7200,100,1,12.8599,100,1,13.8699,200,2,12.7300,100,1,13.9399,2,1,12.7100,100,1,14.0000,100,1,12.5000,700,1,14.2799,100,1,12.4600,100,1,14.4499,100,1,12.4299,700,1,14.5199,100,1,12.4199,700,1,14.5600,800,2,ARL,325718833
1873,2025-07-17T16:04:32.837002825Z,2025-07-17T16:04:32.837002825Z,10,2,1108,C,B,0,13.1199,100,128,166258,273882202,13.1099,100,1,13.6799,15,1,13.0000,2,1,13.6899,100,1,12.8599,100,1,13.7200,100,1,12.7300,100,1,13.8699,200,2,12.7100,100,1,13.9399,2,1,12.5000,700,1,14.0000,100,1,12.4600,100,1,14.2799,100,1,12.4299,700,1,14.4499,100,1,12.4199,700,1,14.5199,100,1,12.3699,700,1,14.5600,800,2,ARL,325718837
1874,2025-07-17T16:04:32.837013456Z,2025-07-17T16:04:32.837013456Z,10,2,1108,A,B,0,12.9800,100,130,166112,273882207,13.1099,100,1,13.6799,15,1,13.0000,2,1,13.6899,100,1,12.9800,100,1,13.7200,100,1,12.8599,100,1,13.8699,200,2,12.7300,100,1,13.9399,2,1,12.7100,100,1,14.0000,100,1,12.5000,700,1,14.2799,100,1,12.4600,100,1,14.4499,100,1,12.4299,700,1,14.5199,100,1,12.4199,700,1,14.5600,800,2,ARL,328489377
1875,2025-07-17T16:04:32.837016087Z,2025-07-17T16:04:32.837016087Z,10,2,1108,A,B,0,12.9800,100,130,165495,273882208,13.1099,100,1,13.6799,15,1,13.0000,2,1,13.6899,100,1,12.9800,200,2,13.7200,100,1,12.8599,100,1,13.8699,200,2,12.7300,100,1,13.9399,2,1,12.7100,100,1,14.0000,100,1,12.5000,700,1,14.2799,100,1,12.4600,100,1,14.4499,100,1,12.4299,700,1,14.5199,100,1,12.4199,700,1,14.5600,800,2,ARL,328489385
1876,2025-07-17T16:04:32.837369811Z,2025-07-17T16:04:32.837369811Z,10,2,1108,C,A,0,14.7899,100,0,166623,273882286,13.1099,100,1,13.6799,15,1,13.0000,2,1,13.6899,100,1,12.9800,200,2,13.7200,100,1,12.8599,100,1,13.8699,200,2,12.7300,100,1,13.9399,2,1,12.7100,100,1,14.0000,100,1,12.5000,700,1,14.2799,100,1,12.4600,100,1,14.4499,100,1,12.4299,700,1,14.5199,100,1,12.4199,700,1,14.5600,800,2,ARL,327864893
1877,2025-07-17T16:04:32.837369811Z,2025-07-17T16:04:32.837369811Z,10,2,1108,A,A,0,14.7500,100,128,166623,273882286,13.1099,100,1,13.6799,15,1,13.0000,2,1,13.6899,100,1,12.9800,200,2,13.7200,100,1,12.8599,100,1,13.8699,200,2,12.7300,100,1,13.9399,2,1,12.7100,100,1,14.0000,100,1,12.5000,700,1,14.2799,100,1,12.4600,100,1,14.4499,100,1,12.4299,700,1,14.5199,100,1,12.4199,700,1,14.5600,800,2,ARL,328489481
1878,2025-07-17T16:04:36.810551890Z,2025-07-17T16:04:36.810551890Z,10,2,1108,A,A,0,13.6500,15,130,165256,273963456,13.1099,100,1,13.6500,15,1,13.0000,2,1,13.6799,15,1,12.9800,200,2,13.6899,100,1,12.8599,100,1,13.7200,100,1,12.7300,100,1,13.8699,200,2,12.7100,100,1,13.9399,2,1,12.5000,700,1,14.0000,100,1,12.4600,100,1,14.2799,100,1,12.4299,700,1,14.4499,100,1,12.4199,700,1,14.5199,100,1,ARL,328603377
1879,2025-07-17T16:04:37.026771973Z,2025-07-17T16:04:37.026771973Z,10,2,1108,A,A,0,13.6899,100,130,165520,273965417,13.1099,100,1,13.6500,15,1,13.0000,2,1,13.6799,15,1,12.9800,200,2,13.6899,200,2,12.8599,100,1,13.7200,100,1,12.7300,100,1,13.8699,200,2,12.7100,100,1,13.9399,2,1,12.5000,700,1,14.0000,100,1,12.4600,100,1,14.2799,100,1,12.4299,700,1,14.4499,100,1,12.4199,700,1,14.5199,100,1,ARL,328606289
1880,2025-07-17T16:04:37.033389265Z,2025-07-17T16:04:37.033389265Z,10,2,1108,C,A,0,13.7200,100,130,165292,273965562,13.1099,100,1,13.6500,15,1,13.0000,2,1,13.6799,15,1,12.9800,200,2,13.6899,200,2,12.8599,100,1,13.8699,200,2,12.7300,100,1,13.9399,2,1,12.7100,100,1,14.0000,100,1,12.5000,700,1,14.2799,100,1,12.4600,100,1,14.4499,100,1,12.4299,700,1,14.5199,100,1,12.4199,700,1,14.5600,800,2,ARL,328437805
1881,2025-07-17T16:04:37.542795711Z,2025-07-17T16:04:37.542795711Z,10,2,1108,C,A,0,13.6899,100,0,165450,273971021,13.1099,100,1,13.6500,15,1,13.0000,2,1,13.6799,15,1,12.9800,200,2,13.6899,100,1,12.8599,100,1,13.8699,200,2,12.7300,100,1,13.9399,2,1,12.7100,100,1,14.0000,100,1,12.5000,700,1,14.2799,100,1,12.4600,100,1,14.4499,100,1,12.4299,700,1,14.5199,100,1,12.4199,700,1,14.5600,800,2,ARL,328489153
1882,2025-07-17T16:04:37.542795711Z,2025-07-17T16:04:37.542795711Z,10,2,1108,A,A,0,13.6600,100,130,165450,273971021,13.1099,100,1,13.6500,15,1,13.0000,2,1,13.6600,100,1,12.9800,200,2,13.6799,15,1,12.8599,100,1,13.6899,100,1,12.7300,100,1,13.8699,200,2,12.7100,100,1,13.9399,2,1,12.5000,700,1,14.0000,100,1,12.4600,100,1,14.2799,100,1,12.4299,700,1,14.4499,100,1,12.4199,700,1,14.5199,100,1,ARL,328614509
1883,2025-07-17T16:04:37.543063240Z,2025-07-17T16:04:37.543063240Z,10,2,1108,C,A,0,13.8699,100,0,167440,273971035,13.1099,100,1,13.6500,15,1,13.0000,2,1,13.6600,100,1,12.9800,200,2,13.6799,15,1,12.8599,100,1,13.6899,100,1,12.7300,100,1,13.8699,100,1,12.7100,100,1,13.9399,2,1,12.5000,700,1,14.0000,100,1,12.4600,100,1,14.2799,100,1,12.4299,700,1,14.4499,100,1,12.4199,700,1,14.5199,100,1,ARL,326730517
1884,2025-07-17T16:04:37.543064690Z,2025-07-17T16:04:37.543064690Z,10,2,1108,C,A,0,13.8699,100,130,165990,273971037,13.1099,100,1,13.6500,15,1,13.0000,2,1,13.6600,100,1,12.9800,200,2,13.6799,15,1,12.8599,100,1,13.6899,100,1,12.7300,100,1,13.9399,2,1,12.7100,100,1,14.0000,100,1,12.5000,700,1,14.2799,100,1,12.4600,100,1,14.4499,100,1,12.4299,700,1,14.5199,100,1,12.4199,700,1,14.5600,800,2,ARL,326730521
1885,2025-07-17T16:04:37.543077174Z,2025-07-17T16:04:37.543077174Z,10,2,1108,A,A,0,13.8000,100,130,165216,273971040,13.1099,100,1,13.6500,15,1,13.0000,2,1,13.6600,100,1,12.9800,200,2,13.6799,15,1,12.8599,100,1,13.6899,100,1,12.7300,100,1,13.8000,100,1,12.7100,100,1,13.9399,2,1,12.5000,700,1,14.0000,100,1,12.4600,100,1,14.2799,100,1,12.4299,700,1,14.4499,100,1,12.4199,700,1,14.5199,100,1,ARL,328614525
1886,2025-07-17T16:04:37.543078532Z,2025-07-17T16:04:37.543078532Z,10,2,1108,A,A,0,13.8000,100,130,165661,273971041,13.1099,100,1,13.6500,15,1,13.0000,2,1,13.6600,100,1,12.9800,200,2,13.6799,15,1,12.8599,100,1,13.6899,100,1,12.7300,100,1,13.8000,200,2,12.7100,100,1,13.9399,2,1,12.5000,700,1,14.0000,100,1,12.4600,100,1,14.2799,100,1,12.4299,700,1,14.4499,100,1,12.4199,700,1,14.5199,100,1,ARL,328614529
1887,2025-07-17T16:04:37.549519006Z,2025-07-17T16:04:37.549519006Z,10,2,1108,C,A,0,14.0000,100,130,165707,273973481,13.1099,100,1,13.6500,15,1,13.0000,2,1,13.6600,100,1,12.9800,200,2,13.6799,15,1,12.8599,100,1,13.6899,100,1,12.7300,100,1,13.8000,200,2,12.7100,100,1,13.9399,2,1,12.5000,700,1,14.2799,100,1,12.4600,100,1,14.4499,100,1,12.4299,700,1,14.5199,100,1,12.4199,700,1,14.5600,800,2,ARL,327869193
1888,2025-07-17T16:04:37.549570649Z,2025-07-17T16:04:37.549570649Z,10,2,1108,A,A,0,13.9299,100,130,165175,273973485,13.1099,100,1,13.6500,15,1,13.0000,2,1,13.6600,100,1,12.9800,200,2,13.6799,15,1,12.8599,100,1,13.6899,100,1,12.7300,100,1,13.8000,200,2,12.7100,100,1,13.9299,100,1,12.5000,700,1,13.9399,2,1,12.4600,100,1,14.2799,100,1,12.4299,700,1,14.4499,100,1,12.4199,700,1,14.5199,100,1,ARL,328616925
1889,2025-07-17T16:04:44.524360626Z,2025-07-17T16:04:44.524360626Z,10,2,1108,C,A,0,13.6799,15,130,165919,274066152,13.1099,100,1,13.6500,15,1,13.0000,2,1,13.6600,100,1,12.9800,200,2,13.6899,100,1,12.8599,100,1,13.8000,200,2,12.7300,100,1,13.9299,100,1,12.7100,100,1,13.9399,2,1,12.5000,700,1,14.2799,100,1,12.4600,100,1,14.4499,100,1,12.4299,700,1,14.5199,100,1,12.4199,700,1,14.5600,800,2,ARL,328437797
1890,2025-07-17T16:04:45.527835033Z,2025-07-17T16:04:45.527835033Z,10,2,1108,A,A,0,13.6300,15,130,165110,274088918,13.1099,100,1,13.6300,15,1,13.0000,2,1,13.6500,15,1,12.9800,200,2,13.6600,100,1,12.8599,100,1,13.6899,100,1,12.7300,100,1,13.8000,200,2,12.7100,100,1,13.9299,100,1,12.5000,700,1,13.9399,2,1,12.4600,100,1,14.2799,100,1,12.4299,700,1,14.4499,100,1,12.4199,700,1,14.5199,100,1,ARL,328780565
1891,2025-07-17T16:04:45.528464092Z,2025-07-17T16:04:45.528464092Z,10,2,1108,C,A,0,14.6400,100,0,165521,274088922,13.1099,100,1,13.6300,15,1,13.0000,2,1,13.6500,15,1,12.9800,200,2,13.6600,100,1,12.8599,100,1,13.6899,100,1,12.7300,100,1,13.8000,200,2,12.7100,100,1,13.9299,100,1,12.5000,700,1,13.9399,2,1,12.4600,100,1,14.2799,100,1,12.4299,700,1,14.4499,100,1,12.4199,700,1,14.5199,100,1,ARL,327856309
1892,2025-07-17T16:04:45.528464092Z,2025-07-17T16:04:45.528464092Z,10,2,1108,A,A,0,14.5199,100,130,165521,274088922,13.1099,100,1,13.6300,15,1,13.0000,2,1,13.6500,15,1,12.9800,200,2,13.6600,100,1,12.8599,100,1,13.6899,100,1,12.7300,100,1,13.8000,200,2,12.7100,100,1,13.9299,100,1,12.5000,700,1,13.9399,2,1,12.4600,100,1,14.2799,100,1,12.4299,700,1,14.4499,100,1,12.4199,700,1,14.5199,200,2,ARL,328780577
1893,2025-07-17T16:04:45.530252804Z,2025-07-17T16:04:45.530252804Z,10,2,1108,C,A,0,14.6400,100,0,165474,274088937,13.1099,100,1,13.6300,15,1,13.0000,2,1,13.6500,15,1,12.9800,200,2,13.6600,100,1,12.8599,100,1,13.6899,100,1,12.7300,100,1,13.8000,200,2,12.7100,100,1,13.9299,100,1,12.5000,700,1,13.9399,2,1,12.4600,100,1,14.2799,100,1,12.4299,700,1,14.4499,100,1,12.4199,700,1,14.5199,200,2,ARL,327856297
1894,2025-07-17T16:04:45.530252804Z,2025-07-17T16:04:45.530252804Z,10,2,1108,A,A,0,14.5199,100,130,165474,274088937,13.1099,100,1,13.6300,15,1,13.0000,2,1,13.6500,15,1,12.9800,200,2,13.6600,100,1,12.8599,100,1,13.6899,100,1,12.7300,100,1,13.8000,200,2,12.7100,100,1,13.9299,100,1,12.5000,700,1,13.9399,2,1,12.4600,100,1,14.2799,100,1,12.4299,700,1,14.4499,100,1,12.4199,700,1,14.5199,300,3,ARL,328780597
1895,2025-07-17T16:04:45.532901874Z,2025-07-17T16:04:45.532901874Z,10,2,1108,C,A,0,13.6600,100,0,165155,274088955,13.1099,100,1,13.6300,15,1,13.0000,2,1,13.6500,15,1,12.9800,200,2,13.6899,100,1,12.8599,100,1,13.8000,200,2,12.7300,100,1,13.9299,100,1,12.7100,100,1,13.9399,2,1,12.5000,700,1,14.2799,100,1,12.4600,100,1,14.4499,100,1,12.4299,700,1,14.5199,300,3,12.4199,700,1,14.5600,800,2,ARL,328614509
1896,2025-07-17T16:04:45.532901874Z,2025-07-17T16:04:45.532901874Z,10,2,1108,A,A,0,13.6400,100,130,165155,274088955,13.1099,100,1,13.6300,15,1,13.0000,2,1,13.6400,100,1,12.9800,200,2,13.6500,15,1,12.8599,100,1,13.6899,100,1,12.7300,100,1,13.8000,200,2,12.7100,100,1,13.9299,100,1,12.5000,700,1,13.9399,2,1,12.4600,100,1,14.2799,100,1,12.4299,700,1,14.4499,100,1,12.4199,700,1,14.5199,300,3,ARL,328780669
1897,2025-07-17T16:04:45.533639142Z,2025-07-17T16:04:45.533639142Z,10,2,1108,C,A,0,14.7500,100,0,165626,274088957,13.1099,100,1,13.6300,15,1,13.0000,2,1,13.6400,100,1,12.9800,200,2,13.6500,15,1,12.8599,100,1,13.6899,100,1,12.7300,100,1,13.8000,200,2,12.7100,100,1,13.9299,100,1,12.5000,700,1,13.9399,2,1,12.4600,100,1,14.2799,100,1,12.4299,700,1,14.4499,100,1,12.4199,700,1,14.5199,300,3,ARL,328489481
1898,2025-07-17T16:04:45.533639142Z,2025-07-17T16:04:45.533639142Z,10,2,1108,A,A,0,14.6999,100,130,165626,274088957,13.1099,100,1,13.6300,15,1,13.0000,2,1,13.6400,100,1,12.9800,200,2,13.6500,15,1,12.8599,100,1,13.6899,100,1,12.7300,100,1,13.8000,200,2,12.7100,100,1,13.9299,100,1,12.5000,700,1,13.9399,2,1,12.4600,100,1,14.2799,100,1,12.4299,700,1,14.4499,100,1,12.4199,700,1,14.5199,300,3,ARL,328780685
1899,2025-07-17T16:04:45.533705428Z,2025-07-17T16:04:45.533705428Z,10,2,1108,A,A,0,13.6699,100,130,165283,274088959,13.1099,100,1,13.6300,15,1,13.0000,2,1,13.6400,100,1,12.9800,200,2,13.6500,15,1,12.8599,100,1,13.6699,100,1,12.7300,100,1,13.6899,100,1,12.7100,100,1,13.8000,200,2,12.5000,700,1,13.9299,100,1,12.4600,100,1,13.9399,2,1,12.4299,700,1,14.2799,100,1,12.4199,700,1,14.4499,100,1,ARL,328780689
1900,2025-07-17T16:04:45.562972204Z,2025-07-17T16:04:45.562972204Z,10,2,1108,C,A,0,13.6899,100,130,165239,274089319,13.1099,100,1,13.6300,15,1,13.0000,2,1,13.6400,100,1,12.9800,200,2,13.6500,15,1,12.8599,100,1,13.6699,100,1,12.7300,100,1,13.8000,200,2,12.7100,100,1,13.9299,100,1,12.5000,700,1,13.9399,2,1,12.4600,100,1,14.2799,100,1,12.4299,700,1,14.4499,100,1,12.4199,700,1,14.5199,300,3,ARL,328606289
1901,2025-07-17T16:04:56.809584701Z,2025-07-17T16:04:56.809584701Z,10,2,1108,C,A,0,13.6500,15,130,165272,274293432,13.1099,100,1,13.6300,15,1,13.0000,2,1,13.6400,100,1,12.9800,200,2,13.6699,100,1,12.8599,100,1,13.8000,200,2,12.7300,100,1,13.9299,100,1,12.7100,100,1,13.9399,2,1,12.5000,700,1,14.2799,100,1,12.4600,100,1,14.4499,100,1,12.4299,700,1,14.5199,300,3,12.4199,700,1,14.5600,800,2,ARL,328603377
1902,2025-07-17T16:04:57.826913717Z,2025-07-17T16:04:57.826913717Z,10,2,1108,A,A,0,13.6099,15,130,165292,274310244,13.1099,100,1,13.6099,15,1,13.0000,2,1,13.6300,15,1,12.9800,200,2,13.6400,100,1,12.8599,100,1,13.6699,100,1,12.7300,100,1,13.8000,200,2,12.7100,100,1,13.9299,100,1,12.5000,700,1,13.9399,2,1,12.4600,100,1,14.2799,100,1,12.4299,700,1,14.4499,100,1,12.4199,700,1,14.5199,300,3,ARL,329068341
1903,2025-07-17T16:04:57.970451236Z,2025-07-17T16:04:57.970451236Z,10,2,1108,C,A,0,13.6400,100,0,165374,274316281,13.1099,100,1,13.6099,15,1,13.0000,2,1,13.6300,15,1,12.9800,200,2,13.6699,100,1,12.8599,100,1,13.8000,200,2,12.7300,100,1,13.9299,100,1,12.7100,100,1,13.9399,2,1,12.5000,700,1,14.2799,100,1,12.4600,100,1,14.4499,100,1,12.4299,700,1,14.5199,300,3,12.4199,700,1,14.5600,800,2,ARL,328780669
1904,2025-07-17T16:04:57.970451236Z,2025-07-17T16:04:57.970451236Z,10,2,1108,A,A,0,13.6199,100,130,165374,274316281,13.1099,100,1,13.6099,15,1,13.0000,2,1,13.6199,100,1,12.9800,200,2,13.6300,15,1,12.8599,100,1,13.6699,100,1,12.7300,100,1,13.8000,200,2,12.7100,100,1,13.9299,100,1,12.5000,700,1,13.9399,2,1,12.4600,100,1,14.2799,100,1,12.4299,700,1,14.4499,100,1,12.4199,700,1,14.5199,300,3,ARL,329074609
1905,2025-07-17T16:04:57.971193734Z,2025-07-17T16:04:57.971193734Z,10,2,1108,C,A,0,14.4499,100,128,166610,274316507,13.1099,100,1,13.6099,15,1,13.0000,2,1,13.6199,100,1,12.9800,200,2,13.6300,15,1,12.8599,100,1,13.6699,100,1,12.7300,100,1,13.8000,200,2,12.7100,100,1,13.9299,100,1,12.5000,700,1,13.9399,2,1,12.4600,100,1,14.2799,100,1,12.4299,700,1,14.5199,300,3,12.4199,700,1,14.5600,800,2,ARL,325714601
1906,2025-07-17T16:04:57.971552262Z,2025-07-17T16:04:57.971552262Z,10,2,1108,A,A,0,14.2300,100,130,165249,274316527,13.1099,100,1,13.6099,15,1,13.0000,2,1,13.6199,100,1,12.9800,200,2,13.6300,15,1,12.8599,100,1,13.6699,100,1,12.7300,100,1,13.8000,200,2,12.7100,100,1,13.9299,100,1,12.5000,700,1,13.9399,2,1,12.4600,100,1,14.2300,100,1,12.4299,700,1,14.2799,100,1,12.4199,700,1,14.5199,300,3,ARL,329074833
1907,2025-07-17T16:04:57.991966904Z,2025-07-17T16:04:57.991966904Z,10,2,1108,C,A,0,13.6099,15,130,164974,274318490,13.1099,100,1,13.6199,100,1,13.0000,2,1,13.6300,15,1,12.9800,200,2,13.6699,100,1,12.8599,100,1,13.8000,200,2,12.7300,100,1,13.9299,100,1,12.7100,100,1,13.9399,2,1,12.5000,700,1,14.2300,100,1,12.4600,100,1,14.2799,100,1,12.4299,700,1,14.5199,300,3,12.4199,700,1,14.5600,800,2,ARL,329068341
1908,2025-07-17T16:04:57.992976406Z,2025-07-17T16:04:57.992976406Z,10,2,1108,C,A,0,13.6199,100,130,165032,274318579,13.1099,100,1,13.6300,15,1,13.0000,2,1,13.6699,100,1,12.9800,200,2,13.8000,200,2,12.8599,100,1,13.9299,100,1,12.7300,100,1,13.9399,2,1,12.7100,100,1,14.2300,100,1,12.5000,700,1,14.2799,100,1,12.4600,100,1,14.5199,300,3,12.4299,700,1,14.5600,800,2,12.4199,700,1,14.5999,700,1,ARL,329074609
1909,2025-07-17T16:04:57.993143873Z,2025-07-17T16:04:57.993143873Z,10,2,1108,C,A,0,13.6300,15,130,165688,274318603,13.1099,100,1,13.6699,100,1,13.0000,2,1,13.8000,200,2,12.9800,200,2,13.9299,100,1,12.8599,100,1,13.9399,2,1,12.7300,100,1,14.2300,100,1,12.7100,100,1,14.2799,100,1,12.5000,700,1,14.5199,300,3,12.4600,100,1,14.5600,800,2,12.4299,700,1,14.5999,700,1,12.4199,700,1,14.6799,1400,2,ARL,328780565
1910,2025-07-17T16:04:58.002094377Z,2025-07-17T16:04:58.002094377Z,10,2,1108,C,A,0,13.6699,100,130,165338,274319058,13.1099,100,1,13.8000,200,2,13.0000,2,1,13.9299,100,1,12.9800,200,2,13.9399,2,1,12.8599,100,1,14.2300,100,1,12.7300,100,1,14.2799,100,1,12.7100,100,1,14.5199,300,3,12.5000,700,1,14.5600,800,2,12.4600,100,1,14.5999,700,1,12.4299,700,1,14.6799,1400,2,12.4199,700,1,14.6999,300,3,ARL,328780689
1911,2025-07-17T16:04:58.002823841Z,2025-07-17T16:04:58.002823841Z,10,2,1108,C,A,0,14.6999,100,0,165589,274319069,13.1099,100,1,13.8000,200,2,13.0000,2,1,13.9299,100,1,12.9800,200,2,13.9399,2,1,12.8599,100,1,14.2300,100,1,12.7300,100,1,14.2799,100,1,12.7100,100,1,14.5199,300,3,12.5000,700,1,14.5600,800,2,12.4600,100,1,14.5999,700,1,12.4299,700,1,14.6799,1400,2,12.4199,700,1,14.6999,200,2,ARL,328780685
1912,2025-07-17T16:04:58.002823841Z,2025-07-17T16:04:58.002823841Z,10,2,1108,A,A,0,14.8699,100,130,165589,274319069,13.1099,100,1,13.8000,200,2,13.0000,2,1,13.9299,100,1,12.9800,200,2,13.9399,2,1,12.8599,100,1,14.2300,100,1,12.7300,100,1,14.2799,100,1,12.7100,100,1,14.5199,300,3,12.5000,700,1,14.5600,800,2,12.4600,100,1,14.5999,700,1,12.4299,700,1,14.6799,1400,2,12.4199,700,1,14.6999,200,2,ARL,329078553
1913,2025-07-17T16:04:58.013739242Z,2025-07-17T16:04:58.013739242Z,10,2,1108,C,A,0,13.9299,100,130,165455,274319298,13.1099,100,1,13.8000,200,2,13.0000,2,1,13.9399,2,1,12.9800,200,2,14.2300,100,1,12.8599,100,1,14.2799,100,1,12.7300,100,1,14.5199,300,3,12.7100,100,1,14.5600,800,2,12.5000,700,1,14.5999,700,1,12.4600,100,1,14.6799,1400,2,12.4299,700,1,14.6999,200,2,12.4199,700,1,14.8699,100,1,ARL,328616925
1914,2025-07-17T16:04:58.013793974Z,2025-07-17T16:04:58.013793974Z,10,2,1108,A,A,0,14.0800,100,130,165259,274319304,13.1099,100,1,13.8000,200,2,13.0000,2,1,13.9399,2,1,12.9800,200,2,14.0800,100,1,12.8599,100,1,14.2300,100,1,12.7300,100,1,14.2799,100,1,12.7100,100,1,14.5199,300,3,12.5000,700,1,14.5600,800,2,12.4600,100,1,14.5999,700,1,12.4299,700,1,14.6799,1400,2,12.4199,700,1,14.6999,200,2,ARL,329078953
1915,2025-07-17T16:04:58.536452621Z,2025-07-17T16:04:58.536452621Z,10,2,1108,A,A,0,13.8100,100,130,165296,274326535,13.1099,100,1,13.8000,200,2,13.0000,2,1,13.8100,100,1,12.9800,200,2,13.9399,2,1,12.8599,100,1,14.0800,100,1,12.7300,100,1,14.2300,100,1,12.7100,100,1,14.2799,100,1,12.5000,700,1,14.5199,300,3,12.4600,100,1,14.5600,800,2,12.4299,700,1,14.5999,700,1,12.4199,700,1,14.6799,1400,2,ARL,329088265
1916,2025-07-17T16:05:46.593966383Z,2025-07-17T16:05:46.593966383Z,10,2,1108,A,A,0,13.7599,100,130,165281,275083968,13.1099,100,1,13.7599,100,1,13.0000,2,1,13.8000,200,2,12.9800,200,2,13.8100,100,1,12.8599,100,1,13.9399,2,1,12.7300,100,1,14.0800,100,1,12.7100,100,1,14.2300,100,1,12.5000,700,1,14.2799,100,1,12.4600,100,1,14.5199,300,3,12.4299,700,1,14.5600,800,2,12.4199,700,1,14.5999,700,1,ARL,330066537
1917,2025-07-17T16:05:46.594705962Z,2025-07-17T16:05:46.594705962Z,10,2,1108,C,A,0,14.8699,100,0,165374,275083970,13.1099,100,1,13.7599,100,1,13.0000,2,1,13.8000,200,2,12.9800,200,2,13.8100,100,1,12.8599,100,1,13.9399,2,1,12.7300,100,1,14.0800,100,1,12.7100,100,1,14.2300,100,1,12.5000,700,1,14.2799,100,1,12.4600,100,1,14.5199,300,3,12.4299,700,1,14.5600,800,2,12.4199,700,1,14.5999,700,1,ARL,329078553
1918,2025-07-17T16:05:46.594705962Z,2025-07-17T16:05:46.594705962Z,10,2,1108,A,A,0,14.8300,100,130,165374,275083970,13.1099,100,1,13.7599,100,1,13.0000,2,1,13.8000,200,2,12.9800,200,2,13.8100,100,1,12.8599,100,1,13.9399,2,1,12.7300,100,1,14.0800,100,1,12.7100,100,1,14.2300,100,1,12.5000,700,1,14.2799,100,1,12.4600,100,1,14.5199,300,3,12.4299,700,1,14.5600,800,2,12.4199,700,1,14.5999,700,1,ARL,330066553
1919,2025-07-17T16:05:46.995837526Z,2025-07-17T16:05:46.995837526Z,10,2,1108,C,A,0,13.8100,100,0,166026,275092978,13.1099,100,1,13.7599,100,1,13.0000,2,1,13.8000,200,2,12.9800,200,2,13.9399,2,1,12.8599,100,1,14.0800,100,1,12.7300,100,1,14.2300,100,1,12.7100,100,1,14.2799,100,1,12.5000,700,1,14.5199,300,3,12.4600,100,1,14.5600,800,2,12.4299,700,1,14.5999,700,1,12.4199,700,1,14.6799,1400,2,ARL,329088265
1920,2025-07-17T16:05:46.995837526Z,2025-07-17T16:05:46.995837526Z,10,2,1108,A,A,0,13.7699,100,130,166026,275092978,13.1099,100,1,13.7599,100,1,13.0000,2,1,13.7699,100,1,12.9800,200,2,13.8000,200,2,12.8599,100,1,13.9399,2,1,12.7300,100,1,14.0800,100,1,12.7100,100,1,14.2300,100,1,12.5000,700,1,14.2799,100,1,12.4600,100,1,14.5199,300,3,12.4299,700,1,14.5600,800,2,12.4199,700,1,14.5999,700,1,ARL,330075425
1921,2025-07-17T16:05:50.680167632Z,2025-07-17T16:05:50.680167632Z,10,2,1108,A,A,0,13.6799,15,130,165519,275152014,13.1099,100,1,13.6799,15,1,13.0000,2,1,13.7599,100,1,12.9800,200,2,13.7699,100,1,12.8599,100,1,13.8000,200,2,12.7300,100,1,13.9399,2,1,12.7100,100,1,14.0800,100,1,12.5000,700,1,14.2300,100,1,12.4600,100,1,14.2799,100,1,12.4299,700,1,14.5199,300,3,12.4199,700,1,14.5600,800,2,ARL,330143813
1922,2025-07-17T16:05:50.697005084Z,2025-07-17T16:05:50.697005084Z,10,2,1108,A,A,0,13.7200,100,130,165236,275152383,13.1099,100,1,13.6799,15,1,13.0000,2,1,13.7200,100,1,12.9800,200,2,13.7599,100,1,12.8599,100,1,13.7699,100,1,12.7300,100,1,13.8000,200,2,12.7100,100,1,13.9399,2,1,12.5000,700,1,14.0800,100,1,12.4600,100,1,14.2300,100,1,12.4299,700,1,14.2799,100,1,12.4199,700,1,14.5199,300,3,ARL,330144301
1923,2025-07-17T16:05:50.697739933Z,2025-07-17T16:05:50.697739933Z,10,2,1108,C,A,0,14.8300,100,0,165439,275152385,13.1099,100,1,13.6799,15,1,13.0000,2,1,13.7200,100,1,12.9800,200,2,13.7599,100,1,12.8599,100,1,13.7699,100,1,12.7300,100,1,13.8000,200,2,12.7100,100,1,13.9399,2,1,12.5000,700,1,14.0800,100,1,12.4600,100,1,14.2300,100,1,12.4299,700,1,14.2799,100,1,12.4199,700,1,14.5199,300,3,ARL,330066553
1924,2025-07-17T16:05:50.697739933Z,2025-07-17T16:05:50.697739933Z,10,2,1108,A,A,0,14.7799,100,130,165439,275152385,13.1099,100,1,13.6799,15,1,13.0000,2,1,13.7200,100,1,12.9800,200,2,13.7599,100,1,12.8599,100,1,13.7699,100,1,12.7300,100,1,13.8000,200,2,12.7100,100,1,13.9399,2,1,12.5000,700,1,14.0800,100,1,12.4600,100,1,14.2300,100,1,12.4299,700,1,14.2799,100,1,12.4199,700,1,14.5199,300,3,ARL,330144321
1925,2025-07-17T16:05:50.704366332Z,2025-07-17T16:05:50.704366332Z,10,2,1108,C,A,0,13.7599,100,130,165416,275152443,13.1099,100,1,13.6799,15,1,13.0000,2,1,13.7200,100,1,12.9800,200,2,13.7699,100,1,12.8599,100,1,13.8000,200,2,12.7300,100,1,13.9399,2,1,12.7100,100,1,14.0800,100,1,12.5000,700,1,14.2300,100,1,12.4600,100,1,14.2799,100,1,12.4299,700,1,14.5199,300,3,12.4199,700,1,14.5600,800,2,ARL,330066537
1926,2025-07-17T16:05:50.708714027Z,2025-07-17T16:05:50.708714027Z,10,2,1108,C,A,0,14.0800,100,130,165284,275152465,13.1099,100,1,13.6799,15,1,13.0000,2,1,13.7200,100,1,12.9800,200,2,13.7699,100,1,12.8599,100,1,13.8000,200,2,12.7300,100,1,13.9399,2,1,12.7100,100,1,14.2300,100,1,12.5000,700,1,14.2799,100,1,12.4600,100,1,14.5199,300,3,12.4299,700,1,14.5600,800,2,12.4199,700,1,14.5999,700,1,ARL,329078953
1927,2025-07-17T16:05:50.708766050Z,2025-07-17T16:05:50.708766050Z,10,2,1108,A,A,0,13.9900,100,130,165139,275152466,13.1099,100,1,13.6799,15,1,13.0000,2,1,13.7200,100,1,12.9800,200,2,13.7699,100,1,12.8599,100,1,13.8000,200,2,12.7300,100,1,13.9399,2,1,12.7100,100,1,13.9900,100,1,12.5000,700,1,14.2300,100,1,12.4600,100,1,14.2799,100,1,12.4299,700,1,14.5199,300,3,12.4199,700,1,14.5600,800,2,ARL,330144513
1928,2025-07-17T16:05:50.913310799Z,2025-07-17T16:05:50.913310799Z,10,2,1108,C,A,0,13.7699,100,0,165469,275159685,13.1099,100,1,13.6799,15,1,13.0000,2,1,13.7200,100,1,12.9800,200,2,13.8000,200,2,12.8599,100,1,13.9399,2,1,12.7300,100,1,13.9900,100,1,12.7100,100,1,14.2300,100,1,12.5000,700,1,14.2799,100,1,12.4600,100,1,14.5199,300,3,12.4299,700,1,14.5600,800,2,12.4199,700,1,14.5999,700,1,ARL,330075425
1929,2025-07-17T16:05:50.913310799Z,2025-07-17T16:05:50.913310799Z,10,2,1108,A,A,0,13.6899,100,130,165469,275159685,13.1099,100,1,13.6799,15,1,13.0000,2,1,13.6899,100,1,12.9800,200,2,13.7200,100,1,12.8599,100,1,13.8000,200,2,12.7300,100,1,13.9399,2,1,12.7100,100,1,13.9900,100,1,12.5000,700,1,14.2300,100,1,12.4600,100,1,14.2799,100,1,12.4299,700,1,14.5199,300,3,12.4199,700,1,14.5600,800,2,ARL,330151389
1930,2025-07-17T16:05:59.704790753Z,2025-07-17T16:05:59.704790753Z,10,2,1108,A,A,0,13.6400,15,130,165217,275325555,13.1099,100,1,13.6400,15,1,13.0000,2,1,13.6799,15,1,12.9800,200,2,13.6899,100,1,12.8599,100,1,13.7200,100,1,12.7300,100,1,13.8000,200,2,12.7100,100,1,13.9399,2,1,12.5000,700,1,13.9900,100,1,12.4600,100,1,14.2300,100,1,12.4299,700,1,14.2799,100,1,12.4199,700,1,14.5199,300,3,ARL,330357473
1931,2025-07-17T16:05:59.714925412Z,2025-07-17T16:05:59.714925412Z,10,2,1108,A,A,0,13.6799,100,130,165250,275325807,13.1099,100,1,13.6400,15,1,13.0000,2,1,13.6799,115,2,12.9800,200,2,13.6899,100,1,12.8599,100,1,13.7200,100,1,12.7300,100,1,13.8000,200,2,12.7100,100,1,13.9399,2,1,12.5000,700,1,13.9900,100,1,12.4600,100,1,14.2300,100,1,12.4299,700,1,14.2799,100,1,12.4199,700,1,14.5199,300,3,ARL,330357633
1932,2025-07-17T16:05:59.722730507Z,2025-07-17T16:05:59.722730507Z,10,2,1108,C,A,0,13.7200,100,130,165243,275325854,13.1099,100,1,13.6400,15,1,13.0000,2,1,13.6799,115,2,12.9800,200,2,13.6899,100,1,12.8599,100,1,13.8000,200,2,12.7300,100,1,13.9399,2,1,12.7100,100,1,13.9900,100,1,12.5000,700,1,14.2300,100,1,12.4600,100,1,14.2799,100,1,12.4299,700,1,14.5199,300,3,12.4199,700,1,14.5600,800,2,ARL,330144301
1933,2025-07-17T16:05:59.802596747Z,2025-07-17T16:05:59.802596747Z,10,2,1108,C,A,0,13.6899,100,0,165340,275327082,13.1099,100,1,13.6400,15,1,13.0000,2,1,13.6799,115,2,12.9800,200,2,13.8000,200,2,12.8599,100,1,13.9399,2,1,12.7300,100,1,13.9900,100,1,12.7100,100,1,14.2300,100,1,12.5000,700,1,14.2799,100,1,12.4600,100,1,14.5199,300,3,12.4299,700,1,14.5600,800,2,12.4199,700,1,14.5999,700,1,ARL,330151389
1934,2025-07-17T16:05:59.802596747Z,2025-07-17T16:05:59.802596747Z,10,2,1108,A,A,0,13.6500,100,130,165340,275327082,13.1099,100,1,13.6400,15,1,13.0000,2,1,13.6500,100,1,12.9800,200,2,13.6799,115,2,12.8599,100,1,13.8000,200,2,12.7300,100,1,13.9399,2,1,12.7100,100,1,13.9900,100,1,12.5000,700,1,14.2300,100,1,12.4600,100,1,14.2799,100,1,12.4299,700,1,14.5199,300,3,12.4199,700,1,14.5600,800,2,ARL,330359197
1935,2025-07-17T16:05:59.803338996Z,2025-07-17T16:05:59.803338996Z,10,2,1108,C,A,0,14.7799,100,0,165662,275327093,13.1099,100,1,13.6400,15,1,13.0000,2,1,13.6500,100,1,12.9800,200,2,13.6799,115,2,12.8599,100,1,13.8000,200,2,12.7300,100,1,13.9399,2,1,12.7100,100,1,13.9900,100,1,12.5000,700,1,14.2300,100,1,12.4600,100,1,14.2799,100,1,12.4299,700,1,14.5199,300,3,12.4199,700,1,14.5600,800,2,ARL,330144321
1936,2025-07-17T16:05:59.803338996Z,2025-07-17T16:05:59.803338996Z,10,2,1108,A,A,0,14.7100,100,130,165662,275327093,13.1099,100,1,13.6400,15,1,13.0000,2,1,13.6500,100,1,12.9800,200,2,13.6799,115,2,12.8599,100,1,13.8000,200,2,12.7300,100,1,13.9399,2,1,12.7100,100,1,13.9900,100,1,12.5000,700,1,14.2300,100,1,12.4600,100,1,14.2799,100,1,12.4299,700,1,14.5199,300,3,12.4199,700,1,14.5600,800,2,ARL,330359225
1937,2025-07-17T16:05:59.827622529Z,2025-07-17T16:05:59.827622529Z,10,2,1108,C,A,0,13.9900,100,130,165308,275327416,13.1099,100,1,13.6400,15,1,13.0000,2,1,13.6500,100,1,12.9800,200,2,13.6799,115,2,12.8599,100,1,13.8000,200,2,12.7300,100,1,13.9399,2,1,12.7100,100,1,14.2300,100,1,12.5000,700,1,14.2799,100,1,12.4600,100,1,14.5199,300,3,12.4299,700,1,14.5600,800,2,12.4199,700,1,14.5999,700,1,ARL,330144513
1938,2025-07-17T16:05:59.827674437Z,2025-07-17T16:05:59.827674437Z,10,2,1108,A,A,0,13.9199,100,130,165365,275327417,13.1099,100,1,13.6400,15,1,13.0000,2,1,13.6500,100,1,12.9800,200,2,13.6799,115,2,12.8599,100,1,13.8000,200,2,12.7300,100,1,13.9199,100,1,12.7100,100,1,13.9399,2,1,12.5000,700,1,14.2300,100,1,12.4600,100,1,14.2799,100,1,12.4299,700,1,14.5199,300,3,12.4199,700,1,14.5600,800,2,ARL,330359625
1939,2025-07-17T16:06:02.724280161Z,2025-07-17T16:06:02.724280161Z,10,2,1108,C,A,0,13.6799,15,128,166176,275430576,13.1099,100,1,13.6400,15,1,13.0000,2,1,13.6500,100,1,12.9800,200,2,13.6799,100,1,12.8599,100,1,13.8000,200,2,12.7300,100,1,13.9199,100,1,12.7100,100,1,13.9399,2,1,12.5000,700,1,14.2300,100,1,12.4600,100,1,14.2799,100,1,12.4299,700,1,14.5199,300,3,12.4199,700,1,14.5600,800,2,ARL,330143813
1940,2025-07-17T16:06:03.729212428Z,2025-07-17T16:06:03.729212428Z,10,2,1108,A,A,0,13.6199,15,130,165342,275517342,13.1099,100,1,13.6199,15,1,13.0000,2,1,13.6400,15,1,12.9800,200,2,13.6500,100,1,12.8599,100,1,13.6799,100,1,12.7300,100,1,13.8000,200,2,12.7100,100,1,13.9199,100,1,12.5000,700,1,13.9399,2,1,12.4600,100,1,14.2300,100,1,12.4299,700,1,14.2799,100,1,12.4199,700,1,14.5199,300,3,ARL,330577045
1941,2025-07-17T16:06:03.738332427Z,2025-07-17T16:06:03.738332427Z,10,2,1108,A,A,0,13.6500,100,130,165218,275517997,13.1099,100,1,13.6199,15,1,13.0000,2,1,13.6400,15,1,12.9800,200,2,13.6500,200,2,12.8599,100,1,13.6799,100,1,12.7300,100,1,13.8000,200,2,12.7100,100,1,13.9199,100,1,12.5000,700,1,13.9399,2,1,12.4600,100,1,14.2300,100,1,12.4299,700,1,14.2799,100,1,12.4199,700,1,14.5199,300,3,ARL,330577773
1942,2025-07-17T16:06:03.747330178Z,2025-07-17T16:06:03.747330178Z,10,2,1108,C,A,0,13.6799,100,130,165491,275518621,13.1099,100,1,13.6199,15,1,13.0000,2,1,13.6400,15,1,12.9800,200,2,13.6500,200,2,12.8599,100,1,13.8000,200,2,12.7300,100,1,13.9199,100,1,12.7100,100,1,13.9399,2,1,12.5000,700,1,14.2300,100,1,12.4600,100,1,14.2799,100,1,12.4299,700,1,14.5199,300,3,12.4199,700,1,14.5600,800,2,ARL,330357633
1943,2025-07-17T16:06:03.887107153Z,2025-07-17T16:06:03.887107153Z,10,2,1108,C,A,0,13.6500,100,0,167517,275532429,13.1099,100,1,13.6199,15,1,13.0000,2,1,13.6400,15,1,12.9800,200,2,13.6500,100,1,12.8599,100,1,13.8000,200,2,12.7300,100,1,13.9199,100,1,12.7100,100,1,13.9399,2,1,12.5000,700,1,14.2300,100,1,12.4600,100,1,14.2799,100,1,12.4299,700,1,14.5199,300,3,12.4199,700,1,14.5600,800,2,ARL,330359197
1944,2025-07-17T16:06:03.887107153Z,2025-07-17T16:06:03.887107153Z,10,2,1108,A,A,0,13.6300,100,130,167517,275532429,13.1099,100,1,13.6199,15,1,13.0000,2,1,13.6300,100,1,12.9800,200,2,13.6400,15,1,12.8599,100,1,13.6500,100,1,12.7300,100,1,13.8000,200,2,12.7100,100,1,13.9199,100,1,12.5000,700,1,13.9399,2,1,12.4600,100,1,14.2300,100,1,12.4299,700,1,14.2799,100,1,12.4199,700,1,14.5199,300,3,ARL,330592465
1945,2025-07-17T16:06:07.509885114Z,2025-07-17T16:06:07.509885114Z,10,2,1108,C,A,0,13.6400,15,130,165644,275647392,13.1099,100,1,13.6199,15,1,13.0000,2,1,13.6300,100,1,12.9800,200,2,13.6500,100,1,12.8599,100,1,13.8000,200,2,12.7300,100,1,13.9199,100,1,12.7100,100,1,13.9399,2,1,12.5000,700,1,14.2300,100,1,12.4600,100,1,14.2799,100,1,12.4299,700,1,14.5199,300,3,12.4199,700,1,14.5600,800,2,ARL,330357473
1946,2025-07-17T16:06:09.884978592Z,2025-07-17T16:06:09.884978592Z,10,2,1108,A,A,0,13.5999,15,130,165317,275699092,13.1099,100,1,13.5999,15,1,13.0000,2,1,13.6199,15,1,12.9800,200,2,13.6300,100,1,12.8599,100,1,13.6500,100,1,12.7300,100,1,13.8000,200,2,12.7100,100,1,13.9199,100,1,12.5000,700,1,13.9399,2,1,12.4600,100,1,14.2300,100,1,12.4299,700,1,14.2799,100,1,12.4199,700,1,14.5199,300,3,ARL,330788421
1947,2025-07-17T16:06:09.967442600Z,2025-07-17T16:06:09.967442600Z,10,2,1108,C,A,0,13.6300,100,0,165461,275700261,13.1099,100,1,13.5999,15,1,13.0000,2,1,13.6199,15,1,12.9800,200,2,13.6500,100,1,12.8599,100,1,13.8000,200,2,12.7300,100,1,13.9199,100,1,12.7100,100,1,13.9399,2,1,12.5000,700,1,14.2300,100,1,12.4600,100,1,14.2799,100,1,12.4299,700,1,14.5199,300,3,12.4199,700,1,14.5600,800,2,ARL,330592465
1948,2025-07-17T16:06:09.967442600Z,2025-07-17T16:06:09.967442600Z,10,2,1108,A,A,0,13.6099,100,130,165461,275700261,13.1099,100,1,13.5999,15,1,13.0000,2,1,13.6099,100,1,12.9800,200,2,13.6199,15,1,12.8599,100,1,13.6500,100,1,12.7300,100,1,13.8000,200,2,12.7100,100,1,13.9199,100,1,12.5000,700,1,13.9399,2,1,12.4600,100,1,14.2300,100,1,12.4299,700,1,14.2799,100,1,12.4199,700,1,14.5199,300,3,ARL,330789481
1949,2025-07-17T16:06:09.968186617Z,2025-07-17T16:06:09.968186617Z,10,2,1108,C,A,0,14.7100,100,0,165449,275700270,13.1099,100,1,13.5999,15,1,13.0000,2,1,13.6099,100,1,12.9800,200,2,13.6199,15,1,12.8599,100,1,13.6500,100,1,12.7300,100,1,13.8000,200,2,12.7100,100,1,13.9199,100,1,12.5000,700,1,13.9399,2,1,12.4600,100,1,14.2300,100,1,12.4299,700,1,14.2799,100,1,12.4199,700,1,14.5199,300,3,ARL,330359225
1950,2025-07-17T16:06:09.968186617Z,2025-07-17T16:06:09.968186617Z,10,2,1108,A,A,0,14.6699,100,130,165449,275700270,13.1099,100,1,13.5999,15,1,13.0000,2,1,13.6099,100,1,12.9800,200,2,13.6199,15,1,12.8599,100,1,13.6500,100,1,12.7300,100,1,13.8000,200,2,12.7100,100,1,13.9199,100,1,12.5000,700,1,13.9399,2,1,12.4600,100,1,14.2300,100,1,12.4299,700,1,14.2799,100,1,12.4199,700,1,14.5199,300,3,ARL,330789501
1951,2025-07-17T16:06:09.969875190Z,2025-07-17T16:06:09.969875190Z,10,2,1108,C,A,0,17.4400,100,0,165496,275700282,13.1099,100,1,13.5999,15,1,13.0000,2,1,13.6099,100,1,12.9800,200,2,13.6199,15,1,12.8599,100,1,13.6500,100,1,12.7300,100,1,13.8000,200,2,12.7100,100,1,13.9199,100,1,12.5000,700,1,13.9399,2,1,12.4600,100,1,14.2300,100,1,12.4299,700,1,14.2799,100,1,12.4199,700,1,14.5199,300,3,ARL,327870217
1952,2025-07-17T16:06:09.969875190Z,2025-07-17T16:06:09.969875190Z,10,2,1108,A,A,0,17.2899,100,130,165496,275700282,13.1099,100,1,13.5999,15,1,13.0000,2,1,13.6099,100,1,12.9800,200,2,13.6199,15,1,12.8599,100,1,13.6500,100,1,12.7300,100,1,13.8000,200,2,12.7100,100,1,13.9199,100,1,12.5000,700,1,13.9399,2,1,12.4600,100,1,14.2300,100,1,12.4299,700,1,14.2799,100,1,12.4199,700,1,14.5199,300,3,ARL,330789509
1953,2025-07-17T16:06:20.470724464Z,2025-07-17T16:06:20.470724464Z,10,2,1108,A,A,0,13.6300,100,130,165387,275896138,13.1099,100,1,13.5999,15,1,13.0000,2,1,13.6099,100,1,12.9800,200,2,13.6199,15,1,12.8599,100,1,13.6300,100,1,12.7300,100,1,13.6500,100,1,12.7100,100,1,13.8000,200,2,12.5000,700,1,13.9199,100,1,12.4600,100,1,13.9399,2,1,12.4299,700,1,14.2300,100,1,12.4199,700,1,14.2799,100,1,ARL,331018065
1954,2025-07-17T16:06:20.477432988Z,2025-07-17T16:06:20.477432988Z,10,2,1108,C,A,0,13.6500,100,130,165590,275896242,13.1099,100,1,13.5999,15,1,13.0000,2,1,13.6099,100,1,12.9800,200,2,13.6199,15,1,12.8599,100,1,13.6300,100,1,12.7300,100,1,13.8000,200,2,12.7100,100,1,13.9199,100,1,12.5000,700,1,13.9399,2,1,12.4600,100,1,14.2300,100,1,12.4299,700,1,14.2799,100,1,12.4199,700,1,14.5199,300,3,ARL,330577773
1955,2025-07-17T16:06:20.810998706Z,2025-07-17T16:06:20.810998706Z,10,2,1108,C,A,0,13.6199,15,130,165472,275900161,13.1099,100,1,13.5999,15,1,13.0000,2,1,13.6099,100,1,12.9800,200,2,13.6300,100,1,12.8599,100,1,13.8000,200,2,12.7300,100,1,13.9199,100,1,12.7100,100,1,13.9399,2,1,12.5000,700,1,14.2300,100,1,12.4600,100,1,14.2799,100,1,12.4299,700,1,14.5199,300,3,12.4199,700,1,14.5600,800,2,ARL,330577045
1956,2025-07-17T16:06:22.151057292Z,2025-07-17T16:06:22.151057292Z,10,2,1108,A,A,0,13.5800,15,130,165527,275926927,13.1099,100,1,13.5800,15,1,13.0000,2,1,13.5999,15,1,12.9800,200,2,13.6099,100,1,12.8599,100,1,13.6300,100,1,12.7300,100,1,13.8000,200,2,12.7100,100,1,13.9199,100,1,12.5000,700,1,13.9399,2,1,12.4600,100,1,14.2300,100,1,12.4299,700,1,14.2799,100,1,12.4199,700,1,14.5199,300,3,ARL,331050981
1957,2025-07-17T16:06:22.151326300Z,2025-07-17T16:06:22.151326300Z,10,2,1108,C,A,0,13.6099,100,0,165532,275926940,13.1099,100,1,13.5800,15,1,13.0000,2,1,13.5999,15,1,12.9800,200,2,13.6300,100,1,12.8599,100,1,13.8000,200,2,12.7300,100,1,13.9199,100,1,12.7100,100,1,13.9399,2,1,12.5000,700,1,14.2300,100,1,12.4600,100,1,14.2799,100,1,12.4299,700,1,14.5199,300,3,12.4199,700,1,14.5600,800,2,ARL,330789481
1958,2025-07-17T16:06:22.151326300Z,2025-07-17T16:06:22.151326300Z,10,2,1108,A,A,0,13.5899,100,130,165532,275926940,13.1099,100,1,13.5800,15,1,13.0000,2,1,13.5899,100,1,12.9800,200,2,13.5999,15,1,12.8599,100,1,13.6300,100,1,12.7300,100,1,13.8000,200,2,12.7100,100,1,13.9199,100,1,12.5000,700,1,13.9399,2,1,12.4600,100,1,14.2300,100,1,12.4299,700,1,14.2799,100,1,12.4199,700,1,14.5199,300,3,ARL,331050989
1959,2025-07-17T16:06:22.151595415Z,2025-07-17T16:06:22.151595415Z,10,2,1108,C,A,0,13.8000,100,0,165914,275926966,13.1099,100,1,13.5800,15,1,13.0000,2,1,13.5899,100,1,12.9800,200,2,13.5999,15,1,12.8599,100,1,13.6300,100,1,12.7300,100,1,13.8000,100,1,12.7100,100,1,13.9199,100,1,12.5000,700,1,13.9399,2,1,12.4600,100,1,14.2300,100,1,12.4299,700,1,14.2799,100,1,12.4199,700,1,14.5199,300,3,ARL,328614525
1960,2025-07-17T16:06:22.151595781Z,2025-07-17T16:06:22.151595781Z,10,2,1108,C,A,0,13.8000,100,130,165548,275926967,13.1099,100,1,13.5800,15,1,13.0000,2,1,13.5899,100,1,12.9800,200,2,13.5999,15,1,12.8599,100,1,13.6300,100,1,12.7300,100,1,13.9199,100,1,12.7100,100,1,13.9399,2,1,12.5000,700,1,14.2300,100,1,12.4600,100,1,14.2799,100,1,12.4299,700,1,14.5199,300,3,12.4199,700,1,14.5600,800,2,ARL,328614529
1961,2025-07-17T16:06:22.152983326Z,2025-07-17T16:06:22.152983326Z,10,2,1108,C,A,0,15.7899,100,0,165567,275927034,13.1099,100,1,13.5800,15,1,13.0000,2,1,13.5899,100,1,12.9800,200,2,13.5999,15,1,12.8599,100,1,13.6300,100,1,12.7300,100,1,13.9199,100,1,12.7100,100,1,13.9399,2,1,12.5000,700,1,14.2300,100,1,12.4600,100,1,14.2799,100,1,12.4299,700,1,14.5199,300,3,12.4199,700,1,14.5600,800,2,ARL,327870361
1962,2025-07-17T16:06:22.152983326Z,2025-07-17T16:06:22.152983326Z,10,2,1108,A,A,0,15.6300,100,130,165567,275927034,13.1099,100,1,13.5800,15,1,13.0000,2,1,13.5899,100,1,12.9800,200,2,13.5999,15,1,12.8599,100,1,13.6300,100,1,12.7300,100,1,13.9199,100,1,12.7100,100,1,13.9399,2,1,12.5000,700,1,14.2300,100,1,12.4600,100,1,14.2799,100,1,12.4299,700,1,14.5199,300,3,12.4199,700,1,14.5600,800,2,ARL,331051145
1963,2025-07-17T16:06:22.153749481Z,2025-07-17T16:06:22.153749481Z,10,2,1108,C,A,0,14.6999,100,0,166688,275927046,13.1099,100,1,13.5800,15,1,13.0000,2,1,13.5899,100,1,12.9800,200,2,13.5999,15,1,12.8599,100,1,13.6300,100,1,12.7300,100,1,13.9199,100,1,12.7100,100,1,13.9399,2,1,12.5000,700,1,14.2300,100,1,12.4600,100,1,14.2799,100,1,12.4299,700,1,14.5199,300,3,12.4199,700,1,14.5600,800,2,ARL,327868421
1964,2025-07-17T16:06:22.153749481Z,2025-07-17T16:06:22.153749481Z,10,2,1108,A,A,0,14.5500,100,130,166688,275927046,13.1099,100,1,13.5800,15,1,13.0000,2,1,13.5899,100,1,12.9800,200,2,13.5999,15,1,12.8599,100,1,13.6300,100,1,12.7300,100,1,13.9199,100,1,12.7100,100,1,13.9399,2,1,12.5000,700,1,14.2300,100,1,12.4600,100,1,14.2799,100,1,12.4299,700,1,14.5199,300,3,12.4199,700,1,14.5500,100,1,ARL,331051173
1965,2025-07-17T16:06:22.155905240Z,2025-07-17T16:06:22.155905240Z,10,2,1108,C,A,0,14.5199,100,0,165458,275927117,13.1099,100,1,13.5800,15,1,13.0000,2,1,13.5899,100,1,12.9800,200,2,13.5999,15,1,12.8599,100,1,13.6300,100,1,12.7300,100,1,13.9199,100,1,12.7100,100,1,13.9399,2,1,12.5000,700,1,14.2300,100,1,12.4600,100,1,14.2799,100,1,12.4299,700,1,14.5199,200,2,12.4199,700,1,14.5500,100,1,ARL,327869529
1966,2025-07-17T16:06:22.155905240Z,2025-07-17T16:06:22.155905240Z,10,2,1108,A,A,0,14.3800,100,130,165458,275927117,13.1099,100,1,13.5800,15,1,13.0000,2,1,13.5899,100,1,12.9800,200,2,13.5999,15,1,12.8599,100,1,13.6300,100,1,12.7300,100,1,13.9199,100,1,12.7100,100,1,13.9399,2,1,12.5000,700,1,14.2300,100,1,12.4600,100,1,14.2799,100,1,12.4299,700,1,14.3800,100,1,12.4199,700,1,14.5199,200,2,ARL,331051369
1967,2025-07-17T16:06:22.177879233Z,2025-07-17T16:06:22.177879233Z,10,2,1108,C,A,0,14.6999,100,0,165442,275927444,13.1099,100,1,13.5800,15,1,13.0000,2,1,13.5899,100,1,12.9800,200,2,13.5999,15,1,12.8599,100,1,13.6300,100,1,12.7300,100,1,13.9199,100,1,12.7100,100,1,13.9399,2,1,12.5000,700,1,14.2300,100,1,12.4600,100,1,14.2799,100,1,12.4299,700,1,14.3800,100,1,12.4199,700,1,14.5199,200,2,ARL,327873009
1968,2025-07-17T16:06:22.177879233Z,2025-07-17T16:06:22.177879233Z,10,2,1108,A,A,0,14.5500,100,130,165442,275927444,13.1099,100,1,13.5800,15,1,13.0000,2,1,13.5899,100,1,12.9800,200,2,13.5999,15,1,12.8599,100,1,13.6300,100,1,12.7300,100,1,13.9199,100,1,12.7100,100,1,13.9399,2,1,12.5000,700,1,14.2300,100,1,12.4600,100,1,14.2799,100,1,12.4299,700,1,14.3800,100,1,12.4199,700,1,14.5199,200,2,ARL,331052197
1969,2025-07-17T16:06:24.519345743Z,2025-07-17T16:06:24.519345743Z,10,2,1108,A,A,0,13.5999,100,130,165385,275968354,13.1099,100,1,13.5800,15,1,13.0000,2,1,13.5899,100,1,12.9800,200,2,13.5999,115,2,12.8599,100,1,13.6300,100,1,12.7300,100,1,13.9199,100,1,12.7100,100,1,13.9399,2,1,12.5000,700,1,14.2300,100,1,12.4600,100,1,14.2799,100,1,12.4299,700,1,14.3800,100,1,12.4199,700,1,14.5199,200,2,ARL,331104725
1970,2025-07-17T16:06:24.526194457Z,2025-07-17T16:06:24.526194457Z,10,2,1108,C,A,0,13.6300,100,130,165259,275968393,13.1099,100,1,13.5800,15,1,13.0000,2,1,13.5899,100,1,12.9800,200,2,13.5999,115,2,12.8599,100,1,13.9199,100,1,12.7300,100,1,13.9399,2,1,12.7100,100,1,14.2300,100,1,12.5000,700,1,14.2799,100,1,12.4600,100,1,14.3800,100,1,12.4299,700,1,14.5199,200,2,12.4199,700,1,14.5500,200,2,ARL,331018065
1971,2025-07-17T16:06:26.610180184Z,2025-07-17T16:06:26.610180184Z,10,2,1108,C,A,0,13.9399,2,0,165616,276013080,13.1099,100,1,13.5800,15,1,13.0000,2,1,13.5899,100,1,12.9800,200,2,13.5999,115,2,12.8599,100,1,13.9199,100,1,12.7300,100,1,14.2300,100,1,12.7100,100,1,14.2799,100,1,12.5000,700,1,14.3800,100,1,12.4600,100,1,14.5199,200,2,12.4299,700,1,14.5500,200,2,12.4199,700,1,14.5600,800,2,ARL,328351217
1972,2025-07-17T16:06:26.610180184Z,2025-07-17T16:06:26.610180184Z,10,2,1108,A,A,0,13.8499,2,130,165616,276013080,13.1099,100,1,13.5800,15,1,13.0000,2,1,13.5899,100,1,12.9800,200,2,13.5999,115,2,12.8599,100,1,13.8499,2,1,12.7300,100,1,13.9199,100,1,12.7100,100,1,14.2300,100,1,12.5000,700,1,14.2799,100,1,12.4600,100,1,14.3800,100,1,12.4299,700,1,14.5199,200,2,12.4199,700,1,14.5500,200,2,ARL,331155889
1973,2025-07-17T16:06:30.625711923Z,2025-07-17T16:06:30.625711923Z,10,2,1108,A,A,0,14.2699,700,130,165291,276103282,13.1099,100,1,13.5800,15,1,13.0000,2,1,13.5899,100,1,12.9800,200,2,13.5999,115,2,12.8599,100,1,13.8499,2,1,12.7300,100,1,13.9199,100,1,12.7100,100,1,14.2300,100,1,12.5000,700,1,14.2699,700,1,12.4600,100,1,14.2799,100,1,12.4299,700,1,14.3800,100,1,12.4199,700,1,14.5199,200,2,ARL,331257169
1974,2025-07-17T16:06:30.625790910Z,2025-07-17T16:06:30.625790910Z,10,2,1108,C,A,0,14.6799,700,130,165397,276103283,13.1099,100,1,13.5800,15,1,13.0000,2,1,13.5899,100,1,12.9800,200,2,13.5999,115,2,12.8599,100,1,13.8499,2,1,12.7300,100,1,13.9199,100,1,12.7100,100,1,14.2300,100,1,12.5000,700,1,14.2699,700,1,12.4600,100,1,14.2799,100,1,12.4299,700,1,14.3800,100,1,12.4199,700,1,14.5199,200,2,ARL,325716945
1975,2025-07-17T16:06:31.127662311Z,2025-07-17T16:06:31.127662311Z,10,2,1108,A,A,0,14.4800,700,130,165494,276118990,13.1099,100,1,13.5800,15,1,13.0000,2,1,13.5899,100,1,12.9800,200,2,13.5999,115,2,12.8599,100,1,13.8499,2,1,12.7300,100,1,13.9199,100,1,12.7100,100,1,14.2300,100,1,12.5000,700,1,14.2699,700,1,12.4600,100,1,14.2799,100,1,12.4299,700,1,14.3800,100,1,12.4199,700,1,14.4800,700,1,ARL,331272997
1976,2025-07-17T16:06:31.128416336Z,2025-07-17T16:06:31.128416336Z,10,2,1108,C,A,0,14.6799,700,130,165495,276119017,13.1099,100,1,13.5800,15,1,13.0000,2,1,13.5899,100,1,12.9800,200,2,13.5999,115,2,12.8599,100,1,13.8499,2,1,12.7300,100,1,13.9199,100,1,12.7100,100,1,14.2300,100,1,12.5000,700,1,14.2699,700,1,12.4600,100,1,14.2799,100,1,12.4299,700,1,14.3800,100,1,12.4199,700,1,14.4800,700,1,ARL,289932801
1977,2025-07-17T16:06:31.990483799Z,2025-07-17T16:06:31.990483799Z,10,2,1108,C,A,0,13.5999,15,130,165430,276135226,13.1099,100,1,13.5800,15,1,13.0000,2,1,13.5899,100,1,12.9800,200,2,13.5999,100,1,12.8599,100,1,13.8499,2,1,12.7300,100,1,13.9199,100,1,12.7100,100,1,14.2300,100,1,12.5000,700,1,14.2699,700,1,12.4600,100,1,14.2799,100,1,12.4299,700,1,14.3800,100,1,12.4199,700,1,14.4800,700,1,ARL,330788421
1978,2025-07-17T16:06:42.812641697Z,2025-07-17T16:06:42.812641697Z,10,2,1108,A,A,0,13.5600,15,130,165399,276276783,13.1099,100,1,13.5600,15,1,13.0000,2,1,13.5800,15,1,12.9800,200,2,13.5899,100,1,12.8599,100,1,13.5999,100,1,12.7300,100,1,13.8499,2,1,12.7100,100,1,13.9199,100,1,12.5000,700,1,14.2300,100,1,12.4600,100,1,14.2699,700,1,12.4299,700,1,14.2799,100,1,12.4199,700,1,14.3800,100,1,ARL,331488089
1979,2025-07-17T16:06:43.012799164Z,2025-07-17T16:06:43.012799164Z,10,2,1108,C,A,0,13.5899,100,0,166793,276279311,13.1099,100,1,13.5600,15,1,13.0000,2,1,13.5800,15,1,12.9800,200,2,13.5999,100,1,12.8599,100,1,13.8499,2,1,12.7300,100,1,13.9199,100,1,12.7100,100,1,14.2300,100,1,12.5000,700,1,14.2699,700,1,12.4600,100,1,14.2799,100,1,12.4299,700,1,14.3800,100,1,12.4199,700,1,14.4800,700,1,ARL,331050989
1980,2025-07-17T16:06:43.012799164Z,2025-07-17T16:06:43.012799164Z,10,2,1108,A,A,0,13.5700,100,128,166793,276279311,13.1099,100,1,13.5600,15,1,13.0000,2,1,13.5700,100,1,12.9800,200,2,13.5800,15,1,12.8599,100,1,13.5999,100,1,12.7300,100,1,13.8499,2,1,12.7100,100,1,13.9199,100,1,12.5000,700,1,14.2300,100,1,12.4600,100,1,14.2699,700,1,12.4299,700,1,14.2799,100,1,12.4199,700,1,14.3800,100,1,ARL,331491049
1981,2025-07-17T16:06:43.013550575Z,2025-07-17T16:06:43.013550575Z,10,2,1108,C,A,0,14.6699,100,0,165630,276279331,13.1099,100,1,13.5600,15,1,13.0000,2,1,13.5700,100,1,12.9800,200,2,13.5800,15,1,12.8599,100,1,13.5999,100,1,12.7300,100,1,13.8499,2,1,12.7100,100,1,13.9199,100,1,12.5000,700,1,14.2300,100,1,12.4600,100,1,14.2699,700,1,12.4299,700,1,14.2799,100,1,12.4199,700,1,14.3800,100,1,ARL,330789501
1982,2025-07-17T16:06:43.013550575Z,2025-07-17T16:06:43.013550575Z,10,2,1108,A,A,0,14.6199,100,130,165630,276279331,13.1099,100,1,13.5600,15,1,13.0000,2,1,13.5700,100,1,12.9800,200,2,13.5800,15,1,12.8599,100,1,13.5999,100,1,12.7300,100,1,13.8499,2,1,12.7100,100,1,13.9199,100,1,12.5000,700,1,14.2300,100,1,12.4600,100,1,14.2699,700,1,12.4299,700,1,14.2799,100,1,12.4199,700,1,14.3800,100,1,ARL,331491077
1983,2025-07-17T16:06:43.024490355Z,2025-07-17T16:06:43.024490355Z,10,2,1108,C,A,0,13.9199,100,130,165668,276279620,13.1099,100,1,13.5600,15,1,13.0000,2,1,13.5700,100,1,12.9800,200,2,13.5800,15,1,12.8599,100,1,13.5999,100,1,12.7300,100,1,13.8499,2,1,12.7100,100,1,14.2300,100,1,12.5000,700,1,14.2699,700,1,12.4600,100,1,14.2799,100,1,12.4299,700,1,14.3800,100,1,12.4199,700,1,14.4800,700,1,ARL,330359625
1984,2025-07-17T16:06:43.024543099Z,2025-07-17T16:06:43.024543099Z,10,2,1108,A,A,0,13.8399,100,130,165205,276279621,13.1099,100,1,13.5600,15,1,13.0000,2,1,13.5700,100,1,12.9800,200,2,13.5800,15,1,12.8599,100,1,13.5999,100,1,12.7300,100,1,13.8399,100,1,12.7100,100,1,13.8499,2,1,12.5000,700,1,14.2300,100,1,12.4600,100,1,14.2699,700,1,12.4299,700,1,14.2799,100,1,12.4199,700,1,14.3800,100,1,ARL,331491269
1985,2025-07-17T16:06:49.613776144Z,2025-07-17T16:06:49.613776144Z,10,2,1108,C,A,0,13.5800,15,130,165677,276382302,13.1099,100,1,13.5600,15,1,13.0000,2,1,13.5700,100,1,12.9800,200,2,13.5999,100,1,12.8599,100,1,13.8399,100,1,12.7300,100,1,13.8499,2,1,12.7100,100,1,14.2300,100,1,12.5000,700,1,14.2699,700,1,12.4600,100,1,14.2799,100,1,12.4299,700,1,14.3800,100,1,12.4199,700,1,14.4800,700,1,ARL,331050981
1986,2025-07-17T16:06:50.618504506Z,2025-07-17T16:06:50.618504506Z,10,2,1108,A,A,0,13.5399,15,130,165337,276408477,13.1099,100,1,13.5399,15,1,13.0000,2,1,13.5600,15,1,12.9800,200,2,13.5700,100,1,12.8599,100,1,13.5999,100,1,12.7300,100,1,13.8399,100,1,12.7100,100,1,13.8499,2,1,12.5000,700,1,14.2300,100,1,12.4600,100,1,14.2699,700,1,12.4299,700,1,14.2799,100,1,12.4199,700,1,14.3800,100,1,ARL,331666961
1987,2025-07-17T16:06:50.626272828Z,2025-07-17T16:06:50.626272828Z,10,2,1108,A,A,0,13.5800,100,130,165377,276408566,13.1099,100,1,13.5399,15,1,13.0000,2,1,13.5600,15,1,12.9800,200,2,13.5700,100,1,12.8599,100,1,13.5800,100,1,12.7300,100,1,13.5999,100,1,12.7100,100,1,13.8399,100,1,12.5000,700,1,13.8499,2,1,12.4600,100,1,14.2300,100,1,12.4299,700,1,14.2699,700,1,12.4199,700,1,14.2799,100,1,ARL,331667121
1988,2025-07-17T16:06:50.632947998Z,2025-07-17T16:06:50.632947998Z,10,2,1108,C,A,0,13.5999,100,130,165559,276408644,13.1099,100,1,13.5399,15,1,13.0000,2,1,13.5600,15,1,12.9800,200,2,13.5700,100,1,12.8599,100,1,13.5800,100,1,12.7300,100,1,13.8399,100,1,12.7100,100,1,13.8499,2,1,12.5000,700,1,14.2300,100,1,12.4600,100,1,14.2699,700,1,12.4299,700,1,14.2799,100,1,12.4199,700,1,14.3800,100,1,ARL,331104725
1989,2025-07-17T16:06:51.754410704Z,2025-07-17T16:06:51.754410704Z,10,2,1108,C,A,0,13.5700,100,0,165618,276428315,13.1099,100,1,13.5399,15,1,13.0000,2,1,13.5600,15,1,12.9800,200,2,13.5800,100,1,12.8599,100,1,13.8399,100,1,12.7300,100,1,13.8499,2,1,12.7100,100,1,14.2300,100,1,12.5000,700,1,14.2699,700,1,12.4600,100,1,14.2799,100,1,12.4299,700,1,14.3800,100,1,12.4199,700,1,14.4800,700,1,ARL,331491049
1990,2025-07-17T16:06:51.754410704Z,2025-07-17T16:06:51.754410704Z,10,2,1108,A,A,0,13.5500,100,130,165618,276428315,13.1099,100,1,13.5399,15,1,13.0000,2,1,13.5500,100,1,12.9800,200,2,13.5600,15,1,12.8599,100,1,13.5800,100,1,12.7300,100,1,13.8399,100,1,12.7100,100,1,13.8499,2,1,12.5000,700,1,14.2300,100,1,12.4600,100,1,14.2699,700,1,12.4299,700,1,14.2799,100,1,12.4199,700,1,14.3800,100,1,ARL,331694265
1991,2025-07-17T16:06:51.757237300Z,2025-07-17T16:06:51.757237300Z,10,2,1108,C,B,0,13.0000,2,0,165809,276428333,13.1099,100,1,13.5399,15,1,12.9800,200,2,13.5500,100,1,12.8599,100,1,13.5600,15,1,12.7300,100,1,13.5800,100,1,12.7100,100,1,13.8399,100,1,12.5000,700,1,13.8499,2,1,12.4600,100,1,14.2300,100,1,12.4299,700,1,14.2699,700,1,12.4199,700,1,14.2799,100,1,12.3699,700,1,14.3800,100,1,ARL,325967705
1992,2025-07-17T16:06:51.757237300Z,2025-07-17T16:06:51.757237300Z,10,2,1108,A,B,0,12.9000,2,130,165809,276428333,13.1099,100,1,13.5399,15,1,12.9800,200,2,13.5500,100,1,12.9000,2,1,13.5600,15,1,12.8599,100,1,13.5800,100,1,12.7300,100,1,13.8399,100,1,12.7100,100,1,13.8499,2,1,12.5000,700,1,14.2300,100,1,12.4600,100,1,14.2699,700,1,12.4299,700,1,14.2799,100,1,12.4199,700,1,14.3800,100,1,ARL,331694297
1993,2025-07-17T16:06:55.056135380Z,2025-07-17T16:06:55.056135380Z,10,2,1108,C,A,0,13.5399,15,130,165481,276516227,13.1099,100,1,13.5500,100,1,12.9800,200,2,13.5600,15,1,12.9000,2,1,13.5800,100,1,12.8599,100,1,13.8399,100,1,12.7300,100,1,13.8499,2,1,12.7100,100,1,14.2300,100,1,12.5000,700,1,14.2699,700,1,12.4600,100,1,14.2799,100,1,12.4299,700,1,14.3800,100,1,12.4199,700,1,14.4800,700,1,ARL,331666961
1994,2025-07-17T16:06:55.056301001Z,2025-07-17T16:06:55.056301001Z,10,2,1108,C,A,0,13.5600,15,130,165230,276516239,13.1099,100,1,13.5500,100,1,12.9800,200,2,13.5800,100,1,12.9000,2,1,13.8399,100,1,12.8599,100,1,13.8499,2,1,12.7300,100,1,14.2300,100,1,12.7100,100,1,14.2699,700,1,12.5000,700,1,14.2799,100,1,12.4600,100,1,14.3800,100,1,12.4299,700,1,14.4800,700,1,12.4199,700,1,14.5199,200,2,ARL,331488089
1995,2025-07-17T16:07:00.010829521Z,2025-07-17T16:07:00.010829521Z,10,2,1108,C,A,0,13.5500,100,130,166037,276611719,13.1099,100,1,13.5800,100,1,12.9800,200,2,13.8399,100,1,12.9000,2,1,13.8499,2,1,12.8599,100,1,14.2300,100,1,12.7300,100,1,14.2699,700,1,12.7100,100,1,14.2799,100,1,12.5000,700,1,14.3800,100,1,12.4600,100,1,14.4800,700,1,12.4299,700,1,14.5199,200,2,12.4199,700,1,14.5500,200,2,ARL,331694265
1996,2025-07-17T16:07:00.023683961Z,2025-07-17T16:07:00.023683961Z,10,2,1108,C,A,0,13.5800,100,130,165219,276613073,13.1099,100,1,13.8399,100,1,12.9800,200,2,13.8499,2,1,12.9000,2,1,14.2300,100,1,12.8599,100,1,14.2699,700,1,12.7300,100,1,14.2799,100,1,12.7100,100,1,14.3800,100,1,12.5000,700,1,14.4800,700,1,12.4600,100,1,14.5199,200,2,12.4299,700,1,14.5500,200,2,12.4199,700,1,14.5600,800,2,ARL,331667121
1997,2025-07-17T16:07:00.023752163Z,2025-07-17T16:07:00.023752163Z,10,2,1108,C,A,0,14.2699,700,130,165380,276613077,13.1099,100,1,13.8399,100,1,12.9800,200,2,13.8499,2,1,12.9000,2,1,14.2300,100,1,12.8599,100,1,14.2799,100,1,12.7300,100,1,14.3800,100,1,12.7100,100,1,14.4800,700,1,12.5000,700,1,14.5199,200,2,12.4600,100,1,14.5500,200,2,12.4299,700,1,14.5600,800,2,12.4199,700,1,14.5999,700,1,ARL,331257169
1998,2025-07-17T16:07:00.023815326Z,2025-07-17T16:07:00.023815326Z,10,2,1108,A,A,0,14.5099,700,130,165479,276613078,13.1099,100,1,13.8399,100,1,12.9800,200,2,13.8499,2,1,12.9000,2,1,14.2300,100,1,12.8599,100,1,14.2799,100,1,12.7300,100,1,14.3800,100,1,12.7100,100,1,14.4800,700,1,12.5000,700,1,14.5099,700,1,12.4600,100,1,14.5199,200,2,12.4299,700,1,14.5500,200,2,12.4199,700,1,14.5600,800,2,ARL,331926981
1999,2025-07-17T16:07:00.024424816Z,2025-07-17T16:07:00.024424816Z,10,2,1108,C,A,0,14.6199,100,0,165467,276613110,13.1099,100,1,13.8399,100,1,12.9800,200,2,13.8499,2,1,12.9000,2,1,14.2300,100,1,12.8599,100,1,14.2799,100,1,12.7300,100,1,14.3800,100,1,12.7100,100,1,14.4800,700,1,12.5000,700,1,14.5099,700,1,12.4600,100,1,14.5199,200,2,12.4299,700,1,14.5500,200,2,12.4199,700,1,14.5600,800,2,ARL,331491077
2000,2025-07-17T16:07:00.024424816Z,2025-07-17T16:07:00.024424816Z,10,2,1108,A,A,0,14.8800,100,130,165467,276613110,13.1099,100,1,13.8399,100,1,12.9800,200,2,13.8499,2,1,12.9000,2,1,14.2300,100,1,12.8599,100,1,14.2799,100,1,12.7300,100,1,14.3800,100,1,12.7100,100,1,14.4800,700,1,12.5000,700,1,14.5099,700,1,12.4600,100,1,14.5199,200,2,12.4299,700,1,14.5500,200,2,12.4199,700,1,14.5600,800,2,ARL,331927017
2001,2025-07-17T16:07:00.025064913Z,2025-07-17T16:07:00.025064913Z,10,2,1108,C,A,0,14.2300,100,130,166251,276613157,13.1099,100,1,13.8399,100,1,12.9800,200,2,13.8499,2,1,12.9000,2,1,14.2799,100,1,12.8599,100,1,14.3800,100,1,12.7300,100,1,14.4800,700,1,12.7100,100,1,14.5099,700,1,12.5000,700,1,14.5199,200,2,12.4600,100,1,14.5500,200,2,12.4299,700,1,14.5600,800,2,12.4199,700,1,14.5999,700,1,ARL,329074833
2002,2025-07-17T16:07:00.025422082Z,2025-07-17T16:07:00.025422082Z,10,2,1108,A,A,0,14.4600,100,130,165467,276613175,13.1099,100,1,13.8399,100,1,12.9800,200,2,13.8499,2,1,12.9000,2,1,14.2799,100,1,12.8599,100,1,14.3800,100,1,12.7300,100,1,14.4600,100,1,12.7100,100,1,14.4800,700,1,12.5000,700,1,14.5099,700,1,12.4600,100,1,14.5199,200,2,12.4299,700,1,14.5500,200,2,12.4199,700,1,14.5600,800,2,ARL,331927161
2003,2025-07-17T16:07:00.025628157Z,2025-07-17T16:07:00.025628157Z,10,2,1108,A,A,0,13.5899,100,130,165103,276613194,13.1099,100,1,13.5899,100,1,12.9800,200,2,13.8399,100,1,12.9000,2,1,13.8499,2,1,12.8599,100,1,14.2799,100,1,12.7300,100,1,14.3800,100,1,12.7100,100,1,14.4600,100,1,12.5000,700,1,14.4800,700,1,12.4600,100,1,14.5099,700,1,12.4299,700,1,14.5199,200,2,12.4199,700,1,14.5500,200,2,ARL,331927177
2004,2025-07-17T16:07:00.026833761Z,2025-07-17T16:07:00.026833761Z,10,2,1108,C,A,0,13.5899,100,130,164934,276613224,13.1099,100,1,13.8399,100,1,12.9800,200,2,13.8499,2,1,12.9000,2,1,14.2799,100,1,12.8599,100,1,14.3800,100,1,12.7300,100,1,14.4600,100,1,12.7100,100,1,14.4800,700,1,12.5000,700,1,14.5099,700,1,12.4600,100,1,14.5199,200,2,12.4299,700,1,14.5500,200,2,12.4199,700,1,14.5600,800,2,ARL,331927177
2005,2025-07-17T16:07:00.032596898Z,2025-07-17T16:07:00.032596898Z,10,2,1108,C,A,0,14.3800,100,130,165284,276613329,13.1099,100,1,13.8399,100,1,12.9800,200,2,13.8499,2,1,12.9000,2,1,14.2799,100,1,12.8599,100,1,14.4600,100,1,12.7300,100,1,14.4800,700,1,12.7100,100,1,14.5099,700,1,12.5000,700,1,14.5199,200,2,12.4600,100,1,14.5500,200,2,12.4299,700,1,14.5600,800,2,12.4199,700,1,14.5999,700,1,ARL,331051369
2006,2025-07-17T16:07:00.032711777Z,2025-07-17T16:07:00.032711777Z,10,2,1108,A,A,0,14.6300,100,130,165170,276613336,13.1099,100,1,13.8399,100,1,12.9800,200,2,13.8499,2,1,12.9000,2,1,14.2799,100,1,12.8599,100,1,14.4600,100,1,12.7300,100,1,14.4800,700,1,12.7100,100,1,14.5099,700,1,12.5000,700,1,14.5199,200,2,12.4600,100,1,14.5500,200,2,12.4299,700,1,14.5600,800,2,12.4199,700,1,14.5999,700,1,ARL,331927477
2007,2025-07-17T16:07:00.045359807Z,2025-07-17T16:07:00.045359807Z,10,2,1108,C,A,0,13.8399,100,130,165240,276613663,13.1099,100,1,13.8499,2,1,12.9800,200,2,14.2799,100,1,12.9000,2,1,14.4600,100,1,12.8599,100,1,14.4800,700,1,12.7300,100,1,14.5099,700,1,12.7100,100,1,14.5199,200,2,12.5000,700,1,14.5500,200,2,12.4600,100,1,14.5600,800,2,12.4299,700,1,14.5999,700,1,12.4199,700,1,14.6300,100,1,ARL,331491269
2008,2025-07-17T16:07:00.045394317Z,2025-07-17T16:07:00.045394317Z,10,2,1108,C,A,0,14.5099,700,130,164955,276613664,13.1099,100,1,13.8499,2,1,12.9800,200,2,14.2799,100,1,12.9000,2,1,14.4600,100,1,12.8599,100,1,14.4800,700,1,12.7300,100,1,14.5199,200,2,12.7100,100,1,14.5500,200,2,12.5000,700,1,14.5600,800,2,12.4600,100,1,14.5999,700,1,12.4299,700,1,14.6300,100,1,12.4199,700,1,14.8800,100,1,ARL,331926981
2009,2025-07-17T16:07:00.045409635Z,2025-07-17T16:07:00.045409635Z,10,2,1108,A,A,0,14.0899,100,130,165151,276613665,13.1099,100,1,13.8499,2,1,12.9800,200,2,14.0899,100,1,12.9000,2,1,14.2799,100,1,12.8599,100,1,14.4600,100,1,12.7300,100,1,14.4800,700,1,12.7100,100,1,14.5199,200,2,12.5000,700,1,14.5500,200,2,12.4600,100,1,14.5600,800,2,12.4299,700,1,14.5999,700,1,12.4199,700,1,14.6300,100,1,ARL,331927857
2010,2025-07-17T16:07:00.046672908Z,2025-07-17T16:07:00.046672908Z,10,2,1108,C,A,0,14.0899,100,130,165694,276613680,13.1099,100,1,13.8499,2,1,12.9800,200,2,14.2799,100,1,12.9000,2,1,14.4600,100,1,12.8599,100,1,14.4800,700,1,12.7300,100,1,14.5199,200,2,12.7100,100,1,14.5500,200,2,12.5000,700,1,14.5600,800,2,12.4600,100,1,14.5999,700,1,12.4299,700,1,14.6300,100,1,12.4199,700,1,14.8800,100,1,ARL,331927857
2011,2025-07-17T16:07:00.046721624Z,2025-07-17T16:07:00.046721624Z,10,2,1108,A,A,0,13.8599,100,130,165381,276613681,13.1099,100,1,13.8499,2,1,12.9800,200,2,13.8599,100,1,12.9000,2,1,14.2799,100,1,12.8599,100,1,14.4600,100,1,12.7300,100,1,14.4800,700,1,12.7100,100,1,14.5199,200,2,12.5000,700,1,14.5500,200,2,12.4600,100,1,14.5600,800,2,12.4299,700,1,14.5999,700,1,12.4199,700,1,14.6300,100,1,ARL,331927877
2012,2025-07-17T16:07:00.047544064Z,2025-07-17T16:07:00.047544064Z,10,2,1108,C,A,0,13.8599,100,130,164872,276613692,13.1099,100,1,13.8499,2,1,12.9800,200,2,14.2799,100,1,12.9000,2,1,14.4600,100,1,12.8599,100,1,14.4800,700,1,12.7300,100,1,14.5199,200,2,12.7100,100,1,14.5500,200,2,12.5000,700,1,14.5600,800,2,12.4600,100,1,14.5999,700,1,12.4299,700,1,14.6300,100,1,12.4199,700,1,14.8800,100,1,ARL,331927877
2013,2025-07-17T16:07:00.047590313Z,2025-07-17T16:07:00.047590313Z,10,2,1108,A,A,0,14.1199,100,130,165185,276613693,13.1099,100,1,13.8499,2,1,12.9800,200,2,14.1199,100,1,12.9000,2,1,14.2799,100,1,12.8599,100,1,14.4600,100,1,12.7300,100,1,14.4800,700,1,12.7100,100,1,14.5199,200,2,12.5000,700,1,14.5500,200,2,12.4600,100,1,14.5600,800,2,12.4299,700,1,14.5999,700,1,12.4199,700,1,14.6300,100,1,ARL,331927921
2014,2025-07-17T16:07:00.053283700Z,2025-07-17T16:07:00.053283700Z,10,2,1108,C,A,0,14.1199,100,130,164970,276613731,13.1099,100,1,13.8499,2,1,12.9800,200,2,14.2799,100,1,12.9000,2,1,14.4600,100,1,12.8599,100,1,14.4800,700,1,12.7300,100,1,14.5199,200,2,12.7100,100,1,14.5500,200,2,12.5000,700,1,14.5600,800,2,12.4600,100,1,14.5999,700,1,12.4299,700,1,14.6300,100,1,12.4199,700,1,14.8800,100,1,ARL,331927921
2015,2025-07-17T16:07:00.053329959Z,2025-07-17T16:07:00.053329959Z,10,2,1108,A,A,0,14.2599,100,130,165136,276613732,13.1099,100,1,13.8499,2,1,12.9800,200,2,14.2599,100,1,12.9000,2,1,14.2799,100,1,12.8599,100,1,14.4600,100,1,12.7300,100,1,14.4800,700,1,12.7100,100,1,14.5199,200,2,12.5000,700,1,14.5500,200,2,12.4600,100,1,14.5600,800,2,12.4299,700,1,14.5999,700,1,12.4199,700,1,14.6300,100,1,ARL,331928009
