,ts_recv,ts_event,rtype,publisher_id,instrument_id,action,side,depth,price,size,flags,ts_in_delta,sequence,bid_px_00,bid_sz_00,bid_ct_00,ask_px_00,ask_sz_00,ask_ct_00,bid_px_01,bid_sz_01,bid_ct_01,ask_px_01,ask_sz_01,ask_ct_01,bid_px_02,bid_sz_02,bid_ct_02,ask_px_02,ask_sz_02,ask_ct_02,bid_px_03,bid_sz_03,bid_ct_03,ask_px_03,ask_sz_03,ask_ct_03,bid_px_04,bid_sz_04,bid_ct_04,ask_px_04,ask_sz_04,ask_ct_04,bid_px_05,bid_sz_05,bid_ct_05,ask_px_05,ask_sz_05,ask_ct_05,bid_px_06,bid_sz_06,bid_ct_06,ask_px_06,ask_sz_06,ask_ct_06,bid_px_07,bid_sz_07,bid_ct_07,ask_px_07,ask_sz_07,ask_ct_07,bid_px_08,bid_sz_08,bid_ct_08,ask_px_08,ask_sz_08,ask_ct_08,bid_px_09,bid_sz_09,bid_ct_09,ask_px_09,ask_sz_09,ask_ct_09,symbol,order_id
1028,2025-07-17T15:42:06.795355762Z,2025-07-17T15:42:06.795355762Z,10,2,1108,C,A,0,14.2599,100,130,165545,251408268,13.2599,100,1,13.9000,15,1,13.0399,2,1,13.9100,100,1,13.0299,100,1,14.0700,2,1,12.7300,100,1,14.4000,100,1,12.7100,100,1,14.5600,900,3,12.5000,700,1,14.5999,700,1,12.4600,200,2,14.6799,1400,2,12.4299,700,1,14.7799,100,1,12.4199,700,1,14.8800,200,2,12.3699,700,1,14.9600,200,2,ARL,296479425
1029,2025-07-17T15:42:06.795408057Z,2025-07-17T15:42:06.795408057Z,10,2,1108,A,A,0,14.1899,100,130,165335,251408269,13.2599,100,1,13.9000,15,1,13.0399,2,1,13.9100,100,1,13.0299,100,1,14.0700,2,1,12.7300,100,1,14.1899,100,1,12.7100,100,1,14.4000,100,1,12.5000,700,1,14.5600,900,3,12.4600,200,2,14.5999,700,1,12.4299,700,1,14.6799,1400,2,12.4199,700,1,14.7799,100,1,12.3699,700,1,14.8800,200,2,ARL,299690593
1030,2025-07-17T15:42:16.263966448Z,2025-07-17T15:42:16.263966448Z,10,2,1108,C,A,0,14.8800,100,0,165711,251574391,13.2599,100,1,13.9000,15,1,13.0399,2,1,13.9100,100,1,13.0299,100,1,14.0700,2,1,12.7300,100,1,14.1899,100,1,12.7100,100,1,14.4000,100,1,12.5000,700,1,14.5600,900,3,12.4600,200,2,14.5999,700,1,12.4299,700,1,14.6799,1400,2,12.4199,700,1,14.7799,100,1,12.3699,700,1,14.8800,100,1,ARL,296679285
1031,2025-07-17T15:42:16.263966448Z,2025-07-17T15:42:16.263966448Z,10,2,1108,A,A,0,14.7599,100,130,165711,251574391,13.2599,100,1,13.9000,15,1,13.0399,2,1,13.9100,100,1,13.0299,100,1,14.0700,2,1,12.7300,100,1,14.1899,100,1,12.7100,100,1,14.4000,100,1,12.5000,700,1,14.5600,900,3,12.4600,200,2,14.5999,700,1,12.4299,700,1,14.6799,1400,2,12.4199,700,1,14.7599,100,1,12.3699,700,1,14.7799,100,1,ARL,299903169
1032,2025-07-17T15:42:17.356601231Z,2025-07-17T15:42:17.356601231Z,10,2,1108,A,A,0,13.8300,15,130,165484,251593608,13.2599,100,1,13.8300,15,1,13.0399,2,1,13.9000,15,1,13.0299,100,1,13.9100,100,1,12.7300,100,1,14.0700,2,1,12.7100,100,1,14.1899,100,1,12.5000,700,1,14.4000,100,1,12.4600,200,2,14.5600,900,3,12.4299,700,1,14.5999,700,1,12.4199,700,1,14.6799,1400,2,12.3699,700,1,14.7599,100,1,ARL,299923773
1033,2025-07-17T15:42:17.577308779Z,2025-07-17T15:42:17.577308779Z,10,2,1108,C,A,0,13.9100,100,0,165467,251595553,13.2599,100,1,13.8300,15,1,13.0399,2,1,13.9000,15,1,13.0299,100,1,14.0700,2,1,12.7300,100,1,14.1899,100,1,12.7100,100,1,14.4000,100,1,12.5000,700,1,14.5600,900,3,12.4600,200,2,14.5999,700,1,12.4299,700,1,14.6799,1400,2,12.4199,700,1,14.7599,100,1,12.3699,700,1,14.7799,100,1,ARL,299689769
1034,2025-07-17T15:42:17.577308779Z,2025-07-17T15:42:17.577308779Z,10,2,1108,A,A,0,13.8399,100,130,165467,251595553,13.2599,100,1,13.8300,15,1,13.0399,2,1,13.8399,100,1,13.0299,100,1,13.9000,15,1,12.7300,100,1,14.0700,2,1,12.7100,100,1,14.1899,100,1,12.5000,700,1,14.4000,100,1,12.4600,200,2,14.5600,900,3,12.4299,700,1,14.5999,700,1,12.4199,700,1,14.6799,1400,2,12.3699,700,1,14.7599,100,1,ARL,299926781
1035,2025-07-17T15:42:17.578053644Z,2025-07-17T15:42:17.578053644Z,10,2,1108,C,A,0,14.9900,100,0,165531,251595563,13.2599,100,1,13.8300,15,1,13.0399,2,1,13.8399,100,1,13.0299,100,1,13.9000,15,1,12.7300,100,1,14.0700,2,1,12.7100,100,1,14.1899,100,1,12.5000,700,1,14.4000,100,1,12.4600,200,2,14.5600,900,3,12.4299,700,1,14.5999,700,1,12.4199,700,1,14.6799,1400,2,12.3699,700,1,14.7599,100,1,ARL,299689857
1036,2025-07-17T15:42:17.578053644Z,2025-07-17T15:42:17.578053644Z,10,2,1108,A,A,0,14.9100,100,130,165531,251595563,13.2599,100,1,13.8300,15,1,13.0399,2,1,13.8399,100,1,13.0299,100,1,13.9000,15,1,12.7300,100,1,14.0700,2,1,12.7100,100,1,14.1899,100,1,12.5000,700,1,14.4000,100,1,12.4600,200,2,14.5600,900,3,12.4299,700,1,14.5999,700,1,12.4199,700,1,14.6799,1400,2,12.3699,700,1,14.7599,100,1,ARL,299926801
1037,2025-07-17T15:42:17.579177582Z,2025-07-17T15:42:17.579177582Z,10,2,1108,C,A,0,14.7799,100,0,165607,251595571,13.2599,100,1,13.8300,15,1,13.0399,2,1,13.8399,100,1,13.0299,100,1,13.9000,15,1,12.7300,100,1,14.0700,2,1,12.7100,100,1,14.1899,100,1,12.5000,700,1,14.4000,100,1,12.4600,200,2,14.5600,900,3,12.4299,700,1,14.5999,700,1,12.4199,700,1,14.6799,1400,2,12.3699,700,1,14.7599,100,1,ARL,296479285
1038,2025-07-17T15:42:17.579177582Z,2025-07-17T15:42:17.579177582Z,10,2,1108,A,A,0,14.6400,100,130,165607,251595571,13.2599,100,1,13.8300,15,1,13.0399,2,1,13.8399,100,1,13.0299,100,1,13.9000,15,1,12.7300,100,1,14.0700,2,1,12.7100,100,1,14.1899,100,1,12.5000,700,1,14.4000,100,1,12.4600,200,2,14.5600,900,3,12.4299,700,1,14.5999,700,1,12.4199,700,1,14.6400,100,1,12.3699,700,1,14.6799,1400,2,ARL,299926813
1039,2025-07-17T15:42:17.579843331Z,2025-07-17T15:42:17.579843331Z,10,2,1108,C,A,0,14.9600,100,0,165538,251595576,13.2599,100,1,13.8300,15,1,13.0399,2,1,13.8399,100,1,13.0299,100,1,13.9000,15,1,12.7300,100,1,14.0700,2,1,12.7100,100,1,14.1899,100,1,12.5000,700,1,14.4000,100,1,12.4600,200,2,14.5600,900,3,12.4299,700,1,14.5999,700,1,12.4199,700,1,14.6400,100,1,12.3699,700,1,14.6799,1400,2,ARL,296479053
1040,2025-07-17T15:42:17.579843331Z,2025-07-17T15:42:17.579843331Z,10,2,1108,A,A,0,14.8100,100,130,165538,251595576,13.2599,100,1,13.8300,15,1,13.0399,2,1,13.8399,100,1,13.0299,100,1,13.9000,15,1,12.7300,100,1,14.0700,2,1,12.7100,100,1,14.1899,100,1,12.5000,700,1,14.4000,100,1,12.4600,200,2,14.5600,900,3,12.4299,700,1,14.5999,700,1,12.4199,700,1,14.6400,100,1,12.3699,700,1,14.6799,1400,2,ARL,299926849
1041,2025-07-17T15:42:17.579870309Z,2025-07-17T15:42:17.579870309Z,10,2,1108,C,A,0,16.0799,100,0,165484,251595577,13.2599,100,1,13.8300,15,1,13.0399,2,1,13.8399,100,1,13.0299,100,1,13.9000,15,1,12.7300,100,1,14.0700,2,1,12.7100,100,1,14.1899,100,1,12.5000,700,1,14.4000,100,1,12.4600,200,2,14.5600,900,3,12.4299,700,1,14.5999,700,1,12.4199,700,1,14.6400,100,1,12.3699,700,1,14.6799,1400,2,ARL,296480097
1042,2025-07-17T15:42:17.579870309Z,2025-07-17T15:42:17.579870309Z,10,2,1108,A,A,0,15.9199,100,130,165484,251595577,13.2599,100,1,13.8300,15,1,13.0399,2,1,13.8399,100,1,13.0299,100,1,13.9000,15,1,12.7300,100,1,14.0700,2,1,12.7100,100,1,14.1899,100,1,12.5000,700,1,14.4000,100,1,12.4600,200,2,14.5600,900,3,12.4299,700,1,14.5999,700,1,12.4199,700,1,14.6400,100,1,12.3699,700,1,14.6799,1400,2,ARL,299926853
1043,2025-07-17T15:42:17.579895610Z,2025-07-17T15:42:17.579895610Z,10,2,1108,C,A,0,14.9600,100,0,165487,251595578,13.2599,100,1,13.8300,15,1,13.0399,2,1,13.8399,100,1,13.0299,100,1,13.9000,15,1,12.7300,100,1,14.0700,2,1,12.7100,100,1,14.1899,100,1,12.5000,700,1,14.4000,100,1,12.4600,200,2,14.5600,900,3,12.4299,700,1,14.5999,700,1,12.4199,700,1,14.6400,100,1,12.3699,700,1,14.6799,1400,2,ARL,296482509
1044,2025-07-17T15:42:17.579895610Z,2025-07-17T15:42:17.579895610Z,10,2,1108,A,A,0,14.8100,100,130,165487,251595578,13.2599,100,1,13.8300,15,1,13.0399,2,1,13.8399,100,1,13.0299,100,1,13.9000,15,1,12.7300,100,1,14.0700,2,1,12.7100,100,1,14.1899,100,1,12.5000,700,1,14.4000,100,1,12.4600,200,2,14.5600,900,3,12.4299,700,1,14.5999,700,1,12.4199,700,1,14.6400,100,1,12.3699,700,1,14.6799,1400,2,ARL,299926857
1045,2025-07-17T15:42:17.579928136Z,2025-07-17T15:42:17.579928136Z,10,2,1108,C,A,0,17.7600,100,0,165399,251595580,13.2599,100,1,13.8300,15,1,13.0399,2,1,13.8399,100,1,13.0299,100,1,13.9000,15,1,12.7300,100,1,14.0700,2,1,12.7100,100,1,14.1899,100,1,12.5000,700,1,14.4000,100,1,12.4600,200,2,14.5600,900,3,12.4299,700,1,14.5999,700,1,12.4199,700,1,14.6400,100,1,12.3699,700,1,14.6799,1400,2,ARL,296479893
1046,2025-07-17T15:42:17.579928136Z,2025-07-17T15:42:17.579928136Z,10,2,1108,A,A,0,17.5799,100,130,165399,251595580,13.2599,100,1,13.8300,15,1,13.0399,2,1,13.8399,100,1,13.0299,100,1,13.9000,15,1,12.7300,100,1,14.0700,2,1,12.7100,100,1,14.1899,100,1,12.5000,700,1,14.4000,100,1,12.4600,200,2,14.5600,900,3,12.4299,700,1,14.5999,700,1,12.4199,700,1,14.6400,100,1,12.3699,700,1,14.6799,1400,2,ARL,299926861
1047,2025-07-17T15:42:17.589098227Z,2025-07-17T15:42:17.589098227Z,10,2,1108,C,A,0,14.1899,100,130,165323,251595691,13.2599,100,1,13.8300,15,1,13.0399,2,1,13.8399,100,1,13.0299,100,1,13.9000,15,1,12.7300,100,1,14.0700,2,1,12.7100,100,1,14.4000,100,1,12.5000,700,1,14.5600,900,3,12.4600,200,2,14.5999,700,1,12.4299,700,1,14.6400,100,1,12.4199,700,1,14.6799,1400,2,12.3699,700,1,14.7599,100,1,ARL,299690593
1048,2025-07-17T15:42:17.589151325Z,2025-07-17T15:42:17.589151325Z,10,2,1108,A,A,0,14.1199,100,130,165586,251595692,13.2599,100,1,13.8300,15,1,13.0399,2,1,13.8399,100,1,13.0299,100,1,13.9000,15,1,12.7300,100,1,14.0700,2,1,12.7100,100,1,14.1199,100,1,12.5000,700,1,14.4000,100,1,12.4600,200,2,14.5600,900,3,12.4299,700,1,14.5999,700,1,12.4199,700,1,14.6400,100,1,12.3699,700,1,14.6799,1400,2,ARL,299926965
1049,2025-07-17T15:42:18.398054465Z,2025-07-17T15:42:18.398054465Z,10,2,1108,C,A,0,14.8800,100,0,165535,251612478,13.2599,100,1,13.8300,15,1,13.0399,2,1,13.8399,100,1,13.0299,100,1,13.9000,15,1,12.7300,100,1,14.0700,2,1,12.7100,100,1,14.1199,100,1,12.5000,700,1,14.4000,100,1,12.4600,200,2,14.5600,900,3,12.4299,700,1,14.5999,700,1,12.4199,700,1,14.6400,100,1,12.3699,700,1,14.6799,1400,2,ARL,296679277
1050,2025-07-17T15:42:18.398054465Z,2025-07-17T15:42:18.398054465Z,10,2,1108,A,A,0,14.7300,100,130,165535,251612478,13.2599,100,1,13.8300,15,1,13.0399,2,1,13.8399,100,1,13.0299,100,1,13.9000,15,1,12.7300,100,1,14.0700,2,1,12.7100,100,1,14.1199,100,1,12.5000,700,1,14.4000,100,1,12.4600,200,2,14.5600,900,3,12.4299,700,1,14.5999,700,1,12.4199,700,1,14.6400,100,1,12.3699,700,1,14.6799,1400,2,ARL,299945073
1051,2025-07-17T15:42:21.517706139Z,2025-07-17T15:42:21.517706139Z,10,2,1108,C,A,0,13.9000,15,130,165575,251668179,13.2599,100,1,13.8300,15,1,13.0399,2,1,13.8399,100,1,13.0299,100,1,14.0700,2,1,12.7300,100,1,14.1199,100,1,12.7100,100,1,14.4000,100,1,12.5000,700,1,14.5600,900,3,12.4600,200,2,14.5999,700,1,12.4299,700,1,14.6400,100,1,12.4199,700,1,14.6799,1400,2,12.3699,700,1,14.7300,100,1,ARL,299689753
1052,2025-07-17T15:42:22.522578675Z,2025-07-17T15:42:22.522578675Z,10,2,1108,A,A,0,13.7899,15,130,165567,251690950,13.2599,100,1,13.7899,15,1,13.0399,2,1,13.8300,15,1,13.0299,100,1,13.8399,100,1,12.7300,100,1,14.0700,2,1,12.7100,100,1,14.1199,100,1,12.5000,700,1,14.4000,100,1,12.4600,200,2,14.5600,900,3,12.4299,700,1,14.5999,700,1,12.4199,700,1,14.6400,100,1,12.3699,700,1,14.6799,1400,2,ARL,300042293
1053,2025-07-17T15:42:22.533515955Z,2025-07-17T15:42:22.533515955Z,10,2,1108,A,A,0,13.8200,100,130,165524,251691033,13.2599,100,1,13.7899,15,1,13.0399,2,1,13.8200,100,1,13.0299,100,1,13.8300,15,1,12.7300,100,1,13.8399,100,1,12.7100,100,1,14.0700,2,1,12.5000,700,1,14.1199,100,1,12.4600,200,2,14.4000,100,1,12.4299,700,1,14.5600,900,3,12.4199,700,1,14.5999,700,1,12.3699,700,1,14.6400,100,1,ARL,300042385
1054,2025-07-17T15:42:23.490079821Z,2025-07-17T15:42:23.490079821Z,10,2,1108,C,A,0,13.8399,100,0,167300,251710173,13.2599,100,1,13.7899,15,1,13.0399,2,1,13.8200,100,1,13.0299,100,1,13.8300,15,1,12.7300,100,1,14.0700,2,1,12.7100,100,1,14.1199,100,1,12.5000,700,1,14.4000,100,1,12.4600,200,2,14.5600,900,3,12.4299,700,1,14.5999,700,1,12.4199,700,1,14.6400,100,1,12.3699,700,1,14.6799,1400,2,ARL,299926781
1055,2025-07-17T15:42:23.490079821Z,2025-07-17T15:42:23.490079821Z,10,2,1108,A,A,0,13.8000,100,128,167300,251710173,13.2599,100,1,13.7899,15,1,13.0399,2,1,13.8000,100,1,13.0299,100,1,13.8200,100,1,12.7300,100,1,13.8300,15,1,12.7100,100,1,14.0700,2,1,12.5000,700,1,14.1199,100,1,12.4600,200,2,14.4000,100,1,12.4299,700,1,14.5600,900,3,12.4199,700,1,14.5999,700,1,12.3699,700,1,14.6400,100,1,ARL,300061581
1056,2025-07-17T15:42:23.491285065Z,2025-07-17T15:42:23.491285065Z,10,2,1108,C,A,0,14.9100,100,0,166303,251710647,13.2599,100,1,13.7899,15,1,13.0399,2,1,13.8000,100,1,13.0299,100,1,13.8200,100,1,12.7300,100,1,13.8300,15,1,12.7100,100,1,14.0700,2,1,12.5000,700,1,14.1199,100,1,12.4600,200,2,14.4000,100,1,12.4299,700,1,14.5600,900,3,12.4199,700,1,14.5999,700,1,12.3699,700,1,14.6400,100,1,ARL,299926801
1057,2025-07-17T15:42:23.491285065Z,2025-07-17T15:42:23.491285065Z,10,2,1108,A,A,0,14.8699,100,128,166303,251710647,13.2599,100,1,13.7899,15,1,13.0399,2,1,13.8000,100,1,13.0299,100,1,13.8200,100,1,12.7300,100,1,13.8300,15,1,12.7100,100,1,14.0700,2,1,12.5000,700,1,14.1199,100,1,12.4600,200,2,14.4000,100,1,12.4299,700,1,14.5600,900,3,12.4199,700,1,14.5999,700,1,12.3699,700,1,14.6400,100,1,ARL,300061989
1058,2025-07-17T15:42:23.588899941Z,2025-07-17T15:42:23.588899941Z,10,2,1108,C,A,0,13.7899,15,130,165213,251718746,13.2599,100,1,13.8000,100,1,13.0399,2,1,13.8200,100,1,13.0299,100,1,13.8300,15,1,12.7300,100,1,14.0700,2,1,12.7100,100,1,14.1199,100,1,12.5000,700,1,14.4000,100,1,12.4600,200,2,14.5600,900,3,12.4299,700,1,14.5999,700,1,12.4199,700,1,14.6400,100,1,12.3699,700,1,14.6799,1400,2,ARL,300042293
1059,2025-07-17T15:42:23.589055082Z,2025-07-17T15:42:23.589055082Z,10,2,1108,C,A,0,13.8300,15,130,165696,251718767,13.2599,100,1,13.8000,100,1,13.0399,2,1,13.8200,100,1,13.0299,100,1,14.0700,2,1,12.7300,100,1,14.1199,100,1,12.7100,100,1,14.4000,100,1,12.5000,700,1,14.5600,900,3,12.4600,200,2,14.5999,700,1,12.4299,700,1,14.6400,100,1,12.4199,700,1,14.6799,1400,2,12.3699,700,1,14.7300,100,1,ARL,299923773
1060,2025-07-17T15:42:34.003544527Z,2025-07-17T15:42:34.003544527Z,10,2,1108,C,A,0,13.8000,100,130,165554,251901273,13.2599,100,1,13.8200,100,1,13.0399,2,1,14.0700,2,1,13.0299,100,1,14.1199,100,1,12.7300,100,1,14.4000,100,1,12.7100,100,1,14.5600,900,3,12.5000,700,1,14.5999,700,1,12.4600,200,2,14.6400,100,1,12.4299,700,1,14.6799,1400,2,12.4199,700,1,14.7300,100,1,12.3699,700,1,14.7599,100,1,ARL,300061581
1061,2025-07-17T15:42:34.003783950Z,2025-07-17T15:42:34.003783950Z,10,2,1108,C,A,0,13.8200,100,130,165390,251901275,13.2599,100,1,14.0700,2,1,13.0399,2,1,14.1199,100,1,13.0299,100,1,14.4000,100,1,12.7300,100,1,14.5600,900,3,12.7100,100,1,14.5999,700,1,12.5000,700,1,14.6400,100,1,12.4600,200,2,14.6799,1400,2,12.4299,700,1,14.7300,100,1,12.4199,700,1,14.7599,100,1,12.3699,700,1,14.8100,200,2,ARL,300042385
1062,2025-07-17T15:42:34.004059450Z,2025-07-17T15:42:34.004059450Z,10,2,1108,C,A,0,14.7300,100,0,165730,251901280,13.2599,100,1,14.0700,2,1,13.0399,2,1,14.1199,100,1,13.0299,100,1,14.4000,100,1,12.7300,100,1,14.5600,900,3,12.7100,100,1,14.5999,700,1,12.5000,700,1,14.6400,100,1,12.4600,200,2,14.6799,1400,2,12.4299,700,1,14.7599,100,1,12.4199,700,1,14.8100,200,2,12.3699,700,1,14.8699,100,1,ARL,299945073
1063,2025-07-17T15:42:34.004059450Z,2025-07-17T15:42:34.004059450Z,10,2,1108,A,A,0,14.8800,100,130,165730,251901280,13.2599,100,1,14.0700,2,1,13.0399,2,1,14.1199,100,1,13.0299,100,1,14.4000,100,1,12.7300,100,1,14.5600,900,3,12.7100,100,1,14.5999,700,1,12.5000,700,1,14.6400,100,1,12.4600,200,2,14.6799,1400,2,12.4299,700,1,14.7599,100,1,12.4199,700,1,14.8100,200,2,12.3699,700,1,14.8699,100,1,ARL,300280745
1064,2025-07-17T15:42:34.004506043Z,2025-07-17T15:42:34.004506043Z,10,2,1108,C,A,0,14.8699,100,0,165609,251901285,13.2599,100,1,14.0700,2,1,13.0399,2,1,14.1199,100,1,13.0299,100,1,14.4000,100,1,12.7300,100,1,14.5600,900,3,12.7100,100,1,14.5999,700,1,12.5000,700,1,14.6400,100,1,12.4600,200,2,14.6799,1400,2,12.4299,700,1,14.7599,100,1,12.4199,700,1,14.8100,200,2,12.3699,700,1,14.8800,100,1,ARL,300061989
1065,2025-07-17T15:42:34.004506043Z,2025-07-17T15:42:34.004506043Z,10,2,1108,A,A,0,15.0600,100,130,165609,251901285,13.2599,100,1,14.0700,2,1,13.0399,2,1,14.1199,100,1,13.0299,100,1,14.4000,100,1,12.7300,100,1,14.5600,900,3,12.7100,100,1,14.5999,700,1,12.5000,700,1,14.6400,100,1,12.4600,200,2,14.6799,1400,2,12.4299,700,1,14.7599,100,1,12.4199,700,1,14.8100,200,2,12.3699,700,1,14.8800,100,1,ARL,300280757
1066,2025-07-17T15:42:34.004512153Z,2025-07-17T15:42:34.004512153Z,10,2,1108,C,A,0,14.7599,100,0,165633,251901286,13.2599,100,1,14.0700,2,1,13.0399,2,1,14.1199,100,1,13.0299,100,1,14.4000,100,1,12.7300,100,1,14.5600,900,3,12.7100,100,1,14.5999,700,1,12.5000,700,1,14.6400,100,1,12.4600,200,2,14.6799,1400,2,12.4299,700,1,14.8100,200,2,12.4199,700,1,14.8800,100,1,12.3699,700,1,15.0600,100,1,ARL,299903169
1067,2025-07-17T15:42:34.004512153Z,2025-07-17T15:42:34.004512153Z,10,2,1108,A,A,0,14.8800,100,130,165633,251901286,13.2599,100,1,14.0700,2,1,13.0399,2,1,14.1199,100,1,13.0299,100,1,14.4000,100,1,12.7300,100,1,14.5600,900,3,12.7100,100,1,14.5999,700,1,12.5000,700,1,14.6400,100,1,12.4600,200,2,14.6799,1400,2,12.4299,700,1,14.8100,200,2,12.4199,700,1,14.8800,200,2,12.3699,700,1,15.0600,100,1,ARL,300280761
1068,2025-07-17T15:42:34.005409139Z,2025-07-17T15:42:34.005409139Z,10,2,1108,C,A,0,15.9199,100,0,165621,251901302,13.2599,100,1,14.0700,2,1,13.0399,2,1,14.1199,100,1,13.0299,100,1,14.4000,100,1,12.7300,100,1,14.5600,900,3,12.7100,100,1,14.5999,700,1,12.5000,700,1,14.6400,100,1,12.4600,200,2,14.6799,1400,2,12.4299,700,1,14.8100,200,2,12.4199,700,1,14.8800,200,2,12.3699,700,1,15.0600,100,1,ARL,299926853
1069,2025-07-17T15:42:34.005409139Z,2025-07-17T15:42:34.005409139Z,10,2,1108,A,A,0,16.0799,100,130,165621,251901302,13.2599,100,1,14.0700,2,1,13.0399,2,1,14.1199,100,1,13.0299,100,1,14.4000,100,1,12.7300,100,1,14.5600,900,3,12.7100,100,1,14.5999,700,1,12.5000,700,1,14.6400,100,1,12.4600,200,2,14.6799,1400,2,12.4299,700,1,14.8100,200,2,12.4199,700,1,14.8800,200,2,12.3699,700,1,15.0600,100,1,ARL,300280773
1070,2025-07-17T15:42:34.005667449Z,2025-07-17T15:42:34.005667449Z,10,2,1108,C,A,0,14.8100,100,0,165477,251901305,13.2599,100,1,14.0700,2,1,13.0399,2,1,14.1199,100,1,13.0299,100,1,14.4000,100,1,12.7300,100,1,14.5600,900,3,12.7100,100,1,14.5999,700,1,12.5000,700,1,14.6400,100,1,12.4600,200,2,14.6799,1400,2,12.4299,700,1,14.8100,100,1,12.4199,700,1,14.8800,200,2,12.3699,700,1,15.0600,100,1,ARL,299926849
1071,2025-07-17T15:42:34.005667449Z,2025-07-17T15:42:34.005667449Z,10,2,1108,A,A,0,14.9600,100,130,165477,251901305,13.2599,100,1,14.0700,2,1,13.0399,2,1,14.1199,100,1,13.0299,100,1,14.4000,100,1,12.7300,100,1,14.5600,900,3,12.7100,100,1,14.5999,700,1,12.5000,700,1,14.6400,100,1,12.4600,200,2,14.6799,1400,2,12.4299,700,1,14.8100,100,1,12.4199,700,1,14.8800,200,2,12.3699,700,1,14.9600,100,1,ARL,300280777
1072,2025-07-17T15:42:34.006665512Z,2025-07-17T15:42:34.006665512Z,10,2,1108,C,A,0,17.5799,100,0,165512,251901319,13.2599,100,1,14.0700,2,1,13.0399,2,1,14.1199,100,1,13.0299,100,1,14.4000,100,1,12.7300,100,1,14.5600,900,3,12.7100,100,1,14.5999,700,1,12.5000,700,1,14.6400,100,1,12.4600,200,2,14.6799,1400,2,12.4299,700,1,14.8100,100,1,12.4199,700,1,14.8800,200,2,12.3699,700,1,14.9600,100,1,ARL,299926861
1073,2025-07-17T15:42:34.006665512Z,2025-07-17T15:42:34.006665512Z,10,2,1108,A,A,0,17.7600,100,130,165512,251901319,13.2599,100,1,14.0700,2,1,13.0399,2,1,14.1199,100,1,13.0299,100,1,14.4000,100,1,12.7300,100,1,14.5600,900,3,12.7100,100,1,14.5999,700,1,12.5000,700,1,14.6400,100,1,12.4600,200,2,14.6799,1400,2,12.4299,700,1,14.8100,100,1,12.4199,700,1,14.8800,200,2,12.3699,700,1,14.9600,100,1,ARL,300280797
1074,2025-07-17T15:42:34.007743383Z,2025-07-17T15:42:34.007743383Z,10,2,1108,C,A,0,14.6400,100,130,165295,251901330,13.2599,100,1,14.0700,2,1,13.0399,2,1,14.1199,100,1,13.0299,100,1,14.4000,100,1,12.7300,100,1,14.5600,900,3,12.7100,100,1,14.5999,700,1,12.5000,700,1,14.6799,1400,2,12.4600,200,2,14.8100,100,1,12.4299,700,1,14.8800,200,2,12.4199,700,1,14.9600,100,1,12.3699,700,1,15.0600,100,1,ARL,299926813
1075,2025-07-17T15:42:34.007907269Z,2025-07-17T15:42:34.007907269Z,10,2,1108,A,A,0,14.7799,100,130,165394,251901331,13.2599,100,1,14.0700,2,1,13.0399,2,1,14.1199,100,1,13.0299,100,1,14.4000,100,1,12.7300,100,1,14.5600,900,3,12.7100,100,1,14.5999,700,1,12.5000,700,1,14.6799,1400,2,12.4600,200,2,14.7799,100,1,12.4299,700,1,14.8100,100,1,12.4199,700,1,14.8800,200,2,12.3699,700,1,14.9600,100,1,ARL,300280825
1076,2025-07-17T15:42:34.010031518Z,2025-07-17T15:42:34.010031518Z,10,2,1108,C,A,0,14.1199,100,130,165313,251901352,13.2599,100,1,14.0700,2,1,13.0399,2,1,14.4000,100,1,13.0299,100,1,14.5600,900,3,12.7300,100,1,14.5999,700,1,12.7100,100,1,14.6799,1400,2,12.5000,700,1,14.7799,100,1,12.4600,200,2,14.8100,100,1,12.4299,700,1,14.8800,200,2,12.4199,700,1,14.9600,100,1,12.3699,700,1,15.0600,100,1,ARL,299926965
1077,2025-07-17T15:42:34.010083409Z,2025-07-17T15:42:34.010083409Z,10,2,1108,A,A,0,14.2599,100,130,165433,251901353,13.2599,100,1,14.0700,2,1,13.0399,2,1,14.2599,100,1,13.0299,100,1,14.4000,100,1,12.7300,100,1,14.5600,900,3,12.7100,100,1,14.5999,700,1,12.5000,700,1,14.6799,1400,2,12.4600,200,2,14.7799,100,1,12.4299,700,1,14.8100,100,1,12.4199,700,1,14.8800,200,2,12.3699,700,1,14.9600,100,1,ARL,300280857
1078,2025-07-17T15:42:34.010406771Z,2025-07-17T15:42:34.010406771Z,10,2,1108,C,A,0,14.8100,100,0,165599,251901355,13.2599,100,1,14.0700,2,1,13.0399,2,1,14.2599,100,1,13.0299,100,1,14.4000,100,1,12.7300,100,1,14.5600,900,3,12.7100,100,1,14.5999,700,1,12.5000,700,1,14.6799,1400,2,12.4600,200,2,14.7799,100,1,12.4299,700,1,14.8800,200,2,12.4199,700,1,14.9600,100,1,12.3699,700,1,15.0600,100,1,ARL,299926857
1079,2025-07-17T15:42:34.010406771Z,2025-07-17T15:42:34.010406771Z,10,2,1108,A,A,0,14.9600,100,130,165599,251901355,13.2599,100,1,14.0700,2,1,13.0399,2,1,14.2599,100,1,13.0299,100,1,14.4000,100,1,12.7300,100,1,14.5600,900,3,12.7100,100,1,14.5999,700,1,12.5000,700,1,14.6799,1400,2,12.4600,200,2,14.7799,100,1,12.4299,700,1,14.8800,200,2,12.4199,700,1,14.9600,200,2,12.3699,700,1,15.0600,100,1,ARL,300280873
1080,2025-07-17T15:42:34.951932909Z,2025-07-17T15:42:34.951932909Z,10,2,1108,A,A,0,14.0800,100,130,165118,251912292,13.2599,100,1,14.0700,2,1,13.0399,2,1,14.0800,100,1,13.0299,100,1,14.2599,100,1,12.7300,100,1,14.4000,100,1,12.7100,100,1,14.5600,900,3,12.5000,700,1,14.5999,700,1,12.4600,200,2,14.6799,1400,2,12.4299,700,1,14.7799,100,1,12.4199,700,1,14.8800,200,2,12.3699,700,1,14.9600,200,2,ARL,300294885
1081,2025-07-17T15:43:21.513673603Z,2025-07-17T15:43:21.513673603Z,10,2,1108,A,A,0,13.9199,15,130,165346,252622568,13.2599,100,1,13.9199,15,1,13.0399,2,1,14.0700,2,1,13.0299,100,1,14.0800,100,1,12.7300,100,1,14.2599,100,1,12.7100,100,1,14.4000,100,1,12.5000,700,1,14.5600,900,3,12.4600,200,2,14.5999,700,1,12.4299,700,1,14.6799,1400,2,12.4199,700,1,14.7799,100,1,12.3699,700,1,14.8800,200,2,ARL,301218889
1082,2025-07-17T15:43:24.878071152Z,2025-07-17T15:43:24.878071152Z,10,2,1108,C,A,0,14.0800,100,0,165608,252681819,13.2599,100,1,13.9199,15,1,13.0399,2,1,14.0700,2,1,13.0299,100,1,14.2599,100,1,12.7300,100,1,14.4000,100,1,12.7100,100,1,14.5600,900,3,12.5000,700,1,14.5999,700,1,12.4600,200,2,14.6799,1400,2,12.4299,700,1,14.7799,100,1,12.4199,700,1,14.8800,200,2,12.3699,700,1,14.9600,200,2,ARL,300294885
1083,2025-07-17T15:43:24.878071152Z,2025-07-17T15:43:24.878071152Z,10,2,1108,A,A,0,13.9299,100,130,165608,252681819,13.2599,100,1,13.9199,15,1,13.0399,2,1,13.9299,100,1,13.0299,100,1,14.0700,2,1,12.7300,100,1,14.2599,100,1,12.7100,100,1,14.4000,100,1,12.5000,700,1,14.5600,900,3,12.4600,200,2,14.5999,700,1,12.4299,700,1,14.6799,1400,2,12.4199,700,1,14.7799,100,1,12.3699,700,1,14.8800,200,2,ARL,301295841
1084,2025-07-17T15:43:24.878837670Z,2025-07-17T15:43:24.878837670Z,10,2,1108,C,A,0,15.0600,100,0,165773,252681832,13.2599,100,1,13.9199,15,1,13.0399,2,1,13.9299,100,1,13.0299,100,1,14.0700,2,1,12.7300,100,1,14.2599,100,1,12.7100,100,1,14.4000,100,1,12.5000,700,1,14.5600,900,3,12.4600,200,2,14.5999,700,1,12.4299,700,1,14.6799,1400,2,12.4199,700,1,14.7799,100,1,12.3699,700,1,14.8800,200,2,ARL,300280757
1085,2025-07-17T15:43:24.878837670Z,2025-07-17T15:43:24.878837670Z,10,2,1108,A,A,0,15.0099,100,130,165773,252681832,13.2599,100,1,13.9199,15,1,13.0399,2,1,13.9299,100,1,13.0299,100,1,14.0700,2,1,12.7300,100,1,14.2599,100,1,12.7100,100,1,14.4000,100,1,12.5000,700,1,14.5600,900,3,12.4600,200,2,14.5999,700,1,12.4299,700,1,14.6799,1400,2,12.4199,700,1,14.7799,100,1,12.3699,700,1,14.8800,200,2,ARL,301295873
1086,2025-07-17T15:43:32.780206927Z,2025-07-17T15:43:32.780206927Z,10,2,1108,A,A,0,13.8800,15,130,165485,252800884,13.2599,100,1,13.8800,15,1,13.0399,2,1,13.9199,15,1,13.0299,100,1,13.9299,100,1,12.7300,100,1,14.0700,2,1,12.7100,100,1,14.2599,100,1,12.5000,700,1,14.4000,100,1,12.4600,200,2,14.5600,900,3,12.4299,700,1,14.5999,700,1,12.4199,700,1,14.6799,1400,2,12.3699,700,1,14.7799,100,1,ARL,301451057
1087,2025-07-17T15:43:32.780474141Z,2025-07-17T15:43:32.780474141Z,10,2,1108,C,A,0,13.9299,100,0,165478,252800887,13.2599,100,1,13.8800,15,1,13.0399,2,1,13.9199,15,1,13.0299,100,1,14.0700,2,1,12.7300,100,1,14.2599,100,1,12.7100,100,1,14.4000,100,1,12.5000,700,1,14.5600,900,3,12.4600,200,2,14.5999,700,1,12.4299,700,1,14.6799,1400,2,12.4199,700,1,14.7799,100,1,12.3699,700,1,14.8800,200,2,ARL,301295841
1088,2025-07-17T15:43:32.780474141Z,2025-07-17T15:43:32.780474141Z,10,2,1108,A,A,0,13.8900,100,130,165478,252800887,13.2599,100,1,13.8800,15,1,13.0399,2,1,13.8900,100,1,13.0299,100,1,13.9199,15,1,12.7300,100,1,14.0700,2,1,12.7100,100,1,14.2599,100,1,12.5000,700,1,14.4000,100,1,12.4600,200,2,14.5600,900,3,12.4299,700,1,14.5999,700,1,12.4199,700,1,14.6799,1400,2,12.3699,700,1,14.7799,100,1,ARL,301451061
1089,2025-07-17T15:43:32.781216589Z,2025-07-17T15:43:32.781216589Z,10,2,1108,C,A,0,15.0099,100,0,165573,252800892,13.2599,100,1,13.8800,15,1,13.0399,2,1,13.8900,100,1,13.0299,100,1,13.9199,15,1,12.7300,100,1,14.0700,2,1,12.7100,100,1,14.2599,100,1,12.5000,700,1,14.4000,100,1,12.4600,200,2,14.5600,900,3,12.4299,700,1,14.5999,700,1,12.4199,700,1,14.6799,1400,2,12.3699,700,1,14.7799,100,1,ARL,301295873
1090,2025-07-17T15:43:32.781216589Z,2025-07-17T15:43:32.781216589Z,10,2,1108,A,A,0,14.9700,100,130,165573,252800892,13.2599,100,1,13.8800,15,1,13.0399,2,1,13.8900,100,1,13.0299,100,1,13.9199,15,1,12.7300,100,1,14.0700,2,1,12.7100,100,1,14.2599,100,1,12.5000,700,1,14.4000,100,1,12.4600,200,2,14.5600,900,3,12.4299,700,1,14.5999,700,1,12.4199,700,1,14.6799,1400,2,12.3699,700,1,14.7799,100,1,ARL,301451077
1091,2025-07-17T15:43:32.791954053Z,2025-07-17T15:43:32.791954053Z,10,2,1108,C,A,0,14.2599,100,130,165645,252801681,13.2599,100,1,13.8800,15,1,13.0399,2,1,13.8900,100,1,13.0299,100,1,13.9199,15,1,12.7300,100,1,14.0700,2,1,12.7100,100,1,14.4000,100,1,12.5000,700,1,14.5600,900,3,12.4600,200,2,14.5999,700,1,12.4299,700,1,14.6799,1400,2,12.4199,700,1,14.7799,100,1,12.3699,700,1,14.8800,200,2,ARL,300280857
1092,2025-07-17T15:43:32.792008881Z,2025-07-17T15:43:32.792008881Z,10,2,1108,A,A,0,14.1699,100,130,165736,252801689,13.2599,100,1,13.8800,15,1,13.0399,2,1,13.8900,100,1,13.0299,100,1,13.9199,15,1,12.7300,100,1,14.0700,2,1,12.7100,100,1,14.1699,100,1,12.5000,700,1,14.4000,100,1,12.4600,200,2,14.5600,900,3,12.4299,700,1,14.5999,700,1,12.4199,700,1,14.6799,1400,2,12.3699,700,1,14.7799,100,1,ARL,301452785
1093,2025-07-17T15:43:44.004667259Z,2025-07-17T15:43:44.004667259Z,10,2,1108,C,A,0,13.9199,15,130,165382,252977583,13.2599,100,1,13.8800,15,1,13.0399,2,1,13.8900,100,1,13.0299,100,1,14.0700,2,1,12.7300,100,1,14.1699,100,1,12.7100,100,1,14.4000,100,1,12.5000,700,1,14.5600,900,3,12.4600,200,2,14.5999,700,1,12.4299,700,1,14.6799,1400,2,12.4199,700,1,14.7799,100,1,12.3699,700,1,14.8800,200,2,ARL,301218889
1094,2025-07-17T15:43:44.005025587Z,2025-07-17T15:43:44.005025587Z,10,2,1108,C,A,0,14.8800,100,0,165524,252977592,13.2599,100,1,13.8800,15,1,13.0399,2,1,13.8900,100,1,13.0299,100,1,14.0700,2,1,12.7300,100,1,14.1699,100,1,12.7100,100,1,14.4000,100,1,12.5000,700,1,14.5600,900,3,12.4600,200,2,14.5999,700,1,12.4299,700,1,14.6799,1400,2,12.4199,700,1,14.7799,100,1,12.3699,700,1,14.8800,100,1,ARL,300280761
1095,2025-07-17T15:43:44.005025587Z,2025-07-17T15:43:44.005025587Z,10,2,1108,A,A,0,14.7699,100,130,165524,252977592,13.2599,100,1,13.8800,15,1,13.0399,2,1,13.8900,100,1,13.0299,100,1,14.0700,2,1,12.7300,100,1,14.1699,100,1,12.7100,100,1,14.4000,100,1,12.5000,700,1,14.5600,900,3,12.4600,200,2,14.5999,700,1,12.4299,700,1,14.6799,1400,2,12.4199,700,1,14.7699,100,1,12.3699,700,1,14.7799,100,1,ARL,301671709
1096,2025-07-17T15:43:44.005147707Z,2025-07-17T15:43:44.005147707Z,10,2,1108,C,A,0,14.8800,100,0,165364,252977595,13.2599,100,1,13.8800,15,1,13.0399,2,1,13.8900,100,1,13.0299,100,1,14.0700,2,1,12.7300,100,1,14.1699,100,1,12.7100,100,1,14.4000,100,1,12.5000,700,1,14.5600,900,3,12.4600,200,2,14.5999,700,1,12.4299,700,1,14.6799,1400,2,12.4199,700,1,14.7699,100,1,12.3699,700,1,14.7799,100,1,ARL,300280745
1097,2025-07-17T15:43:44.005147707Z,2025-07-17T15:43:44.005147707Z,10,2,1108,A,A,0,14.7699,100,130,165364,252977595,13.2599,100,1,13.8800,15,1,13.0399,2,1,13.8900,100,1,13.0299,100,1,14.0700,2,1,12.7300,100,1,14.1699,100,1,12.7100,100,1,14.4000,100,1,12.5000,700,1,14.5600,900,3,12.4600,200,2,14.5999,700,1,12.4299,700,1,14.6799,1400,2,12.4199,700,1,14.7699,200,2,12.3699,700,1,14.7799,100,1,ARL,301671713
1098,2025-07-17T15:43:48.787332399Z,2025-07-17T15:43:48.787332399Z,10,2,1108,A,A,0,13.8300,15,130,165265,253027890,13.2599,100,1,13.8300,15,1,13.0399,2,1,13.8800,15,1,13.0299,100,1,13.8900,100,1,12.7300,100,1,14.0700,2,1,12.7100,100,1,14.1699,100,1,12.5000,700,1,14.4000,100,1,12.4600,200,2,14.5600,900,3,12.4299,700,1,14.5999,700,1,12.4199,700,1,14.6799,1400,2,12.3699,700,1,14.7699,200,2,ARL,301746941
1099,2025-07-17T15:43:48.787601640Z,2025-07-17T15:43:48.787601640Z,10,2,1108,C,A,0,13.8900,100,0,165267,253027924,13.2599,100,1,13.8300,15,1,13.0399,2,1,13.8800,15,1,13.0299,100,1,14.0700,2,1,12.7300,100,1,14.1699,100,1,12.7100,100,1,14.4000,100,1,12.5000,700,1,14.5600,900,3,12.4600,200,2,14.5999,700,1,12.4299,700,1,14.6799,1400,2,12.4199,700,1,14.7699,200,2,12.3699,700,1,14.7799,100,1,ARL,301451061
1100,2025-07-17T15:43:48.787601640Z,2025-07-17T15:43:48.787601640Z,10,2,1108,A,A,0,13.8399,100,130,165267,253027924,13.2599,100,1,13.8300,15,1,13.0399,2,1,13.8399,100,1,13.0299,100,1,13.8800,15,1,12.7300,100,1,14.0700,2,1,12.7100,100,1,14.1699,100,1,12.5000,700,1,14.4000,100,1,12.4600,200,2,14.5600,900,3,12.4299,700,1,14.5999,700,1,12.4199,700,1,14.6799,1400,2,12.3699,700,1,14.7699,200,2,ARL,301746949
1101,2025-07-17T15:43:48.788345787Z,2025-07-17T15:43:48.788345787Z,10,2,1108,C,A,0,14.9700,100,0,166235,253027959,13.2599,100,1,13.8300,15,1,13.0399,2,1,13.8399,100,1,13.0299,100,1,13.8800,15,1,12.7300,100,1,14.0700,2,1,12.7100,100,1,14.1699,100,1,12.5000,700,1,14.4000,100,1,12.4600,200,2,14.5600,900,3,12.4299,700,1,14.5999,700,1,12.4199,700,1,14.6799,1400,2,12.3699,700,1,14.7699,200,2,ARL,301451077
1102,2025-07-17T15:43:48.788345787Z,2025-07-17T15:43:48.788345787Z,10,2,1108,A,A,0,14.9100,100,128,166235,253027959,13.2599,100,1,13.8300,15,1,13.0399,2,1,13.8399,100,1,13.0299,100,1,13.8800,15,1,12.7300,100,1,14.0700,2,1,12.7100,100,1,14.1699,100,1,12.5000,700,1,14.4000,100,1,12.4600,200,2,14.5600,900,3,12.4299,700,1,14.5999,700,1,12.4199,700,1,14.6799,1400,2,12.3699,700,1,14.7699,200,2,ARL,301746969
1103,2025-07-17T15:43:48.790408191Z,2025-07-17T15:43:48.790408191Z,10,2,1108,C,A,0,14.9600,100,0,165629,253028026,13.2599,100,1,13.8300,15,1,13.0399,2,1,13.8399,100,1,13.0299,100,1,13.8800,15,1,12.7300,100,1,14.0700,2,1,12.7100,100,1,14.1699,100,1,12.5000,700,1,14.4000,100,1,12.4600,200,2,14.5600,900,3,12.4299,700,1,14.5999,700,1,12.4199,700,1,14.6799,1400,2,12.3699,700,1,14.7699,200,2,ARL,300280777
1104,2025-07-17T15:43:48.790408191Z,2025-07-17T15:43:48.790408191Z,10,2,1108,A,A,0,14.8100,100,130,165629,253028026,13.2599,100,1,13.8300,15,1,13.0399,2,1,13.8399,100,1,13.0299,100,1,13.8800,15,1,12.7300,100,1,14.0700,2,1,12.7100,100,1,14.1699,100,1,12.5000,700,1,14.4000,100,1,12.4600,200,2,14.5600,900,3,12.4299,700,1,14.5999,700,1,12.4199,700,1,14.6799,1400,2,12.3699,700,1,14.7699,200,2,ARL,301747001
1105,2025-07-17T15:43:48.790434947Z,2025-07-17T15:43:48.790434947Z,10,2,1108,C,A,0,14.7799,100,0,165599,253028027,13.2599,100,1,13.8300,15,1,13.0399,2,1,13.8399,100,1,13.0299,100,1,13.8800,15,1,12.7300,100,1,14.0700,2,1,12.7100,100,1,14.1699,100,1,12.5000,700,1,14.4000,100,1,12.4600,200,2,14.5600,900,3,12.4299,700,1,14.5999,700,1,12.4199,700,1,14.6799,1400,2,12.3699,700,1,14.7699,200,2,ARL,300280825
1106,2025-07-17T15:43:48.790434947Z,2025-07-17T15:43:48.790434947Z,10,2,1108,A,A,0,14.6400,100,130,165599,253028027,13.2599,100,1,13.8300,15,1,13.0399,2,1,13.8399,100,1,13.0299,100,1,13.8800,15,1,12.7300,100,1,14.0700,2,1,12.7100,100,1,14.1699,100,1,12.5000,700,1,14.4000,100,1,12.4600,200,2,14.5600,900,3,12.4299,700,1,14.5999,700,1,12.4199,700,1,14.6400,100,1,12.3699,700,1,14.6799,1400,2,ARL,301747005
1107,2025-07-17T15:43:48.800794196Z,2025-07-17T15:43:48.800794196Z,10,2,1108,C,A,0,17.7600,100,0,165402,253028707,13.2599,100,1,13.8300,15,1,13.0399,2,1,13.8399,100,1,13.0299,100,1,13.8800,15,1,12.7300,100,1,14.0700,2,1,12.7100,100,1,14.1699,100,1,12.5000,700,1,14.4000,100,1,12.4600,200,2,14.5600,900,3,12.4299,700,1,14.5999,700,1,12.4199,700,1,14.6400,100,1,12.3699,700,1,14.6799,1400,2,ARL,300280797
1108,2025-07-17T15:43:48.800794196Z,2025-07-17T15:43:48.800794196Z,10,2,1108,A,A,0,17.5799,100,130,165402,253028707,13.2599,100,1,13.8300,15,1,13.0399,2,1,13.8399,100,1,13.0299,100,1,13.8800,15,1,12.7300,100,1,14.0700,2,1,12.7100,100,1,14.1699,100,1,12.5000,700,1,14.4000,100,1,12.4600,200,2,14.5600,900,3,12.4299,700,1,14.5999,700,1,12.4199,700,1,14.6400,100,1,12.3699,700,1,14.6799,1400,2,ARL,301747261
1109,2025-07-17T15:43:48.806679708Z,2025-07-17T15:43:48.806679708Z,10,2,1108,C,A,0,16.0799,100,0,165541,253028803,13.2599,100,1,13.8300,15,1,13.0399,2,1,13.8399,100,1,13.0299,100,1,13.8800,15,1,12.7300,100,1,14.0700,2,1,12.7100,100,1,14.1699,100,1,12.5000,700,1,14.4000,100,1,12.4600,200,2,14.5600,900,3,12.4299,700,1,14.5999,700,1,12.4199,700,1,14.6400,100,1,12.3699,700,1,14.6799,1400,2,ARL,300280773
1110,2025-07-17T15:43:48.806679708Z,2025-07-17T15:43:48.806679708Z,10,2,1108,A,A,0,15.9199,100,130,165541,253028803,13.2599,100,1,13.8300,15,1,13.0399,2,1,13.8399,100,1,13.0299,100,1,13.8800,15,1,12.7300,100,1,14.0700,2,1,12.7100,100,1,14.1699,100,1,12.5000,700,1,14.4000,100,1,12.4600,200,2,14.5600,900,3,12.4299,700,1,14.5999,700,1,12.4199,700,1,14.6400,100,1,12.3699,700,1,14.6799,1400,2,ARL,301747301
1111,2025-07-17T15:43:48.852405047Z,2025-07-17T15:43:48.852405047Z,10,2,1108,C,A,0,14.9600,100,0,165806,253029437,13.2599,100,1,13.8300,15,1,13.0399,2,1,13.8399,100,1,13.0299,100,1,13.8800,15,1,12.7300,100,1,14.0700,2,1,12.7100,100,1,14.1699,100,1,12.5000,700,1,14.4000,100,1,12.4600,200,2,14.5600,900,3,12.4299,700,1,14.5999,700,1,12.4199,700,1,14.6400,100,1,12.3699,700,1,14.6799,1400,2,ARL,300280873
1112,2025-07-17T15:43:48.852405047Z,2025-07-17T15:43:48.852405047Z,10,2,1108,A,A,0,14.8100,100,130,165806,253029437,13.2599,100,1,13.8300,15,1,13.0399,2,1,13.8399,100,1,13.0299,100,1,13.8800,15,1,12.7300,100,1,14.0700,2,1,12.7100,100,1,14.1699,100,1,12.5000,700,1,14.4000,100,1,12.4600,200,2,14.5600,900,3,12.4299,700,1,14.5999,700,1,12.4199,700,1,14.6400,100,1,12.3699,700,1,14.6799,1400,2,ARL,301747957
1113,2025-07-17T15:43:53.123652480Z,2025-07-17T15:43:53.123652480Z,10,2,1108,C,A,0,13.8800,15,130,165279,253100941,13.2599,100,1,13.8300,15,1,13.0399,2,1,13.8399,100,1,13.0299,100,1,14.0700,2,1,12.7300,100,1,14.1699,100,1,12.7100,100,1,14.4000,100,1,12.5000,700,1,14.5600,900,3,12.4600,200,2,14.5999,700,1,12.4299,700,1,14.6400,100,1,12.4199,700,1,14.6799,1400,2,12.3699,700,1,14.7699,200,2,ARL,301451057
1114,2025-07-17T15:43:54.126111293Z,2025-07-17T15:43:54.126111293Z,10,2,1108,A,A,0,13.8100,15,130,165683,253121467,13.2599,100,1,13.8100,15,1,13.0399,2,1,13.8300,15,1,13.0299,100,1,13.8399,100,1,12.7300,100,1,14.0700,2,1,12.7100,100,1,14.1699,100,1,12.5000,700,1,14.4000,100,1,12.4600,200,2,14.5600,900,3,12.4299,700,1,14.5999,700,1,12.4199,700,1,14.6400,100,1,12.3699,700,1,14.6799,1400,2,ARL,301867541
1115,2025-07-17T15:43:54.998073317Z,2025-07-17T15:43:54.998073317Z,10,2,1108,C,A,0,13.8399,100,0,165616,253137948,13.2599,100,1,13.8100,15,1,13.0399,2,1,13.8300,15,1,13.0299,100,1,14.0700,2,1,12.7300,100,1,14.1699,100,1,12.7100,100,1,14.4000,100,1,12.5000,700,1,14.5600,900,3,12.4600,200,2,14.5999,700,1,12.4299,700,1,14.6400,100,1,12.4199,700,1,14.6799,1400,2,12.3699,700,1,14.7699,200,2,ARL,301746949
1116,2025-07-17T15:43:54.998073317Z,2025-07-17T15:43:54.998073317Z,10,2,1108,A,A,0,13.8200,100,130,165616,253137948,13.2599,100,1,13.8100,15,1,13.0399,2,1,13.8200,100,1,13.0299,100,1,13.8300,15,1,12.7300,100,1,14.0700,2,1,12.7100,100,1,14.1699,100,1,12.5000,700,1,14.4000,100,1,12.4600,200,2,14.5600,900,3,12.4299,700,1,14.5999,700,1,12.4199,700,1,14.6400,100,1,12.3699,700,1,14.6799,1400,2,ARL,301885353
1117,2025-07-17T15:43:55.019007300Z,2025-07-17T15:43:55.019007300Z,10,2,1108,C,A,0,14.1699,100,130,165441,253138492,13.2599,100,1,13.8100,15,1,13.0399,2,1,13.8200,100,1,13.0299,100,1,13.8300,15,1,12.7300,100,1,14.0700,2,1,12.7100,100,1,14.4000,100,1,12.5000,700,1,14.5600,900,3,12.4600,200,2,14.5999,700,1,12.4299,700,1,14.6400,100,1,12.4199,700,1,14.6799,1400,2,12.3699,700,1,14.7699,200,2,ARL,301452785
1118,2025-07-17T15:43:55.019060515Z,2025-07-17T15:43:55.019060515Z,10,2,1108,A,A,0,14.0999,100,130,165420,253138493,13.2599,100,1,13.8100,15,1,13.0399,2,1,13.8200,100,1,13.0299,100,1,13.8300,15,1,12.7300,100,1,14.0700,2,1,12.7100,100,1,14.0999,100,1,12.5000,700,1,14.4000,100,1,12.4600,200,2,14.5600,900,3,12.4299,700,1,14.5999,700,1,12.4199,700,1,14.6400,100,1,12.3699,700,1,14.6799,1400,2,ARL,301886057
1119,2025-07-17T15:44:01.698626200Z,2025-07-17T15:44:01.698626200Z,10,2,1108,C,A,0,13.8300,15,130,165267,253246317,13.2599,100,1,13.8100,15,1,13.0399,2,1,13.8200,100,1,13.0299,100,1,14.0700,2,1,12.7300,100,1,14.0999,100,1,12.7100,100,1,14.4000,100,1,12.5000,700,1,14.5600,900,3,12.4600,200,2,14.5999,700,1,12.4299,700,1,14.6400,100,1,12.4199,700,1,14.6799,1400,2,12.3699,700,1,14.7699,200,2,ARL,301746941
1120,2025-07-17T15:44:04.014712730Z,2025-07-17T15:44:04.014712730Z,10,2,1108,A,A,0,13.8300,100,130,165426,253292355,13.2599,100,1,13.8100,15,1,13.0399,2,1,13.8200,100,1,13.0299,100,1,13.8300,100,1,12.7300,100,1,14.0700,2,1,12.7100,100,1,14.0999,100,1,12.5000,700,1,14.4000,100,1,12.4600,200,2,14.5600,900,3,12.4299,700,1,14.5999,700,1,12.4199,700,1,14.6400,100,1,12.3699,700,1,14.6799,1400,2,ARL,302078553
1121,2025-07-17T15:44:05.055461574Z,2025-07-17T15:44:05.055461574Z,10,2,1108,A,A,0,13.8100,100,130,165374,253307083,13.2599,100,1,13.8100,115,2,13.0399,2,1,13.8200,100,1,13.0299,100,1,13.8300,100,1,12.7300,100,1,14.0700,2,1,12.7100,100,1,14.0999,100,1,12.5000,700,1,14.4000,100,1,12.4600,200,2,14.5600,900,3,12.4299,700,1,14.5999,700,1,12.4199,700,1,14.6400,100,1,12.3699,700,1,14.6799,1400,2,ARL,302100649
1122,2025-07-17T15:44:05.062266845Z,2025-07-17T15:44:05.062266845Z,10,2,1108,C,A,0,13.8300,100,130,165104,253307147,13.2599,100,1,13.8100,115,2,13.0399,2,1,13.8200,100,1,13.0299,100,1,14.0700,2,1,12.7300,100,1,14.0999,100,1,12.7100,100,1,14.4000,100,1,12.5000,700,1,14.5600,900,3,12.4600,200,2,14.5999,700,1,12.4299,700,1,14.6400,100,1,12.4199,700,1,14.6799,1400,2,12.3699,700,1,14.7699,200,2,ARL,302078553
1123,2025-07-17T15:44:09.389548394Z,2025-07-17T15:44:09.389548394Z,10,2,1108,A,A,0,13.7599,15,130,165336,253384422,13.2599,100,1,13.7599,15,1,13.0399,2,1,13.8100,115,2,13.0299,100,1,13.8200,100,1,12.7300,100,1,14.0700,2,1,12.7100,100,1,14.0999,100,1,12.5000,700,1,14.4000,100,1,12.4600,200,2,14.5600,900,3,12.4299,700,1,14.5999,700,1,12.4199,700,1,14.6400,100,1,12.3699,700,1,14.6799,1400,2,ARL,302205249
1124,2025-07-17T15:44:09.390329935Z,2025-07-17T15:44:09.390329935Z,10,2,1108,C,A,0,14.7699,100,0,166205,253384438,13.2599,100,1,13.7599,15,1,13.0399,2,1,13.8100,115,2,13.0299,100,1,13.8200,100,1,12.7300,100,1,14.0700,2,1,12.7100,100,1,14.0999,100,1,12.5000,700,1,14.4000,100,1,12.4600,200,2,14.5600,900,3,12.4299,700,1,14.5999,700,1,12.4199,700,1,14.6400,100,1,12.3699,700,1,14.6799,1400,2,ARL,301671709
1125,2025-07-17T15:44:09.390329935Z,2025-07-17T15:44:09.390329935Z,10,2,1108,A,A,0,14.6600,100,128,166205,253384438,13.2599,100,1,13.7599,15,1,13.0399,2,1,13.8100,115,2,13.0299,100,1,13.8200,100,1,12.7300,100,1,14.0700,2,1,12.7100,100,1,14.0999,100,1,12.5000,700,1,14.4000,100,1,12.4600,200,2,14.5600,900,3,12.4299,700,1,14.5999,700,1,12.4199,700,1,14.6400,100,1,12.3699,700,1,14.6600,100,1,ARL,302205289
1126,2025-07-17T15:44:09.390893172Z,2025-07-17T15:44:09.390893172Z,10,2,1108,C,A,0,14.7699,100,0,165314,253384456,13.2599,100,1,13.7599,15,1,13.0399,2,1,13.8100,115,2,13.0299,100,1,13.8200,100,1,12.7300,100,1,14.0700,2,1,12.7100,100,1,14.0999,100,1,12.5000,700,1,14.4000,100,1,12.4600,200,2,14.5600,900,3,12.4299,700,1,14.5999,700,1,12.4199,700,1,14.6400,100,1,12.3699,700,1,14.6600,100,1,ARL,301671713
1127,2025-07-17T15:44:09.390893172Z,2025-07-17T15:44:09.390893172Z,10,2,1108,A,A,0,14.6600,100,130,165314,253384456,13.2599,100,1,13.7599,15,1,13.0399,2,1,13.8100,115,2,13.0299,100,1,13.8200,100,1,12.7300,100,1,14.0700,2,1,12.7100,100,1,14.0999,100,1,12.5000,700,1,14.4000,100,1,12.4600,200,2,14.5600,900,3,12.4299,700,1,14.5999,700,1,12.4199,700,1,14.6400,100,1,12.3699,700,1,14.6600,200,2,ARL,302205309
1128,2025-07-17T15:44:09.395281780Z,2025-07-17T15:44:09.395281780Z,10,2,1108,C,A,0,13.8200,100,0,165832,253384698,13.2599,100,1,13.7599,15,1,13.0399,2,1,13.8100,115,2,13.0299,100,1,14.0700,2,1,12.7300,100,1,14.0999,100,1,12.7100,100,1,14.4000,100,1,12.5000,700,1,14.5600,900,3,12.4600,200,2,14.5999,700,1,12.4299,700,1,14.6400,100,1,12.4199,700,1,14.6600,200,2,12.3699,700,1,14.6799,1400,2,ARL,301885353
1129,2025-07-17T15:44:09.395281780Z,2025-07-17T15:44:09.395281780Z,10,2,1108,A,A,0,13.7699,100,130,165832,253384698,13.2599,100,1,13.7599,15,1,13.0399,2,1,13.7699,100,1,13.0299,100,1,13.8100,115,2,12.7300,100,1,14.0700,2,1,12.7100,100,1,14.0999,100,1,12.5000,700,1,14.4000,100,1,12.4600,200,2,14.5600,900,3,12.4299,700,1,14.5999,700,1,12.4199,700,1,14.6400,100,1,12.3699,700,1,14.6600,200,2,ARL,302205493
1130,2025-07-17T15:44:09.396030225Z,2025-07-17T15:44:09.396030225Z,10,2,1108,C,A,0,14.9100,100,0,165422,253384731,13.2599,100,1,13.7599,15,1,13.0399,2,1,13.7699,100,1,13.0299,100,1,13.8100,115,2,12.7300,100,1,14.0700,2,1,12.7100,100,1,14.0999,100,1,12.5000,700,1,14.4000,100,1,12.4600,200,2,14.5600,900,3,12.4299,700,1,14.5999,700,1,12.4199,700,1,14.6400,100,1,12.3699,700,1,14.6600,200,2,ARL,301746969
1131,2025-07-17T15:44:09.396030225Z,2025-07-17T15:44:09.396030225Z,10,2,1108,A,A,0,14.8399,100,130,165422,253384731,13.2599,100,1,13.7599,15,1,13.0399,2,1,13.7699,100,1,13.0299,100,1,13.8100,115,2,12.7300,100,1,14.0700,2,1,12.7100,100,1,14.0999,100,1,12.5000,700,1,14.4000,100,1,12.4600,200,2,14.5600,900,3,12.4299,700,1,14.5999,700,1,12.4199,700,1,14.6400,100,1,12.3699,700,1,14.6600,200,2,ARL,302205537
1132,2025-07-17T15:44:09.397845986Z,2025-07-17T15:44:09.397845986Z,10,2,1108,A,A,0,13.7899,100,130,165200,253384788,13.2599,100,1,13.7599,15,1,13.0399,2,1,13.7699,100,1,13.0299,100,1,13.7899,100,1,12.7300,100,1,13.8100,115,2,12.7100,100,1,14.0700,2,1,12.5000,700,1,14.0999,100,1,12.4600,200,2,14.4000,100,1,12.4299,700,1,14.5600,900,3,12.4199,700,1,14.5999,700,1,12.3699,700,1,14.6400,100,1,ARL,302205561
1133,2025-07-17T15:44:09.404663816Z,2025-07-17T15:44:09.404663816Z,10,2,1108,C,A,0,13.8100,100,130,165140,253385013,13.2599,100,1,13.7599,15,1,13.0399,2,1,13.7699,100,1,13.0299,100,1,13.7899,100,1,12.7300,100,1,13.8100,15,1,12.7100,100,1,14.0700,2,1,12.5000,700,1,14.0999,100,1,12.4600,200,2,14.4000,100,1,12.4299,700,1,14.5600,900,3,12.4199,700,1,14.5999,700,1,12.3699,700,1,14.6400,100,1,ARL,302100649
1134,2025-07-17T15:44:20.402370565Z,2025-07-17T15:44:20.402370565Z,10,2,1108,C,A,0,13.8100,15,130,165266,253562230,13.2599,100,1,13.7599,15,1,13.0399,2,1,13.7699,100,1,13.0299,100,1,13.7899,100,1,12.7300,100,1,14.0700,2,1,12.7100,100,1,14.0999,100,1,12.5000,700,1,14.4000,100,1,12.4600,200,2,14.5600,900,3,12.4299,700,1,14.5999,700,1,12.4199,700,1,14.6400,100,1,12.3699,700,1,14.6600,200,2,ARL,301867541
1135,2025-07-17T15:44:21.405320730Z,2025-07-17T15:44:21.405320730Z,10,2,1108,A,A,0,13.7400,15,130,165392,253582427,13.2599,100,1,13.7400,15,1,13.0399,2,1,13.7599,15,1,13.0299,100,1,13.7699,100,1,12.7300,100,1,13.7899,100,1,12.7100,100,1,14.0700,2,1,12.5000,700,1,14.0999,100,1,12.4600,200,2,14.4000,100,1,12.4299,700,1,14.5600,900,3,12.4199,700,1,14.5999,700,1,12.3699,700,1,14.6400,100,1,ARL,302458113
1136,2025-07-17T15:44:21.843070079Z,2025-07-17T15:44:21.843070079Z,10,2,1108,C,A,0,13.7699,100,0,165832,253590641,13.2599,100,1,13.7400,15,1,13.0399,2,1,13.7599,15,1,13.0299,100,1,13.7899,100,1,12.7300,100,1,14.0700,2,1,12.7100,100,1,14.0999,100,1,12.5000,700,1,14.4000,100,1,12.4600,200,2,14.5600,900,3,12.4299,700,1,14.5999,700,1,12.4199,700,1,14.6400,100,1,12.3699,700,1,14.6600,200,2,ARL,302205493
1137,2025-07-17T15:44:21.843070079Z,2025-07-17T15:44:21.843070079Z,10,2,1108,A,A,0,13.7500,100,130,165832,253590641,13.2599,100,1,13.7400,15,1,13.0399,2,1,13.7500,100,1,13.0299,100,1,13.7599,15,1,12.7300,100,1,13.7899,100,1,12.7100,100,1,14.0700,2,1,12.5000,700,1,14.0999,100,1,12.4600,200,2,14.4000,100,1,12.4299,700,1,14.5600,900,3,12.4199,700,1,14.5999,700,1,12.3699,700,1,14.6400,100,1,ARL,302466045
1138,2025-07-17T15:44:21.855250804Z,2025-07-17T15:44:21.855250804Z,10,2,1108,C,A,0,14.0999,100,130,165289,253590837,13.2599,100,1,13.7400,15,1,13.0399,2,1,13.7500,100,1,13.0299,100,1,13.7599,15,1,12.7300,100,1,13.7899,100,1,12.7100,100,1,14.0700,2,1,12.5000,700,1,14.4000,100,1,12.4600,200,2,14.5600,900,3,12.4299,700,1,14.5999,700,1,12.4199,700,1,14.6400,100,1,12.3699,700,1,14.6600,200,2,ARL,301886057
1139,2025-07-17T15:44:21.855305995Z,2025-07-17T15:44:21.855305995Z,10,2,1108,A,A,0,14.0299,100,130,165163,253590838,13.2599,100,1,13.7400,15,1,13.0399,2,1,13.7500,100,1,13.0299,100,1,13.7599,15,1,12.7300,100,1,13.7899,100,1,12.7100,100,1,14.0299,100,1,12.5000,700,1,14.0700,2,1,12.4600,200,2,14.4000,100,1,12.4299,700,1,14.5600,900,3,12.4199,700,1,14.5999,700,1,12.3699,700,1,14.6400,100,1,ARL,302466157
1140,2025-07-17T15:44:24.446910206Z,2025-07-17T15:44:24.446910206Z,10,2,1108,A,A,0,13.7699,100,130,165326,253614407,13.2599,100,1,13.7400,15,1,13.0399,2,1,13.7500,100,1,13.0299,100,1,13.7599,15,1,12.7300,100,1,13.7699,100,1,12.7100,100,1,13.7899,100,1,12.5000,700,1,14.0299,100,1,12.4600,200,2,14.0700,2,1,12.4299,700,1,14.4000,100,1,12.4199,700,1,14.5600,900,3,12.3699,700,1,14.5999,700,1,ARL,302500469
1141,2025-07-17T15:44:24.465390625Z,2025-07-17T15:44:24.465390625Z,10,2,1108,C,A,0,13.7899,100,130,165193,253614591,13.2599,100,1,13.7400,15,1,13.0399,2,1,13.7500,100,1,13.0299,100,1,13.7599,15,1,12.7300,100,1,13.7699,100,1,12.7100,100,1,14.0299,100,1,12.5000,700,1,14.0700,2,1,12.4600,200,2,14.4000,100,1,12.4299,700,1,14.5600,900,3,12.4199,700,1,14.5999,700,1,12.3699,700,1,14.6400,100,1,ARL,302205561
1142,2025-07-17T15:44:30.846657613Z,2025-07-17T15:44:30.846657613Z,10,2,1108,C,A,0,13.7599,15,130,165370,253704439,13.2599,100,1,13.7400,15,1,13.0399,2,1,13.7500,100,1,13.0299,100,1,13.7699,100,1,12.7300,100,1,14.0299,100,1,12.7100,100,1,14.0700,2,1,12.5000,700,1,14.4000,100,1,12.4600,200,2,14.5600,900,3,12.4299,700,1,14.5999,700,1,12.4199,700,1,14.6400,100,1,12.3699,700,1,14.6600,200,2,ARL,302205249
1143,2025-07-17T15:44:31.849618640Z,2025-07-17T15:44:31.849618640Z,10,2,1108,A,A,0,13.7200,15,130,166053,253721156,13.2599,100,1,13.7200,15,1,13.0399,2,1,13.7400,15,1,13.0299,100,1,13.7500,100,1,12.7300,100,1,13.7699,100,1,12.7100,100,1,14.0299,100,1,12.5000,700,1,14.0700,2,1,12.4600,200,2,14.4000,100,1,12.4299,700,1,14.5600,900,3,12.4199,700,1,14.5999,700,1,12.3699,700,1,14.6400,100,1,ARL,302649021
1144,2025-07-17T15:44:31.849756452Z,2025-07-17T15:44:31.849756452Z,10,2,1108,A,A,0,13.7500,100,130,165405,253721157,13.2599,100,1,13.7200,15,1,13.0399,2,1,13.7400,15,1,13.0299,100,1,13.7500,200,2,12.7300,100,1,13.7699,100,1,12.7100,100,1,14.0299,100,1,12.5000,700,1,14.0700,2,1,12.4600,200,2,14.4000,100,1,12.4299,700,1,14.5600,900,3,12.4199,700,1,14.5999,700,1,12.3699,700,1,14.6400,100,1,ARL,302649029
1145,2025-07-17T15:44:31.909959614Z,2025-07-17T15:44:31.909959614Z,10,2,1108,C,A,0,13.7699,100,130,165364,253722140,13.2599,100,1,13.7200,15,1,13.0399,2,1,13.7400,15,1,13.0299,100,1,13.7500,200,2,12.7300,100,1,14.0299,100,1,12.7100,100,1,14.0700,2,1,12.5000,700,1,14.4000,100,1,12.4600,200,2,14.5600,900,3,12.4299,700,1,14.5999,700,1,12.4199,700,1,14.6400,100,1,12.3699,700,1,14.6600,200,2,ARL,302500469
1146,2025-07-17T15:44:32.484331764Z,2025-07-17T15:44:32.484331764Z,10,2,1108,C,A,0,13.7500,100,0,165466,253730877,13.2599,100,1,13.7200,15,1,13.0399,2,1,13.7400,15,1,13.0299,100,1,13.7500,100,1,12.7300,100,1,14.0299,100,1,12.7100,100,1,14.0700,2,1,12.5000,700,1,14.4000,100,1,12.4600,200,2,14.5600,900,3,12.4299,700,1,14.5999,700,1,12.4199,700,1,14.6400,100,1,12.3699,700,1,14.6600,200,2,ARL,302466045
1147,2025-07-17T15:44:32.484331764Z,2025-07-17T15:44:32.484331764Z,10,2,1108,A,A,0,13.7300,100,130,165466,253730877,13.2599,100,1,13.7200,15,1,13.0399,2,1,13.7300,100,1,13.0299,100,1,13.7400,15,1,12.7300,100,1,13.7500,100,1,12.7100,100,1,14.0299,100,1,12.5000,700,1,14.0700,2,1,12.4600,200,2,14.4000,100,1,12.4299,700,1,14.5600,900,3,12.4199,700,1,14.5999,700,1,12.3699,700,1,14.6400,100,1,ARL,302662769
1148,2025-07-17T15:44:32.485072552Z,2025-07-17T15:44:32.485072552Z,10,2,1108,C,A,0,14.8399,100,0,165657,253730907,13.2599,100,1,13.7200,15,1,13.0399,2,1,13.7300,100,1,13.0299,100,1,13.7400,15,1,12.7300,100,1,13.7500,100,1,12.7100,100,1,14.0299,100,1,12.5000,700,1,14.0700,2,1,12.4600,200,2,14.4000,100,1,12.4299,700,1,14.5600,900,3,12.4199,700,1,14.5999,700,1,12.3699,700,1,14.6400,100,1,ARL,302205537
1149,2025-07-17T15:44:32.485072552Z,2025-07-17T15:44:32.485072552Z,10,2,1108,A,A,0,14.7899,100,130,165657,253730907,13.2599,100,1,13.7200,15,1,13.0399,2,1,13.7300,100,1,13.0299,100,1,13.7400,15,1,12.7300,100,1,13.7500,100,1,12.7100,100,1,14.0299,100,1,12.5000,700,1,14.0700,2,1,12.4600,200,2,14.4000,100,1,12.4299,700,1,14.5600,900,3,12.4199,700,1,14.5999,700,1,12.3699,700,1,14.6400,100,1,ARL,302662821
1150,2025-07-17T15:44:33.389222513Z,2025-07-17T15:44:33.389222513Z,10,2,1108,A,A,0,14.2799,100,130,165301,253745665,13.2599,100,1,13.7200,15,1,13.0399,2,1,13.7300,100,1,13.0299,100,1,13.7400,15,1,12.7300,100,1,13.7500,100,1,12.7100,100,1,14.0299,100,1,12.5000,700,1,14.0700,2,1,12.4600,200,2,14.2799,100,1,12.4299,700,1,14.4000,100,1,12.4199,700,1,14.5600,900,3,12.3699,700,1,14.5999,700,1,ARL,302681357
1151,2025-07-17T15:44:33.389223581Z,2025-07-17T15:44:33.389223581Z,10,2,1108,C,A,0,14.5600,100,130,165449,253745666,13.2599,100,1,13.7200,15,1,13.0399,2,1,13.7300,100,1,13.0299,100,1,13.7400,15,1,12.7300,100,1,13.7500,100,1,12.7100,100,1,14.0299,100,1,12.5000,700,1,14.0700,2,1,12.4600,200,2,14.2799,100,1,12.4299,700,1,14.4000,100,1,12.4199,700,1,14.5600,800,2,12.3699,700,1,14.5999,700,1,ARL,146960005
1152,2025-07-17T15:44:36.362022168Z,2025-07-17T15:44:36.362022168Z,10,2,1108,C,A,0,13.7400,15,130,165505,253783635,13.2599,100,1,13.7200,15,1,13.0399,2,1,13.7300,100,1,13.0299,100,1,13.7500,100,1,12.7300,100,1,14.0299,100,1,12.7100,100,1,14.0700,2,1,12.5000,700,1,14.2799,100,1,12.4600,200,2,14.4000,100,1,12.4299,700,1,14.5600,800,2,12.4199,700,1,14.5999,700,1,12.3699,700,1,14.6400,100,1,ARL,302458113
1153,2025-07-17T15:44:37.364212109Z,2025-07-17T15:44:37.364212109Z,10,2,1108,A,A,0,13.6999,15,130,165310,253797506,13.2599,100,1,13.6999,15,1,13.0399,2,1,13.7200,15,1,13.0299,100,1,13.7300,100,1,12.7300,100,1,13.7500,100,1,12.7100,100,1,14.0299,100,1,12.5000,700,1,14.0700,2,1,12.4600,200,2,14.2799,100,1,12.4299,700,1,14.4000,100,1,12.4199,700,1,14.5600,800,2,12.3699,700,1,14.5999,700,1,ARL,302750929
1154,2025-07-17T15:44:37.364353897Z,2025-07-17T15:44:37.364353897Z,10,2,1108,A,A,0,13.7300,100,130,165170,253797510,13.2599,100,1,13.6999,15,1,13.0399,2,1,13.7200,15,1,13.0299,100,1,13.7300,200,2,12.7300,100,1,13.7500,100,1,12.7100,100,1,14.0299,100,1,12.5000,700,1,14.0700,2,1,12.4600,200,2,14.2799,100,1,12.4299,700,1,14.4000,100,1,12.4199,700,1,14.5600,800,2,12.3699,700,1,14.5999,700,1,ARL,302750937
1155,2025-07-17T15:44:37.457954350Z,2025-07-17T15:44:37.457954350Z,10,2,1108,C,A,0,13.7500,100,130,165144,253798432,13.2599,100,1,13.6999,15,1,13.0399,2,1,13.7200,15,1,13.0299,100,1,13.7300,200,2,12.7300,100,1,14.0299,100,1,12.7100,100,1,14.0700,2,1,12.5000,700,1,14.2799,100,1,12.4600,200,2,14.4000,100,1,12.4299,700,1,14.5600,800,2,12.4199,700,1,14.5999,700,1,12.3699,700,1,14.6400,100,1,ARL,302649029
1156,2025-07-17T15:44:38.432294362Z,2025-07-17T15:44:38.432294362Z,10,2,1108,C,A,0,13.7300,100,0,166147,253807786,13.2599,100,1,13.6999,15,1,13.0399,2,1,13.7200,15,1,13.0299,100,1,13.7300,100,1,12.7300,100,1,14.0299,100,1,12.7100,100,1,14.0700,2,1,12.5000,700,1,14.2799,100,1,12.4600,200,2,14.4000,100,1,12.4299,700,1,14.5600,800,2,12.4199,700,1,14.5999,700,1,12.3699,700,1,14.6400,100,1,ARL,302662769
1157,2025-07-17T15:44:38.432294362Z,2025-07-17T15:44:38.432294362Z,10,2,1108,A,A,0,13.7100,100,130,166147,253807786,13.2599,100,1,13.6999,15,1,13.0399,2,1,13.7100,100,1,13.0299,100,1,13.7200,15,1,12.7300,100,1,13.7300,100,1,12.7100,100,1,14.0299,100,1,12.5000,700,1,14.0700,2,1,12.4600,200,2,14.2799,100,1,12.4299,700,1,14.4000,100,1,12.4199,700,1,14.5600,800,2,12.3699,700,1,14.5999,700,1,ARL,302763889
1158,2025-07-17T15:44:38.439088042Z,2025-07-17T15:44:38.439088042Z,10,2,1108,C,A,0,15.9199,100,0,165933,253808105,13.2599,100,1,13.6999,15,1,13.0399,2,1,13.7100,100,1,13.0299,100,1,13.7200,15,1,12.7300,100,1,13.7300,100,1,12.7100,100,1,14.0299,100,1,12.5000,700,1,14.0700,2,1,12.4600,200,2,14.2799,100,1,12.4299,700,1,14.4000,100,1,12.4199,700,1,14.5600,800,2,12.3699,700,1,14.5999,700,1,ARL,301747301
1159,2025-07-17T15:44:38.439088042Z,2025-07-17T15:44:38.439088042Z,10,2,1108,A,A,0,15.7699,100,130,165933,253808105,13.2599,100,1,13.6999,15,1,13.0399,2,1,13.7100,100,1,13.0299,100,1,13.7200,15,1,12.7300,100,1,13.7300,100,1,12.7100,100,1,14.0299,100,1,12.5000,700,1,14.0700,2,1,12.4600,200,2,14.2799,100,1,12.4299,700,1,14.4000,100,1,12.4199,700,1,14.5600,800,2,12.3699,700,1,14.5999,700,1,ARL,302764121
1160,2025-07-17T15:44:38.440156077Z,2025-07-17T15:44:38.440156077Z,10,2,1108,C,A,0,17.5799,100,0,165620,253808122,13.2599,100,1,13.6999,15,1,13.0399,2,1,13.7100,100,1,13.0299,100,1,13.7200,15,1,12.7300,100,1,13.7300,100,1,12.7100,100,1,14.0299,100,1,12.5000,700,1,14.0700,2,1,12.4600,200,2,14.2799,100,1,12.4299,700,1,14.4000,100,1,12.4199,700,1,14.5600,800,2,12.3699,700,1,14.5999,700,1,ARL,301747261
1161,2025-07-17T15:44:38.440156077Z,2025-07-17T15:44:38.440156077Z,10,2,1108,A,A,0,17.4200,100,130,165620,253808122,13.2599,100,1,13.6999,15,1,13.0399,2,1,13.7100,100,1,13.0299,100,1,13.7200,15,1,12.7300,100,1,13.7300,100,1,12.7100,100,1,14.0299,100,1,12.5000,700,1,14.0700,2,1,12.4600,200,2,14.2799,100,1,12.4299,700,1,14.4000,100,1,12.4199,700,1,14.5600,800,2,12.3699,700,1,14.5999,700,1,ARL,302764137
1162,2025-07-17T15:44:43.019083502Z,2025-07-17T15:44:43.019083502Z,10,2,1108,C,A,0,13.6999,15,128,178715,253875920,13.2599,100,1,13.7100,100,1,13.0399,2,1,13.7200,15,1,13.0299,100,1,13.7300,100,1,12.7300,100,1,14.0299,100,1,12.7100,100,1,14.0700,2,1,12.5000,700,1,14.2799,100,1,12.4600,200,2,14.4000,100,1,12.4299,700,1,14.5600,800,2,12.4199,700,1,14.5999,700,1,12.3699,700,1,14.6400,100,1,ARL,302750929
1163,2025-07-17T15:44:43.019184132Z,2025-07-17T15:44:43.019184132Z,10,2,1108,C,A,0,13.7200,15,128,168526,253876010,13.2599,100,1,13.7100,100,1,13.0399,2,1,13.7300,100,1,13.0299,100,1,14.0299,100,1,12.7300,100,1,14.0700,2,1,12.7100,100,1,14.2799,100,1,12.5000,700,1,14.4000,100,1,12.4600,200,2,14.5600,800,2,12.4299,700,1,14.5999,700,1,12.4199,700,1,14.6400,100,1,12.3699,700,1,14.6600,200,2,ARL,302649021
1164,2025-07-17T15:44:44.075843113Z,2025-07-17T15:44:44.075843113Z,10,2,1108,A,A,0,13.6999,15,128,166886,253892869,13.2599,100,1,13.6999,15,1,13.0399,2,1,13.7100,100,1,13.0299,100,1,13.7300,100,1,12.7300,100,1,14.0299,100,1,12.7100,100,1,14.0700,2,1,12.5000,700,1,14.2799,100,1,12.4600,200,2,14.4000,100,1,12.4299,700,1,14.5600,800,2,12.4199,700,1,14.5999,700,1,12.3699,700,1,14.6400,100,1,ARL,302867209
1165,2025-07-17T15:44:44.781464821Z,2025-07-17T15:44:44.781464821Z,10,2,1108,C,A,0,13.6999,15,130,165911,253901222,13.2599,100,1,13.7100,100,1,13.0399,2,1,13.7300,100,1,13.0299,100,1,14.0299,100,1,12.7300,100,1,14.0700,2,1,12.7100,100,1,14.2799,100,1,12.5000,700,1,14.4000,100,1,12.4600,200,2,14.5600,800,2,12.4299,700,1,14.5999,700,1,12.4199,700,1,14.6400,100,1,12.3699,700,1,14.6600,200,2,ARL,302867209
1166,2025-07-17T15:44:53.143083969Z,2025-07-17T15:44:53.143083969Z,10,2,1108,C,A,0,13.7300,100,130,165301,254011871,13.2599,100,1,13.7100,100,1,13.0399,2,1,14.0299,100,1,13.0299,100,1,14.0700,2,1,12.7300,100,1,14.2799,100,1,12.7100,100,1,14.4000,100,1,12.5000,700,1,14.5600,800,2,12.4600,200,2,14.5999,700,1,12.4299,700,1,14.6400,100,1,12.4199,700,1,14.6600,200,2,12.3699,700,1,14.6799,1400,2,ARL,302750937
1167,2025-07-17T15:44:57.191023026Z,2025-07-17T15:44:57.191023026Z,10,2,1108,A,A,0,13.7500,100,130,165444,254079162,13.2599,100,1,13.7100,100,1,13.0399,2,1,13.7500,100,1,13.0299,100,1,14.0299,100,1,12.7300,100,1,14.0700,2,1,12.7100,100,1,14.2799,100,1,12.5000,700,1,14.4000,100,1,12.4600,200,2,14.5600,800,2,12.4299,700,1,14.5999,700,1,12.4199,700,1,14.6400,100,1,12.3699,700,1,14.6600,200,2,ARL,303118785
1168,2025-07-17T15:45:07.065587919Z,2025-07-17T15:45:07.065587919Z,10,2,1108,C,A,0,13.7100,100,128,168655,254244597,13.2599,100,1,13.7500,100,1,13.0399,2,1,14.0299,100,1,13.0299,100,1,14.0700,2,1,12.7300,100,1,14.2799,100,1,12.7100,100,1,14.4000,100,1,12.5000,700,1,14.5600,800,2,12.4600,200,2,14.5999,700,1,12.4299,700,1,14.6400,100,1,12.4199,700,1,14.6600,200,2,12.3699,700,1,14.6799,1400,2,ARL,302763889
1169,2025-07-17T15:45:07.079966224Z,2025-07-17T15:45:07.079966224Z,10,2,1108,C,A,0,13.7500,100,130,165281,254245492,13.2599,100,1,14.0299,100,1,13.0399,2,1,14.0700,2,1,13.0299,100,1,14.2799,100,1,12.7300,100,1,14.4000,100,1,12.7100,100,1,14.5600,800,2,12.5000,700,1,14.5999,700,1,12.4600,200,2,14.6400,100,1,12.4299,700,1,14.6600,200,2,12.4199,700,1,14.6799,1400,2,12.3699,700,1,14.7899,100,1,ARL,303118785
1170,2025-07-17T15:45:07.080521807Z,2025-07-17T15:45:07.080521807Z,10,2,1108,C,A,0,14.6600,100,0,165408,254245505,13.2599,100,1,14.0299,100,1,13.0399,2,1,14.0700,2,1,13.0299,100,1,14.2799,100,1,12.7300,100,1,14.4000,100,1,12.7100,100,1,14.5600,800,2,12.5000,700,1,14.5999,700,1,12.4600,200,2,14.6400,100,1,12.4299,700,1,14.6600,100,1,12.4199,700,1,14.6799,1400,2,12.3699,700,1,14.7899,100,1,ARL,302205289
1171,2025-07-17T15:45:07.080521807Z,2025-07-17T15:45:07.080521807Z,10,2,1108,A,A,0,14.8900,100,130,165408,254245505,13.2599,100,1,14.0299,100,1,13.0399,2,1,14.0700,2,1,13.0299,100,1,14.2799,100,1,12.7300,100,1,14.4000,100,1,12.7100,100,1,14.5600,800,2,12.5000,700,1,14.5999,700,1,12.4600,200,2,14.6400,100,1,12.4299,700,1,14.6600,100,1,12.4199,700,1,14.6799,1400,2,12.3699,700,1,14.7899,100,1,ARL,303330477
1172,2025-07-17T15:45:07.080706110Z,2025-07-17T15:45:07.080706110Z,10,2,1108,C,A,0,14.7899,100,0,166135,254245511,13.2599,100,1,14.0299,100,1,13.0399,2,1,14.0700,2,1,13.0299,100,1,14.2799,100,1,12.7300,100,1,14.4000,100,1,12.7100,100,1,14.5600,800,2,12.5000,700,1,14.5999,700,1,12.4600,200,2,14.6400,100,1,12.4299,700,1,14.6600,100,1,12.4199,700,1,14.6799,1400,2,12.3699,700,1,14.8100,200,2,ARL,302662821
1173,2025-07-17T15:45:07.080706110Z,2025-07-17T15:45:07.080706110Z,10,2,1108,A,A,0,15.0600,100,130,166135,254245511,13.2599,100,1,14.0299,100,1,13.0399,2,1,14.0700,2,1,13.0299,100,1,14.2799,100,1,12.7300,100,1,14.4000,100,1,12.7100,100,1,14.5600,800,2,12.5000,700,1,14.5999,700,1,12.4600,200,2,14.6400,100,1,12.4299,700,1,14.6600,100,1,12.4199,700,1,14.6799,1400,2,12.3699,700,1,14.8100,200,2,ARL,303330485
1174,2025-07-17T15:45:07.081407507Z,2025-07-17T15:45:07.081407507Z,10,2,1108,C,A,0,14.8100,100,0,170557,254245568,13.2599,100,1,14.0299,100,1,13.0399,2,1,14.0700,2,1,13.0299,100,1,14.2799,100,1,12.7300,100,1,14.4000,100,1,12.7100,100,1,14.5600,800,2,12.5000,700,1,14.5999,700,1,12.4600,200,2,14.6400,100,1,12.4299,700,1,14.6600,100,1,12.4199,700,1,14.6799,1400,2,12.3699,700,1,14.8100,100,1,ARL,301747001
1175,2025-07-17T15:45:07.081407507Z,2025-07-17T15:45:07.081407507Z,10,2,1108,A,A,0,14.9600,100,128,170557,254245568,13.2599,100,1,14.0299,100,1,13.0399,2,1,14.0700,2,1,13.0299,100,1,14.2799,100,1,12.7300,100,1,14.4000,100,1,12.7100,100,1,14.5600,800,2,12.5000,700,1,14.5999,700,1,12.4600,200,2,14.6400,100,1,12.4299,700,1,14.6600,100,1,12.4199,700,1,14.6799,1400,2,12.3699,700,1,14.8100,100,1,ARL,303330509
1176,2025-07-17T15:45:07.081441134Z,2025-07-17T15:45:07.081441134Z,10,2,1108,C,A,0,14.6600,100,0,166836,254245576,13.2599,100,1,14.0299,100,1,13.0399,2,1,14.0700,2,1,13.0299,100,1,14.2799,100,1,12.7300,100,1,14.4000,100,1,12.7100,100,1,14.5600,800,2,12.5000,700,1,14.5999,700,1,12.4600,200,2,14.6400,100,1,12.4299,700,1,14.6799,1400,2,12.4199,700,1,14.8100,100,1,12.3699,700,1,14.8900,100,1,ARL,302205309
1177,2025-07-17T15:45:07.081441134Z,2025-07-17T15:45:07.081441134Z,10,2,1108,A,A,0,14.8900,100,130,166836,254245576,13.2599,100,1,14.0299,100,1,13.0399,2,1,14.0700,2,1,13.0299,100,1,14.2799,100,1,12.7300,100,1,14.4000,100,1,12.7100,100,1,14.5600,800,2,12.5000,700,1,14.5999,700,1,12.4600,200,2,14.6400,100,1,12.4299,700,1,14.6799,1400,2,12.4199,700,1,14.8100,100,1,12.3699,700,1,14.8900,200,2,ARL,303330521
1178,2025-07-17T15:45:07.083732443Z,2025-07-17T15:45:07.083732443Z,10,2,1108,C,A,0,17.4200,100,0,166556,254246327,13.2599,100,1,14.0299,100,1,13.0399,2,1,14.0700,2,1,13.0299,100,1,14.2799,100,1,12.7300,100,1,14.4000,100,1,12.7100,100,1,14.5600,800,2,12.5000,700,1,14.5999,700,1,12.4600,200,2,14.6400,100,1,12.4299,700,1,14.6799,1400,2,12.4199,700,1,14.8100,100,1,12.3699,700,1,14.8900,200,2,ARL,302764137
1179,2025-07-17T15:45:07.083732443Z,2025-07-17T15:45:07.083732443Z,10,2,1108,A,A,0,17.7600,100,130,166556,254246327,13.2599,100,1,14.0299,100,1,13.0399,2,1,14.0700,2,1,13.0299,100,1,14.2799,100,1,12.7300,100,1,14.4000,100,1,12.7100,100,1,14.5600,800,2,12.5000,700,1,14.5999,700,1,12.4600,200,2,14.6400,100,1,12.4299,700,1,14.6799,1400,2,12.4199,700,1,14.8100,100,1,12.3699,700,1,14.8900,200,2,ARL,303331309
1180,2025-07-17T15:45:07.085057258Z,2025-07-17T15:45:07.085057258Z,10,2,1108,C,A,0,14.0299,100,130,165267,254246434,13.2599,100,1,14.0700,2,1,13.0399,2,1,14.2799,100,1,13.0299,100,1,14.4000,100,1,12.7300,100,1,14.5600,800,2,12.7100,100,1,14.5999,700,1,12.5000,700,1,14.6400,100,1,12.4600,200,2,14.6799,1400,2,12.4299,700,1,14.8100,100,1,12.4199,700,1,14.8900,200,2,12.3699,700,1,14.9600,100,1,ARL,302466157
1181,2025-07-17T15:45:07.085109545Z,2025-07-17T15:45:07.085109545Z,10,2,1108,A,A,0,14.2599,100,130,165307,254246437,13.2599,100,1,14.0700,2,1,13.0399,2,1,14.2599,100,1,13.0299,100,1,14.2799,100,1,12.7300,100,1,14.4000,100,1,12.7100,100,1,14.5600,800,2,12.5000,700,1,14.5999,700,1,12.4600,200,2,14.6400,100,1,12.4299,700,1,14.6799,1400,2,12.4199,700,1,14.8100,100,1,12.3699,700,1,14.8900,200,2,ARL,303331401
1182,2025-07-17T15:45:07.086368957Z,2025-07-17T15:45:07.086368957Z,10,2,1108,C,A,0,14.6400,100,130,165743,254246501,13.2599,100,1,14.0700,2,1,13.0399,2,1,14.2599,100,1,13.0299,100,1,14.2799,100,1,12.7300,100,1,14.4000,100,1,12.7100,100,1,14.5600,800,2,12.5000,700,1,14.5999,700,1,12.4600,200,2,14.6799,1400,2,12.4299,700,1,14.8100,100,1,12.4199,700,1,14.8900,200,2,12.3699,700,1,14.9600,100,1,ARL,301747005
1183,2025-07-17T15:45:07.086494745Z,2025-07-17T15:45:07.086494745Z,10,2,1108,A,A,0,14.7799,100,130,165580,254246502,13.2599,100,1,14.0700,2,1,13.0399,2,1,14.2599,100,1,13.0299,100,1,14.2799,100,1,12.7300,100,1,14.4000,100,1,12.7100,100,1,14.5600,800,2,12.5000,700,1,14.5999,700,1,12.4600,200,2,14.6799,1400,2,12.4299,700,1,14.7799,100,1,12.4199,700,1,14.8100,100,1,12.3699,700,1,14.8900,200,2,ARL,303331425
1184,2025-07-17T15:45:07.087223859Z,2025-07-17T15:45:07.087223859Z,10,2,1108,C,A,0,15.7699,100,0,165607,254246529,13.2599,100,1,14.0700,2,1,13.0399,2,1,14.2599,100,1,13.0299,100,1,14.2799,100,1,12.7300,100,1,14.4000,100,1,12.7100,100,1,14.5600,800,2,12.5000,700,1,14.5999,700,1,12.4600,200,2,14.6799,1400,2,12.4299,700,1,14.7799,100,1,12.4199,700,1,14.8100,100,1,12.3699,700,1,14.8900,200,2,ARL,302764121
1185,2025-07-17T15:45:07.087223859Z,2025-07-17T15:45:07.087223859Z,10,2,1108,A,A,0,16.0799,100,130,165607,254246529,13.2599,100,1,14.0700,2,1,13.0399,2,1,14.2599,100,1,13.0299,100,1,14.2799,100,1,12.7300,100,1,14.4000,100,1,12.7100,100,1,14.5600,800,2,12.5000,700,1,14.5999,700,1,12.4600,200,2,14.6799,1400,2,12.4299,700,1,14.7799,100,1,12.4199,700,1,14.8100,100,1,12.3699,700,1,14.8900,200,2,ARL,303331429
1186,2025-07-17T15:45:07.133812895Z,2025-07-17T15:45:07.133812895Z,10,2,1108,C,A,0,14.8100,100,0,165593,254250625,13.2599,100,1,14.0700,2,1,13.0399,2,1,14.2599,100,1,13.0299,100,1,14.2799,100,1,12.7300,100,1,14.4000,100,1,12.7100,100,1,14.5600,800,2,12.5000,700,1,14.5999,700,1,12.4600,200,2,14.6799,1400,2,12.4299,700,1,14.7799,100,1,12.4199,700,1,14.8900,200,2,12.3699,700,1,14.9600,100,1,ARL,301747957
1187,2025-07-17T15:45:07.133812895Z,2025-07-17T15:45:07.133812895Z,10,2,1108,A,A,0,14.9600,100,130,165593,254250625,13.2599,100,1,14.0700,2,1,13.0399,2,1,14.2599,100,1,13.0299,100,1,14.2799,100,1,12.7300,100,1,14.4000,100,1,12.7100,100,1,14.5600,800,2,12.5000,700,1,14.5999,700,1,12.4600,200,2,14.6799,1400,2,12.4299,700,1,14.7799,100,1,12.4199,700,1,14.8900,200,2,12.3699,700,1,14.9600,200,2,ARL,303334253
1188,2025-07-17T15:45:07.469796155Z,2025-07-17T15:45:07.469796155Z,10,2,1108,A,A,0,14.0800,100,130,165147,254258029,13.2599,100,1,14.0700,2,1,13.0399,2,1,14.0800,100,1,13.0299,100,1,14.2599,100,1,12.7300,100,1,14.2799,100,1,12.7100,100,1,14.4000,100,1,12.5000,700,1,14.5600,800,2,12.4600,200,2,14.5999,700,1,12.4299,700,1,14.6799,1400,2,12.4199,700,1,14.7799,100,1,12.3699,700,1,14.8900,200,2,ARL,303340405
1189,2025-07-17T15:45:08.094603115Z,2025-07-17T15:45:08.094603115Z,10,2,1108,C,A,0,14.8900,100,0,165437,254266885,13.2599,100,1,14.0700,2,1,13.0399,2,1,14.0800,100,1,13.0299,100,1,14.2599,100,1,12.7300,100,1,14.2799,100,1,12.7100,100,1,14.4000,100,1,12.5000,700,1,14.5600,800,2,12.4600,200,2,14.5999,700,1,12.4299,700,1,14.6799,1400,2,12.4199,700,1,14.7799,100,1,12.3699,700,1,14.8900,100,1,ARL,303330521
1190,2025-07-17T15:45:08.094603115Z,2025-07-17T15:45:08.094603115Z,10,2,1108,A,A,0,15.0999,100,130,165437,254266885,13.2599,100,1,14.0700,2,1,13.0399,2,1,14.0800,100,1,13.0299,100,1,14.2599,100,1,12.7300,100,1,14.2799,100,1,12.7100,100,1,14.4000,100,1,12.5000,700,1,14.5600,800,2,12.4600,200,2,14.5999,700,1,12.4299,700,1,14.6799,1400,2,12.4199,700,1,14.7799,100,1,12.3699,700,1,14.8900,100,1,ARL,303349309
1191,2025-07-17T15:45:08.103141155Z,2025-07-17T15:45:08.103141155Z,10,2,1108,C,A,0,14.8900,100,0,165489,254266971,13.2599,100,1,14.0700,2,1,13.0399,2,1,14.0800,100,1,13.0299,100,1,14.2599,100,1,12.7300,100,1,14.2799,100,1,12.7100,100,1,14.4000,100,1,12.5000,700,1,14.5600,800,2,12.4600,200,2,14.5999,700,1,12.4299,700,1,14.6799,1400,2,12.4199,700,1,14.7799,100,1,12.3699,700,1,14.9600,200,2,ARL,303330477
1192,2025-07-17T15:45:08.103141155Z,2025-07-17T15:45:08.103141155Z,10,2,1108,A,A,0,15.0999,100,130,165489,254266971,13.2599,100,1,14.0700,2,1,13.0399,2,1,14.0800,100,1,13.0299,100,1,14.2599,100,1,12.7300,100,1,14.2799,100,1,12.7100,100,1,14.4000,100,1,12.5000,700,1,14.5600,800,2,12.4600,200,2,14.5999,700,1,12.4299,700,1,14.6799,1400,2,12.4199,700,1,14.7799,100,1,12.3699,700,1,14.9600,200,2,ARL,303349377
1193,2025-07-17T15:45:24.186842413Z,2025-07-17T15:45:24.186842413Z,10,2,1108,C,A,0,15.0999,100,0,165865,254547413,13.2599,100,1,14.0700,2,1,13.0399,2,1,14.0800,100,1,13.0299,100,1,14.2599,100,1,12.7300,100,1,14.2799,100,1,12.7100,100,1,14.4000,100,1,12.5000,700,1,14.5600,800,2,12.4600,200,2,14.5999,700,1,12.4299,700,1,14.6799,1400,2,12.4199,700,1,14.7799,100,1,12.3699,700,1,14.9600,200,2,ARL,303349309
1194,2025-07-17T15:45:24.186842413Z,2025-07-17T15:45:24.186842413Z,10,2,1108,A,A,0,14.8800,100,130,165865,254547413,13.2599,100,1,14.0700,2,1,13.0399,2,1,14.0800,100,1,13.0299,100,1,14.2599,100,1,12.7300,100,1,14.2799,100,1,12.7100,100,1,14.4000,100,1,12.5000,700,1,14.5600,800,2,12.4600,200,2,14.5999,700,1,12.4299,700,1,14.6799,1400,2,12.4199,700,1,14.7799,100,1,12.3699,700,1,14.8800,100,1,ARL,303682385
1195,2025-07-17T15:45:24.187276389Z,2025-07-17T15:45:24.187276389Z,10,2,1108,C,A,0,15.0999,100,0,165503,254547415,13.2599,100,1,14.0700,2,1,13.0399,2,1,14.0800,100,1,13.0299,100,1,14.2599,100,1,12.7300,100,1,14.2799,100,1,12.7100,100,1,14.4000,100,1,12.5000,700,1,14.5600,800,2,12.4600,200,2,14.5999,700,1,12.4299,700,1,14.6799,1400,2,12.4199,700,1,14.7799,100,1,12.3699,700,1,14.8800,100,1,ARL,303349377
1196,2025-07-17T15:45:24.187276389Z,2025-07-17T15:45:24.187276389Z,10,2,1108,A,A,0,14.8800,100,130,165503,254547415,13.2599,100,1,14.0700,2,1,13.0399,2,1,14.0800,100,1,13.0299,100,1,14.2599,100,1,12.7300,100,1,14.2799,100,1,12.7100,100,1,14.4000,100,1,12.5000,700,1,14.5600,800,2,12.4600,200,2,14.5999,700,1,12.4299,700,1,14.6799,1400,2,12.4199,700,1,14.7799,100,1,12.3699,700,1,14.8800,200,2,ARL,303682389
1197,2025-07-17T15:45:37.509289536Z,2025-07-17T15:45:37.509289536Z,10,2,1108,A,A,0,13.9399,15,130,165352,254851462,13.2599,100,1,13.9399,15,1,13.0399,2,1,14.0700,2,1,13.0299,100,1,14.0800,100,1,12.7300,100,1,14.2599,100,1,12.7100,100,1,14.2799,100,1,12.5000,700,1,14.4000,100,1,12.4600,200,2,14.5600,800,2,12.4299,700,1,14.5999,700,1,12.4199,700,1,14.6799,1400,2,12.3699,700,1,14.7799,100,1,ARL,304056997
1198,2025-07-17T15:45:37.997967775Z,2025-07-17T15:45:37.997967775Z,10,2,1108,C,A,0,14.0800,100,0,165722,254864588,13.2599,100,1,13.9399,15,1,13.0399,2,1,14.0700,2,1,13.0299,100,1,14.2599,100,1,12.7300,100,1,14.2799,100,1,12.7100,100,1,14.4000,100,1,12.5000,700,1,14.5600,800,2,12.4600,200,2,14.5999,700,1,12.4299,700,1,14.6799,1400,2,12.4199,700,1,14.7799,100,1,12.3699,700,1,14.8800,200,2,ARL,303340405
1199,2025-07-17T15:45:37.997967775Z,2025-07-17T15:45:37.997967775Z,10,2,1108,A,A,0,13.9499,100,130,165722,254864588,13.2599,100,1,13.9399,15,1,13.0399,2,1,13.9499,100,1,13.0299,100,1,14.0700,2,1,12.7300,100,1,14.2599,100,1,12.7100,100,1,14.2799,100,1,12.5000,700,1,14.4000,100,1,12.4600,200,2,14.5600,800,2,12.4299,700,1,14.5999,700,1,12.4199,700,1,14.6799,1400,2,12.3699,700,1,14.7799,100,1,ARL,304072245
1200,2025-07-17T15:45:44.700428155Z,2025-07-17T15:45:44.700428155Z,10,2,1108,A,A,0,13.8900,15,130,165253,254999429,13.2599,100,1,13.8900,15,1,13.0399,2,1,13.9399,15,1,13.0299,100,1,13.9499,100,1,12.7300,100,1,14.0700,2,1,12.7100,100,1,14.2599,100,1,12.5000,700,1,14.2799,100,1,12.4600,200,2,14.4000,100,1,12.4299,700,1,14.5600,800,2,12.4199,700,1,14.5999,700,1,12.3699,700,1,14.6799,1400,2,ARL,304238913
1201,2025-07-17T15:45:45.262371701Z,2025-07-17T15:45:45.262371701Z,10,2,1108,C,A,0,13.9499,100,0,165421,255010979,13.2599,100,1,13.8900,15,1,13.0399,2,1,13.9399,15,1,13.0299,100,1,14.0700,2,1,12.7300,100,1,14.2599,100,1,12.7100,100,1,14.2799,100,1,12.5000,700,1,14.4000,100,1,12.4600,200,2,14.5600,800,2,12.4299,700,1,14.5999,700,1,12.4199,700,1,14.6799,1400,2,12.3699,700,1,14.7799,100,1,ARL,304072245
1202,2025-07-17T15:45:45.262371701Z,2025-07-17T15:45:45.262371701Z,10,2,1108,A,A,0,13.9000,100,130,165421,255010979,13.2599,100,1,13.8900,15,1,13.0399,2,1,13.9000,100,1,13.0299,100,1,13.9399,15,1,12.7300,100,1,14.0700,2,1,12.7100,100,1,14.2599,100,1,12.5000,700,1,14.2799,100,1,12.4600,200,2,14.4000,100,1,12.4299,700,1,14.5600,800,2,12.4199,700,1,14.5999,700,1,12.3699,700,1,14.6799,1400,2,ARL,304252313
1203,2025-07-17T15:45:45.263123432Z,2025-07-17T15:45:45.263123432Z,10,2,1108,C,A,0,15.0600,100,0,165591,255010987,13.2599,100,1,13.8900,15,1,13.0399,2,1,13.9000,100,1,13.0299,100,1,13.9399,15,1,12.7300,100,1,14.0700,2,1,12.7100,100,1,14.2599,100,1,12.5000,700,1,14.2799,100,1,12.4600,200,2,14.4000,100,1,12.4299,700,1,14.5600,800,2,12.4199,700,1,14.5999,700,1,12.3699,700,1,14.6799,1400,2,ARL,303330485
1204,2025-07-17T15:45:45.263123432Z,2025-07-17T15:45:45.263123432Z,10,2,1108,A,A,0,14.9800,100,130,165591,255010987,13.2599,100,1,13.8900,15,1,13.0399,2,1,13.9000,100,1,13.0299,100,1,13.9399,15,1,12.7300,100,1,14.0700,2,1,12.7100,100,1,14.2599,100,1,12.5000,700,1,14.2799,100,1,12.4600,200,2,14.4000,100,1,12.4299,700,1,14.5600,800,2,12.4199,700,1,14.5999,700,1,12.3699,700,1,14.6799,1400,2,ARL,304252333
1205,2025-07-17T15:45:45.274194870Z,2025-07-17T15:45:45.274194870Z,10,2,1108,C,A,0,14.2599,100,130,165512,255011158,13.2599,100,1,13.8900,15,1,13.0399,2,1,13.9000,100,1,13.0299,100,1,13.9399,15,1,12.7300,100,1,14.0700,2,1,12.7100,100,1,14.2799,100,1,12.5000,700,1,14.4000,100,1,12.4600,200,2,14.5600,800,2,12.4299,700,1,14.5999,700,1,12.4199,700,1,14.6799,1400,2,12.3699,700,1,14.7799,100,1,ARL,303331401
1206,2025-07-17T15:45:45.274245387Z,2025-07-17T15:45:45.274245387Z,10,2,1108,A,A,0,14.1799,100,130,165334,255011161,13.2599,100,1,13.8900,15,1,13.0399,2,1,13.9000,100,1,13.0299,100,1,13.9399,15,1,12.7300,100,1,14.0700,2,1,12.7100,100,1,14.1799,100,1,12.5000,700,1,14.2799,100,1,12.4600,200,2,14.4000,100,1,12.4299,700,1,14.5600,800,2,12.4199,700,1,14.5999,700,1,12.3699,700,1,14.6799,1400,2,ARL,304252469
1207,2025-07-17T15:45:58.419617935Z,2025-07-17T15:45:58.419617935Z,10,2,1108,C,A,0,13.9399,15,130,165398,255183198,13.2599,100,1,13.8900,15,1,13.0399,2,1,13.9000,100,1,13.0299,100,1,14.0700,2,1,12.7300,100,1,14.1799,100,1,12.7100,100,1,14.2799,100,1,12.5000,700,1,14.4000,100,1,12.4600,200,2,14.5600,800,2,12.4299,700,1,14.5999,700,1,12.4199,700,1,14.6799,1400,2,12.3699,700,1,14.7799,100,1,ARL,304056997
1208,2025-07-17T15:45:58.420113307Z,2025-07-17T15:45:58.420113307Z,10,2,1108,C,A,0,14.8800,100,0,165384,255183203,13.2599,100,1,13.8900,15,1,13.0399,2,1,13.9000,100,1,13.0299,100,1,14.0700,2,1,12.7300,100,1,14.1799,100,1,12.7100,100,1,14.2799,100,1,12.5000,700,1,14.4000,100,1,12.4600,200,2,14.5600,800,2,12.4299,700,1,14.5999,700,1,12.4199,700,1,14.6799,1400,2,12.3699,700,1,14.7799,100,1,ARL,303682389
1209,2025-07-17T15:45:58.420113307Z,2025-07-17T15:45:58.420113307Z,10,2,1108,A,A,0,14.7699,100,130,165384,255183203,13.2599,100,1,13.8900,15,1,13.0399,2,1,13.9000,100,1,13.0299,100,1,14.0700,2,1,12.7300,100,1,14.1799,100,1,12.7100,100,1,14.2799,100,1,12.5000,700,1,14.4000,100,1,12.4600,200,2,14.5600,800,2,12.4299,700,1,14.5999,700,1,12.4199,700,1,14.6799,1400,2,12.3699,700,1,14.7699,100,1,ARL,304503585
1210,2025-07-17T15:45:58.420590199Z,2025-07-17T15:45:58.420590199Z,10,2,1108,C,A,0,14.8800,100,0,165690,255183204,13.2599,100,1,13.8900,15,1,13.0399,2,1,13.9000,100,1,13.0299,100,1,14.0700,2,1,12.7300,100,1,14.1799,100,1,12.7100,100,1,14.2799,100,1,12.5000,700,1,14.4000,100,1,12.4600,200,2,14.5600,800,2,12.4299,700,1,14.5999,700,1,12.4199,700,1,14.6799,1400,2,12.3699,700,1,14.7699,100,1,ARL,303682385
1211,2025-07-17T15:45:58.420590199Z,2025-07-17T15:45:58.420590199Z,10,2,1108,A,A,0,14.7699,100,130,165690,255183204,13.2599,100,1,13.8900,15,1,13.0399,2,1,13.9000,100,1,13.0299,100,1,14.0700,2,1,12.7300,100,1,14.1799,100,1,12.7100,100,1,14.2799,100,1,12.5000,700,1,14.4000,100,1,12.4600,200,2,14.5600,800,2,12.4299,700,1,14.5999,700,1,12.4199,700,1,14.6799,1400,2,12.3699,700,1,14.7699,200,2,ARL,304503593
1212,2025-07-17T15:45:58.782726994Z,2025-07-17T15:45:58.782726994Z,10,2,1108,C,A,0,13.8900,15,130,165115,255189425,13.2599,100,1,13.9000,100,1,13.0399,2,1,14.0700,2,1,13.0299,100,1,14.1799,100,1,12.7300,100,1,14.2799,100,1,12.7100,100,1,14.4000,100,1,12.5000,700,1,14.5600,800,2,12.4600,200,2,14.5999,700,1,12.4299,700,1,14.6799,1400,2,12.4199,700,1,14.7699,200,2,12.3699,700,1,14.7799,100,1,ARL,304238913
1213,2025-07-17T15:46:16.782892334Z,2025-07-17T15:46:16.782892334Z,10,2,1108,A,A,0,13.8800,15,130,165282,255552962,13.2599,100,1,13.8800,15,1,13.0399,2,1,13.9000,100,1,13.0299,100,1,14.0700,2,1,12.7300,100,1,14.1799,100,1,12.7100,100,1,14.2799,100,1,12.5000,700,1,14.4000,100,1,12.4600,200,2,14.5600,800,2,12.4299,700,1,14.5999,700,1,12.4199,700,1,14.6799,1400,2,12.3699,700,1,14.7699,200,2,ARL,304949689
1214,2025-07-17T15:46:16.783160795Z,2025-07-17T15:46:16.783160795Z,10,2,1108,C,A,0,13.9000,100,0,165446,255552970,13.2599,100,1,13.8800,15,1,13.0399,2,1,14.0700,2,1,13.0299,100,1,14.1799,100,1,12.7300,100,1,14.2799,100,1,12.7100,100,1,14.4000,100,1,12.5000,700,1,14.5600,800,2,12.4600,200,2,14.5999,700,1,12.4299,700,1,14.6799,1400,2,12.4199,700,1,14.7699,200,2,12.3699,700,1,14.7799,100,1,ARL,304252313
1215,2025-07-17T15:46:16.783160795Z,2025-07-17T15:46:16.783160795Z,10,2,1108,A,A,0,13.8900,100,130,165446,255552970,13.2599,100,1,13.8800,15,1,13.0399,2,1,13.8900,100,1,13.0299,100,1,14.0700,2,1,12.7300,100,1,14.1799,100,1,12.7100,100,1,14.2799,100,1,12.5000,700,1,14.4000,100,1,12.4600,200,2,14.5600,800,2,12.4299,700,1,14.5999,700,1,12.4199,700,1,14.6799,1400,2,12.3699,700,1,14.7699,200,2,ARL,304949697
1216,2025-07-17T15:46:18.782732218Z,2025-07-17T15:46:18.782732218Z,10,2,1108,C,A,0,13.8800,15,130,165352,255587336,13.2599,100,1,13.8900,100,1,13.0399,2,1,14.0700,2,1,13.0299,100,1,14.1799,100,1,12.7300,100,1,14.2799,100,1,12.7100,100,1,14.4000,100,1,12.5000,700,1,14.5600,800,2,12.4600,200,2,14.5999,700,1,12.4299,700,1,14.6799,1400,2,12.4199,700,1,14.7699,200,2,12.3699,700,1,14.7799,100,1,ARL,304949689
1217,2025-07-17T15:46:28.474001551Z,2025-07-17T15:46:28.474001551Z,10,2,1108,C,A,0,13.8900,100,130,165346,255746167,13.2599,100,1,14.0700,2,1,13.0399,2,1,14.1799,100,1,13.0299,100,1,14.2799,100,1,12.7300,100,1,14.4000,100,1,12.7100,100,1,14.5600,800,2,12.5000,700,1,14.5999,700,1,12.4600,200,2,14.6799,1400,2,12.4299,700,1,14.7699,200,2,12.4199,700,1,14.7799,100,1,12.3699,700,1,14.9600,200,2,ARL,304949697
1218,2025-07-17T15:46:28.474561156Z,2025-07-17T15:46:28.474561156Z,10,2,1108,C,A,0,14.7699,100,0,165438,255746173,13.2599,100,1,14.0700,2,1,13.0399,2,1,14.1799,100,1,13.0299,100,1,14.2799,100,1,12.7300,100,1,14.4000,100,1,12.7100,100,1,14.5600,800,2,12.5000,700,1,14.5999,700,1,12.4600,200,2,14.6799,1400,2,12.4299,700,1,14.7699,100,1,12.4199,700,1,14.7799,100,1,12.3699,700,1,14.9600,200,2,ARL,304503593
1219,2025-07-17T15:46:28.474561156Z,2025-07-17T15:46:28.474561156Z,10,2,1108,A,A,0,14.8800,100,130,165438,255746173,13.2599,100,1,14.0700,2,1,13.0399,2,1,14.1799,100,1,13.0299,100,1,14.2799,100,1,12.7300,100,1,14.4000,100,1,12.7100,100,1,14.5600,800,2,12.5000,700,1,14.5999,700,1,12.4600,200,2,14.6799,1400,2,12.4299,700,1,14.7699,100,1,12.4199,700,1,14.7799,100,1,12.3699,700,1,14.8800,100,1,ARL,305184937
1220,2025-07-17T15:46:28.474730225Z,2025-07-17T15:46:28.474730225Z,10,2,1108,C,A,0,14.7699,100,0,166235,255746176,13.2599,100,1,14.0700,2,1,13.0399,2,1,14.1799,100,1,13.0299,100,1,14.2799,100,1,12.7300,100,1,14.4000,100,1,12.7100,100,1,14.5600,800,2,12.5000,700,1,14.5999,700,1,12.4600,200,2,14.6799,1400,2,12.4299,700,1,14.7799,100,1,12.4199,700,1,14.8800,100,1,12.3699,700,1,14.9600,200,2,ARL,304503585
1221,2025-07-17T15:46:28.474730225Z,2025-07-17T15:46:28.474730225Z,10,2,1108,A,A,0,14.8800,100,130,166235,255746176,13.2599,100,1,14.0700,2,1,13.0399,2,1,14.1799,100,1,13.0299,100,1,14.2799,100,1,12.7300,100,1,14.4000,100,1,12.7100,100,1,14.5600,800,2,12.5000,700,1,14.5999,700,1,12.4600,200,2,14.6799,1400,2,12.4299,700,1,14.7799,100,1,12.4199,700,1,14.8800,200,2,12.3699,700,1,14.9600,200,2,ARL,305184953
1222,2025-07-17T15:46:28.474736101Z,2025-07-17T15:46:28.474736101Z,10,2,1108,C,A,0,14.9800,100,0,166053,255746178,13.2599,100,1,14.0700,2,1,13.0399,2,1,14.1799,100,1,13.0299,100,1,14.2799,100,1,12.7300,100,1,14.4000,100,1,12.7100,100,1,14.5600,800,2,12.5000,700,1,14.5999,700,1,12.4600,200,2,14.6799,1400,2,12.4299,700,1,14.7799,100,1,12.4199,700,1,14.8800,200,2,12.3699,700,1,14.9600,200,2,ARL,304252333
1223,2025-07-17T15:46:28.474736101Z,2025-07-17T15:46:28.474736101Z,10,2,1108,A,A,0,15.0299,100,128,166053,255746178,13.2599,100,1,14.0700,2,1,13.0399,2,1,14.1799,100,1,13.0299,100,1,14.2799,100,1,12.7300,100,1,14.4000,100,1,12.7100,100,1,14.5600,800,2,12.5000,700,1,14.5999,700,1,12.4600,200,2,14.6799,1400,2,12.4299,700,1,14.7799,100,1,12.4199,700,1,14.8800,200,2,12.3699,700,1,14.9600,200,2,ARL,305184957
1224,2025-07-17T15:46:28.492716775Z,2025-07-17T15:46:28.492716775Z,10,2,1108,C,A,0,14.1799,100,130,165205,255746619,13.2599,100,1,14.0700,2,1,13.0399,2,1,14.2799,100,1,13.0299,100,1,14.4000,100,1,12.7300,100,1,14.5600,800,2,12.7100,100,1,14.5999,700,1,12.5000,700,1,14.6799,1400,2,12.4600,200,2,14.7799,100,1,12.4299,700,1,14.8800,200,2,12.4199,700,1,14.9600,200,2,12.3699,700,1,15.0299,100,1,ARL,304252469
1225,2025-07-17T15:46:28.492765859Z,2025-07-17T15:46:28.492765859Z,10,2,1108,A,A,0,14.2599,100,130,165420,255746621,13.2599,100,1,14.0700,2,1,13.0399,2,1,14.2599,100,1,13.0299,100,1,14.2799,100,1,12.7300,100,1,14.4000,100,1,12.7100,100,1,14.5600,800,2,12.5000,700,1,14.5999,700,1,12.4600,200,2,14.6799,1400,2,12.4299,700,1,14.7799,100,1,12.4199,700,1,14.8800,200,2,12.3699,700,1,14.9600,200,2,ARL,305185529
1226,2025-07-17T15:46:28.646108242Z,2025-07-17T15:46:28.646108242Z,10,2,1108,A,A,0,14.0800,100,130,165225,255748568,13.2599,100,1,14.0700,2,1,13.0399,2,1,14.0800,100,1,13.0299,100,1,14.2599,100,1,12.7300,100,1,14.2799,100,1,12.7100,100,1,14.4000,100,1,12.5000,700,1,14.5600,800,2,12.4600,200,2,14.5999,700,1,12.4299,700,1,14.6799,1400,2,12.4199,700,1,14.7799,100,1,12.3699,700,1,14.8800,200,2,ARL,305187077
1227,2025-07-17T15:46:57.523859388Z,2025-07-17T15:46:57.523859388Z,10,2,1108,A,A,0,13.9199,15,130,165270,256268482,13.2599,100,1,13.9199,15,1,13.0399,2,1,14.0700,2,1,13.0299,100,1,14.0800,100,1,12.7300,100,1,14.2599,100,1,12.7100,100,1,14.2799,100,1,12.5000,700,1,14.4000,100,1,12.4600,200,2,14.5600,800,2,12.4299,700,1,14.5999,700,1,12.4199,700,1,14.6799,1400,2,12.3699,700,1,14.7799,100,1,ARL,305862145
1228,2025-07-17T15:46:57.932677299Z,2025-07-17T15:46:57.932677299Z,10,2,1108,C,A,0,14.0800,100,0,165695,256280751,13.2599,100,1,13.9199,15,1,13.0399,2,1,14.0700,2,1,13.0299,100,1,14.2599,100,1,12.7300,100,1,14.2799,100,1,12.7100,100,1,14.4000,100,1,12.5000,700,1,14.5600,800,2,12.4600,200,2,14.5999,700,1,12.4299,700,1,14.6799,1400,2,12.4199,700,1,14.7799,100,1,12.3699,700,1,14.8800,200,2,ARL,305187077
1229,2025-07-17T15:46:57.932677299Z,2025-07-17T15:46:57.932677299Z,10,2,1108,A,A,0,13.9299,100,130,165695,256280751,13.2599,100,1,13.9199,15,1,13.0399,2,1,13.9299,100,1,13.0299,100,1,14.0700,2,1,12.7300,100,1,14.2599,100,1,12.7100,100,1,14.2799,100,1,12.5000,700,1,14.4000,100,1,12.4600,200,2,14.5600,800,2,12.4299,700,1,14.5999,700,1,12.4199,700,1,14.6799,1400,2,12.3699,700,1,14.7799,100,1,ARL,305878881
1230,2025-07-17T15:47:06.609290857Z,2025-07-17T15:47:06.609290857Z,10,2,1108,A,A,0,13.8800,15,130,165394,256488374,13.2599,100,1,13.8800,15,1,13.0399,2,1,13.9199,15,1,13.0299,100,1,13.9299,100,1,12.7300,100,1,14.0700,2,1,12.7100,100,1,14.2599,100,1,12.5000,700,1,14.2799,100,1,12.4600,200,2,14.4000,100,1,12.4299,700,1,14.5600,800,2,12.4199,700,1,14.5999,700,1,12.3699,700,1,14.6799,1400,2,ARL,306121113
1231,2025-07-17T15:47:08.787529505Z,2025-07-17T15:47:08.787529505Z,10,2,1108,C,A,0,13.9299,100,0,165639,256532991,13.2599,100,1,13.8800,15,1,13.0399,2,1,13.9199,15,1,13.0299,100,1,14.0700,2,1,12.7300,100,1,14.2599,100,1,12.7100,100,1,14.2799,100,1,12.5000,700,1,14.4000,100,1,12.4600,200,2,14.5600,800,2,12.4299,700,1,14.5999,700,1,12.4199,700,1,14.6799,1400,2,12.3699,700,1,14.7799,100,1,ARL,305878881
1232,2025-07-17T15:47:08.787529505Z,2025-07-17T15:47:08.787529505Z,10,2,1108,A,A,0,13.8900,100,130,165639,256532991,13.2599,100,1,13.8800,15,1,13.0399,2,1,13.8900,100,1,13.0299,100,1,13.9199,15,1,12.7300,100,1,14.0700,2,1,12.7100,100,1,14.2599,100,1,12.5000,700,1,14.2799,100,1,12.4600,200,2,14.4000,100,1,12.4299,700,1,14.5600,800,2,12.4199,700,1,14.5999,700,1,12.3699,700,1,14.6799,1400,2,ARL,306170837
1233,2025-07-17T15:47:08.788275184Z,2025-07-17T15:47:08.788275184Z,10,2,1108,C,A,0,15.0299,100,0,165578,256533005,13.2599,100,1,13.8800,15,1,13.0399,2,1,13.8900,100,1,13.0299,100,1,13.9199,15,1,12.7300,100,1,14.0700,2,1,12.7100,100,1,14.2599,100,1,12.5000,700,1,14.2799,100,1,12.4600,200,2,14.4000,100,1,12.4299,700,1,14.5600,800,2,12.4199,700,1,14.5999,700,1,12.3699,700,1,14.6799,1400,2,ARL,305184957
1234,2025-07-17T15:47:08.788275184Z,2025-07-17T15:47:08.788275184Z,10,2,1108,A,A,0,14.9700,100,130,165578,256533005,13.2599,100,1,13.8800,15,1,13.0399,2,1,13.8900,100,1,13.0299,100,1,13.9199,15,1,12.7300,100,1,14.0700,2,1,12.7100,100,1,14.2599,100,1,12.5000,700,1,14.2799,100,1,12.4600,200,2,14.4000,100,1,12.4299,700,1,14.5600,800,2,12.4199,700,1,14.5999,700,1,12.3699,700,1,14.6799,1400,2,ARL,306170869
1235,2025-07-17T15:47:08.805818249Z,2025-07-17T15:47:08.805818249Z,10,2,1108,C,A,0,14.2599,100,130,165157,256533442,13.2599,100,1,13.8800,15,1,13.0399,2,1,13.8900,100,1,13.0299,100,1,13.9199,15,1,12.7300,100,1,14.0700,2,1,12.7100,100,1,14.2799,100,1,12.5000,700,1,14.4000,100,1,12.4600,200,2,14.5600,800,2,12.4299,700,1,14.5999,700,1,12.4199,700,1,14.6799,1400,2,12.3699,700,1,14.7799,100,1,ARL,305185529
1236,2025-07-17T15:47:08.805868059Z,2025-07-17T15:47:08.805868059Z,10,2,1108,A,A,0,14.1699,100,130,165714,256533443,13.2599,100,1,13.8800,15,1,13.0399,2,1,13.8900,100,1,13.0299,100,1,13.9199,15,1,12.7300,100,1,14.0700,2,1,12.7100,100,1,14.1699,100,1,12.5000,700,1,14.2799,100,1,12.4600,200,2,14.4000,100,1,12.4299,700,1,14.5600,800,2,12.4199,700,1,14.5999,700,1,12.3699,700,1,14.6799,1400,2,ARL,306171457
1237,2025-07-17T15:47:13.121288953Z,2025-07-17T15:47:13.121288953Z,10,2,1108,C,A,0,13.8800,15,130,165402,256612694,13.2599,100,1,13.8900,100,1,13.0399,2,1,13.9199,15,1,13.0299,100,1,14.0700,2,1,12.7300,100,1,14.1699,100,1,12.7100,100,1,14.2799,100,1,12.5000,700,1,14.4000,100,1,12.4600,200,2,14.5600,800,2,12.4299,700,1,14.5999,700,1,12.4199,700,1,14.6799,1400,2,12.3699,700,1,14.7799,100,1,ARL,306121113
1238,2025-07-17T15:47:13.122396816Z,2025-07-17T15:47:13.122396816Z,10,2,1108,C,A,0,13.9199,15,130,165717,256612757,13.2599,100,1,13.8900,100,1,13.0399,2,1,14.0700,2,1,13.0299,100,1,14.1699,100,1,12.7300,100,1,14.2799,100,1,12.7100,100,1,14.4000,100,1,12.5000,700,1,14.5600,800,2,12.4600,200,2,14.5999,700,1,12.4299,700,1,14.6799,1400,2,12.4199,700,1,14.7799,100,1,12.3699,700,1,14.8800,200,2,ARL,305862145
1239,2025-07-17T15:47:24.786310694Z,2025-07-17T15:47:24.786310694Z,10,2,1108,A,A,0,13.8699,15,130,165572,256812416,13.2599,100,1,13.8699,15,1,13.0399,2,1,13.8900,100,1,13.0299,100,1,14.0700,2,1,12.7300,100,1,14.1699,100,1,12.7100,100,1,14.2799,100,1,12.5000,700,1,14.4000,100,1,12.4600,200,2,14.5600,800,2,12.4299,700,1,14.5999,700,1,12.4199,700,1,14.6799,1400,2,12.3699,700,1,14.7799,100,1,ARL,306519385
1240,2025-07-17T15:47:24.786580061Z,2025-07-17T15:47:24.786580061Z,10,2,1108,C,A,0,13.8900,100,0,165596,256812420,13.2599,100,1,13.8699,15,1,13.0399,2,1,14.0700,2,1,13.0299,100,1,14.1699,100,1,12.7300,100,1,14.2799,100,1,12.7100,100,1,14.4000,100,1,12.5000,700,1,14.5600,800,2,12.4600,200,2,14.5999,700,1,12.4299,700,1,14.6799,1400,2,12.4199,700,1,14.7799,100,1,12.3699,700,1,14.8800,200,2,ARL,306170837
1241,2025-07-17T15:47:24.786580061Z,2025-07-17T15:47:24.786580061Z,10,2,1108,A,A,0,13.8800,100,130,165596,256812420,13.2599,100,1,13.8699,15,1,13.0399,2,1,13.8800,100,1,13.0299,100,1,14.0700,2,1,12.7300,100,1,14.1699,100,1,12.7100,100,1,14.2799,100,1,12.5000,700,1,14.4000,100,1,12.4600,200,2,14.5600,800,2,12.4299,700,1,14.5999,700,1,12.4199,700,1,14.6799,1400,2,12.3699,700,1,14.7799,100,1,ARL,306519397
1242,2025-07-17T15:47:24.786759805Z,2025-07-17T15:47:24.786759805Z,10,2,1108,C,A,0,14.8800,100,0,165924,256812422,13.2599,100,1,13.8699,15,1,13.0399,2,1,13.8800,100,1,13.0299,100,1,14.0700,2,1,12.7300,100,1,14.1699,100,1,12.7100,100,1,14.2799,100,1,12.5000,700,1,14.4000,100,1,12.4600,200,2,14.5600,800,2,12.4299,700,1,14.5999,700,1,12.4199,700,1,14.6799,1400,2,12.3699,700,1,14.7799,100,1,ARL,305184937
1243,2025-07-17T15:47:24.786759805Z,2025-07-17T15:47:24.786759805Z,10,2,1108,A,A,0,14.7699,100,130,165924,256812422,13.2599,100,1,13.8699,15,1,13.0399,2,1,13.8800,100,1,13.0299,100,1,14.0700,2,1,12.7300,100,1,14.1699,100,1,12.7100,100,1,14.2799,100,1,12.5000,700,1,14.4000,100,1,12.4600,200,2,14.5600,800,2,12.4299,700,1,14.5999,700,1,12.4199,700,1,14.6799,1400,2,12.3699,700,1,14.7699,100,1,ARL,306519409
1244,2025-07-17T15:47:24.800449950Z,2025-07-17T15:47:24.800449950Z,10,2,1108,C,A,0,14.8800,100,0,166054,256812578,13.2599,100,1,13.8699,15,1,13.0399,2,1,13.8800,100,1,13.0299,100,1,14.0700,2,1,12.7300,100,1,14.1699,100,1,12.7100,100,1,14.2799,100,1,12.5000,700,1,14.4000,100,1,12.4600,200,2,14.5600,800,2,12.4299,700,1,14.5999,700,1,12.4199,700,1,14.6799,1400,2,12.3699,700,1,14.7699,100,1,ARL,305184953
1245,2025-07-17T15:47:24.800449950Z,2025-07-17T15:47:24.800449950Z,10,2,1108,A,A,0,14.7500,100,130,166054,256812578,13.2599,100,1,13.8699,15,1,13.0399,2,1,13.8800,100,1,13.0299,100,1,14.0700,2,1,12.7300,100,1,14.1699,100,1,12.7100,100,1,14.2799,100,1,12.5000,700,1,14.4000,100,1,12.4600,200,2,14.5600,800,2,12.4299,700,1,14.5999,700,1,12.4199,700,1,14.6799,1400,2,12.3699,700,1,14.7500,100,1,ARL,306519741
1246,2025-07-17T15:47:27.860107552Z,2025-07-17T15:47:27.860107552Z,10,2,1108,A,A,0,13.8300,15,130,165340,256866835,13.2599,100,1,13.8300,15,1,13.0399,2,1,13.8699,15,1,13.0299,100,1,13.8800,100,1,12.7300,100,1,14.0700,2,1,12.7100,100,1,14.1699,100,1,12.5000,700,1,14.2799,100,1,12.4600,200,2,14.4000,100,1,12.4299,700,1,14.5600,800,2,12.4199,700,1,14.5999,700,1,12.3699,700,1,14.6799,1400,2,ARL,306587393
1247,2025-07-17T15:47:31.406863918Z,2025-07-17T15:47:31.406863918Z,10,2,1108,C,A,0,13.8800,100,0,165394,256910124,13.2599,100,1,13.8300,15,1,13.0399,2,1,13.8699,15,1,13.0299,100,1,14.0700,2,1,12.7300,100,1,14.1699,100,1,12.7100,100,1,14.2799,100,1,12.5000,700,1,14.4000,100,1,12.4600,200,2,14.5600,800,2,12.4299,700,1,14.5999,700,1,12.4199,700,1,14.6799,1400,2,12.3699,700,1,14.7500,100,1,ARL,306519397
1248,2025-07-17T15:47:31.406863918Z,2025-07-17T15:47:31.406863918Z,10,2,1108,A,A,0,13.8399,100,130,165394,256910124,13.2599,100,1,13.8300,15,1,13.0399,2,1,13.8399,100,1,13.0299,100,1,13.8699,15,1,12.7300,100,1,14.0700,2,1,12.7100,100,1,14.1699,100,1,12.5000,700,1,14.2799,100,1,12.4600,200,2,14.4000,100,1,12.4299,700,1,14.5600,800,2,12.4199,700,1,14.5999,700,1,12.3699,700,1,14.6799,1400,2,ARL,306647425
1249,2025-07-17T15:47:31.407605685Z,2025-07-17T15:47:31.407605685Z,10,2,1108,C,A,0,14.9700,100,0,165425,256910129,13.2599,100,1,13.8300,15,1,13.0399,2,1,13.8399,100,1,13.0299,100,1,13.8699,15,1,12.7300,100,1,14.0700,2,1,12.7100,100,1,14.1699,100,1,12.5000,700,1,14.2799,100,1,12.4600,200,2,14.4000,100,1,12.4299,700,1,14.5600,800,2,12.4199,700,1,14.5999,700,1,12.3699,700,1,14.6799,1400,2,ARL,306170869
1250,2025-07-17T15:47:31.407605685Z,2025-07-17T15:47:31.407605685Z,10,2,1108,A,A,0,14.9100,100,130,165425,256910129,13.2599,100,1,13.8300,15,1,13.0399,2,1,13.8399,100,1,13.0299,100,1,13.8699,15,1,12.7300,100,1,14.0700,2,1,12.7100,100,1,14.1699,100,1,12.5000,700,1,14.2799,100,1,12.4600,200,2,14.4000,100,1,12.4299,700,1,14.5600,800,2,12.4199,700,1,14.5999,700,1,12.3699,700,1,14.6799,1400,2,ARL,306647445
1251,2025-07-17T15:47:31.413325908Z,2025-07-17T15:47:31.413325908Z,10,2,1108,C,A,0,14.7799,100,0,165569,256910184,13.2599,100,1,13.8300,15,1,13.0399,2,1,13.8399,100,1,13.0299,100,1,13.8699,15,1,12.7300,100,1,14.0700,2,1,12.7100,100,1,14.1699,100,1,12.5000,700,1,14.2799,100,1,12.4600,200,2,14.4000,100,1,12.4299,700,1,14.5600,800,2,12.4199,700,1,14.5999,700,1,12.3699,700,1,14.6799,1400,2,ARL,303331425
1252,2025-07-17T15:47:31.413325908Z,2025-07-17T15:47:31.413325908Z,10,2,1108,A,A,0,14.6400,100,130,165569,256910184,13.2599,100,1,13.8300,15,1,13.0399,2,1,13.8399,100,1,13.0299,100,1,13.8699,15,1,12.7300,100,1,14.0700,2,1,12.7100,100,1,14.1699,100,1,12.5000,700,1,14.2799,100,1,12.4600,200,2,14.4000,100,1,12.4299,700,1,14.5600,800,2,12.4199,700,1,14.5999,700,1,12.3699,700,1,14.6400,100,1,ARL,306647521
1253,2025-07-17T15:47:31.433320466Z,2025-07-17T15:47:31.433320466Z,10,2,1108,C,A,0,14.9600,100,0,165817,256910721,13.2599,100,1,13.8300,15,1,13.0399,2,1,13.8399,100,1,13.0299,100,1,13.8699,15,1,12.7300,100,1,14.0700,2,1,12.7100,100,1,14.1699,100,1,12.5000,700,1,14.2799,100,1,12.4600,200,2,14.4000,100,1,12.4299,700,1,14.5600,800,2,12.4199,700,1,14.5999,700,1,12.3699,700,1,14.6400,100,1,ARL,303330509
1254,2025-07-17T15:47:31.433320466Z,2025-07-17T15:47:31.433320466Z,10,2,1108,A,A,0,14.8100,100,130,165817,256910721,13.2599,100,1,13.8300,15,1,13.0399,2,1,13.8399,100,1,13.0299,100,1,13.8699,15,1,12.7300,100,1,14.0700,2,1,12.7100,100,1,14.1699,100,1,12.5000,700,1,14.2799,100,1,12.4600,200,2,14.4000,100,1,12.4299,700,1,14.5600,800,2,12.4199,700,1,14.5999,700,1,12.3699,700,1,14.6400,100,1,ARL,306649913
1255,2025-07-17T15:47:31.573963059Z,2025-07-17T15:47:31.573963059Z,10,2,1108,C,A,0,16.0799,100,0,165445,256912087,13.2599,100,1,13.8300,15,1,13.0399,2,1,13.8399,100,1,13.0299,100,1,13.8699,15,1,12.7300,100,1,14.0700,2,1,12.7100,100,1,14.1699,100,1,12.5000,700,1,14.2799,100,1,12.4600,200,2,14.4000,100,1,12.4299,700,1,14.5600,800,2,12.4199,700,1,14.5999,700,1,12.3699,700,1,14.6400,100,1,ARL,303331429
1256,2025-07-17T15:47:31.573963059Z,2025-07-17T15:47:31.573963059Z,10,2,1108,A,A,0,15.9199,100,130,165445,256912087,13.2599,100,1,13.8300,15,1,13.0399,2,1,13.8399,100,1,13.0299,100,1,13.8699,15,1,12.7300,100,1,14.0700,2,1,12.7100,100,1,14.1699,100,1,12.5000,700,1,14.2799,100,1,12.4600,200,2,14.4000,100,1,12.4299,700,1,14.5600,800,2,12.4199,700,1,14.5999,700,1,12.3699,700,1,14.6400,100,1,ARL,306652001
1257,2025-07-17T15:47:31.575209032Z,2025-07-17T15:47:31.575209032Z,10,2,1108,C,A,0,17.7600,100,0,165449,256912094,13.2599,100,1,13.8300,15,1,13.0399,2,1,13.8399,100,1,13.0299,100,1,13.8699,15,1,12.7300,100,1,14.0700,2,1,12.7100,100,1,14.1699,100,1,12.5000,700,1,14.2799,100,1,12.4600,200,2,14.4000,100,1,12.4299,700,1,14.5600,800,2,12.4199,700,1,14.5999,700,1,12.3699,700,1,14.6400,100,1,ARL,303331309
1258,2025-07-17T15:47:31.575209032Z,2025-07-17T15:47:31.575209032Z,10,2,1108,A,A,0,17.5799,100,130,165449,256912094,13.2599,100,1,13.8300,15,1,13.0399,2,1,13.8399,100,1,13.0299,100,1,13.8699,15,1,12.7300,100,1,14.0700,2,1,12.7100,100,1,14.1699,100,1,12.5000,700,1,14.2799,100,1,12.4600,200,2,14.4000,100,1,12.4299,700,1,14.5600,800,2,12.4199,700,1,14.5999,700,1,12.3699,700,1,14.6400,100,1,ARL,306652017
1259,2025-07-17T15:47:31.739930142Z,2025-07-17T15:47:31.739930142Z,10,2,1108,C,A,0,14.9600,100,0,165572,256914067,13.2599,100,1,13.8300,15,1,13.0399,2,1,13.8399,100,1,13.0299,100,1,13.8699,15,1,12.7300,100,1,14.0700,2,1,12.7100,100,1,14.1699,100,1,12.5000,700,1,14.2799,100,1,12.4600,200,2,14.4000,100,1,12.4299,700,1,14.5600,800,2,12.4199,700,1,14.5999,700,1,12.3699,700,1,14.6400,100,1,ARL,303334253
1260,2025-07-17T15:47:31.739930142Z,2025-07-17T15:47:31.739930142Z,10,2,1108,A,A,0,14.8100,100,130,165572,256914067,13.2599,100,1,13.8300,15,1,13.0399,2,1,13.8399,100,1,13.0299,100,1,13.8699,15,1,12.7300,100,1,14.0700,2,1,12.7100,100,1,14.1699,100,1,12.5000,700,1,14.2799,100,1,12.4600,200,2,14.4000,100,1,12.4299,700,1,14.5600,800,2,12.4199,700,1,14.5999,700,1,12.3699,700,1,14.6400,100,1,ARL,306653713
1261,2025-07-17T15:47:37.159424166Z,2025-07-17T15:47:37.159424166Z,10,2,1108,C,A,0,13.8699,15,130,165638,256983942,13.2599,100,1,13.8300,15,1,13.0399,2,1,13.8399,100,1,13.0299,100,1,14.0700,2,1,12.7300,100,1,14.1699,100,1,12.7100,100,1,14.2799,100,1,12.5000,700,1,14.4000,100,1,12.4600,200,2,14.5600,800,2,12.4299,700,1,14.5999,700,1,12.4199,700,1,14.6400,100,1,12.3699,700,1,14.6799,1400,2,ARL,306519385
1262,2025-07-17T15:47:37.171834941Z,2025-07-17T15:47:37.171834941Z,10,2,1108,A,A,0,13.8499,100,130,165499,256984053,13.2599,100,1,13.8300,15,1,13.0399,2,1,13.8399,100,1,13.0299,100,1,13.8499,100,1,12.7300,100,1,14.0700,2,1,12.7100,100,1,14.1699,100,1,12.5000,700,1,14.2799,100,1,12.4600,200,2,14.4000,100,1,12.4299,700,1,14.5600,800,2,12.4199,700,1,14.5999,700,1,12.3699,700,1,14.6400,100,1,ARL,306749753
1263,2025-07-17T15:47:38.161015969Z,2025-07-17T15:47:38.161015969Z,10,2,1108,A,A,0,13.7899,15,130,165314,256998606,13.2599,100,1,13.7899,15,1,13.0399,2,1,13.8300,15,1,13.0299,100,1,13.8399,100,1,12.7300,100,1,13.8499,100,1,12.7100,100,1,14.0700,2,1,12.5000,700,1,14.1699,100,1,12.4600,200,2,14.2799,100,1,12.4299,700,1,14.4000,100,1,12.4199,700,1,14.5600,800,2,12.3699,700,1,14.5999,700,1,ARL,306770041
1264,2025-07-17T15:47:38.794795887Z,2025-07-17T15:47:38.794795887Z,10,2,1108,C,A,0,13.8399,100,0,166358,257010989,13.2599,100,1,13.7899,15,1,13.0399,2,1,13.8300,15,1,13.0299,100,1,13.8499,100,1,12.7300,100,1,14.0700,2,1,12.7100,100,1,14.1699,100,1,12.5000,700,1,14.2799,100,1,12.4600,200,2,14.4000,100,1,12.4299,700,1,14.5600,800,2,12.4199,700,1,14.5999,700,1,12.3699,700,1,14.6400,100,1,ARL,306647425
1265,2025-07-17T15:47:38.794795887Z,2025-07-17T15:47:38.794795887Z,10,2,1108,A,A,0,13.8000,100,128,166358,257010989,13.2599,100,1,13.7899,15,1,13.0399,2,1,13.8000,100,1,13.0299,100,1,13.8300,15,1,12.7300,100,1,13.8499,100,1,12.7100,100,1,14.0700,2,1,12.5000,700,1,14.1699,100,1,12.4600,200,2,14.2799,100,1,12.4299,700,1,14.4000,100,1,12.4199,700,1,14.5600,800,2,12.3699,700,1,14.5999,700,1,ARL,306784133
1266,2025-07-17T15:47:38.795557785Z,2025-07-17T15:47:38.795557785Z,10,2,1108,C,A,0,14.9100,100,0,165785,257011058,13.2599,100,1,13.7899,15,1,13.0399,2,1,13.8000,100,1,13.0299,100,1,13.8300,15,1,12.7300,100,1,13.8499,100,1,12.7100,100,1,14.0700,2,1,12.5000,700,1,14.1699,100,1,12.4600,200,2,14.2799,100,1,12.4299,700,1,14.4000,100,1,12.4199,700,1,14.5600,800,2,12.3699,700,1,14.5999,700,1,ARL,306647445
1267,2025-07-17T15:47:38.795557785Z,2025-07-17T15:47:38.795557785Z,10,2,1108,A,A,0,14.8699,100,130,165785,257011058,13.2599,100,1,13.7899,15,1,13.0399,2,1,13.8000,100,1,13.0299,100,1,13.8300,15,1,12.7300,100,1,13.8499,100,1,12.7100,100,1,14.0700,2,1,12.5000,700,1,14.1699,100,1,12.4600,200,2,14.2799,100,1,12.4299,700,1,14.4000,100,1,12.4199,700,1,14.5600,800,2,12.3699,700,1,14.5999,700,1,ARL,306784201
1268,2025-07-17T15:47:38.804458744Z,2025-07-17T15:47:38.804458744Z,10,2,1108,C,A,0,14.1699,100,130,165514,257011716,13.2599,100,1,13.7899,15,1,13.0399,2,1,13.8000,100,1,13.0299,100,1,13.8300,15,1,12.7300,100,1,13.8499,100,1,12.7100,100,1,14.0700,2,1,12.5000,700,1,14.2799,100,1,12.4600,200,2,14.4000,100,1,12.4299,700,1,14.5600,800,2,12.4199,700,1,14.5999,700,1,12.3699,700,1,14.6400,100,1,ARL,306171457
1269,2025-07-17T15:47:38.804513793Z,2025-07-17T15:47:38.804513793Z,10,2,1108,A,A,0,14.0800,100,130,165799,257011717,13.2599,100,1,13.7899,15,1,13.0399,2,1,13.8000,100,1,13.0299,100,1,13.8300,15,1,12.7300,100,1,13.8499,100,1,12.7100,100,1,14.0700,2,1,12.5000,700,1,14.0800,100,1,12.4600,200,2,14.2799,100,1,12.4299,700,1,14.4000,100,1,12.4199,700,1,14.5600,800,2,12.3699,700,1,14.5999,700,1,ARL,306784853
1270,2025-07-17T15:47:39.092305947Z,2025-07-17T15:47:39.092305947Z,10,2,1108,C,A,0,13.7899,15,130,166112,257018687,13.2599,100,1,13.8000,100,1,13.0399,2,1,13.8300,15,1,13.0299,100,1,13.8499,100,1,12.7300,100,1,14.0700,2,1,12.7100,100,1,14.0800,100,1,12.5000,700,1,14.2799,100,1,12.4600,200,2,14.4000,100,1,12.4299,700,1,14.5600,800,2,12.4199,700,1,14.5999,700,1,12.3699,700,1,14.6400,100,1,ARL,306770041
1271,2025-07-17T15:47:39.095755335Z,2025-07-17T15:47:39.095755335Z,10,2,1108,C,A,0,13.8300,15,130,165524,257018796,13.2599,100,1,13.8000,100,1,13.0399,2,1,13.8499,100,1,13.0299,100,1,14.0700,2,1,12.7300,100,1,14.0800,100,1,12.7100,100,1,14.2799,100,1,12.5000,700,1,14.4000,100,1,12.4600,200,2,14.5600,800,2,12.4299,700,1,14.5999,700,1,12.4199,700,1,14.6400,100,1,12.3699,700,1,14.6799,1400,2,ARL,306587393
1272,2025-07-17T15:48:08.909201576Z,2025-07-17T15:48:08.909201576Z,10,2,1108,A,A,0,13.8300,100,130,165329,257603755,13.2599,100,1,13.8000,100,1,13.0399,2,1,13.8300,100,1,13.0299,100,1,13.8499,100,1,12.7300,100,1,14.0700,2,1,12.7100,100,1,14.0800,100,1,12.5000,700,1,14.2799,100,1,12.4600,200,2,14.4000,100,1,12.4299,700,1,14.5600,800,2,12.4199,700,1,14.5999,700,1,12.3699,700,1,14.6400,100,1,ARL,307567929
1273,2025-07-17T15:48:08.916555821Z,2025-07-17T15:48:08.916555821Z,10,2,1108,C,A,0,13.8499,100,130,165277,257604057,13.2599,100,1,13.8000,100,1,13.0399,2,1,13.8300,100,1,13.0299,100,1,14.0700,2,1,12.7300,100,1,14.0800,100,1,12.7100,100,1,14.2799,100,1,12.5000,700,1,14.4000,100,1,12.4600,200,2,14.5600,800,2,12.4299,700,1,14.5999,700,1,12.4199,700,1,14.6400,100,1,12.3699,700,1,14.6799,1400,2,ARL,306749753
1274,2025-07-17T15:48:09.653308042Z,2025-07-17T15:48:09.653308042Z,10,2,1108,A,A,0,13.7799,15,130,165423,257621095,13.2599,100,1,13.7799,15,1,13.0399,2,1,13.8000,100,1,13.0299,100,1,13.8300,100,1,12.7300,100,1,14.0700,2,1,12.7100,100,1,14.0800,100,1,12.5000,700,1,14.2799,100,1,12.4600,200,2,14.4000,100,1,12.4299,700,1,14.5600,800,2,12.4199,700,1,14.5999,700,1,12.3699,700,1,14.6400,100,1,ARL,307587873
1275,2025-07-17T15:48:11.166517494Z,2025-07-17T15:48:11.166517494Z,10,2,1108,C,A,0,13.7799,15,128,171760,257644020,13.2599,100,1,13.8000,100,1,13.0399,2,1,13.8300,100,1,13.0299,100,1,14.0700,2,1,12.7300,100,1,14.0800,100,1,12.7100,100,1,14.2799,100,1,12.5000,700,1,14.4000,100,1,12.4600,200,2,14.5600,800,2,12.4299,700,1,14.5999,700,1,12.4199,700,1,14.6400,100,1,12.3699,700,1,14.6799,1400,2,ARL,307587873
1276,2025-07-17T15:48:13.508913083Z,2025-07-17T15:48:13.508913083Z,10,2,1108,A,A,0,13.7799,15,130,165470,257727039,13.2599,100,1,13.7799,15,1,13.0399,2,1,13.8000,100,1,13.0299,100,1,13.8300,100,1,12.7300,100,1,14.0700,2,1,12.7100,100,1,14.0800,100,1,12.5000,700,1,14.2799,100,1,12.4600,200,2,14.4000,100,1,12.4299,700,1,14.5600,800,2,12.4199,700,1,14.5999,700,1,12.3699,700,1,14.6400,100,1,ARL,307714769
1277,2025-07-17T15:48:13.525788139Z,2025-07-17T15:48:13.525788139Z,10,2,1108,A,A,0,13.8100,100,130,165406,257727301,13.2599,100,1,13.7799,15,1,13.0399,2,1,13.8000,100,1,13.0299,100,1,13.8100,100,1,12.7300,100,1,13.8300,100,1,12.7100,100,1,14.0700,2,1,12.5000,700,1,14.0800,100,1,12.4600,200,2,14.2799,100,1,12.4299,700,1,14.4000,100,1,12.4199,700,1,14.5600,800,2,12.3699,700,1,14.5999,700,1,ARL,307715101
1278,2025-07-17T15:48:13.532443045Z,2025-07-17T15:48:13.532443045Z,10,2,1108,C,A,0,13.8300,100,130,165829,257727457,13.2599,100,1,13.7799,15,1,13.0399,2,1,13.8000,100,1,13.0299,100,1,13.8100,100,1,12.7300,100,1,14.0700,2,1,12.7100,100,1,14.0800,100,1,12.5000,700,1,14.2799,100,1,12.4600,200,2,14.4000,100,1,12.4299,700,1,14.5600,800,2,12.4199,700,1,14.5999,700,1,12.3699,700,1,14.6400,100,1,ARL,307567929
1279,2025-07-17T15:48:15.568378275Z,2025-07-17T15:48:15.568378275Z,10,2,1108,C,A,0,13.8000,100,0,165879,257757458,13.2599,100,1,13.7799,15,1,13.0399,2,1,13.8100,100,1,13.0299,100,1,14.0700,2,1,12.7300,100,1,14.0800,100,1,12.7100,100,1,14.2799,100,1,12.5000,700,1,14.4000,100,1,12.4600,200,2,14.5600,800,2,12.4299,700,1,14.5999,700,1,12.4199,700,1,14.6400,100,1,12.3699,700,1,14.6799,1400,2,ARL,306784133
1280,2025-07-17T15:48:15.568378275Z,2025-07-17T15:48:15.568378275Z,10,2,1108,A,A,0,13.7899,100,130,165879,257757458,13.2599,100,1,13.7799,15,1,13.0399,2,1,13.7899,100,1,13.0299,100,1,13.8100,100,1,12.7300,100,1,14.0700,2,1,12.7100,100,1,14.0800,100,1,12.5000,700,1,14.2799,100,1,12.4600,200,2,14.4000,100,1,12.4299,700,1,14.5600,800,2,12.4199,700,1,14.5999,700,1,12.3699,700,1,14.6400,100,1,ARL,307753241
1281,2025-07-17T15:48:24.009190157Z,2025-07-17T15:48:24.009190157Z,10,2,1108,A,A,0,13.7500,15,130,165189,257928318,13.2599,100,1,13.7500,15,1,13.0399,2,1,13.7799,15,1,13.0299,100,1,13.7899,100,1,12.7300,100,1,13.8100,100,1,12.7100,100,1,14.0700,2,1,12.5000,700,1,14.0800,100,1,12.4600,200,2,14.2799,100,1,12.4299,700,1,14.4000,100,1,12.4199,700,1,14.5600,800,2,12.3699,700,1,14.5999,700,1,ARL,307964605
1282,2025-07-17T15:48:24.009357442Z,2025-07-17T15:48:24.009357442Z,10,2,1108,A,A,0,13.7899,100,130,165191,257928319,13.2599,100,1,13.7500,15,1,13.0399,2,1,13.7799,15,1,13.0299,100,1,13.7899,200,2,12.7300,100,1,13.8100,100,1,12.7100,100,1,14.0700,2,1,12.5000,700,1,14.0800,100,1,12.4600,200,2,14.2799,100,1,12.4299,700,1,14.4000,100,1,12.4199,700,1,14.5600,800,2,12.3699,700,1,14.5999,700,1,ARL,307964609
1283,2025-07-17T15:48:24.009778967Z,2025-07-17T15:48:24.009778967Z,10,2,1108,C,A,0,13.7899,100,0,165414,257928325,13.2599,100,1,13.7500,15,1,13.0399,2,1,13.7799,15,1,13.0299,100,1,13.7899,100,1,12.7300,100,1,13.8100,100,1,12.7100,100,1,14.0700,2,1,12.5000,700,1,14.0800,100,1,12.4600,200,2,14.2799,100,1,12.4299,700,1,14.4000,100,1,12.4199,700,1,14.5600,800,2,12.3699,700,1,14.5999,700,1,ARL,307753241
1284,2025-07-17T15:48:24.009778967Z,2025-07-17T15:48:24.009778967Z,10,2,1108,A,A,0,13.7599,100,130,165414,257928325,13.2599,100,1,13.7500,15,1,13.0399,2,1,13.7599,100,1,13.0299,100,1,13.7799,15,1,12.7300,100,1,13.7899,100,1,12.7100,100,1,13.8100,100,1,12.5000,700,1,14.0700,2,1,12.4600,200,2,14.0800,100,1,12.4299,700,1,14.2799,100,1,12.4199,700,1,14.4000,100,1,12.3699,700,1,14.5600,800,2,ARL,307964621
1285,2025-07-17T15:48:24.009808793Z,2025-07-17T15:48:24.009808793Z,10,2,1108,C,A,0,13.8100,100,130,165373,257928326,13.2599,100,1,13.7500,15,1,13.0399,2,1,13.7599,100,1,13.0299,100,1,13.7799,15,1,12.7300,100,1,13.7899,100,1,12.7100,100,1,14.0700,2,1,12.5000,700,1,14.0800,100,1,12.4600,200,2,14.2799,100,1,12.4299,700,1,14.4000,100,1,12.4199,700,1,14.5600,800,2,12.3699,700,1,14.5999,700,1,ARL,307715101
1286,2025-07-17T15:48:24.010390029Z,2025-07-17T15:48:24.010390029Z,10,2,1108,C,A,0,14.7699,100,0,165387,257928333,13.2599,100,1,13.7500,15,1,13.0399,2,1,13.7599,100,1,13.0299,100,1,13.7799,15,1,12.7300,100,1,13.7899,100,1,12.7100,100,1,14.0700,2,1,12.5000,700,1,14.0800,100,1,12.4600,200,2,14.2799,100,1,12.4299,700,1,14.4000,100,1,12.4199,700,1,14.5600,800,2,12.3699,700,1,14.5999,700,1,ARL,306519409
1287,2025-07-17T15:48:24.010390029Z,2025-07-17T15:48:24.010390029Z,10,2,1108,A,A,0,14.6500,100,130,165387,257928333,13.2599,100,1,13.7500,15,1,13.0399,2,1,13.7599,100,1,13.0299,100,1,13.7799,15,1,12.7300,100,1,13.7899,100,1,12.7100,100,1,14.0700,2,1,12.5000,700,1,14.0800,100,1,12.4600,200,2,14.2799,100,1,12.4299,700,1,14.4000,100,1,12.4199,700,1,14.5600,800,2,12.3699,700,1,14.5999,700,1,ARL,307964661
1288,2025-07-17T15:48:24.010512050Z,2025-07-17T15:48:24.010512050Z,10,2,1108,C,A,0,14.8699,100,0,165472,257928340,13.2599,100,1,13.7500,15,1,13.0399,2,1,13.7599,100,1,13.0299,100,1,13.7799,15,1,12.7300,100,1,13.7899,100,1,12.7100,100,1,14.0700,2,1,12.5000,700,1,14.0800,100,1,12.4600,200,2,14.2799,100,1,12.4299,700,1,14.4000,100,1,12.4199,700,1,14.5600,800,2,12.3699,700,1,14.5999,700,1,ARL,306784201
1289,2025-07-17T15:48:24.010512050Z,2025-07-17T15:48:24.010512050Z,10,2,1108,A,A,0,14.8300,100,130,165472,257928340,13.2599,100,1,13.7500,15,1,13.0399,2,1,13.7599,100,1,13.0299,100,1,13.7799,15,1,12.7300,100,1,13.7899,100,1,12.7100,100,1,14.0700,2,1,12.5000,700,1,14.0800,100,1,12.4600,200,2,14.2799,100,1,12.4299,700,1,14.4000,100,1,12.4199,700,1,14.5600,800,2,12.3699,700,1,14.5999,700,1,ARL,307964665
1290,2025-07-17T15:48:42.009788565Z,2025-07-17T15:48:42.009788565Z,10,2,1108,C,A,0,13.7799,15,130,165481,258199397,13.2599,100,1,13.7500,15,1,13.0399,2,1,13.7599,100,1,13.0299,100,1,13.7899,100,1,12.7300,100,1,14.0700,2,1,12.7100,100,1,14.0800,100,1,12.5000,700,1,14.2799,100,1,12.4600,200,2,14.4000,100,1,12.4299,700,1,14.5600,800,2,12.4199,700,1,14.5999,700,1,12.3699,700,1,14.6400,100,1,ARL,307714769
1291,2025-07-17T15:48:42.011680742Z,2025-07-17T15:48:42.011680742Z,10,2,1108,C,A,0,14.7500,100,0,165650,258199535,13.2599,100,1,13.7500,15,1,13.0399,2,1,13.7599,100,1,13.0299,100,1,13.7899,100,1,12.7300,100,1,14.0700,2,1,12.7100,100,1,14.0800,100,1,12.5000,700,1,14.2799,100,1,12.4600,200,2,14.4000,100,1,12.4299,700,1,14.5600,800,2,12.4199,700,1,14.5999,700,1,12.3699,700,1,14.6400,100,1,ARL,306519741
1292,2025-07-17T15:48:42.011680742Z,2025-07-17T15:48:42.011680742Z,10,2,1108,A,A,0,14.6400,100,130,165650,258199535,13.2599,100,1,13.7500,15,1,13.0399,2,1,13.7599,100,1,13.0299,100,1,13.7899,100,1,12.7300,100,1,14.0700,2,1,12.7100,100,1,14.0800,100,1,12.5000,700,1,14.2799,100,1,12.4600,200,2,14.4000,100,1,12.4299,700,1,14.5600,800,2,12.4199,700,1,14.5999,700,1,12.3699,700,1,14.6400,200,2,ARL,308296381
1293,2025-07-17T15:48:42.016595806Z,2025-07-17T15:48:42.016595806Z,10,2,1108,A,A,0,13.7699,100,130,165568,258199787,13.2599,100,1,13.7500,15,1,13.0399,2,1,13.7599,100,1,13.0299,100,1,13.7699,100,1,12.7300,100,1,13.7899,100,1,12.7100,100,1,14.0700,2,1,12.5000,700,1,14.0800,100,1,12.4600,200,2,14.2799,100,1,12.4299,700,1,14.4000,100,1,12.4199,700,1,14.5600,800,2,12.3699,700,1,14.5999,700,1,ARL,308296741
1294,2025-07-17T15:48:42.023266760Z,2025-07-17T15:48:42.023266760Z,10,2,1108,C,A,0,13.7899,100,130,165647,258199990,13.2599,100,1,13.7500,15,1,13.0399,2,1,13.7599,100,1,13.0299,100,1,13.7699,100,1,12.7300,100,1,14.0700,2,1,12.7100,100,1,14.0800,100,1,12.5000,700,1,14.2799,100,1,12.4600,200,2,14.4000,100,1,12.4299,700,1,14.5600,800,2,12.4199,700,1,14.5999,700,1,12.3699,700,1,14.6400,200,2,ARL,307964609
1295,2025-07-17T15:48:46.749922127Z,2025-07-17T15:48:46.749922127Z,10,2,1108,A,A,0,13.7300,15,128,166363,258260871,13.2599,100,1,13.7300,15,1,13.0399,2,1,13.7500,15,1,13.0299,100,1,13.7599,100,1,12.7300,100,1,13.7699,100,1,12.7100,100,1,14.0700,2,1,12.5000,700,1,14.0800,100,1,12.4600,200,2,14.2799,100,1,12.4299,700,1,14.4000,100,1,12.4199,700,1,14.5600,800,2,12.3699,700,1,14.5999,700,1,ARL,308374537
1296,2025-07-17T15:48:46.758385367Z,2025-07-17T15:48:46.758385367Z,10,2,1108,C,A,0,13.7599,100,0,165666,258261154,13.2599,100,1,13.7300,15,1,13.0399,2,1,13.7500,15,1,13.0299,100,1,13.7699,100,1,12.7300,100,1,14.0700,2,1,12.7100,100,1,14.0800,100,1,12.5000,700,1,14.2799,100,1,12.4600,200,2,14.4000,100,1,12.4299,700,1,14.5600,800,2,12.4199,700,1,14.5999,700,1,12.3699,700,1,14.6400,200,2,ARL,307964621
1297,2025-07-17T15:48:46.758385367Z,2025-07-17T15:48:46.758385367Z,10,2,1108,A,A,0,13.7400,100,130,165666,258261154,13.2599,100,1,13.7300,15,1,13.0399,2,1,13.7400,100,1,13.0299,100,1,13.7500,15,1,12.7300,100,1,13.7699,100,1,12.7100,100,1,14.0700,2,1,12.5000,700,1,14.0800,100,1,12.4600,200,2,14.2799,100,1,12.4299,700,1,14.4000,100,1,12.4199,700,1,14.5600,800,2,12.3699,700,1,14.5999,700,1,ARL,308374881
1298,2025-07-17T15:48:46.773503306Z,2025-07-17T15:48:46.773503306Z,10,2,1108,C,A,0,14.0800,100,130,165682,258261538,13.2599,100,1,13.7300,15,1,13.0399,2,1,13.7400,100,1,13.0299,100,1,13.7500,15,1,12.7300,100,1,13.7699,100,1,12.7100,100,1,14.0700,2,1,12.5000,700,1,14.2799,100,1,12.4600,200,2,14.4000,100,1,12.4299,700,1,14.5600,800,2,12.4199,700,1,14.5999,700,1,12.3699,700,1,14.6400,200,2,ARL,306784853
1299,2025-07-17T15:48:46.773555566Z,2025-07-17T15:48:46.773555566Z,10,2,1108,A,A,0,14.0099,100,130,165160,258261539,13.2599,100,1,13.7300,15,1,13.0399,2,1,13.7400,100,1,13.0299,100,1,13.7500,15,1,12.7300,100,1,13.7699,100,1,12.7100,100,1,14.0099,100,1,12.5000,700,1,14.0700,2,1,12.4600,200,2,14.2799,100,1,12.4299,700,1,14.4000,100,1,12.4199,700,1,14.5600,800,2,12.3699,700,1,14.5999,700,1,ARL,308375185
1300,2025-07-17T15:49:02.010329052Z,2025-07-17T15:49:02.010329052Z,10,2,1108,A,A,0,13.7500,100,130,165428,258502869,13.2599,100,1,13.7300,15,1,13.0399,2,1,13.7400,100,1,13.0299,100,1,13.7500,115,2,12.7300,100,1,13.7699,100,1,12.7100,100,1,14.0099,100,1,12.5000,700,1,14.0700,2,1,12.4600,200,2,14.2799,100,1,12.4299,700,1,14.4000,100,1,12.4199,700,1,14.5600,800,2,12.3699,700,1,14.5999,700,1,ARL,308705489
1301,2025-07-17T15:49:02.019824230Z,2025-07-17T15:49:02.019824230Z,10,2,1108,C,A,0,13.7699,100,130,165337,258502929,13.2599,100,1,13.7300,15,1,13.0399,2,1,13.7400,100,1,13.0299,100,1,13.7500,115,2,12.7300,100,1,14.0099,100,1,12.7100,100,1,14.0700,2,1,12.5000,700,1,14.2799,100,1,12.4600,200,2,14.4000,100,1,12.4299,700,1,14.5600,800,2,12.4199,700,1,14.5999,700,1,12.3699,700,1,14.6400,200,2,ARL,308296741
1302,2025-07-17T15:49:03.405840358Z,2025-07-17T15:49:03.405840358Z,10,2,1108,C,A,0,13.7500,15,130,165232,258527308,13.2599,100,1,13.7300,15,1,13.0399,2,1,13.7400,100,1,13.0299,100,1,13.7500,100,1,12.7300,100,1,14.0099,100,1,12.7100,100,1,14.0700,2,1,12.5000,700,1,14.2799,100,1,12.4600,200,2,14.4000,100,1,12.4299,700,1,14.5600,800,2,12.4199,700,1,14.5999,700,1,12.3699,700,1,14.6400,200,2,ARL,307964605
1303,2025-07-17T15:49:04.713831675Z,2025-07-17T15:49:04.713831675Z,10,2,1108,A,A,0,13.7100,15,128,166250,258547335,13.2599,100,1,13.7100,15,1,13.0399,2,1,13.7300,15,1,13.0299,100,1,13.7400,100,1,12.7300,100,1,13.7500,100,1,12.7100,100,1,14.0099,100,1,12.5000,700,1,14.0700,2,1,12.4600,200,2,14.2799,100,1,12.4299,700,1,14.4000,100,1,12.4199,700,1,14.5600,800,2,12.3699,700,1,14.5999,700,1,ARL,308763065
1304,2025-07-17T15:49:06.012946379Z,2025-07-17T15:49:06.012946379Z,10,2,1108,A,A,0,13.7300,100,130,165562,258567259,13.2599,100,1,13.7100,15,1,13.0399,2,1,13.7300,115,2,13.0299,100,1,13.7400,100,1,12.7300,100,1,13.7500,100,1,12.7100,100,1,14.0099,100,1,12.5000,700,1,14.0700,2,1,12.4600,200,2,14.2799,100,1,12.4299,700,1,14.4000,100,1,12.4199,700,1,14.5600,800,2,12.3699,700,1,14.5999,700,1,ARL,308786185
1305,2025-07-17T15:49:06.023126600Z,2025-07-17T15:49:06.023126600Z,10,2,1108,C,A,0,13.7500,100,130,165547,258567405,13.2599,100,1,13.7100,15,1,13.0399,2,1,13.7300,115,2,13.0299,100,1,13.7400,100,1,12.7300,100,1,14.0099,100,1,12.7100,100,1,14.0700,2,1,12.5000,700,1,14.2799,100,1,12.4600,200,2,14.4000,100,1,12.4299,700,1,14.5600,800,2,12.4199,700,1,14.5999,700,1,12.3699,700,1,14.6400,200,2,ARL,308705489
1306,2025-07-17T15:49:06.344191321Z,2025-07-17T15:49:06.344191321Z,10,2,1108,C,A,0,13.7400,100,0,165569,258574949,13.2599,100,1,13.7100,15,1,13.0399,2,1,13.7300,115,2,13.0299,100,1,14.0099,100,1,12.7300,100,1,14.0700,2,1,12.7100,100,1,14.2799,100,1,12.5000,700,1,14.4000,100,1,12.4600,200,2,14.5600,800,2,12.4299,700,1,14.5999,700,1,12.4199,700,1,14.6400,200,2,12.3699,700,1,14.6500,100,1,ARL,308374881
1307,2025-07-17T15:49:06.344191321Z,2025-07-17T15:49:06.344191321Z,10,2,1108,A,A,0,13.7200,100,130,165569,258574949,13.2599,100,1,13.7100,15,1,13.0399,2,1,13.7200,100,1,13.0299,100,1,13.7300,115,2,12.7300,100,1,14.0099,100,1,12.7100,100,1,14.0700,2,1,12.5000,700,1,14.2799,100,1,12.4600,200,2,14.4000,100,1,12.4299,700,1,14.5600,800,2,12.4199,700,1,14.5999,700,1,12.3699,700,1,14.6400,200,2,ARL,308797069
1308,2025-07-17T15:49:06.344938975Z,2025-07-17T15:49:06.344938975Z,10,2,1108,C,A,0,14.8300,100,0,165516,258575013,13.2599,100,1,13.7100,15,1,13.0399,2,1,13.7200,100,1,13.0299,100,1,13.7300,115,2,12.7300,100,1,14.0099,100,1,12.7100,100,1,14.0700,2,1,12.5000,700,1,14.2799,100,1,12.4600,200,2,14.4000,100,1,12.4299,700,1,14.5600,800,2,12.4199,700,1,14.5999,700,1,12.3699,700,1,14.6400,200,2,ARL,307964665
1309,2025-07-17T15:49:06.344938975Z,2025-07-17T15:49:06.344938975Z,10,2,1108,A,A,0,14.7799,100,130,165516,258575013,13.2599,100,1,13.7100,15,1,13.0399,2,1,13.7200,100,1,13.0299,100,1,13.7300,115,2,12.7300,100,1,14.0099,100,1,12.7100,100,1,14.0700,2,1,12.5000,700,1,14.2799,100,1,12.4600,200,2,14.4000,100,1,12.4299,700,1,14.5600,800,2,12.4199,700,1,14.5999,700,1,12.3699,700,1,14.6400,200,2,ARL,308797245
1310,2025-07-17T15:49:06.362779870Z,2025-07-17T15:49:06.362779870Z,10,2,1108,C,A,0,17.5799,100,0,165540,258575963,13.2599,100,1,13.7100,15,1,13.0399,2,1,13.7200,100,1,13.0299,100,1,13.7300,115,2,12.7300,100,1,14.0099,100,1,12.7100,100,1,14.0700,2,1,12.5000,700,1,14.2799,100,1,12.4600,200,2,14.4000,100,1,12.4299,700,1,14.5600,800,2,12.4199,700,1,14.5999,700,1,12.3699,700,1,14.6400,200,2,ARL,306652017
1311,2025-07-17T15:49:06.362779870Z,2025-07-17T15:49:06.362779870Z,10,2,1108,A,A,0,17.4299,100,130,165540,258575963,13.2599,100,1,13.7100,15,1,13.0399,2,1,13.7200,100,1,13.0299,100,1,13.7300,115,2,12.7300,100,1,14.0099,100,1,12.7100,100,1,14.0700,2,1,12.5000,700,1,14.2799,100,1,12.4600,200,2,14.4000,100,1,12.4299,700,1,14.5600,800,2,12.4199,700,1,14.5999,700,1,12.3699,700,1,14.6400,200,2,ARL,308799373
1312,2025-07-17T15:49:10.459152457Z,2025-07-17T15:49:10.459152457Z,10,2,1108,C,A,0,13.7300,15,130,165428,258636400,13.2599,100,1,13.7100,15,1,13.0399,2,1,13.7200,100,1,13.0299,100,1,13.7300,100,1,12.7300,100,1,14.0099,100,1,12.7100,100,1,14.0700,2,1,12.5000,700,1,14.2799,100,1,12.4600,200,2,14.4000,100,1,12.4299,700,1,14.5600,800,2,12.4199,700,1,14.5999,700,1,12.3699,700,1,14.6400,200,2,ARL,308374537
1313,2025-07-17T15:49:11.460432218Z,2025-07-17T15:49:11.460432218Z,10,2,1108,A,A,0,13.6899,15,130,165382,258650544,13.2599,100,1,13.6899,15,1,13.0399,2,1,13.7100,15,1,13.0299,100,1,13.7200,100,1,12.7300,100,1,13.7300,100,1,12.7100,100,1,14.0099,100,1,12.5000,700,1,14.0700,2,1,12.4600,200,2,14.2799,100,1,12.4299,700,1,14.4000,100,1,12.4199,700,1,14.5600,800,2,12.3699,700,1,14.5999,700,1,ARL,308893737
1314,2025-07-17T15:49:11.891477604Z,2025-07-17T15:49:11.891477604Z,10,2,1108,C,A,0,13.7200,100,0,165495,258658721,13.2599,100,1,13.6899,15,1,13.0399,2,1,13.7100,15,1,13.0299,100,1,13.7300,100,1,12.7300,100,1,14.0099,100,1,12.7100,100,1,14.0700,2,1,12.5000,700,1,14.2799,100,1,12.4600,200,2,14.4000,100,1,12.4299,700,1,14.5600,800,2,12.4199,700,1,14.5999,700,1,12.3699,700,1,14.6400,200,2,ARL,308797069
1315,2025-07-17T15:49:11.891477604Z,2025-07-17T15:49:11.891477604Z,10,2,1108,A,A,0,13.6999,100,130,165495,258658721,13.2599,100,1,13.6899,15,1,13.0399,2,1,13.6999,100,1,13.0299,100,1,13.7100,15,1,12.7300,100,1,13.7300,100,1,12.7100,100,1,14.0099,100,1,12.5000,700,1,14.0700,2,1,12.4600,200,2,14.2799,100,1,12.4299,700,1,14.4000,100,1,12.4199,700,1,14.5600,800,2,12.3699,700,1,14.5999,700,1,ARL,308901793
1316,2025-07-17T15:49:11.893823458Z,2025-07-17T15:49:11.893823458Z,10,2,1108,C,A,0,14.8100,100,0,165613,258658835,13.2599,100,1,13.6899,15,1,13.0399,2,1,13.6999,100,1,13.0299,100,1,13.7100,15,1,12.7300,100,1,13.7300,100,1,12.7100,100,1,14.0099,100,1,12.5000,700,1,14.0700,2,1,12.4600,200,2,14.2799,100,1,12.4299,700,1,14.4000,100,1,12.4199,700,1,14.5600,800,2,12.3699,700,1,14.5999,700,1,ARL,306649913
1317,2025-07-17T15:49:11.893823458Z,2025-07-17T15:49:11.893823458Z,10,2,1108,A,A,0,14.6600,100,130,165613,258658835,13.2599,100,1,13.6899,15,1,13.0399,2,1,13.6999,100,1,13.0299,100,1,13.7100,15,1,12.7300,100,1,13.7300,100,1,12.7100,100,1,14.0099,100,1,12.5000,700,1,14.0700,2,1,12.4600,200,2,14.2799,100,1,12.4299,700,1,14.4000,100,1,12.4199,700,1,14.5600,800,2,12.3699,700,1,14.5999,700,1,ARL,308901981
1318,2025-07-17T15:49:11.904065674Z,2025-07-17T15:49:11.904065674Z,10,2,1108,C,A,0,15.9199,100,0,165475,258659039,13.2599,100,1,13.6899,15,1,13.0399,2,1,13.6999,100,1,13.0299,100,1,13.7100,15,1,12.7300,100,1,13.7300,100,1,12.7100,100,1,14.0099,100,1,12.5000,700,1,14.0700,2,1,12.4600,200,2,14.2799,100,1,12.4299,700,1,14.4000,100,1,12.4199,700,1,14.5600,800,2,12.3699,700,1,14.5999,700,1,ARL,306652001
1319,2025-07-17T15:49:11.904065674Z,2025-07-17T15:49:11.904065674Z,10,2,1108,A,A,0,15.7599,100,130,165475,258659039,13.2599,100,1,13.6899,15,1,13.0399,2,1,13.6999,100,1,13.0299,100,1,13.7100,15,1,12.7300,100,1,13.7300,100,1,12.7100,100,1,14.0099,100,1,12.5000,700,1,14.0700,2,1,12.4600,200,2,14.2799,100,1,12.4299,700,1,14.4000,100,1,12.4199,700,1,14.5600,800,2,12.3699,700,1,14.5999,700,1,ARL,308902229
1320,2025-07-17T15:49:11.935356090Z,2025-07-17T15:49:11.935356090Z,10,2,1108,C,A,0,14.8100,100,0,165597,258659320,13.2599,100,1,13.6899,15,1,13.0399,2,1,13.6999,100,1,13.0299,100,1,13.7100,15,1,12.7300,100,1,13.7300,100,1,12.7100,100,1,14.0099,100,1,12.5000,700,1,14.0700,2,1,12.4600,200,2,14.2799,100,1,12.4299,700,1,14.4000,100,1,12.4199,700,1,14.5600,800,2,12.3699,700,1,14.5999,700,1,ARL,306653713
1321,2025-07-17T15:49:11.935356090Z,2025-07-17T15:49:11.935356090Z,10,2,1108,A,A,0,14.6600,100,130,165597,258659320,13.2599,100,1,13.6899,15,1,13.0399,2,1,13.6999,100,1,13.0299,100,1,13.7100,15,1,12.7300,100,1,13.7300,100,1,12.7100,100,1,14.0099,100,1,12.5000,700,1,14.0700,2,1,12.4600,200,2,14.2799,100,1,12.4299,700,1,14.4000,100,1,12.4199,700,1,14.5600,800,2,12.3699,700,1,14.5999,700,1,ARL,308903001
1322,2025-07-17T15:49:11.948535655Z,2025-07-17T15:49:11.948535655Z,10,2,1108,C,A,0,14.6400,100,130,165394,258659496,13.2599,100,1,13.6899,15,1,13.0399,2,1,13.6999,100,1,13.0299,100,1,13.7100,15,1,12.7300,100,1,13.7300,100,1,12.7100,100,1,14.0099,100,1,12.5000,700,1,14.0700,2,1,12.4600,200,2,14.2799,100,1,12.4299,700,1,14.4000,100,1,12.4199,700,1,14.5600,800,2,12.3699,700,1,14.5999,700,1,ARL,306647521
1323,2025-07-17T15:49:11.948663655Z,2025-07-17T15:49:11.948663655Z,10,2,1108,A,A,0,14.5000,100,130,165457,258659499,13.2599,100,1,13.6899,15,1,13.0399,2,1,13.6999,100,1,13.0299,100,1,13.7100,15,1,12.7300,100,1,13.7300,100,1,12.7100,100,1,14.0099,100,1,12.5000,700,1,14.0700,2,1,12.4600,200,2,14.2799,100,1,12.4299,700,1,14.4000,100,1,12.4199,700,1,14.5000,100,1,12.3699,700,1,14.5600,800,2,ARL,308903349
1324,2025-07-17T15:49:12.221056085Z,2025-07-17T15:49:12.221056085Z,10,2,1108,A,A,0,13.7100,100,130,165282,258663292,13.2599,100,1,13.6899,15,1,13.0399,2,1,13.6999,100,1,13.0299,100,1,13.7100,115,2,12.7300,100,1,13.7300,100,1,12.7100,100,1,14.0099,100,1,12.5000,700,1,14.0700,2,1,12.4600,200,2,14.2799,100,1,12.4299,700,1,14.4000,100,1,12.4199,700,1,14.5000,100,1,12.3699,700,1,14.5600,800,2,ARL,308909249
1325,2025-07-17T15:49:12.227821500Z,2025-07-17T15:49:12.227821500Z,10,2,1108,C,A,0,13.7300,100,130,165405,258663378,13.2599,100,1,13.6899,15,1,13.0399,2,1,13.6999,100,1,13.0299,100,1,13.7100,115,2,12.7300,100,1,14.0099,100,1,12.7100,100,1,14.0700,2,1,12.5000,700,1,14.2799,100,1,12.4600,200,2,14.4000,100,1,12.4299,700,1,14.5000,100,1,12.4199,700,1,14.5600,800,2,12.3699,700,1,14.5999,700,1,ARL,308786185
1326,2025-07-17T15:49:14.463063539Z,2025-07-17T15:49:14.463063539Z,10,2,1108,C,A,0,13.7100,15,130,165582,258702625,13.2599,100,1,13.6899,15,1,13.0399,2,1,13.6999,100,1,13.0299,100,1,13.7100,100,1,12.7300,100,1,14.0099,100,1,12.7100,100,1,14.0700,2,1,12.5000,700,1,14.2799,100,1,12.4600,200,2,14.4000,100,1,12.4299,700,1,14.5000,100,1,12.4199,700,1,14.5600,800,2,12.3699,700,1,14.5999,700,1,ARL,308763065
1327,2025-07-17T15:49:15.466199239Z,2025-07-17T15:49:15.466199239Z,10,2,1108,A,A,0,13.6699,15,130,165883,258716863,13.2599,100,1,13.6699,15,1,13.0399,2,1,13.6899,15,1,13.0299,100,1,13.6999,100,1,12.7300,100,1,13.7100,100,1,12.7100,100,1,14.0099,100,1,12.5000,700,1,14.0700,2,1,12.4600,200,2,14.2799,100,1,12.4299,700,1,14.4000,100,1,12.4199,700,1,14.5000,100,1,12.3699,700,1,14.5600,800,2,ARL,308980305
1328,2025-07-17T15:49:16.350859152Z,2025-07-17T15:49:16.350859152Z,10,2,1108,C,A,0,13.6999,100,0,165436,258727929,13.2599,100,1,13.6699,15,1,13.0399,2,1,13.6899,15,1,13.0299,100,1,13.7100,100,1,12.7300,100,1,14.0099,100,1,12.7100,100,1,14.0700,2,1,12.5000,700,1,14.2799,100,1,12.4600,200,2,14.4000,100,1,12.4299,700,1,14.5000,100,1,12.4199,700,1,14.5600,800,2,12.3699,700,1,14.5999,700,1,ARL,308901793
1329,2025-07-17T15:49:16.350859152Z,2025-07-17T15:49:16.350859152Z,10,2,1108,A,A,0,13.6799,100,130,165436,258727929,13.2599,100,1,13.6699,15,1,13.0399,2,1,13.6799,100,1,13.0299,100,1,13.6899,15,1,12.7300,100,1,13.7100,100,1,12.7100,100,1,14.0099,100,1,12.5000,700,1,14.0700,2,1,12.4600,200,2,14.2799,100,1,12.4299,700,1,14.4000,100,1,12.4199,700,1,14.5000,100,1,12.3699,700,1,14.5600,800,2,ARL,308998225
1330,2025-07-17T15:49:16.351594042Z,2025-07-17T15:49:16.351594042Z,10,2,1108,C,A,0,14.7799,100,0,165576,258727956,13.2599,100,1,13.6699,15,1,13.0399,2,1,13.6799,100,1,13.0299,100,1,13.6899,15,1,12.7300,100,1,13.7100,100,1,12.7100,100,1,14.0099,100,1,12.5000,700,1,14.0700,2,1,12.4600,200,2,14.2799,100,1,12.4299,700,1,14.4000,100,1,12.4199,700,1,14.5000,100,1,12.3699,700,1,14.5600,800,2,ARL,308797245
1331,2025-07-17T15:49:16.351594042Z,2025-07-17T15:49:16.351594042Z,10,2,1108,A,A,0,14.7400,100,130,165576,258727956,13.2599,100,1,13.6699,15,1,13.0399,2,1,13.6799,100,1,13.0299,100,1,13.6899,15,1,12.7300,100,1,13.7100,100,1,12.7100,100,1,14.0099,100,1,12.5000,700,1,14.0700,2,1,12.4600,200,2,14.2799,100,1,12.4299,700,1,14.4000,100,1,12.4199,700,1,14.5000,100,1,12.3699,700,1,14.5600,800,2,ARL,308998341
1332,2025-07-17T15:49:16.493946243Z,2025-07-17T15:49:16.493946243Z,10,2,1108,A,A,0,13.6899,100,130,165247,258729266,13.2599,100,1,13.6699,15,1,13.0399,2,1,13.6799,100,1,13.0299,100,1,13.6899,115,2,12.7300,100,1,13.7100,100,1,12.7100,100,1,14.0099,100,1,12.5000,700,1,14.0700,2,1,12.4600,200,2,14.2799,100,1,12.4299,700,1,14.4000,100,1,12.4199,700,1,14.5000,100,1,12.3699,700,1,14.5600,800,2,ARL,309001525
1333,2025-07-17T15:49:16.557759633Z,2025-07-17T15:49:16.557759633Z,10,2,1108,C,A,0,13.7100,100,130,165230,258730034,13.2599,100,1,13.6699,15,1,13.0399,2,1,13.6799,100,1,13.0299,100,1,13.6899,115,2,12.7300,100,1,14.0099,100,1,12.7100,100,1,14.0700,2,1,12.5000,700,1,14.2799,100,1,12.4600,200,2,14.4000,100,1,12.4299,700,1,14.5000,100,1,12.4199,700,1,14.5600,800,2,12.3699,700,1,14.5999,700,1,ARL,308909249
1334,2025-07-17T15:49:21.185984774Z,2025-07-17T15:49:21.185984774Z,10,2,1108,C,A,0,14.0700,2,0,165713,258786552,13.2599,100,1,13.6699,15,1,13.0399,2,1,13.6799,100,1,13.0299,100,1,13.6899,115,2,12.7300,100,1,14.0099,100,1,12.7100,100,1,14.2799,100,1,12.5000,700,1,14.4000,100,1,12.4600,200,2,14.5000,100,1,12.4299,700,1,14.5600,800,2,12.4199,700,1,14.5999,700,1,12.3699,700,1,14.6400,100,1,ARL,296478973
1335,2025-07-17T15:49:21.185984774Z,2025-07-17T15:49:21.185984774Z,10,2,1108,A,A,0,13.9800,2,130,165713,258786552,13.2599,100,1,13.6699,15,1,13.0399,2,1,13.6799,100,1,13.0299,100,1,13.6899,115,2,12.7300,100,1,13.9800,2,1,12.7100,100,1,14.0099,100,1,12.5000,700,1,14.2799,100,1,12.4600,200,2,14.4000,100,1,12.4299,700,1,14.5000,100,1,12.4199,700,1,14.5600,800,2,12.3699,700,1,14.5999,700,1,ARL,309091513
1336,2025-07-17T15:49:24.282985894Z,2025-07-17T15:49:24.282985894Z,10,2,1108,C,A,0,13.6899,15,130,166218,258838460,13.2599,100,1,13.6699,15,1,13.0399,2,1,13.6799,100,1,13.0299,100,1,13.6899,100,1,12.7300,100,1,13.9800,2,1,12.7100,100,1,14.0099,100,1,12.5000,700,1,14.2799,100,1,12.4600,200,2,14.4000,100,1,12.4299,700,1,14.5000,100,1,12.4199,700,1,14.5600,800,2,12.3699,700,1,14.5999,700,1,ARL,308893737
1337,2025-07-17T15:49:34.570031718Z,2025-07-17T15:49:34.570031718Z,10,2,1108,C,A,0,13.6699,15,130,165416,258980876,13.2599,100,1,13.6799,100,1,13.0399,2,1,13.6899,100,1,13.0299,100,1,13.9800,2,1,12.7300,100,1,14.0099,100,1,12.7100,100,1,14.2799,100,1,12.5000,700,1,14.4000,100,1,12.4600,200,2,14.5000,100,1,12.4299,700,1,14.5600,800,2,12.4199,700,1,14.5999,700,1,12.3699,700,1,14.6400,100,1,ARL,308980305
1338,2025-07-17T15:49:34.591347169Z,2025-07-17T15:49:34.591347169Z,10,2,1108,C,A,0,13.6899,100,130,165746,258983321,13.2599,100,1,13.6799,100,1,13.0399,2,1,13.9800,2,1,13.0299,100,1,14.0099,100,1,12.7300,100,1,14.2799,100,1,12.7100,100,1,14.4000,100,1,12.5000,700,1,14.5000,100,1,12.4600,200,2,14.5600,800,2,12.4299,700,1,14.5999,700,1,12.4199,700,1,14.6400,100,1,12.3699,700,1,14.6500,100,1,ARL,309001525
1339,2025-07-17T15:49:38.609851985Z,2025-07-17T15:49:38.609851985Z,10,2,1108,A,A,0,13.7200,100,130,165409,259031220,13.2599,100,1,13.6799,100,1,13.0399,2,1,13.7200,100,1,13.0299,100,1,13.9800,2,1,12.7300,100,1,14.0099,100,1,12.7100,100,1,14.2799,100,1,12.5000,700,1,14.4000,100,1,12.4600,200,2,14.5000,100,1,12.4299,700,1,14.5600,800,2,12.4199,700,1,14.5999,700,1,12.3699,700,1,14.6400,100,1,ARL,309410565
1340,2025-07-17T15:49:38.609907720Z,2025-07-17T15:49:38.609907720Z,10,2,1108,C,B,0,13.2599,100,130,165614,259031221,13.0399,2,1,13.6799,100,1,13.0299,100,1,13.7200,100,1,12.7300,100,1,13.9800,2,1,12.7100,100,1,14.0099,100,1,12.5000,700,1,14.2799,100,1,12.4600,200,2,14.4000,100,1,12.4299,700,1,14.5000,100,1,12.4199,700,1,14.5600,800,2,12.3699,700,1,14.5999,700,1,12.3599,200,2,14.6400,100,1,ARL,291975017
1341,2025-07-17T15:49:39.068349660Z,2025-07-17T15:49:39.068349660Z,10,2,1108,A,B,0,13.0199,100,130,165345,259035032,13.0399,2,1,13.6799,100,1,13.0299,100,1,13.7200,100,1,13.0199,100,1,13.9800,2,1,12.7300,100,1,14.0099,100,1,12.7100,100,1,14.2799,100,1,12.5000,700,1,14.4000,100,1,12.4600,200,2,14.5000,100,1,12.4299,700,1,14.5600,800,2,12.4199,700,1,14.5999,700,1,12.3699,700,1,14.6400,100,1,ARL,309415429
1342,2025-07-17T15:49:44.788249210Z,2025-07-17T15:49:44.788249210Z,10,2,1108,A,A,0,13.6699,15,130,165191,259105347,13.0399,2,1,13.6699,15,1,13.0299,100,1,13.6799,100,1,13.0199,100,1,13.7200,100,1,12.7300,100,1,13.9800,2,1,12.7100,100,1,14.0099,100,1,12.5000,700,1,14.2799,100,1,12.4600,200,2,14.4000,100,1,12.4299,700,1,14.5000,100,1,12.4199,700,1,14.5600,800,2,12.3699,700,1,14.5999,700,1,ARL,309524921
1343,2025-07-17T15:49:44.788855587Z,2025-07-17T15:49:44.788855587Z,10,2,1108,A,A,0,13.6999,100,130,165170,259105361,13.0399,2,1,13.6699,15,1,13.0299,100,1,13.6799,100,1,13.0199,100,1,13.6999,100,1,12.7300,100,1,13.7200,100,1,12.7100,100,1,13.9800,2,1,12.5000,700,1,14.0099,100,1,12.4600,200,2,14.2799,100,1,12.4299,700,1,14.4000,100,1,12.4199,700,1,14.5000,100,1,12.3699,700,1,14.5600,800,2,ARL,309524933
1344,2025-07-17T15:49:44.789537536Z,2025-07-17T15:49:44.789537536Z,10,2,1108,C,A,0,13.7200,100,130,165380,259105380,13.0399,2,1,13.6699,15,1,13.0299,100,1,13.6799,100,1,13.0199,100,1,13.6999,100,1,12.7300,100,1,13.9800,2,1,12.7100,100,1,14.0099,100,1,12.5000,700,1,14.2799,100,1,12.4600,200,2,14.4000,100,1,12.4299,700,1,14.5000,100,1,12.4199,700,1,14.5600,800,2,12.3699,700,1,14.5999,700,1,ARL,309410565
1345,2025-07-17T15:49:54.788493605Z,2025-07-17T15:49:54.788493605Z,10,2,1108,A,A,0,13.6500,15,130,165236,259253294,13.0399,2,1,13.6500,15,1,13.0299,100,1,13.6699,15,1,13.0199,100,1,13.6799,100,1,12.7300,100,1,13.6999,100,1,12.7100,100,1,13.9800,2,1,12.5000,700,1,14.0099,100,1,12.4600,200,2,14.2799,100,1,12.4299,700,1,14.4000,100,1,12.4199,700,1,14.5000,100,1,12.3699,700,1,14.5600,800,2,ARL,309707269
1346,2025-07-17T15:49:54.799370442Z,2025-07-17T15:49:54.799370442Z,10,2,1108,A,A,0,13.6799,100,130,165302,259253527,13.0399,2,1,13.6500,15,1,13.0299,100,1,13.6699,15,1,13.0199,100,1,13.6799,200,2,12.7300,100,1,13.6999,100,1,12.7100,100,1,13.9800,2,1,12.5000,700,1,14.0099,100,1,12.4600,200,2,14.2799,100,1,12.4299,700,1,14.4000,100,1,12.4199,700,1,14.5000,100,1,12.3699,700,1,14.5600,800,2,ARL,309707413
1347,2025-07-17T15:49:54.820469390Z,2025-07-17T15:49:54.820469390Z,10,2,1108,C,A,0,13.6999,100,130,165527,259253732,13.0399,2,1,13.6500,15,1,13.0299,100,1,13.6699,15,1,13.0199,100,1,13.6799,200,2,12.7300,100,1,13.9800,2,1,12.7100,100,1,14.0099,100,1,12.5000,700,1,14.2799,100,1,12.4600,200,2,14.4000,100,1,12.4299,700,1,14.5000,100,1,12.4199,700,1,14.5600,800,2,12.3699,700,1,14.5999,700,1,ARL,309524933
1348,2025-07-17T15:49:59.511938438Z,2025-07-17T15:49:59.511938438Z,10,2,1108,C,A,0,13.6799,100,0,165626,259313537,13.0399,2,1,13.6500,15,1,13.0299,100,1,13.6699,15,1,13.0199,100,1,13.6799,100,1,12.7300,100,1,13.9800,2,1,12.7100,100,1,14.0099,100,1,12.5000,700,1,14.2799,100,1,12.4600,200,2,14.4000,100,1,12.4299,700,1,14.5000,100,1,12.4199,700,1,14.5600,800,2,12.3699,700,1,14.5999,700,1,ARL,308998225
1349,2025-07-17T15:49:59.511938438Z,2025-07-17T15:49:59.511938438Z,10,2,1108,A,A,0,13.6600,100,130,165626,259313537,13.0399,2,1,13.6500,15,1,13.0299,100,1,13.6600,100,1,13.0199,100,1,13.6699,15,1,12.7300,100,1,13.6799,100,1,12.7100,100,1,13.9800,2,1,12.5000,700,1,14.0099,100,1,12.4600,200,2,14.2799,100,1,12.4299,700,1,14.4000,100,1,12.4199,700,1,14.5000,100,1,12.3699,700,1,14.5600,800,2,ARL,309782481
1350,2025-07-17T15:49:59.533897369Z,2025-07-17T15:49:59.533897369Z,10,2,1108,C,A,0,14.0099,100,130,165265,259314032,13.0399,2,1,13.6500,15,1,13.0299,100,1,13.6600,100,1,13.0199,100,1,13.6699,15,1,12.7300,100,1,13.6799,100,1,12.7100,100,1,13.9800,2,1,12.5000,700,1,14.2799,100,1,12.4600,200,2,14.4000,100,1,12.4299,700,1,14.5000,100,1,12.4199,700,1,14.5600,800,2,12.3699,700,1,14.5999,700,1,ARL,308375185
1351,2025-07-17T15:49:59.533948952Z,2025-07-17T15:49:59.533948952Z,10,2,1108,A,A,0,13.9299,100,130,166323,259314033,13.0399,2,1,13.6500,15,1,13.0299,100,1,13.6600,100,1,13.0199,100,1,13.6699,15,1,12.7300,100,1,13.6799,100,1,12.7100,100,1,13.9299,100,1,12.5000,700,1,13.9800,2,1,12.4600,200,2,14.2799,100,1,12.4299,700,1,14.4000,100,1,12.4199,700,1,14.5000,100,1,12.3699,700,1,14.5600,800,2,ARL,309782973
1352,2025-07-17T15:50:00.547239401Z,2025-07-17T15:50:00.547239401Z,10,2,1108,C,A,0,13.6699,15,130,165571,259349868,13.0399,2,1,13.6500,15,1,13.0299,100,1,13.6600,100,1,13.0199,100,1,13.6799,100,1,12.7300,100,1,13.9299,100,1,12.7100,100,1,13.9800,2,1,12.5000,700,1,14.2799,100,1,12.4600,200,2,14.4000,100,1,12.4299,700,1,14.5000,100,1,12.4199,700,1,14.5600,800,2,12.3699,700,1,14.5999,700,1,ARL,309524921
1353,2025-07-17T15:50:00.555363249Z,2025-07-17T15:50:00.555363249Z,10,2,1108,C,A,0,14.6500,100,0,173439,259353226,13.0399,2,1,13.6500,15,1,13.0299,100,1,13.6600,100,1,13.0199,100,1,13.6799,100,1,12.7300,100,1,13.9299,100,1,12.7100,100,1,13.9800,2,1,12.5000,700,1,14.2799,100,1,12.4600,200,2,14.4000,100,1,12.4299,700,1,14.5000,100,1,12.4199,700,1,14.5600,800,2,12.3699,700,1,14.5999,700,1,ARL,307964661
1354,2025-07-17T15:50:00.555363249Z,2025-07-17T15:50:00.555363249Z,10,2,1108,A,A,0,14.5399,100,128,173439,259353226,13.0399,2,1,13.6500,15,1,13.0299,100,1,13.6600,100,1,13.0199,100,1,13.6799,100,1,12.7300,100,1,13.9299,100,1,12.7100,100,1,13.9800,2,1,12.5000,700,1,14.2799,100,1,12.4600,200,2,14.4000,100,1,12.4299,700,1,14.5000,100,1,12.4199,700,1,14.5399,100,1,12.3699,700,1,14.5600,800,2,ARL,309823025
1355,2025-07-17T15:50:03.412257475Z,2025-07-17T15:50:03.412257475Z,10,2,1108,A,A,0,13.6300,15,130,165405,259413272,13.0399,2,1,13.6300,15,1,13.0299,100,1,13.6500,15,1,13.0199,100,1,13.6600,100,1,12.7300,100,1,13.6799,100,1,12.7100,100,1,13.9299,100,1,12.5000,700,1,13.9800,2,1,12.4600,200,2,14.2799,100,1,12.4299,700,1,14.4000,100,1,12.4199,700,1,14.5000,100,1,12.3699,700,1,14.5399,100,1,ARL,309899025
1356,2025-07-17T15:50:03.415361851Z,2025-07-17T15:50:03.415361851Z,10,2,1108,C,A,0,14.6400,100,0,165521,259413427,13.0399,2,1,13.6300,15,1,13.0299,100,1,13.6500,15,1,13.0199,100,1,13.6600,100,1,12.7300,100,1,13.6799,100,1,12.7100,100,1,13.9299,100,1,12.5000,700,1,13.9800,2,1,12.4600,200,2,14.2799,100,1,12.4299,700,1,14.4000,100,1,12.4199,700,1,14.5000,100,1,12.3699,700,1,14.5399,100,1,ARL,308296381
1357,2025-07-17T15:50:03.415361851Z,2025-07-17T15:50:03.415361851Z,10,2,1108,A,A,0,14.5299,100,130,165521,259413427,13.0399,2,1,13.6300,15,1,13.0299,100,1,13.6500,15,1,13.0199,100,1,13.6600,100,1,12.7300,100,1,13.6799,100,1,12.7100,100,1,13.9299,100,1,12.5000,700,1,13.9800,2,1,12.4600,200,2,14.2799,100,1,12.4299,700,1,14.4000,100,1,12.4199,700,1,14.5000,100,1,12.3699,700,1,14.5299,100,1,ARL,309899141
1358,2025-07-17T15:50:03.824126753Z,2025-07-17T15:50:03.824126753Z,10,2,1108,C,A,0,13.6600,100,0,165399,259418661,13.0399,2,1,13.6300,15,1,13.0299,100,1,13.6500,15,1,13.0199,100,1,13.6799,100,1,12.7300,100,1,13.9299,100,1,12.7100,100,1,13.9800,2,1,12.5000,700,1,14.2799,100,1,12.4600,200,2,14.4000,100,1,12.4299,700,1,14.5000,100,1,12.4199,700,1,14.5299,100,1,12.3699,700,1,14.5399,100,1,ARL,309782481
1359,2025-07-17T15:50:03.824126753Z,2025-07-17T15:50:03.824126753Z,10,2,1108,A,A,0,13.6400,100,130,165399,259418661,13.0399,2,1,13.6300,15,1,13.0299,100,1,13.6400,100,1,13.0199,100,1,13.6500,15,1,12.7300,100,1,13.6799,100,1,12.7100,100,1,13.9299,100,1,12.5000,700,1,13.9800,2,1,12.4600,200,2,14.2799,100,1,12.4299,700,1,14.4000,100,1,12.4199,700,1,14.5000,100,1,12.3699,700,1,14.5299,100,1,ARL,309903973
1360,2025-07-17T15:50:03.824863026Z,2025-07-17T15:50:03.824863026Z,10,2,1108,C,A,0,14.7400,100,0,165434,259418664,13.0399,2,1,13.6300,15,1,13.0299,100,1,13.6400,100,1,13.0199,100,1,13.6500,15,1,12.7300,100,1,13.6799,100,1,12.7100,100,1,13.9299,100,1,12.5000,700,1,13.9800,2,1,12.4600,200,2,14.2799,100,1,12.4299,700,1,14.4000,100,1,12.4199,700,1,14.5000,100,1,12.3699,700,1,14.5299,100,1,ARL,308998341
1361,2025-07-17T15:50:03.824863026Z,2025-07-17T15:50:03.824863026Z,10,2,1108,A,A,0,14.6999,100,130,165434,259418664,13.0399,2,1,13.6300,15,1,13.0299,100,1,13.6400,100,1,13.0199,100,1,13.6500,15,1,12.7300,100,1,13.6799,100,1,12.7100,100,1,13.9299,100,1,12.5000,700,1,13.9800,2,1,12.4600,200,2,14.2799,100,1,12.4299,700,1,14.4000,100,1,12.4199,700,1,14.5000,100,1,12.3699,700,1,14.5299,100,1,ARL,309903993
1362,2025-07-17T15:50:04.484733438Z,2025-07-17T15:50:04.484733438Z,10,2,1108,A,A,0,13.6600,100,130,165321,259433904,13.0399,2,1,13.6300,15,1,13.0299,100,1,13.6400,100,1,13.0199,100,1,13.6500,15,1,12.7300,100,1,13.6600,100,1,12.7100,100,1,13.6799,100,1,12.5000,700,1,13.9299,100,1,12.4600,200,2,13.9800,2,1,12.4299,700,1,14.2799,100,1,12.4199,700,1,14.4000,100,1,12.3699,700,1,14.5000,100,1,ARL,309922345
1363,2025-07-17T15:50:04.524563568Z,2025-07-17T15:50:04.524563568Z,10,2,1108,C,A,0,13.6799,100,130,165471,259434652,13.0399,2,1,13.6300,15,1,13.0299,100,1,13.6400,100,1,13.0199,100,1,13.6500,15,1,12.7300,100,1,13.6600,100,1,12.7100,100,1,13.9299,100,1,12.5000,700,1,13.9800,2,1,12.4600,200,2,14.2799,100,1,12.4299,700,1,14.4000,100,1,12.4199,700,1,14.5000,100,1,12.3699,700,1,14.5299,100,1,ARL,309707413
1364,2025-07-17T15:50:06.787661846Z,2025-07-17T15:50:06.787661846Z,10,2,1108,C,A,0,13.6300,15,130,165129,259472951,13.0399,2,1,13.6400,100,1,13.0299,100,1,13.6500,15,1,13.0199,100,1,13.6600,100,1,12.7300,100,1,13.9299,100,1,12.7100,100,1,13.9800,2,1,12.5000,700,1,14.2799,100,1,12.4600,200,2,14.4000,100,1,12.4299,700,1,14.5000,100,1,12.4199,700,1,14.5299,100,1,12.3699,700,1,14.5399,100,1,ARL,309899025
1365,2025-07-17T15:50:09.185334126Z,2025-07-17T15:50:09.185334126Z,10,2,1108,A,A,0,13.6099,15,130,165241,259516855,13.0399,2,1,13.6099,15,1,13.0299,100,1,13.6400,100,1,13.0199,100,1,13.6500,15,1,12.7300,100,1,13.6600,100,1,12.7100,100,1,13.9299,100,1,12.5000,700,1,13.9800,2,1,12.4600,200,2,14.2799,100,1,12.4299,700,1,14.4000,100,1,12.4199,700,1,14.5000,100,1,12.3699,700,1,14.5299,100,1,ARL,310030465
1366,2025-07-17T15:50:09.198311198Z,2025-07-17T15:50:09.198311198Z,10,2,1108,A,A,0,13.6400,100,130,165239,259517754,13.0399,2,1,13.6099,15,1,13.0299,100,1,13.6400,200,2,13.0199,100,1,13.6500,15,1,12.7300,100,1,13.6600,100,1,12.7100,100,1,13.9299,100,1,12.5000,700,1,13.9800,2,1,12.4600,200,2,14.2799,100,1,12.4299,700,1,14.4000,100,1,12.4199,700,1,14.5000,100,1,12.3699,700,1,14.5299,100,1,ARL,310031625
1367,2025-07-17T15:50:09.205322092Z,2025-07-17T15:50:09.205322092Z,10,2,1108,C,A,0,13.6600,100,130,165324,259517973,13.0399,2,1,13.6099,15,1,13.0299,100,1,13.6400,200,2,13.0199,100,1,13.6500,15,1,12.7300,100,1,13.9299,100,1,12.7100,100,1,13.9800,2,1,12.5000,700,1,14.2799,100,1,12.4600,200,2,14.4000,100,1,12.4299,700,1,14.5000,100,1,12.4199,700,1,14.5299,100,1,12.3699,700,1,14.5399,100,1,ARL,309922345
1368,2025-07-17T15:50:09.330572653Z,2025-07-17T15:50:09.330572653Z,10,2,1108,C,A,0,13.6400,100,0,165500,259522708,13.0399,2,1,13.6099,15,1,13.0299,100,1,13.6400,100,1,13.0199,100,1,13.6500,15,1,12.7300,100,1,13.9299,100,1,12.7100,100,1,13.9800,2,1,12.5000,700,1,14.2799,100,1,12.4600,200,2,14.4000,100,1,12.4299,700,1,14.5000,100,1,12.4199,700,1,14.5299,100,1,12.3699,700,1,14.5399,100,1,ARL,309903973
1369,2025-07-17T15:50:09.330572653Z,2025-07-17T15:50:09.330572653Z,10,2,1108,A,A,0,13.6199,100,130,165500,259522708,13.0399,2,1,13.6099,15,1,13.0299,100,1,13.6199,100,1,13.0199,100,1,13.6400,100,1,12.7300,100,1,13.6500,15,1,12.7100,100,1,13.9299,100,1,12.5000,700,1,13.9800,2,1,12.4600,200,2,14.2799,100,1,12.4299,700,1,14.4000,100,1,12.4199,700,1,14.5000,100,1,12.3699,700,1,14.5299,100,1,ARL,310037965
1370,2025-07-17T15:50:20.204373858Z,2025-07-17T15:50:20.204373858Z,10,2,1108,C,A,0,13.6500,15,130,165327,259737768,13.0399,2,1,13.6099,15,1,13.0299,100,1,13.6199,100,1,13.0199,100,1,13.6400,100,1,12.7300,100,1,13.9299,100,1,12.7100,100,1,13.9800,2,1,12.5000,700,1,14.2799,100,1,12.4600,200,2,14.4000,100,1,12.4299,700,1,14.5000,100,1,12.4199,700,1,14.5299,100,1,12.3699,700,1,14.5399,100,1,ARL,309707269
1371,2025-07-17T15:50:25.935412900Z,2025-07-17T15:50:25.935412900Z,10,2,1108,A,A,0,13.5899,15,128,166134,259828644,13.0399,2,1,13.5899,15,1,13.0299,100,1,13.6099,15,1,13.0199,100,1,13.6199,100,1,12.7300,100,1,13.6400,100,1,12.7100,100,1,13.9299,100,1,12.5000,700,1,13.9800,2,1,12.4600,200,2,14.2799,100,1,12.4299,700,1,14.4000,100,1,12.4199,700,1,14.5000,100,1,12.3699,700,1,14.5299,100,1,ARL,310424077
1372,2025-07-17T15:50:26.954662143Z,2025-07-17T15:50:26.954662143Z,10,2,1108,C,A,0,13.6199,100,0,166007,259847181,13.0399,2,1,13.5899,15,1,13.0299,100,1,13.6099,15,1,13.0199,100,1,13.6400,100,1,12.7300,100,1,13.9299,100,1,12.7100,100,1,13.9800,2,1,12.5000,700,1,14.2799,100,1,12.4600,200,2,14.4000,100,1,12.4299,700,1,14.5000,100,1,12.4199,700,1,14.5299,100,1,12.3699,700,1,14.5399,100,1,ARL,310037965
1373,2025-07-17T15:50:26.954662143Z,2025-07-17T15:50:26.954662143Z,10,2,1108,A,A,0,13.5999,100,130,166007,259847181,13.0399,2,1,13.5899,15,1,13.0299,100,1,13.5999,100,1,13.0199,100,1,13.6099,15,1,12.7300,100,1,13.6400,100,1,12.7100,100,1,13.9299,100,1,12.5000,700,1,13.9800,2,1,12.4600,200,2,14.2799,100,1,12.4299,700,1,14.4000,100,1,12.4199,700,1,14.5000,100,1,12.3699,700,1,14.5299,100,1,ARL,310446249
1374,2025-07-17T15:50:26.955400327Z,2025-07-17T15:50:26.955400327Z,10,2,1108,C,A,0,14.6999,100,0,165577,259847190,13.0399,2,1,13.5899,15,1,13.0299,100,1,13.5999,100,1,13.0199,100,1,13.6099,15,1,12.7300,100,1,13.6400,100,1,12.7100,100,1,13.9299,100,1,12.5000,700,1,13.9800,2,1,12.4600,200,2,14.2799,100,1,12.4299,700,1,14.4000,100,1,12.4199,700,1,14.5000,100,1,12.3699,700,1,14.5299,100,1,ARL,309903993
1375,2025-07-17T15:50:26.955400327Z,2025-07-17T15:50:26.955400327Z,10,2,1108,A,A,0,14.6500,100,130,165577,259847190,13.0399,2,1,13.5899,15,1,13.0299,100,1,13.5999,100,1,13.0199,100,1,13.6099,15,1,12.7300,100,1,13.6400,100,1,12.7100,100,1,13.9299,100,1,12.5000,700,1,13.9800,2,1,12.4600,200,2,14.2799,100,1,12.4299,700,1,14.4000,100,1,12.4199,700,1,14.5000,100,1,12.3699,700,1,14.5299,100,1,ARL,310446269
1376,2025-07-17T15:50:26.956094101Z,2025-07-17T15:50:26.956094101Z,10,2,1108,C,A,0,17.4299,100,0,165407,259847199,13.0399,2,1,13.5899,15,1,13.0299,100,1,13.5999,100,1,13.0199,100,1,13.6099,15,1,12.7300,100,1,13.6400,100,1,12.7100,100,1,13.9299,100,1,12.5000,700,1,13.9800,2,1,12.4600,200,2,14.2799,100,1,12.4299,700,1,14.4000,100,1,12.4199,700,1,14.5000,100,1,12.3699,700,1,14.5299,100,1,ARL,308799373
1377,2025-07-17T15:50:26.956094101Z,2025-07-17T15:50:26.956094101Z,10,2,1108,A,A,0,17.2800,100,130,165407,259847199,13.0399,2,1,13.5899,15,1,13.0299,100,1,13.5999,100,1,13.0199,100,1,13.6099,15,1,12.7300,100,1,13.6400,100,1,12.7100,100,1,13.9299,100,1,12.5000,700,1,13.9800,2,1,12.4600,200,2,14.2799,100,1,12.4299,700,1,14.4000,100,1,12.4199,700,1,14.5000,100,1,12.3699,700,1,14.5299,100,1,ARL,310446293
1378,2025-07-17T15:50:26.982879448Z,2025-07-17T15:50:26.982879448Z,10,2,1108,A,A,0,15.5099,100,130,165288,259847556,13.0399,2,1,13.5899,15,1,13.0299,100,1,13.5999,100,1,13.0199,100,1,13.6099,15,1,12.7300,100,1,13.6400,100,1,12.7100,100,1,13.9299,100,1,12.5000,700,1,13.9800,2,1,12.4600,200,2,14.2799,100,1,12.4299,700,1,14.4000,100,1,12.4199,700,1,14.5000,100,1,12.3699,700,1,14.5299,100,1,ARL,310447441
1379,2025-07-17T15:50:26.982892468Z,2025-07-17T15:50:26.982892468Z,10,2,1108,C,A,0,15.7799,100,130,165207,259847557,13.0399,2,1,13.5899,15,1,13.0299,100,1,13.5999,100,1,13.0199,100,1,13.6099,15,1,12.7300,100,1,13.6400,100,1,12.7100,100,1,13.9299,100,1,12.5000,700,1,13.9800,2,1,12.4600,200,2,14.2799,100,1,12.4299,700,1,14.4000,100,1,12.4199,700,1,14.5000,100,1,12.3699,700,1,14.5299,100,1,ARL,282776733
1380,2025-07-17T15:50:30.046714265Z,2025-07-17T15:50:30.046714265Z,10,2,1108,C,A,0,13.5899,15,130,165304,259916670,13.0399,2,1,13.5999,100,1,13.0299,100,1,13.6099,15,1,13.0199,100,1,13.6400,100,1,12.7300,100,1,13.9299,100,1,12.7100,100,1,13.9800,2,1,12.5000,700,1,14.2799,100,1,12.4600,200,2,14.4000,100,1,12.4299,700,1,14.5000,100,1,12.4199,700,1,14.5299,100,1,12.3699,700,1,14.5399,100,1,ARL,310424077
1381,2025-07-17T15:50:30.046849726Z,2025-07-17T15:50:30.046849726Z,10,2,1108,C,A,0,13.6099,15,130,165388,259916674,13.0399,2,1,13.5999,100,1,13.0299,100,1,13.6400,100,1,13.0199,100,1,13.9299,100,1,12.7300,100,1,13.9800,2,1,12.7100,100,1,14.2799,100,1,12.5000,700,1,14.4000,100,1,12.4600,200,2,14.5000,100,1,12.4299,700,1,14.5299,100,1,12.4199,700,1,14.5399,100,1,12.3699,700,1,14.5600,800,2,ARL,310030465
1382,2025-07-17T15:51:37.985992174Z,2025-07-17T15:51:37.985992174Z,10,2,1108,C,A,0,13.9800,2,0,166156,261130345,13.0399,2,1,13.5999,100,1,13.0299,100,1,13.6400,100,1,13.0199,100,1,13.9299,100,1,12.7300,100,1,14.2799,100,1,12.7100,100,1,14.4000,100,1,12.5000,700,1,14.5000,100,1,12.4600,200,2,14.5299,100,1,12.4299,700,1,14.5399,100,1,12.4199,700,1,14.5600,800,2,12.3699,700,1,14.5999,700,1,ARL,309091513
1383,2025-07-17T15:51:37.985992174Z,2025-07-17T15:51:37.985992174Z,10,2,1108,A,A,0,13.8900,2,130,166156,261130345,13.0399,2,1,13.5999,100,1,13.0299,100,1,13.6400,100,1,13.0199,100,1,13.8900,2,1,12.7300,100,1,13.9299,100,1,12.7100,100,1,14.2799,100,1,12.5000,700,1,14.4000,100,1,12.4600,200,2,14.5000,100,1,12.4299,700,1,14.5299,100,1,12.4199,700,1,14.5399,100,1,12.3699,700,1,14.5600,800,2,ARL,311979125
1384,2025-07-17T15:52:16.371351021Z,2025-07-17T15:52:16.371351021Z,10,2,1108,T,N,0,13.4100,58,0,166818,261713745,13.0399,2,1,13.5999,100,1,13.0299,100,1,13.6400,100,1,13.0199,100,1,13.8900,2,1,12.7300,100,1,13.9299,100,1,12.7100,100,1,14.2799,100,1,12.5000,700,1,14.4000,100,1,12.4600,200,2,14.5000,100,1,12.4299,700,1,14.5299,100,1,12.4199,700,1,14.5399,100,1,12.3699,700,1,14.5600,800,2,ARL,0
1385,2025-07-17T15:52:16.371351021Z,2025-07-17T15:52:16.371351021Z,10,2,1108,T,N,0,13.2799,12,130,166818,261713746,13.0399,2,1,13.5999,100,1,13.0299,100,1,13.6400,100,1,13.0199,100,1,13.8900,2,1,12.7300,100,1,13.9299,100,1,12.7100,100,1,14.2799,100,1,12.5000,700,1,14.4000,100,1,12.4600,200,2,14.5000,100,1,12.4299,700,1,14.5299,100,1,12.4199,700,1,14.5399,100,1,12.3699,700,1,14.5600,800,2,ARL,0
1386,2025-07-17T15:52:16.372269170Z,2025-07-17T15:52:16.372269170Z,10,2,1108,C,A,0,13.5999,100,130,165455,261713790,13.0399,2,1,13.6400,100,1,13.0299,100,1,13.8900,2,1,13.0199,100,1,13.9299,100,1,12.7300,100,1,14.2799,100,1,12.7100,100,1,14.4000,100,1,12.5000,700,1,14.5000,100,1,12.4600,200,2,14.5299,100,1,12.4299,700,1,14.5399,100,1,12.4199,700,1,14.5600,800,2,12.3699,700,1,14.5999,700,1,ARL,310446249
1387,2025-07-17T15:52:16.373023186Z,2025-07-17T15:52:16.373023186Z,10,2,1108,C,A,0,14.6500,100,0,165605,261713830,13.0399,2,1,13.6400,100,1,13.0299,100,1,13.8900,2,1,13.0199,100,1,13.9299,100,1,12.7300,100,1,14.2799,100,1,12.7100,100,1,14.4000,100,1,12.5000,700,1,14.5000,100,1,12.4600,200,2,14.5299,100,1,12.4299,700,1,14.5399,100,1,12.4199,700,1,14.5600,800,2,12.3699,700,1,14.5999,700,1,ARL,310446269
1388,2025-07-17T15:52:16.373023186Z,2025-07-17T15:52:16.373023186Z,10,2,1108,A,A,0,14.6999,100,130,165605,261713830,13.0399,2,1,13.6400,100,1,13.0299,100,1,13.8900,2,1,13.0199,100,1,13.9299,100,1,12.7300,100,1,14.2799,100,1,12.7100,100,1,14.4000,100,1,12.5000,700,1,14.5000,100,1,12.4600,200,2,14.5299,100,1,12.4299,700,1,14.5399,100,1,12.4199,700,1,14.5600,800,2,12.3699,700,1,14.5999,700,1,ARL,312771573
1389,2025-07-17T15:52:16.374186508Z,2025-07-17T15:52:16.374186508Z,10,2,1108,C,A,0,13.6400,100,130,166651,261713870,13.0399,2,1,13.8900,2,1,13.0299,100,1,13.9299,100,1,13.0199,100,1,14.2799,100,1,12.7300,100,1,14.4000,100,1,12.7100,100,1,14.5000,100,1,12.5000,700,1,14.5299,100,1,12.4600,200,2,14.5399,100,1,12.4299,700,1,14.5600,800,2,12.4199,700,1,14.5999,700,1,12.3699,700,1,14.6600,200,2,ARL,310031625
1390,2025-07-17T15:52:16.374312976Z,2025-07-17T15:52:16.374312976Z,10,2,1108,A,A,0,15.8599,100,128,167207,261713880,13.0399,2,1,13.8900,2,1,13.0299,100,1,13.9299,100,1,13.0199,100,1,14.2799,100,1,12.7300,100,1,14.4000,100,1,12.7100,100,1,14.5000,100,1,12.5000,700,1,14.5299,100,1,12.4600,200,2,14.5399,100,1,12.4299,700,1,14.5600,800,2,12.4199,700,1,14.5999,700,1,12.3699,700,1,14.6600,200,2,ARL,312771645
1391,2025-07-17T15:52:16.374327668Z,2025-07-17T15:52:16.374327668Z,10,2,1108,C,A,0,15.5099,100,130,165982,261713884,13.0399,2,1,13.8900,2,1,13.0299,100,1,13.9299,100,1,13.0199,100,1,14.2799,100,1,12.7300,100,1,14.4000,100,1,12.7100,100,1,14.5000,100,1,12.5000,700,1,14.5299,100,1,12.4600,200,2,14.5399,100,1,12.4299,700,1,14.5600,800,2,12.4199,700,1,14.5999,700,1,12.3699,700,1,14.6600,200,2,ARL,310447441
1392,2025-07-17T15:52:16.375222836Z,2025-07-17T15:52:16.375222836Z,10,2,1108,C,A,0,14.5399,100,0,165449,261713944,13.0399,2,1,13.8900,2,1,13.0299,100,1,13.9299,100,1,13.0199,100,1,14.2799,100,1,12.7300,100,1,14.4000,100,1,12.7100,100,1,14.5000,100,1,12.5000,700,1,14.5299,100,1,12.4600,200,2,14.5600,800,2,12.4299,700,1,14.5999,700,1,12.4199,700,1,14.6600,200,2,12.3699,700,1,14.6799,1400,2,ARL,309823025
1393,2025-07-17T15:52:16.375222836Z,2025-07-17T15:52:16.375222836Z,10,2,1108,A,A,0,14.8100,100,130,165449,261713944,13.0399,2,1,13.8900,2,1,13.0299,100,1,13.9299,100,1,13.0199,100,1,14.2799,100,1,12.7300,100,1,14.4000,100,1,12.7100,100,1,14.5000,100,1,12.5000,700,1,14.5299,100,1,12.4600,200,2,14.5600,800,2,12.4299,700,1,14.5999,700,1,12.4199,700,1,14.6600,200,2,12.3699,700,1,14.6799,1400,2,ARL,312771781
1394,2025-07-17T15:52:16.375248654Z,2025-07-17T15:52:16.375248654Z,10,2,1108,C,A,0,14.6600,100,0,165593,261713945,13.0399,2,1,13.8900,2,1,13.0299,100,1,13.9299,100,1,13.0199,100,1,14.2799,100,1,12.7300,100,1,14.4000,100,1,12.7100,100,1,14.5000,100,1,12.5000,700,1,14.5299,100,1,12.4600,200,2,14.5600,800,2,12.4299,700,1,14.5999,700,1,12.4199,700,1,14.6600,100,1,12.3699,700,1,14.6799,1400,2,ARL,308901981
1395,2025-07-17T15:52:16.375248654Z,2025-07-17T15:52:16.375248654Z,10,2,1108,A,A,0,14.8900,100,130,165593,261713945,13.0399,2,1,13.8900,2,1,13.0299,100,1,13.9299,100,1,13.0199,100,1,14.2799,100,1,12.7300,100,1,14.4000,100,1,12.7100,100,1,14.5000,100,1,12.5000,700,1,14.5299,100,1,12.4600,200,2,14.5600,800,2,12.4299,700,1,14.5999,700,1,12.4199,700,1,14.6600,100,1,12.3699,700,1,14.6799,1400,2,ARL,312771785
1396,2025-07-17T15:52:16.375662552Z,2025-07-17T15:52:16.375662552Z,10,2,1108,C,A,0,14.5299,100,0,165602,261713959,13.0399,2,1,13.8900,2,1,13.0299,100,1,13.9299,100,1,13.0199,100,1,14.2799,100,1,12.7300,100,1,14.4000,100,1,12.7100,100,1,14.5000,100,1,12.5000,700,1,14.5600,800,2,12.4600,200,2,14.5999,700,1,12.4299,700,1,14.6600,100,1,12.4199,700,1,14.6799,1400,2,12.3699,700,1,14.6999,100,1,ARL,309899141
1397,2025-07-17T15:52:16.375662552Z,2025-07-17T15:52:16.375662552Z,10,2,1108,A,A,0,14.7599,100,130,165602,261713959,13.0399,2,1,13.8900,2,1,13.0299,100,1,13.9299,100,1,13.0199,100,1,14.2799,100,1,12.7300,100,1,14.4000,100,1,12.7100,100,1,14.5000,100,1,12.5000,700,1,14.5600,800,2,12.4600,200,2,14.5999,700,1,12.4299,700,1,14.6600,100,1,12.4199,700,1,14.6799,1400,2,12.3699,700,1,14.6999,100,1,ARL,312771829
1398,2025-07-17T15:52:16.377179230Z,2025-07-17T15:52:16.377179230Z,10,2,1108,C,A,0,17.2800,100,0,165823,261714104,13.0399,2,1,13.8900,2,1,13.0299,100,1,13.9299,100,1,13.0199,100,1,14.2799,100,1,12.7300,100,1,14.4000,100,1,12.7100,100,1,14.5000,100,1,12.5000,700,1,14.5600,800,2,12.4600,200,2,14.5999,700,1,12.4299,700,1,14.6600,100,1,12.4199,700,1,14.6799,1400,2,12.3699,700,1,14.6999,100,1,ARL,310446293
1399,2025-07-17T15:52:16.377179230Z,2025-07-17T15:52:16.377179230Z,10,2,1108,A,A,0,17.6999,100,130,165823,261714104,13.0399,2,1,13.8900,2,1,13.0299,100,1,13.9299,100,1,13.0199,100,1,14.2799,100,1,12.7300,100,1,14.4000,100,1,12.7100,100,1,14.5000,100,1,12.5000,700,1,14.5600,800,2,12.4600,200,2,14.5999,700,1,12.4299,700,1,14.6600,100,1,12.4199,700,1,14.6799,1400,2,12.3699,700,1,14.6999,100,1,ARL,312772009
1400,2025-07-17T15:52:16.378073674Z,2025-07-17T15:52:16.378073674Z,10,2,1108,C,A,0,15.7599,100,0,165440,261714140,13.0399,2,1,13.8900,2,1,13.0299,100,1,13.9299,100,1,13.0199,100,1,14.2799,100,1,12.7300,100,1,14.4000,100,1,12.7100,100,1,14.5000,100,1,12.5000,700,1,14.5600,800,2,12.4600,200,2,14.5999,700,1,12.4299,700,1,14.6600,100,1,12.4199,700,1,14.6799,1400,2,12.3699,700,1,14.6999,100,1,ARL,308902229
1401,2025-07-17T15:52:16.378073674Z,2025-07-17T15:52:16.378073674Z,10,2,1108,A,A,0,16.0199,100,130,165440,261714140,13.0399,2,1,13.8900,2,1,13.0299,100,1,13.9299,100,1,13.0199,100,1,14.2799,100,1,12.7300,100,1,14.4000,100,1,12.7100,100,1,14.5000,100,1,12.5000,700,1,14.5600,800,2,12.4600,200,2,14.5999,700,1,12.4299,700,1,14.6600,100,1,12.4199,700,1,14.6799,1400,2,12.3699,700,1,14.6999,100,1,ARL,312772057
1402,2025-07-17T15:52:16.378220434Z,2025-07-17T15:52:16.378220434Z,10,2,1108,C,A,0,14.5000,100,0,165509,261714145,13.0399,2,1,13.8900,2,1,13.0299,100,1,13.9299,100,1,13.0199,100,1,14.2799,100,1,12.7300,100,1,14.4000,100,1,12.7100,100,1,14.5600,800,2,12.5000,700,1,14.5999,700,1,12.4600,200,2,14.6600,100,1,12.4299,700,1,14.6799,1400,2,12.4199,700,1,14.6999,100,1,12.3699,700,1,14.7599,100,1,ARL,308903349
1403,2025-07-17T15:52:16.378220434Z,2025-07-17T15:52:16.378220434Z,10,2,1108,A,A,0,14.7200,100,130,165509,261714145,13.0399,2,1,13.8900,2,1,13.0299,100,1,13.9299,100,1,13.0199,100,1,14.2799,100,1,12.7300,100,1,14.4000,100,1,12.7100,100,1,14.5600,800,2,12.5000,700,1,14.5999,700,1,12.4600,200,2,14.6600,100,1,12.4299,700,1,14.6799,1400,2,12.4199,700,1,14.6999,100,1,12.3699,700,1,14.7200,100,1,ARL,312772061
1404,2025-07-17T15:52:16.378705201Z,2025-07-17T15:52:16.378705201Z,10,2,1108,A,B,0,13.2699,10,130,165437,261714171,13.2699,10,1,13.8900,2,1,13.0399,2,1,13.9299,100,1,13.0299,100,1,14.2799,100,1,13.0199,100,1,14.4000,100,1,12.7300,100,1,14.5600,800,2,12.7100,100,1,14.5999,700,1,12.5000,700,1,14.6600,100,1,12.4600,200,2,14.6799,1400,2,12.4299,700,1,14.6999,100,1,12.4199,700,1,14.7200,100,1,ARL,312772069
1405,2025-07-17T15:52:16.378707041Z,2025-07-17T15:52:16.378707041Z,10,2,1108,A,A,0,13.8599,15,130,165344,261714172,13.2699,10,1,13.8599,15,1,13.0399,2,1,13.8900,2,1,13.0299,100,1,13.9299,100,1,13.0199,100,1,14.2799,100,1,12.7300,100,1,14.4000,100,1,12.7100,100,1,14.5600,800,2,12.5000,700,1,14.5999,700,1,12.4600,200,2,14.6600,100,1,12.4299,700,1,14.6799,1400,2,12.4199,700,1,14.6999,100,1,ARL,312772073
1406,2025-07-17T15:52:16.378962330Z,2025-07-17T15:52:16.378962330Z,10,2,1108,C,B,0,13.0199,100,0,165452,261714185,13.2699,10,1,13.8599,15,1,13.0399,2,1,13.8900,2,1,13.0299,100,1,13.9299,100,1,12.7300,100,1,14.2799,100,1,12.7100,100,1,14.4000,100,1,12.5000,700,1,14.5600,800,2,12.4600,200,2,14.5999,700,1,12.4299,700,1,14.6600,100,1,12.4199,700,1,14.6799,1400,2,12.3699,700,1,14.6999,100,1,ARL,309415429
1407,2025-07-17T15:52:16.378962330Z,2025-07-17T15:52:16.378962330Z,10,2,1108,A,B,0,13.2599,100,130,165452,261714185,13.2699,10,1,13.8599,15,1,13.2599,100,1,13.8900,2,1,13.0399,2,1,13.9299,100,1,13.0299,100,1,14.2799,100,1,12.7300,100,1,14.4000,100,1,12.7100,100,1,14.5600,800,2,12.5000,700,1,14.5999,700,1,12.4600,200,2,14.6600,100,1,12.4299,700,1,14.6799,1400,2,12.4199,700,1,14.6999,100,1,ARL,312772077
1408,2025-07-17T15:52:16.388859982Z,2025-07-17T15:52:16.388859982Z,10,2,1108,C,A,0,13.9299,100,130,165487,261714477,13.2699,10,1,13.8599,15,1,13.2599,100,1,13.8900,2,1,13.0399,2,1,14.2799,100,1,13.0299,100,1,14.4000,100,1,12.7300,100,1,14.5600,800,2,12.7100,100,1,14.5999,700,1,12.5000,700,1,14.6600,100,1,12.4600,200,2,14.6799,1400,2,12.4299,700,1,14.6999,100,1,12.4199,700,1,14.7200,100,1,ARL,309782973
1409,2025-07-17T15:52:16.388917108Z,2025-07-17T15:52:16.388917108Z,10,2,1108,A,A,0,14.1899,100,130,165343,261714481,13.2699,10,1,13.8599,15,1,13.2599,100,1,13.8900,2,1,13.0399,2,1,14.1899,100,1,13.0299,100,1,14.2799,100,1,12.7300,100,1,14.4000,100,1,12.7100,100,1,14.5600,800,2,12.5000,700,1,14.5999,700,1,12.4600,200,2,14.6600,100,1,12.4299,700,1,14.6799,1400,2,12.4199,700,1,14.6999,100,1,ARL,312772501
1410,2025-07-17T15:52:16.396008715Z,2025-07-17T15:52:16.396008715Z,10,2,1108,C,A,0,14.6600,100,0,165787,261714603,13.2699,10,1,13.8599,15,1,13.2599,100,1,13.8900,2,1,13.0399,2,1,14.1899,100,1,13.0299,100,1,14.2799,100,1,12.7300,100,1,14.4000,100,1,12.7100,100,1,14.5600,800,2,12.5000,700,1,14.5999,700,1,12.4600,200,2,14.6799,1400,2,12.4299,700,1,14.6999,100,1,12.4199,700,1,14.7200,100,1,ARL,308903001
1411,2025-07-17T15:52:16.396008715Z,2025-07-17T15:52:16.396008715Z,10,2,1108,A,A,0,14.9600,100,130,165787,261714603,13.2699,10,1,13.8599,15,1,13.2599,100,1,13.8900,2,1,13.0399,2,1,14.1899,100,1,13.0299,100,1,14.2799,100,1,12.7300,100,1,14.4000,100,1,12.7100,100,1,14.5600,800,2,12.5000,700,1,14.5999,700,1,12.4600,200,2,14.6799,1400,2,12.4299,700,1,14.6999,100,1,12.4199,700,1,14.7200,100,1,ARL,312772869
1412,2025-07-17T15:52:16.397512710Z,2025-07-17T15:52:16.397512710Z,10,2,1108,C,A,0,14.1899,100,130,164971,261714619,13.2699,10,1,13.8599,15,1,13.2599,100,1,13.8900,2,1,13.0399,2,1,14.2799,100,1,13.0299,100,1,14.4000,100,1,12.7300,100,1,14.5600,800,2,12.7100,100,1,14.5999,700,1,12.5000,700,1,14.6799,1400,2,12.4600,200,2,14.6999,100,1,12.4299,700,1,14.7200,100,1,12.4199,700,1,14.7599,100,1,ARL,312772501
1413,2025-07-17T15:52:16.397561691Z,2025-07-17T15:52:16.397561691Z,10,2,1108,A,A,0,14.2599,100,130,165351,261714620,13.2699,10,1,13.8599,15,1,13.2599,100,1,13.8900,2,1,13.0399,2,1,14.2599,100,1,13.0299,100,1,14.2799,100,1,12.7300,100,1,14.4000,100,1,12.7100,100,1,14.5600,800,2,12.5000,700,1,14.5999,700,1,12.4600,200,2,14.6799,1400,2,12.4299,700,1,14.6999,100,1,12.4199,700,1,14.7200,100,1,ARL,312772901
1414,2025-07-17T15:52:16.423972000Z,2025-07-17T15:52:16.423972000Z,10,2,1108,C,A,0,14.6999,100,0,165423,261714976,13.2699,10,1,13.8599,15,1,13.2599,100,1,13.8900,2,1,13.0399,2,1,14.2599,100,1,13.0299,100,1,14.2799,100,1,12.7300,100,1,14.4000,100,1,12.7100,100,1,14.5600,800,2,12.5000,700,1,14.5999,700,1,12.4600,200,2,14.6799,1400,2,12.4299,700,1,14.7200,100,1,12.4199,700,1,14.7599,100,1,ARL,312771573
1415,2025-07-17T15:52:16.423972000Z,2025-07-17T15:52:16.423972000Z,10,2,1108,A,A,0,15.0600,100,130,165423,261714976,13.2699,10,1,13.8599,15,1,13.2599,100,1,13.8900,2,1,13.0399,2,1,14.2599,100,1,13.0299,100,1,14.2799,100,1,12.7300,100,1,14.4000,100,1,12.7100,100,1,14.5600,800,2,12.5000,700,1,14.5999,700,1,12.4600,200,2,14.6799,1400,2,12.4299,700,1,14.7200,100,1,12.4199,700,1,14.7599,100,1,ARL,312773353
1416,2025-07-17T15:52:16.464616142Z,2025-07-17T15:52:16.464616142Z,10,2,1108,A,A,0,13.8699,100,130,165201,261715303,13.2699,10,1,13.8599,15,1,13.2599,100,1,13.8699,100,1,13.0399,2,1,13.8900,2,1,13.0299,100,1,14.2599,100,1,12.7300,100,1,14.2799,100,1,12.7100,100,1,14.4000,100,1,12.5000,700,1,14.5600,800,2,12.4600,200,2,14.5999,700,1,12.4299,700,1,14.6799,1400,2,12.4199,700,1,14.7200,100,1,ARL,312773881
1417,2025-07-17T15:52:16.473391480Z,2025-07-17T15:52:16.473391480Z,10,2,1108,C,A,0,15.0600,100,0,165468,261715409,13.2699,10,1,13.8599,15,1,13.2599,100,1,13.8699,100,1,13.0399,2,1,13.8900,2,1,13.0299,100,1,14.2599,100,1,12.7300,100,1,14.2799,100,1,12.7100,100,1,14.4000,100,1,12.5000,700,1,14.5600,800,2,12.4600,200,2,14.5999,700,1,12.4299,700,1,14.6799,1400,2,12.4199,700,1,14.7200,100,1,ARL,312773353
1418,2025-07-17T15:52:16.473391480Z,2025-07-17T15:52:16.473391480Z,10,2,1108,A,A,0,14.9499,100,130,165468,261715409,13.2699,10,1,13.8599,15,1,13.2599,100,1,13.8699,100,1,13.0399,2,1,13.8900,2,1,13.0299,100,1,14.2599,100,1,12.7300,100,1,14.2799,100,1,12.7100,100,1,14.4000,100,1,12.5000,700,1,14.5600,800,2,12.4600,200,2,14.5999,700,1,12.4299,700,1,14.6799,1400,2,12.4199,700,1,14.7200,100,1,ARL,312774001
1419,2025-07-17T15:52:16.479925781Z,2025-07-17T15:52:16.479925781Z,10,2,1108,C,A,0,14.2599,100,130,165113,261715467,13.2699,10,1,13.8599,15,1,13.2599,100,1,13.8699,100,1,13.0399,2,1,13.8900,2,1,13.0299,100,1,14.2799,100,1,12.7300,100,1,14.4000,100,1,12.7100,100,1,14.5600,800,2,12.5000,700,1,14.5999,700,1,12.4600,200,2,14.6799,1400,2,12.4299,700,1,14.7200,100,1,12.4199,700,1,14.7599,100,1,ARL,312772901
1420,2025-07-17T15:52:16.479974840Z,2025-07-17T15:52:16.479974840Z,10,2,1108,A,A,0,14.1500,100,130,165291,261715468,13.2699,10,1,13.8599,15,1,13.2599,100,1,13.8699,100,1,13.0399,2,1,13.8900,2,1,13.0299,100,1,14.1500,100,1,12.7300,100,1,14.2799,100,1,12.7100,100,1,14.4000,100,1,12.5000,700,1,14.5600,800,2,12.4600,200,2,14.5999,700,1,12.4299,700,1,14.6799,1400,2,12.4199,700,1,14.7200,100,1,ARL,312774033
1421,2025-07-17T15:52:28.787151494Z,2025-07-17T15:52:28.787151494Z,10,2,1108,C,B,0,13.2699,10,130,165371,261883294,13.2599,100,1,13.8599,15,1,13.0399,2,1,13.8699,100,1,13.0299,100,1,13.8900,2,1,12.7300,100,1,14.1500,100,1,12.7100,100,1,14.2799,100,1,12.5000,700,1,14.4000,100,1,12.4600,200,2,14.5600,800,2,12.4299,700,1,14.5999,700,1,12.4199,700,1,14.6799,1400,2,12.3699,700,1,14.7200,100,1,ARL,312772069
1422,2025-07-17T15:52:28.787152437Z,2025-07-17T15:52:28.787152437Z,10,2,1108,C,A,0,13.8599,15,130,165390,261883295,13.2599,100,1,13.8699,100,1,13.0399,2,1,13.8900,2,1,13.0299,100,1,14.1500,100,1,12.7300,100,1,14.2799,100,1,12.7100,100,1,14.4000,100,1,12.5000,700,1,14.5600,800,2,12.4600,200,2,14.5999,700,1,12.4299,700,1,14.6799,1400,2,12.4199,700,1,14.7200,100,1,12.3699,700,1,14.7599,100,1,ARL,312772073
1423,2025-07-17T15:52:43.128203357Z,2025-07-17T15:52:43.128203357Z,10,2,1108,C,A,0,13.8900,2,0,167676,262115170,13.2599,100,1,13.8699,100,1,13.0399,2,1,14.1500,100,1,13.0299,100,1,14.2799,100,1,12.7300,100,1,14.4000,100,1,12.7100,100,1,14.5600,800,2,12.5000,700,1,14.5999,700,1,12.4600,200,2,14.6799,1400,2,12.4299,700,1,14.7200,100,1,12.4199,700,1,14.7599,100,1,12.3699,700,1,14.8100,100,1,ARL,311979125
1424,2025-07-17T15:52:43.128203357Z,2025-07-17T15:52:43.128203357Z,10,2,1108,A,A,0,13.9900,2,128,167676,262115170,13.2599,100,1,13.8699,100,1,13.0399,2,1,13.9900,2,1,13.0299,100,1,14.1500,100,1,12.7300,100,1,14.2799,100,1,12.7100,100,1,14.4000,100,1,12.5000,700,1,14.5600,800,2,12.4600,200,2,14.5999,700,1,12.4299,700,1,14.6799,1400,2,12.4199,700,1,14.7200,100,1,12.3699,700,1,14.7599,100,1,ARL,313336713
1425,2025-07-17T15:54:24.908318259Z,2025-07-17T15:54:24.908318259Z,10,2,1108,A,B,0,13.2899,10,130,165523,263863872,13.2899,10,1,13.8699,100,1,13.2599,100,1,13.9900,2,1,13.0399,2,1,14.1500,100,1,13.0299,100,1,14.2799,100,1,12.7300,100,1,14.4000,100,1,12.7100,100,1,14.5600,800,2,12.5000,700,1,14.5999,700,1,12.4600,200,2,14.6799,1400,2,12.4299,700,1,14.7200,100,1,12.4199,700,1,14.7599,100,1,ARL,315581981
1426,2025-07-17T15:54:26.792313320Z,2025-07-17T15:54:26.792313320Z,10,2,1108,C,B,0,13.2899,10,130,165136,263895481,13.2599,100,1,13.8699,100,1,13.0399,2,1,13.9900,2,1,13.0299,100,1,14.1500,100,1,12.7300,100,1,14.2799,100,1,12.7100,100,1,14.4000,100,1,12.5000,700,1,14.5600,800,2,12.4600,200,2,14.5999,700,1,12.4299,700,1,14.6799,1400,2,12.4199,700,1,14.7200,100,1,12.3699,700,1,14.7599,100,1,ARL,315581981
1427,2025-07-17T15:54:52.985950259Z,2025-07-17T15:54:52.985950259Z,10,2,1108,C,A,0,13.9900,2,0,165824,264262615,13.2599,100,1,13.8699,100,1,13.0399,2,1,14.1500,100,1,13.0299,100,1,14.2799,100,1,12.7300,100,1,14.4000,100,1,12.7100,100,1,14.5600,800,2,12.5000,700,1,14.5999,700,1,12.4600,200,2,14.6799,1400,2,12.4299,700,1,14.7200,100,1,12.4199,700,1,14.7599,100,1,12.3699,700,1,14.8100,100,1,ARL,313336713
1428,2025-07-17T15:54:52.985950259Z,2025-07-17T15:54:52.985950259Z,10,2,1108,A,A,0,14.0999,2,130,165824,264262615,13.2599,100,1,13.8699,100,1,13.0399,2,1,14.0999,2,1,13.0299,100,1,14.1500,100,1,12.7300,100,1,14.2799,100,1,12.7100,100,1,14.4000,100,1,12.5000,700,1,14.5600,800,2,12.4600,200,2,14.5999,700,1,12.4299,700,1,14.6799,1400,2,12.4199,700,1,14.7200,100,1,12.3699,700,1,14.7599,100,1,ARL,316098525
1429,2025-07-17T15:55:33.673432762Z,2025-07-17T15:55:33.673432762Z,10,2,1108,A,B,0,13.2899,10,130,165490,264905534,13.2899,10,1,13.8699,100,1,13.2599,100,1,14.0999,2,1,13.0399,2,1,14.1500,100,1,13.0299,100,1,14.2799,100,1,12.7300,100,1,14.4000,100,1,12.7100,100,1,14.5600,800,2,12.5000,700,1,14.5999,700,1,12.4600,200,2,14.6799,1400,2,12.4299,700,1,14.7200,100,1,12.4199,700,1,14.7599,100,1,ARL,316911465
1430,2025-07-17T15:55:34.257251787Z,2025-07-17T15:55:34.257251787Z,10,2,1108,C,B,0,13.2599,100,0,165417,264919835,13.2899,10,1,13.8699,100,1,13.0399,2,1,14.0999,2,1,13.0299,100,1,14.1500,100,1,12.7300,100,1,14.2799,100,1,12.7100,100,1,14.4000,100,1,12.5000,700,1,14.5600,800,2,12.4600,200,2,14.5999,700,1,12.4299,700,1,14.6799,1400,2,12.4199,700,1,14.7200,100,1,12.3699,700,1,14.7599,100,1,ARL,312772077
1431,2025-07-17T15:55:34.257251787Z,2025-07-17T15:55:34.257251787Z,10,2,1108,A,B,0,13.2799,100,130,165417,264919835,13.2899,10,1,13.8699,100,1,13.2799,100,1,14.0999,2,1,13.0399,2,1,14.1500,100,1,13.0299,100,1,14.2799,100,1,12.7300,100,1,14.4000,100,1,12.7100,100,1,14.5600,800,2,12.5000,700,1,14.5999,700,1,12.4600,200,2,14.6799,1400,2,12.4299,700,1,14.7200,100,1,12.4199,700,1,14.7599,100,1,ARL,316924721
1432,2025-07-17T15:55:40.197584524Z,2025-07-17T15:55:40.197584524Z,10,2,1108,C,B,0,13.2899,10,130,165876,265015966,13.2799,100,1,13.8699,100,1,13.0399,2,1,14.0999,2,1,13.0299,100,1,14.1500,100,1,12.7300,100,1,14.2799,100,1,12.7100,100,1,14.4000,100,1,12.5000,700,1,14.5600,800,2,12.4600,200,2,14.5999,700,1,12.4299,700,1,14.6799,1400,2,12.4199,700,1,14.7200,100,1,12.3699,700,1,14.7599,100,1,ARL,316911465
1433,2025-07-17T15:57:51.111121910Z,2025-07-17T15:57:51.111121910Z,10,2,1108,T,N,0,13.5999,1,0,167045,267268162,13.2799,100,1,13.8699,100,1,13.0399,2,1,14.0999,2,1,13.0299,100,1,14.1500,100,1,12.7300,100,1,14.2799,100,1,12.7100,100,1,14.4000,100,1,12.5000,700,1,14.5600,800,2,12.4600,200,2,14.5999,700,1,12.4299,700,1,14.6799,1400,2,12.4199,700,1,14.7200,100,1,12.3699,700,1,14.7599,100,1,ARL,0
1434,2025-07-17T15:57:51.111121910Z,2025-07-17T15:57:51.111121910Z,10,2,1108,T,N,0,13.5749,99,130,167045,267268163,13.2799,100,1,13.8699,100,1,13.0399,2,1,14.0999,2,1,13.0299,100,1,14.1500,100,1,12.7300,100,1,14.2799,100,1,12.7100,100,1,14.4000,100,1,12.5000,700,1,14.5600,800,2,12.4600,200,2,14.5999,700,1,12.4299,700,1,14.6799,1400,2,12.4199,700,1,14.7200,100,1,12.3699,700,1,14.7599,100,1,ARL,0
1435,2025-07-17T15:57:51.111527963Z,2025-07-17T15:57:51.111527963Z,10,2,1108,T,N,0,13.5749,100,130,165792,267268168,13.2799,100,1,13.8699,100,1,13.0399,2,1,14.0999,2,1,13.0299,100,1,14.1500,100,1,12.7300,100,1,14.2799,100,1,12.7100,100,1,14.4000,100,1,12.5000,700,1,14.5600,800,2,12.4600,200,2,14.5999,700,1,12.4299,700,1,14.6799,1400,2,12.4199,700,1,14.7200,100,1,12.3699,700,1,14.7599,100,1,ARL,0
1436,2025-07-17T15:57:51.111911476Z,2025-07-17T15:57:51.111911476Z,10,2,1108,T,N,0,13.5749,1,130,166056,267268183,13.2799,100,1,13.8699,100,1,13.0399,2,1,14.0999,2,1,13.0299,100,1,14.1500,100,1,12.7300,100,1,14.2799,100,1,12.7100,100,1,14.4000,100,1,12.5000,700,1,14.5600,800,2,12.4600,200,2,14.5999,700,1,12.4299,700,1,14.6799,1400,2,12.4199,700,1,14.7200,100,1,12.3699,700,1,14.7599,100,1,ARL,0
1437,2025-07-17T15:57:51.328698198Z,2025-07-17T15:57:51.328698198Z,10,2,1108,C,A,0,13.8699,100,130,165362,267272430,13.2799,100,1,14.0999,2,1,13.0399,2,1,14.1500,100,1,13.0299,100,1,14.2799,100,1,12.7300,100,1,14.4000,100,1,12.7100,100,1,14.5600,800,2,12.5000,700,1,14.5999,700,1,12.4600,200,2,14.6799,1400,2,12.4299,700,1,14.7200,100,1,12.4199,700,1,14.7599,100,1,12.3699,700,1,14.8100,100,1,ARL,312773881
1438,2025-07-17T15:57:51.329447325Z,2025-07-17T15:57:51.329447325Z,10,2,1108,C,A,0,14.9499,100,0,166259,267272438,13.2799,100,1,14.0999,2,1,13.0399,2,1,14.1500,100,1,13.0299,100,1,14.2799,100,1,12.7300,100,1,14.4000,100,1,12.7100,100,1,14.5600,800,2,12.5000,700,1,14.5999,700,1,12.4600,200,2,14.6799,1400,2,12.4299,700,1,14.7200,100,1,12.4199,700,1,14.7599,100,1,12.3699,700,1,14.8100,100,1,ARL,312774001
1439,2025-07-17T15:57:51.329447325Z,2025-07-17T15:57:51.329447325Z,10,2,1108,A,A,0,15.0000,100,130,166259,267272438,13.2799,100,1,14.0999,2,1,13.0399,2,1,14.1500,100,1,13.0299,100,1,14.2799,100,1,12.7300,100,1,14.4000,100,1,12.7100,100,1,14.5600,800,2,12.5000,700,1,14.5999,700,1,12.4600,200,2,14.6799,1400,2,12.4299,700,1,14.7200,100,1,12.4199,700,1,14.7599,100,1,12.3699,700,1,14.8100,100,1,ARL,319985021
1440,2025-07-17T15:57:51.329692071Z,2025-07-17T15:57:51.329692071Z,10,2,1108,C,A,0,14.7599,100,0,165601,267272442,13.2799,100,1,14.0999,2,1,13.0399,2,1,14.1500,100,1,13.0299,100,1,14.2799,100,1,12.7300,100,1,14.4000,100,1,12.7100,100,1,14.5600,800,2,12.5000,700,1,14.5999,700,1,12.4600,200,2,14.6799,1400,2,12.4299,700,1,14.7200,100,1,12.4199,700,1,14.8100,100,1,12.3699,700,1,14.8900,100,1,ARL,312771829
1441,2025-07-17T15:57:51.329692071Z,2025-07-17T15:57:51.329692071Z,10,2,1108,A,A,0,14.8900,100,130,165601,267272442,13.2799,100,1,14.0999,2,1,13.0399,2,1,14.1500,100,1,13.0299,100,1,14.2799,100,1,12.7300,100,1,14.4000,100,1,12.7100,100,1,14.5600,800,2,12.5000,700,1,14.5999,700,1,12.4600,200,2,14.6799,1400,2,12.4299,700,1,14.7200,100,1,12.4199,700,1,14.8100,100,1,12.3699,700,1,14.8900,200,2,ARL,319985025
1442,2025-07-17T15:57:51.339162512Z,2025-07-17T15:57:51.339162512Z,10,2,1108,C,A,0,14.1500,100,130,165707,267272660,13.2799,100,1,14.0999,2,1,13.0399,2,1,14.2799,100,1,13.0299,100,1,14.4000,100,1,12.7300,100,1,14.5600,800,2,12.7100,100,1,14.5999,700,1,12.5000,700,1,14.6799,1400,2,12.4600,200,2,14.7200,100,1,12.4299,700,1,14.8100,100,1,12.4199,700,1,14.8900,200,2,12.3699,700,1,14.9600,100,1,ARL,312774033
1443,2025-07-17T15:57:51.339216923Z,2025-07-17T15:57:51.339216923Z,10,2,1108,A,A,0,14.2599,100,130,165175,267272665,13.2799,100,1,14.0999,2,1,13.0399,2,1,14.2599,100,1,13.0299,100,1,14.2799,100,1,12.7300,100,1,14.4000,100,1,12.7100,100,1,14.5600,800,2,12.5000,700,1,14.5999,700,1,12.4600,200,2,14.6799,1400,2,12.4299,700,1,14.7200,100,1,12.4199,700,1,14.8100,100,1,12.3699,700,1,14.8900,200,2,ARL,319985165
1444,2025-07-17T15:57:51.379570470Z,2025-07-17T15:57:51.379570470Z,10,2,1108,C,A,0,15.0000,100,0,166382,267273071,13.2799,100,1,14.0999,2,1,13.0399,2,1,14.2599,100,1,13.0299,100,1,14.2799,100,1,12.7300,100,1,14.4000,100,1,12.7100,100,1,14.5600,800,2,12.5000,700,1,14.5999,700,1,12.4600,200,2,14.6799,1400,2,12.4299,700,1,14.7200,100,1,12.4199,700,1,14.8100,100,1,12.3699,700,1,14.8900,200,2,ARL,319985021
1445,2025-07-17T15:57:51.379570470Z,2025-07-17T15:57:51.379570470Z,10,2,1108,A,A,0,15.0600,100,128,166382,267273071,13.2799,100,1,14.0999,2,1,13.0399,2,1,14.2599,100,1,13.0299,100,1,14.2799,100,1,12.7300,100,1,14.4000,100,1,12.7100,100,1,14.5600,800,2,12.5000,700,1,14.5999,700,1,12.4600,200,2,14.6799,1400,2,12.4299,700,1,14.7200,100,1,12.4199,700,1,14.8100,100,1,12.3699,700,1,14.8900,200,2,ARL,319985497
1446,2025-07-17T15:57:52.378204338Z,2025-07-17T15:57:52.378204338Z,10,2,1108,A,A,0,14.1099,100,130,165186,267283873,13.2799,100,1,14.0999,2,1,13.0399,2,1,14.1099,100,1,13.0299,100,1,14.2599,100,1,12.7300,100,1,14.2799,100,1,12.7100,100,1,14.4000,100,1,12.5000,700,1,14.5600,800,2,12.4600,200,2,14.5999,700,1,12.4299,700,1,14.6799,1400,2,12.4199,700,1,14.7200,100,1,12.3699,700,1,14.8100,100,1,ARL,320000233
1447,2025-07-17T15:58:14.483712278Z,2025-07-17T15:58:14.483712278Z,10,2,1108,T,N,0,13.4100,44,130,166801,267657010,13.2799,100,1,14.0999,2,1,13.0399,2,1,14.1099,100,1,13.0299,100,1,14.2599,100,1,12.7300,100,1,14.2799,100,1,12.7100,100,1,14.4000,100,1,12.5000,700,1,14.5600,800,2,12.4600,200,2,14.5999,700,1,12.4299,700,1,14.6799,1400,2,12.4199,700,1,14.7200,100,1,12.3699,700,1,14.8100,100,1,ARL,0
1448,2025-07-17T15:58:14.483743947Z,2025-07-17T15:58:14.483743947Z,10,2,1108,A,A,0,13.7599,4,130,165407,267657011,13.2799,100,1,13.7599,4,1,13.0399,2,1,14.0999,2,1,13.0299,100,1,14.1099,100,1,12.7300,100,1,14.2599,100,1,12.7100,100,1,14.2799,100,1,12.5000,700,1,14.4000,100,1,12.4600,200,2,14.5600,800,2,12.4299,700,1,14.5999,700,1,12.4199,700,1,14.6799,1400,2,12.3699,700,1,14.7200,100,1,ARL,320484625
1449,2025-07-17T15:58:14.483999049Z,2025-07-17T15:58:14.483999049Z,10,2,1108,C,A,0,14.1099,100,0,165502,267657013,13.2799,100,1,13.7599,4,1,13.0399,2,1,14.0999,2,1,13.0299,100,1,14.2599,100,1,12.7300,100,1,14.2799,100,1,12.7100,100,1,14.4000,100,1,12.5000,700,1,14.5600,800,2,12.4600,200,2,14.5999,700,1,12.4299,700,1,14.6799,1400,2,12.4199,700,1,14.7200,100,1,12.3699,700,1,14.8100,100,1,ARL,320000233
1450,2025-07-17T15:58:14.483999049Z,2025-07-17T15:58:14.483999049Z,10,2,1108,A,A,0,13.7699,100,130,165502,267657013,13.2799,100,1,13.7599,4,1,13.0399,2,1,13.7699,100,1,13.0299,100,1,14.0999,2,1,12.7300,100,1,14.2599,100,1,12.7100,100,1,14.2799,100,1,12.5000,700,1,14.4000,100,1,12.4600,200,2,14.5600,800,2,12.4299,700,1,14.5999,700,1,12.4199,700,1,14.6799,1400,2,12.3699,700,1,14.7200,100,1,ARL,320484637
1451,2025-07-17T15:58:14.484017806Z,2025-07-17T15:58:14.484017806Z,10,2,1108,C,B,0,13.2799,100,130,165607,267657014,13.0399,2,1,13.7599,4,1,13.0299,100,1,13.7699,100,1,12.7300,100,1,14.0999,2,1,12.7100,100,1,14.2599,100,1,12.5000,700,1,14.2799,100,1,12.4600,200,2,14.4000,100,1,12.4299,700,1,14.5600,800,2,12.4199,700,1,14.5999,700,1,12.3699,700,1,14.6799,1400,2,12.3599,200,2,14.7200,100,1,ARL,316924721
1452,2025-07-17T15:58:14.484133730Z,2025-07-17T15:58:14.484133730Z,10,2,1108,T,N,0,13.4100,8,130,165720,267657017,13.0399,2,1,13.7599,4,1,13.0299,100,1,13.7699,100,1,12.7300,100,1,14.0999,2,1,12.7100,100,1,14.2599,100,1,12.5000,700,1,14.2799,100,1,12.4600,200,2,14.4000,100,1,12.4299,700,1,14.5600,800,2,12.4199,700,1,14.5999,700,1,12.3699,700,1,14.6799,1400,2,12.3599,200,2,14.7200,100,1,ARL,0
1453,2025-07-17T15:58:14.484147359Z,2025-07-17T15:58:14.484147359Z,10,2,1108,A,A,0,13.7899,100,130,165173,267657020,13.0399,2,1,13.7599,4,1,13.0299,100,1,13.7699,100,1,12.7300,100,1,13.7899,100,1,12.7100,100,1,14.0999,2,1,12.5000,700,1,14.2599,100,1,12.4600,200,2,14.2799,100,1,12.4299,700,1,14.4000,100,1,12.4199,700,1,14.5600,800,2,12.3699,700,1,14.5999,700,1,12.3599,200,2,14.6799,1400,2,ARL,320484661
1454,2025-07-17T15:58:14.484736787Z,2025-07-17T15:58:14.484736787Z,10,2,1108,C,A,0,15.0600,100,0,165388,267657063,13.0399,2,1,13.7599,4,1,13.0299,100,1,13.7699,100,1,12.7300,100,1,13.7899,100,1,12.7100,100,1,14.0999,2,1,12.5000,700,1,14.2599,100,1,12.4600,200,2,14.2799,100,1,12.4299,700,1,14.4000,100,1,12.4199,700,1,14.5600,800,2,12.3699,700,1,14.5999,700,1,12.3599,200,2,14.6799,1400,2,ARL,319985497
1455,2025-07-17T15:58:14.484736787Z,2025-07-17T15:58:14.484736787Z,10,2,1108,A,A,0,14.8399,100,130,165388,267657063,13.0399,2,1,13.7599,4,1,13.0299,100,1,13.7699,100,1,12.7300,100,1,13.7899,100,1,12.7100,100,1,14.0999,2,1,12.5000,700,1,14.2599,100,1,12.4600,200,2,14.2799,100,1,12.4299,700,1,14.4000,100,1,12.4199,700,1,14.5600,800,2,12.3699,700,1,14.5999,700,1,12.3599,200,2,14.6799,1400,2,ARL,320484709
1456,2025-07-17T15:58:14.484761664Z,2025-07-17T15:58:14.484761664Z,10,2,1108,C,A,0,13.7599,4,128,166184,267657070,13.0399,2,1,13.7699,100,1,13.0299,100,1,13.7899,100,1,12.7300,100,1,14.0999,2,1,12.7100,100,1,14.2599,100,1,12.5000,700,1,14.2799,100,1,12.4600,200,2,14.4000,100,1,12.4299,700,1,14.5600,800,2,12.4199,700,1,14.5999,700,1,12.3699,700,1,14.6799,1400,2,12.3599,200,2,14.7200,100,1,ARL,320484625
1457,2025-07-17T15:58:14.484798779Z,2025-07-17T15:58:14.484798779Z,10,2,1108,C,A,0,13.7699,100,130,165091,267657073,13.0399,2,1,13.7899,100,1,13.0299,100,1,14.0999,2,1,12.7300,100,1,14.2599,100,1,12.7100,100,1,14.2799,100,1,12.5000,700,1,14.4000,100,1,12.4600,200,2,14.5600,800,2,12.4299,700,1,14.5999,700,1,12.4199,700,1,14.6799,1400,2,12.3699,700,1,14.7200,100,1,12.3599,200,2,14.8100,100,1,ARL,320484637
1458,2025-07-17T15:58:14.485227487Z,2025-07-17T15:58:14.485227487Z,10,2,1108,C,A,0,14.8100,100,0,165416,267657092,13.0399,2,1,13.7899,100,1,13.0299,100,1,14.0999,2,1,12.7300,100,1,14.2599,100,1,12.7100,100,1,14.2799,100,1,12.5000,700,1,14.4000,100,1,12.4600,200,2,14.5600,800,2,12.4299,700,1,14.5999,700,1,12.4199,700,1,14.6799,1400,2,12.3699,700,1,14.7200,100,1,12.3599,200,2,14.8399,100,1,ARL,312771781
1459,2025-07-17T15:58:14.485227487Z,2025-07-17T15:58:14.485227487Z,10,2,1108,A,A,0,14.6799,100,130,165416,267657092,13.0399,2,1,13.7899,100,1,13.0299,100,1,14.0999,2,1,12.7300,100,1,14.2599,100,1,12.7100,100,1,14.2799,100,1,12.5000,700,1,14.4000,100,1,12.4600,200,2,14.5600,800,2,12.4299,700,1,14.5999,700,1,12.4199,700,1,14.6799,1500,3,12.3699,700,1,14.7200,100,1,12.3599,200,2,14.8399,100,1,ARL,320484781
1460,2025-07-17T15:58:14.485666254Z,2025-07-17T15:58:14.485666254Z,10,2,1108,C,A,0,16.0199,100,0,165348,267657097,13.0399,2,1,13.7899,100,1,13.0299,100,1,14.0999,2,1,12.7300,100,1,14.2599,100,1,12.7100,100,1,14.2799,100,1,12.5000,700,1,14.4000,100,1,12.4600,200,2,14.5600,800,2,12.4299,700,1,14.5999,700,1,12.4199,700,1,14.6799,1500,3,12.3699,700,1,14.7200,100,1,12.3599,200,2,14.8399,100,1,ARL,312772057
1461,2025-07-17T15:58:14.485666254Z,2025-07-17T15:58:14.485666254Z,10,2,1108,A,A,0,15.8599,100,130,165348,267657097,13.0399,2,1,13.7899,100,1,13.0299,100,1,14.0999,2,1,12.7300,100,1,14.2599,100,1,12.7100,100,1,14.2799,100,1,12.5000,700,1,14.4000,100,1,12.4600,200,2,14.5600,800,2,12.4299,700,1,14.5999,700,1,12.4199,700,1,14.6799,1500,3,12.3699,700,1,14.7200,100,1,12.3599,200,2,14.8399,100,1,ARL,320484817
1462,2025-07-17T15:58:14.485685308Z,2025-07-17T15:58:14.485685308Z,10,2,1108,C,A,0,14.9600,100,0,165566,267657098,13.0399,2,1,13.7899,100,1,13.0299,100,1,14.0999,2,1,12.7300,100,1,14.2599,100,1,12.7100,100,1,14.2799,100,1,12.5000,700,1,14.4000,100,1,12.4600,200,2,14.5600,800,2,12.4299,700,1,14.5999,700,1,12.4199,700,1,14.6799,1500,3,12.3699,700,1,14.7200,100,1,12.3599,200,2,14.8399,100,1,ARL,312772869
1463,2025-07-17T15:58:14.485685308Z,2025-07-17T15:58:14.485685308Z,10,2,1108,A,A,0,14.7599,100,130,165566,267657098,13.0399,2,1,13.7899,100,1,13.0299,100,1,14.0999,2,1,12.7300,100,1,14.2599,100,1,12.7100,100,1,14.2799,100,1,12.5000,700,1,14.4000,100,1,12.4600,200,2,14.5600,800,2,12.4299,700,1,14.5999,700,1,12.4199,700,1,14.6799,1500,3,12.3699,700,1,14.7200,100,1,12.3599,200,2,14.7599,100,1,ARL,320484821
1464,2025-07-17T15:58:14.485824228Z,2025-07-17T15:58:14.485824228Z,10,2,1108,C,A,0,14.8900,100,0,165415,267657101,13.0399,2,1,13.7899,100,1,13.0299,100,1,14.0999,2,1,12.7300,100,1,14.2599,100,1,12.7100,100,1,14.2799,100,1,12.5000,700,1,14.4000,100,1,12.4600,200,2,14.5600,800,2,12.4299,700,1,14.5999,700,1,12.4199,700,1,14.6799,1500,3,12.3699,700,1,14.7200,100,1,12.3599,200,2,14.7599,100,1,ARL,319985025
1465,2025-07-17T15:58:14.485824228Z,2025-07-17T15:58:14.485824228Z,10,2,1108,A,A,0,14.6899,100,130,165415,267657101,13.0399,2,1,13.7899,100,1,13.0299,100,1,14.0999,2,1,12.7300,100,1,14.2599,100,1,12.7100,100,1,14.2799,100,1,12.5000,700,1,14.4000,100,1,12.4600,200,2,14.5600,800,2,12.4299,700,1,14.5999,700,1,12.4199,700,1,14.6799,1500,3,12.3699,700,1,14.6899,100,1,12.3599,200,2,14.7200,100,1,ARL,320484825
1466,2025-07-17T15:58:14.486240860Z,2025-07-17T15:58:14.486240860Z,10,2,1108,C,A,0,17.6999,100,0,165495,267657116,13.0399,2,1,13.7899,100,1,13.0299,100,1,14.0999,2,1,12.7300,100,1,14.2599,100,1,12.7100,100,1,14.2799,100,1,12.5000,700,1,14.4000,100,1,12.4600,200,2,14.5600,800,2,12.4299,700,1,14.5999,700,1,12.4199,700,1,14.6799,1500,3,12.3699,700,1,14.6899,100,1,12.3599,200,2,14.7200,100,1,ARL,312772009
1467,2025-07-17T15:58:14.486240860Z,2025-07-17T15:58:14.486240860Z,10,2,1108,A,A,0,17.5199,100,130,165495,267657116,13.0399,2,1,13.7899,100,1,13.0299,100,1,14.0999,2,1,12.7300,100,1,14.2599,100,1,12.7100,100,1,14.2799,100,1,12.5000,700,1,14.4000,100,1,12.4600,200,2,14.5600,800,2,12.4299,700,1,14.5999,700,1,12.4199,700,1,14.6799,1500,3,12.3699,700,1,14.6899,100,1,12.3599,200,2,14.7200,100,1,ARL,320484837
1468,2025-07-17T15:58:14.508012098Z,2025-07-17T15:58:14.508012098Z,10,2,1108,C,A,0,14.2599,100,130,165158,267657330,13.0399,2,1,13.7899,100,1,13.0299,100,1,14.0999,2,1,12.7300,100,1,14.2799,100,1,12.7100,100,1,14.4000,100,1,12.5000,700,1,14.5600,800,2,12.4600,200,2,14.5999,700,1,12.4299,700,1,14.6799,1500,3,12.4199,700,1,14.6899,100,1,12.3699,700,1,14.7200,100,1,12.3599,200,2,14.7599,100,1,ARL,319985165
1469,2025-07-17T15:58:14.508062605Z,2025-07-17T15:58:14.508062605Z,10,2,1108,A,A,0,14.0500,100,130,165285,267657333,13.0399,2,1,13.7899,100,1,13.0299,100,1,14.0500,100,1,12.7300,100,1,14.0999,2,1,12.7100,100,1,14.2799,100,1,12.5000,700,1,14.4000,100,1,12.4600,200,2,14.5600,800,2,12.4299,700,1,14.5999,700,1,12.4199,700,1,14.6799,1500,3,12.3699,700,1,14.6899,100,1,12.3599,200,2,14.7200,100,1,ARL,320484985
1470,2025-07-17T15:58:14.529391743Z,2025-07-17T15:58:14.529391743Z,10,2,1108,A,B,0,13.0199,100,130,165365,267657561,13.0399,2,1,13.7899,100,1,13.0299,100,1,14.0500,100,1,13.0199,100,1,14.0999,2,1,12.7300,100,1,14.2799,100,1,12.7100,100,1,14.4000,100,1,12.5000,700,1,14.5600,800,2,12.4600,200,2,14.5999,700,1,12.4299,700,1,14.6799,1500,3,12.4199,700,1,14.6899,100,1,12.3699,700,1,14.7200,100,1,ARL,320485385
1471,2025-07-17T15:58:14.529413184Z,2025-07-17T15:58:14.529413184Z,10,2,1108,A,A,0,13.8000,100,130,165107,267657562,13.0399,2,1,13.7899,100,1,13.0299,100,1,13.8000,100,1,13.0199,100,1,14.0500,100,1,12.7300,100,1,14.0999,2,1,12.7100,100,1,14.2799,100,1,12.5000,700,1,14.4000,100,1,12.4600,200,2,14.5600,800,2,12.4299,700,1,14.5999,700,1,12.4199,700,1,14.6799,1500,3,12.3699,700,1,14.6899,100,1,ARL,320485389
1472,2025-07-17T15:58:14.659734381Z,2025-07-17T15:58:14.659734381Z,10,2,1108,C,A,0,13.7899,100,130,165045,267658873,13.0399,2,1,13.8000,100,1,13.0299,100,1,14.0500,100,1,13.0199,100,1,14.0999,2,1,12.7300,100,1,14.2799,100,1,12.7100,100,1,14.4000,100,1,12.5000,700,1,14.5600,800,2,12.4600,200,2,14.5999,700,1,12.4299,700,1,14.6799,1500,3,12.4199,700,1,14.6899,100,1,12.3699,700,1,14.7200,100,1,ARL,320484661
1473,2025-07-17T15:58:14.659773896Z,2025-07-17T15:58:14.659773896Z,10,2,1108,C,A,0,13.8000,100,130,165334,267658879,13.0399,2,1,14.0500,100,1,13.0299,100,1,14.0999,2,1,13.0199,100,1,14.2799,100,1,12.7300,100,1,14.4000,100,1,12.7100,100,1,14.5600,800,2,12.5000,700,1,14.5999,700,1,12.4600,200,2,14.6799,1500,3,12.4299,700,1,14.6899,100,1,12.4199,700,1,14.7200,100,1,12.3699,700,1,14.7599,100,1,ARL,320485389
1474,2025-07-17T15:58:14.660502341Z,2025-07-17T15:58:14.660502341Z,10,2,1108,C,A,0,14.8399,100,0,165295,267658892,13.0399,2,1,14.0500,100,1,13.0299,100,1,14.0999,2,1,13.0199,100,1,14.2799,100,1,12.7300,100,1,14.4000,100,1,12.7100,100,1,14.5600,800,2,12.5000,700,1,14.5999,700,1,12.4600,200,2,14.6799,1500,3,12.4299,700,1,14.6899,100,1,12.4199,700,1,14.7200,100,1,12.3699,700,1,14.7599,100,1,ARL,320484709
1475,2025-07-17T15:58:14.660502341Z,2025-07-17T15:58:14.660502341Z,10,2,1108,A,A,0,14.9100,100,130,165295,267658892,13.0399,2,1,14.0500,100,1,13.0299,100,1,14.0999,2,1,13.0199,100,1,14.2799,100,1,12.7300,100,1,14.4000,100,1,12.7100,100,1,14.5600,800,2,12.5000,700,1,14.5999,700,1,12.4600,200,2,14.6799,1500,3,12.4299,700,1,14.6899,100,1,12.4199,700,1,14.7200,100,1,12.3699,700,1,14.7599,100,1,ARL,320486925
1476,2025-07-17T15:58:14.664213722Z,2025-07-17T15:58:14.664213722Z,10,2,1108,C,A,0,17.5199,100,0,165240,267658928,13.0399,2,1,14.0500,100,1,13.0299,100,1,14.0999,2,1,13.0199,100,1,14.2799,100,1,12.7300,100,1,14.4000,100,1,12.7100,100,1,14.5600,800,2,12.5000,700,1,14.5999,700,1,12.4600,200,2,14.6799,1500,3,12.4299,700,1,14.6899,100,1,12.4199,700,1,14.7200,100,1,12.3699,700,1,14.7599,100,1,ARL,320484837
1477,2025-07-17T15:58:14.664213722Z,2025-07-17T15:58:14.664213722Z,10,2,1108,A,A,0,17.7600,100,130,165240,267658928,13.0399,2,1,14.0500,100,1,13.0299,100,1,14.0999,2,1,13.0199,100,1,14.2799,100,1,12.7300,100,1,14.4000,100,1,12.7100,100,1,14.5600,800,2,12.5000,700,1,14.5999,700,1,12.4600,200,2,14.6799,1500,3,12.4299,700,1,14.6899,100,1,12.4199,700,1,14.7200,100,1,12.3699,700,1,14.7599,100,1,ARL,320486937
1478,2025-07-17T15:58:14.664774078Z,2025-07-17T15:58:14.664774078Z,10,2,1108,C,A,0,15.8599,100,0,165232,267658931,13.0399,2,1,14.0500,100,1,13.0299,100,1,14.0999,2,1,13.0199,100,1,14.2799,100,1,12.7300,100,1,14.4000,100,1,12.7100,100,1,14.5600,800,2,12.5000,700,1,14.5999,700,1,12.4600,200,2,14.6799,1500,3,12.4299,700,1,14.6899,100,1,12.4199,700,1,14.7200,100,1,12.3699,700,1,14.7599,100,1,ARL,320484817
1479,2025-07-17T15:58:14.664774078Z,2025-07-17T15:58:14.664774078Z,10,2,1108,A,A,0,16.0799,100,130,165232,267658931,13.0399,2,1,14.0500,100,1,13.0299,100,1,14.0999,2,1,13.0199,100,1,14.2799,100,1,12.7300,100,1,14.4000,100,1,12.7100,100,1,14.5600,800,2,12.5000,700,1,14.5999,700,1,12.4600,200,2,14.6799,1500,3,12.4299,700,1,14.6899,100,1,12.4199,700,1,14.7200,100,1,12.3699,700,1,14.7599,100,1,ARL,320486945
1480,2025-07-17T15:58:14.672150755Z,2025-07-17T15:58:14.672150755Z,10,2,1108,C,A,0,14.0500,100,130,165051,267658982,13.0399,2,1,14.0999,2,1,13.0299,100,1,14.2799,100,1,13.0199,100,1,14.4000,100,1,12.7300,100,1,14.5600,800,2,12.7100,100,1,14.5999,700,1,12.5000,700,1,14.6799,1500,3,12.4600,200,2,14.6899,100,1,12.4299,700,1,14.7200,100,1,12.4199,700,1,14.7599,100,1,12.3699,700,1,14.8900,100,1,ARL,320484985
1481,2025-07-17T15:58:14.672200872Z,2025-07-17T15:58:14.672200872Z,10,2,1108,A,A,0,14.1199,100,130,165102,267658983,13.0399,2,1,14.0999,2,1,13.0299,100,1,14.1199,100,1,13.0199,100,1,14.2799,100,1,12.7300,100,1,14.4000,100,1,12.7100,100,1,14.5600,800,2,12.5000,700,1,14.5999,700,1,12.4600,200,2,14.6799,1500,3,12.4299,700,1,14.6899,100,1,12.4199,700,1,14.7200,100,1,12.3699,700,1,14.7599,100,1,ARL,320487017
1482,2025-07-17T15:58:14.673019194Z,2025-07-17T15:58:14.673019194Z,10,2,1108,C,A,0,14.1199,100,130,164922,267658989,13.0399,2,1,14.0999,2,1,13.0299,100,1,14.2799,100,1,13.0199,100,1,14.4000,100,1,12.7300,100,1,14.5600,800,2,12.7100,100,1,14.5999,700,1,12.5000,700,1,14.6799,1500,3,12.4600,200,2,14.6899,100,1,12.4299,700,1,14.7200,100,1,12.4199,700,1,14.7599,100,1,12.3699,700,1,14.8900,100,1,ARL,320487017
1483,2025-07-17T15:58:14.673065320Z,2025-07-17T15:58:14.673065320Z,10,2,1108,A,A,0,14.2599,100,130,165160,267658990,13.0399,2,1,14.0999,2,1,13.0299,100,1,14.2599,100,1,13.0199,100,1,14.2799,100,1,12.7300,100,1,14.4000,100,1,12.7100,100,1,14.5600,800,2,12.5000,700,1,14.5999,700,1,12.4600,200,2,14.6799,1500,3,12.4299,700,1,14.6899,100,1,12.4199,700,1,14.7200,100,1,12.3699,700,1,14.7599,100,1,ARL,320487025
1484,2025-07-17T15:58:14.682780396Z,2025-07-17T15:58:14.682780396Z,10,2,1108,C,A,0,14.7599,100,0,165145,267659018,13.0399,2,1,14.0999,2,1,13.0299,100,1,14.2599,100,1,13.0199,100,1,14.2799,100,1,12.7300,100,1,14.4000,100,1,12.7100,100,1,14.5600,800,2,12.5000,700,1,14.5999,700,1,12.4600,200,2,14.6799,1500,3,12.4299,700,1,14.6899,100,1,12.4199,700,1,14.7200,100,1,12.3699,700,1,14.8900,100,1,ARL,320484821
1485,2025-07-17T15:58:14.682780396Z,2025-07-17T15:58:14.682780396Z,10,2,1108,A,A,0,14.9600,100,130,165145,267659018,13.0399,2,1,14.0999,2,1,13.0299,100,1,14.2599,100,1,13.0199,100,1,14.2799,100,1,12.7300,100,1,14.4000,100,1,12.7100,100,1,14.5600,800,2,12.5000,700,1,14.5999,700,1,12.4600,200,2,14.6799,1500,3,12.4299,700,1,14.6899,100,1,12.4199,700,1,14.7200,100,1,12.3699,700,1,14.8900,100,1,ARL,320487105
1486,2025-07-17T15:58:14.710622495Z,2025-07-17T15:58:14.710622495Z,10,2,1108,C,A,0,14.9100,100,0,165396,267659178,13.0399,2,1,14.0999,2,1,13.0299,100,1,14.2599,100,1,13.0199,100,1,14.2799,100,1,12.7300,100,1,14.4000,100,1,12.7100,100,1,14.5600,800,2,12.5000,700,1,14.5999,700,1,12.4600,200,2,14.6799,1500,3,12.4299,700,1,14.6899,100,1,12.4199,700,1,14.7200,100,1,12.3699,700,1,14.8900,100,1,ARL,320486925
1487,2025-07-17T15:58:14.710622495Z,2025-07-17T15:58:14.710622495Z,10,2,1108,A,A,0,15.0600,100,130,165396,267659178,13.0399,2,1,14.0999,2,1,13.0299,100,1,14.2599,100,1,13.0199,100,1,14.2799,100,1,12.7300,100,1,14.4000,100,1,12.7100,100,1,14.5600,800,2,12.5000,700,1,14.5999,700,1,12.4600,200,2,14.6799,1500,3,12.4299,700,1,14.6899,100,1,12.4199,700,1,14.7200,100,1,12.3699,700,1,14.8900,100,1,ARL,320487357
1488,2025-07-17T15:58:15.563904700Z,2025-07-17T15:58:15.563904700Z,10,2,1108,C,A,0,14.6799,100,0,165556,267672469,13.0399,2,1,14.0999,2,1,13.0299,100,1,14.2599,100,1,13.0199,100,1,14.2799,100,1,12.7300,100,1,14.4000,100,1,12.7100,100,1,14.5600,800,2,12.5000,700,1,14.5999,700,1,12.4600,200,2,14.6799,1400,2,12.4299,700,1,14.6899,100,1,12.4199,700,1,14.7200,100,1,12.3699,700,1,14.8900,100,1,ARL,320484781
1489,2025-07-17T15:58:15.563904700Z,2025-07-17T15:58:15.563904700Z,10,2,1108,A,A,0,14.8699,100,130,165556,267672469,13.0399,2,1,14.0999,2,1,13.0299,100,1,14.2599,100,1,13.0199,100,1,14.2799,100,1,12.7300,100,1,14.4000,100,1,12.7100,100,1,14.5600,800,2,12.5000,700,1,14.5999,700,1,12.4600,200,2,14.6799,1400,2,12.4299,700,1,14.6899,100,1,12.4199,700,1,14.7200,100,1,12.3699,700,1,14.8699,100,1,ARL,320504473
1490,2025-07-17T15:58:15.577554368Z,2025-07-17T15:58:15.577554368Z,10,2,1108,C,A,0,14.6899,100,0,165428,267672549,13.0399,2,1,14.0999,2,1,13.0299,100,1,14.2599,100,1,13.0199,100,1,14.2799,100,1,12.7300,100,1,14.4000,100,1,12.7100,100,1,14.5600,800,2,12.5000,700,1,14.5999,700,1,12.4600,200,2,14.6799,1400,2,12.4299,700,1,14.7200,100,1,12.4199,700,1,14.8699,100,1,12.3699,700,1,14.8900,100,1,ARL,320484825
1491,2025-07-17T15:58:15.577554368Z,2025-07-17T15:58:15.577554368Z,10,2,1108,A,A,0,14.8800,100,130,165428,267672549,13.0399,2,1,14.0999,2,1,13.0299,100,1,14.2599,100,1,13.0199,100,1,14.2799,100,1,12.7300,100,1,14.4000,100,1,12.7100,100,1,14.5600,800,2,12.5000,700,1,14.5999,700,1,12.4600,200,2,14.6799,1400,2,12.4299,700,1,14.7200,100,1,12.4199,700,1,14.8699,100,1,12.3699,700,1,14.8800,100,1,ARL,320504609
1492,2025-07-17T15:58:16.501915292Z,2025-07-17T15:58:16.501915292Z,10,2,1108,A,A,0,14.1099,100,130,165223,267685252,13.0399,2,1,14.0999,2,1,13.0299,100,1,14.1099,100,1,13.0199,100,1,14.2599,100,1,12.7300,100,1,14.2799,100,1,12.7100,100,1,14.4000,100,1,12.5000,700,1,14.5600,800,2,12.4600,200,2,14.5999,700,1,12.4299,700,1,14.6799,1400,2,12.4199,700,1,14.7200,100,1,12.3699,700,1,14.8699,100,1,ARL,320519893
1493,2025-07-17T15:58:19.965034325Z,2025-07-17T15:58:19.965034325Z,10,2,1108,A,A,0,13.9399,15,130,166655,267738403,13.0399,2,1,13.9399,15,1,13.0299,100,1,14.0999,2,1,13.0199,100,1,14.1099,100,1,12.7300,100,1,14.2599,100,1,12.7100,100,1,14.2799,100,1,12.5000,700,1,14.4000,100,1,12.4600,200,2,14.5600,800,2,12.4299,700,1,14.5999,700,1,12.4199,700,1,14.6799,1400,2,12.3699,700,1,14.7200,100,1,ARL,320588689
1494,2025-07-17T15:58:20.237668047Z,2025-07-17T15:58:20.237668047Z,10,2,1108,C,A,0,14.1099,100,0,165355,267745213,13.0399,2,1,13.9399,15,1,13.0299,100,1,14.0999,2,1,13.0199,100,1,14.2599,100,1,12.7300,100,1,14.2799,100,1,12.7100,100,1,14.4000,100,1,12.5000,700,1,14.5600,800,2,12.4600,200,2,14.5999,700,1,12.4299,700,1,14.6799,1400,2,12.4199,700,1,14.7200,100,1,12.3699,700,1,14.8699,100,1,ARL,320519893
1495,2025-07-17T15:58:20.237668047Z,2025-07-17T15:58:20.237668047Z,10,2,1108,A,A,0,13.9499,100,130,165355,267745213,13.0399,2,1,13.9399,15,1,13.0299,100,1,13.9499,100,1,13.0199,100,1,14.0999,2,1,12.7300,100,1,14.2599,100,1,12.7100,100,1,14.2799,100,1,12.5000,700,1,14.4000,100,1,12.4600,200,2,14.5600,800,2,12.4299,700,1,14.5999,700,1,12.4199,700,1,14.6799,1400,2,12.3699,700,1,14.7200,100,1,ARL,320595817
1496,2025-07-17T15:58:20.705344578Z,2025-07-17T15:58:20.705344578Z,10,2,1108,C,A,0,13.9399,15,128,167593,267754327,13.0399,2,1,13.9499,100,1,13.0299,100,1,14.0999,2,1,13.0199,100,1,14.2599,100,1,12.7300,100,1,14.2799,100,1,12.7100,100,1,14.4000,100,1,12.5000,700,1,14.5600,800,2,12.4600,200,2,14.5999,700,1,12.4299,700,1,14.6799,1400,2,12.4199,700,1,14.7200,100,1,12.3699,700,1,14.8699,100,1,ARL,320588689
1497,2025-07-17T15:58:30.799887713Z,2025-07-17T15:58:30.799887713Z,10,2,1108,A,A,0,13.8900,15,130,165349,267913947,13.0399,2,1,13.8900,15,1,13.0299,100,1,13.9499,100,1,13.0199,100,1,14.0999,2,1,12.7300,100,1,14.2599,100,1,12.7100,100,1,14.2799,100,1,12.5000,700,1,14.4000,100,1,12.4600,200,2,14.5600,800,2,12.4299,700,1,14.5999,700,1,12.4199,700,1,14.6799,1400,2,12.3699,700,1,14.7200,100,1,ARL,320833897
1498,2025-07-17T15:58:30.905491759Z,2025-07-17T15:58:30.905491759Z,10,2,1108,C,A,0,13.9499,100,0,165560,267919515,13.0399,2,1,13.8900,15,1,13.0299,100,1,14.0999,2,1,13.0199,100,1,14.2599,100,1,12.7300,100,1,14.2799,100,1,12.7100,100,1,14.4000,100,1,12.5000,700,1,14.5600,800,2,12.4600,200,2,14.5999,700,1,12.4299,700,1,14.6799,1400,2,12.4199,700,1,14.7200,100,1,12.3699,700,1,14.8699,100,1,ARL,320595817
1499,2025-07-17T15:58:30.905491759Z,2025-07-17T15:58:30.905491759Z,10,2,1108,A,A,0,13.9000,100,130,165560,267919515,13.0399,2,1,13.8900,15,1,13.0299,100,1,13.9000,100,1,13.0199,100,1,14.0999,2,1,12.7300,100,1,14.2599,100,1,12.7100,100,1,14.2799,100,1,12.5000,700,1,14.4000,100,1,12.4600,200,2,14.5600,800,2,12.4299,700,1,14.5999,700,1,12.4199,700,1,14.6799,1400,2,12.3699,700,1,14.7200,100,1,ARL,320839125
1500,2025-07-17T15:58:30.906246950Z,2025-07-17T15:58:30.906246950Z,10,2,1108,C,A,0,15.0600,100,0,165336,267919540,13.0399,2,1,13.8900,15,1,13.0299,100,1,13.9000,100,1,13.0199,100,1,14.0999,2,1,12.7300,100,1,14.2599,100,1,12.7100,100,1,14.2799,100,1,12.5000,700,1,14.4000,100,1,12.4600,200,2,14.5600,800,2,12.4299,700,1,14.5999,700,1,12.4199,700,1,14.6799,1400,2,12.3699,700,1,14.7200,100,1,ARL,320487357
1501,2025-07-17T15:58:30.906246950Z,2025-07-17T15:58:30.906246950Z,10,2,1108,A,A,0,14.9800,100,130,165336,267919540,13.0399,2,1,13.8900,15,1,13.0299,100,1,13.9000,100,1,13.0199,100,1,14.0999,2,1,12.7300,100,1,14.2599,100,1,12.7100,100,1,14.2799,100,1,12.5000,700,1,14.4000,100,1,12.4600,200,2,14.5600,800,2,12.4299,700,1,14.5999,700,1,12.4199,700,1,14.6799,1400,2,12.3699,700,1,14.7200,100,1,ARL,320839149
1502,2025-07-17T15:58:30.916561264Z,2025-07-17T15:58:30.916561264Z,10,2,1108,C,A,0,14.2599,100,130,165089,267919917,13.0399,2,1,13.8900,15,1,13.0299,100,1,13.9000,100,1,13.0199,100,1,14.0999,2,1,12.7300,100,1,14.2799,100,1,12.7100,100,1,14.4000,100,1,12.5000,700,1,14.5600,800,2,12.4600,200,2,14.5999,700,1,12.4299,700,1,14.6799,1400,2,12.4199,700,1,14.7200,100,1,12.3699,700,1,14.8699,100,1,ARL,320487025
1503,2025-07-17T15:58:30.916619122Z,2025-07-17T15:58:30.916619122Z,10,2,1108,A,A,0,14.1799,100,130,165156,267919919,13.0399,2,1,13.8900,15,1,13.0299,100,1,13.9000,100,1,13.0199,100,1,14.0999,2,1,12.7300,100,1,14.1799,100,1,12.7100,100,1,14.2799,100,1,12.5000,700,1,14.4000,100,1,12.4600,200,2,14.5600,800,2,12.4299,700,1,14.5999,700,1,12.4199,700,1,14.6799,1400,2,12.3699,700,1,14.7200,100,1,ARL,320839577
1504,2025-07-17T15:58:31.124222733Z,2025-07-17T15:58:31.124222733Z,10,2,1108,C,A,0,14.8699,100,0,165984,267925564,13.0399,2,1,13.8900,15,1,13.0299,100,1,13.9000,100,1,13.0199,100,1,14.0999,2,1,12.7300,100,1,14.1799,100,1,12.7100,100,1,14.2799,100,1,12.5000,700,1,14.4000,100,1,12.4600,200,2,14.5600,800,2,12.4299,700,1,14.5999,700,1,12.4199,700,1,14.6799,1400,2,12.3699,700,1,14.7200,100,1,ARL,320504473
1505,2025-07-17T15:58:31.124222733Z,2025-07-17T15:58:31.124222733Z,10,2,1108,A,A,0,14.7599,100,130,165984,267925564,13.0399,2,1,13.8900,15,1,13.0299,100,1,13.9000,100,1,13.0199,100,1,14.0999,2,1,12.7300,100,1,14.1799,100,1,12.7100,100,1,14.2799,100,1,12.5000,700,1,14.4000,100,1,12.4600,200,2,14.5600,800,2,12.4299,700,1,14.5999,700,1,12.4199,700,1,14.6799,1400,2,12.3699,700,1,14.7200,100,1,ARL,320845893
1506,2025-07-17T15:58:31.136273403Z,2025-07-17T15:58:31.136273403Z,10,2,1108,C,A,0,14.8800,100,0,165845,267925951,13.0399,2,1,13.8900,15,1,13.0299,100,1,13.9000,100,1,13.0199,100,1,14.0999,2,1,12.7300,100,1,14.1799,100,1,12.7100,100,1,14.2799,100,1,12.5000,700,1,14.4000,100,1,12.4600,200,2,14.5600,800,2,12.4299,700,1,14.5999,700,1,12.4199,700,1,14.6799,1400,2,12.3699,700,1,14.7200,100,1,ARL,320504609
1507,2025-07-17T15:58:31.136273403Z,2025-07-17T15:58:31.136273403Z,10,2,1108,A,A,0,14.7699,100,130,165845,267925951,13.0399,2,1,13.8900,15,1,13.0299,100,1,13.9000,100,1,13.0199,100,1,14.0999,2,1,12.7300,100,1,14.1799,100,1,12.7100,100,1,14.2799,100,1,12.5000,700,1,14.4000,100,1,12.4600,200,2,14.5600,800,2,12.4299,700,1,14.5999,700,1,12.4199,700,1,14.6799,1400,2,12.3699,700,1,14.7200,100,1,ARL,320846429
1508,2025-07-17T15:58:40.799787018Z,2025-07-17T15:58:40.799787018Z,10,2,1108,A,A,0,13.8300,15,130,165225,268074431,13.0399,2,1,13.8300,15,1,13.0299,100,1,13.8900,15,1,13.0199,100,1,13.9000,100,1,12.7300,100,1,14.0999,2,1,12.7100,100,1,14.1799,100,1,12.5000,700,1,14.2799,100,1,12.4600,200,2,14.4000,100,1,12.4299,700,1,14.5600,800,2,12.4199,700,1,14.5999,700,1,12.3699,700,1,14.6799,1400,2,ARL,321038033
1509,2025-07-17T15:58:43.690078924Z,2025-07-17T15:58:43.690078924Z,10,2,1108,C,A,0,13.9000,100,0,165549,268115228,13.0399,2,1,13.8300,15,1,13.0299,100,1,13.8900,15,1,13.0199,100,1,14.0999,2,1,12.7300,100,1,14.1799,100,1,12.7100,100,1,14.2799,100,1,12.5000,700,1,14.4000,100,1,12.4600,200,2,14.5600,800,2,12.4299,700,1,14.5999,700,1,12.4199,700,1,14.6799,1400,2,12.3699,700,1,14.7200,100,1,ARL,320839125
1510,2025-07-17T15:58:43.690078924Z,2025-07-17T15:58:43.690078924Z,10,2,1108,A,A,0,13.8399,100,130,165549,268115228,13.0399,2,1,13.8300,15,1,13.0299,100,1,13.8399,100,1,13.0199,100,1,13.8900,15,1,12.7300,100,1,14.0999,2,1,12.7100,100,1,14.1799,100,1,12.5000,700,1,14.2799,100,1,12.4600,200,2,14.4000,100,1,12.4299,700,1,14.5600,800,2,12.4199,700,1,14.5999,700,1,12.3699,700,1,14.6799,1400,2,ARL,321096769
1511,2025-07-17T15:58:43.690823184Z,2025-07-17T15:58:43.690823184Z,10,2,1108,C,A,0,14.9800,100,0,165737,268115235,13.0399,2,1,13.8300,15,1,13.0299,100,1,13.8399,100,1,13.0199,100,1,13.8900,15,1,12.7300,100,1,14.0999,2,1,12.7100,100,1,14.1799,100,1,12.5000,700,1,14.2799,100,1,12.4600,200,2,14.4000,100,1,12.4299,700,1,14.5600,800,2,12.4199,700,1,14.5999,700,1,12.3699,700,1,14.6799,1400,2,ARL,320839149
1512,2025-07-17T15:58:43.690823184Z,2025-07-17T15:58:43.690823184Z,10,2,1108,A,A,0,14.9100,100,130,165737,268115235,13.0399,2,1,13.8300,15,1,13.0299,100,1,13.8399,100,1,13.0199,100,1,13.8900,15,1,12.7300,100,1,14.0999,2,1,12.7100,100,1,14.1799,100,1,12.5000,700,1,14.2799,100,1,12.4600,200,2,14.4000,100,1,12.4299,700,1,14.5600,800,2,12.4199,700,1,14.5999,700,1,12.3699,700,1,14.6799,1400,2,ARL,321096793
1513,2025-07-17T15:58:43.693228946Z,2025-07-17T15:58:43.693228946Z,10,2,1108,C,A,0,17.7600,100,0,165554,268115265,13.0399,2,1,13.8300,15,1,13.0299,100,1,13.8399,100,1,13.0199,100,1,13.8900,15,1,12.7300,100,1,14.0999,2,1,12.7100,100,1,14.1799,100,1,12.5000,700,1,14.2799,100,1,12.4600,200,2,14.4000,100,1,12.4299,700,1,14.5600,800,2,12.4199,700,1,14.5999,700,1,12.3699,700,1,14.6799,1400,2,ARL,320486937
1514,2025-07-17T15:58:43.693228946Z,2025-07-17T15:58:43.693228946Z,10,2,1108,A,A,0,17.5799,100,130,165554,268115265,13.0399,2,1,13.8300,15,1,13.0299,100,1,13.8399,100,1,13.0199,100,1,13.8900,15,1,12.7300,100,1,14.0999,2,1,12.7100,100,1,14.1799,100,1,12.5000,700,1,14.2799,100,1,12.4600,200,2,14.4000,100,1,12.4299,700,1,14.5600,800,2,12.4199,700,1,14.5999,700,1,12.3699,700,1,14.6799,1400,2,ARL,321096825
1515,2025-07-17T15:58:43.694890264Z,2025-07-17T15:58:43.694890264Z,10,2,1108,C,A,0,16.0799,100,0,165521,268115287,13.0399,2,1,13.8300,15,1,13.0299,100,1,13.8399,100,1,13.0199,100,1,13.8900,15,1,12.7300,100,1,14.0999,2,1,12.7100,100,1,14.1799,100,1,12.5000,700,1,14.2799,100,1,12.4600,200,2,14.4000,100,1,12.4299,700,1,14.5600,800,2,12.4199,700,1,14.5999,700,1,12.3699,700,1,14.6799,1400,2,ARL,320486945
1516,2025-07-17T15:58:43.694890264Z,2025-07-17T15:58:43.694890264Z,10,2,1108,A,A,0,15.9199,100,130,165521,268115287,13.0399,2,1,13.8300,15,1,13.0299,100,1,13.8399,100,1,13.0199,100,1,13.8900,15,1,12.7300,100,1,14.0999,2,1,12.7100,100,1,14.1799,100,1,12.5000,700,1,14.2799,100,1,12.4600,200,2,14.4000,100,1,12.4299,700,1,14.5600,800,2,12.4199,700,1,14.5999,700,1,12.3699,700,1,14.6799,1400,2,ARL,321096889
1517,2025-07-17T15:58:43.716271172Z,2025-07-17T15:58:43.716271172Z,10,2,1108,C,A,0,14.9600,100,0,165952,268115456,13.0399,2,1,13.8300,15,1,13.0299,100,1,13.8399,100,1,13.0199,100,1,13.8900,15,1,12.7300,100,1,14.0999,2,1,12.7100,100,1,14.1799,100,1,12.5000,700,1,14.2799,100,1,12.4600,200,2,14.4000,100,1,12.4299,700,1,14.5600,800,2,12.4199,700,1,14.5999,700,1,12.3699,700,1,14.6799,1400,2,ARL,320487105
1518,2025-07-17T15:58:43.716271172Z,2025-07-17T15:58:43.716271172Z,10,2,1108,A,A,0,14.8100,100,130,165952,268115456,13.0399,2,1,13.8300,15,1,13.0299,100,1,13.8399,100,1,13.0199,100,1,13.8900,15,1,12.7300,100,1,14.0999,2,1,12.7100,100,1,14.1799,100,1,12.5000,700,1,14.2799,100,1,12.4600,200,2,14.4000,100,1,12.4299,700,1,14.5600,800,2,12.4199,700,1,14.5999,700,1,12.3699,700,1,14.6799,1400,2,ARL,321097197
1519,2025-07-17T15:58:44.903574654Z,2025-07-17T15:58:44.903574654Z,10,2,1108,A,A,0,13.8300,100,130,165455,268129040,13.0399,2,1,13.8300,115,2,13.0299,100,1,13.8399,100,1,13.0199,100,1,13.8900,15,1,12.7300,100,1,14.0999,2,1,12.7100,100,1,14.1799,100,1,12.5000,700,1,14.2799,100,1,12.4600,200,2,14.4000,100,1,12.4299,700,1,14.5600,800,2,12.4199,700,1,14.5999,700,1,12.3699,700,1,14.6799,1400,2,ARL,321114473
1520,2025-07-17T15:58:44.923948853Z,2025-07-17T15:58:44.923948853Z,10,2,1108,C,A,0,14.1799,100,130,165415,268129217,13.0399,2,1,13.8300,115,2,13.0299,100,1,13.8399,100,1,13.0199,100,1,13.8900,15,1,12.7300,100,1,14.0999,2,1,12.7100,100,1,14.2799,100,1,12.5000,700,1,14.4000,100,1,12.4600,200,2,14.5600,800,2,12.4299,700,1,14.5999,700,1,12.4199,700,1,14.6799,1400,2,12.3699,700,1,14.7200,100,1,ARL,320839577
1521,2025-07-17T15:58:44.924000519Z,2025-07-17T15:58:44.924000519Z,10,2,1108,A,A,0,14.1099,100,130,165356,268129218,13.0399,2,1,13.8300,115,2,13.0299,100,1,13.8399,100,1,13.0199,100,1,13.8900,15,1,12.7300,100,1,14.0999,2,1,12.7100,100,1,14.1099,100,1,12.5000,700,1,14.2799,100,1,12.4600,200,2,14.4000,100,1,12.4299,700,1,14.5600,800,2,12.4199,700,1,14.5999,700,1,12.3699,700,1,14.6799,1400,2,ARL,321114729
