,ts_recv,ts_event,rtype,publisher_id,instrument_id,action,side,depth,price,size,flags,ts_in_delta,sequence,bid_px_00,bid_sz_00,bid_ct_00,ask_px_00,ask_sz_00,ask_ct_00,bid_px_01,bid_sz_01,bid_ct_01,ask_px_01,ask_sz_01,ask_ct_01,bid_px_02,bid_sz_02,bid_ct_02,ask_px_02,ask_sz_02,ask_ct_02,bid_px_03,bid_sz_03,bid_ct_03,ask_px_03,ask_sz_03,ask_ct_03,bid_px_04,bid_sz_04,bid_ct_04,ask_px_04,ask_sz_04,ask_ct_04,bid_px_05,bid_sz_05,bid_ct_05,ask_px_05,ask_sz_05,ask_ct_05,bid_px_06,bid_sz_06,bid_ct_06,ask_px_06,ask_sz_06,ask_ct_06,bid_px_07,bid_sz_07,bid_ct_07,ask_px_07,ask_sz_07,ask_ct_07,bid_px_08,bid_sz_08,bid_ct_08,ask_px_08,ask_sz_08,ask_ct_08,bid_px_09,bid_sz_09,bid_ct_09,ask_px_09,ask_sz_09,ask_ct_09,symbol,order_id
0,2025-07-17T07:05:09.035627674Z,2025-07-17T07:05:09.035627674Z,10,2,1108,R,N,0,,0,8,0,0,,0,0,,0,0,,0,0,,0,0,,0,0,,0,0,,0,0,,0,0,,0,0,,0,0,,0,0,,0,0,,0,0,,0,0,,0,0,,0,0,,0,0,,0,0,,0,0,,0,0,ARL,0
1,2025-07-17T08:05:03.360677248Z,2025-07-17T08:05:03.360677248Z,10,2,1108,A,B,0,5.5099,100,130,165200,851012,5.5099,100,1,,0,0,,0,0,,0,0,,0,0,,0,0,,0,0,,0,0,,0,0,,0,0,,0,0,,0,0,,0,0,,0,0,,0,0,,0,0,,0,0,,0,0,,0,0,,0,0,ARL,817593
2,2025-07-17T08:05:03.360683462Z,2025-07-17T08:05:03.360683462Z,10,2,1108,A,A,0,21.3299,100,130,165331,851013,5.5099,100,1,21.3299,100,1,,0,0,,0,0,,0,0,,0,0,,0,0,,0,0,,0,0,,0,0,,0,0,,0,0,,0,0,,0,0,,0,0,,0,0,,0,0,,0,0,,0,0,,0,0,ARL,817597
3,2025-07-17T08:05:03.361327319Z,2025-07-17T08:05:03.361327319Z,10,2,1108,A,B,0,5.9000,100,130,165198,851022,5.9000,100,1,21.3299,100,1,5.5099,100,1,,0,0,,0,0,,0,0,,0,0,,0,0,,0,0,,0,0,,0,0,,0,0,,0,0,,0,0,,0,0,,0,0,,0,0,,0,0,,0,0,,0,0,ARL,817633
4,2025-07-17T08:05:03.361332576Z,2025-07-17T08:05:03.361332576Z,10,2,1108,A,A,0,20.9400,100,130,165247,851023,5.9000,100,1,20.9400,100,1,5.5099,100,1,21.3299,100,1,,0,0,,0,0,,0,0,,0,0,,0,0,,0,0,,0,0,,0,0,,0,0,,0,0,,0,0,,0,0,,0,0,,0,0,,0,0,,0,0,ARL,817637
5,2025-07-17T08:09:48.860696464Z,2025-07-17T08:09:48.860696464Z,10,2,1108,C,B,0,5.5099,100,130,165631,1289631,5.9000,100,1,20.9400,100,1,,0,0,21.3299,100,1,,0,0,,0,0,,0,0,,0,0,,0,0,,0,0,,0,0,,0,0,,0,0,,0,0,,0,0,,0,0,,0,0,,0,0,,0,0,,0,0,ARL,817593
6,2025-07-17T08:09:48.860705588Z,2025-07-17T08:09:48.860705588Z,10,2,1108,A,B,0,5.3700,100,130,165297,1289632,5.9000,100,1,20.9400,100,1,5.3700,100,1,21.3299,100,1,,0,0,,0,0,,0,0,,0,0,,0,0,,0,0,,0,0,,0,0,,0,0,,0,0,,0,0,,0,0,,0,0,,0,0,,0,0,,0,0,ARL,1263973
7,2025-07-17T08:09:49.157896784Z,2025-07-17T08:09:49.157896784Z,10,2,1108,C,B,0,5.9000,100,130,165115,1290626,5.3700,100,1,20.9400,100,1,,0,0,21.3299,100,1,,0,0,,0,0,,0,0,,0,0,,0,0,,0,0,,0,0,,0,0,,0,0,,0,0,,0,0,,0,0,,0,0,,0,0,,0,0,,0,0,ARL,817633
8,2025-07-17T08:09:49.157903443Z,2025-07-17T08:09:49.157903443Z,10,2,1108,A,B,0,5.4000,100,0,166009,1290627,5.4000,100,1,20.9400,100,1,5.3700,100,1,21.3299,100,1,,0,0,,0,0,,0,0,,0,0,,0,0,,0,0,,0,0,,0,0,,0,0,,0,0,,0,0,,0,0,,0,0,,0,0,,0,0,,0,0,ARL,1264721
9,2025-07-17T08:09:49.157903798Z,2025-07-17T08:09:49.157903798Z,10,2,1108,C,A,0,20.9400,100,130,165654,1290628,5.4000,100,1,21.3299,100,1,5.3700,100,1,,0,0,,0,0,,0,0,,0,0,,0,0,,0,0,,0,0,,0,0,,0,0,,0,0,,0,0,,0,0,,0,0,,0,0,,0,0,,0,0,,0,0,ARL,817637
10,2025-07-17T08:09:49.157909054Z,2025-07-17T08:09:49.157909054Z,10,2,1108,A,A,0,21.4699,100,130,165545,1290629,5.4000,100,1,21.3299,100,1,5.3700,100,1,21.4699,100,1,,0,0,,0,0,,0,0,,0,0,,0,0,,0,0,,0,0,,0,0,,0,0,,0,0,,0,0,,0,0,,0,0,,0,0,,0,0,,0,0,ARL,1264725
11,2025-07-17T11:00:00.125174985Z,2025-07-17T11:00:00.125174985Z,10,2,1108,C,B,0,5.3700,100,130,165929,10583317,5.4000,100,1,21.3299,100,1,,0,0,21.4699,100,1,,0,0,,0,0,,0,0,,0,0,,0,0,,0,0,,0,0,,0,0,,0,0,,0,0,,0,0,,0,0,,0,0,,0,0,,0,0,,0,0,ARL,1263973
12,2025-07-17T11:00:00.125182048Z,2025-07-17T11:00:00.125182048Z,10,2,1108,A,B,0,9.7899,100,130,165199,10583320,9.7899,100,1,21.3299,100,1,5.4000,100,1,21.4699,100,1,,0,0,,0,0,,0,0,,0,0,,0,0,,0,0,,0,0,,0,0,,0,0,,0,0,,0,0,,0,0,,0,0,,0,0,,0,0,,0,0,ARL,12852457
13,2025-07-17T11:00:00.125454029Z,2025-07-17T11:00:00.125454029Z,10,2,1108,C,B,0,5.4000,100,130,165713,10583363,9.7899,100,1,21.3299,100,1,,0,0,21.4699,100,1,,0,0,,0,0,,0,0,,0,0,,0,0,,0,0,,0,0,,0,0,,0,0,,0,0,,0,0,,0,0,,0,0,,0,0,,0,0,,0,0,ARL,1264721
14,2025-07-17T11:00:00.125460962Z,2025-07-17T11:00:00.125460962Z,10,2,1108,A,B,0,9.8399,100,130,165088,10583364,9.8399,100,1,21.3299,100,1,9.7899,100,1,21.4699,100,1,,0,0,,0,0,,0,0,,0,0,,0,0,,0,0,,0,0,,0,0,,0,0,,0,0,,0,0,,0,0,,0,0,,0,0,,0,0,,0,0,ARL,12852537
15,2025-07-17T11:00:07.975824831Z,2025-07-17T11:00:07.975824831Z,10,2,1108,C,A,0,21.3299,100,130,165390,10674471,9.8399,100,1,21.4699,100,1,9.7899,100,1,,0,0,,0,0,,0,0,,0,0,,0,0,,0,0,,0,0,,0,0,,0,0,,0,0,,0,0,,0,0,,0,0,,0,0,,0,0,,0,0,,0,0,ARL,817597
16,2025-07-17T11:00:07.975837956Z,2025-07-17T11:00:07.975837956Z,10,2,1108,A,A,0,17.4400,100,130,165427,10674472,9.8399,100,1,17.4400,100,1,9.7899,100,1,21.4699,100,1,,0,0,,0,0,,0,0,,0,0,,0,0,,0,0,,0,0,,0,0,,0,0,,0,0,,0,0,,0,0,,0,0,,0,0,,0,0,,0,0,ARL,12983425
17,2025-07-17T11:00:07.975972618Z,2025-07-17T11:00:07.975972618Z,10,2,1108,C,A,0,21.4699,100,130,165484,10674473,9.8399,100,1,17.4400,100,1,9.7899,100,1,,0,0,,0,0,,0,0,,0,0,,0,0,,0,0,,0,0,,0,0,,0,0,,0,0,,0,0,,0,0,,0,0,,0,0,,0,0,,0,0,,0,0,ARL,1264725
18,2025-07-17T11:00:07.975979367Z,2025-07-17T11:00:07.975979367Z,10,2,1108,A,A,0,17.3599,100,130,165357,10674474,9.8399,100,1,17.3599,100,1,9.7899,100,1,17.4400,100,1,,0,0,,0,0,,0,0,,0,0,,0,0,,0,0,,0,0,,0,0,,0,0,,0,0,,0,0,,0,0,,0,0,,0,0,,0,0,,0,0,ARL,12983429
19,2025-07-17T11:00:08.254975294Z,2025-07-17T11:00:08.254975294Z,10,2,1108,C,A,0,17.4400,100,130,165204,10676310,9.8399,100,1,17.3599,100,1,9.7899,100,1,,0,0,,0,0,,0,0,,0,0,,0,0,,0,0,,0,0,,0,0,,0,0,,0,0,,0,0,,0,0,,0,0,,0,0,,0,0,,0,0,,0,0,ARL,12983425
20,2025-07-17T11:00:08.254985173Z,2025-07-17T11:00:08.254985173Z,10,2,1108,A,A,0,18.9200,100,130,165286,10676311,9.8399,100,1,17.3599,100,1,9.7899,100,1,18.9200,100,1,,0,0,,0,0,,0,0,,0,0,,0,0,,0,0,,0,0,,0,0,,0,0,,0,0,,0,0,,0,0,,0,0,,0,0,,0,0,,0,0,ARL,12985397
21,2025-07-17T11:00:08.255147130Z,2025-07-17T11:00:08.255147130Z,10,2,1108,C,A,0,17.3599,100,130,165096,10676314,9.8399,100,1,18.9200,100,1,9.7899,100,1,,0,0,,0,0,,0,0,,0,0,,0,0,,0,0,,0,0,,0,0,,0,0,,0,0,,0,0,,0,0,,0,0,,0,0,,0,0,,0,0,,0,0,ARL,12983429
22,2025-07-17T11:00:08.255155317Z,2025-07-17T11:00:08.255155317Z,10,2,1108,A,A,0,18.8399,100,130,165097,10676315,9.8399,100,1,18.8399,100,1,9.7899,100,1,18.9200,100,1,,0,0,,0,0,,0,0,,0,0,,0,0,,0,0,,0,0,,0,0,,0,0,,0,0,,0,0,,0,0,,0,0,,0,0,,0,0,,0,0,ARL,12985401
23,2025-07-17T11:00:08.255862656Z,2025-07-17T11:00:08.255862656Z,10,2,1108,C,A,0,18.9200,100,130,165036,10676320,9.8399,100,1,18.8399,100,1,9.7899,100,1,,0,0,,0,0,,0,0,,0,0,,0,0,,0,0,,0,0,,0,0,,0,0,,0,0,,0,0,,0,0,,0,0,,0,0,,0,0,,0,0,,0,0,ARL,12985397
24,2025-07-17T11:00:08.255871843Z,2025-07-17T11:00:08.255871843Z,10,2,1108,A,A,0,20.6200,100,130,165232,10676321,9.8399,100,1,18.8399,100,1,9.7899,100,1,20.6200,100,1,,0,0,,0,0,,0,0,,0,0,,0,0,,0,0,,0,0,,0,0,,0,0,,0,0,,0,0,,0,0,,0,0,,0,0,,0,0,,0,0,ARL,12985405
25,2025-07-17T11:00:08.256168895Z,2025-07-17T11:00:08.256168895Z,10,2,1108,C,A,0,18.8399,100,130,165011,10676324,9.8399,100,1,20.6200,100,1,9.7899,100,1,,0,0,,0,0,,0,0,,0,0,,0,0,,0,0,,0,0,,0,0,,0,0,,0,0,,0,0,,0,0,,0,0,,0,0,,0,0,,0,0,,0,0,ARL,12985401
26,2025-07-17T11:00:08.256175346Z,2025-07-17T11:00:08.256175346Z,10,2,1108,A,A,0,20.5300,100,130,165269,10676325,9.8399,100,1,20.5300,100,1,9.7899,100,1,20.6200,100,1,,0,0,,0,0,,0,0,,0,0,,0,0,,0,0,,0,0,,0,0,,0,0,,0,0,,0,0,,0,0,,0,0,,0,0,,0,0,,0,0,ARL,12985413
27,2025-07-17T11:00:08.256885010Z,2025-07-17T11:00:08.256885010Z,10,2,1108,C,A,0,20.6200,100,130,165272,10676333,9.8399,100,1,20.5300,100,1,9.7899,100,1,,0,0,,0,0,,0,0,,0,0,,0,0,,0,0,,0,0,,0,0,,0,0,,0,0,,0,0,,0,0,,0,0,,0,0,,0,0,,0,0,,0,0,ARL,12985405
28,2025-07-17T11:00:08.256892686Z,2025-07-17T11:00:08.256892686Z,10,2,1108,A,A,0,21.4699,100,130,165384,10676334,9.8399,100,1,20.5300,100,1,9.7899,100,1,21.4699,100,1,,0,0,,0,0,,0,0,,0,0,,0,0,,0,0,,0,0,,0,0,,0,0,,0,0,,0,0,,0,0,,0,0,,0,0,,0,0,,0,0,ARL,12985417
29,2025-07-17T11:00:08.257069458Z,2025-07-17T11:00:08.257069458Z,10,2,1108,C,A,0,20.5300,100,130,165354,10676335,9.8399,100,1,21.4699,100,1,9.7899,100,1,,0,0,,0,0,,0,0,,0,0,,0,0,,0,0,,0,0,,0,0,,0,0,,0,0,,0,0,,0,0,,0,0,,0,0,,0,0,,0,0,,0,0,ARL,12985413
30,2025-07-17T11:00:08.257076085Z,2025-07-17T11:00:08.257076085Z,10,2,1108,A,A,0,21.4699,100,130,165249,10676336,9.8399,100,1,21.4699,200,2,9.7899,100,1,,0,0,,0,0,,0,0,,0,0,,0,0,,0,0,,0,0,,0,0,,0,0,,0,0,,0,0,,0,0,,0,0,,0,0,,0,0,,0,0,,0,0,ARL,12985421
31,2025-07-17T11:01:05.260421351Z,2025-07-17T11:01:05.260421351Z,10,2,1108,C,A,0,21.4699,100,130,165317,10824633,9.8399,100,1,21.4699,100,1,9.7899,100,1,,0,0,,0,0,,0,0,,0,0,,0,0,,0,0,,0,0,,0,0,,0,0,,0,0,,0,0,,0,0,,0,0,,0,0,,0,0,,0,0,,0,0,ARL,12985417
32,2025-07-17T11:01:05.260445703Z,2025-07-17T11:01:05.260445703Z,10,2,1108,A,A,0,17.4400,100,130,165434,10824634,9.8399,100,1,17.4400,100,1,9.7899,100,1,21.4699,100,1,,0,0,,0,0,,0,0,,0,0,,0,0,,0,0,,0,0,,0,0,,0,0,,0,0,,0,0,,0,0,,0,0,,0,0,,0,0,,0,0,ARL,13174157
33,2025-07-17T11:01:05.260693130Z,2025-07-17T11:01:05.260693130Z,10,2,1108,C,A,0,21.4699,100,130,165306,10824635,9.8399,100,1,17.4400,100,1,9.7899,100,1,,0,0,,0,0,,0,0,,0,0,,0,0,,0,0,,0,0,,0,0,,0,0,,0,0,,0,0,,0,0,,0,0,,0,0,,0,0,,0,0,,0,0,ARL,12985421
34,2025-07-17T11:01:05.260709480Z,2025-07-17T11:01:05.260709480Z,10,2,1108,A,A,0,17.3599,100,130,165150,10824636,9.8399,100,1,17.3599,100,1,9.7899,100,1,17.4400,100,1,,0,0,,0,0,,0,0,,0,0,,0,0,,0,0,,0,0,,0,0,,0,0,,0,0,,0,0,,0,0,,0,0,,0,0,,0,0,,0,0,ARL,13174161
35,2025-07-17T11:56:26.691461161Z,2025-07-17T11:56:26.691461161Z,10,2,1108,C,B,0,9.7899,100,130,165682,14213017,9.8399,100,1,17.3599,100,1,,0,0,17.4400,100,1,,0,0,,0,0,,0,0,,0,0,,0,0,,0,0,,0,0,,0,0,,0,0,,0,0,,0,0,,0,0,,0,0,,0,0,,0,0,,0,0,ARL,12852457
36,2025-07-17T11:56:26.691465204Z,2025-07-17T11:56:26.691465204Z,10,2,1108,C,A,0,17.4400,100,130,165335,14213018,9.8399,100,1,17.3599,100,1,,0,0,,0,0,,0,0,,0,0,,0,0,,0,0,,0,0,,0,0,,0,0,,0,0,,0,0,,0,0,,0,0,,0,0,,0,0,,0,0,,0,0,,0,0,ARL,13174157
37,2025-07-17T11:56:26.694767820Z,2025-07-17T11:56:26.694767820Z,10,2,1108,A,B,0,9.7899,100,130,165430,14213075,9.8399,100,1,17.3599,100,1,9.7899,100,1,,0,0,,0,0,,0,0,,0,0,,0,0,,0,0,,0,0,,0,0,,0,0,,0,0,,0,0,,0,0,,0,0,,0,0,,0,0,,0,0,,0,0,ARL,19202569
38,2025-07-17T11:56:26.694772016Z,2025-07-17T11:56:26.694772016Z,10,2,1108,A,A,0,17.4400,100,130,165345,14213076,9.8399,100,1,17.3599,100,1,9.7899,100,1,17.4400,100,1,,0,0,,0,0,,0,0,,0,0,,0,0,,0,0,,0,0,,0,0,,0,0,,0,0,,0,0,,0,0,,0,0,,0,0,,0,0,,0,0,ARL,19202573
39,2025-07-17T11:56:30.445937099Z,2025-07-17T11:56:30.445937099Z,10,2,1108,C,A,0,17.4400,100,130,165310,14219824,9.8399,100,1,17.3599,100,1,9.7899,100,1,,0,0,,0,0,,0,0,,0,0,,0,0,,0,0,,0,0,,0,0,,0,0,,0,0,,0,0,,0,0,,0,0,,0,0,,0,0,,0,0,,0,0,ARL,19202573
40,2025-07-17T11:56:30.445951937Z,2025-07-17T11:56:30.445951937Z,10,2,1108,A,A,0,17.9299,100,130,165512,14219825,9.8399,100,1,17.3599,100,1,9.7899,100,1,17.9299,100,1,,0,0,,0,0,,0,0,,0,0,,0,0,,0,0,,0,0,,0,0,,0,0,,0,0,,0,0,,0,0,,0,0,,0,0,,0,0,,0,0,ARL,19218909
41,2025-07-17T11:56:30.446066952Z,2025-07-17T11:56:30.446066952Z,10,2,1108,C,A,0,17.9299,100,130,165013,14219826,9.8399,100,1,17.3599,100,1,9.7899,100,1,,0,0,,0,0,,0,0,,0,0,,0,0,,0,0,,0,0,,0,0,,0,0,,0,0,,0,0,,0,0,,0,0,,0,0,,0,0,,0,0,,0,0,ARL,19218909
42,2025-07-17T11:56:30.446084801Z,2025-07-17T11:56:30.446084801Z,10,2,1108,A,A,0,17.4400,100,130,165347,14219827,9.8399,100,1,17.3599,100,1,9.7899,100,1,17.4400,100,1,,0,0,,0,0,,0,0,,0,0,,0,0,,0,0,,0,0,,0,0,,0,0,,0,0,,0,0,,0,0,,0,0,,0,0,,0,0,,0,0,ARL,19218913
43,2025-07-17T11:56:30.446191769Z,2025-07-17T11:56:30.446191769Z,10,2,1108,C,A,0,17.3599,100,130,165423,14219828,9.8399,100,1,17.4400,100,1,9.7899,100,1,,0,0,,0,0,,0,0,,0,0,,0,0,,0,0,,0,0,,0,0,,0,0,,0,0,,0,0,,0,0,,0,0,,0,0,,0,0,,0,0,,0,0,ARL,13174161
44,2025-07-17T11:56:30.446213519Z,2025-07-17T11:56:30.446213519Z,10,2,1108,A,A,0,17.8500,100,130,165517,14219829,9.8399,100,1,17.4400,100,1,9.7899,100,1,17.8500,100,1,,0,0,,0,0,,0,0,,0,0,,0,0,,0,0,,0,0,,0,0,,0,0,,0,0,,0,0,,0,0,,0,0,,0,0,,0,0,,0,0,ARL,19218917
45,2025-07-17T11:56:30.446378732Z,2025-07-17T11:56:30.446378732Z,10,2,1108,C,A,0,17.8500,100,130,164905,14219830,9.8399,100,1,17.4400,100,1,9.7899,100,1,,0,0,,0,0,,0,0,,0,0,,0,0,,0,0,,0,0,,0,0,,0,0,,0,0,,0,0,,0,0,,0,0,,0,0,,0,0,,0,0,,0,0,ARL,19218917
46,2025-07-17T11:56:30.446558412Z,2025-07-17T11:56:30.446558412Z,10,2,1108,A,A,0,17.3599,100,130,165234,14219831,9.8399,100,1,17.3599,100,1,9.7899,100,1,17.4400,100,1,,0,0,,0,0,,0,0,,0,0,,0,0,,0,0,,0,0,,0,0,,0,0,,0,0,,0,0,,0,0,,0,0,,0,0,,0,0,,0,0,ARL,19218921
47,2025-07-17T11:57:30.222822537Z,2025-07-17T11:57:30.222822537Z,10,2,1108,C,B,0,9.8399,100,130,165260,14325877,9.7899,100,1,17.3599,100,1,,0,0,17.4400,100,1,,0,0,,0,0,,0,0,,0,0,,0,0,,0,0,,0,0,,0,0,,0,0,,0,0,,0,0,,0,0,,0,0,,0,0,,0,0,,0,0,ARL,12852537
48,2025-07-17T11:57:30.222823580Z,2025-07-17T11:57:30.222823580Z,10,2,1108,C,A,0,17.3599,100,130,165198,14325878,9.7899,100,1,17.4400,100,1,,0,0,,0,0,,0,0,,0,0,,0,0,,0,0,,0,0,,0,0,,0,0,,0,0,,0,0,,0,0,,0,0,,0,0,,0,0,,0,0,,0,0,,0,0,ARL,19218921
49,2025-07-17T11:57:30.223986626Z,2025-07-17T11:57:30.223986626Z,10,2,1108,A,B,0,9.8399,100,130,165341,14325937,9.8399,100,1,17.4400,100,1,9.7899,100,1,,0,0,,0,0,,0,0,,0,0,,0,0,,0,0,,0,0,,0,0,,0,0,,0,0,,0,0,,0,0,,0,0,,0,0,,0,0,,0,0,,0,0,ARL,19346173
50,2025-07-17T11:57:30.223991040Z,2025-07-17T11:57:30.223991040Z,10,2,1108,A,A,0,17.3599,100,130,165106,14325938,9.8399,100,1,17.3599,100,1,9.7899,100,1,17.4400,100,1,,0,0,,0,0,,0,0,,0,0,,0,0,,0,0,,0,0,,0,0,,0,0,,0,0,,0,0,,0,0,,0,0,,0,0,,0,0,,0,0,ARL,19346177
51,2025-07-17T12:30:01.317842911Z,2025-07-17T12:30:01.317842911Z,10,2,1108,A,A,0,20.4800,100,130,165874,16864046,9.8399,100,1,17.3599,100,1,9.7899,100,1,17.4400,100,1,,0,0,20.4800,100,1,,0,0,,0,0,,0,0,,0,0,,0,0,,0,0,,0,0,,0,0,,0,0,,0,0,,0,0,,0,0,,0,0,,0,0,ARL,23570297
52,2025-07-17T12:30:03.426300621Z,2025-07-17T12:30:03.426300621Z,10,2,1108,A,B,0,7.7400,100,130,165236,16882670,9.8399,100,1,17.3599,100,1,9.7899,100,1,17.4400,100,1,7.7400,100,1,20.4800,100,1,,0,0,,0,0,,0,0,,0,0,,0,0,,0,0,,0,0,,0,0,,0,0,,0,0,,0,0,,0,0,,0,0,,0,0,ARL,23616197
53,2025-07-17T12:30:03.426301523Z,2025-07-17T12:30:03.426301523Z,10,2,1108,A,A,0,20.4800,100,130,165339,16882671,9.8399,100,1,17.3599,100,1,9.7899,100,1,17.4400,100,1,7.7400,100,1,20.4800,200,2,,0,0,,0,0,,0,0,,0,0,,0,0,,0,0,,0,0,,0,0,,0,0,,0,0,,0,0,,0,0,,0,0,,0,0,ARL,23616201
54,2025-07-17T12:30:03.604533925Z,2025-07-17T12:30:03.604533925Z,10,2,1108,A,B,0,7.7400,100,130,165243,16886020,9.8399,100,1,17.3599,100,1,9.7899,100,1,17.4400,100,1,7.7400,200,2,20.4800,200,2,,0,0,,0,0,,0,0,,0,0,,0,0,,0,0,,0,0,,0,0,,0,0,,0,0,,0,0,,0,0,,0,0,,0,0,ARL,23622101
55,2025-07-17T12:30:51.178228608Z,2025-07-17T12:30:51.178228608Z,10,2,1108,A,A,0,20.4800,100,130,165625,17120703,9.8399,100,1,17.3599,100,1,9.7899,100,1,17.4400,100,1,7.7400,200,2,20.4800,300,3,,0,0,,0,0,,0,0,,0,0,,0,0,,0,0,,0,0,,0,0,,0,0,,0,0,,0,0,,0,0,,0,0,,0,0,ARL,24099409
56,2025-07-17T12:30:51.642959794Z,2025-07-17T12:30:51.642959794Z,10,2,1108,A,B,0,7.7400,100,130,165373,17122998,9.8399,100,1,17.3599,100,1,9.7899,100,1,17.4400,100,1,7.7400,300,3,20.4800,300,3,,0,0,,0,0,,0,0,,0,0,,0,0,,0,0,,0,0,,0,0,,0,0,,0,0,,0,0,,0,0,,0,0,,0,0,ARL,24102329
57,2025-07-17T13:15:00.032446132Z,2025-07-17T13:15:00.032446132Z,10,2,1108,C,A,0,17.4400,100,130,165604,23080007,9.8399,100,1,17.3599,100,1,9.7899,100,1,20.4800,300,3,7.7400,300,3,,0,0,,0,0,,0,0,,0,0,,0,0,,0,0,,0,0,,0,0,,0,0,,0,0,,0,0,,0,0,,0,0,,0,0,,0,0,ARL,19218913
58,2025-07-17T13:15:00.032483824Z,2025-07-17T13:15:00.032483824Z,10,2,1108,C,B,0,9.7899,100,128,167387,23080041,9.8399,100,1,17.3599,100,1,7.7400,300,3,20.4800,300,3,,0,0,,0,0,,0,0,,0,0,,0,0,,0,0,,0,0,,0,0,,0,0,,0,0,,0,0,,0,0,,0,0,,0,0,,0,0,,0,0,ARL,19202569
59,2025-07-17T13:15:00.058314138Z,2025-07-17T13:15:00.058314138Z,10,2,1108,C,A,0,17.3599,100,128,166100,23101369,9.8399,100,1,20.4800,300,3,7.7400,300,3,,0,0,,0,0,,0,0,,0,0,,0,0,,0,0,,0,0,,0,0,,0,0,,0,0,,0,0,,0,0,,0,0,,0,0,,0,0,,0,0,,0,0,ARL,19346177
60,2025-07-17T13:15:00.058371545Z,2025-07-17T13:15:00.058371545Z,10,2,1108,C,B,0,9.8399,100,130,165839,23101396,7.7400,300,3,20.4800,300,3,,0,0,,0,0,,0,0,,0,0,,0,0,,0,0,,0,0,,0,0,,0,0,,0,0,,0,0,,0,0,,0,0,,0,0,,0,0,,0,0,,0,0,,0,0,ARL,19346173
61,2025-07-17T13:15:01.925073727Z,2025-07-17T13:15:01.925073727Z,10,2,1108,A,B,0,7.7400,100,130,165317,23123943,7.7400,400,4,20.4800,300,3,,0,0,,0,0,,0,0,,0,0,,0,0,,0,0,,0,0,,0,0,,0,0,,0,0,,0,0,,0,0,,0,0,,0,0,,0,0,,0,0,,0,0,,0,0,ARL,31960841
62,2025-07-17T13:15:02.042741730Z,2025-07-17T13:15:02.042741730Z,10,2,1108,A,A,0,20.4800,100,130,165217,23124563,7.7400,400,4,20.4800,400,4,,0,0,,0,0,,0,0,,0,0,,0,0,,0,0,,0,0,,0,0,,0,0,,0,0,,0,0,,0,0,,0,0,,0,0,,0,0,,0,0,,0,0,,0,0,ARL,31962113
63,2025-07-17T13:17:49.831164624Z,2025-07-17T13:17:49.831164624Z,10,2,1108,A,B,0,7.7400,100,130,165264,23465434,7.7400,500,5,20.4800,400,4,,0,0,,0,0,,0,0,,0,0,,0,0,,0,0,,0,0,,0,0,,0,0,,0,0,,0,0,,0,0,,0,0,,0,0,,0,0,,0,0,,0,0,,0,0,ARL,33574717
64,2025-07-17T13:17:49.831544051Z,2025-07-17T13:17:49.831544051Z,10,2,1108,A,A,0,20.4800,100,130,165314,23465435,7.7400,500,5,20.4800,500,5,,0,0,,0,0,,0,0,,0,0,,0,0,,0,0,,0,0,,0,0,,0,0,,0,0,,0,0,,0,0,,0,0,,0,0,,0,0,,0,0,,0,0,,0,0,ARL,33574725
65,2025-07-17T13:19:57.597203040Z,2025-07-17T13:19:57.597203040Z,10,2,1108,A,B,0,8.7400,100,130,165281,23710201,8.7400,100,1,20.4800,500,5,7.7400,500,5,,0,0,,0,0,,0,0,,0,0,,0,0,,0,0,,0,0,,0,0,,0,0,,0,0,,0,0,,0,0,,0,0,,0,0,,0,0,,0,0,,0,0,ARL,34790041
66,2025-07-17T13:19:57.597291053Z,2025-07-17T13:19:57.597291053Z,10,2,1108,A,A,0,18.3500,100,130,165217,23710202,8.7400,100,1,18.3500,100,1,7.7400,500,5,20.4800,500,5,,0,0,,0,0,,0,0,,0,0,,0,0,,0,0,,0,0,,0,0,,0,0,,0,0,,0,0,,0,0,,0,0,,0,0,,0,0,,0,0,ARL,34790045
67,2025-07-17T13:19:58.492619751Z,2025-07-17T13:19:58.492619751Z,10,2,1108,A,A,0,18.2399,100,130,165309,23728432,8.7400,100,1,18.2399,100,1,7.7400,500,5,18.3500,100,1,,0,0,20.4800,500,5,,0,0,,0,0,,0,0,,0,0,,0,0,,0,0,,0,0,,0,0,,0,0,,0,0,,0,0,,0,0,,0,0,,0,0,ARL,34810233
68,2025-07-17T13:19:58.492634480Z,2025-07-17T13:19:58.492634480Z,10,2,1108,A,B,0,9.2400,100,130,165346,23728435,9.2400,100,1,18.2399,100,1,8.7400,100,1,18.3500,100,1,7.7400,500,5,20.4800,500,5,,0,0,,0,0,,0,0,,0,0,,0,0,,0,0,,0,0,,0,0,,0,0,,0,0,,0,0,,0,0,,0,0,,0,0,ARL,34810241
69,2025-07-17T13:20:00.525263842Z,2025-07-17T13:20:00.525263842Z,10,2,1108,C,A,0,18.2399,100,0,166519,23765825,9.2400,100,1,18.3500,100,1,8.7400,100,1,20.4800,500,5,7.7400,500,5,,0,0,,0,0,,0,0,,0,0,,0,0,,0,0,,0,0,,0,0,,0,0,,0,0,,0,0,,0,0,,0,0,,0,0,,0,0,ARL,34810233
70,2025-07-17T13:20:00.525264700Z,2025-07-17T13:20:00.525264700Z,10,2,1108,C,B,0,9.2400,100,130,165661,23765826,8.7400,100,1,18.3500,100,1,7.7400,500,5,20.4800,500,5,,0,0,,0,0,,0,0,,0,0,,0,0,,0,0,,0,0,,0,0,,0,0,,0,0,,0,0,,0,0,,0,0,,0,0,,0,0,,0,0,ARL,34810241
71,2025-07-17T13:25:00.157467184Z,2025-07-17T13:25:00.157467184Z,10,2,1108,C,B,0,8.7400,100,130,165039,24448205,7.7400,500,5,18.3500,100,1,,0,0,20.4800,500,5,,0,0,,0,0,,0,0,,0,0,,0,0,,0,0,,0,0,,0,0,,0,0,,0,0,,0,0,,0,0,,0,0,,0,0,,0,0,,0,0,ARL,34790041
72,2025-07-17T13:25:00.157473422Z,2025-07-17T13:25:00.157473422Z,10,2,1108,C,A,0,18.3500,100,130,165090,24448207,7.7400,500,5,20.4800,500,5,,0,0,,0,0,,0,0,,0,0,,0,0,,0,0,,0,0,,0,0,,0,0,,0,0,,0,0,,0,0,,0,0,,0,0,,0,0,,0,0,,0,0,,0,0,ARL,34790045
73,2025-07-17T13:25:01.732320109Z,2025-07-17T13:25:01.732320109Z,10,2,1108,A,B,0,7.7400,100,130,165277,24478872,7.7400,600,6,20.4800,500,5,,0,0,,0,0,,0,0,,0,0,,0,0,,0,0,,0,0,,0,0,,0,0,,0,0,,0,0,,0,0,,0,0,,0,0,,0,0,,0,0,,0,0,,0,0,ARL,38041417
74,2025-07-17T13:25:01.819282823Z,2025-07-17T13:25:01.819282823Z,10,2,1108,A,A,0,20.4800,100,130,165137,24480276,7.7400,600,6,20.4800,600,6,,0,0,,0,0,,0,0,,0,0,,0,0,,0,0,,0,0,,0,0,,0,0,,0,0,,0,0,,0,0,,0,0,,0,0,,0,0,,0,0,,0,0,,0,0,ARL,38043741
75,2025-07-17T13:28:08.191915168Z,2025-07-17T13:28:08.191915168Z,10,2,1108,A,B,0,7.7400,100,130,165295,25597187,7.7400,700,7,20.4800,600,6,,0,0,,0,0,,0,0,,0,0,,0,0,,0,0,,0,0,,0,0,,0,0,,0,0,,0,0,,0,0,,0,0,,0,0,,0,0,,0,0,,0,0,,0,0,ARL,40617777
76,2025-07-17T13:28:08.191982270Z,2025-07-17T13:28:08.191982270Z,10,2,1108,A,A,0,20.4800,100,130,165331,25597189,7.7400,700,7,20.4800,700,7,,0,0,,0,0,,0,0,,0,0,,0,0,,0,0,,0,0,,0,0,,0,0,,0,0,,0,0,,0,0,,0,0,,0,0,,0,0,,0,0,,0,0,,0,0,ARL,40617785
77,2025-07-17T13:28:21.011249114Z,2025-07-17T13:28:21.011249114Z,10,2,1108,A,A,0,18.3200,700,130,165478,25907820,7.7400,700,7,18.3200,700,1,,0,0,20.4800,700,7,,0,0,,0,0,,0,0,,0,0,,0,0,,0,0,,0,0,,0,0,,0,0,,0,0,,0,0,,0,0,,0,0,,0,0,,0,0,,0,0,ARL,40846101
78,2025-07-17T13:28:21.028865155Z,2025-07-17T13:28:21.028865155Z,10,2,1108,A,B,0,9.2899,700,130,165210,25917006,9.2899,700,1,18.3200,700,1,7.7400,700,7,20.4800,700,7,,0,0,,0,0,,0,0,,0,0,,0,0,,0,0,,0,0,,0,0,,0,0,,0,0,,0,0,,0,0,,0,0,,0,0,,0,0,,0,0,ARL,40851989
79,2025-07-17T13:28:30.048730211Z,2025-07-17T13:28:30.048730211Z,10,2,1108,A,B,0,9.6699,100,130,165257,26140646,9.6699,100,1,18.3200,700,1,9.2899,700,1,20.4800,700,7,7.7400,700,7,,0,0,,0,0,,0,0,,0,0,,0,0,,0,0,,0,0,,0,0,,0,0,,0,0,,0,0,,0,0,,0,0,,0,0,,0,0,ARL,40999441
80,2025-07-17T13:28:30.048741690Z,2025-07-17T13:28:30.048741690Z,10,2,1108,A,A,0,17.6000,100,130,165762,26140658,9.6699,100,1,17.6000,100,1,9.2899,700,1,18.3200,700,1,7.7400,700,7,20.4800,700,7,,0,0,,0,0,,0,0,,0,0,,0,0,,0,0,,0,0,,0,0,,0,0,,0,0,,0,0,,0,0,,0,0,,0,0,ARL,40999449
81,2025-07-17T13:28:30.051894007Z,2025-07-17T13:28:30.051894007Z,10,2,1108,A,B,0,9.9900,100,130,167791,26142104,9.9900,100,1,17.6000,100,1,9.6699,100,1,18.3200,700,1,9.2899,700,1,20.4800,700,7,7.7400,700,7,,0,0,,0,0,,0,0,,0,0,,0,0,,0,0,,0,0,,0,0,,0,0,,0,0,,0,0,,0,0,,0,0,ARL,41000165
82,2025-07-17T13:28:30.051907073Z,2025-07-17T13:28:30.051907073Z,10,2,1108,A,A,0,17.1200,100,130,165495,26142118,9.9900,100,1,17.1200,100,1,9.6699,100,1,17.6000,100,1,9.2899,700,1,18.3200,700,1,7.7400,700,7,20.4800,700,7,,0,0,,0,0,,0,0,,0,0,,0,0,,0,0,,0,0,,0,0,,0,0,,0,0,,0,0,,0,0,ARL,41000173
83,2025-07-17T13:28:30.256853564Z,2025-07-17T13:28:30.256853564Z,10,2,1108,A,B,0,9.6699,100,130,165280,26170917,9.9900,100,1,17.1200,100,1,9.6699,200,2,17.6000,100,1,9.2899,700,1,18.3200,700,1,7.7400,700,7,20.4800,700,7,,0,0,,0,0,,0,0,,0,0,,0,0,,0,0,,0,0,,0,0,,0,0,,0,0,,0,0,,0,0,ARL,41021369
84,2025-07-17T13:28:30.256865858Z,2025-07-17T13:28:30.256865858Z,10,2,1108,A,A,0,17.6000,100,130,165298,26170918,9.9900,100,1,17.1200,100,1,9.6699,200,2,17.6000,200,2,9.2899,700,1,18.3200,700,1,7.7400,700,7,20.4800,700,7,,0,0,,0,0,,0,0,,0,0,,0,0,,0,0,,0,0,,0,0,,0,0,,0,0,,0,0,,0,0,ARL,41021373
85,2025-07-17T13:28:30.277457031Z,2025-07-17T13:28:30.277457031Z,10,2,1108,A,B,0,9.9900,100,130,165315,26171531,9.9900,200,2,17.1200,100,1,9.6699,200,2,17.6000,200,2,9.2899,700,1,18.3200,700,1,7.7400,700,7,20.4800,700,7,,0,0,,0,0,,0,0,,0,0,,0,0,,0,0,,0,0,,0,0,,0,0,,0,0,,0,0,,0,0,ARL,41021837
86,2025-07-17T13:28:30.277470320Z,2025-07-17T13:28:30.277470320Z,10,2,1108,A,A,0,17.1200,100,130,165325,26171533,9.9900,200,2,17.1200,200,2,9.6699,200,2,17.6000,200,2,9.2899,700,1,18.3200,700,1,7.7400,700,7,20.4800,700,7,,0,0,,0,0,,0,0,,0,0,,0,0,,0,0,,0,0,,0,0,,0,0,,0,0,,0,0,,0,0,ARL,41021841
87,2025-07-17T13:28:30.613317490Z,2025-07-17T13:28:30.613317490Z,10,2,1108,A,B,0,9.1300,100,130,165177,26182390,9.9900,200,2,17.1200,200,2,9.6699,200,2,17.6000,200,2,9.2899,700,1,18.3200,700,1,9.1300,100,1,20.4800,700,7,7.7400,700,7,,0,0,,0,0,,0,0,,0,0,,0,0,,0,0,,0,0,,0,0,,0,0,,0,0,,0,0,ARL,41032049
88,2025-07-17T13:28:30.613329849Z,2025-07-17T13:28:30.613329849Z,10,2,1108,A,A,0,18.3999,100,130,165208,26182393,9.9900,200,2,17.1200,200,2,9.6699,200,2,17.6000,200,2,9.2899,700,1,18.3200,700,1,9.1300,100,1,18.3999,100,1,7.7400,700,7,20.4800,700,7,,0,0,,0,0,,0,0,,0,0,,0,0,,0,0,,0,0,,0,0,,0,0,,0,0,ARL,41032057
89,2025-07-17T13:28:41.476711173Z,2025-07-17T13:28:41.476711173Z,10,2,1108,A,B,0,7.8399,100,130,165374,26518296,9.9900,200,2,17.1200,200,2,9.6699,200,2,17.6000,200,2,9.2899,700,1,18.3200,700,1,9.1300,100,1,18.3999,100,1,7.8399,100,1,20.4800,700,7,7.7400,700,7,,0,0,,0,0,,0,0,,0,0,,0,0,,0,0,,0,0,,0,0,,0,0,ARL,41306441
90,2025-07-17T13:28:41.476722715Z,2025-07-17T13:28:41.476722715Z,10,2,1108,A,A,0,20.3200,100,130,165260,26518297,9.9900,200,2,17.1200,200,2,9.6699,200,2,17.6000,200,2,9.2899,700,1,18.3200,700,1,9.1300,100,1,18.3999,100,1,7.8399,100,1,20.3200,100,1,7.7400,700,7,20.4800,700,7,,0,0,,0,0,,0,0,,0,0,,0,0,,0,0,,0,0,,0,0,ARL,41306445
91,2025-07-17T13:28:46.014739305Z,2025-07-17T13:28:46.014739305Z,10,2,1108,A,A,0,15.3000,100,130,165569,26613800,9.9900,200,2,15.3000,100,1,9.6699,200,2,17.1200,200,2,9.2899,700,1,17.6000,200,2,9.1300,100,1,18.3200,700,1,7.8399,100,1,18.3999,100,1,7.7400,700,7,20.3200,100,1,,0,0,20.4800,700,7,,0,0,,0,0,,0,0,,0,0,,0,0,,0,0,ARL,41370837
92,2025-07-17T13:28:46.014802018Z,2025-07-17T13:28:46.014802018Z,10,2,1108,C,A,0,20.4800,100,0,165982,26613836,9.9900,200,2,15.3000,100,1,9.6699,200,2,17.1200,200,2,9.2899,700,1,17.6000,200,2,9.1300,100,1,18.3200,700,1,7.8399,100,1,18.3999,100,1,7.7400,700,7,20.3200,100,1,,0,0,20.4800,600,6,,0,0,,0,0,,0,0,,0,0,,0,0,,0,0,ARL,23570297
93,2025-07-17T13:28:46.014802018Z,2025-07-17T13:28:46.014802018Z,10,2,1108,A,A,0,19.5799,100,130,165982,26613836,9.9900,200,2,15.3000,100,1,9.6699,200,2,17.1200,200,2,9.2899,700,1,17.6000,200,2,9.1300,100,1,18.3200,700,1,7.8399,100,1,18.3999,100,1,7.7400,700,7,19.5799,100,1,,0,0,20.3200,100,1,,0,0,20.4800,600,6,,0,0,,0,0,,0,0,,0,0,ARL,41370945
94,2025-07-17T13:28:46.014803011Z,2025-07-17T13:28:46.014803011Z,10,2,1108,C,A,0,20.4800,100,0,166124,26613837,9.9900,200,2,15.3000,100,1,9.6699,200,2,17.1200,200,2,9.2899,700,1,17.6000,200,2,9.1300,100,1,18.3200,700,1,7.8399,100,1,18.3999,100,1,7.7400,700,7,19.5799,100,1,,0,0,20.3200,100,1,,0,0,20.4800,500,5,,0,0,,0,0,,0,0,,0,0,ARL,23616201
95,2025-07-17T13:28:46.014803011Z,2025-07-17T13:28:46.014803011Z,10,2,1108,A,A,0,19.5799,100,130,166124,26613837,9.9900,200,2,15.3000,100,1,9.6699,200,2,17.1200,200,2,9.2899,700,1,17.6000,200,2,9.1300,100,1,18.3200,700,1,7.8399,100,1,18.3999,100,1,7.7400,700,7,19.5799,200,2,,0,0,20.3200,100,1,,0,0,20.4800,500,5,,0,0,,0,0,,0,0,,0,0,ARL,41370949
96,2025-07-17T13:28:46.014804158Z,2025-07-17T13:28:46.014804158Z,10,2,1108,C,A,0,20.4800,100,0,166541,26613838,9.9900,200,2,15.3000,100,1,9.6699,200,2,17.1200,200,2,9.2899,700,1,17.6000,200,2,9.1300,100,1,18.3200,700,1,7.8399,100,1,18.3999,100,1,7.7400,700,7,19.5799,200,2,,0,0,20.3200,100,1,,0,0,20.4800,400,4,,0,0,,0,0,,0,0,,0,0,ARL,24099409
97,2025-07-17T13:28:46.014804158Z,2025-07-17T13:28:46.014804158Z,10,2,1108,A,A,0,19.5799,100,0,166541,26613838,9.9900,200,2,15.3000,100,1,9.6699,200,2,17.1200,200,2,9.2899,700,1,17.6000,200,2,9.1300,100,1,18.3200,700,1,7.8399,100,1,18.3999,100,1,7.7400,700,7,19.5799,300,3,,0,0,20.3200,100,1,,0,0,20.4800,400,4,,0,0,,0,0,,0,0,,0,0,ARL,41370953
98,2025-07-17T13:28:46.014804564Z,2025-07-17T13:28:46.014804564Z,10,2,1108,C,A,0,20.4800,100,0,166135,26613839,9.9900,200,2,15.3000,100,1,9.6699,200,2,17.1200,200,2,9.2899,700,1,17.6000,200,2,9.1300,100,1,18.3200,700,1,7.8399,100,1,18.3999,100,1,7.7400,700,7,19.5799,300,3,,0,0,20.3200,100,1,,0,0,20.4800,300,3,,0,0,,0,0,,0,0,,0,0,ARL,31962113
99,2025-07-17T13:28:46.014804564Z,2025-07-17T13:28:46.014804564Z,10,2,1108,A,A,0,19.5799,100,130,166135,26613839,9.9900,200,2,15.3000,100,1,9.6699,200,2,17.1200,200,2,9.2899,700,1,17.6000,200,2,9.1300,100,1,18.3200,700,1,7.8399,100,1,18.3999,100,1,7.7400,700,7,19.5799,400,4,,0,0,20.3200,100,1,,0,0,20.4800,300,3,,0,0,,0,0,,0,0,,0,0,ARL,41370957
100,2025-07-17T13:28:46.014805680Z,2025-07-17T13:28:46.014805680Z,10,2,1108,C,A,0,20.4800,100,0,166471,26613840,9.9900,200,2,15.3000,100,1,9.6699,200,2,17.1200,200,2,9.2899,700,1,17.6000,200,2,9.1300,100,1,18.3200,700,1,7.8399,100,1,18.3999,100,1,7.7400,700,7,19.5799,400,4,,0,0,20.3200,100,1,,0,0,20.4800,200,2,,0,0,,0,0,,0,0,,0,0,ARL,33574725
101,2025-07-17T13:28:46.014805680Z,2025-07-17T13:28:46.014805680Z,10,2,1108,A,A,0,19.5799,100,0,166471,26613840,9.9900,200,2,15.3000,100,1,9.6699,200,2,17.1200,200,2,9.2899,700,1,17.6000,200,2,9.1300,100,1,18.3200,700,1,7.8399,100,1,18.3999,100,1,7.7400,700,7,19.5799,500,5,,0,0,20.3200,100,1,,0,0,20.4800,200,2,,0,0,,0,0,,0,0,,0,0,ARL,41370961
102,2025-07-17T13:28:46.014805841Z,2025-07-17T13:28:46.014805841Z,10,2,1108,C,A,0,20.4800,100,0,166310,26613841,9.9900,200,2,15.3000,100,1,9.6699,200,2,17.1200,200,2,9.2899,700,1,17.6000,200,2,9.1300,100,1,18.3200,700,1,7.8399,100,1,18.3999,100,1,7.7400,700,7,19.5799,500,5,,0,0,20.3200,100,1,,0,0,20.4800,100,1,,0,0,,0,0,,0,0,,0,0,ARL,38043741
103,2025-07-17T13:28:46.014805841Z,2025-07-17T13:28:46.014805841Z,10,2,1108,A,A,0,19.5799,100,130,166310,26613841,9.9900,200,2,15.3000,100,1,9.6699,200,2,17.1200,200,2,9.2899,700,1,17.6000,200,2,9.1300,100,1,18.3200,700,1,7.8399,100,1,18.3999,100,1,7.7400,700,7,19.5799,600,6,,0,0,20.3200,100,1,,0,0,20.4800,100,1,,0,0,,0,0,,0,0,,0,0,ARL,41370965
104,2025-07-17T13:28:46.014807086Z,2025-07-17T13:28:46.014807086Z,10,2,1108,C,A,0,20.4800,100,0,166257,26613842,9.9900,200,2,15.3000,100,1,9.6699,200,2,17.1200,200,2,9.2899,700,1,17.6000,200,2,9.1300,100,1,18.3200,700,1,7.8399,100,1,18.3999,100,1,7.7400,700,7,19.5799,600,6,,0,0,20.3200,100,1,,0,0,,0,0,,0,0,,0,0,,0,0,,0,0,ARL,40617785
105,2025-07-17T13:28:46.014807086Z,2025-07-17T13:28:46.014807086Z,10,2,1108,A,A,0,19.5799,100,130,166257,26613842,9.9900,200,2,15.3000,100,1,9.6699,200,2,17.1200,200,2,9.2899,700,1,17.6000,200,2,9.1300,100,1,18.3200,700,1,7.8399,100,1,18.3999,100,1,7.7400,700,7,19.5799,700,7,,0,0,20.3200,100,1,,0,0,,0,0,,0,0,,0,0,,0,0,,0,0,ARL,41370969
106,2025-07-17T13:28:46.015523291Z,2025-07-17T13:28:46.015523291Z,10,2,1108,A,B,0,10.1799,700,130,167070,26614152,10.1799,700,1,15.3000,100,1,9.9900,200,2,17.1200,200,2,9.6699,200,2,17.6000,200,2,9.2899,700,1,18.3200,700,1,9.1300,100,1,18.3999,100,1,7.8399,100,1,19.5799,700,7,7.7400,700,7,20.3200,100,1,,0,0,,0,0,,0,0,,0,0,,0,0,,0,0,ARL,41371221
107,2025-07-17T13:28:46.015525315Z,2025-07-17T13:28:46.015525315Z,10,2,1108,A,A,0,16.1099,700,130,166302,26614155,10.1799,700,1,15.3000,100,1,9.9900,200,2,16.1099,700,1,9.6699,200,2,17.1200,200,2,9.2899,700,1,17.6000,200,2,9.1300,100,1,18.3200,700,1,7.8399,100,1,18.3999,100,1,7.7400,700,7,19.5799,700,7,,0,0,20.3200,100,1,,0,0,,0,0,,0,0,,0,0,ARL,41371225
108,2025-07-17T13:28:46.017209641Z,2025-07-17T13:28:46.017209641Z,10,2,1108,C,A,0,17.1200,100,0,165527,26614961,10.1799,700,1,15.3000,100,1,9.9900,200,2,16.1099,700,1,9.6699,200,2,17.1200,100,1,9.2899,700,1,17.6000,200,2,9.1300,100,1,18.3200,700,1,7.8399,100,1,18.3999,100,1,7.7400,700,7,19.5799,700,7,,0,0,20.3200,100,1,,0,0,,0,0,,0,0,,0,0,ARL,41000173
109,2025-07-17T13:28:46.017209641Z,2025-07-17T13:28:46.017209641Z,10,2,1108,A,A,0,16.3799,100,130,165527,26614961,10.1799,700,1,15.3000,100,1,9.9900,200,2,16.1099,700,1,9.6699,200,2,16.3799,100,1,9.2899,700,1,17.1200,100,1,9.1300,100,1,17.6000,200,2,7.8399,100,1,18.3200,700,1,7.7400,700,7,18.3999,100,1,,0,0,19.5799,700,7,,0,0,20.3200,100,1,,0,0,,0,0,ARL,41372085
110,2025-07-17T13:28:46.017260228Z,2025-07-17T13:28:46.017260228Z,10,2,1108,C,A,0,17.6000,100,0,165399,26614991,10.1799,700,1,15.3000,100,1,9.9900,200,2,16.1099,700,1,9.6699,200,2,16.3799,100,1,9.2899,700,1,17.1200,100,1,9.1300,100,1,17.6000,100,1,7.8399,100,1,18.3200,700,1,7.7400,700,7,18.3999,100,1,,0,0,19.5799,700,7,,0,0,20.3200,100,1,,0,0,,0,0,ARL,40999449
111,2025-07-17T13:28:46.017260228Z,2025-07-17T13:28:46.017260228Z,10,2,1108,A,A,0,16.8299,100,130,165399,26614991,10.1799,700,1,15.3000,100,1,9.9900,200,2,16.1099,700,1,9.6699,200,2,16.3799,100,1,9.2899,700,1,16.8299,100,1,9.1300,100,1,17.1200,100,1,7.8399,100,1,17.6000,100,1,7.7400,700,7,18.3200,700,1,,0,0,18.3999,100,1,,0,0,19.5799,700,7,,0,0,20.3200,100,1,ARL,41372125
112,2025-07-17T13:28:46.017531156Z,2025-07-17T13:28:46.017531156Z,10,2,1108,C,A,0,17.1200,100,0,165417,26615138,10.1799,700,1,15.3000,100,1,9.9900,200,2,16.1099,700,1,9.6699,200,2,16.3799,100,1,9.2899,700,1,16.8299,100,1,9.1300,100,1,17.6000,100,1,7.8399,100,1,18.3200,700,1,7.7400,700,7,18.3999,100,1,,0,0,19.5799,700,7,,0,0,20.3200,100,1,,0,0,,0,0,ARL,41021841
113,2025-07-17T13:28:46.017531156Z,2025-07-17T13:28:46.017531156Z,10,2,1108,A,A,0,16.3799,100,130,165417,26615138,10.1799,700,1,15.3000,100,1,9.9900,200,2,16.1099,700,1,9.6699,200,2,16.3799,200,2,9.2899,700,1,16.8299,100,1,9.1300,100,1,17.6000,100,1,7.8399,100,1,18.3200,700,1,7.7400,700,7,18.3999,100,1,,0,0,19.5799,700,7,,0,0,20.3200,100,1,,0,0,,0,0,ARL,41372369
114,2025-07-17T13:28:46.017657609Z,2025-07-17T13:28:46.017657609Z,10,2,1108,C,A,0,17.6000,100,0,165464,26615203,10.1799,700,1,15.3000,100,1,9.9900,200,2,16.1099,700,1,9.6699,200,2,16.3799,200,2,9.2899,700,1,16.8299,100,1,9.1300,100,1,18.3200,700,1,7.8399,100,1,18.3999,100,1,7.7400,700,7,19.5799,700,7,,0,0,20.3200,100,1,,0,0,,0,0,,0,0,,0,0,ARL,41021373
115,2025-07-17T13:28:46.017657609Z,2025-07-17T13:28:46.017657609Z,10,2,1108,A,A,0,16.8299,100,130,165464,26615203,10.1799,700,1,15.3000,100,1,9.9900,200,2,16.1099,700,1,9.6699,200,2,16.3799,200,2,9.2899,700,1,16.8299,200,2,9.1300,100,1,18.3200,700,1,7.8399,100,1,18.3999,100,1,7.7400,700,7,19.5799,700,7,,0,0,20.3200,100,1,,0,0,,0,0,,0,0,,0,0,ARL,41372469
116,2025-07-17T13:28:46.017721028Z,2025-07-17T13:28:46.017721028Z,10,2,1108,C,A,0,18.3999,100,0,165400,26615230,10.1799,700,1,15.3000,100,1,9.9900,200,2,16.1099,700,1,9.6699,200,2,16.3799,200,2,9.2899,700,1,16.8299,200,2,9.1300,100,1,18.3200,700,1,7.8399,100,1,19.5799,700,7,7.7400,700,7,20.3200,100,1,,0,0,,0,0,,0,0,,0,0,,0,0,,0,0,ARL,41032057
117,2025-07-17T13:28:46.017721028Z,2025-07-17T13:28:46.017721028Z,10,2,1108,A,A,0,17.6000,100,130,165400,26615230,10.1799,700,1,15.3000,100,1,9.9900,200,2,16.1099,700,1,9.6699,200,2,16.3799,200,2,9.2899,700,1,16.8299,200,2,9.1300,100,1,17.6000,100,1,7.8399,100,1,18.3200,700,1,7.7400,700,7,19.5799,700,7,,0,0,20.3200,100,1,,0,0,,0,0,,0,0,,0,0,ARL,41372493
118,2025-07-17T13:28:46.017837874Z,2025-07-17T13:28:46.017837874Z,10,2,1108,C,A,0,20.3200,100,0,165245,26615283,10.1799,700,1,15.3000,100,1,9.9900,200,2,16.1099,700,1,9.6699,200,2,16.3799,200,2,9.2899,700,1,16.8299,200,2,9.1300,100,1,17.6000,100,1,7.8399,100,1,18.3200,700,1,7.7400,700,7,19.5799,700,7,,0,0,,0,0,,0,0,,0,0,,0,0,,0,0,ARL,41306445
119,2025-07-17T13:28:46.017837874Z,2025-07-17T13:28:46.017837874Z,10,2,1108,A,A,0,19.4400,100,130,165245,26615283,10.1799,700,1,15.3000,100,1,9.9900,200,2,16.1099,700,1,9.6699,200,2,16.3799,200,2,9.2899,700,1,16.8299,200,2,9.1300,100,1,17.6000,100,1,7.8399,100,1,18.3200,700,1,7.7400,700,7,19.4400,100,1,,0,0,19.5799,700,7,,0,0,,0,0,,0,0,,0,0,ARL,41372549
120,2025-07-17T13:28:46.022095254Z,2025-07-17T13:28:46.022095254Z,10,2,1108,A,B,0,10.0500,700,128,167174,26616844,10.1799,700,1,15.3000,100,1,10.0500,700,1,16.1099,700,1,9.9900,200,2,16.3799,200,2,9.6699,200,2,16.8299,200,2,9.2899,700,1,17.6000,100,1,9.1300,100,1,18.3200,700,1,7.8399,100,1,19.4400,100,1,7.7400,700,7,19.5799,700,7,,0,0,,0,0,,0,0,,0,0,ARL,41375793
121,2025-07-17T13:28:46.022822832Z,2025-07-17T13:28:46.022822832Z,10,2,1108,A,A,0,16.3000,700,130,165231,26617168,10.1799,700,1,15.3000,100,1,10.0500,700,1,16.1099,700,1,9.9900,200,2,16.3000,700,1,9.6699,200,2,16.3799,200,2,9.2899,700,1,16.8299,200,2,9.1300,100,1,17.6000,100,1,7.8399,100,1,18.3200,700,1,7.7400,700,7,19.4400,100,1,,0,0,19.5799,700,7,,0,0,,0,0,ARL,41375973
122,2025-07-17T13:28:46.025816567Z,2025-07-17T13:28:46.025816567Z,10,2,1108,A,B,0,11.7599,100,130,165012,26618403,11.7599,100,1,15.3000,100,1,10.1799,700,1,16.1099,700,1,10.0500,700,1,16.3000,700,1,9.9900,200,2,16.3799,200,2,9.6699,200,2,16.8299,200,2,9.2899,700,1,17.6000,100,1,9.1300,100,1,18.3200,700,1,7.8399,100,1,19.4400,100,1,7.7400,700,7,19.5799,700,7,,0,0,,0,0,ARL,41376297
123,2025-07-17T13:28:46.025870563Z,2025-07-17T13:28:46.025870563Z,10,2,1108,C,B,0,7.7400,100,0,166599,26618436,11.7599,100,1,15.3000,100,1,10.1799,700,1,16.1099,700,1,10.0500,700,1,16.3000,700,1,9.9900,200,2,16.3799,200,2,9.6699,200,2,16.8299,200,2,9.2899,700,1,17.6000,100,1,9.1300,100,1,18.3200,700,1,7.8399,100,1,19.4400,100,1,7.7400,600,6,19.5799,700,7,,0,0,,0,0,ARL,23616197
124,2025-07-17T13:28:46.025870563Z,2025-07-17T13:28:46.025870563Z,10,2,1108,A,B,0,8.4700,100,130,166599,26618436,11.7599,100,1,15.3000,100,1,10.1799,700,1,16.1099,700,1,10.0500,700,1,16.3000,700,1,9.9900,200,2,16.3799,200,2,9.6699,200,2,16.8299,200,2,9.2899,700,1,17.6000,100,1,9.1300,100,1,18.3200,700,1,8.4700,100,1,19.4400,100,1,7.8399,100,1,19.5799,700,7,7.7400,600,6,,0,0,ARL,41376333
125,2025-07-17T13:28:46.025872146Z,2025-07-17T13:28:46.025872146Z,10,2,1108,C,B,0,7.7400,100,0,165912,26618438,11.7599,100,1,15.3000,100,1,10.1799,700,1,16.1099,700,1,10.0500,700,1,16.3000,700,1,9.9900,200,2,16.3799,200,2,9.6699,200,2,16.8299,200,2,9.2899,700,1,17.6000,100,1,9.1300,100,1,18.3200,700,1,8.4700,100,1,19.4400,100,1,7.8399,100,1,19.5799,700,7,7.7400,500,5,,0,0,ARL,23622101
126,2025-07-17T13:28:46.025872146Z,2025-07-17T13:28:46.025872146Z,10,2,1108,A,B,0,8.4700,100,130,165912,26618438,11.7599,100,1,15.3000,100,1,10.1799,700,1,16.1099,700,1,10.0500,700,1,16.3000,700,1,9.9900,200,2,16.3799,200,2,9.6699,200,2,16.8299,200,2,9.2899,700,1,17.6000,100,1,9.1300,100,1,18.3200,700,1,8.4700,200,2,19.4400,100,1,7.8399,100,1,19.5799,700,7,7.7400,500,5,,0,0,ARL,41376337
127,2025-07-17T13:28:46.025873388Z,2025-07-17T13:28:46.025873388Z,10,2,1108,C,B,0,7.7400,100,0,166299,26618439,11.7599,100,1,15.3000,100,1,10.1799,700,1,16.1099,700,1,10.0500,700,1,16.3000,700,1,9.9900,200,2,16.3799,200,2,9.6699,200,2,16.8299,200,2,9.2899,700,1,17.6000,100,1,9.1300,100,1,18.3200,700,1,8.4700,200,2,19.4400,100,1,7.8399,100,1,19.5799,700,7,7.7400,400,4,,0,0,ARL,24102329
128,2025-07-17T13:28:46.025873388Z,2025-07-17T13:28:46.025873388Z,10,2,1108,A,B,0,8.4700,100,128,166299,26618439,11.7599,100,1,15.3000,100,1,10.1799,700,1,16.1099,700,1,10.0500,700,1,16.3000,700,1,9.9900,200,2,16.3799,200,2,9.6699,200,2,16.8299,200,2,9.2899,700,1,17.6000,100,1,9.1300,100,1,18.3200,700,1,8.4700,300,3,19.4400,100,1,7.8399,100,1,19.5799,700,7,7.7400,400,4,,0,0,ARL,41376341
129,2025-07-17T13:28:46.025874774Z,2025-07-17T13:28:46.025874774Z,10,2,1108,C,B,0,7.7400,100,0,170905,26618441,11.7599,100,1,15.3000,100,1,10.1799,700,1,16.1099,700,1,10.0500,700,1,16.3000,700,1,9.9900,200,2,16.3799,200,2,9.6699,200,2,16.8299,200,2,9.2899,700,1,17.6000,100,1,9.1300,100,1,18.3200,700,1,8.4700,300,3,19.4400,100,1,7.8399,100,1,19.5799,700,7,7.7400,300,3,,0,0,ARL,31960841
130,2025-07-17T13:28:46.025874774Z,2025-07-17T13:28:46.025874774Z,10,2,1108,A,B,0,8.4700,100,0,170905,26618441,11.7599,100,1,15.3000,100,1,10.1799,700,1,16.1099,700,1,10.0500,700,1,16.3000,700,1,9.9900,200,2,16.3799,200,2,9.6699,200,2,16.8299,200,2,9.2899,700,1,17.6000,100,1,9.1300,100,1,18.3200,700,1,8.4700,400,4,19.4400,100,1,7.8399,100,1,19.5799,700,7,7.7400,300,3,,0,0,ARL,41376345
131,2025-07-17T13:28:46.025875041Z,2025-07-17T13:28:46.025875041Z,10,2,1108,C,B,0,7.7400,100,0,170638,26618442,11.7599,100,1,15.3000,100,1,10.1799,700,1,16.1099,700,1,10.0500,700,1,16.3000,700,1,9.9900,200,2,16.3799,200,2,9.6699,200,2,16.8299,200,2,9.2899,700,1,17.6000,100,1,9.1300,100,1,18.3200,700,1,8.4700,400,4,19.4400,100,1,7.8399,100,1,19.5799,700,7,7.7400,200,2,,0,0,ARL,33574717
132,2025-07-17T13:28:46.025875041Z,2025-07-17T13:28:46.025875041Z,10,2,1108,A,B,0,8.4700,100,0,170638,26618442,11.7599,100,1,15.3000,100,1,10.1799,700,1,16.1099,700,1,10.0500,700,1,16.3000,700,1,9.9900,200,2,16.3799,200,2,9.6699,200,2,16.8299,200,2,9.2899,700,1,17.6000,100,1,9.1300,100,1,18.3200,700,1,8.4700,500,5,19.4400,100,1,7.8399,100,1,19.5799,700,7,7.7400,200,2,,0,0,ARL,41376349
133,2025-07-17T13:28:46.025875401Z,2025-07-17T13:28:46.025875401Z,10,2,1108,C,B,0,7.7400,100,0,170278,26618443,11.7599,100,1,15.3000,100,1,10.1799,700,1,16.1099,700,1,10.0500,700,1,16.3000,700,1,9.9900,200,2,16.3799,200,2,9.6699,200,2,16.8299,200,2,9.2899,700,1,17.6000,100,1,9.1300,100,1,18.3200,700,1,8.4700,500,5,19.4400,100,1,7.8399,100,1,19.5799,700,7,7.7400,100,1,,0,0,ARL,38041417
134,2025-07-17T13:28:46.025875401Z,2025-07-17T13:28:46.025875401Z,10,2,1108,A,B,0,8.4700,100,0,170278,26618443,11.7599,100,1,15.3000,100,1,10.1799,700,1,16.1099,700,1,10.0500,700,1,16.3000,700,1,9.9900,200,2,16.3799,200,2,9.6699,200,2,16.8299,200,2,9.2899,700,1,17.6000,100,1,9.1300,100,1,18.3200,700,1,8.4700,600,6,19.4400,100,1,7.8399,100,1,19.5799,700,7,7.7400,100,1,,0,0,ARL,41376353
135,2025-07-17T13:28:46.025877502Z,2025-07-17T13:28:46.025877502Z,10,2,1108,C,B,0,7.7400,100,0,168177,26618447,11.7599,100,1,15.3000,100,1,10.1799,700,1,16.1099,700,1,10.0500,700,1,16.3000,700,1,9.9900,200,2,16.3799,200,2,9.6699,200,2,16.8299,200,2,9.2899,700,1,17.6000,100,1,9.1300,100,1,18.3200,700,1,8.4700,600,6,19.4400,100,1,7.8399,100,1,19.5799,700,7,,0,0,,0,0,ARL,40617777
136,2025-07-17T13:28:46.025877502Z,2025-07-17T13:28:46.025877502Z,10,2,1108,A,B,0,8.4700,100,130,168177,26618447,11.7599,100,1,15.3000,100,1,10.1799,700,1,16.1099,700,1,10.0500,700,1,16.3000,700,1,9.9900,200,2,16.3799,200,2,9.6699,200,2,16.8299,200,2,9.2899,700,1,17.6000,100,1,9.1300,100,1,18.3200,700,1,8.4700,700,7,19.4400,100,1,7.8399,100,1,19.5799,700,7,,0,0,,0,0,ARL,41376357
137,2025-07-17T13:28:46.027560174Z,2025-07-17T13:28:46.027560174Z,10,2,1108,C,B,0,9.9900,100,0,165509,26619144,11.7599,100,1,15.3000,100,1,10.1799,700,1,16.1099,700,1,10.0500,700,1,16.3000,700,1,9.9900,100,1,16.3799,200,2,9.6699,200,2,16.8299,200,2,9.2899,700,1,17.6000,100,1,9.1300,100,1,18.3200,700,1,8.4700,700,7,19.4400,100,1,7.8399,100,1,19.5799,700,7,,0,0,,0,0,ARL,41000165
138,2025-07-17T13:28:46.027560174Z,2025-07-17T13:28:46.027560174Z,10,2,1108,A,B,0,10.9299,100,130,165509,26619144,11.7599,100,1,15.3000,100,1,10.9299,100,1,16.1099,700,1,10.1799,700,1,16.3000,700,1,10.0500,700,1,16.3799,200,2,9.9900,100,1,16.8299,200,2,9.6699,200,2,17.6000,100,1,9.2899,700,1,18.3200,700,1,9.1300,100,1,19.4400,100,1,8.4700,700,7,19.5799,700,7,7.8399,100,1,,0,0,ARL,41376501
139,2025-07-17T13:28:46.029556957Z,2025-07-17T13:28:46.029556957Z,10,2,1108,C,B,0,9.6699,100,0,169828,26619966,11.7599,100,1,15.3000,100,1,10.9299,100,1,16.1099,700,1,10.1799,700,1,16.3000,700,1,10.0500,700,1,16.3799,200,2,9.9900,100,1,16.8299,200,2,9.6699,100,1,17.6000,100,1,9.2899,700,1,18.3200,700,1,9.1300,100,1,19.4400,100,1,8.4700,700,7,19.5799,700,7,7.8399,100,1,,0,0,ARL,40999441
140,2025-07-17T13:28:46.029556957Z,2025-07-17T13:28:46.029556957Z,10,2,1108,A,B,0,10.5800,100,128,169828,26619966,11.7599,100,1,15.3000,100,1,10.9299,100,1,16.1099,700,1,10.5800,100,1,16.3000,700,1,10.1799,700,1,16.3799,200,2,10.0500,700,1,16.8299,200,2,9.9900,100,1,17.6000,100,1,9.6699,100,1,18.3200,700,1,9.2899,700,1,19.4400,100,1,9.1300,100,1,19.5799,700,7,8.4700,700,7,,0,0,ARL,41376725
141,2025-07-17T13:28:46.029609064Z,2025-07-17T13:28:46.029609064Z,10,2,1108,C,B,0,7.8399,100,0,166186,26619999,11.7599,100,1,15.3000,100,1,10.9299,100,1,16.1099,700,1,10.5800,100,1,16.3000,700,1,10.1799,700,1,16.3799,200,2,10.0500,700,1,16.8299,200,2,9.9900,100,1,17.6000,100,1,9.6699,100,1,18.3200,700,1,9.2899,700,1,19.4400,100,1,9.1300,100,1,19.5799,700,7,8.4700,700,7,,0,0,ARL,41306441
142,2025-07-17T13:28:46.029609064Z,2025-07-17T13:28:46.029609064Z,10,2,1108,A,B,0,8.5800,100,130,166186,26619999,11.7599,100,1,15.3000,100,1,10.9299,100,1,16.1099,700,1,10.5800,100,1,16.3000,700,1,10.1799,700,1,16.3799,200,2,10.0500,700,1,16.8299,200,2,9.9900,100,1,17.6000,100,1,9.6699,100,1,18.3200,700,1,9.2899,700,1,19.4400,100,1,9.1300,100,1,19.5799,700,7,8.5800,100,1,,0,0,ARL,41376733
143,2025-07-17T13:28:46.031073916Z,2025-07-17T13:28:46.031073916Z,10,2,1108,C,B,0,9.1300,100,0,165536,26620530,11.7599,100,1,15.3000,100,1,10.9299,100,1,16.1099,700,1,10.5800,100,1,16.3000,700,1,10.1799,700,1,16.3799,200,2,10.0500,700,1,16.8299,200,2,9.9900,100,1,17.6000,100,1,9.6699,100,1,18.3200,700,1,9.2899,700,1,19.4400,100,1,8.5800,100,1,19.5799,700,7,8.4700,700,7,,0,0,ARL,41032049
144,2025-07-17T13:28:46.031073916Z,2025-07-17T13:28:46.031073916Z,10,2,1108,A,B,0,9.9900,100,130,165536,26620530,11.7599,100,1,15.3000,100,1,10.9299,100,1,16.1099,700,1,10.5800,100,1,16.3000,700,1,10.1799,700,1,16.3799,200,2,10.0500,700,1,16.8299,200,2,9.9900,200,2,17.6000,100,1,9.6699,100,1,18.3200,700,1,9.2899,700,1,19.4400,100,1,8.5800,100,1,19.5799,700,7,8.4700,700,7,,0,0,ARL,41376769
145,2025-07-17T13:28:46.037954661Z,2025-07-17T13:28:46.037954661Z,10,2,1108,C,B,0,9.6699,100,0,166331,26623213,11.7599,100,1,15.3000,100,1,10.9299,100,1,16.1099,700,1,10.5800,100,1,16.3000,700,1,10.1799,700,1,16.3799,200,2,10.0500,700,1,16.8299,200,2,9.9900,200,2,17.6000,100,1,9.2899,700,1,18.3200,700,1,8.5800,100,1,19.4400,100,1,8.4700,700,7,19.5799,700,7,,0,0,,0,0,ARL,41021369
146,2025-07-17T13:28:46.037954661Z,2025-07-17T13:28:46.037954661Z,10,2,1108,A,B,0,10.5800,100,128,166331,26623213,11.7599,100,1,15.3000,100,1,10.9299,100,1,16.1099,700,1,10.5800,200,2,16.3000,700,1,10.1799,700,1,16.3799,200,2,10.0500,700,1,16.8299,200,2,9.9900,200,2,17.6000,100,1,9.2899,700,1,18.3200,700,1,8.5800,100,1,19.4400,100,1,8.4700,700,7,19.5799,700,7,,0,0,,0,0,ARL,41377117
147,2025-07-17T13:28:46.042858782Z,2025-07-17T13:28:46.042858782Z,10,2,1108,C,B,0,9.9900,100,0,165640,26625366,11.7599,100,1,15.3000,100,1,10.9299,100,1,16.1099,700,1,10.5800,200,2,16.3000,700,1,10.1799,700,1,16.3799,200,2,10.0500,700,1,16.8299,200,2,9.9900,100,1,17.6000,100,1,9.2899,700,1,18.3200,700,1,8.5800,100,1,19.4400,100,1,8.4700,700,7,19.5799,700,7,,0,0,,0,0,ARL,41021837
148,2025-07-17T13:28:46.042858782Z,2025-07-17T13:28:46.042858782Z,10,2,1108,A,B,0,10.9299,100,130,165640,26625366,11.7599,100,1,15.3000,100,1,10.9299,200,2,16.1099,700,1,10.5800,200,2,16.3000,700,1,10.1799,700,1,16.3799,200,2,10.0500,700,1,16.8299,200,2,9.9900,100,1,17.6000,100,1,9.2899,700,1,18.3200,700,1,8.5800,100,1,19.4400,100,1,8.4700,700,7,19.5799,700,7,,0,0,,0,0,ARL,41379985
149,2025-07-17T13:28:52.312295020Z,2025-07-17T13:28:52.312295020Z,10,2,1108,A,B,0,10.7500,700,130,165354,26806665,11.7599,100,1,15.3000,100,1,10.9299,200,2,16.1099,700,1,10.7500,700,1,16.3000,700,1,10.5800,200,2,16.3799,200,2,10.1799,700,1,16.8299,200,2,10.0500,700,1,17.6000,100,1,9.9900,100,1,18.3200,700,1,9.2899,700,1,19.4400,100,1,8.5800,100,1,19.5799,700,7,8.4700,700,7,,0,0,ARL,41507073
150,2025-07-17T13:28:52.312330796Z,2025-07-17T13:28:52.312330796Z,10,2,1108,C,B,0,10.0500,700,130,165236,26806666,11.7599,100,1,15.3000,100,1,10.9299,200,2,16.1099,700,1,10.7500,700,1,16.3000,700,1,10.5800,200,2,16.3799,200,2,10.1799,700,1,16.8299,200,2,9.9900,100,1,17.6000,100,1,9.2899,700,1,18.3200,700,1,8.5800,100,1,19.4400,100,1,8.4700,700,7,19.5799,700,7,,0,0,,0,0,ARL,41375793
151,2025-07-17T13:28:52.512292648Z,2025-07-17T13:28:52.512292648Z,10,2,1108,A,B,0,10.9900,700,130,165261,26808221,11.7599,100,1,15.3000,100,1,10.9900,700,1,16.1099,700,1,10.9299,200,2,16.3000,700,1,10.7500,700,1,16.3799,200,2,10.5800,200,2,16.8299,200,2,10.1799,700,1,17.6000,100,1,9.9900,100,1,18.3200,700,1,9.2899,700,1,19.4400,100,1,8.5800,100,1,19.5799,700,7,8.4700,700,7,,0,0,ARL,41509393
152,2025-07-17T13:28:52.513090520Z,2025-07-17T13:28:52.513090520Z,10,2,1108,C,B,0,10.7500,700,130,165032,26808222,11.7599,100,1,15.3000,100,1,10.9900,700,1,16.1099,700,1,10.9299,200,2,16.3000,700,1,10.5800,200,2,16.3799,200,2,10.1799,700,1,16.8299,200,2,9.9900,100,1,17.6000,100,1,9.2899,700,1,18.3200,700,1,8.5800,100,1,19.4400,100,1,8.4700,700,7,19.5799,700,7,,0,0,,0,0,ARL,41507073
153,2025-07-17T13:28:53.957067631Z,2025-07-17T13:28:53.957067631Z,10,2,1108,A,A,0,16.1499,700,130,165517,26835971,11.7599,100,1,15.3000,100,1,10.9900,700,1,16.1099,700,1,10.9299,200,2,16.1499,700,1,10.5800,200,2,16.3000,700,1,10.1799,700,1,16.3799,200,2,9.9900,100,1,16.8299,200,2,9.2899,700,1,17.6000,100,1,8.5800,100,1,18.3200,700,1,8.4700,700,7,19.4400,100,1,,0,0,19.5799,700,7,ARL,41528029
154,2025-07-17T13:28:53.957116061Z,2025-07-17T13:28:53.957116061Z,10,2,1108,C,A,0,18.3200,700,130,165456,26835974,11.7599,100,1,15.3000,100,1,10.9900,700,1,16.1099,700,1,10.9299,200,2,16.1499,700,1,10.5800,200,2,16.3000,700,1,10.1799,700,1,16.3799,200,2,9.9900,100,1,16.8299,200,2,9.2899,700,1,17.6000,100,1,8.5800,100,1,19.4400,100,1,8.4700,700,7,19.5799,700,7,,0,0,,0,0,ARL,40846101
155,2025-07-17T13:28:54.128310778Z,2025-07-17T13:28:54.128310778Z,10,2,1108,A,B,0,9.9900,700,130,165441,26850111,11.7599,100,1,15.3000,100,1,10.9900,700,1,16.1099,700,1,10.9299,200,2,16.1499,700,1,10.5800,200,2,16.3000,700,1,10.1799,700,1,16.3799,200,2,9.9900,800,2,16.8299,200,2,9.2899,700,1,17.6000,100,1,8.5800,100,1,19.4400,100,1,8.4700,700,7,19.5799,700,7,,0,0,,0,0,ARL,41530665
156,2025-07-17T13:28:54.128338727Z,2025-07-17T13:28:54.128338727Z,10,2,1108,C,B,0,9.2899,700,130,165207,26850112,11.7599,100,1,15.3000,100,1,10.9900,700,1,16.1099,700,1,10.9299,200,2,16.1499,700,1,10.5800,200,2,16.3000,700,1,10.1799,700,1,16.3799,200,2,9.9900,800,2,16.8299,200,2,8.5800,100,1,17.6000,100,1,8.4700,700,7,19.4400,100,1,,0,0,19.5799,700,7,,0,0,,0,0,ARL,40851989
157,2025-07-17T13:28:54.328487063Z,2025-07-17T13:28:54.328487063Z,10,2,1108,A,B,0,10.2599,700,130,165274,26851888,11.7599,100,1,15.3000,100,1,10.9900,700,1,16.1099,700,1,10.9299,200,2,16.1499,700,1,10.5800,200,2,16.3000,700,1,10.2599,700,1,16.3799,200,2,10.1799,700,1,16.8299,200,2,9.9900,800,2,17.6000,100,1,8.5800,100,1,19.4400,100,1,8.4700,700,7,19.5799,700,7,,0,0,,0,0,ARL,41533513
158,2025-07-17T13:28:54.328519057Z,2025-07-17T13:28:54.328519057Z,10,2,1108,C,B,0,9.9900,700,130,165029,26851889,11.7599,100,1,15.3000,100,1,10.9900,700,1,16.1099,700,1,10.9299,200,2,16.1499,700,1,10.5800,200,2,16.3000,700,1,10.2599,700,1,16.3799,200,2,10.1799,700,1,16.8299,200,2,9.9900,100,1,17.6000,100,1,8.5800,100,1,19.4400,100,1,8.4700,700,7,19.5799,700,7,,0,0,,0,0,ARL,41530665
159,2025-07-17T13:28:54.477455479Z,2025-07-17T13:28:54.477455479Z,10,2,1108,A,B,0,11.1400,700,130,165275,26853475,11.7599,100,1,15.3000,100,1,11.1400,700,1,16.1099,700,1,10.9900,700,1,16.1499,700,1,10.9299,200,2,16.3000,700,1,10.5800,200,2,16.3799,200,2,10.2599,700,1,16.8299,200,2,10.1799,700,1,17.6000,100,1,9.9900,100,1,19.4400,100,1,8.5800,100,1,19.5799,700,7,8.4700,700,7,,0,0,ARL,41534785
160,2025-07-17T13:28:54.477852651Z,2025-07-17T13:28:54.477852651Z,10,2,1108,C,B,0,10.1799,700,130,165350,26853478,11.7599,100,1,15.3000,100,1,11.1400,700,1,16.1099,700,1,10.9900,700,1,16.1499,700,1,10.9299,200,2,16.3000,700,1,10.5800,200,2,16.3799,200,2,10.2599,700,1,16.8299,200,2,9.9900,100,1,17.6000,100,1,8.5800,100,1,19.4400,100,1,8.4700,700,7,19.5799,700,7,,0,0,,0,0,ARL,41371221
161,2025-07-17T13:28:54.528542919Z,2025-07-17T13:28:54.528542919Z,10,2,1108,A,B,0,10.5299,700,130,165324,26853925,11.7599,100,1,15.3000,100,1,11.1400,700,1,16.1099,700,1,10.9900,700,1,16.1499,700,1,10.9299,200,2,16.3000,700,1,10.5800,200,2,16.3799,200,2,10.5299,700,1,16.8299,200,2,10.2599,700,1,17.6000,100,1,9.9900,100,1,19.4400,100,1,8.5800,100,1,19.5799,700,7,8.4700,700,7,,0,0,ARL,41535173
162,2025-07-17T13:28:54.528571375Z,2025-07-17T13:28:54.528571375Z,10,2,1108,C,B,0,10.2599,700,130,165179,26853926,11.7599,100,1,15.3000,100,1,11.1400,700,1,16.1099,700,1,10.9900,700,1,16.1499,700,1,10.9299,200,2,16.3000,700,1,10.5800,200,2,16.3799,200,2,10.5299,700,1,16.8299,200,2,9.9900,100,1,17.6000,100,1,8.5800,100,1,19.4400,100,1,8.4700,700,7,19.5799,700,7,,0,0,,0,0,ARL,41533513
163,2025-07-17T13:28:54.728575124Z,2025-07-17T13:28:54.728575124Z,10,2,1108,A,B,0,10.8000,700,130,165189,26856081,11.7599,100,1,15.3000,100,1,11.1400,700,1,16.1099,700,1,10.9900,700,1,16.1499,700,1,10.9299,200,2,16.3000,700,1,10.8000,700,1,16.3799,200,2,10.5800,200,2,16.8299,200,2,10.5299,700,1,17.6000,100,1,9.9900,100,1,19.4400,100,1,8.5800,100,1,19.5799,700,7,8.4700,700,7,,0,0,ARL,41537525
164,2025-07-17T13:28:54.728651317Z,2025-07-17T13:28:54.728651317Z,10,2,1108,C,B,0,10.5299,700,130,164958,26856082,11.7599,100,1,15.3000,100,1,11.1400,700,1,16.1099,700,1,10.9900,700,1,16.1499,700,1,10.9299,200,2,16.3000,700,1,10.8000,700,1,16.3799,200,2,10.5800,200,2,16.8299,200,2,9.9900,100,1,17.6000,100,1,8.5800,100,1,19.4400,100,1,8.4700,700,7,19.5799,700,7,,0,0,,0,0,ARL,41535173
165,2025-07-17T13:28:54.928412211Z,2025-07-17T13:28:54.928412211Z,10,2,1108,A,B,0,11.0700,700,130,165195,26858349,11.7599,100,1,15.3000,100,1,11.1400,700,1,16.1099,700,1,11.0700,700,1,16.1499,700,1,10.9900,700,1,16.3000,700,1,10.9299,200,2,16.3799,200,2,10.8000,700,1,16.8299,200,2,10.5800,200,2,17.6000,100,1,9.9900,100,1,19.4400,100,1,8.5800,100,1,19.5799,700,7,8.4700,700,7,,0,0,ARL,41539477
166,2025-07-17T13:28:54.928488170Z,2025-07-17T13:28:54.928488170Z,10,2,1108,C,B,0,10.8000,700,130,165133,26858351,11.7599,100,1,15.3000,100,1,11.1400,700,1,16.1099,700,1,11.0700,700,1,16.1499,700,1,10.9900,700,1,16.3000,700,1,10.9299,200,2,16.3799,200,2,10.5800,200,2,16.8299,200,2,9.9900,100,1,17.6000,100,1,8.5800,100,1,19.4400,100,1,8.4700,700,7,19.5799,700,7,,0,0,,0,0,ARL,41537525
167,2025-07-17T13:29:00.583110843Z,2025-07-17T13:29:00.583110843Z,10,2,1108,A,B,0,10.8399,100,130,165620,27000961,11.7599,100,1,15.3000,100,1,11.1400,700,1,16.1099,700,1,11.0700,700,1,16.1499,700,1,10.9900,700,1,16.3000,700,1,10.9299,200,2,16.3799,200,2,10.8399,100,1,16.8299,200,2,10.5800,200,2,17.6000,100,1,9.9900,100,1,19.4400,100,1,8.5800,100,1,19.5799,700,7,8.4700,700,7,,0,0,ARL,41635065
168,2025-07-17T13:29:00.583124331Z,2025-07-17T13:29:00.583124331Z,10,2,1108,A,A,0,16.4899,100,130,165469,27000962,11.7599,100,1,15.3000,100,1,11.1400,700,1,16.1099,700,1,11.0700,700,1,16.1499,700,1,10.9900,700,1,16.3000,700,1,10.9299,200,2,16.3799,200,2,10.8399,100,1,16.4899,100,1,10.5800,200,2,16.8299,200,2,9.9900,100,1,17.6000,100,1,8.5800,100,1,19.4400,100,1,8.4700,700,7,19.5799,700,7,ARL,41635069
169,2025-07-17T13:29:31.666485583Z,2025-07-17T13:29:31.666485583Z,10,2,1108,A,B,0,11.0500,100,130,165401,27592251,11.7599,100,1,15.3000,100,1,11.1400,700,1,16.1099,700,1,11.0700,700,1,16.1499,700,1,11.0500,100,1,16.3000,700,1,10.9900,700,1,16.3799,200,2,10.9299,200,2,16.4899,100,1,10.8399,100,1,16.8299,200,2,10.5800,200,2,17.6000,100,1,9.9900,100,1,19.4400,100,1,8.5800,100,1,19.5799,700,7,ARL,42089321
170,2025-07-17T13:29:31.666510533Z,2025-07-17T13:29:31.666510533Z,10,2,1108,A,A,0,16.2199,100,130,165507,27592252,11.7599,100,1,15.3000,100,1,11.1400,700,1,16.1099,700,1,11.0700,700,1,16.1499,700,1,11.0500,100,1,16.2199,100,1,10.9900,700,1,16.3000,700,1,10.9299,200,2,16.3799,200,2,10.8399,100,1,16.4899,100,1,10.5800,200,2,16.8299,200,2,9.9900,100,1,17.6000,100,1,8.5800,100,1,19.4400,100,1,ARL,42089325
171,2025-07-17T13:29:32.011088073Z,2025-07-17T13:29:32.011088073Z,10,2,1108,A,B,0,11.2899,100,130,165263,27599196,11.7599,100,1,15.3000,100,1,11.2899,100,1,16.1099,700,1,11.1400,700,1,16.1499,700,1,11.0700,700,1,16.2199,100,1,11.0500,100,1,16.3000,700,1,10.9900,700,1,16.3799,200,2,10.9299,200,2,16.4899,100,1,10.8399,100,1,16.8299,200,2,10.5800,200,2,17.6000,100,1,9.9900,100,1,19.4400,100,1,ARL,42099317
172,2025-07-17T13:29:32.011092154Z,2025-07-17T13:29:32.011092154Z,10,2,1108,A,A,0,15.9100,100,130,165147,27599197,11.7599,100,1,15.3000,100,1,11.2899,100,1,15.9100,100,1,11.1400,700,1,16.1099,700,1,11.0700,700,1,16.1499,700,1,11.0500,100,1,16.2199,100,1,10.9900,700,1,16.3000,700,1,10.9299,200,2,16.3799,200,2,10.8399,100,1,16.4899,100,1,10.5800,200,2,16.8299,200,2,9.9900,100,1,17.6000,100,1,ARL,42099321
173,2025-07-17T13:29:39.839973111Z,2025-07-17T13:29:39.839973111Z,10,2,1108,A,B,0,8.4700,100,130,165302,27759427,11.7599,100,1,15.3000,100,1,11.2899,100,1,15.9100,100,1,11.1400,700,1,16.1099,700,1,11.0700,700,1,16.1499,700,1,11.0500,100,1,16.2199,100,1,10.9900,700,1,16.3000,700,1,10.9299,200,2,16.3799,200,2,10.8399,100,1,16.4899,100,1,10.5800,200,2,16.8299,200,2,9.9900,100,1,17.6000,100,1,ARL,42202297
174,2025-07-17T13:29:40.000183284Z,2025-07-17T13:29:40.000183284Z,10,2,1108,A,A,0,19.5799,100,130,166283,27760200,11.7599,100,1,15.3000,100,1,11.2899,100,1,15.9100,100,1,11.1400,700,1,16.1099,700,1,11.0700,700,1,16.1499,700,1,11.0500,100,1,16.2199,100,1,10.9900,700,1,16.3000,700,1,10.9299,200,2,16.3799,200,2,10.8399,100,1,16.4899,100,1,10.5800,200,2,16.8299,200,2,9.9900,100,1,17.6000,100,1,ARL,42204681
175,2025-07-17T13:29:55.529183618Z,2025-07-17T13:29:55.529183618Z,10,2,1108,A,B,0,11.5199,100,130,165379,28123971,11.7599,100,1,15.3000,100,1,11.5199,100,1,15.9100,100,1,11.2899,100,1,16.1099,700,1,11.1400,700,1,16.1499,700,1,11.0700,700,1,16.2199,100,1,11.0500,100,1,16.3000,700,1,10.9900,700,1,16.3799,200,2,10.9299,200,2,16.4899,100,1,10.8399,100,1,16.8299,200,2,10.5800,200,2,17.6000,100,1,ARL,42446497
176,2025-07-17T13:29:55.529200619Z,2025-07-17T13:29:55.529200619Z,10,2,1108,A,A,0,15.6099,100,130,165283,28123973,11.7599,100,1,15.3000,100,1,11.5199,100,1,15.6099,100,1,11.2899,100,1,15.9100,100,1,11.1400,700,1,16.1099,700,1,11.0700,700,1,16.1499,700,1,11.0500,100,1,16.2199,100,1,10.9900,700,1,16.3000,700,1,10.9299,200,2,16.3799,200,2,10.8399,100,1,16.4899,100,1,10.5800,200,2,16.8299,200,2,ARL,42446501
177,2025-07-17T13:29:59.677285294Z,2025-07-17T13:29:59.677285294Z,10,2,1108,A,B,0,10.1099,100,130,165389,28321241,11.7599,100,1,15.3000,100,1,11.5199,100,1,15.6099,100,1,11.2899,100,1,15.9100,100,1,11.1400,700,1,16.1099,700,1,11.0700,700,1,16.1499,700,1,11.0500,100,1,16.2199,100,1,10.9900,700,1,16.3000,700,1,10.9299,200,2,16.3799,200,2,10.8399,100,1,16.4899,100,1,10.5800,200,2,16.8299,200,2,ARL,42583289
178,2025-07-17T13:29:59.677290064Z,2025-07-17T13:29:59.677290064Z,10,2,1108,A,A,0,17.4499,100,128,167123,28321242,11.7599,100,1,15.3000,100,1,11.5199,100,1,15.6099,100,1,11.2899,100,1,15.9100,100,1,11.1400,700,1,16.1099,700,1,11.0700,700,1,16.1499,700,1,11.0500,100,1,16.2199,100,1,10.9900,700,1,16.3000,700,1,10.9299,200,2,16.3799,200,2,10.8399,100,1,16.4899,100,1,10.5800,200,2,16.8299,200,2,ARL,42583293
179,2025-07-17T13:30:00.092900330Z,2025-07-17T13:30:00.092900330Z,10,2,1108,A,B,0,11.0099,100,128,185149,28409476,11.7599,100,1,15.3000,100,1,11.5199,100,1,15.6099,100,1,11.2899,100,1,15.9100,100,1,11.1400,700,1,16.1099,700,1,11.0700,700,1,16.1499,700,1,11.0500,100,1,16.2199,100,1,11.0099,100,1,16.3000,700,1,10.9900,700,1,16.3799,200,2,10.9299,200,2,16.4899,100,1,10.8399,100,1,16.8299,200,2,ARL,42674817
180,2025-07-17T13:30:00.092988904Z,2025-07-17T13:30:00.092988904Z,10,2,1108,A,A,0,16.1000,100,128,175662,28409593,11.7599,100,1,15.3000,100,1,11.5199,100,1,15.6099,100,1,11.2899,100,1,15.9100,100,1,11.1400,700,1,16.1000,100,1,11.0700,700,1,16.1099,700,1,11.0500,100,1,16.1499,700,1,11.0099,100,1,16.2199,100,1,10.9900,700,1,16.3000,700,1,10.9299,200,2,16.3799,200,2,10.8399,100,1,16.4899,100,1,ARL,42674989
181,2025-07-17T13:30:00.412637542Z,2025-07-17T13:30:00.412637542Z,10,2,1108,A,A,0,19.5799,100,128,179199,28676200,11.7599,100,1,15.3000,100,1,11.5199,100,1,15.6099,100,1,11.2899,100,1,15.9100,100,1,11.1400,700,1,16.1000,100,1,11.0700,700,1,16.1099,700,1,11.0500,100,1,16.1499,700,1,11.0099,100,1,16.2199,100,1,10.9900,700,1,16.3000,700,1,10.9299,200,2,16.3799,200,2,10.8399,100,1,16.4899,100,1,ARL,42946053
182,2025-07-17T13:30:00.421937186Z,2025-07-17T13:30:00.421937186Z,10,2,1108,A,B,0,8.4700,100,128,166733,28680759,11.7599,100,1,15.3000,100,1,11.5199,100,1,15.6099,100,1,11.2899,100,1,15.9100,100,1,11.1400,700,1,16.1000,100,1,11.0700,700,1,16.1099,700,1,11.0500,100,1,16.1499,700,1,11.0099,100,1,16.2199,100,1,10.9900,700,1,16.3000,700,1,10.9299,200,2,16.3799,200,2,10.8399,100,1,16.4899,100,1,ARL,42951397
183,2025-07-17T13:30:00.675553569Z,2025-07-17T13:30:00.675553569Z,10,2,1108,A,B,0,10.9199,100,128,171792,28833560,11.7599,100,1,15.3000,100,1,11.5199,100,1,15.6099,100,1,11.2899,100,1,15.9100,100,1,11.1400,700,1,16.1000,100,1,11.0700,700,1,16.1099,700,1,11.0500,100,1,16.1499,700,1,11.0099,100,1,16.2199,100,1,10.9900,700,1,16.3000,700,1,10.9299,200,2,16.3799,200,2,10.9199,100,1,16.4899,100,1,ARL,43143317
184,2025-07-17T13:30:00.675570319Z,2025-07-17T13:30:00.675570319Z,10,2,1108,A,A,0,16.1999,100,128,178220,28833574,11.7599,100,1,15.3000,100,1,11.5199,100,1,15.6099,100,1,11.2899,100,1,15.9100,100,1,11.1400,700,1,16.1000,100,1,11.0700,700,1,16.1099,700,1,11.0500,100,1,16.1499,700,1,11.0099,100,1,16.1999,100,1,10.9900,700,1,16.2199,100,1,10.9299,200,2,16.3000,700,1,10.9199,100,1,16.3799,200,2,ARL,43143333
185,2025-07-17T13:30:00.730688348Z,2025-07-17T13:30:00.730688348Z,10,2,1108,A,B,0,10.9199,100,130,170880,28858298,11.7599,100,1,15.3000,100,1,11.5199,100,1,15.6099,100,1,11.2899,100,1,15.9100,100,1,11.1400,700,1,16.1000,100,1,11.0700,700,1,16.1099,700,1,11.0500,100,1,16.1499,700,1,11.0099,100,1,16.1999,100,1,10.9900,700,1,16.2199,100,1,10.9299,200,2,16.3000,700,1,10.9199,200,2,16.3799,200,2,ARL,43191333
186,2025-07-17T13:30:00.730693126Z,2025-07-17T13:30:00.730693126Z,10,2,1108,A,A,0,16.1999,100,128,174279,28858300,11.7599,100,1,15.3000,100,1,11.5199,100,1,15.6099,100,1,11.2899,100,1,15.9100,100,1,11.1400,700,1,16.1000,100,1,11.0700,700,1,16.1099,700,1,11.0500,100,1,16.1499,700,1,11.0099,100,1,16.1999,200,2,10.9900,700,1,16.2199,100,1,10.9299,200,2,16.3000,700,1,10.9199,200,2,16.3799,200,2,ARL,43191369
187,2025-07-17T13:30:00.869714108Z,2025-07-17T13:30:00.869714108Z,10,2,1108,A,B,0,9.4100,100,0,179257,28963643,11.7599,100,1,15.3000,100,1,11.5199,100,1,15.6099,100,1,11.2899,100,1,15.9100,100,1,11.1400,700,1,16.1000,100,1,11.0700,700,1,16.1099,700,1,11.0500,100,1,16.1499,700,1,11.0099,100,1,16.1999,200,2,10.9900,700,1,16.2199,100,1,10.9299,200,2,16.3000,700,1,10.9199,200,2,16.3799,200,2,ARL,43313553
188,2025-07-17T13:30:00.869715708Z,2025-07-17T13:30:00.869715708Z,10,2,1108,A,A,0,18.3599,100,128,177657,28963646,11.7599,100,1,15.3000,100,1,11.5199,100,1,15.6099,100,1,11.2899,100,1,15.9100,100,1,11.1400,700,1,16.1000,100,1,11.0700,700,1,16.1099,700,1,11.0500,100,1,16.1499,700,1,11.0099,100,1,16.1999,200,2,10.9900,700,1,16.2199,100,1,10.9299,200,2,16.3000,700,1,10.9199,200,2,16.3799,200,2,ARL,43313565
189,2025-07-17T13:30:00.869746905Z,2025-07-17T13:30:00.869746905Z,10,2,1108,A,A,0,18.3599,100,128,175773,28963685,11.7599,100,1,15.3000,100,1,11.5199,100,1,15.6099,100,1,11.2899,100,1,15.9100,100,1,11.1400,700,1,16.1000,100,1,11.0700,700,1,16.1099,700,1,11.0500,100,1,16.1499,700,1,11.0099,100,1,16.1999,200,2,10.9900,700,1,16.2199,100,1,10.9299,200,2,16.3000,700,1,10.9199,200,2,16.3799,200,2,ARL,43313633
190,2025-07-17T13:30:00.869768981Z,2025-07-17T13:30:00.869768981Z,10,2,1108,A,B,0,9.4100,100,130,172234,28963699,11.7599,100,1,15.3000,100,1,11.5199,100,1,15.6099,100,1,11.2899,100,1,15.9100,100,1,11.1400,700,1,16.1000,100,1,11.0700,700,1,16.1099,700,1,11.0500,100,1,16.1499,700,1,11.0099,100,1,16.1999,200,2,10.9900,700,1,16.2199,100,1,10.9299,200,2,16.3000,700,1,10.9199,200,2,16.3799,200,2,ARL,43313681
191,2025-07-17T13:30:00.869883482Z,2025-07-17T13:30:00.869883482Z,10,2,1108,A,B,0,11.2400,100,128,173434,28963823,11.7599,100,1,15.3000,100,1,11.5199,100,1,15.6099,100,1,11.2899,100,1,15.9100,100,1,11.2400,100,1,16.1000,100,1,11.1400,700,1,16.1099,700,1,11.0700,700,1,16.1499,700,1,11.0500,100,1,16.1999,200,2,11.0099,100,1,16.2199,100,1,10.9900,700,1,16.3000,700,1,10.9299,200,2,16.3799,200,2,ARL,43313941
192,2025-07-17T13:30:00.869917271Z,2025-07-17T13:30:00.869917271Z,10,2,1108,A,A,0,15.9800,100,130,169036,28963843,11.7599,100,1,15.3000,100,1,11.5199,100,1,15.6099,100,1,11.2899,100,1,15.9100,100,1,11.2400,100,1,15.9800,100,1,11.1400,700,1,16.1000,100,1,11.0700,700,1,16.1099,700,1,11.0500,100,1,16.1499,700,1,11.0099,100,1,16.1999,200,2,10.9900,700,1,16.2199,100,1,10.9299,200,2,16.3000,700,1,ARL,43314009
193,2025-07-17T13:30:00.869979897Z,2025-07-17T13:30:00.869979897Z,10,2,1108,C,B,0,8.4700,100,0,181404,28963935,11.7599,100,1,15.3000,100,1,11.5199,100,1,15.6099,100,1,11.2899,100,1,15.9100,100,1,11.2400,100,1,15.9800,100,1,11.1400,700,1,16.1000,100,1,11.0700,700,1,16.1099,700,1,11.0500,100,1,16.1499,700,1,11.0099,100,1,16.1999,200,2,10.9900,700,1,16.2199,100,1,10.9299,200,2,16.3000,700,1,ARL,41376333
194,2025-07-17T13:30:00.869979897Z,2025-07-17T13:30:00.869979897Z,10,2,1108,A,B,0,9.5500,100,0,181404,28963935,11.7599,100,1,15.3000,100,1,11.5199,100,1,15.6099,100,1,11.2899,100,1,15.9100,100,1,11.2400,100,1,15.9800,100,1,11.1400,700,1,16.1000,100,1,11.0700,700,1,16.1099,700,1,11.0500,100,1,16.1499,700,1,11.0099,100,1,16.1999,200,2,10.9900,700,1,16.2199,100,1,10.9299,200,2,16.3000,700,1,ARL,43314145
195,2025-07-17T13:30:00.869983764Z,2025-07-17T13:30:00.869983764Z,10,2,1108,C,B,0,8.4700,100,0,177537,28963938,11.7599,100,1,15.3000,100,1,11.5199,100,1,15.6099,100,1,11.2899,100,1,15.9100,100,1,11.2400,100,1,15.9800,100,1,11.1400,700,1,16.1000,100,1,11.0700,700,1,16.1099,700,1,11.0500,100,1,16.1499,700,1,11.0099,100,1,16.1999,200,2,10.9900,700,1,16.2199,100,1,10.9299,200,2,16.3000,700,1,ARL,41376337
196,2025-07-17T13:30:00.869983764Z,2025-07-17T13:30:00.869983764Z,10,2,1108,A,B,0,9.5500,100,128,177537,28963938,11.7599,100,1,15.3000,100,1,11.5199,100,1,15.6099,100,1,11.2899,100,1,15.9100,100,1,11.2400,100,1,15.9800,100,1,11.1400,700,1,16.1000,100,1,11.0700,700,1,16.1099,700,1,11.0500,100,1,16.1499,700,1,11.0099,100,1,16.1999,200,2,10.9900,700,1,16.2199,100,1,10.9299,200,2,16.3000,700,1,ARL,43314149
197,2025-07-17T13:30:00.869988740Z,2025-07-17T13:30:00.869988740Z,10,2,1108,C,B,0,8.4700,100,0,176579,28963943,11.7599,100,1,15.3000,100,1,11.5199,100,1,15.6099,100,1,11.2899,100,1,15.9100,100,1,11.2400,100,1,15.9800,100,1,11.1400,700,1,16.1000,100,1,11.0700,700,1,16.1099,700,1,11.0500,100,1,16.1499,700,1,11.0099,100,1,16.1999,200,2,10.9900,700,1,16.2199,100,1,10.9299,200,2,16.3000,700,1,ARL,41376341
198,2025-07-17T13:30:00.869988740Z,2025-07-17T13:30:00.869988740Z,10,2,1108,A,B,0,9.5500,100,0,176579,28963943,11.7599,100,1,15.3000,100,1,11.5199,100,1,15.6099,100,1,11.2899,100,1,15.9100,100,1,11.2400,100,1,15.9800,100,1,11.1400,700,1,16.1000,100,1,11.0700,700,1,16.1099,700,1,11.0500,100,1,16.1499,700,1,11.0099,100,1,16.1999,200,2,10.9900,700,1,16.2199,100,1,10.9299,200,2,16.3000,700,1,ARL,43314153
199,2025-07-17T13:30:00.869989204Z,2025-07-17T13:30:00.869989204Z,10,2,1108,C,B,0,8.4700,100,0,176115,28963944,11.7599,100,1,15.3000,100,1,11.5199,100,1,15.6099,100,1,11.2899,100,1,15.9100,100,1,11.2400,100,1,15.9800,100,1,11.1400,700,1,16.1000,100,1,11.0700,700,1,16.1099,700,1,11.0500,100,1,16.1499,700,1,11.0099,100,1,16.1999,200,2,10.9900,700,1,16.2199,100,1,10.9299,200,2,16.3000,700,1,ARL,41376345
200,2025-07-17T13:30:00.869989204Z,2025-07-17T13:30:00.869989204Z,10,2,1108,A,B,0,9.5500,100,128,176115,28963944,11.7599,100,1,15.3000,100,1,11.5199,100,1,15.6099,100,1,11.2899,100,1,15.9100,100,1,11.2400,100,1,15.9800,100,1,11.1400,700,1,16.1000,100,1,11.0700,700,1,16.1099,700,1,11.0500,100,1,16.1499,700,1,11.0099,100,1,16.1999,200,2,10.9900,700,1,16.2199,100,1,10.9299,200,2,16.3000,700,1,ARL,43314157
201,2025-07-17T13:30:00.869996105Z,2025-07-17T13:30:00.869996105Z,10,2,1108,C,B,0,8.4700,100,0,178535,28963952,11.7599,100,1,15.3000,100,1,11.5199,100,1,15.6099,100,1,11.2899,100,1,15.9100,100,1,11.2400,100,1,15.9800,100,1,11.1400,700,1,16.1000,100,1,11.0700,700,1,16.1099,700,1,11.0500,100,1,16.1499,700,1,11.0099,100,1,16.1999,200,2,10.9900,700,1,16.2199,100,1,10.9299,200,2,16.3000,700,1,ARL,41376349
202,2025-07-17T13:30:00.869996105Z,2025-07-17T13:30:00.869996105Z,10,2,1108,A,B,0,9.5500,100,0,178535,28963952,11.7599,100,1,15.3000,100,1,11.5199,100,1,15.6099,100,1,11.2899,100,1,15.9100,100,1,11.2400,100,1,15.9800,100,1,11.1400,700,1,16.1000,100,1,11.0700,700,1,16.1099,700,1,11.0500,100,1,16.1499,700,1,11.0099,100,1,16.1999,200,2,10.9900,700,1,16.2199,100,1,10.9299,200,2,16.3000,700,1,ARL,43314161
203,2025-07-17T13:30:00.869996504Z,2025-07-17T13:30:00.869996504Z,10,2,1108,C,B,0,8.4700,100,0,178136,28963953,11.7599,100,1,15.3000,100,1,11.5199,100,1,15.6099,100,1,11.2899,100,1,15.9100,100,1,11.2400,100,1,15.9800,100,1,11.1400,700,1,16.1000,100,1,11.0700,700,1,16.1099,700,1,11.0500,100,1,16.1499,700,1,11.0099,100,1,16.1999,200,2,10.9900,700,1,16.2199,100,1,10.9299,200,2,16.3000,700,1,ARL,41376353
204,2025-07-17T13:30:00.869996504Z,2025-07-17T13:30:00.869996504Z,10,2,1108,A,B,0,9.5500,100,0,178136,28963953,11.7599,100,1,15.3000,100,1,11.5199,100,1,15.6099,100,1,11.2899,100,1,15.9100,100,1,11.2400,100,1,15.9800,100,1,11.1400,700,1,16.1000,100,1,11.0700,700,1,16.1099,700,1,11.0500,100,1,16.1499,700,1,11.0099,100,1,16.1999,200,2,10.9900,700,1,16.2199,100,1,10.9299,200,2,16.3000,700,1,ARL,43314165
205,2025-07-17T13:30:00.869997057Z,2025-07-17T13:30:00.869997057Z,10,2,1108,C,B,0,8.4700,100,0,177583,28963954,11.7599,100,1,15.3000,100,1,11.5199,100,1,15.6099,100,1,11.2899,100,1,15.9100,100,1,11.2400,100,1,15.9800,100,1,11.1400,700,1,16.1000,100,1,11.0700,700,1,16.1099,700,1,11.0500,100,1,16.1499,700,1,11.0099,100,1,16.1999,200,2,10.9900,700,1,16.2199,100,1,10.9299,200,2,16.3000,700,1,ARL,41376357
206,2025-07-17T13:30:00.869997057Z,2025-07-17T13:30:00.869997057Z,10,2,1108,A,B,0,9.5500,100,128,177583,28963954,11.7599,100,1,15.3000,100,1,11.5199,100,1,15.6099,100,1,11.2899,100,1,15.9100,100,1,11.2400,100,1,15.9800,100,1,11.1400,700,1,16.1000,100,1,11.0700,700,1,16.1099,700,1,11.0500,100,1,16.1499,700,1,11.0099,100,1,16.1999,200,2,10.9900,700,1,16.2199,100,1,10.9299,200,2,16.3000,700,1,ARL,43314169
207,2025-07-17T13:30:00.870003387Z,2025-07-17T13:30:00.870003387Z,10,2,1108,C,B,0,8.4700,100,0,176364,28963962,11.7599,100,1,15.3000,100,1,11.5199,100,1,15.6099,100,1,11.2899,100,1,15.9100,100,1,11.2400,100,1,15.9800,100,1,11.1400,700,1,16.1000,100,1,11.0700,700,1,16.1099,700,1,11.0500,100,1,16.1499,700,1,11.0099,100,1,16.1999,200,2,10.9900,700,1,16.2199,100,1,10.9299,200,2,16.3000,700,1,ARL,42202297
208,2025-07-17T13:30:00.870003387Z,2025-07-17T13:30:00.870003387Z,10,2,1108,A,B,0,9.5500,100,0,176364,28963962,11.7599,100,1,15.3000,100,1,11.5199,100,1,15.6099,100,1,11.2899,100,1,15.9100,100,1,11.2400,100,1,15.9800,100,1,11.1400,700,1,16.1000,100,1,11.0700,700,1,16.1099,700,1,11.0500,100,1,16.1499,700,1,11.0099,100,1,16.1999,200,2,10.9900,700,1,16.2199,100,1,10.9299,200,2,16.3000,700,1,ARL,43314173
209,2025-07-17T13:30:00.870004158Z,2025-07-17T13:30:00.870004158Z,10,2,1108,C,B,0,8.4700,100,0,175593,28963963,11.7599,100,1,15.3000,100,1,11.5199,100,1,15.6099,100,1,11.2899,100,1,15.9100,100,1,11.2400,100,1,15.9800,100,1,11.1400,700,1,16.1000,100,1,11.0700,700,1,16.1099,700,1,11.0500,100,1,16.1499,700,1,11.0099,100,1,16.1999,200,2,10.9900,700,1,16.2199,100,1,10.9299,200,2,16.3000,700,1,ARL,42951397
210,2025-07-17T13:30:00.870004158Z,2025-07-17T13:30:00.870004158Z,10,2,1108,A,B,0,9.5500,100,128,175593,28963963,11.7599,100,1,15.3000,100,1,11.5199,100,1,15.6099,100,1,11.2899,100,1,15.9100,100,1,11.2400,100,1,15.9800,100,1,11.1400,700,1,16.1000,100,1,11.0700,700,1,16.1099,700,1,11.0500,100,1,16.1499,700,1,11.0099,100,1,16.1999,200,2,10.9900,700,1,16.2199,100,1,10.9299,200,2,16.3000,700,1,ARL,43314177
211,2025-07-17T13:30:00.870009922Z,2025-07-17T13:30:00.870009922Z,10,2,1108,C,A,0,19.5799,100,0,176506,28963970,11.7599,100,1,15.3000,100,1,11.5199,100,1,15.6099,100,1,11.2899,100,1,15.9100,100,1,11.2400,100,1,15.9800,100,1,11.1400,700,1,16.1000,100,1,11.0700,700,1,16.1099,700,1,11.0500,100,1,16.1499,700,1,11.0099,100,1,16.1999,200,2,10.9900,700,1,16.2199,100,1,10.9299,200,2,16.3000,700,1,ARL,41370945
212,2025-07-17T13:30:00.870009922Z,2025-07-17T13:30:00.870009922Z,10,2,1108,A,A,0,18.3799,100,0,176506,28963970,11.7599,100,1,15.3000,100,1,11.5199,100,1,15.6099,100,1,11.2899,100,1,15.9100,100,1,11.2400,100,1,15.9800,100,1,11.1400,700,1,16.1000,100,1,11.0700,700,1,16.1099,700,1,11.0500,100,1,16.1499,700,1,11.0099,100,1,16.1999,200,2,10.9900,700,1,16.2199,100,1,10.9299,200,2,16.3000,700,1,ARL,43314181
213,2025-07-17T13:30:00.870010386Z,2025-07-17T13:30:00.870010386Z,10,2,1108,C,A,0,19.5799,100,0,176042,28963971,11.7599,100,1,15.3000,100,1,11.5199,100,1,15.6099,100,1,11.2899,100,1,15.9100,100,1,11.2400,100,1,15.9800,100,1,11.1400,700,1,16.1000,100,1,11.0700,700,1,16.1099,700,1,11.0500,100,1,16.1499,700,1,11.0099,100,1,16.1999,200,2,10.9900,700,1,16.2199,100,1,10.9299,200,2,16.3000,700,1,ARL,41370949
214,2025-07-17T13:30:00.870010386Z,2025-07-17T13:30:00.870010386Z,10,2,1108,A,A,0,18.3799,100,128,176042,28963971,11.7599,100,1,15.3000,100,1,11.5199,100,1,15.6099,100,1,11.2899,100,1,15.9100,100,1,11.2400,100,1,15.9800,100,1,11.1400,700,1,16.1000,100,1,11.0700,700,1,16.1099,700,1,11.0500,100,1,16.1499,700,1,11.0099,100,1,16.1999,200,2,10.9900,700,1,16.2199,100,1,10.9299,200,2,16.3000,700,1,ARL,43314185
215,2025-07-17T13:30:00.870017071Z,2025-07-17T13:30:00.870017071Z,10,2,1108,C,A,0,19.5799,100,0,177323,28963981,11.7599,100,1,15.3000,100,1,11.5199,100,1,15.6099,100,1,11.2899,100,1,15.9100,100,1,11.2400,100,1,15.9800,100,1,11.1400,700,1,16.1000,100,1,11.0700,700,1,16.1099,700,1,11.0500,100,1,16.1499,700,1,11.0099,100,1,16.1999,200,2,10.9900,700,1,16.2199,100,1,10.9299,200,2,16.3000,700,1,ARL,41370953
216,2025-07-17T13:30:00.870017071Z,2025-07-17T13:30:00.870017071Z,10,2,1108,A,A,0,18.3799,100,0,177323,28963981,11.7599,100,1,15.3000,100,1,11.5199,100,1,15.6099,100,1,11.2899,100,1,15.9100,100,1,11.2400,100,1,15.9800,100,1,11.1400,700,1,16.1000,100,1,11.0700,700,1,16.1099,700,1,11.0500,100,1,16.1499,700,1,11.0099,100,1,16.1999,200,2,10.9900,700,1,16.2199,100,1,10.9299,200,2,16.3000,700,1,ARL,43314189
217,2025-07-17T13:30:00.870022776Z,2025-07-17T13:30:00.870022776Z,10,2,1108,C,A,0,19.5799,100,0,171618,28963983,11.7599,100,1,15.3000,100,1,11.5199,100,1,15.6099,100,1,11.2899,100,1,15.9100,100,1,11.2400,100,1,15.9800,100,1,11.1400,700,1,16.1000,100,1,11.0700,700,1,16.1099,700,1,11.0500,100,1,16.1499,700,1,11.0099,100,1,16.1999,200,2,10.9900,700,1,16.2199,100,1,10.9299,200,2,16.3000,700,1,ARL,41370957
218,2025-07-17T13:30:00.870022776Z,2025-07-17T13:30:00.870022776Z,10,2,1108,A,A,0,18.3799,100,0,171618,28963983,11.7599,100,1,15.3000,100,1,11.5199,100,1,15.6099,100,1,11.2899,100,1,15.9100,100,1,11.2400,100,1,15.9800,100,1,11.1400,700,1,16.1000,100,1,11.0700,700,1,16.1099,700,1,11.0500,100,1,16.1499,700,1,11.0099,100,1,16.1999,200,2,10.9900,700,1,16.2199,100,1,10.9299,200,2,16.3000,700,1,ARL,43314233
219,2025-07-17T13:30:00.870023199Z,2025-07-17T13:30:00.870023199Z,10,2,1108,C,A,0,19.5799,100,0,171195,28963984,11.7599,100,1,15.3000,100,1,11.5199,100,1,15.6099,100,1,11.2899,100,1,15.9100,100,1,11.2400,100,1,15.9800,100,1,11.1400,700,1,16.1000,100,1,11.0700,700,1,16.1099,700,1,11.0500,100,1,16.1499,700,1,11.0099,100,1,16.1999,200,2,10.9900,700,1,16.2199,100,1,10.9299,200,2,16.3000,700,1,ARL,41370961
220,2025-07-17T13:30:00.870023199Z,2025-07-17T13:30:00.870023199Z,10,2,1108,A,A,0,18.3799,100,0,171195,28963984,11.7599,100,1,15.3000,100,1,11.5199,100,1,15.6099,100,1,11.2899,100,1,15.9100,100,1,11.2400,100,1,15.9800,100,1,11.1400,700,1,16.1000,100,1,11.0700,700,1,16.1099,700,1,11.0500,100,1,16.1499,700,1,11.0099,100,1,16.1999,200,2,10.9900,700,1,16.2199,100,1,10.9299,200,2,16.3000,700,1,ARL,43314237
221,2025-07-17T13:30:00.870023701Z,2025-07-17T13:30:00.870023701Z,10,2,1108,C,A,0,19.5799,100,0,170693,28963985,11.7599,100,1,15.3000,100,1,11.5199,100,1,15.6099,100,1,11.2899,100,1,15.9100,100,1,11.2400,100,1,15.9800,100,1,11.1400,700,1,16.1000,100,1,11.0700,700,1,16.1099,700,1,11.0500,100,1,16.1499,700,1,11.0099,100,1,16.1999,200,2,10.9900,700,1,16.2199,100,1,10.9299,200,2,16.3000,700,1,ARL,41370965
222,2025-07-17T13:30:00.870023701Z,2025-07-17T13:30:00.870023701Z,10,2,1108,A,A,0,18.3799,100,130,170693,28963985,11.7599,100,1,15.3000,100,1,11.5199,100,1,15.6099,100,1,11.2899,100,1,15.9100,100,1,11.2400,100,1,15.9800,100,1,11.1400,700,1,16.1000,100,1,11.0700,700,1,16.1099,700,1,11.0500,100,1,16.1499,700,1,11.0099,100,1,16.1999,200,2,10.9900,700,1,16.2199,100,1,10.9299,200,2,16.3000,700,1,ARL,43314241
223,2025-07-17T13:30:00.870053023Z,2025-07-17T13:30:00.870053023Z,10,2,1108,C,A,0,19.5799,100,0,176378,28964015,11.7599,100,1,15.3000,100,1,11.5199,100,1,15.6099,100,1,11.2899,100,1,15.9100,100,1,11.2400,100,1,15.9800,100,1,11.1400,700,1,16.1000,100,1,11.0700,700,1,16.1099,700,1,11.0500,100,1,16.1499,700,1,11.0099,100,1,16.1999,200,2,10.9900,700,1,16.2199,100,1,10.9299,200,2,16.3000,700,1,ARL,41370969
224,2025-07-17T13:30:00.870053023Z,2025-07-17T13:30:00.870053023Z,10,2,1108,A,A,0,18.3799,100,0,176378,28964015,11.7599,100,1,15.3000,100,1,11.5199,100,1,15.6099,100,1,11.2899,100,1,15.9100,100,1,11.2400,100,1,15.9800,100,1,11.1400,700,1,16.1000,100,1,11.0700,700,1,16.1099,700,1,11.0500,100,1,16.1499,700,1,11.0099,100,1,16.1999,200,2,10.9900,700,1,16.2199,100,1,10.9299,200,2,16.3000,700,1,ARL,43314245
225,2025-07-17T13:30:00.870053791Z,2025-07-17T13:30:00.870053791Z,10,2,1108,C,A,0,19.5799,100,0,175610,28964016,11.7599,100,1,15.3000,100,1,11.5199,100,1,15.6099,100,1,11.2899,100,1,15.9100,100,1,11.2400,100,1,15.9800,100,1,11.1400,700,1,16.1000,100,1,11.0700,700,1,16.1099,700,1,11.0500,100,1,16.1499,700,1,11.0099,100,1,16.1999,200,2,10.9900,700,1,16.2199,100,1,10.9299,200,2,16.3000,700,1,ARL,42204681
226,2025-07-17T13:30:00.870053791Z,2025-07-17T13:30:00.870053791Z,10,2,1108,A,A,0,18.3799,100,0,175610,28964016,11.7599,100,1,15.3000,100,1,11.5199,100,1,15.6099,100,1,11.2899,100,1,15.9100,100,1,11.2400,100,1,15.9800,100,1,11.1400,700,1,16.1000,100,1,11.0700,700,1,16.1099,700,1,11.0500,100,1,16.1499,700,1,11.0099,100,1,16.1999,200,2,10.9900,700,1,16.2199,100,1,10.9299,200,2,16.3000,700,1,ARL,43314253
227,2025-07-17T13:30:00.870054073Z,2025-07-17T13:30:00.870054073Z,10,2,1108,C,A,0,19.5799,100,0,175328,28964017,11.7599,100,1,15.3000,100,1,11.5199,100,1,15.6099,100,1,11.2899,100,1,15.9100,100,1,11.2400,100,1,15.9800,100,1,11.1400,700,1,16.1000,100,1,11.0700,700,1,16.1099,700,1,11.0500,100,1,16.1499,700,1,11.0099,100,1,16.1999,200,2,10.9900,700,1,16.2199,100,1,10.9299,200,2,16.3000,700,1,ARL,42946053
228,2025-07-17T13:30:00.870054073Z,2025-07-17T13:30:00.870054073Z,10,2,1108,A,A,0,18.3799,100,128,175328,28964017,11.7599,100,1,15.3000,100,1,11.5199,100,1,15.6099,100,1,11.2899,100,1,15.9100,100,1,11.2400,100,1,15.9800,100,1,11.1400,700,1,16.1000,100,1,11.0700,700,1,16.1099,700,1,11.0500,100,1,16.1499,700,1,11.0099,100,1,16.1999,200,2,10.9900,700,1,16.2199,100,1,10.9299,200,2,16.3000,700,1,ARL,43314257
229,2025-07-17T13:30:00.870063003Z,2025-07-17T13:30:00.870063003Z,10,2,1108,C,A,0,18.3599,100,0,173143,28964020,11.7599,100,1,15.3000,100,1,11.5199,100,1,15.6099,100,1,11.2899,100,1,15.9100,100,1,11.2400,100,1,15.9800,100,1,11.1400,700,1,16.1000,100,1,11.0700,700,1,16.1099,700,1,11.0500,100,1,16.1499,700,1,11.0099,100,1,16.1999,200,2,10.9900,700,1,16.2199,100,1,10.9299,200,2,16.3000,700,1,ARL,43313633
230,2025-07-17T13:30:00.870063920Z,2025-07-17T13:30:00.870063920Z,10,2,1108,C,B,0,9.4100,100,128,172226,28964021,11.7599,100,1,15.3000,100,1,11.5199,100,1,15.6099,100,1,11.2899,100,1,15.9100,100,1,11.2400,100,1,15.9800,100,1,11.1400,700,1,16.1000,100,1,11.0700,700,1,16.1099,700,1,11.0500,100,1,16.1499,700,1,11.0099,100,1,16.1999,200,2,10.9900,700,1,16.2199,100,1,10.9299,200,2,16.3000,700,1,ARL,43313681
231,2025-07-17T13:30:00.870151543Z,2025-07-17T13:30:00.870151543Z,10,2,1108,A,B,0,10.6099,100,128,167854,28964128,11.7599,100,1,15.3000,100,1,11.5199,100,1,15.6099,100,1,11.2899,100,1,15.9100,100,1,11.2400,100,1,15.9800,100,1,11.1400,700,1,16.1000,100,1,11.0700,700,1,16.1099,700,1,11.0500,100,1,16.1499,700,1,11.0099,100,1,16.1999,200,2,10.9900,700,1,16.2199,100,1,10.9299,200,2,16.3000,700,1,ARL,43314465
232,2025-07-17T13:30:00.870209113Z,2025-07-17T13:30:00.870209113Z,10,2,1108,A,A,0,17.2300,100,128,181115,28964207,11.7599,100,1,15.3000,100,1,11.5199,100,1,15.6099,100,1,11.2899,100,1,15.9100,100,1,11.2400,100,1,15.9800,100,1,11.1400,700,1,16.1000,100,1,11.0700,700,1,16.1099,700,1,11.0500,100,1,16.1499,700,1,11.0099,100,1,16.1999,200,2,10.9900,700,1,16.2199,100,1,10.9299,200,2,16.3000,700,1,ARL,43314561
233,2025-07-17T13:30:00.870273955Z,2025-07-17T13:30:00.870273955Z,10,2,1108,C,B,0,11.2400,100,0,178095,28964259,11.7599,100,1,15.3000,100,1,11.5199,100,1,15.6099,100,1,11.2899,100,1,15.9100,100,1,11.1400,700,1,15.9800,100,1,11.0700,700,1,16.1000,100,1,11.0500,100,1,16.1099,700,1,11.0099,100,1,16.1499,700,1,10.9900,700,1,16.1999,200,2,10.9299,200,2,16.2199,100,1,10.9199,200,2,16.3000,700,1,ARL,43313941
234,2025-07-17T13:30:00.870278857Z,2025-07-17T13:30:00.870278857Z,10,2,1108,C,A,0,15.9800,100,128,173193,28964260,11.7599,100,1,15.3000,100,1,11.5199,100,1,15.6099,100,1,11.2899,100,1,15.9100,100,1,11.1400,700,1,16.1000,100,1,11.0700,700,1,16.1099,700,1,11.0500,100,1,16.1499,700,1,11.0099,100,1,16.1999,200,2,10.9900,700,1,16.2199,100,1,10.9299,200,2,16.3000,700,1,10.9199,200,2,16.3799,200,2,ARL,43314009
235,2025-07-17T13:30:00.870579856Z,2025-07-17T13:30:00.870579856Z,10,2,1108,C,B,0,9.4100,100,0,169065,28964629,11.7599,100,1,15.3000,100,1,11.5199,100,1,15.6099,100,1,11.2899,100,1,15.9100,100,1,11.1400,700,1,16.1000,100,1,11.0700,700,1,16.1099,700,1,11.0500,100,1,16.1499,700,1,11.0099,100,1,16.1999,200,2,10.9900,700,1,16.2199,100,1,10.9299,200,2,16.3000,700,1,10.9199,200,2,16.3799,200,2,ARL,43313553
236,2025-07-17T13:30:00.870580243Z,2025-07-17T13:30:00.870580243Z,10,2,1108,C,A,0,18.3599,100,128,168678,28964630,11.7599,100,1,15.3000,100,1,11.5199,100,1,15.6099,100,1,11.2899,100,1,15.9100,100,1,11.1400,700,1,16.1000,100,1,11.0700,700,1,16.1099,700,1,11.0500,100,1,16.1499,700,1,11.0099,100,1,16.1999,200,2,10.9900,700,1,16.2199,100,1,10.9299,200,2,16.3000,700,1,10.9199,200,2,16.3799,200,2,ARL,43313565
237,2025-07-17T13:30:00.870848973Z,2025-07-17T13:30:00.870848973Z,10,2,1108,A,B,0,11.4000,100,128,175937,28964903,11.7599,100,1,15.3000,100,1,11.5199,100,1,15.6099,100,1,11.4000,100,1,15.9100,100,1,11.2899,100,1,16.1000,100,1,11.1400,700,1,16.1099,700,1,11.0700,700,1,16.1499,700,1,11.0500,100,1,16.1999,200,2,11.0099,100,1,16.2199,100,1,10.9900,700,1,16.3000,700,1,10.9299,200,2,16.3799,200,2,ARL,43315905
238,2025-07-17T13:30:00.870874152Z,2025-07-17T13:30:00.870874152Z,10,2,1108,C,B,0,10.1099,100,128,173195,28964931,11.7599,100,1,15.3000,100,1,11.5199,100,1,15.6099,100,1,11.4000,100,1,15.9100,100,1,11.2899,100,1,16.1000,100,1,11.1400,700,1,16.1099,700,1,11.0700,700,1,16.1499,700,1,11.0500,100,1,16.1999,200,2,11.0099,100,1,16.2199,100,1,10.9900,700,1,16.3000,700,1,10.9299,200,2,16.3799,200,2,ARL,42583289
239,2025-07-17T13:30:00.871359085Z,2025-07-17T13:30:00.871359085Z,10,2,1108,A,A,0,16.3799,100,128,176400,28965402,11.7599,100,1,15.3000,100,1,11.5199,100,1,15.6099,100,1,11.4000,100,1,15.9100,100,1,11.2899,100,1,16.1000,100,1,11.1400,700,1,16.1099,700,1,11.0700,700,1,16.1499,700,1,11.0500,100,1,16.1999,200,2,11.0099,100,1,16.2199,100,1,10.9900,700,1,16.3000,700,1,10.9299,200,2,16.3799,300,3,ARL,43317137
240,2025-07-17T13:30:00.871371794Z,2025-07-17T13:30:00.871371794Z,10,2,1108,A,B,0,10.6099,100,128,172541,28965409,11.7599,100,1,15.3000,100,1,11.5199,100,1,15.6099,100,1,11.4000,100,1,15.9100,100,1,11.2899,100,1,16.1000,100,1,11.1400,700,1,16.1099,700,1,11.0700,700,1,16.1499,700,1,11.0500,100,1,16.1999,200,2,11.0099,100,1,16.2199,100,1,10.9900,700,1,16.3000,700,1,10.9299,200,2,16.3799,300,3,ARL,43317177
241,2025-07-17T13:30:00.871379595Z,2025-07-17T13:30:00.871379595Z,10,2,1108,A,A,0,17.2300,100,0,172422,28965416,11.7599,100,1,15.3000,100,1,11.5199,100,1,15.6099,100,1,11.4000,100,1,15.9100,100,1,11.2899,100,1,16.1000,100,1,11.1400,700,1,16.1099,700,1,11.0700,700,1,16.1499,700,1,11.0500,100,1,16.1999,200,2,11.0099,100,1,16.2199,100,1,10.9900,700,1,16.3000,700,1,10.9299,200,2,16.3799,300,3,ARL,43317185
242,2025-07-17T13:30:00.871381021Z,2025-07-17T13:30:00.871381021Z,10,2,1108,C,A,0,17.4499,100,128,170996,28965418,11.7599,100,1,15.3000,100,1,11.5199,100,1,15.6099,100,1,11.4000,100,1,15.9100,100,1,11.2899,100,1,16.1000,100,1,11.1400,700,1,16.1099,700,1,11.0700,700,1,16.1499,700,1,11.0500,100,1,16.1999,200,2,11.0099,100,1,16.2199,100,1,10.9900,700,1,16.3000,700,1,10.9299,200,2,16.3799,300,3,ARL,42583293
243,2025-07-17T13:30:00.871520352Z,2025-07-17T13:30:00.871520352Z,10,2,1108,C,B,0,10.8399,100,0,180652,28965571,11.7599,100,1,15.3000,100,1,11.5199,100,1,15.6099,100,1,11.4000,100,1,15.9100,100,1,11.2899,100,1,16.1000,100,1,11.1400,700,1,16.1099,700,1,11.0700,700,1,16.1499,700,1,11.0500,100,1,16.1999,200,2,11.0099,100,1,16.2199,100,1,10.9900,700,1,16.3000,700,1,10.9299,200,2,16.3799,300,3,ARL,41635065
244,2025-07-17T13:30:00.871520352Z,2025-07-17T13:30:00.871520352Z,10,2,1108,A,B,0,12.2300,100,128,180652,28965571,12.2300,100,1,15.3000,100,1,11.7599,100,1,15.6099,100,1,11.5199,100,1,15.9100,100,1,11.4000,100,1,16.1000,100,1,11.2899,100,1,16.1099,700,1,11.1400,700,1,16.1499,700,1,11.0700,700,1,16.1999,200,2,11.0500,100,1,16.2199,100,1,11.0099,100,1,16.3000,700,1,10.9900,700,1,16.3799,300,3,ARL,43317473
245,2025-07-17T13:30:00.871548318Z,2025-07-17T13:30:00.871548318Z,10,2,1108,C,A,0,16.4899,100,0,174965,28965592,12.2300,100,1,15.3000,100,1,11.7599,100,1,15.6099,100,1,11.5199,100,1,15.9100,100,1,11.4000,100,1,16.1000,100,1,11.2899,100,1,16.1099,700,1,11.1400,700,1,16.1499,700,1,11.0700,700,1,16.1999,200,2,11.0500,100,1,16.2199,100,1,11.0099,100,1,16.3000,700,1,10.9900,700,1,16.3799,300,3,ARL,41635069
246,2025-07-17T13:30:00.871548318Z,2025-07-17T13:30:00.871548318Z,10,2,1108,A,A,0,15.4700,100,128,174965,28965592,12.2300,100,1,15.3000,100,1,11.7599,100,1,15.4700,100,1,11.5199,100,1,15.6099,100,1,11.4000,100,1,15.9100,100,1,11.2899,100,1,16.1000,100,1,11.1400,700,1,16.1099,700,1,11.0700,700,1,16.1499,700,1,11.0500,100,1,16.1999,200,2,11.0099,100,1,16.2199,100,1,10.9900,700,1,16.3000,700,1,ARL,43317561
247,2025-07-17T13:30:00.911486897Z,2025-07-17T13:30:00.911486897Z,10,2,1108,A,B,0,11.6899,2,128,224530,28973032,12.2300,100,1,15.3000,100,1,11.7599,100,1,15.4700,100,1,11.6899,2,1,15.6099,100,1,11.5199,100,1,15.9100,100,1,11.4000,100,1,16.1000,100,1,11.2899,100,1,16.1099,700,1,11.1400,700,1,16.1499,700,1,11.0700,700,1,16.1999,200,2,11.0500,100,1,16.2199,100,1,11.0099,100,1,16.3000,700,1,ARL,43324133
248,2025-07-17T13:30:00.914351054Z,2025-07-17T13:30:00.914351054Z,10,2,1108,A,A,0,15.3100,2,128,177681,28975648,12.2300,100,1,15.3000,100,1,11.7599,100,1,15.3100,2,1,11.6899,2,1,15.4700,100,1,11.5199,100,1,15.6099,100,1,11.4000,100,1,15.9100,100,1,11.2899,100,1,16.1000,100,1,11.1400,700,1,16.1099,700,1,11.0700,700,1,16.1499,700,1,11.0500,100,1,16.1999,200,2,11.0099,100,1,16.2199,100,1,ARL,43328313
249,2025-07-17T13:30:00.915197739Z,2025-07-17T13:30:00.915197739Z,10,2,1108,C,B,0,10.5800,100,0,174269,28976307,12.2300,100,1,15.3000,100,1,11.7599,100,1,15.3100,2,1,11.6899,2,1,15.4700,100,1,11.5199,100,1,15.6099,100,1,11.4000,100,1,15.9100,100,1,11.2899,100,1,16.1000,100,1,11.1400,700,1,16.1099,700,1,11.0700,700,1,16.1499,700,1,11.0500,100,1,16.1999,200,2,11.0099,100,1,16.2199,100,1,ARL,41376725
250,2025-07-17T13:30:00.915197739Z,2025-07-17T13:30:00.915197739Z,10,2,1108,A,B,0,11.9299,100,130,174269,28976307,12.2300,100,1,15.3000,100,1,11.9299,100,1,15.3100,2,1,11.7599,100,1,15.4700,100,1,11.6899,2,1,15.6099,100,1,11.5199,100,1,15.9100,100,1,11.4000,100,1,16.1000,100,1,11.2899,100,1,16.1099,700,1,11.1400,700,1,16.1499,700,1,11.0700,700,1,16.1999,200,2,11.0500,100,1,16.2199,100,1,ARL,43329953
251,2025-07-17T13:30:00.916332252Z,2025-07-17T13:30:00.916332252Z,10,2,1108,C,A,0,16.8299,100,0,175728,28977103,12.2300,100,1,15.3000,100,1,11.9299,100,1,15.3100,2,1,11.7599,100,1,15.4700,100,1,11.6899,2,1,15.6099,100,1,11.5199,100,1,15.9100,100,1,11.4000,100,1,16.1000,100,1,11.2899,100,1,16.1099,700,1,11.1400,700,1,16.1499,700,1,11.0700,700,1,16.1999,200,2,11.0500,100,1,16.2199,100,1,ARL,41372125
252,2025-07-17T13:30:00.916332252Z,2025-07-17T13:30:00.916332252Z,10,2,1108,A,A,0,15.8000,100,128,175728,28977103,12.2300,100,1,15.3000,100,1,11.9299,100,1,15.3100,2,1,11.7599,100,1,15.4700,100,1,11.6899,2,1,15.6099,100,1,11.5199,100,1,15.8000,100,1,11.4000,100,1,15.9100,100,1,11.2899,100,1,16.1000,100,1,11.1400,700,1,16.1099,700,1,11.0700,700,1,16.1499,700,1,11.0500,100,1,16.1999,200,2,ARL,43331877
253,2025-07-17T13:30:00.920144110Z,2025-07-17T13:30:00.920144110Z,10,2,1108,C,A,0,18.3799,100,0,175435,28979475,12.2300,100,1,15.3000,100,1,11.9299,100,1,15.3100,2,1,11.7599,100,1,15.4700,100,1,11.6899,2,1,15.6099,100,1,11.5199,100,1,15.8000,100,1,11.4000,100,1,15.9100,100,1,11.2899,100,1,16.1000,100,1,11.1400,700,1,16.1099,700,1,11.0700,700,1,16.1499,700,1,11.0500,100,1,16.1999,200,2,ARL,43314181
254,2025-07-17T13:30:00.920144110Z,2025-07-17T13:30:00.920144110Z,10,2,1108,A,A,0,17.1499,100,0,175435,28979475,12.2300,100,1,15.3000,100,1,11.9299,100,1,15.3100,2,1,11.7599,100,1,15.4700,100,1,11.6899,2,1,15.6099,100,1,11.5199,100,1,15.8000,100,1,11.4000,100,1,15.9100,100,1,11.2899,100,1,16.1000,100,1,11.1400,700,1,16.1099,700,1,11.0700,700,1,16.1499,700,1,11.0500,100,1,16.1999,200,2,ARL,43339133
255,2025-07-17T13:30:00.920147410Z,2025-07-17T13:30:00.920147410Z,10,2,1108,C,A,0,18.3799,100,0,172135,28979478,12.2300,100,1,15.3000,100,1,11.9299,100,1,15.3100,2,1,11.7599,100,1,15.4700,100,1,11.6899,2,1,15.6099,100,1,11.5199,100,1,15.8000,100,1,11.4000,100,1,15.9100,100,1,11.2899,100,1,16.1000,100,1,11.1400,700,1,16.1099,700,1,11.0700,700,1,16.1499,700,1,11.0500,100,1,16.1999,200,2,ARL,43314185
256,2025-07-17T13:30:00.920147410Z,2025-07-17T13:30:00.920147410Z,10,2,1108,A,A,0,17.1499,100,130,172135,28979478,12.2300,100,1,15.3000,100,1,11.9299,100,1,15.3100,2,1,11.7599,100,1,15.4700,100,1,11.6899,2,1,15.6099,100,1,11.5199,100,1,15.8000,100,1,11.4000,100,1,15.9100,100,1,11.2899,100,1,16.1000,100,1,11.1400,700,1,16.1099,700,1,11.0700,700,1,16.1499,700,1,11.0500,100,1,16.1999,200,2,ARL,43339165
257,2025-07-17T13:30:00.920208398Z,2025-07-17T13:30:00.920208398Z,10,2,1108,C,A,0,18.3799,100,0,171843,28979515,12.2300,100,1,15.3000,100,1,11.9299,100,1,15.3100,2,1,11.7599,100,1,15.4700,100,1,11.6899,2,1,15.6099,100,1,11.5199,100,1,15.8000,100,1,11.4000,100,1,15.9100,100,1,11.2899,100,1,16.1000,100,1,11.1400,700,1,16.1099,700,1,11.0700,700,1,16.1499,700,1,11.0500,100,1,16.1999,200,2,ARL,43314189
258,2025-07-17T13:30:00.920208398Z,2025-07-17T13:30:00.920208398Z,10,2,1108,A,A,0,17.1499,100,0,171843,28979515,12.2300,100,1,15.3000,100,1,11.9299,100,1,15.3100,2,1,11.7599,100,1,15.4700,100,1,11.6899,2,1,15.6099,100,1,11.5199,100,1,15.8000,100,1,11.4000,100,1,15.9100,100,1,11.2899,100,1,16.1000,100,1,11.1400,700,1,16.1099,700,1,11.0700,700,1,16.1499,700,1,11.0500,100,1,16.1999,200,2,ARL,43339333
259,2025-07-17T13:30:00.920208920Z,2025-07-17T13:30:00.920208920Z,10,2,1108,C,A,0,18.3799,100,0,171321,28979516,12.2300,100,1,15.3000,100,1,11.9299,100,1,15.3100,2,1,11.7599,100,1,15.4700,100,1,11.6899,2,1,15.6099,100,1,11.5199,100,1,15.8000,100,1,11.4000,100,1,15.9100,100,1,11.2899,100,1,16.1000,100,1,11.1400,700,1,16.1099,700,1,11.0700,700,1,16.1499,700,1,11.0500,100,1,16.1999,200,2,ARL,43314233
260,2025-07-17T13:30:00.920208920Z,2025-07-17T13:30:00.920208920Z,10,2,1108,A,A,0,17.1499,100,130,171321,28979516,12.2300,100,1,15.3000,100,1,11.9299,100,1,15.3100,2,1,11.7599,100,1,15.4700,100,1,11.6899,2,1,15.6099,100,1,11.5199,100,1,15.8000,100,1,11.4000,100,1,15.9100,100,1,11.2899,100,1,16.1000,100,1,11.1400,700,1,16.1099,700,1,11.0700,700,1,16.1499,700,1,11.0500,100,1,16.1999,200,2,ARL,43339337
261,2025-07-17T13:30:00.920209286Z,2025-07-17T13:30:00.920209286Z,10,2,1108,C,A,0,18.3799,100,0,180719,28979517,12.2300,100,1,15.3000,100,1,11.9299,100,1,15.3100,2,1,11.7599,100,1,15.4700,100,1,11.6899,2,1,15.6099,100,1,11.5199,100,1,15.8000,100,1,11.4000,100,1,15.9100,100,1,11.2899,100,1,16.1000,100,1,11.1400,700,1,16.1099,700,1,11.0700,700,1,16.1499,700,1,11.0500,100,1,16.1999,200,2,ARL,43314237
262,2025-07-17T13:30:00.920209286Z,2025-07-17T13:30:00.920209286Z,10,2,1108,A,A,0,17.1499,100,0,180719,28979517,12.2300,100,1,15.3000,100,1,11.9299,100,1,15.3100,2,1,11.7599,100,1,15.4700,100,1,11.6899,2,1,15.6099,100,1,11.5199,100,1,15.8000,100,1,11.4000,100,1,15.9100,100,1,11.2899,100,1,16.1000,100,1,11.1400,700,1,16.1099,700,1,11.0700,700,1,16.1499,700,1,11.0500,100,1,16.1999,200,2,ARL,43339341
263,2025-07-17T13:30:00.920216613Z,2025-07-17T13:30:00.920216613Z,10,2,1108,C,A,0,18.3799,100,0,173392,28979521,12.2300,100,1,15.3000,100,1,11.9299,100,1,15.3100,2,1,11.7599,100,1,15.4700,100,1,11.6899,2,1,15.6099,100,1,11.5199,100,1,15.8000,100,1,11.4000,100,1,15.9100,100,1,11.2899,100,1,16.1000,100,1,11.1400,700,1,16.1099,700,1,11.0700,700,1,16.1499,700,1,11.0500,100,1,16.1999,200,2,ARL,43314241
264,2025-07-17T13:30:00.920216613Z,2025-07-17T13:30:00.920216613Z,10,2,1108,A,A,0,17.1499,100,0,173392,28979521,12.2300,100,1,15.3000,100,1,11.9299,100,1,15.3100,2,1,11.7599,100,1,15.4700,100,1,11.6899,2,1,15.6099,100,1,11.5199,100,1,15.8000,100,1,11.4000,100,1,15.9100,100,1,11.2899,100,1,16.1000,100,1,11.1400,700,1,16.1099,700,1,11.0700,700,1,16.1499,700,1,11.0500,100,1,16.1999,200,2,ARL,43339377
265,2025-07-17T13:30:00.920217193Z,2025-07-17T13:30:00.920217193Z,10,2,1108,C,A,0,18.3799,100,0,172812,28979522,12.2300,100,1,15.3000,100,1,11.9299,100,1,15.3100,2,1,11.7599,100,1,15.4700,100,1,11.6899,2,1,15.6099,100,1,11.5199,100,1,15.8000,100,1,11.4000,100,1,15.9100,100,1,11.2899,100,1,16.1000,100,1,11.1400,700,1,16.1099,700,1,11.0700,700,1,16.1499,700,1,11.0500,100,1,16.1999,200,2,ARL,43314245
266,2025-07-17T13:30:00.920217193Z,2025-07-17T13:30:00.920217193Z,10,2,1108,A,A,0,17.1499,100,0,172812,28979522,12.2300,100,1,15.3000,100,1,11.9299,100,1,15.3100,2,1,11.7599,100,1,15.4700,100,1,11.6899,2,1,15.6099,100,1,11.5199,100,1,15.8000,100,1,11.4000,100,1,15.9100,100,1,11.2899,100,1,16.1000,100,1,11.1400,700,1,16.1099,700,1,11.0700,700,1,16.1499,700,1,11.0500,100,1,16.1999,200,2,ARL,43339381
267,2025-07-17T13:30:00.920217632Z,2025-07-17T13:30:00.920217632Z,10,2,1108,C,A,0,18.3799,100,0,172373,28979523,12.2300,100,1,15.3000,100,1,11.9299,100,1,15.3100,2,1,11.7599,100,1,15.4700,100,1,11.6899,2,1,15.6099,100,1,11.5199,100,1,15.8000,100,1,11.4000,100,1,15.9100,100,1,11.2899,100,1,16.1000,100,1,11.1400,700,1,16.1099,700,1,11.0700,700,1,16.1499,700,1,11.0500,100,1,16.1999,200,2,ARL,43314253
268,2025-07-17T13:30:00.920217632Z,2025-07-17T13:30:00.920217632Z,10,2,1108,A,A,0,17.1499,100,130,172373,28979523,12.2300,100,1,15.3000,100,1,11.9299,100,1,15.3100,2,1,11.7599,100,1,15.4700,100,1,11.6899,2,1,15.6099,100,1,11.5199,100,1,15.8000,100,1,11.4000,100,1,15.9100,100,1,11.2899,100,1,16.1000,100,1,11.1400,700,1,16.1099,700,1,11.0700,700,1,16.1499,700,1,11.0500,100,1,16.1999,200,2,ARL,43339385
269,2025-07-17T13:30:00.920351772Z,2025-07-17T13:30:00.920351772Z,10,2,1108,C,A,0,18.3799,100,0,178333,28979649,12.2300,100,1,15.3000,100,1,11.9299,100,1,15.3100,2,1,11.7599,100,1,15.4700,100,1,11.6899,2,1,15.6099,100,1,11.5199,100,1,15.8000,100,1,11.4000,100,1,15.9100,100,1,11.2899,100,1,16.1000,100,1,11.1400,700,1,16.1099,700,1,11.0700,700,1,16.1499,700,1,11.0500,100,1,16.1999,200,2,ARL,43314257
270,2025-07-17T13:30:00.920351772Z,2025-07-17T13:30:00.920351772Z,10,2,1108,A,A,0,17.1499,100,128,178333,28979649,12.2300,100,1,15.3000,100,1,11.9299,100,1,15.3100,2,1,11.7599,100,1,15.4700,100,1,11.6899,2,1,15.6099,100,1,11.5199,100,1,15.8000,100,1,11.4000,100,1,15.9100,100,1,11.2899,100,1,16.1000,100,1,11.1400,700,1,16.1099,700,1,11.0700,700,1,16.1499,700,1,11.0500,100,1,16.1999,200,2,ARL,43339565
271,2025-07-17T13:30:00.931432717Z,2025-07-17T13:30:00.931432717Z,10,2,1108,C,A,0,15.8000,100,0,172973,28991138,12.2300,100,1,15.3000,100,1,11.9299,100,1,15.3100,2,1,11.7599,100,1,15.4700,100,1,11.6899,2,1,15.6099,100,1,11.5199,100,1,15.9100,100,1,11.4000,100,1,16.1000,100,1,11.2899,100,1,16.1099,700,1,11.1400,700,1,16.1499,700,1,11.0700,700,1,16.1999,200,2,11.0500,100,1,16.2199,100,1,ARL,43331877
272,2025-07-17T13:30:00.931432717Z,2025-07-17T13:30:00.931432717Z,10,2,1108,A,A,0,14.7400,100,128,172973,28991138,12.2300,100,1,14.7400,100,1,11.9299,100,1,15.3000,100,1,11.7599,100,1,15.3100,2,1,11.6899,2,1,15.4700,100,1,11.5199,100,1,15.6099,100,1,11.4000,100,1,15.9100,100,1,11.2899,100,1,16.1000,100,1,11.1400,700,1,16.1099,700,1,11.0700,700,1,16.1499,700,1,11.0500,100,1,16.1999,200,2,ARL,43357029
273,2025-07-17T13:30:00.940916945Z,2025-07-17T13:30:00.940916945Z,10,2,1108,C,A,0,15.4700,100,0,165656,29000554,12.2300,100,1,14.7400,100,1,11.9299,100,1,15.3000,100,1,11.7599,100,1,15.3100,2,1,11.6899,2,1,15.6099,100,1,11.5199,100,1,15.9100,100,1,11.4000,100,1,16.1000,100,1,11.2899,100,1,16.1099,700,1,11.1400,700,1,16.1499,700,1,11.0700,700,1,16.1999,200,2,11.0500,100,1,16.2199,100,1,ARL,43317561
274,2025-07-17T13:30:00.940916945Z,2025-07-17T13:30:00.940916945Z,10,2,1108,A,A,0,14.4399,100,130,165656,29000554,12.2300,100,1,14.4399,100,1,11.9299,100,1,14.7400,100,1,11.7599,100,1,15.3000,100,1,11.6899,2,1,15.3100,2,1,11.5199,100,1,15.6099,100,1,11.4000,100,1,15.9100,100,1,11.2899,100,1,16.1000,100,1,11.1400,700,1,16.1099,700,1,11.0700,700,1,16.1499,700,1,11.0500,100,1,16.1999,200,2,ARL,43373009
275,2025-07-17T13:30:00.941071231Z,2025-07-17T13:30:00.941071231Z,10,2,1108,A,A,0,15.2799,100,130,165631,29000677,12.2300,100,1,14.4399,100,1,11.9299,100,1,14.7400,100,1,11.7599,100,1,15.2799,100,1,11.6899,2,1,15.3000,100,1,11.5199,100,1,15.3100,2,1,11.4000,100,1,15.6099,100,1,11.2899,100,1,15.9100,100,1,11.1400,700,1,16.1000,100,1,11.0700,700,1,16.1099,700,1,11.0500,100,1,16.1499,700,1,ARL,43373085
276,2025-07-17T13:30:00.941085073Z,2025-07-17T13:30:00.941085073Z,10,2,1108,C,A,0,16.3799,100,128,170084,29000688,12.2300,100,1,14.4399,100,1,11.9299,100,1,14.7400,100,1,11.7599,100,1,15.2799,100,1,11.6899,2,1,15.3000,100,1,11.5199,100,1,15.3100,2,1,11.4000,100,1,15.6099,100,1,11.2899,100,1,15.9100,100,1,11.1400,700,1,16.1000,100,1,11.0700,700,1,16.1099,700,1,11.0500,100,1,16.1499,700,1,ARL,43317137
277,2025-07-17T13:30:01.086438727Z,2025-07-17T13:30:01.086438727Z,10,2,1108,C,B,0,11.0099,100,0,167223,29116818,12.2300,100,1,14.4399,100,1,11.9299,100,1,14.7400,100,1,11.7599,100,1,15.2799,100,1,11.6899,2,1,15.3000,100,1,11.5199,100,1,15.3100,2,1,11.4000,100,1,15.6099,100,1,11.2899,100,1,15.9100,100,1,11.1400,700,1,16.1000,100,1,11.0700,700,1,16.1099,700,1,11.0500,100,1,16.1499,700,1,ARL,42674817
278,2025-07-17T13:30:01.086438727Z,2025-07-17T13:30:01.086438727Z,10,2,1108,A,B,0,12.4700,100,130,167223,29116818,12.4700,100,1,14.4399,100,1,12.2300,100,1,14.7400,100,1,11.9299,100,1,15.2799,100,1,11.7599,100,1,15.3000,100,1,11.6899,2,1,15.3100,2,1,11.5199,100,1,15.6099,100,1,11.4000,100,1,15.9100,100,1,11.2899,100,1,16.1000,100,1,11.1400,700,1,16.1099,700,1,11.0700,700,1,16.1499,700,1,ARL,43554133
279,2025-07-17T13:30:01.086456460Z,2025-07-17T13:30:01.086456460Z,10,2,1108,C,A,0,16.1000,100,0,168766,29116862,12.4700,100,1,14.4399,100,1,12.2300,100,1,14.7400,100,1,11.9299,100,1,15.2799,100,1,11.7599,100,1,15.3000,100,1,11.6899,2,1,15.3100,2,1,11.5199,100,1,15.6099,100,1,11.4000,100,1,15.9100,100,1,11.2899,100,1,16.1099,700,1,11.1400,700,1,16.1499,700,1,11.0700,700,1,16.1999,200,2,ARL,42674989
280,2025-07-17T13:30:01.086456460Z,2025-07-17T13:30:01.086456460Z,10,2,1108,A,A,0,14.1999,100,128,168766,29116862,12.4700,100,1,14.1999,100,1,12.2300,100,1,14.4399,100,1,11.9299,100,1,14.7400,100,1,11.7599,100,1,15.2799,100,1,11.6899,2,1,15.3000,100,1,11.5199,100,1,15.3100,2,1,11.4000,100,1,15.6099,100,1,11.2899,100,1,15.9100,100,1,11.1400,700,1,16.1099,700,1,11.0700,700,1,16.1499,700,1,ARL,43554141
281,2025-07-17T13:30:01.214703183Z,2025-07-17T13:30:01.214703183Z,10,2,1108,A,B,0,12.6699,100,0,179739,29196804,12.6699,100,1,14.1999,100,1,12.4700,100,1,14.4399,100,1,12.2300,100,1,14.7400,100,1,11.9299,100,1,15.2799,100,1,11.7599,100,1,15.3000,100,1,11.6899,2,1,15.3100,2,1,11.5199,100,1,15.6099,100,1,11.4000,100,1,15.9100,100,1,11.2899,100,1,16.1099,700,1,11.1400,700,1,16.1499,700,1,ARL,43663229
282,2025-07-17T13:30:01.214704496Z,2025-07-17T13:30:01.214704496Z,10,2,1108,A,A,0,14.0000,100,128,178426,29196805,12.6699,100,1,14.0000,100,1,12.4700,100,1,14.1999,100,1,12.2300,100,1,14.4399,100,1,11.9299,100,1,14.7400,100,1,11.7599,100,1,15.2799,100,1,11.6899,2,1,15.3000,100,1,11.5199,100,1,15.3100,2,1,11.4000,100,1,15.6099,100,1,11.2899,100,1,15.9100,100,1,11.1400,700,1,16.1099,700,1,ARL,43663233
283,2025-07-17T13:30:01.252206360Z,2025-07-17T13:30:01.252206360Z,10,2,1108,A,B,0,7.7400,100,0,180019,29221770,12.6699,100,1,14.0000,100,1,12.4700,100,1,14.1999,100,1,12.2300,100,1,14.4399,100,1,11.9299,100,1,14.7400,100,1,11.7599,100,1,15.2799,100,1,11.6899,2,1,15.3000,100,1,11.5199,100,1,15.3100,2,1,11.4000,100,1,15.6099,100,1,11.2899,100,1,15.9100,100,1,11.1400,700,1,16.1099,700,1,ARL,27015957
284,2025-07-17T13:30:01.252206360Z,2025-07-17T13:30:01.252206360Z,10,2,1108,A,A,0,20.4800,100,0,180019,29221771,12.6699,100,1,14.0000,100,1,12.4700,100,1,14.1999,100,1,12.2300,100,1,14.4399,100,1,11.9299,100,1,14.7400,100,1,11.7599,100,1,15.2799,100,1,11.6899,2,1,15.3000,100,1,11.5199,100,1,15.3100,2,1,11.4000,100,1,15.6099,100,1,11.2899,100,1,15.9100,100,1,11.1400,700,1,16.1099,700,1,ARL,27015965
285,2025-07-17T13:30:01.252206360Z,2025-07-17T13:30:01.252206360Z,10,2,1108,A,B,0,7.7400,100,0,180019,29221772,12.6699,100,1,14.0000,100,1,12.4700,100,1,14.1999,100,1,12.2300,100,1,14.4399,100,1,11.9299,100,1,14.7400,100,1,11.7599,100,1,15.2799,100,1,11.6899,2,1,15.3000,100,1,11.5199,100,1,15.3100,2,1,11.4000,100,1,15.6099,100,1,11.2899,100,1,15.9100,100,1,11.1400,700,1,16.1099,700,1,ARL,38084501
286,2025-07-17T13:30:01.252206360Z,2025-07-17T13:30:01.252206360Z,10,2,1108,A,A,0,20.4800,100,0,180019,29221773,12.6699,100,1,14.0000,100,1,12.4700,100,1,14.1999,100,1,12.2300,100,1,14.4399,100,1,11.9299,100,1,14.7400,100,1,11.7599,100,1,15.2799,100,1,11.6899,2,1,15.3000,100,1,11.5199,100,1,15.3100,2,1,11.4000,100,1,15.6099,100,1,11.2899,100,1,15.9100,100,1,11.1400,700,1,16.1099,700,1,ARL,38073517
287,2025-07-17T13:30:01.252206360Z,2025-07-17T13:30:01.252206360Z,10,2,1108,A,B,0,7.7400,100,0,180019,29221774,12.6699,100,1,14.0000,100,1,12.4700,100,1,14.1999,100,1,12.2300,100,1,14.4399,100,1,11.9299,100,1,14.7400,100,1,11.7599,100,1,15.2799,100,1,11.6899,2,1,15.3000,100,1,11.5199,100,1,15.3100,2,1,11.4000,100,1,15.6099,100,1,11.2899,100,1,15.9100,100,1,11.1400,700,1,16.1099,700,1,ARL,38130589
288,2025-07-17T13:30:01.252206360Z,2025-07-17T13:30:01.252206360Z,10,2,1108,A,A,0,20.4800,100,0,180019,29221775,12.6699,100,1,14.0000,100,1,12.4700,100,1,14.1999,100,1,12.2300,100,1,14.4399,100,1,11.9299,100,1,14.7400,100,1,11.7599,100,1,15.2799,100,1,11.6899,2,1,15.3000,100,1,11.5199,100,1,15.3100,2,1,11.4000,100,1,15.6099,100,1,11.2899,100,1,15.9100,100,1,11.1400,700,1,16.1099,700,1,ARL,38134973
289,2025-07-17T13:30:01.252206360Z,2025-07-17T13:30:01.252206360Z,10,2,1108,A,B,0,7.7400,100,0,180019,29221776,12.6699,100,1,14.0000,100,1,12.4700,100,1,14.1999,100,1,12.2300,100,1,14.4399,100,1,11.9299,100,1,14.7400,100,1,11.7599,100,1,15.2799,100,1,11.6899,2,1,15.3000,100,1,11.5199,100,1,15.3100,2,1,11.4000,100,1,15.6099,100,1,11.2899,100,1,15.9100,100,1,11.1400,700,1,16.1099,700,1,ARL,38470185
290,2025-07-17T13:30:01.252206360Z,2025-07-17T13:30:01.252206360Z,10,2,1108,A,A,0,20.4800,100,0,180019,29221777,12.6699,100,1,14.0000,100,1,12.4700,100,1,14.1999,100,1,12.2300,100,1,14.4399,100,1,11.9299,100,1,14.7400,100,1,11.7599,100,1,15.2799,100,1,11.6899,2,1,15.3000,100,1,11.5199,100,1,15.3100,2,1,11.4000,100,1,15.6099,100,1,11.2899,100,1,15.9100,100,1,11.1400,700,1,16.1099,700,1,ARL,38471493
291,2025-07-17T13:30:01.252206360Z,2025-07-17T13:30:01.252206360Z,10,2,1108,A,B,0,7.7400,100,0,180019,29221778,12.6699,100,1,14.0000,100,1,12.4700,100,1,14.1999,100,1,12.2300,100,1,14.4399,100,1,11.9299,100,1,14.7400,100,1,11.7599,100,1,15.2799,100,1,11.6899,2,1,15.3000,100,1,11.5199,100,1,15.3100,2,1,11.4000,100,1,15.6099,100,1,11.2899,100,1,15.9100,100,1,11.1400,700,1,16.1099,700,1,ARL,38759997
292,2025-07-17T13:30:01.252206360Z,2025-07-17T13:30:01.252206360Z,10,2,1108,A,A,0,20.4800,100,0,180019,29221779,12.6699,100,1,14.0000,100,1,12.4700,100,1,14.1999,100,1,12.2300,100,1,14.4399,100,1,11.9299,100,1,14.7400,100,1,11.7599,100,1,15.2799,100,1,11.6899,2,1,15.3000,100,1,11.5199,100,1,15.3100,2,1,11.4000,100,1,15.6099,100,1,11.2899,100,1,15.9100,100,1,11.1400,700,1,16.1099,700,1,ARL,38758965
293,2025-07-17T13:30:01.252206360Z,2025-07-17T13:30:01.252206360Z,10,2,1108,A,B,0,7.7400,100,0,180019,29221780,12.6699,100,1,14.0000,100,1,12.4700,100,1,14.1999,100,1,12.2300,100,1,14.4399,100,1,11.9299,100,1,14.7400,100,1,11.7599,100,1,15.2799,100,1,11.6899,2,1,15.3000,100,1,11.5199,100,1,15.3100,2,1,11.4000,100,1,15.6099,100,1,11.2899,100,1,15.9100,100,1,11.1400,700,1,16.1099,700,1,ARL,38775373
294,2025-07-17T13:30:01.252206360Z,2025-07-17T13:30:01.252206360Z,10,2,1108,A,A,0,20.4800,100,0,180019,29221781,12.6699,100,1,14.0000,100,1,12.4700,100,1,14.1999,100,1,12.2300,100,1,14.4399,100,1,11.9299,100,1,14.7400,100,1,11.7599,100,1,15.2799,100,1,11.6899,2,1,15.3000,100,1,11.5199,100,1,15.3100,2,1,11.4000,100,1,15.6099,100,1,11.2899,100,1,15.9100,100,1,11.1400,700,1,16.1099,700,1,ARL,38776877
295,2025-07-17T13:30:01.252206360Z,2025-07-17T13:30:01.252206360Z,10,2,1108,A,B,0,7.7400,100,0,180019,29221782,12.6699,100,1,14.0000,100,1,12.4700,100,1,14.1999,100,1,12.2300,100,1,14.4399,100,1,11.9299,100,1,14.7400,100,1,11.7599,100,1,15.2799,100,1,11.6899,2,1,15.3000,100,1,11.5199,100,1,15.3100,2,1,11.4000,100,1,15.6099,100,1,11.2899,100,1,15.9100,100,1,11.1400,700,1,16.1099,700,1,ARL,38865193
296,2025-07-17T13:30:01.252206360Z,2025-07-17T13:30:01.252206360Z,10,2,1108,A,A,0,20.4800,100,128,180019,29221783,12.6699,100,1,14.0000,100,1,12.4700,100,1,14.1999,100,1,12.2300,100,1,14.4399,100,1,11.9299,100,1,14.7400,100,1,11.7599,100,1,15.2799,100,1,11.6899,2,1,15.3000,100,1,11.5199,100,1,15.3100,2,1,11.4000,100,1,15.6099,100,1,11.2899,100,1,15.9100,100,1,11.1400,700,1,16.1099,700,1,ARL,38863877
297,2025-07-17T13:30:01.252269158Z,2025-07-17T13:30:01.252269158Z,10,2,1108,C,B,0,7.7400,100,0,175261,29221828,12.6699,100,1,14.0000,100,1,12.4700,100,1,14.1999,100,1,12.2300,100,1,14.4399,100,1,11.9299,100,1,14.7400,100,1,11.7599,100,1,15.2799,100,1,11.6899,2,1,15.3000,100,1,11.5199,100,1,15.3100,2,1,11.4000,100,1,15.6099,100,1,11.2899,100,1,15.9100,100,1,11.1400,700,1,16.1099,700,1,ARL,27015957
298,2025-07-17T13:30:01.252269158Z,2025-07-17T13:30:01.252269158Z,10,2,1108,A,B,0,9.5500,100,0,175261,29221828,12.6699,100,1,14.0000,100,1,12.4700,100,1,14.1999,100,1,12.2300,100,1,14.4399,100,1,11.9299,100,1,14.7400,100,1,11.7599,100,1,15.2799,100,1,11.6899,2,1,15.3000,100,1,11.5199,100,1,15.3100,2,1,11.4000,100,1,15.6099,100,1,11.2899,100,1,15.9100,100,1,11.1400,700,1,16.1099,700,1,ARL,43690797
299,2025-07-17T13:30:01.252269575Z,2025-07-17T13:30:01.252269575Z,10,2,1108,C,B,0,7.7400,100,0,174844,29221829,12.6699,100,1,14.0000,100,1,12.4700,100,1,14.1999,100,1,12.2300,100,1,14.4399,100,1,11.9299,100,1,14.7400,100,1,11.7599,100,1,15.2799,100,1,11.6899,2,1,15.3000,100,1,11.5199,100,1,15.3100,2,1,11.4000,100,1,15.6099,100,1,11.2899,100,1,15.9100,100,1,11.1400,700,1,16.1099,700,1,ARL,38084501
300,2025-07-17T13:30:01.252269575Z,2025-07-17T13:30:01.252269575Z,10,2,1108,A,B,0,9.5500,100,0,174844,29221829,12.6699,100,1,14.0000,100,1,12.4700,100,1,14.1999,100,1,12.2300,100,1,14.4399,100,1,11.9299,100,1,14.7400,100,1,11.7599,100,1,15.2799,100,1,11.6899,2,1,15.3000,100,1,11.5199,100,1,15.3100,2,1,11.4000,100,1,15.6099,100,1,11.2899,100,1,15.9100,100,1,11.1400,700,1,16.1099,700,1,ARL,43690801
301,2025-07-17T13:30:01.252269960Z,2025-07-17T13:30:01.252269960Z,10,2,1108,C,B,0,7.7400,100,0,174459,29221830,12.6699,100,1,14.0000,100,1,12.4700,100,1,14.1999,100,1,12.2300,100,1,14.4399,100,1,11.9299,100,1,14.7400,100,1,11.7599,100,1,15.2799,100,1,11.6899,2,1,15.3000,100,1,11.5199,100,1,15.3100,2,1,11.4000,100,1,15.6099,100,1,11.2899,100,1,15.9100,100,1,11.1400,700,1,16.1099,700,1,ARL,38130589
302,2025-07-17T13:30:01.252269960Z,2025-07-17T13:30:01.252269960Z,10,2,1108,A,B,0,9.5500,100,0,174459,29221830,12.6699,100,1,14.0000,100,1,12.4700,100,1,14.1999,100,1,12.2300,100,1,14.4399,100,1,11.9299,100,1,14.7400,100,1,11.7599,100,1,15.2799,100,1,11.6899,2,1,15.3000,100,1,11.5199,100,1,15.3100,2,1,11.4000,100,1,15.6099,100,1,11.2899,100,1,15.9100,100,1,11.1400,700,1,16.1099,700,1,ARL,43690805
303,2025-07-17T13:30:01.252270596Z,2025-07-17T13:30:01.252270596Z,10,2,1108,C,B,0,7.7400,100,0,173823,29221831,12.6699,100,1,14.0000,100,1,12.4700,100,1,14.1999,100,1,12.2300,100,1,14.4399,100,1,11.9299,100,1,14.7400,100,1,11.7599,100,1,15.2799,100,1,11.6899,2,1,15.3000,100,1,11.5199,100,1,15.3100,2,1,11.4000,100,1,15.6099,100,1,11.2899,100,1,15.9100,100,1,11.1400,700,1,16.1099,700,1,ARL,38470185
304,2025-07-17T13:30:01.252270596Z,2025-07-17T13:30:01.252270596Z,10,2,1108,A,B,0,9.5500,100,0,173823,29221831,12.6699,100,1,14.0000,100,1,12.4700,100,1,14.1999,100,1,12.2300,100,1,14.4399,100,1,11.9299,100,1,14.7400,100,1,11.7599,100,1,15.2799,100,1,11.6899,2,1,15.3000,100,1,11.5199,100,1,15.3100,2,1,11.4000,100,1,15.6099,100,1,11.2899,100,1,15.9100,100,1,11.1400,700,1,16.1099,700,1,ARL,43690809
305,2025-07-17T13:30:01.252270987Z,2025-07-17T13:30:01.252270987Z,10,2,1108,C,B,0,7.7400,100,0,173432,29221832,12.6699,100,1,14.0000,100,1,12.4700,100,1,14.1999,100,1,12.2300,100,1,14.4399,100,1,11.9299,100,1,14.7400,100,1,11.7599,100,1,15.2799,100,1,11.6899,2,1,15.3000,100,1,11.5199,100,1,15.3100,2,1,11.4000,100,1,15.6099,100,1,11.2899,100,1,15.9100,100,1,11.1400,700,1,16.1099,700,1,ARL,38759997
306,2025-07-17T13:30:01.252270987Z,2025-07-17T13:30:01.252270987Z,10,2,1108,A,B,0,9.5500,100,0,173432,29221832,12.6699,100,1,14.0000,100,1,12.4700,100,1,14.1999,100,1,12.2300,100,1,14.4399,100,1,11.9299,100,1,14.7400,100,1,11.7599,100,1,15.2799,100,1,11.6899,2,1,15.3000,100,1,11.5199,100,1,15.3100,2,1,11.4000,100,1,15.6099,100,1,11.2899,100,1,15.9100,100,1,11.1400,700,1,16.1099,700,1,ARL,43690813
307,2025-07-17T13:30:01.252271274Z,2025-07-17T13:30:01.252271274Z,10,2,1108,C,B,0,7.7400,100,0,173145,29221833,12.6699,100,1,14.0000,100,1,12.4700,100,1,14.1999,100,1,12.2300,100,1,14.4399,100,1,11.9299,100,1,14.7400,100,1,11.7599,100,1,15.2799,100,1,11.6899,2,1,15.3000,100,1,11.5199,100,1,15.3100,2,1,11.4000,100,1,15.6099,100,1,11.2899,100,1,15.9100,100,1,11.1400,700,1,16.1099,700,1,ARL,38775373
308,2025-07-17T13:30:01.252271274Z,2025-07-17T13:30:01.252271274Z,10,2,1108,A,B,0,9.5500,100,0,173145,29221833,12.6699,100,1,14.0000,100,1,12.4700,100,1,14.1999,100,1,12.2300,100,1,14.4399,100,1,11.9299,100,1,14.7400,100,1,11.7599,100,1,15.2799,100,1,11.6899,2,1,15.3000,100,1,11.5199,100,1,15.3100,2,1,11.4000,100,1,15.6099,100,1,11.2899,100,1,15.9100,100,1,11.1400,700,1,16.1099,700,1,ARL,43690817
309,2025-07-17T13:30:01.252272011Z,2025-07-17T13:30:01.252272011Z,10,2,1108,C,B,0,7.7400,100,0,172408,29221834,12.6699,100,1,14.0000,100,1,12.4700,100,1,14.1999,100,1,12.2300,100,1,14.4399,100,1,11.9299,100,1,14.7400,100,1,11.7599,100,1,15.2799,100,1,11.6899,2,1,15.3000,100,1,11.5199,100,1,15.3100,2,1,11.4000,100,1,15.6099,100,1,11.2899,100,1,15.9100,100,1,11.1400,700,1,16.1099,700,1,ARL,38865193
310,2025-07-17T13:30:01.252272011Z,2025-07-17T13:30:01.252272011Z,10,2,1108,A,B,0,9.5500,100,128,172408,29221834,12.6699,100,1,14.0000,100,1,12.4700,100,1,14.1999,100,1,12.2300,100,1,14.4399,100,1,11.9299,100,1,14.7400,100,1,11.7599,100,1,15.2799,100,1,11.6899,2,1,15.3000,100,1,11.5199,100,1,15.3100,2,1,11.4000,100,1,15.6099,100,1,11.2899,100,1,15.9100,100,1,11.1400,700,1,16.1099,700,1,ARL,43690821
311,2025-07-17T13:30:01.252279681Z,2025-07-17T13:30:01.252279681Z,10,2,1108,C,A,0,20.4800,100,0,178217,29221840,12.6699,100,1,14.0000,100,1,12.4700,100,1,14.1999,100,1,12.2300,100,1,14.4399,100,1,11.9299,100,1,14.7400,100,1,11.7599,100,1,15.2799,100,1,11.6899,2,1,15.3000,100,1,11.5199,100,1,15.3100,2,1,11.4000,100,1,15.6099,100,1,11.2899,100,1,15.9100,100,1,11.1400,700,1,16.1099,700,1,ARL,27015965
312,2025-07-17T13:30:01.252279681Z,2025-07-17T13:30:01.252279681Z,10,2,1108,A,A,0,17.1499,100,0,178217,29221840,12.6699,100,1,14.0000,100,1,12.4700,100,1,14.1999,100,1,12.2300,100,1,14.4399,100,1,11.9299,100,1,14.7400,100,1,11.7599,100,1,15.2799,100,1,11.6899,2,1,15.3000,100,1,11.5199,100,1,15.3100,2,1,11.4000,100,1,15.6099,100,1,11.2899,100,1,15.9100,100,1,11.1400,700,1,16.1099,700,1,ARL,43690825
313,2025-07-17T13:30:01.252280017Z,2025-07-17T13:30:01.252280017Z,10,2,1108,C,A,0,20.4800,100,0,177881,29221841,12.6699,100,1,14.0000,100,1,12.4700,100,1,14.1999,100,1,12.2300,100,1,14.4399,100,1,11.9299,100,1,14.7400,100,1,11.7599,100,1,15.2799,100,1,11.6899,2,1,15.3000,100,1,11.5199,100,1,15.3100,2,1,11.4000,100,1,15.6099,100,1,11.2899,100,1,15.9100,100,1,11.1400,700,1,16.1099,700,1,ARL,38073517
314,2025-07-17T13:30:01.252280017Z,2025-07-17T13:30:01.252280017Z,10,2,1108,A,A,0,17.1499,100,0,177881,29221841,12.6699,100,1,14.0000,100,1,12.4700,100,1,14.1999,100,1,12.2300,100,1,14.4399,100,1,11.9299,100,1,14.7400,100,1,11.7599,100,1,15.2799,100,1,11.6899,2,1,15.3000,100,1,11.5199,100,1,15.3100,2,1,11.4000,100,1,15.6099,100,1,11.2899,100,1,15.9100,100,1,11.1400,700,1,16.1099,700,1,ARL,43690829
315,2025-07-17T13:30:01.252280383Z,2025-07-17T13:30:01.252280383Z,10,2,1108,C,A,0,20.4800,100,0,177515,29221842,12.6699,100,1,14.0000,100,1,12.4700,100,1,14.1999,100,1,12.2300,100,1,14.4399,100,1,11.9299,100,1,14.7400,100,1,11.7599,100,1,15.2799,100,1,11.6899,2,1,15.3000,100,1,11.5199,100,1,15.3100,2,1,11.4000,100,1,15.6099,100,1,11.2899,100,1,15.9100,100,1,11.1400,700,1,16.1099,700,1,ARL,38134973
316,2025-07-17T13:30:01.252280383Z,2025-07-17T13:30:01.252280383Z,10,2,1108,A,A,0,17.1499,100,0,177515,29221842,12.6699,100,1,14.0000,100,1,12.4700,100,1,14.1999,100,1,12.2300,100,1,14.4399,100,1,11.9299,100,1,14.7400,100,1,11.7599,100,1,15.2799,100,1,11.6899,2,1,15.3000,100,1,11.5199,100,1,15.3100,2,1,11.4000,100,1,15.6099,100,1,11.2899,100,1,15.9100,100,1,11.1400,700,1,16.1099,700,1,ARL,43690833
317,2025-07-17T13:30:01.252280683Z,2025-07-17T13:30:01.252280683Z,10,2,1108,C,A,0,20.4800,100,0,177215,29221843,12.6699,100,1,14.0000,100,1,12.4700,100,1,14.1999,100,1,12.2300,100,1,14.4399,100,1,11.9299,100,1,14.7400,100,1,11.7599,100,1,15.2799,100,1,11.6899,2,1,15.3000,100,1,11.5199,100,1,15.3100,2,1,11.4000,100,1,15.6099,100,1,11.2899,100,1,15.9100,100,1,11.1400,700,1,16.1099,700,1,ARL,38471493
318,2025-07-17T13:30:01.252280683Z,2025-07-17T13:30:01.252280683Z,10,2,1108,A,A,0,17.1499,100,0,177215,29221843,12.6699,100,1,14.0000,100,1,12.4700,100,1,14.1999,100,1,12.2300,100,1,14.4399,100,1,11.9299,100,1,14.7400,100,1,11.7599,100,1,15.2799,100,1,11.6899,2,1,15.3000,100,1,11.5199,100,1,15.3100,2,1,11.4000,100,1,15.6099,100,1,11.2899,100,1,15.9100,100,1,11.1400,700,1,16.1099,700,1,ARL,43690837
319,2025-07-17T13:30:01.252281079Z,2025-07-17T13:30:01.252281079Z,10,2,1108,C,A,0,20.4800,100,0,176819,29221844,12.6699,100,1,14.0000,100,1,12.4700,100,1,14.1999,100,1,12.2300,100,1,14.4399,100,1,11.9299,100,1,14.7400,100,1,11.7599,100,1,15.2799,100,1,11.6899,2,1,15.3000,100,1,11.5199,100,1,15.3100,2,1,11.4000,100,1,15.6099,100,1,11.2899,100,1,15.9100,100,1,11.1400,700,1,16.1099,700,1,ARL,38758965
320,2025-07-17T13:30:01.252281079Z,2025-07-17T13:30:01.252281079Z,10,2,1108,A,A,0,17.1499,100,0,176819,29221844,12.6699,100,1,14.0000,100,1,12.4700,100,1,14.1999,100,1,12.2300,100,1,14.4399,100,1,11.9299,100,1,14.7400,100,1,11.7599,100,1,15.2799,100,1,11.6899,2,1,15.3000,100,1,11.5199,100,1,15.3100,2,1,11.4000,100,1,15.6099,100,1,11.2899,100,1,15.9100,100,1,11.1400,700,1,16.1099,700,1,ARL,43690841
321,2025-07-17T13:30:01.252281306Z,2025-07-17T13:30:01.252281306Z,10,2,1108,C,A,0,20.4800,100,0,176592,29221845,12.6699,100,1,14.0000,100,1,12.4700,100,1,14.1999,100,1,12.2300,100,1,14.4399,100,1,11.9299,100,1,14.7400,100,1,11.7599,100,1,15.2799,100,1,11.6899,2,1,15.3000,100,1,11.5199,100,1,15.3100,2,1,11.4000,100,1,15.6099,100,1,11.2899,100,1,15.9100,100,1,11.1400,700,1,16.1099,700,1,ARL,38776877
322,2025-07-17T13:30:01.252281306Z,2025-07-17T13:30:01.252281306Z,10,2,1108,A,A,0,17.1499,100,0,176592,29221845,12.6699,100,1,14.0000,100,1,12.4700,100,1,14.1999,100,1,12.2300,100,1,14.4399,100,1,11.9299,100,1,14.7400,100,1,11.7599,100,1,15.2799,100,1,11.6899,2,1,15.3000,100,1,11.5199,100,1,15.3100,2,1,11.4000,100,1,15.6099,100,1,11.2899,100,1,15.9100,100,1,11.1400,700,1,16.1099,700,1,ARL,43690845
323,2025-07-17T13:30:01.252281648Z,2025-07-17T13:30:01.252281648Z,10,2,1108,C,A,0,20.4800,100,0,176250,29221846,12.6699,100,1,14.0000,100,1,12.4700,100,1,14.1999,100,1,12.2300,100,1,14.4399,100,1,11.9299,100,1,14.7400,100,1,11.7599,100,1,15.2799,100,1,11.6899,2,1,15.3000,100,1,11.5199,100,1,15.3100,2,1,11.4000,100,1,15.6099,100,1,11.2899,100,1,15.9100,100,1,11.1400,700,1,16.1099,700,1,ARL,38863877
324,2025-07-17T13:30:01.252281648Z,2025-07-17T13:30:01.252281648Z,10,2,1108,A,A,0,17.1499,100,130,176250,29221846,12.6699,100,1,14.0000,100,1,12.4700,100,1,14.1999,100,1,12.2300,100,1,14.4399,100,1,11.9299,100,1,14.7400,100,1,11.7599,100,1,15.2799,100,1,11.6899,2,1,15.3000,100,1,11.5199,100,1,15.3100,2,1,11.4000,100,1,15.6099,100,1,11.2899,100,1,15.9100,100,1,11.1400,700,1,16.1099,700,1,ARL,43690849
325,2025-07-17T13:30:01.254829854Z,2025-07-17T13:30:01.254829854Z,10,2,1108,C,B,0,11.6899,2,0,177685,29223480,12.6699,100,1,14.0000,100,1,12.4700,100,1,14.1999,100,1,12.2300,100,1,14.4399,100,1,11.9299,100,1,14.7400,100,1,11.7599,100,1,15.2799,100,1,11.5199,100,1,15.3000,100,1,11.4000,100,1,15.3100,2,1,11.2899,100,1,15.6099,100,1,11.1400,700,1,15.9100,100,1,11.0700,700,1,16.1099,700,1,ARL,43324133
326,2025-07-17T13:30:01.254829854Z,2025-07-17T13:30:01.254829854Z,10,2,1108,A,B,0,12.3300,2,128,177685,29223480,12.6699,100,1,14.0000,100,1,12.4700,100,1,14.1999,100,1,12.3300,2,1,14.4399,100,1,12.2300,100,1,14.7400,100,1,11.9299,100,1,15.2799,100,1,11.7599,100,1,15.3000,100,1,11.5199,100,1,15.3100,2,1,11.4000,100,1,15.6099,100,1,11.2899,100,1,15.9100,100,1,11.1400,700,1,16.1099,700,1,ARL,43692153
327,2025-07-17T13:30:01.254836082Z,2025-07-17T13:30:01.254836082Z,10,2,1108,C,A,0,15.3100,2,0,180884,29223485,12.6699,100,1,14.0000,100,1,12.4700,100,1,14.1999,100,1,12.3300,2,1,14.4399,100,1,12.2300,100,1,14.7400,100,1,11.9299,100,1,15.2799,100,1,11.7599,100,1,15.3000,100,1,11.5199,100,1,15.6099,100,1,11.4000,100,1,15.9100,100,1,11.2899,100,1,16.1099,700,1,11.1400,700,1,16.1499,700,1,ARL,43328313
328,2025-07-17T13:30:01.254836082Z,2025-07-17T13:30:01.254836082Z,10,2,1108,A,A,0,14.6500,2,128,180884,29223485,12.6699,100,1,14.0000,100,1,12.4700,100,1,14.1999,100,1,12.3300,2,1,14.4399,100,1,12.2300,100,1,14.6500,2,1,11.9299,100,1,14.7400,100,1,11.7599,100,1,15.2799,100,1,11.5199,100,1,15.3000,100,1,11.4000,100,1,15.6099,100,1,11.2899,100,1,15.9100,100,1,11.1400,700,1,16.1099,700,1,ARL,43692157
329,2025-07-17T13:30:01.326934077Z,2025-07-17T13:30:01.326934077Z,10,2,1108,C,B,0,11.5199,100,130,175400,29250087,12.6699,100,1,14.0000,100,1,12.4700,100,1,14.1999,100,1,12.3300,2,1,14.4399,100,1,12.2300,100,1,14.6500,2,1,11.9299,100,1,14.7400,100,1,11.7599,100,1,15.2799,100,1,11.4000,100,1,15.3000,100,1,11.2899,100,1,15.6099,100,1,11.1400,700,1,15.9100,100,1,11.0700,700,1,16.1099,700,1,ARL,42446497
330,2025-07-17T13:30:01.327714478Z,2025-07-17T13:30:01.327714478Z,10,2,1108,C,A,0,15.6099,100,128,180420,29250293,12.6699,100,1,14.0000,100,1,12.4700,100,1,14.1999,100,1,12.3300,2,1,14.4399,100,1,12.2300,100,1,14.6500,2,1,11.9299,100,1,14.7400,100,1,11.7599,100,1,15.2799,100,1,11.4000,100,1,15.3000,100,1,11.2899,100,1,15.9100,100,1,11.1400,700,1,16.1099,700,1,11.0700,700,1,16.1499,700,1,ARL,42446501
331,2025-07-17T13:30:01.367244122Z,2025-07-17T13:30:01.367244122Z,10,2,1108,C,B,0,10.9299,100,0,166111,29262273,12.6699,100,1,14.0000,100,1,12.4700,100,1,14.1999,100,1,12.3300,2,1,14.4399,100,1,12.2300,100,1,14.6500,2,1,11.9299,100,1,14.7400,100,1,11.7599,100,1,15.2799,100,1,11.4000,100,1,15.3000,100,1,11.2899,100,1,15.9100,100,1,11.1400,700,1,16.1099,700,1,11.0700,700,1,16.1499,700,1,ARL,41376501
332,2025-07-17T13:30:01.367244122Z,2025-07-17T13:30:01.367244122Z,10,2,1108,A,B,0,12.3300,100,130,166111,29262273,12.6699,100,1,14.0000,100,1,12.4700,100,1,14.1999,100,1,12.3300,102,2,14.4399,100,1,12.2300,100,1,14.6500,2,1,11.9299,100,1,14.7400,100,1,11.7599,100,1,15.2799,100,1,11.4000,100,1,15.3000,100,1,11.2899,100,1,15.9100,100,1,11.1400,700,1,16.1099,700,1,11.0700,700,1,16.1499,700,1,ARL,43755813
333,2025-07-17T13:30:01.367256226Z,2025-07-17T13:30:01.367256226Z,10,2,1108,C,A,0,16.3799,100,0,165618,29262274,12.6699,100,1,14.0000,100,1,12.4700,100,1,14.1999,100,1,12.3300,102,2,14.4399,100,1,12.2300,100,1,14.6500,2,1,11.9299,100,1,14.7400,100,1,11.7599,100,1,15.2799,100,1,11.4000,100,1,15.3000,100,1,11.2899,100,1,15.9100,100,1,11.1400,700,1,16.1099,700,1,11.0700,700,1,16.1499,700,1,ARL,41372085
334,2025-07-17T13:30:01.367256226Z,2025-07-17T13:30:01.367256226Z,10,2,1108,A,A,0,14.3399,100,130,165618,29262274,12.6699,100,1,14.0000,100,1,12.4700,100,1,14.1999,100,1,12.3300,102,2,14.3399,100,1,12.2300,100,1,14.4399,100,1,11.9299,100,1,14.6500,2,1,11.7599,100,1,14.7400,100,1,11.4000,100,1,15.2799,100,1,11.2899,100,1,15.3000,100,1,11.1400,700,1,15.9100,100,1,11.0700,700,1,16.1099,700,1,ARL,43755821
335,2025-07-17T13:30:01.456460560Z,2025-07-17T13:30:01.456460560Z,10,2,1108,C,B,0,10.9199,100,0,171287,29285993,12.6699,100,1,14.0000,100,1,12.4700,100,1,14.1999,100,1,12.3300,102,2,14.3399,100,1,12.2300,100,1,14.4399,100,1,11.9299,100,1,14.6500,2,1,11.7599,100,1,14.7400,100,1,11.4000,100,1,15.2799,100,1,11.2899,100,1,15.3000,100,1,11.1400,700,1,15.9100,100,1,11.0700,700,1,16.1099,700,1,ARL,43143317
336,2025-07-17T13:30:01.456460560Z,2025-07-17T13:30:01.456460560Z,10,2,1108,A,B,0,12.3599,100,130,171287,29285993,12.6699,100,1,14.0000,100,1,12.4700,100,1,14.1999,100,1,12.3599,100,1,14.3399,100,1,12.3300,102,2,14.4399,100,1,12.2300,100,1,14.6500,2,1,11.9299,100,1,14.7400,100,1,11.7599,100,1,15.2799,100,1,11.4000,100,1,15.3000,100,1,11.2899,100,1,15.9100,100,1,11.1400,700,1,16.1099,700,1,ARL,43781537
337,2025-07-17T13:30:01.456476348Z,2025-07-17T13:30:01.456476348Z,10,2,1108,C,A,0,16.1999,100,0,166602,29285996,12.6699,100,1,14.0000,100,1,12.4700,100,1,14.1999,100,1,12.3599,100,1,14.3399,100,1,12.3300,102,2,14.4399,100,1,12.2300,100,1,14.6500,2,1,11.9299,100,1,14.7400,100,1,11.7599,100,1,15.2799,100,1,11.4000,100,1,15.3000,100,1,11.2899,100,1,15.9100,100,1,11.1400,700,1,16.1099,700,1,ARL,43143333
338,2025-07-17T13:30:01.456476348Z,2025-07-17T13:30:01.456476348Z,10,2,1108,A,A,0,14.9000,100,130,166602,29285996,12.6699,100,1,14.0000,100,1,12.4700,100,1,14.1999,100,1,12.3599,100,1,14.3399,100,1,12.3300,102,2,14.4399,100,1,12.2300,100,1,14.6500,2,1,11.9299,100,1,14.7400,100,1,11.7599,100,1,14.9000,100,1,11.4000,100,1,15.2799,100,1,11.2899,100,1,15.3000,100,1,11.1400,700,1,15.9100,100,1,ARL,43781545
339,2025-07-17T13:30:01.487884350Z,2025-07-17T13:30:01.487884350Z,10,2,1108,C,B,0,10.9199,100,0,165832,29297612,12.6699,100,1,14.0000,100,1,12.4700,100,1,14.1999,100,1,12.3599,100,1,14.3399,100,1,12.3300,102,2,14.4399,100,1,12.2300,100,1,14.6500,2,1,11.9299,100,1,14.7400,100,1,11.7599,100,1,14.9000,100,1,11.4000,100,1,15.2799,100,1,11.2899,100,1,15.3000,100,1,11.1400,700,1,15.9100,100,1,ARL,43191333
340,2025-07-17T13:30:01.487884350Z,2025-07-17T13:30:01.487884350Z,10,2,1108,A,B,0,12.3599,100,130,165832,29297612,12.6699,100,1,14.0000,100,1,12.4700,100,1,14.1999,100,1,12.3599,200,2,14.3399,100,1,12.3300,102,2,14.4399,100,1,12.2300,100,1,14.6500,2,1,11.9299,100,1,14.7400,100,1,11.7599,100,1,14.9000,100,1,11.4000,100,1,15.2799,100,1,11.2899,100,1,15.3000,100,1,11.1400,700,1,15.9100,100,1,ARL,43787977
341,2025-07-17T13:30:01.487905785Z,2025-07-17T13:30:01.487905785Z,10,2,1108,C,A,0,16.1999,100,0,177067,29297619,12.6699,100,1,14.0000,100,1,12.4700,100,1,14.1999,100,1,12.3599,200,2,14.3399,100,1,12.3300,102,2,14.4399,100,1,12.2300,100,1,14.6500,2,1,11.9299,100,1,14.7400,100,1,11.7599,100,1,14.9000,100,1,11.4000,100,1,15.2799,100,1,11.2899,100,1,15.3000,100,1,11.1400,700,1,15.9100,100,1,ARL,43191369
342,2025-07-17T13:30:01.487905785Z,2025-07-17T13:30:01.487905785Z,10,2,1108,A,A,0,14.9000,100,128,177067,29297619,12.6699,100,1,14.0000,100,1,12.4700,100,1,14.1999,100,1,12.3599,200,2,14.3399,100,1,12.3300,102,2,14.4399,100,1,12.2300,100,1,14.6500,2,1,11.9299,100,1,14.7400,100,1,11.7599,100,1,14.9000,200,2,11.4000,100,1,15.2799,100,1,11.2899,100,1,15.3000,100,1,11.1400,700,1,15.9100,100,1,ARL,43787985
343,2025-07-17T13:30:01.488809902Z,2025-07-17T13:30:01.488809902Z,10,2,1108,C,A,0,17.2300,100,128,171390,29298089,12.6699,100,1,14.0000,100,1,12.4700,100,1,14.1999,100,1,12.3599,200,2,14.3399,100,1,12.3300,102,2,14.4399,100,1,12.2300,100,1,14.6500,2,1,11.9299,100,1,14.7400,100,1,11.7599,100,1,14.9000,200,2,11.4000,100,1,15.2799,100,1,11.2899,100,1,15.3000,100,1,11.1400,700,1,15.9100,100,1,ARL,43314561
344,2025-07-17T13:30:01.488866053Z,2025-07-17T13:30:01.488866053Z,10,2,1108,A,A,0,16.0799,100,128,172059,29298118,12.6699,100,1,14.0000,100,1,12.4700,100,1,14.1999,100,1,12.3599,200,2,14.3399,100,1,12.3300,102,2,14.4399,100,1,12.2300,100,1,14.6500,2,1,11.9299,100,1,14.7400,100,1,11.7599,100,1,14.9000,200,2,11.4000,100,1,15.2799,100,1,11.2899,100,1,15.3000,100,1,11.1400,700,1,15.9100,100,1,ARL,43788313
345,2025-07-17T13:30:01.532274368Z,2025-07-17T13:30:01.532274368Z,10,2,1108,A,B,0,12.4600,100,128,170630,29318499,12.6699,100,1,14.0000,100,1,12.4700,100,1,14.1999,100,1,12.4600,100,1,14.3399,100,1,12.3599,200,2,14.4399,100,1,12.3300,102,2,14.6500,2,1,12.2300,100,1,14.7400,100,1,11.9299,100,1,14.9000,200,2,11.7599,100,1,15.2799,100,1,11.4000,100,1,15.3000,100,1,11.2899,100,1,15.9100,100,1,ARL,43804025
346,2025-07-17T13:30:01.532293890Z,2025-07-17T13:30:01.532293890Z,10,2,1108,C,B,0,11.0500,100,128,180602,29318513,12.6699,100,1,14.0000,100,1,12.4700,100,1,14.1999,100,1,12.4600,100,1,14.3399,100,1,12.3599,200,2,14.4399,100,1,12.3300,102,2,14.6500,2,1,12.2300,100,1,14.7400,100,1,11.9299,100,1,14.9000,200,2,11.7599,100,1,15.2799,100,1,11.4000,100,1,15.3000,100,1,11.2899,100,1,15.9100,100,1,ARL,42089321
347,2025-07-17T13:30:01.532324961Z,2025-07-17T13:30:01.532324961Z,10,2,1108,A,A,0,14.1999,100,128,173333,29318528,12.6699,100,1,14.0000,100,1,12.4700,100,1,14.1999,200,2,12.4600,100,1,14.3399,100,1,12.3599,200,2,14.4399,100,1,12.3300,102,2,14.6500,2,1,12.2300,100,1,14.7400,100,1,11.9299,100,1,14.9000,200,2,11.7599,100,1,15.2799,100,1,11.4000,100,1,15.3000,100,1,11.2899,100,1,15.9100,100,1,ARL,43804081
348,2025-07-17T13:30:01.532347519Z,2025-07-17T13:30:01.532347519Z,10,2,1108,C,A,0,16.2199,100,128,180696,29318534,12.6699,100,1,14.0000,100,1,12.4700,100,1,14.1999,200,2,12.4600,100,1,14.3399,100,1,12.3599,200,2,14.4399,100,1,12.3300,102,2,14.6500,2,1,12.2300,100,1,14.7400,100,1,11.9299,100,1,14.9000,200,2,11.7599,100,1,15.2799,100,1,11.4000,100,1,15.3000,100,1,11.2899,100,1,15.9100,100,1,ARL,42089325
349,2025-07-17T13:30:01.537195873Z,2025-07-17T13:30:01.537195873Z,10,2,1108,A,B,0,12.9900,100,128,177786,29320724,12.9900,100,1,14.0000,100,1,12.6699,100,1,14.1999,200,2,12.4700,100,1,14.3399,100,1,12.4600,100,1,14.4399,100,1,12.3599,200,2,14.6500,2,1,12.3300,102,2,14.7400,100,1,12.2300,100,1,14.9000,200,2,11.9299,100,1,15.2799,100,1,11.7599,100,1,15.3000,100,1,11.4000,100,1,15.9100,100,1,ARL,43805737
350,2025-07-17T13:30:01.537219414Z,2025-07-17T13:30:01.537219414Z,10,2,1108,A,A,0,14.6500,100,128,167618,29320743,12.9900,100,1,14.0000,100,1,12.6699,100,1,14.1999,200,2,12.4700,100,1,14.3399,100,1,12.4600,100,1,14.4399,100,1,12.3599,200,2,14.6500,102,2,12.3300,102,2,14.7400,100,1,12.2300,100,1,14.9000,200,2,11.9299,100,1,15.2799,100,1,11.7599,100,1,15.3000,100,1,11.4000,100,1,15.9100,100,1,ARL,43805773
351,2025-07-17T13:30:01.571375465Z,2025-07-17T13:30:01.571375465Z,10,2,1108,A,B,0,13.1999,28,130,183336,29336931,13.1999,28,1,14.0000,100,1,12.9900,100,1,14.1999,200,2,12.6699,100,1,14.3399,100,1,12.4700,100,1,14.4399,100,1,12.4600,100,1,14.6500,102,2,12.3599,200,2,14.7400,100,1,12.3300,102,2,14.9000,200,2,12.2300,100,1,15.2799,100,1,11.9299,100,1,15.3000,100,1,11.7599,100,1,15.9100,100,1,ARL,43820541
352,2025-07-17T13:30:01.589592733Z,2025-07-17T13:30:01.589592733Z,10,2,1108,C,A,0,17.2300,100,128,174848,29345825,13.1999,28,1,14.0000,100,1,12.9900,100,1,14.1999,200,2,12.6699,100,1,14.3399,100,1,12.4700,100,1,14.4399,100,1,12.4600,100,1,14.6500,102,2,12.3599,200,2,14.7400,100,1,12.3300,102,2,14.9000,200,2,12.2300,100,1,15.2799,100,1,11.9299,100,1,15.3000,100,1,11.7599,100,1,15.9100,100,1,ARL,43317185
353,2025-07-17T13:30:01.590381387Z,2025-07-17T13:30:01.590381387Z,10,2,1108,A,A,0,16.0799,100,128,183147,29346224,13.1999,28,1,14.0000,100,1,12.9900,100,1,14.1999,200,2,12.6699,100,1,14.3399,100,1,12.4700,100,1,14.4399,100,1,12.4600,100,1,14.6500,102,2,12.3599,200,2,14.7400,100,1,12.3300,102,2,14.9000,200,2,12.2300,100,1,15.2799,100,1,11.9299,100,1,15.3000,100,1,11.7599,100,1,15.9100,100,1,ARL,43826261
354,2025-07-17T13:30:01.592507554Z,2025-07-17T13:30:01.592507554Z,10,2,1108,C,B,0,9.9900,100,0,183966,29347436,13.1999,28,1,14.0000,100,1,12.9900,100,1,14.1999,200,2,12.6699,100,1,14.3399,100,1,12.4700,100,1,14.4399,100,1,12.4600,100,1,14.6500,102,2,12.3599,200,2,14.7400,100,1,12.3300,102,2,14.9000,200,2,12.2300,100,1,15.2799,100,1,11.9299,100,1,15.3000,100,1,11.7599,100,1,15.9100,100,1,ARL,41376769
355,2025-07-17T13:30:01.592507554Z,2025-07-17T13:30:01.592507554Z,10,2,1108,A,B,0,11.2699,100,128,183966,29347436,13.1999,28,1,14.0000,100,1,12.9900,100,1,14.1999,200,2,12.6699,100,1,14.3399,100,1,12.4700,100,1,14.4399,100,1,12.4600,100,1,14.6500,102,2,12.3599,200,2,14.7400,100,1,12.3300,102,2,14.9000,200,2,12.2300,100,1,15.2799,100,1,11.9299,100,1,15.3000,100,1,11.7599,100,1,15.9100,100,1,ARL,43826785
356,2025-07-17T13:30:01.592539240Z,2025-07-17T13:30:01.592539240Z,10,2,1108,C,A,0,17.6000,100,0,172822,29347463,13.1999,28,1,14.0000,100,1,12.9900,100,1,14.1999,200,2,12.6699,100,1,14.3399,100,1,12.4700,100,1,14.4399,100,1,12.4600,100,1,14.6500,102,2,12.3599,200,2,14.7400,100,1,12.3300,102,2,14.9000,200,2,12.2300,100,1,15.2799,100,1,11.9299,100,1,15.3000,100,1,11.7599,100,1,15.9100,100,1,ARL,41372493
357,2025-07-17T13:30:01.592539240Z,2025-07-17T13:30:01.592539240Z,10,2,1108,A,A,0,15.4100,100,128,172822,29347463,13.1999,28,1,14.0000,100,1,12.9900,100,1,14.1999,200,2,12.6699,100,1,14.3399,100,1,12.4700,100,1,14.4399,100,1,12.4600,100,1,14.6500,102,2,12.3599,200,2,14.7400,100,1,12.3300,102,2,14.9000,200,2,12.2300,100,1,15.2799,100,1,11.9299,100,1,15.3000,100,1,11.7599,100,1,15.4100,100,1,ARL,43826805
358,2025-07-17T13:30:01.661958252Z,2025-07-17T13:30:01.661958252Z,10,2,1108,C,B,0,10.5800,100,0,165451,29378719,13.1999,28,1,14.0000,100,1,12.9900,100,1,14.1999,200,2,12.6699,100,1,14.3399,100,1,12.4700,100,1,14.4399,100,1,12.4600,100,1,14.6500,102,2,12.3599,200,2,14.7400,100,1,12.3300,102,2,14.9000,200,2,12.2300,100,1,15.2799,100,1,11.9299,100,1,15.3000,100,1,11.7599,100,1,15.4100,100,1,ARL,41377117
359,2025-07-17T13:30:01.661958252Z,2025-07-17T13:30:01.661958252Z,10,2,1108,A,B,0,11.9299,100,130,165451,29378719,13.1999,28,1,14.0000,100,1,12.9900,100,1,14.1999,200,2,12.6699,100,1,14.3399,100,1,12.4700,100,1,14.4399,100,1,12.4600,100,1,14.6500,102,2,12.3599,200,2,14.7400,100,1,12.3300,102,2,14.9000,200,2,12.2300,100,1,15.2799,100,1,11.9299,200,2,15.3000,100,1,11.7599,100,1,15.4100,100,1,ARL,43852121
360,2025-07-17T13:30:01.661989524Z,2025-07-17T13:30:01.661989524Z,10,2,1108,C,A,0,16.8299,100,0,170086,29378727,13.1999,28,1,14.0000,100,1,12.9900,100,1,14.1999,200,2,12.6699,100,1,14.3399,100,1,12.4700,100,1,14.4399,100,1,12.4600,100,1,14.6500,102,2,12.3599,200,2,14.7400,100,1,12.3300,102,2,14.9000,200,2,12.2300,100,1,15.2799,100,1,11.9299,200,2,15.3000,100,1,11.7599,100,1,15.4100,100,1,ARL,41372469
361,2025-07-17T13:30:01.661989524Z,2025-07-17T13:30:01.661989524Z,10,2,1108,A,A,0,14.7400,100,128,170086,29378727,13.1999,28,1,14.0000,100,1,12.9900,100,1,14.1999,200,2,12.6699,100,1,14.3399,100,1,12.4700,100,1,14.4399,100,1,12.4600,100,1,14.6500,102,2,12.3599,200,2,14.7400,200,2,12.3300,102,2,14.9000,200,2,12.2300,100,1,15.2799,100,1,11.9299,200,2,15.3000,100,1,11.7599,100,1,15.4100,100,1,ARL,43852129
362,2025-07-17T13:30:01.929395142Z,2025-07-17T13:30:01.929395142Z,10,2,1108,C,A,0,14.6500,100,130,165367,29480243,13.1999,28,1,14.0000,100,1,12.9900,100,1,14.1999,200,2,12.6699,100,1,14.3399,100,1,12.4700,100,1,14.4399,100,1,12.4600,100,1,14.6500,2,1,12.3599,200,2,14.7400,200,2,12.3300,102,2,14.9000,200,2,12.2300,100,1,15.2799,100,1,11.9299,200,2,15.3000,100,1,11.7599,100,1,15.4100,100,1,ARL,43805773
363,2025-07-17T13:30:01.930800767Z,2025-07-17T13:30:01.930800767Z,10,2,1108,A,A,0,13.6699,100,130,165610,29480698,13.1999,28,1,13.6699,100,1,12.9900,100,1,14.0000,100,1,12.6699,100,1,14.1999,200,2,12.4700,100,1,14.3399,100,1,12.4600,100,1,14.4399,100,1,12.3599,200,2,14.6500,2,1,12.3300,102,2,14.7400,200,2,12.2300,100,1,14.9000,200,2,11.9299,200,2,15.2799,100,1,11.7599,100,1,15.3000,100,1,ARL,43953649
364,2025-07-17T13:30:02.208989359Z,2025-07-17T13:30:02.208989359Z,10,2,1108,A,A,0,17.1499,100,130,165620,29556866,13.1999,28,1,13.6699,100,1,12.9900,100,1,14.0000,100,1,12.6699,100,1,14.1999,200,2,12.4700,100,1,14.3399,100,1,12.4600,100,1,14.4399,100,1,12.3599,200,2,14.6500,2,1,12.3300,102,2,14.7400,200,2,12.2300,100,1,14.9000,200,2,11.9299,200,2,15.2799,100,1,11.7599,100,1,15.3000,100,1,ARL,44040361
365,2025-07-17T13:30:02.209004229Z,2025-07-17T13:30:02.209004229Z,10,2,1108,A,B,0,9.5500,100,128,166436,29556867,13.1999,28,1,13.6699,100,1,12.9900,100,1,14.0000,100,1,12.6699,100,1,14.1999,200,2,12.4700,100,1,14.3399,100,1,12.4600,100,1,14.4399,100,1,12.3599,200,2,14.6500,2,1,12.3300,102,2,14.7400,200,2,12.2300,100,1,14.9000,200,2,11.9299,200,2,15.2799,100,1,11.7599,100,1,15.3000,100,1,ARL,44040369
366,2025-07-17T13:30:02.378274380Z,2025-07-17T13:30:02.378274380Z,10,2,1108,A,B,0,12.7300,100,130,165674,29585499,13.1999,28,1,13.6699,100,1,12.9900,100,1,14.0000,100,1,12.7300,100,1,14.1999,200,2,12.6699,100,1,14.3399,100,1,12.4700,100,1,14.4399,100,1,12.4600,100,1,14.6500,2,1,12.3599,200,2,14.7400,200,2,12.3300,102,2,14.9000,200,2,12.2300,100,1,15.2799,100,1,11.9299,200,2,15.3000,100,1,ARL,44066409
367,2025-07-17T13:30:02.378280610Z,2025-07-17T13:30:02.378280610Z,10,2,1108,A,A,0,13.9299,100,130,165619,29585501,13.1999,28,1,13.6699,100,1,12.9900,100,1,13.9299,100,1,12.7300,100,1,14.0000,100,1,12.6699,100,1,14.1999,200,2,12.4700,100,1,14.3399,100,1,12.4600,100,1,14.4399,100,1,12.3599,200,2,14.6500,2,1,12.3300,102,2,14.7400,200,2,12.2300,100,1,14.9000,200,2,11.9299,200,2,15.2799,100,1,ARL,44066417
368,2025-07-17T13:30:02.378286605Z,2025-07-17T13:30:02.378286605Z,10,2,1108,C,B,0,11.2899,100,128,167993,29585502,13.1999,28,1,13.6699,100,1,12.9900,100,1,13.9299,100,1,12.7300,100,1,14.0000,100,1,12.6699,100,1,14.1999,200,2,12.4700,100,1,14.3399,100,1,12.4600,100,1,14.4399,100,1,12.3599,200,2,14.6500,2,1,12.3300,102,2,14.7400,200,2,12.2300,100,1,14.9000,200,2,11.9299,200,2,15.2799,100,1,ARL,42099317
369,2025-07-17T13:30:02.378293244Z,2025-07-17T13:30:02.378293244Z,10,2,1108,C,A,0,15.9100,100,130,165639,29585504,13.1999,28,1,13.6699,100,1,12.9900,100,1,13.9299,100,1,12.7300,100,1,14.0000,100,1,12.6699,100,1,14.1999,200,2,12.4700,100,1,14.3399,100,1,12.4600,100,1,14.4399,100,1,12.3599,200,2,14.6500,2,1,12.3300,102,2,14.7400,200,2,12.2300,100,1,14.9000,200,2,11.9299,200,2,15.2799,100,1,ARL,42099321
370,2025-07-17T13:30:02.476818222Z,2025-07-17T13:30:02.476818222Z,10,2,1108,C,A,0,14.9000,100,0,165584,29601178,13.1999,28,1,13.6699,100,1,12.9900,100,1,13.9299,100,1,12.7300,100,1,14.0000,100,1,12.6699,100,1,14.1999,200,2,12.4700,100,1,14.3399,100,1,12.4600,100,1,14.4399,100,1,12.3599,200,2,14.6500,2,1,12.3300,102,2,14.7400,200,2,12.2300,100,1,14.9000,100,1,11.9299,200,2,15.2799,100,1,ARL,43781545
371,2025-07-17T13:30:02.476818222Z,2025-07-17T13:30:02.476818222Z,10,2,1108,A,A,0,14.5700,100,130,165584,29601178,13.1999,28,1,13.6699,100,1,12.9900,100,1,13.9299,100,1,12.7300,100,1,14.0000,100,1,12.6699,100,1,14.1999,200,2,12.4700,100,1,14.3399,100,1,12.4600,100,1,14.4399,100,1,12.3599,200,2,14.5700,100,1,12.3300,102,2,14.6500,2,1,12.2300,100,1,14.7400,200,2,11.9299,200,2,14.9000,100,1,ARL,44076709
372,2025-07-17T13:30:02.483131658Z,2025-07-17T13:30:02.483131658Z,10,2,1108,C,A,0,14.9000,100,0,166103,29601999,13.1999,28,1,13.6699,100,1,12.9900,100,1,13.9299,100,1,12.7300,100,1,14.0000,100,1,12.6699,100,1,14.1999,200,2,12.4700,100,1,14.3399,100,1,12.4600,100,1,14.4399,100,1,12.3599,200,2,14.5700,100,1,12.3300,102,2,14.6500,2,1,12.2300,100,1,14.7400,200,2,11.9299,200,2,15.2799,100,1,ARL,43787985
373,2025-07-17T13:30:02.483131658Z,2025-07-17T13:30:02.483131658Z,10,2,1108,A,A,0,14.5700,100,130,166103,29601999,13.1999,28,1,13.6699,100,1,12.9900,100,1,13.9299,100,1,12.7300,100,1,14.0000,100,1,12.6699,100,1,14.1999,200,2,12.4700,100,1,14.3399,100,1,12.4600,100,1,14.4399,100,1,12.3599,200,2,14.5700,200,2,12.3300,102,2,14.6500,2,1,12.2300,100,1,14.7400,200,2,11.9299,200,2,15.2799,100,1,ARL,44077497
374,2025-07-17T13:30:02.524755932Z,2025-07-17T13:30:02.524755932Z,10,2,1108,C,B,0,8.5800,100,0,165854,29608933,13.1999,28,1,13.6699,100,1,12.9900,100,1,13.9299,100,1,12.7300,100,1,14.0000,100,1,12.6699,100,1,14.1999,200,2,12.4700,100,1,14.3399,100,1,12.4600,100,1,14.4399,100,1,12.3599,200,2,14.5700,200,2,12.3300,102,2,14.6500,2,1,12.2300,100,1,14.7400,200,2,11.9299,200,2,15.2799,100,1,ARL,41376733
375,2025-07-17T13:30:02.524755932Z,2025-07-17T13:30:02.524755932Z,10,2,1108,A,B,0,9.6699,100,130,165854,29608933,13.1999,28,1,13.6699,100,1,12.9900,100,1,13.9299,100,1,12.7300,100,1,14.0000,100,1,12.6699,100,1,14.1999,200,2,12.4700,100,1,14.3399,100,1,12.4600,100,1,14.4399,100,1,12.3599,200,2,14.5700,200,2,12.3300,102,2,14.6500,2,1,12.2300,100,1,14.7400,200,2,11.9299,200,2,15.2799,100,1,ARL,44082961
376,2025-07-17T13:30:02.524769583Z,2025-07-17T13:30:02.524769583Z,10,2,1108,C,A,0,19.4400,100,0,165598,29608936,13.1999,28,1,13.6699,100,1,12.9900,100,1,13.9299,100,1,12.7300,100,1,14.0000,100,1,12.6699,100,1,14.1999,200,2,12.4700,100,1,14.3399,100,1,12.4600,100,1,14.4399,100,1,12.3599,200,2,14.5700,200,2,12.3300,102,2,14.6500,2,1,12.2300,100,1,14.7400,200,2,11.9299,200,2,15.2799,100,1,ARL,41372549
377,2025-07-17T13:30:02.524769583Z,2025-07-17T13:30:02.524769583Z,10,2,1108,A,A,0,17.0199,100,130,165598,29608936,13.1999,28,1,13.6699,100,1,12.9900,100,1,13.9299,100,1,12.7300,100,1,14.0000,100,1,12.6699,100,1,14.1999,200,2,12.4700,100,1,14.3399,100,1,12.4600,100,1,14.4399,100,1,12.3599,200,2,14.5700,200,2,12.3300,102,2,14.6500,2,1,12.2300,100,1,14.7400,200,2,11.9299,200,2,15.2799,100,1,ARL,44082969
378,2025-07-17T13:30:02.573606685Z,2025-07-17T13:30:02.573606685Z,10,2,1108,C,B,0,10.9299,100,0,167628,29618524,13.1999,28,1,13.6699,100,1,12.9900,100,1,13.9299,100,1,12.7300,100,1,14.0000,100,1,12.6699,100,1,14.1999,200,2,12.4700,100,1,14.3399,100,1,12.4600,100,1,14.4399,100,1,12.3599,200,2,14.5700,200,2,12.3300,102,2,14.6500,2,1,12.2300,100,1,14.7400,200,2,11.9299,200,2,15.2799,100,1,ARL,41379985
379,2025-07-17T13:30:02.573606685Z,2025-07-17T13:30:02.573606685Z,10,2,1108,A,B,0,12.3300,100,128,167628,29618524,13.1999,28,1,13.6699,100,1,12.9900,100,1,13.9299,100,1,12.7300,100,1,14.0000,100,1,12.6699,100,1,14.1999,200,2,12.4700,100,1,14.3399,100,1,12.4600,100,1,14.4399,100,1,12.3599,200,2,14.5700,200,2,12.3300,202,3,14.6500,2,1,12.2300,100,1,14.7400,200,2,11.9299,200,2,15.2799,100,1,ARL,44088633
380,2025-07-17T13:30:02.573623478Z,2025-07-17T13:30:02.573623478Z,10,2,1108,C,A,0,16.3799,100,0,168568,29618531,13.1999,28,1,13.6699,100,1,12.9900,100,1,13.9299,100,1,12.7300,100,1,14.0000,100,1,12.6699,100,1,14.1999,200,2,12.4700,100,1,14.3399,100,1,12.4600,100,1,14.4399,100,1,12.3599,200,2,14.5700,200,2,12.3300,202,3,14.6500,2,1,12.2300,100,1,14.7400,200,2,11.9299,200,2,15.2799,100,1,ARL,41372369
381,2025-07-17T13:30:02.573623478Z,2025-07-17T13:30:02.573623478Z,10,2,1108,A,A,0,14.3399,100,128,168568,29618531,13.1999,28,1,13.6699,100,1,12.9900,100,1,13.9299,100,1,12.7300,100,1,14.0000,100,1,12.6699,100,1,14.1999,200,2,12.4700,100,1,14.3399,200,2,12.4600,100,1,14.4399,100,1,12.3599,200,2,14.5700,200,2,12.3300,202,3,14.6500,2,1,12.2300,100,1,14.7400,200,2,11.9299,200,2,15.2799,100,1,ARL,44088637
382,2025-07-17T13:30:06.757383618Z,2025-07-17T13:30:06.757383618Z,10,2,1108,A,A,0,14.2699,700,130,165451,30107583,13.1999,28,1,13.6699,100,1,12.9900,100,1,13.9299,100,1,12.7300,100,1,14.0000,100,1,12.6699,100,1,14.1999,200,2,12.4700,100,1,14.2699,700,1,12.4600,100,1,14.3399,200,2,12.3599,200,2,14.4399,100,1,12.3300,202,3,14.5700,200,2,12.2300,100,1,14.6500,2,1,11.9299,200,2,14.7400,200,2,ARL,44491681
383,2025-07-17T13:30:06.757435491Z,2025-07-17T13:30:06.757435491Z,10,2,1108,C,A,0,16.1499,700,130,165425,30107590,13.1999,28,1,13.6699,100,1,12.9900,100,1,13.9299,100,1,12.7300,100,1,14.0000,100,1,12.6699,100,1,14.1999,200,2,12.4700,100,1,14.2699,700,1,12.4600,100,1,14.3399,200,2,12.3599,200,2,14.4399,100,1,12.3300,202,3,14.5700,200,2,12.2300,100,1,14.6500,2,1,11.9299,200,2,14.7400,200,2,ARL,41528029
384,2025-07-17T13:30:07.194841610Z,2025-07-17T13:30:07.194841610Z,10,2,1108,A,A,0,15.3000,700,130,165270,30150210,13.1999,28,1,13.6699,100,1,12.9900,100,1,13.9299,100,1,12.7300,100,1,14.0000,100,1,12.6699,100,1,14.1999,200,2,12.4700,100,1,14.2699,700,1,12.4600,100,1,14.3399,200,2,12.3599,200,2,14.4399,100,1,12.3300,202,3,14.5700,200,2,12.2300,100,1,14.6500,2,1,11.9299,200,2,14.7400,200,2,ARL,44520965
385,2025-07-17T13:30:07.194880522Z,2025-07-17T13:30:07.194880522Z,10,2,1108,C,A,0,16.3000,700,128,166407,30150214,13.1999,28,1,13.6699,100,1,12.9900,100,1,13.9299,100,1,12.7300,100,1,14.0000,100,1,12.6699,100,1,14.1999,200,2,12.4700,100,1,14.2699,700,1,12.4600,100,1,14.3399,200,2,12.3599,200,2,14.4399,100,1,12.3300,202,3,14.5700,200,2,12.2300,100,1,14.6500,2,1,11.9299,200,2,14.7400,200,2,ARL,41375973
386,2025-07-17T13:30:07.394882479Z,2025-07-17T13:30:07.394882479Z,10,2,1108,A,A,0,15.0000,700,130,165154,30169157,13.1999,28,1,13.6699,100,1,12.9900,100,1,13.9299,100,1,12.7300,100,1,14.0000,100,1,12.6699,100,1,14.1999,200,2,12.4700,100,1,14.2699,700,1,12.4600,100,1,14.3399,200,2,12.3599,200,2,14.4399,100,1,12.3300,202,3,14.5700,200,2,12.2300,100,1,14.6500,2,1,11.9299,200,2,14.7400,200,2,ARL,44533061
387,2025-07-17T13:30:07.395357697Z,2025-07-17T13:30:07.395357697Z,10,2,1108,C,A,0,15.3000,700,130,165147,30169278,13.1999,28,1,13.6699,100,1,12.9900,100,1,13.9299,100,1,12.7300,100,1,14.0000,100,1,12.6699,100,1,14.1999,200,2,12.4700,100,1,14.2699,700,1,12.4600,100,1,14.3399,200,2,12.3599,200,2,14.4399,100,1,12.3300,202,3,14.5700,200,2,12.2300,100,1,14.6500,2,1,11.9299,200,2,14.7400,200,2,ARL,44520965
388,2025-07-17T13:30:07.594772046Z,2025-07-17T13:30:07.594772046Z,10,2,1108,A,A,0,14.6999,700,128,176513,30189080,13.1999,28,1,13.6699,100,1,12.9900,100,1,13.9299,100,1,12.7300,100,1,14.0000,100,1,12.6699,100,1,14.1999,200,2,12.4700,100,1,14.2699,700,1,12.4600,100,1,14.3399,200,2,12.3599,200,2,14.4399,100,1,12.3300,202,3,14.5700,200,2,12.2300,100,1,14.6500,2,1,11.9299,200,2,14.6999,700,1,ARL,44545381
389,2025-07-17T13:30:07.594797098Z,2025-07-17T13:30:07.594797098Z,10,2,1108,C,A,0,15.0000,700,130,165138,30189120,13.1999,28,1,13.6699,100,1,12.9900,100,1,13.9299,100,1,12.7300,100,1,14.0000,100,1,12.6699,100,1,14.1999,200,2,12.4700,100,1,14.2699,700,1,12.4600,100,1,14.3399,200,2,12.3599,200,2,14.4399,100,1,12.3300,202,3,14.5700,200,2,12.2300,100,1,14.6500,2,1,11.9299,200,2,14.6999,700,1,ARL,44533061
390,2025-07-17T13:30:07.663083798Z,2025-07-17T13:30:07.663083798Z,10,2,1108,A,A,0,14.4600,700,130,165352,30194197,13.1999,28,1,13.6699,100,1,12.9900,100,1,13.9299,100,1,12.7300,100,1,14.0000,100,1,12.6699,100,1,14.1999,200,2,12.4700,100,1,14.2699,700,1,12.4600,100,1,14.3399,200,2,12.3599,200,2,14.4399,100,1,12.3300,202,3,14.4600,700,1,12.2300,100,1,14.5700,200,2,11.9299,200,2,14.6500,2,1,ARL,44548325
391,2025-07-17T13:30:07.663798482Z,2025-07-17T13:30:07.663798482Z,10,2,1108,C,A,0,14.6999,700,130,165092,30194234,13.1999,28,1,13.6699,100,1,12.9900,100,1,13.9299,100,1,12.7300,100,1,14.0000,100,1,12.6699,100,1,14.1999,200,2,12.4700,100,1,14.2699,700,1,12.4600,100,1,14.3399,200,2,12.3599,200,2,14.4399,100,1,12.3300,202,3,14.4600,700,1,12.2300,100,1,14.5700,200,2,11.9299,200,2,14.6500,2,1,ARL,44545381
392,2025-07-17T13:30:07.914271879Z,2025-07-17T13:30:07.914271879Z,10,2,1108,A,B,0,11.7599,700,130,165347,30213834,13.1999,28,1,13.6699,100,1,12.9900,100,1,13.9299,100,1,12.7300,100,1,14.0000,100,1,12.6699,100,1,14.1999,200,2,12.4700,100,1,14.2699,700,1,12.4600,100,1,14.3399,200,2,12.3599,200,2,14.4399,100,1,12.3300,202,3,14.4600,700,1,12.2300,100,1,14.5700,200,2,11.9299,200,2,14.6500,2,1,ARL,44560257
393,2025-07-17T13:30:07.914949951Z,2025-07-17T13:30:07.914949951Z,10,2,1108,C,B,0,10.9900,700,130,165463,30213941,13.1999,28,1,13.6699,100,1,12.9900,100,1,13.9299,100,1,12.7300,100,1,14.0000,100,1,12.6699,100,1,14.1999,200,2,12.4700,100,1,14.2699,700,1,12.4600,100,1,14.3399,200,2,12.3599,200,2,14.4399,100,1,12.3300,202,3,14.4600,700,1,12.2300,100,1,14.5700,200,2,11.9299,200,2,14.6500,2,1,ARL,41509393
394,2025-07-17T13:30:08.025660842Z,2025-07-17T13:30:08.025660842Z,10,2,1108,A,B,0,12.0199,700,130,165350,30224657,13.1999,28,1,13.6699,100,1,12.9900,100,1,13.9299,100,1,12.7300,100,1,14.0000,100,1,12.6699,100,1,14.1999,200,2,12.4700,100,1,14.2699,700,1,12.4600,100,1,14.3399,200,2,12.3599,200,2,14.4399,100,1,12.3300,202,3,14.4600,700,1,12.2300,100,1,14.5700,200,2,12.0199,700,1,14.6500,2,1,ARL,44565617
395,2025-07-17T13:30:08.025673570Z,2025-07-17T13:30:08.025673570Z,10,2,1108,C,B,0,11.7599,700,130,165018,30224658,13.1999,28,1,13.6699,100,1,12.9900,100,1,13.9299,100,1,12.7300,100,1,14.0000,100,1,12.6699,100,1,14.1999,200,2,12.4700,100,1,14.2699,700,1,12.4600,100,1,14.3399,200,2,12.3599,200,2,14.4399,100,1,12.3300,202,3,14.4600,700,1,12.2300,100,1,14.5700,200,2,12.0199,700,1,14.6500,2,1,ARL,44560257
396,2025-07-17T13:30:08.114272470Z,2025-07-17T13:30:08.114272470Z,10,2,1108,A,B,0,12.2599,700,130,165367,30233944,13.1999,28,1,13.6699,100,1,12.9900,100,1,13.9299,100,1,12.7300,100,1,14.0000,100,1,12.6699,100,1,14.1999,200,2,12.4700,100,1,14.2699,700,1,12.4600,100,1,14.3399,200,2,12.3599,200,2,14.4399,100,1,12.3300,202,3,14.4600,700,1,12.2599,700,1,14.5700,200,2,12.2300,100,1,14.6500,2,1,ARL,44570585
397,2025-07-17T13:30:08.115068904Z,2025-07-17T13:30:08.115068904Z,10,2,1108,C,B,0,12.0199,700,130,165580,30234078,13.1999,28,1,13.6699,100,1,12.9900,100,1,13.9299,100,1,12.7300,100,1,14.0000,100,1,12.6699,100,1,14.1999,200,2,12.4700,100,1,14.2699,700,1,12.4600,100,1,14.3399,200,2,12.3599,200,2,14.4399,100,1,12.3300,202,3,14.4600,700,1,12.2599,700,1,14.5700,200,2,12.2300,100,1,14.6500,2,1,ARL,44565617
398,2025-07-17T13:30:08.394373251Z,2025-07-17T13:30:08.394373251Z,10,2,1108,A,B,0,13.2500,11,130,165414,30258008,13.2500,11,1,13.6699,100,1,13.1999,28,1,13.9299,100,1,12.9900,100,1,14.0000,100,1,12.7300,100,1,14.1999,200,2,12.6699,100,1,14.2699,700,1,12.4700,100,1,14.3399,200,2,12.4600,100,1,14.4399,100,1,12.3599,200,2,14.4600,700,1,12.3300,202,3,14.5700,200,2,12.2599,700,1,14.6500,2,1,ARL,44586753
399,2025-07-17T13:30:08.402012613Z,2025-07-17T13:30:08.402012613Z,10,2,1108,C,B,0,13.1999,28,130,165269,30259240,13.2500,11,1,13.6699,100,1,12.9900,100,1,13.9299,100,1,12.7300,100,1,14.0000,100,1,12.6699,100,1,14.1999,200,2,12.4700,100,1,14.2699,700,1,12.4600,100,1,14.3399,200,2,12.3599,200,2,14.4399,100,1,12.3300,202,3,14.4600,700,1,12.2599,700,1,14.5700,200,2,12.2300,100,1,14.6500,2,1,ARL,43820541
400,2025-07-17T13:30:08.512579639Z,2025-07-17T13:30:08.512579639Z,10,2,1108,A,A,0,14.2599,700,130,165281,30276907,13.2500,11,1,13.6699,100,1,12.9900,100,1,13.9299,100,1,12.7300,100,1,14.0000,100,1,12.6699,100,1,14.1999,200,2,12.4700,100,1,14.2599,700,1,12.4600,100,1,14.2699,700,1,12.3599,200,2,14.3399,200,2,12.3300,202,3,14.4399,100,1,12.2599,700,1,14.4600,700,1,12.2300,100,1,14.5700,200,2,ARL,44598153
401,2025-07-17T13:30:08.512974877Z,2025-07-17T13:30:08.512974877Z,10,2,1108,C,A,0,16.1099,700,130,166005,30276990,13.2500,11,1,13.6699,100,1,12.9900,100,1,13.9299,100,1,12.7300,100,1,14.0000,100,1,12.6699,100,1,14.1999,200,2,12.4700,100,1,14.2599,700,1,12.4600,100,1,14.2699,700,1,12.3599,200,2,14.3399,200,2,12.3300,202,3,14.4399,100,1,12.2599,700,1,14.4600,700,1,12.2300,100,1,14.5700,200,2,ARL,41371225
402,2025-07-17T13:30:09.128991840Z,2025-07-17T13:30:09.128991840Z,10,2,1108,A,B,0,11.7599,700,128,166428,30336805,13.2500,11,1,13.6699,100,1,12.9900,100,1,13.9299,100,1,12.7300,100,1,14.0000,100,1,12.6699,100,1,14.1999,200,2,12.4700,100,1,14.2599,700,1,12.4600,100,1,14.2699,700,1,12.3599,200,2,14.3399,200,2,12.3300,202,3,14.4399,100,1,12.2599,700,1,14.4600,700,1,12.2300,100,1,14.5700,200,2,ARL,44628617
403,2025-07-17T13:30:09.129006013Z,2025-07-17T13:30:09.129006013Z,10,2,1108,C,B,0,11.0700,700,130,165554,30336807,13.2500,11,1,13.6699,100,1,12.9900,100,1,13.9299,100,1,12.7300,100,1,14.0000,100,1,12.6699,100,1,14.1999,200,2,12.4700,100,1,14.2599,700,1,12.4600,100,1,14.2699,700,1,12.3599,200,2,14.3399,200,2,12.3300,202,3,14.4399,100,1,12.2599,700,1,14.4600,700,1,12.2300,100,1,14.5700,200,2,ARL,41539477
404,2025-07-17T13:30:09.329050977Z,2025-07-17T13:30:09.329050977Z,10,2,1108,A,B,0,12.0199,700,130,165582,30353905,13.2500,11,1,13.6699,100,1,12.9900,100,1,13.9299,100,1,12.7300,100,1,14.0000,100,1,12.6699,100,1,14.1999,200,2,12.4700,100,1,14.2599,700,1,12.4600,100,1,14.2699,700,1,12.3599,200,2,14.3399,200,2,12.3300,202,3,14.4399,100,1,12.2599,700,1,14.4600,700,1,12.2300,100,1,14.5700,200,2,ARL,44641397
405,2025-07-17T13:30:09.329118219Z,2025-07-17T13:30:09.329118219Z,10,2,1108,C,B,0,11.7599,700,130,165285,30353910,13.2500,11,1,13.6699,100,1,12.9900,100,1,13.9299,100,1,12.7300,100,1,14.0000,100,1,12.6699,100,1,14.1999,200,2,12.4700,100,1,14.2599,700,1,12.4600,100,1,14.2699,700,1,12.3599,200,2,14.3399,200,2,12.3300,202,3,14.4399,100,1,12.2599,700,1,14.4600,700,1,12.2300,100,1,14.5700,200,2,ARL,44628617
406,2025-07-17T13:30:10.081175039Z,2025-07-17T13:30:10.081175039Z,10,2,1108,A,A,0,13.4000,10,130,165480,30441651,13.2500,11,1,13.4000,10,1,12.9900,100,1,13.6699,100,1,12.7300,100,1,13.9299,100,1,12.6699,100,1,14.0000,100,1,12.4700,100,1,14.1999,200,2,12.4600,100,1,14.2599,700,1,12.3599,200,2,14.2699,700,1,12.3300,202,3,14.3399,200,2,12.2599,700,1,14.4399,100,1,12.2300,100,1,14.4600,700,1,ARL,44719917
407,2025-07-17T13:30:10.082150107Z,2025-07-17T13:30:10.082150107Z,10,2,1108,C,A,0,14.5700,100,0,165551,30441855,13.2500,11,1,13.4000,10,1,12.9900,100,1,13.6699,100,1,12.7300,100,1,13.9299,100,1,12.6699,100,1,14.0000,100,1,12.4700,100,1,14.1999,200,2,12.4600,100,1,14.2599,700,1,12.3599,200,2,14.2699,700,1,12.3300,202,3,14.3399,200,2,12.2599,700,1,14.4399,100,1,12.2300,100,1,14.4600,700,1,ARL,44076709
408,2025-07-17T13:30:10.082150107Z,2025-07-17T13:30:10.082150107Z,10,2,1108,A,A,0,14.2899,100,130,165551,30441855,13.2500,11,1,13.4000,10,1,12.9900,100,1,13.6699,100,1,12.7300,100,1,13.9299,100,1,12.6699,100,1,14.0000,100,1,12.4700,100,1,14.1999,200,2,12.4600,100,1,14.2599,700,1,12.3599,200,2,14.2699,700,1,12.3300,202,3,14.2899,100,1,12.2599,700,1,14.3399,200,2,12.2300,100,1,14.4399,100,1,ARL,44719985
409,2025-07-17T13:30:10.082662762Z,2025-07-17T13:30:10.082662762Z,10,2,1108,C,A,0,14.5700,100,0,165590,30441930,13.2500,11,1,13.4000,10,1,12.9900,100,1,13.6699,100,1,12.7300,100,1,13.9299,100,1,12.6699,100,1,14.0000,100,1,12.4700,100,1,14.1999,200,2,12.4600,100,1,14.2599,700,1,12.3599,200,2,14.2699,700,1,12.3300,202,3,14.2899,100,1,12.2599,700,1,14.3399,200,2,12.2300,100,1,14.4399,100,1,ARL,44077497
410,2025-07-17T13:30:10.082662762Z,2025-07-17T13:30:10.082662762Z,10,2,1108,A,A,0,14.2899,100,130,165590,30441930,13.2500,11,1,13.4000,10,1,12.9900,100,1,13.6699,100,1,12.7300,100,1,13.9299,100,1,12.6699,100,1,14.0000,100,1,12.4700,100,1,14.1999,200,2,12.4600,100,1,14.2599,700,1,12.3599,200,2,14.2699,700,1,12.3300,202,3,14.2899,200,2,12.2599,700,1,14.3399,200,2,12.2300,100,1,14.4399,100,1,ARL,44720033
411,2025-07-17T13:30:10.084896414Z,2025-07-17T13:30:10.084896414Z,10,2,1108,A,B,0,12.4199,700,130,165787,30442720,13.2500,11,1,13.4000,10,1,12.9900,100,1,13.6699,100,1,12.7300,100,1,13.9299,100,1,12.6699,100,1,14.0000,100,1,12.4700,100,1,14.1999,200,2,12.4600,100,1,14.2599,700,1,12.4199,700,1,14.2699,700,1,12.3599,200,2,14.2899,200,2,12.3300,202,3,14.3399,200,2,12.2599,700,1,14.4399,100,1,ARL,44720357
412,2025-07-17T13:30:10.085332605Z,2025-07-17T13:30:10.085332605Z,10,2,1108,C,B,0,11.1400,700,130,165165,30442750,13.2500,11,1,13.4000,10,1,12.9900,100,1,13.6699,100,1,12.7300,100,1,13.9299,100,1,12.6699,100,1,14.0000,100,1,12.4700,100,1,14.1999,200,2,12.4600,100,1,14.2599,700,1,12.4199,700,1,14.2699,700,1,12.3599,200,2,14.2899,200,2,12.3300,202,3,14.3399,200,2,12.2599,700,1,14.4399,100,1,ARL,41534785
413,2025-07-17T13:30:12.194582572Z,2025-07-17T13:30:12.194582572Z,10,2,1108,C,A,0,14.6500,2,0,165601,30681385,13.2500,11,1,13.4000,10,1,12.9900,100,1,13.6699,100,1,12.7300,100,1,13.9299,100,1,12.6699,100,1,14.0000,100,1,12.4700,100,1,14.1999,200,2,12.4600,100,1,14.2599,700,1,12.4199,700,1,14.2699,700,1,12.3599,200,2,14.2899,200,2,12.3300,202,3,14.3399,200,2,12.2599,700,1,14.4399,100,1,ARL,43692157
414,2025-07-17T13:30:12.194582572Z,2025-07-17T13:30:12.194582572Z,10,2,1108,A,A,0,14.4299,2,130,165601,30681385,13.2500,11,1,13.4000,10,1,12.9900,100,1,13.6699,100,1,12.7300,100,1,13.9299,100,1,12.6699,100,1,14.0000,100,1,12.4700,100,1,14.1999,200,2,12.4600,100,1,14.2599,700,1,12.4199,700,1,14.2699,700,1,12.3599,200,2,14.2899,200,2,12.3300,202,3,14.3399,200,2,12.2599,700,1,14.4299,2,1,ARL,44904733
415,2025-07-17T13:30:14.128932140Z,2025-07-17T13:30:14.128932140Z,10,2,1108,A,B,0,12.3699,700,130,165430,30851531,13.2500,11,1,13.4000,10,1,12.9900,100,1,13.6699,100,1,12.7300,100,1,13.9299,100,1,12.6699,100,1,14.0000,100,1,12.4700,100,1,14.1999,200,2,12.4600,100,1,14.2599,700,1,12.4199,700,1,14.2699,700,1,12.3699,700,1,14.2899,200,2,12.3599,200,2,14.3399,200,2,12.3300,202,3,14.4299,2,1,ARL,45025165
416,2025-07-17T13:30:14.129008546Z,2025-07-17T13:30:14.129008546Z,10,2,1108,C,B,0,12.0199,700,130,165480,30851532,13.2500,11,1,13.4000,10,1,12.9900,100,1,13.6699,100,1,12.7300,100,1,13.9299,100,1,12.6699,100,1,14.0000,100,1,12.4700,100,1,14.1999,200,2,12.4600,100,1,14.2599,700,1,12.4199,700,1,14.2699,700,1,12.3699,700,1,14.2899,200,2,12.3599,200,2,14.3399,200,2,12.3300,202,3,14.4299,2,1,ARL,44641397
417,2025-07-17T13:30:23.695564208Z,2025-07-17T13:30:23.695564208Z,10,2,1108,A,A,0,13.4000,12,130,165276,31649134,13.2500,11,1,13.4000,22,2,12.9900,100,1,13.6699,100,1,12.7300,100,1,13.9299,100,1,12.6699,100,1,14.0000,100,1,12.4700,100,1,14.1999,200,2,12.4600,100,1,14.2599,700,1,12.4199,700,1,14.2699,700,1,12.3699,700,1,14.2899,200,2,12.3599,200,2,14.3399,200,2,12.3300,202,3,14.4299,2,1,ARL,45593201
418,2025-07-17T13:30:25.512069243Z,2025-07-17T13:30:25.512069243Z,10,2,1108,C,A,0,13.4000,10,128,166200,31806233,13.2500,11,1,13.4000,12,1,12.9900,100,1,13.6699,100,1,12.7300,100,1,13.9299,100,1,12.6699,100,1,14.0000,100,1,12.4700,100,1,14.1999,200,2,12.4600,100,1,14.2599,700,1,12.4199,700,1,14.2699,700,1,12.3699,700,1,14.2899,200,2,12.3599,200,2,14.3399,200,2,12.3300,202,3,14.4299,2,1,ARL,44719917
419,2025-07-17T13:30:26.553160650Z,2025-07-17T13:30:26.553160650Z,10,2,1108,A,A,0,13.4000,10,130,165329,31897785,13.2500,11,1,13.4000,22,2,12.9900,100,1,13.6699,100,1,12.7300,100,1,13.9299,100,1,12.6699,100,1,14.0000,100,1,12.4700,100,1,14.1999,200,2,12.4600,100,1,14.2599,700,1,12.4199,700,1,14.2699,700,1,12.3699,700,1,14.2899,200,2,12.3599,200,2,14.3399,200,2,12.3300,202,3,14.4299,2,1,ARL,45748261
420,2025-07-17T13:30:35.240400172Z,2025-07-17T13:30:35.240400172Z,10,2,1108,C,A,0,13.4000,10,130,169818,32725426,13.2500,11,1,13.4000,12,1,12.9900,100,1,13.6699,100,1,12.7300,100,1,13.9299,100,1,12.6699,100,1,14.0000,100,1,12.4700,100,1,14.1999,200,2,12.4600,100,1,14.2599,700,1,12.4199,700,1,14.2699,700,1,12.3699,700,1,14.2899,200,2,12.3599,200,2,14.3399,200,2,12.3300,202,3,14.4299,2,1,ARL,45748261
421,2025-07-17T13:30:43.952999157Z,2025-07-17T13:30:43.952999157Z,10,2,1108,C,A,0,13.4000,12,130,165229,33659635,13.2500,11,1,13.6699,100,1,12.9900,100,1,13.9299,100,1,12.7300,100,1,14.0000,100,1,12.6699,100,1,14.1999,200,2,12.4700,100,1,14.2599,700,1,12.4600,100,1,14.2699,700,1,12.4199,700,1,14.2899,200,2,12.3699,700,1,14.3399,200,2,12.3599,200,2,14.4299,2,1,12.3300,202,3,14.4399,100,1,ARL,45593201
422,2025-07-17T13:30:43.953363128Z,2025-07-17T13:30:43.953363128Z,10,2,1108,A,A,0,13.4000,24,130,165363,33659657,13.2500,11,1,13.4000,24,1,12.9900,100,1,13.6699,100,1,12.7300,100,1,13.9299,100,1,12.6699,100,1,14.0000,100,1,12.4700,100,1,14.1999,200,2,12.4600,100,1,14.2599,700,1,12.4199,700,1,14.2699,700,1,12.3699,700,1,14.2899,200,2,12.3599,200,2,14.3399,200,2,12.3300,202,3,14.4299,2,1,ARL,46613073
423,2025-07-17T13:30:47.814108950Z,2025-07-17T13:30:47.814108950Z,10,2,1108,A,A,0,13.4000,10,130,166303,34075767,13.2500,11,1,13.4000,34,2,12.9900,100,1,13.6699,100,1,12.7300,100,1,13.9299,100,1,12.6699,100,1,14.0000,100,1,12.4700,100,1,14.1999,200,2,12.4600,100,1,14.2599,700,1,12.4199,700,1,14.2699,700,1,12.3699,700,1,14.2899,200,2,12.3599,200,2,14.3399,200,2,12.3300,202,3,14.4299,2,1,ARL,46784085
424,2025-07-17T13:30:48.271611303Z,2025-07-17T13:30:48.271611303Z,10,2,1108,C,A,0,13.4000,10,130,166528,34129837,13.2500,11,1,13.4000,24,1,12.9900,100,1,13.6699,100,1,12.7300,100,1,13.9299,100,1,12.6699,100,1,14.0000,100,1,12.4700,100,1,14.1999,200,2,12.4600,100,1,14.2599,700,1,12.4199,700,1,14.2699,700,1,12.3699,700,1,14.2899,200,2,12.3599,200,2,14.3399,200,2,12.3300,202,3,14.4299,2,1,ARL,46784085
425,2025-07-17T13:30:56.518283181Z,2025-07-17T13:30:56.518283181Z,10,2,1108,A,A,0,13.4000,10,130,165400,34951153,13.2500,11,1,13.4000,34,2,12.9900,100,1,13.6699,100,1,12.7300,100,1,13.9299,100,1,12.6699,100,1,14.0000,100,1,12.4700,100,1,14.1999,200,2,12.4600,100,1,14.2599,700,1,12.4199,700,1,14.2699,700,1,12.3699,700,1,14.2899,200,2,12.3599,200,2,14.3399,200,2,12.3300,202,3,14.4299,2,1,ARL,47164169
426,2025-07-17T13:31:01.011743292Z,2025-07-17T13:31:01.011743292Z,10,2,1108,A,A,0,14.1999,700,128,166113,35180694,13.2500,11,1,13.4000,34,2,12.9900,100,1,13.6699,100,1,12.7300,100,1,13.9299,100,1,12.6699,100,1,14.0000,100,1,12.4700,100,1,14.1999,900,3,12.4600,100,1,14.2599,700,1,12.4199,700,1,14.2699,700,1,12.3699,700,1,14.2899,200,2,12.3599,200,2,14.3399,200,2,12.3300,202,3,14.4299,2,1,ARL,47376925
427,2025-07-17T13:31:01.028848502Z,2025-07-17T13:31:01.028848502Z,10,2,1108,A,B,0,12.4299,700,130,165268,35188622,13.2500,11,1,13.4000,34,2,12.9900,100,1,13.6699,100,1,12.7300,100,1,13.9299,100,1,12.6699,100,1,14.0000,100,1,12.4700,100,1,14.1999,900,3,12.4600,100,1,14.2599,700,1,12.4299,700,1,14.2699,700,1,12.4199,700,1,14.2899,200,2,12.3699,700,1,14.3399,200,2,12.3599,200,2,14.4299,2,1,ARL,47383873
428,2025-07-17T13:31:01.131557345Z,2025-07-17T13:31:01.131557345Z,10,2,1108,C,A,0,13.4000,10,128,168465,35203355,13.2500,11,1,13.4000,24,1,12.9900,100,1,13.6699,100,1,12.7300,100,1,13.9299,100,1,12.6699,100,1,14.0000,100,1,12.4700,100,1,14.1999,900,3,12.4600,100,1,14.2599,700,1,12.4299,700,1,14.2699,700,1,12.4199,700,1,14.2899,200,2,12.3699,700,1,14.3399,200,2,12.3599,200,2,14.4299,2,1,ARL,47164169
429,2025-07-17T13:31:08.376321454Z,2025-07-17T13:31:08.376321454Z,10,2,1108,C,A,0,13.4000,24,130,165179,35703639,13.2500,11,1,13.6699,100,1,12.9900,100,1,13.9299,100,1,12.7300,100,1,14.0000,100,1,12.6699,100,1,14.1999,900,3,12.4700,100,1,14.2599,700,1,12.4600,100,1,14.2699,700,1,12.4299,700,1,14.2899,200,2,12.4199,700,1,14.3399,200,2,12.3699,700,1,14.4299,2,1,12.3599,200,2,14.4399,100,1,ARL,46613073
430,2025-07-17T13:31:08.376692815Z,2025-07-17T13:31:08.376692815Z,10,2,1108,A,A,0,13.4000,18,130,165233,35703653,13.2500,11,1,13.4000,18,1,12.9900,100,1,13.6699,100,1,12.7300,100,1,13.9299,100,1,12.6699,100,1,14.0000,100,1,12.4700,100,1,14.1999,900,3,12.4600,100,1,14.2599,700,1,12.4299,700,1,14.2699,700,1,12.4199,700,1,14.2899,200,2,12.3699,700,1,14.3399,200,2,12.3599,200,2,14.4299,2,1,ARL,47873813
431,2025-07-17T13:31:08.377022927Z,2025-07-17T13:31:08.377022927Z,10,2,1108,C,A,0,14.2899,100,0,165541,35703666,13.2500,11,1,13.4000,18,1,12.9900,100,1,13.6699,100,1,12.7300,100,1,13.9299,100,1,12.6699,100,1,14.0000,100,1,12.4700,100,1,14.1999,900,3,12.4600,100,1,14.2599,700,1,12.4299,700,1,14.2699,700,1,12.4199,700,1,14.2899,100,1,12.3699,700,1,14.3399,200,2,12.3599,200,2,14.4299,2,1,ARL,44720033
432,2025-07-17T13:31:08.377022927Z,2025-07-17T13:31:08.377022927Z,10,2,1108,A,A,0,14.5600,100,130,165541,35703666,13.2500,11,1,13.4000,18,1,12.9900,100,1,13.6699,100,1,12.7300,100,1,13.9299,100,1,12.6699,100,1,14.0000,100,1,12.4700,100,1,14.1999,900,3,12.4600,100,1,14.2599,700,1,12.4299,700,1,14.2699,700,1,12.4199,700,1,14.2899,100,1,12.3699,700,1,14.3399,200,2,12.3599,200,2,14.4299,2,1,ARL,47873821
433,2025-07-17T13:31:09.399928944Z,2025-07-17T13:31:09.399928944Z,10,2,1108,C,A,0,14.5600,100,0,165829,35758774,13.2500,11,1,13.4000,18,1,12.9900,100,1,13.6699,100,1,12.7300,100,1,13.9299,100,1,12.6699,100,1,14.0000,100,1,12.4700,100,1,14.1999,900,3,12.4600,100,1,14.2599,700,1,12.4299,700,1,14.2699,700,1,12.4199,700,1,14.2899,100,1,12.3699,700,1,14.3399,200,2,12.3599,200,2,14.4299,2,1,ARL,47873821
434,2025-07-17T13:31:09.399928944Z,2025-07-17T13:31:09.399928944Z,10,2,1108,A,A,0,14.2899,100,130,165829,35758774,13.2500,11,1,13.4000,18,1,12.9900,100,1,13.6699,100,1,12.7300,100,1,13.9299,100,1,12.6699,100,1,14.0000,100,1,12.4700,100,1,14.1999,900,3,12.4600,100,1,14.2599,700,1,12.4299,700,1,14.2699,700,1,12.4199,700,1,14.2899,200,2,12.3699,700,1,14.3399,200,2,12.3599,200,2,14.4299,2,1,ARL,47927629
435,2025-07-17T13:31:16.538876621Z,2025-07-17T13:31:16.538876621Z,10,2,1108,A,A,0,13.4000,10,130,165436,36186495,13.2500,11,1,13.4000,28,2,12.9900,100,1,13.6699,100,1,12.7300,100,1,13.9299,100,1,12.6699,100,1,14.0000,100,1,12.4700,100,1,14.1999,900,3,12.4600,100,1,14.2599,700,1,12.4299,700,1,14.2699,700,1,12.4199,700,1,14.2899,200,2,12.3699,700,1,14.3399,200,2,12.3599,200,2,14.4299,2,1,ARL,48315949
436,2025-07-17T13:31:17.448559991Z,2025-07-17T13:31:17.448559991Z,10,2,1108,C,A,0,13.4000,10,128,167985,36232894,13.2500,11,1,13.4000,18,1,12.9900,100,1,13.6699,100,1,12.7300,100,1,13.9299,100,1,12.6699,100,1,14.0000,100,1,12.4700,100,1,14.1999,900,3,12.4600,100,1,14.2599,700,1,12.4299,700,1,14.2699,700,1,12.4199,700,1,14.2899,200,2,12.3699,700,1,14.3399,200,2,12.3599,200,2,14.4299,2,1,ARL,48315949
437,2025-07-17T13:31:34.835937627Z,2025-07-17T13:31:34.835937627Z,10,2,1108,C,A,0,13.4000,18,130,165335,37177882,13.2500,11,1,13.6699,100,1,12.9900,100,1,13.9299,100,1,12.7300,100,1,14.0000,100,1,12.6699,100,1,14.1999,900,3,12.4700,100,1,14.2599,700,1,12.4600,100,1,14.2699,700,1,12.4299,700,1,14.2899,200,2,12.4199,700,1,14.3399,200,2,12.3699,700,1,14.4299,2,1,12.3599,200,2,14.4399,100,1,ARL,47873813
438,2025-07-17T13:31:34.836694504Z,2025-07-17T13:31:34.836694504Z,10,2,1108,C,A,0,14.2899,100,0,166354,37177896,13.2500,11,1,13.6699,100,1,12.9900,100,1,13.9299,100,1,12.7300,100,1,14.0000,100,1,12.6699,100,1,14.1999,900,3,12.4700,100,1,14.2599,700,1,12.4600,100,1,14.2699,700,1,12.4299,700,1,14.2899,100,1,12.4199,700,1,14.3399,200,2,12.3699,700,1,14.4299,2,1,12.3599,200,2,14.4399,100,1,ARL,44719985
439,2025-07-17T13:31:34.836694504Z,2025-07-17T13:31:34.836694504Z,10,2,1108,A,A,0,14.5600,100,130,166354,37177896,13.2500,11,1,13.6699,100,1,12.9900,100,1,13.9299,100,1,12.7300,100,1,14.0000,100,1,12.6699,100,1,14.1999,900,3,12.4700,100,1,14.2599,700,1,12.4600,100,1,14.2699,700,1,12.4299,700,1,14.2899,100,1,12.4199,700,1,14.3399,200,2,12.3699,700,1,14.4299,2,1,12.3599,200,2,14.4399,100,1,ARL,49226081
440,2025-07-17T13:31:34.837099615Z,2025-07-17T13:31:34.837099615Z,10,2,1108,C,A,0,14.2899,100,0,165450,37177905,13.2500,11,1,13.6699,100,1,12.9900,100,1,13.9299,100,1,12.7300,100,1,14.0000,100,1,12.6699,100,1,14.1999,900,3,12.4700,100,1,14.2599,700,1,12.4600,100,1,14.2699,700,1,12.4299,700,1,14.3399,200,2,12.4199,700,1,14.4299,2,1,12.3699,700,1,14.4399,100,1,12.3599,200,2,14.4600,700,1,ARL,47927629
441,2025-07-17T13:31:34.837099615Z,2025-07-17T13:31:34.837099615Z,10,2,1108,A,A,0,14.5600,100,130,165450,37177905,13.2500,11,1,13.6699,100,1,12.9900,100,1,13.9299,100,1,12.7300,100,1,14.0000,100,1,12.6699,100,1,14.1999,900,3,12.4700,100,1,14.2599,700,1,12.4600,100,1,14.2699,700,1,12.4299,700,1,14.3399,200,2,12.4199,700,1,14.4299,2,1,12.3699,700,1,14.4399,100,1,12.3599,200,2,14.4600,700,1,ARL,49226101
442,2025-07-17T13:35:00.187526221Z,2025-07-17T13:35:00.187526221Z,10,2,1108,C,B,0,12.3300,2,0,167974,45447658,13.2500,11,1,13.6699,100,1,12.9900,100,1,13.9299,100,1,12.7300,100,1,14.0000,100,1,12.6699,100,1,14.1999,900,3,12.4700,100,1,14.2599,700,1,12.4600,100,1,14.2699,700,1,12.4299,700,1,14.3399,200,2,12.4199,700,1,14.4299,2,1,12.3699,700,1,14.4399,100,1,12.3599,200,2,14.4600,700,1,ARL,43692153
443,2025-07-17T13:35:00.187526221Z,2025-07-17T13:35:00.187526221Z,10,2,1108,A,B,0,12.8800,2,128,167974,45447658,13.2500,11,1,13.6699,100,1,12.9900,100,1,13.9299,100,1,12.8800,2,1,14.0000,100,1,12.7300,100,1,14.1999,900,3,12.6699,100,1,14.2599,700,1,12.4700,100,1,14.2699,700,1,12.4600,100,1,14.3399,200,2,12.4299,700,1,14.4299,2,1,12.4199,700,1,14.4399,100,1,12.3699,700,1,14.4600,700,1,ARL,58709193
444,2025-07-17T13:35:00.187528642Z,2025-07-17T13:35:00.187528642Z,10,2,1108,C,A,0,14.4299,2,0,166078,45447661,13.2500,11,1,13.6699,100,1,12.9900,100,1,13.9299,100,1,12.8800,2,1,14.0000,100,1,12.7300,100,1,14.1999,900,3,12.6699,100,1,14.2599,700,1,12.4700,100,1,14.2699,700,1,12.4600,100,1,14.3399,200,2,12.4299,700,1,14.4399,100,1,12.4199,700,1,14.4600,700,1,12.3699,700,1,14.5600,200,2,ARL,44904733
445,2025-07-17T13:35:00.187528642Z,2025-07-17T13:35:00.187528642Z,10,2,1108,A,A,0,13.7799,2,130,166078,45447661,13.2500,11,1,13.6699,100,1,12.9900,100,1,13.7799,2,1,12.8800,2,1,13.9299,100,1,12.7300,100,1,14.0000,100,1,12.6699,100,1,14.1999,900,3,12.4700,100,1,14.2599,700,1,12.4600,100,1,14.2699,700,1,12.4299,700,1,14.3399,200,2,12.4199,700,1,14.4399,100,1,12.3699,700,1,14.4600,700,1,ARL,58709197
446,2025-07-17T13:37:31.076154614Z,2025-07-17T13:37:31.076154614Z,10,2,1108,C,A,0,14.5600,100,0,165432,51978366,13.2500,11,1,13.6699,100,1,12.9900,100,1,13.7799,2,1,12.8800,2,1,13.9299,100,1,12.7300,100,1,14.0000,100,1,12.6699,100,1,14.1999,900,3,12.4700,100,1,14.2599,700,1,12.4600,100,1,14.2699,700,1,12.4299,700,1,14.3399,200,2,12.4199,700,1,14.4399,100,1,12.3699,700,1,14.4600,700,1,ARL,49226101
447,2025-07-17T13:37:31.076154614Z,2025-07-17T13:37:31.076154614Z,10,2,1108,A,A,0,14.2899,100,130,165432,51978366,13.2500,11,1,13.6699,100,1,12.9900,100,1,13.7799,2,1,12.8800,2,1,13.9299,100,1,12.7300,100,1,14.0000,100,1,12.6699,100,1,14.1999,900,3,12.4700,100,1,14.2599,700,1,12.4600,100,1,14.2699,700,1,12.4299,700,1,14.2899,100,1,12.4199,700,1,14.3399,200,2,12.3699,700,1,14.4399,100,1,ARL,65160189
448,2025-07-17T13:37:31.076330756Z,2025-07-17T13:37:31.076330756Z,10,2,1108,C,A,0,14.5600,100,0,165647,51978372,13.2500,11,1,13.6699,100,1,12.9900,100,1,13.7799,2,1,12.8800,2,1,13.9299,100,1,12.7300,100,1,14.0000,100,1,12.6699,100,1,14.1999,900,3,12.4700,100,1,14.2599,700,1,12.4600,100,1,14.2699,700,1,12.4299,700,1,14.2899,100,1,12.4199,700,1,14.3399,200,2,12.3699,700,1,14.4399,100,1,ARL,49226081
449,2025-07-17T13:37:31.076330756Z,2025-07-17T13:37:31.076330756Z,10,2,1108,A,A,0,14.2899,100,130,165647,51978372,13.2500,11,1,13.6699,100,1,12.9900,100,1,13.7799,2,1,12.8800,2,1,13.9299,100,1,12.7300,100,1,14.0000,100,1,12.6699,100,1,14.1999,900,3,12.4700,100,1,14.2599,700,1,12.4600,100,1,14.2699,700,1,12.4299,700,1,14.2899,200,2,12.4199,700,1,14.3399,200,2,12.3699,700,1,14.4399,100,1,ARL,65160193
450,2025-07-17T13:38:08.679744459Z,2025-07-17T13:38:08.679744459Z,10,2,1108,C,A,0,14.2899,100,0,165730,53264917,13.2500,11,1,13.6699,100,1,12.9900,100,1,13.7799,2,1,12.8800,2,1,13.9299,100,1,12.7300,100,1,14.0000,100,1,12.6699,100,1,14.1999,900,3,12.4700,100,1,14.2599,700,1,12.4600,100,1,14.2699,700,1,12.4299,700,1,14.2899,100,1,12.4199,700,1,14.3399,200,2,12.3699,700,1,14.4399,100,1,ARL,65160189
451,2025-07-17T13:38:08.679744459Z,2025-07-17T13:38:08.679744459Z,10,2,1108,A,A,0,14.5600,100,130,165730,53264917,13.2500,11,1,13.6699,100,1,12.9900,100,1,13.7799,2,1,12.8800,2,1,13.9299,100,1,12.7300,100,1,14.0000,100,1,12.6699,100,1,14.1999,900,3,12.4700,100,1,14.2599,700,1,12.4600,100,1,14.2699,700,1,12.4299,700,1,14.2899,100,1,12.4199,700,1,14.3399,200,2,12.3699,700,1,14.4399,100,1,ARL,66501333
452,2025-07-17T13:38:08.679752190Z,2025-07-17T13:38:08.679752190Z,10,2,1108,C,A,0,14.2899,100,0,165642,53264918,13.2500,11,1,13.6699,100,1,12.9900,100,1,13.7799,2,1,12.8800,2,1,13.9299,100,1,12.7300,100,1,14.0000,100,1,12.6699,100,1,14.1999,900,3,12.4700,100,1,14.2599,700,1,12.4600,100,1,14.2699,700,1,12.4299,700,1,14.3399,200,2,12.4199,700,1,14.4399,100,1,12.3699,700,1,14.4600,700,1,ARL,65160193
453,2025-07-17T13:38:08.679752190Z,2025-07-17T13:38:08.679752190Z,10,2,1108,A,A,0,14.5600,100,130,165642,53264918,13.2500,11,1,13.6699,100,1,12.9900,100,1,13.7799,2,1,12.8800,2,1,13.9299,100,1,12.7300,100,1,14.0000,100,1,12.6699,100,1,14.1999,900,3,12.4700,100,1,14.2599,700,1,12.4600,100,1,14.2699,700,1,12.4299,700,1,14.3399,200,2,12.4199,700,1,14.4399,100,1,12.3699,700,1,14.4600,700,1,ARL,66501341
454,2025-07-17T13:38:09.686863512Z,2025-07-17T13:38:09.686863512Z,10,2,1108,C,A,0,14.5600,100,0,165458,53302839,13.2500,11,1,13.6699,100,1,12.9900,100,1,13.7799,2,1,12.8800,2,1,13.9299,100,1,12.7300,100,1,14.0000,100,1,12.6699,100,1,14.1999,900,3,12.4700,100,1,14.2599,700,1,12.4600,100,1,14.2699,700,1,12.4299,700,1,14.3399,200,2,12.4199,700,1,14.4399,100,1,12.3699,700,1,14.4600,700,1,ARL,66501333
455,2025-07-17T13:38:09.686863512Z,2025-07-17T13:38:09.686863512Z,10,2,1108,A,A,0,14.2899,100,130,165458,53302839,13.2500,11,1,13.6699,100,1,12.9900,100,1,13.7799,2,1,12.8800,2,1,13.9299,100,1,12.7300,100,1,14.0000,100,1,12.6699,100,1,14.1999,900,3,12.4700,100,1,14.2599,700,1,12.4600,100,1,14.2699,700,1,12.4299,700,1,14.2899,100,1,12.4199,700,1,14.3399,200,2,12.3699,700,1,14.4399,100,1,ARL,66538149
456,2025-07-17T13:38:09.708029202Z,2025-07-17T13:38:09.708029202Z,10,2,1108,C,A,0,14.5600,100,0,165801,53303094,13.2500,11,1,13.6699,100,1,12.9900,100,1,13.7799,2,1,12.8800,2,1,13.9299,100,1,12.7300,100,1,14.0000,100,1,12.6699,100,1,14.1999,900,3,12.4700,100,1,14.2599,700,1,12.4600,100,1,14.2699,700,1,12.4299,700,1,14.2899,100,1,12.4199,700,1,14.3399,200,2,12.3699,700,1,14.4399,100,1,ARL,66501341
457,2025-07-17T13:38:09.708029202Z,2025-07-17T13:38:09.708029202Z,10,2,1108,A,A,0,14.2899,100,130,165801,53303094,13.2500,11,1,13.6699,100,1,12.9900,100,1,13.7799,2,1,12.8800,2,1,13.9299,100,1,12.7300,100,1,14.0000,100,1,12.6699,100,1,14.1999,900,3,12.4700,100,1,14.2599,700,1,12.4600,100,1,14.2699,700,1,12.4299,700,1,14.2899,200,2,12.4199,700,1,14.3399,200,2,12.3699,700,1,14.4399,100,1,ARL,66538573
458,2025-07-17T13:38:44.678957477Z,2025-07-17T13:38:44.678957477Z,10,2,1108,A,A,0,13.4000,15,130,165385,54485050,13.2500,11,1,13.4000,15,1,12.9900,100,1,13.6699,100,1,12.8800,2,1,13.7799,2,1,12.7300,100,1,13.9299,100,1,12.6699,100,1,14.0000,100,1,12.4700,100,1,14.1999,900,3,12.4600,100,1,14.2599,700,1,12.4299,700,1,14.2699,700,1,12.4199,700,1,14.2899,200,2,12.3699,700,1,14.3399,200,2,ARL,67832461
459,2025-07-17T13:38:44.679278833Z,2025-07-17T13:38:44.679278833Z,10,2,1108,C,A,0,14.2899,100,0,165513,54485052,13.2500,11,1,13.4000,15,1,12.9900,100,1,13.6699,100,1,12.8800,2,1,13.7799,2,1,12.7300,100,1,13.9299,100,1,12.6699,100,1,14.0000,100,1,12.4700,100,1,14.1999,900,3,12.4600,100,1,14.2599,700,1,12.4299,700,1,14.2699,700,1,12.4199,700,1,14.2899,100,1,12.3699,700,1,14.3399,200,2,ARL,66538149
460,2025-07-17T13:38:44.679278833Z,2025-07-17T13:38:44.679278833Z,10,2,1108,A,A,0,14.5600,100,130,165513,54485052,13.2500,11,1,13.4000,15,1,12.9900,100,1,13.6699,100,1,12.8800,2,1,13.7799,2,1,12.7300,100,1,13.9299,100,1,12.6699,100,1,14.0000,100,1,12.4700,100,1,14.1999,900,3,12.4600,100,1,14.2599,700,1,12.4299,700,1,14.2699,700,1,12.4199,700,1,14.2899,100,1,12.3699,700,1,14.3399,200,2,ARL,67832465
461,2025-07-17T13:38:45.695265148Z,2025-07-17T13:38:45.695265148Z,10,2,1108,C,A,0,14.5600,100,0,165372,54508575,13.2500,11,1,13.4000,15,1,12.9900,100,1,13.6699,100,1,12.8800,2,1,13.7799,2,1,12.7300,100,1,13.9299,100,1,12.6699,100,1,14.0000,100,1,12.4700,100,1,14.1999,900,3,12.4600,100,1,14.2599,700,1,12.4299,700,1,14.2699,700,1,12.4199,700,1,14.2899,100,1,12.3699,700,1,14.3399,200,2,ARL,67832465
462,2025-07-17T13:38:45.695265148Z,2025-07-17T13:38:45.695265148Z,10,2,1108,A,A,0,14.2899,100,130,165372,54508575,13.2500,11,1,13.4000,15,1,12.9900,100,1,13.6699,100,1,12.8800,2,1,13.7799,2,1,12.7300,100,1,13.9299,100,1,12.6699,100,1,14.0000,100,1,12.4700,100,1,14.1999,900,3,12.4600,100,1,14.2599,700,1,12.4299,700,1,14.2699,700,1,12.4199,700,1,14.2899,200,2,12.3699,700,1,14.3399,200,2,ARL,67857641
463,2025-07-17T13:39:08.713907562Z,2025-07-17T13:39:08.713907562Z,10,2,1108,C,A,0,13.4000,15,130,165320,55204868,13.2500,11,1,13.6699,100,1,12.9900,100,1,13.7799,2,1,12.8800,2,1,13.9299,100,1,12.7300,100,1,14.0000,100,1,12.6699,100,1,14.1999,900,3,12.4700,100,1,14.2599,700,1,12.4600,100,1,14.2699,700,1,12.4299,700,1,14.2899,200,2,12.4199,700,1,14.3399,200,2,12.3699,700,1,14.4399,100,1,ARL,67832461
464,2025-07-17T13:39:08.714284059Z,2025-07-17T13:39:08.714284059Z,10,2,1108,A,A,0,13.4000,24,130,165491,55204884,13.2500,11,1,13.4000,24,1,12.9900,100,1,13.6699,100,1,12.8800,2,1,13.7799,2,1,12.7300,100,1,13.9299,100,1,12.6699,100,1,14.0000,100,1,12.4700,100,1,14.1999,900,3,12.4600,100,1,14.2599,700,1,12.4299,700,1,14.2699,700,1,12.4199,700,1,14.2899,200,2,12.3699,700,1,14.3399,200,2,ARL,68625181
465,2025-07-17T13:39:39.996436857Z,2025-07-17T13:39:39.996436857Z,10,2,1108,T,B,0,13.4000,1,130,166323,56150102,13.2500,11,1,13.4000,24,1,12.9900,100,1,13.6699,100,1,12.8800,2,1,13.7799,2,1,12.7300,100,1,13.9299,100,1,12.6699,100,1,14.0000,100,1,12.4700,100,1,14.1999,900,3,12.4600,100,1,14.2599,700,1,12.4299,700,1,14.2699,700,1,12.4199,700,1,14.2899,200,2,12.3699,700,1,14.3399,200,2,ARL,0
466,2025-07-17T13:39:39.996436857Z,2025-07-17T13:39:39.996436857Z,10,2,1108,F,A,0,13.4000,1,130,166323,56150102,13.2500,11,1,13.4000,24,1,12.9900,100,1,13.6699,100,1,12.8800,2,1,13.7799,2,1,12.7300,100,1,13.9299,100,1,12.6699,100,1,14.0000,100,1,12.4700,100,1,14.1999,900,3,12.4600,100,1,14.2599,700,1,12.4299,700,1,14.2699,700,1,12.4199,700,1,14.2899,200,2,12.3699,700,1,14.3399,200,2,ARL,68625181
467,2025-07-17T13:39:39.996436857Z,2025-07-17T13:39:39.996436857Z,10,2,1108,C,A,0,13.4000,1,130,166323,56150102,13.2500,11,1,13.4000,23,1,12.9900,100,1,13.6699,100,1,12.8800,2,1,13.7799,2,1,12.7300,100,1,13.9299,100,1,12.6699,100,1,14.0000,100,1,12.4700,100,1,14.1999,900,3,12.4600,100,1,14.2599,700,1,12.4299,700,1,14.2699,700,1,12.4199,700,1,14.2899,200,2,12.3699,700,1,14.3399,200,2,ARL,68625181
468,2025-07-17T13:39:39.996833282Z,2025-07-17T13:39:39.996833282Z,10,2,1108,C,A,0,13.4000,23,130,165052,56150114,13.2500,11,1,13.6699,100,1,12.9900,100,1,13.7799,2,1,12.8800,2,1,13.9299,100,1,12.7300,100,1,14.0000,100,1,12.6699,100,1,14.1999,900,3,12.4700,100,1,14.2599,700,1,12.4600,100,1,14.2699,700,1,12.4299,700,1,14.2899,200,2,12.4199,700,1,14.3399,200,2,12.3699,700,1,14.4399,100,1,ARL,68625181
469,2025-07-17T13:39:39.997144158Z,2025-07-17T13:39:39.997144158Z,10,2,1108,C,A,0,14.2899,100,0,165357,56150130,13.2500,11,1,13.6699,100,1,12.9900,100,1,13.7799,2,1,12.8800,2,1,13.9299,100,1,12.7300,100,1,14.0000,100,1,12.6699,100,1,14.1999,900,3,12.4700,100,1,14.2599,700,1,12.4600,100,1,14.2699,700,1,12.4299,700,1,14.2899,100,1,12.4199,700,1,14.3399,200,2,12.3699,700,1,14.4399,100,1,ARL,66538573
470,2025-07-17T13:39:39.997144158Z,2025-07-17T13:39:39.997144158Z,10,2,1108,A,A,0,14.5700,100,130,165357,56150130,13.2500,11,1,13.6699,100,1,12.9900,100,1,13.7799,2,1,12.8800,2,1,13.9299,100,1,12.7300,100,1,14.0000,100,1,12.6699,100,1,14.1999,900,3,12.4700,100,1,14.2599,700,1,12.4600,100,1,14.2699,700,1,12.4299,700,1,14.2899,100,1,12.4199,700,1,14.3399,200,2,12.3699,700,1,14.4399,100,1,ARL,69677517
471,2025-07-17T13:39:39.997211562Z,2025-07-17T13:39:39.997211562Z,10,2,1108,A,A,0,13.4000,24,130,165311,56150131,13.2500,11,1,13.4000,24,1,12.9900,100,1,13.6699,100,1,12.8800,2,1,13.7799,2,1,12.7300,100,1,13.9299,100,1,12.6699,100,1,14.0000,100,1,12.4700,100,1,14.1999,900,3,12.4600,100,1,14.2599,700,1,12.4299,700,1,14.2699,700,1,12.4199,700,1,14.2899,100,1,12.3699,700,1,14.3399,200,2,ARL,69677521
472,2025-07-17T13:39:41.018783466Z,2025-07-17T13:39:41.018783466Z,10,2,1108,C,A,0,14.5700,100,0,165467,56183429,13.2500,11,1,13.4000,24,1,12.9900,100,1,13.6699,100,1,12.8800,2,1,13.7799,2,1,12.7300,100,1,13.9299,100,1,12.6699,100,1,14.0000,100,1,12.4700,100,1,14.1999,900,3,12.4600,100,1,14.2599,700,1,12.4299,700,1,14.2699,700,1,12.4199,700,1,14.2899,100,1,12.3699,700,1,14.3399,200,2,ARL,69677517
473,2025-07-17T13:39:41.018783466Z,2025-07-17T13:39:41.018783466Z,10,2,1108,A,A,0,14.3000,100,130,165467,56183429,13.2500,11,1,13.4000,24,1,12.9900,100,1,13.6699,100,1,12.8800,2,1,13.7799,2,1,12.7300,100,1,13.9299,100,1,12.6699,100,1,14.0000,100,1,12.4700,100,1,14.1999,900,3,12.4600,100,1,14.2599,700,1,12.4299,700,1,14.2699,700,1,12.4199,700,1,14.2899,100,1,12.3699,700,1,14.3000,100,1,ARL,69725541
474,2025-07-17T13:40:08.782383621Z,2025-07-17T13:40:08.782383621Z,10,2,1108,C,A,0,13.4000,24,130,165426,57235944,13.2500,11,1,13.6699,100,1,12.9900,100,1,13.7799,2,1,12.8800,2,1,13.9299,100,1,12.7300,100,1,14.0000,100,1,12.6699,100,1,14.1999,900,3,12.4700,100,1,14.2599,700,1,12.4600,100,1,14.2699,700,1,12.4299,700,1,14.2899,100,1,12.4199,700,1,14.3000,100,1,12.3699,700,1,14.3399,200,2,ARL,69677521
475,2025-07-17T13:40:08.782758499Z,2025-07-17T13:40:08.782758499Z,10,2,1108,A,A,0,13.4000,18,130,165479,57235956,13.2500,11,1,13.4000,18,1,12.9900,100,1,13.6699,100,1,12.8800,2,1,13.7799,2,1,12.7300,100,1,13.9299,100,1,12.6699,100,1,14.0000,100,1,12.4700,100,1,14.1999,900,3,12.4600,100,1,14.2599,700,1,12.4299,700,1,14.2699,700,1,12.4199,700,1,14.2899,100,1,12.3699,700,1,14.3000,100,1,ARL,70897053
476,2025-07-17T13:41:08.818711250Z,2025-07-17T13:41:08.818711250Z,10,2,1108,C,A,0,13.4000,18,130,165322,59313726,13.2500,11,1,13.6699,100,1,12.9900,100,1,13.7799,2,1,12.8800,2,1,13.9299,100,1,12.7300,100,1,14.0000,100,1,12.6699,100,1,14.1999,900,3,12.4700,100,1,14.2599,700,1,12.4600,100,1,14.2699,700,1,12.4299,700,1,14.2899,100,1,12.4199,700,1,14.3000,100,1,12.3699,700,1,14.3399,200,2,ARL,70897053
477,2025-07-17T13:41:08.819083504Z,2025-07-17T13:41:08.819083504Z,10,2,1108,A,A,0,13.4000,24,130,166041,59313736,13.2500,11,1,13.4000,24,1,12.9900,100,1,13.6699,100,1,12.8800,2,1,13.7799,2,1,12.7300,100,1,13.9299,100,1,12.6699,100,1,14.0000,100,1,12.4700,100,1,14.1999,900,3,12.4600,100,1,14.2599,700,1,12.4299,700,1,14.2699,700,1,12.4199,700,1,14.2899,100,1,12.3699,700,1,14.3000,100,1,ARL,73109413
478,2025-07-17T13:41:08.819104931Z,2025-07-17T13:41:08.819104931Z,10,2,1108,C,A,0,14.3000,100,0,165581,59313739,13.2500,11,1,13.4000,24,1,12.9900,100,1,13.6699,100,1,12.8800,2,1,13.7799,2,1,12.7300,100,1,13.9299,100,1,12.6699,100,1,14.0000,100,1,12.4700,100,1,14.1999,900,3,12.4600,100,1,14.2599,700,1,12.4299,700,1,14.2699,700,1,12.4199,700,1,14.2899,100,1,12.3699,700,1,14.3399,200,2,ARL,69725541
479,2025-07-17T13:41:08.819104931Z,2025-07-17T13:41:08.819104931Z,10,2,1108,A,A,0,14.5700,100,130,165581,59313739,13.2500,11,1,13.4000,24,1,12.9900,100,1,13.6699,100,1,12.8800,2,1,13.7799,2,1,12.7300,100,1,13.9299,100,1,12.6699,100,1,14.0000,100,1,12.4700,100,1,14.1999,900,3,12.4600,100,1,14.2599,700,1,12.4299,700,1,14.2699,700,1,12.4199,700,1,14.2899,100,1,12.3699,700,1,14.3399,200,2,ARL,73109417
480,2025-07-17T13:41:09.881085734Z,2025-07-17T13:41:09.881085734Z,10,2,1108,C,A,0,14.5700,100,0,165459,59383199,13.2500,11,1,13.4000,24,1,12.9900,100,1,13.6699,100,1,12.8800,2,1,13.7799,2,1,12.7300,100,1,13.9299,100,1,12.6699,100,1,14.0000,100,1,12.4700,100,1,14.1999,900,3,12.4600,100,1,14.2599,700,1,12.4299,700,1,14.2699,700,1,12.4199,700,1,14.2899,100,1,12.3699,700,1,14.3399,200,2,ARL,73109417
481,2025-07-17T13:41:09.881085734Z,2025-07-17T13:41:09.881085734Z,10,2,1108,A,A,0,14.3000,100,130,165459,59383199,13.2500,11,1,13.4000,24,1,12.9900,100,1,13.6699,100,1,12.8800,2,1,13.7799,2,1,12.7300,100,1,13.9299,100,1,12.6699,100,1,14.0000,100,1,12.4700,100,1,14.1999,900,3,12.4600,100,1,14.2599,700,1,12.4299,700,1,14.2699,700,1,12.4199,700,1,14.2899,100,1,12.3699,700,1,14.3000,100,1,ARL,73183421
482,2025-07-17T13:41:44.348494744Z,2025-07-17T13:41:44.348494744Z,10,2,1108,C,A,0,13.4000,24,130,165361,60614543,13.2500,11,1,13.6699,100,1,12.9900,100,1,13.7799,2,1,12.8800,2,1,13.9299,100,1,12.7300,100,1,14.0000,100,1,12.6699,100,1,14.1999,900,3,12.4700,100,1,14.2599,700,1,12.4600,100,1,14.2699,700,1,12.4299,700,1,14.2899,100,1,12.4199,700,1,14.3000,100,1,12.3699,700,1,14.3399,200,2,ARL,73109413
483,2025-07-17T13:41:44.349416601Z,2025-07-17T13:41:44.349416601Z,10,2,1108,C,A,0,14.3000,100,0,165376,60614557,13.2500,11,1,13.6699,100,1,12.9900,100,1,13.7799,2,1,12.8800,2,1,13.9299,100,1,12.7300,100,1,14.0000,100,1,12.6699,100,1,14.1999,900,3,12.4700,100,1,14.2599,700,1,12.4600,100,1,14.2699,700,1,12.4299,700,1,14.2899,100,1,12.4199,700,1,14.3399,200,2,12.3699,700,1,14.4399,100,1,ARL,73183421
484,2025-07-17T13:41:44.349416601Z,2025-07-17T13:41:44.349416601Z,10,2,1108,A,A,0,14.5700,100,130,165376,60614557,13.2500,11,1,13.6699,100,1,12.9900,100,1,13.7799,2,1,12.8800,2,1,13.9299,100,1,12.7300,100,1,14.0000,100,1,12.6699,100,1,14.1999,900,3,12.4700,100,1,14.2599,700,1,12.4600,100,1,14.2699,700,1,12.4299,700,1,14.2899,100,1,12.4199,700,1,14.3399,200,2,12.3699,700,1,14.4399,100,1,ARL,74549681
485,2025-07-17T13:41:45.405013016Z,2025-07-17T13:41:45.405013016Z,10,2,1108,C,A,0,14.5700,100,0,165828,60651462,13.2500,11,1,13.6699,100,1,12.9900,100,1,13.7799,2,1,12.8800,2,1,13.9299,100,1,12.7300,100,1,14.0000,100,1,12.6699,100,1,14.1999,900,3,12.4700,100,1,14.2599,700,1,12.4600,100,1,14.2699,700,1,12.4299,700,1,14.2899,100,1,12.4199,700,1,14.3399,200,2,12.3699,700,1,14.4399,100,1,ARL,74549681
486,2025-07-17T13:41:45.405013016Z,2025-07-17T13:41:45.405013016Z,10,2,1108,A,A,0,14.3000,100,130,165828,60651462,13.2500,11,1,13.6699,100,1,12.9900,100,1,13.7799,2,1,12.8800,2,1,13.9299,100,1,12.7300,100,1,14.0000,100,1,12.6699,100,1,14.1999,900,3,12.4700,100,1,14.2599,700,1,12.4600,100,1,14.2699,700,1,12.4299,700,1,14.2899,100,1,12.4199,700,1,14.3000,100,1,12.3699,700,1,14.3399,200,2,ARL,74589605
487,2025-07-17T13:42:08.821155108Z,2025-07-17T13:42:08.821155108Z,10,2,1108,C,A,0,14.2899,100,0,165715,61488742,13.2500,11,1,13.6699,100,1,12.9900,100,1,13.7799,2,1,12.8800,2,1,13.9299,100,1,12.7300,100,1,14.0000,100,1,12.6699,100,1,14.1999,900,3,12.4700,100,1,14.2599,700,1,12.4600,100,1,14.2699,700,1,12.4299,700,1,14.3000,100,1,12.4199,700,1,14.3399,200,2,12.3699,700,1,14.4399,100,1,ARL,67857641
488,2025-07-17T13:42:08.821155108Z,2025-07-17T13:42:08.821155108Z,10,2,1108,A,A,0,14.5700,100,130,165715,61488742,13.2500,11,1,13.6699,100,1,12.9900,100,1,13.7799,2,1,12.8800,2,1,13.9299,100,1,12.7300,100,1,14.0000,100,1,12.6699,100,1,14.1999,900,3,12.4700,100,1,14.2599,700,1,12.4600,100,1,14.2699,700,1,12.4299,700,1,14.3000,100,1,12.4199,700,1,14.3399,200,2,12.3699,700,1,14.4399,100,1,ARL,75537553
489,2025-07-17T13:42:09.826891682Z,2025-07-17T13:42:09.826891682Z,10,2,1108,C,A,0,14.5700,100,0,165656,61523538,13.2500,11,1,13.6699,100,1,12.9900,100,1,13.7799,2,1,12.8800,2,1,13.9299,100,1,12.7300,100,1,14.0000,100,1,12.6699,100,1,14.1999,900,3,12.4700,100,1,14.2599,700,1,12.4600,100,1,14.2699,700,1,12.4299,700,1,14.3000,100,1,12.4199,700,1,14.3399,200,2,12.3699,700,1,14.4399,100,1,ARL,75537553
490,2025-07-17T13:42:09.826891682Z,2025-07-17T13:42:09.826891682Z,10,2,1108,A,A,0,14.3000,100,130,165656,61523538,13.2500,11,1,13.6699,100,1,12.9900,100,1,13.7799,2,1,12.8800,2,1,13.9299,100,1,12.7300,100,1,14.0000,100,1,12.6699,100,1,14.1999,900,3,12.4700,100,1,14.2599,700,1,12.4600,100,1,14.2699,700,1,12.4299,700,1,14.3000,200,2,12.4199,700,1,14.3399,200,2,12.3699,700,1,14.4399,100,1,ARL,75577257
491,2025-07-17T13:43:08.826078491Z,2025-07-17T13:43:08.826078491Z,10,2,1108,C,A,0,14.3000,100,0,165634,63579150,13.2500,11,1,13.6699,100,1,12.9900,100,1,13.7799,2,1,12.8800,2,1,13.9299,100,1,12.7300,100,1,14.0000,100,1,12.6699,100,1,14.1999,900,3,12.4700,100,1,14.2599,700,1,12.4600,100,1,14.2699,700,1,12.4299,700,1,14.3000,100,1,12.4199,700,1,14.3399,200,2,12.3699,700,1,14.4399,100,1,ARL,75577257
492,2025-07-17T13:43:08.826078491Z,2025-07-17T13:43:08.826078491Z,10,2,1108,A,A,0,14.5700,100,130,165634,63579150,13.2500,11,1,13.6699,100,1,12.9900,100,1,13.7799,2,1,12.8800,2,1,13.9299,100,1,12.7300,100,1,14.0000,100,1,12.6699,100,1,14.1999,900,3,12.4700,100,1,14.2599,700,1,12.4600,100,1,14.2699,700,1,12.4299,700,1,14.3000,100,1,12.4199,700,1,14.3399,200,2,12.3699,700,1,14.4399,100,1,ARL,77879933
493,2025-07-17T13:43:09.832406764Z,2025-07-17T13:43:09.832406764Z,10,2,1108,C,A,0,14.5700,100,0,165651,63604352,13.2500,11,1,13.6699,100,1,12.9900,100,1,13.7799,2,1,12.8800,2,1,13.9299,100,1,12.7300,100,1,14.0000,100,1,12.6699,100,1,14.1999,900,3,12.4700,100,1,14.2599,700,1,12.4600,100,1,14.2699,700,1,12.4299,700,1,14.3000,100,1,12.4199,700,1,14.3399,200,2,12.3699,700,1,14.4399,100,1,ARL,77879933
494,2025-07-17T13:43:09.832406764Z,2025-07-17T13:43:09.832406764Z,10,2,1108,A,A,0,14.3000,100,130,165651,63604352,13.2500,11,1,13.6699,100,1,12.9900,100,1,13.7799,2,1,12.8800,2,1,13.9299,100,1,12.7300,100,1,14.0000,100,1,12.6699,100,1,14.1999,900,3,12.4700,100,1,14.2599,700,1,12.4600,100,1,14.2699,700,1,12.4299,700,1,14.3000,200,2,12.4199,700,1,14.3399,200,2,12.3699,700,1,14.4399,100,1,ARL,77910357
495,2025-07-17T13:46:09.540851349Z,2025-07-17T13:46:09.540851349Z,10,2,1108,C,A,0,14.1999,700,130,165550,69578535,13.2500,11,1,13.6699,100,1,12.9900,100,1,13.7799,2,1,12.8800,2,1,13.9299,100,1,12.7300,100,1,14.0000,100,1,12.6699,100,1,14.1999,200,2,12.4700,100,1,14.2599,700,1,12.4600,100,1,14.2699,700,1,12.4299,700,1,14.3000,200,2,12.4199,700,1,14.3399,200,2,12.3699,700,1,14.4399,100,1,ARL,47376925
496,2025-07-17T13:46:09.540892810Z,2025-07-17T13:46:09.540892810Z,10,2,1108,A,A,0,14.3599,700,130,165423,69578537,13.2500,11,1,13.6699,100,1,12.9900,100,1,13.7799,2,1,12.8800,2,1,13.9299,100,1,12.7300,100,1,14.0000,100,1,12.6699,100,1,14.1999,200,2,12.4700,100,1,14.2599,700,1,12.4600,100,1,14.2699,700,1,12.4299,700,1,14.3000,200,2,12.4199,700,1,14.3399,200,2,12.3699,700,1,14.3599,700,1,ARL,84607761
497,2025-07-17T13:46:09.540932260Z,2025-07-17T13:46:09.540932260Z,10,2,1108,A,A,0,15.5899,100,130,165278,69578539,13.2500,11,1,13.6699,100,1,12.9900,100,1,13.7799,2,1,12.8800,2,1,13.9299,100,1,12.7300,100,1,14.0000,100,1,12.6699,100,1,14.1999,200,2,12.4700,100,1,14.2599,700,1,12.4600,100,1,14.2699,700,1,12.4299,700,1,14.3000,200,2,12.4199,700,1,14.3399,200,2,12.3699,700,1,14.3599,700,1,ARL,84607765
498,2025-07-17T13:46:09.540944549Z,2025-07-17T13:46:09.540944549Z,10,2,1108,C,A,0,15.2799,100,130,165332,69578540,13.2500,11,1,13.6699,100,1,12.9900,100,1,13.7799,2,1,12.8800,2,1,13.9299,100,1,12.7300,100,1,14.0000,100,1,12.6699,100,1,14.1999,200,2,12.4700,100,1,14.2599,700,1,12.4600,100,1,14.2699,700,1,12.4299,700,1,14.3000,200,2,12.4199,700,1,14.3399,200,2,12.3699,700,1,14.3599,700,1,ARL,43373085
499,2025-07-17T13:46:09.541269186Z,2025-07-17T13:46:09.541269186Z,10,2,1108,C,A,0,14.4399,100,0,165390,69578543,13.2500,11,1,13.6699,100,1,12.9900,100,1,13.7799,2,1,12.8800,2,1,13.9299,100,1,12.7300,100,1,14.0000,100,1,12.6699,100,1,14.1999,200,2,12.4700,100,1,14.2599,700,1,12.4600,100,1,14.2699,700,1,12.4299,700,1,14.3000,200,2,12.4199,700,1,14.3399,200,2,12.3699,700,1,14.3599,700,1,ARL,43373009
500,2025-07-17T13:46:09.541269186Z,2025-07-17T13:46:09.541269186Z,10,2,1108,A,A,0,14.4900,100,130,165390,69578543,13.2500,11,1,13.6699,100,1,12.9900,100,1,13.7799,2,1,12.8800,2,1,13.9299,100,1,12.7300,100,1,14.0000,100,1,12.6699,100,1,14.1999,200,2,12.4700,100,1,14.2599,700,1,12.4600,100,1,14.2699,700,1,12.4299,700,1,14.3000,200,2,12.4199,700,1,14.3399,200,2,12.3699,700,1,14.3599,700,1,ARL,84607785
501,2025-07-17T13:46:09.541327298Z,2025-07-17T13:46:09.541327298Z,10,2,1108,C,A,0,14.0000,100,130,165331,69578544,13.2500,11,1,13.6699,100,1,12.9900,100,1,13.7799,2,1,12.8800,2,1,13.9299,100,1,12.7300,100,1,14.1999,200,2,12.6699,100,1,14.2599,700,1,12.4700,100,1,14.2699,700,1,12.4600,100,1,14.3000,200,2,12.4299,700,1,14.3399,200,2,12.4199,700,1,14.3599,700,1,12.3699,700,1,14.4600,700,1,ARL,43663233
502,2025-07-17T13:46:09.541629920Z,2025-07-17T13:46:09.541629920Z,10,2,1108,C,A,0,14.3399,100,0,165336,69578547,13.2500,11,1,13.6699,100,1,12.9900,100,1,13.7799,2,1,12.8800,2,1,13.9299,100,1,12.7300,100,1,14.1999,200,2,12.6699,100,1,14.2599,700,1,12.4700,100,1,14.2699,700,1,12.4600,100,1,14.3000,200,2,12.4299,700,1,14.3399,100,1,12.4199,700,1,14.3599,700,1,12.3699,700,1,14.4600,700,1,ARL,43755821
503,2025-07-17T13:46:09.541629920Z,2025-07-17T13:46:09.541629920Z,10,2,1108,A,A,0,14.6300,100,130,165336,69578547,13.2500,11,1,13.6699,100,1,12.9900,100,1,13.7799,2,1,12.8800,2,1,13.9299,100,1,12.7300,100,1,14.1999,200,2,12.6699,100,1,14.2599,700,1,12.4700,100,1,14.2699,700,1,12.4600,100,1,14.3000,200,2,12.4299,700,1,14.3399,100,1,12.4199,700,1,14.3599,700,1,12.3699,700,1,14.4600,700,1,ARL,84607801
504,2025-07-17T13:46:09.541680473Z,2025-07-17T13:46:09.541680473Z,10,2,1108,C,A,0,14.7400,100,0,166081,69578550,13.2500,11,1,13.6699,100,1,12.9900,100,1,13.7799,2,1,12.8800,2,1,13.9299,100,1,12.7300,100,1,14.1999,200,2,12.6699,100,1,14.2599,700,1,12.4700,100,1,14.2699,700,1,12.4600,100,1,14.3000,200,2,12.4299,700,1,14.3399,100,1,12.4199,700,1,14.3599,700,1,12.3699,700,1,14.4600,700,1,ARL,43357029
505,2025-07-17T13:46:09.541680473Z,2025-07-17T13:46:09.541680473Z,10,2,1108,A,A,0,15.0399,100,130,166081,69578550,13.2500,11,1,13.6699,100,1,12.9900,100,1,13.7799,2,1,12.8800,2,1,13.9299,100,1,12.7300,100,1,14.1999,200,2,12.6699,100,1,14.2599,700,1,12.4700,100,1,14.2699,700,1,12.4600,100,1,14.3000,200,2,12.4299,700,1,14.3399,100,1,12.4199,700,1,14.3599,700,1,12.3699,700,1,14.4600,700,1,ARL,84607805
506,2025-07-17T13:46:09.541682402Z,2025-07-17T13:46:09.541682402Z,10,2,1108,A,A,0,14.2799,100,130,165117,69578551,13.2500,11,1,13.6699,100,1,12.9900,100,1,13.7799,2,1,12.8800,2,1,13.9299,100,1,12.7300,100,1,14.1999,200,2,12.6699,100,1,14.2599,700,1,12.4700,100,1,14.2699,700,1,12.4600,100,1,14.2799,100,1,12.4299,700,1,14.3000,200,2,12.4199,700,1,14.3399,100,1,12.3699,700,1,14.3599,700,1,ARL,84607809
507,2025-07-17T13:46:09.542796050Z,2025-07-17T13:46:09.542796050Z,10,2,1108,C,A,0,15.4100,100,0,165706,69578574,13.2500,11,1,13.6699,100,1,12.9900,100,1,13.7799,2,1,12.8800,2,1,13.9299,100,1,12.7300,100,1,14.1999,200,2,12.6699,100,1,14.2599,700,1,12.4700,100,1,14.2699,700,1,12.4600,100,1,14.2799,100,1,12.4299,700,1,14.3000,200,2,12.4199,700,1,14.3399,100,1,12.3699,700,1,14.3599,700,1,ARL,43826805
508,2025-07-17T13:46:09.542796050Z,2025-07-17T13:46:09.542796050Z,10,2,1108,A,A,0,15.7300,100,130,165706,69578574,13.2500,11,1,13.6699,100,1,12.9900,100,1,13.7799,2,1,12.8800,2,1,13.9299,100,1,12.7300,100,1,14.1999,200,2,12.6699,100,1,14.2599,700,1,12.4700,100,1,14.2699,700,1,12.4600,100,1,14.2799,100,1,12.4299,700,1,14.3000,200,2,12.4199,700,1,14.3399,100,1,12.3699,700,1,14.3599,700,1,ARL,84607837
509,2025-07-17T13:46:09.543344724Z,2025-07-17T13:46:09.543344724Z,10,2,1108,C,A,0,17.0199,100,0,165431,69578598,13.2500,11,1,13.6699,100,1,12.9900,100,1,13.7799,2,1,12.8800,2,1,13.9299,100,1,12.7300,100,1,14.1999,200,2,12.6699,100,1,14.2599,700,1,12.4700,100,1,14.2699,700,1,12.4600,100,1,14.2799,100,1,12.4299,700,1,14.3000,200,2,12.4199,700,1,14.3399,100,1,12.3699,700,1,14.3599,700,1,ARL,44082969
510,2025-07-17T13:46:09.543344724Z,2025-07-17T13:46:09.543344724Z,10,2,1108,A,A,0,17.3700,100,130,165431,69578598,13.2500,11,1,13.6699,100,1,12.9900,100,1,13.7799,2,1,12.8800,2,1,13.9299,100,1,12.7300,100,1,14.1999,200,2,12.6699,100,1,14.2599,700,1,12.4700,100,1,14.2699,700,1,12.4600,100,1,14.2799,100,1,12.4299,700,1,14.3000,200,2,12.4199,700,1,14.3399,100,1,12.3699,700,1,14.3599,700,1,ARL,84607861
511,2025-07-17T13:46:09.546381306Z,2025-07-17T13:46:09.546381306Z,10,2,1108,C,A,0,14.1999,100,130,165176,69578814,13.2500,11,1,13.6699,100,1,12.9900,100,1,13.7799,2,1,12.8800,2,1,13.9299,100,1,12.7300,100,1,14.1999,100,1,12.6699,100,1,14.2599,700,1,12.4700,100,1,14.2699,700,1,12.4600,100,1,14.2799,100,1,12.4299,700,1,14.3000,200,2,12.4199,700,1,14.3399,100,1,12.3699,700,1,14.3599,700,1,ARL,43554141
512,2025-07-17T13:46:09.546491223Z,2025-07-17T13:46:09.546491223Z,10,2,1108,A,A,0,14.4700,100,130,165773,69578831,13.2500,11,1,13.6699,100,1,12.9900,100,1,13.7799,2,1,12.8800,2,1,13.9299,100,1,12.7300,100,1,14.1999,100,1,12.6699,100,1,14.2599,700,1,12.4700,100,1,14.2699,700,1,12.4600,100,1,14.2799,100,1,12.4299,700,1,14.3000,200,2,12.4199,700,1,14.3399,100,1,12.3699,700,1,14.3599,700,1,ARL,84608321
513,2025-07-17T13:46:09.560753276Z,2025-07-17T13:46:09.560753276Z,10,2,1108,C,A,0,13.6699,100,130,165344,69579444,13.2500,11,1,13.7799,2,1,12.9900,100,1,13.9299,100,1,12.8800,2,1,14.1999,100,1,12.7300,100,1,14.2599,700,1,12.6699,100,1,14.2699,700,1,12.4700,100,1,14.2799,100,1,12.4600,100,1,14.3000,200,2,12.4299,700,1,14.3399,100,1,12.4199,700,1,14.3599,700,1,12.3699,700,1,14.4600,700,1,ARL,43953649
514,2025-07-17T13:46:09.560789009Z,2025-07-17T13:46:09.560789009Z,10,2,1108,C,A,0,14.3599,700,130,164841,69579446,13.2500,11,1,13.7799,2,1,12.9900,100,1,13.9299,100,1,12.8800,2,1,14.1999,100,1,12.7300,100,1,14.2599,700,1,12.6699,100,1,14.2699,700,1,12.4700,100,1,14.2799,100,1,12.4600,100,1,14.3000,200,2,12.4299,700,1,14.3399,100,1,12.4199,700,1,14.4600,700,1,12.3699,700,1,14.4700,100,1,ARL,84607761
515,2025-07-17T13:46:09.560803559Z,2025-07-17T13:46:09.560803559Z,10,2,1108,A,A,0,13.9399,100,130,165260,69579448,13.2500,11,1,13.7799,2,1,12.9900,100,1,13.9299,100,1,12.8800,2,1,13.9399,100,1,12.7300,100,1,14.1999,100,1,12.6699,100,1,14.2599,700,1,12.4700,100,1,14.2699,700,1,12.4600,100,1,14.2799,100,1,12.4299,700,1,14.3000,200,2,12.4199,700,1,14.3399,100,1,12.3699,700,1,14.4600,700,1,ARL,84609305
516,2025-07-17T13:46:09.560815603Z,2025-07-17T13:46:09.560815603Z,10,2,1108,C,A,0,14.2699,700,130,165417,69579449,13.2500,11,1,13.7799,2,1,12.9900,100,1,13.9299,100,1,12.8800,2,1,13.9399,100,1,12.7300,100,1,14.1999,100,1,12.6699,100,1,14.2599,700,1,12.4700,100,1,14.2799,100,1,12.4600,100,1,14.3000,200,2,12.4299,700,1,14.3399,100,1,12.4199,700,1,14.4600,700,1,12.3699,700,1,14.4700,100,1,ARL,44491681
517,2025-07-17T13:46:09.560825413Z,2025-07-17T13:46:09.560825413Z,10,2,1108,A,A,0,15.8900,100,130,165356,69579450,13.2500,11,1,13.7799,2,1,12.9900,100,1,13.9299,100,1,12.8800,2,1,13.9399,100,1,12.7300,100,1,14.1999,100,1,12.6699,100,1,14.2599,700,1,12.4700,100,1,14.2799,100,1,12.4600,100,1,14.3000,200,2,12.4299,700,1,14.3399,100,1,12.4199,700,1,14.4600,700,1,12.3699,700,1,14.4700,100,1,ARL,84609309
518,2025-07-17T13:46:09.560837771Z,2025-07-17T13:46:09.560837771Z,10,2,1108,C,A,0,15.5899,100,130,164929,69579453,13.2500,11,1,13.7799,2,1,12.9900,100,1,13.9299,100,1,12.8800,2,1,13.9399,100,1,12.7300,100,1,14.1999,100,1,12.6699,100,1,14.2599,700,1,12.4700,100,1,14.2799,100,1,12.4600,100,1,14.3000,200,2,12.4299,700,1,14.3399,100,1,12.4199,700,1,14.4600,700,1,12.3699,700,1,14.4700,100,1,ARL,84607765
519,2025-07-17T13:46:09.560893546Z,2025-07-17T13:46:09.560893546Z,10,2,1108,A,A,0,14.6999,700,130,165475,69579455,13.2500,11,1,13.7799,2,1,12.9900,100,1,13.9299,100,1,12.8800,2,1,13.9399,100,1,12.7300,100,1,14.1999,100,1,12.6699,100,1,14.2599,700,1,12.4700,100,1,14.2799,100,1,12.4600,100,1,14.3000,200,2,12.4299,700,1,14.3399,100,1,12.4199,700,1,14.4600,700,1,12.3699,700,1,14.4700,100,1,ARL,84609321
520,2025-07-17T13:46:09.561543868Z,2025-07-17T13:46:09.561543868Z,10,2,1108,C,A,0,14.2599,700,128,167043,69579488,13.2500,11,1,13.7799,2,1,12.9900,100,1,13.9299,100,1,12.8800,2,1,13.9399,100,1,12.7300,100,1,14.1999,100,1,12.6699,100,1,14.2799,100,1,12.4700,100,1,14.3000,200,2,12.4600,100,1,14.3399,100,1,12.4299,700,1,14.4600,700,1,12.4199,700,1,14.4700,100,1,12.3699,700,1,14.4900,100,1,ARL,44598153
521,2025-07-17T13:46:09.561788417Z,2025-07-17T13:46:09.561788417Z,10,2,1108,C,A,0,15.0399,100,0,166572,69579536,13.2500,11,1,13.7799,2,1,12.9900,100,1,13.9299,100,1,12.8800,2,1,13.9399,100,1,12.7300,100,1,14.1999,100,1,12.6699,100,1,14.2799,100,1,12.4700,100,1,14.3000,200,2,12.4600,100,1,14.3399,100,1,12.4299,700,1,14.4600,700,1,12.4199,700,1,14.4700,100,1,12.3699,700,1,14.4900,100,1,ARL,84607805
522,2025-07-17T13:46:09.561788417Z,2025-07-17T13:46:09.561788417Z,10,2,1108,A,A,0,15.3300,100,0,166572,69579536,13.2500,11,1,13.7799,2,1,12.9900,100,1,13.9299,100,1,12.8800,2,1,13.9399,100,1,12.7300,100,1,14.1999,100,1,12.6699,100,1,14.2799,100,1,12.4700,100,1,14.3000,200,2,12.4600,100,1,14.3399,100,1,12.4299,700,1,14.4600,700,1,12.4199,700,1,14.4700,100,1,12.3699,700,1,14.4900,100,1,ARL,84609385
523,2025-07-17T13:46:09.561788902Z,2025-07-17T13:46:09.561788902Z,10,2,1108,C,A,0,14.6300,100,0,166087,69579537,13.2500,11,1,13.7799,2,1,12.9900,100,1,13.9299,100,1,12.8800,2,1,13.9399,100,1,12.7300,100,1,14.1999,100,1,12.6699,100,1,14.2799,100,1,12.4700,100,1,14.3000,200,2,12.4600,100,1,14.3399,100,1,12.4299,700,1,14.4600,700,1,12.4199,700,1,14.4700,100,1,12.3699,700,1,14.4900,100,1,ARL,84607801
524,2025-07-17T13:46:09.561788902Z,2025-07-17T13:46:09.561788902Z,10,2,1108,A,A,0,14.9100,100,130,166087,69579537,13.2500,11,1,13.7799,2,1,12.9900,100,1,13.9299,100,1,12.8800,2,1,13.9399,100,1,12.7300,100,1,14.1999,100,1,12.6699,100,1,14.2799,100,1,12.4700,100,1,14.3000,200,2,12.4600,100,1,14.3399,100,1,12.4299,700,1,14.4600,700,1,12.4199,700,1,14.4700,100,1,12.3699,700,1,14.4900,100,1,ARL,84609389
525,2025-07-17T13:46:09.561992206Z,2025-07-17T13:46:09.561992206Z,10,2,1108,A,A,0,14.6699,700,130,165245,69579579,13.2500,11,1,13.7799,2,1,12.9900,100,1,13.9299,100,1,12.8800,2,1,13.9399,100,1,12.7300,100,1,14.1999,100,1,12.6699,100,1,14.2799,100,1,12.4700,100,1,14.3000,200,2,12.4600,100,1,14.3399,100,1,12.4299,700,1,14.4600,700,1,12.4199,700,1,14.4700,100,1,12.3699,700,1,14.4900,100,1,ARL,84609409
526,2025-07-17T13:46:09.563617017Z,2025-07-17T13:46:09.563617017Z,10,2,1108,C,A,0,17.3700,100,0,165380,69579787,13.2500,11,1,13.7799,2,1,12.9900,100,1,13.9299,100,1,12.8800,2,1,13.9399,100,1,12.7300,100,1,14.1999,100,1,12.6699,100,1,14.2799,100,1,12.4700,100,1,14.3000,200,2,12.4600,100,1,14.3399,100,1,12.4299,700,1,14.4600,700,1,12.4199,700,1,14.4700,100,1,12.3699,700,1,14.4900,100,1,ARL,84607861
527,2025-07-17T13:46:09.563617017Z,2025-07-17T13:46:09.563617017Z,10,2,1108,A,A,0,17.6999,100,130,165380,69579787,13.2500,11,1,13.7799,2,1,12.9900,100,1,13.9299,100,1,12.8800,2,1,13.9399,100,1,12.7300,100,1,14.1999,100,1,12.6699,100,1,14.2799,100,1,12.4700,100,1,14.3000,200,2,12.4600,100,1,14.3399,100,1,12.4299,700,1,14.4600,700,1,12.4199,700,1,14.4700,100,1,12.3699,700,1,14.4900,100,1,ARL,84609557
528,2025-07-17T13:46:09.565213822Z,2025-07-17T13:46:09.565213822Z,10,2,1108,C,A,0,13.7799,2,0,165722,69579892,13.2500,11,1,13.9299,100,1,12.9900,100,1,13.9399,100,1,12.8800,2,1,14.1999,100,1,12.7300,100,1,14.2799,100,1,12.6699,100,1,14.3000,200,2,12.4700,100,1,14.3399,100,1,12.4600,100,1,14.4600,700,1,12.4299,700,1,14.4700,100,1,12.4199,700,1,14.4900,100,1,12.3699,700,1,14.6699,700,1,ARL,58709197
529,2025-07-17T13:46:09.565213822Z,2025-07-17T13:46:09.565213822Z,10,2,1108,A,A,0,13.9299,2,130,165722,69579892,13.2500,11,1,13.9299,102,2,12.9900,100,1,13.9399,100,1,12.8800,2,1,14.1999,100,1,12.7300,100,1,14.2799,100,1,12.6699,100,1,14.3000,200,2,12.4700,100,1,14.3399,100,1,12.4600,100,1,14.4600,700,1,12.4299,700,1,14.4700,100,1,12.4199,700,1,14.4900,100,1,12.3699,700,1,14.6699,700,1,ARL,84609637
530,2025-07-17T13:46:09.565237899Z,2025-07-17T13:46:09.565237899Z,10,2,1108,C,A,0,15.7300,100,0,165699,69579893,13.2500,11,1,13.9299,102,2,12.9900,100,1,13.9399,100,1,12.8800,2,1,14.1999,100,1,12.7300,100,1,14.2799,100,1,12.6699,100,1,14.3000,200,2,12.4700,100,1,14.3399,100,1,12.4600,100,1,14.4600,700,1,12.4299,700,1,14.4700,100,1,12.4199,700,1,14.4900,100,1,12.3699,700,1,14.6699,700,1,ARL,84607837
531,2025-07-17T13:46:09.565237899Z,2025-07-17T13:46:09.565237899Z,10,2,1108,A,A,0,16.0199,100,130,165699,69579893,13.2500,11,1,13.9299,102,2,12.9900,100,1,13.9399,100,1,12.8800,2,1,14.1999,100,1,12.7300,100,1,14.2799,100,1,12.6699,100,1,14.3000,200,2,12.4700,100,1,14.3399,100,1,12.4600,100,1,14.4600,700,1,12.4299,700,1,14.4700,100,1,12.4199,700,1,14.4900,100,1,12.3699,700,1,14.6699,700,1,ARL,84609645
