,ts_recv,ts_event,rtype,publisher_id,instrument_id,action,side,depth,price,size,flags,ts_in_delta,sequence,bid_px_00,bid_sz_00,bid_ct_00,ask_px_00,ask_sz_00,ask_ct_00,bid_px_01,bid_sz_01,bid_ct_01,ask_px_01,ask_sz_01,ask_ct_01,bid_px_02,bid_sz_02,bid_ct_02,ask_px_02,ask_sz_02,ask_ct_02,bid_px_03,bid_sz_03,bid_ct_03,ask_px_03,ask_sz_03,ask_ct_03,bid_px_04,bid_sz_04,bid_ct_04,ask_px_04,ask_sz_04,ask_ct_04,bid_px_05,bid_sz_05,bid_ct_05,ask_px_05,ask_sz_05,ask_ct_05,bid_px_06,bid_sz_06,bid_ct_06,ask_px_06,ask_sz_06,ask_ct_06,bid_px_07,bid_sz_07,bid_ct_07,ask_px_07,ask_sz_07,ask_ct_07,bid_px_08,bid_sz_08,bid_ct_08,ask_px_08,ask_sz_08,ask_ct_08,bid_px_09,bid_sz_09,bid_ct_09,ask_px_09,ask_sz_09,ask_ct_09,symbol,order_id
2016,2025-07-17T16:07:00.057644427Z,2025-07-17T16:07:00.057644427Z,10,2,1108,C,A,0,14.5500,100,0,165430,276613800,13.1099,100,1,13.8499,2,1,12.9800,200,2,14.2599,100,1,12.9000,2,1,14.2799,100,1,12.8599,100,1,14.4600,100,1,12.7300,100,1,14.4800,700,1,12.7100,100,1,14.5199,200,2,12.5000,700,1,14.5500,100,1,12.4600,100,1,14.5600,800,2,12.4299,700,1,14.5999,700,1,12.4199,700,1,14.6300,100,1,ARL,331052197
2017,2025-07-17T16:07:00.057644427Z,2025-07-17T16:07:00.057644427Z,10,2,1108,A,A,0,14.9600,100,130,165430,276613800,13.1099,100,1,13.8499,2,1,12.9800,200,2,14.2599,100,1,12.9000,2,1,14.2799,100,1,12.8599,100,1,14.4600,100,1,12.7300,100,1,14.4800,700,1,12.7100,100,1,14.5199,200,2,12.5000,700,1,14.5500,100,1,12.4600,100,1,14.5600,800,2,12.4299,700,1,14.5999,700,1,12.4199,700,1,14.6300,100,1,ARL,331928129
2018,2025-07-17T16:07:00.070325784Z,2025-07-17T16:07:00.070325784Z,10,2,1108,C,A,0,14.2599,100,130,165051,276614087,13.1099,100,1,13.8499,2,1,12.9800,200,2,14.2799,100,1,12.9000,2,1,14.4600,100,1,12.8599,100,1,14.4800,700,1,12.7300,100,1,14.5199,200,2,12.7100,100,1,14.5500,100,1,12.5000,700,1,14.5600,800,2,12.4600,100,1,14.5999,700,1,12.4299,700,1,14.6300,100,1,12.4199,700,1,14.8800,100,1,ARL,331928009
2019,2025-07-17T16:07:00.070373975Z,2025-07-17T16:07:00.070373975Z,10,2,1108,A,A,0,14.1400,100,130,165247,276614089,13.1099,100,1,13.8499,2,1,12.9800,200,2,14.1400,100,1,12.9000,2,1,14.2799,100,1,12.8599,100,1,14.4600,100,1,12.7300,100,1,14.4800,700,1,12.7100,100,1,14.5199,200,2,12.5000,700,1,14.5500,100,1,12.4600,100,1,14.5600,800,2,12.4299,700,1,14.5999,700,1,12.4199,700,1,14.6300,100,1,ARL,331929033
2020,2025-07-17T16:07:00.071194493Z,2025-07-17T16:07:00.071194493Z,10,2,1108,C,A,0,14.1400,100,130,164857,276614094,13.1099,100,1,13.8499,2,1,12.9800,200,2,14.2799,100,1,12.9000,2,1,14.4600,100,1,12.8599,100,1,14.4800,700,1,12.7300,100,1,14.5199,200,2,12.7100,100,1,14.5500,100,1,12.5000,700,1,14.5600,800,2,12.4600,100,1,14.5999,700,1,12.4299,700,1,14.6300,100,1,12.4199,700,1,14.8800,100,1,ARL,331929033
2021,2025-07-17T16:07:00.071239867Z,2025-07-17T16:07:00.071239867Z,10,2,1108,A,A,0,14.2599,100,130,165238,276614095,13.1099,100,1,13.8499,2,1,12.9800,200,2,14.2599,100,1,12.9000,2,1,14.2799,100,1,12.8599,100,1,14.4600,100,1,12.7300,100,1,14.4800,700,1,12.7100,100,1,14.5199,200,2,12.5000,700,1,14.5500,100,1,12.4600,100,1,14.5600,800,2,12.4299,700,1,14.5999,700,1,12.4199,700,1,14.6300,100,1,ARL,331929041
2022,2025-07-17T16:07:00.074415631Z,2025-07-17T16:07:00.074415631Z,10,2,1108,C,A,0,14.8800,100,0,165315,276614119,13.1099,100,1,13.8499,2,1,12.9800,200,2,14.2599,100,1,12.9000,2,1,14.2799,100,1,12.8599,100,1,14.4600,100,1,12.7300,100,1,14.4800,700,1,12.7100,100,1,14.5199,200,2,12.5000,700,1,14.5500,100,1,12.4600,100,1,14.5600,800,2,12.4299,700,1,14.5999,700,1,12.4199,700,1,14.6300,100,1,ARL,331927017
2023,2025-07-17T16:07:00.074415631Z,2025-07-17T16:07:00.074415631Z,10,2,1108,A,A,0,15.0600,100,130,165315,276614119,13.1099,100,1,13.8499,2,1,12.9800,200,2,14.2599,100,1,12.9000,2,1,14.2799,100,1,12.8599,100,1,14.4600,100,1,12.7300,100,1,14.4800,700,1,12.7100,100,1,14.5199,200,2,12.5000,700,1,14.5500,100,1,12.4600,100,1,14.5600,800,2,12.4299,700,1,14.5999,700,1,12.4199,700,1,14.6300,100,1,ARL,331929065
2024,2025-07-17T16:07:00.084965637Z,2025-07-17T16:07:00.084965637Z,10,2,1108,C,A,0,15.0700,100,0,165626,276614295,13.1099,100,1,13.8499,2,1,12.9800,200,2,14.2599,100,1,12.9000,2,1,14.2799,100,1,12.8599,100,1,14.4600,100,1,12.7300,100,1,14.4800,700,1,12.7100,100,1,14.5199,200,2,12.5000,700,1,14.5500,100,1,12.4600,100,1,14.5600,800,2,12.4299,700,1,14.5999,700,1,12.4199,700,1,14.6300,100,1,ARL,326837501
2025,2025-07-17T16:07:00.084965637Z,2025-07-17T16:07:00.084965637Z,10,2,1108,A,A,0,15.3800,100,130,165626,276614295,13.1099,100,1,13.8499,2,1,12.9800,200,2,14.2599,100,1,12.9000,2,1,14.2799,100,1,12.8599,100,1,14.4600,100,1,12.7300,100,1,14.4800,700,1,12.7100,100,1,14.5199,200,2,12.5000,700,1,14.5500,100,1,12.4600,100,1,14.5600,800,2,12.4299,700,1,14.5999,700,1,12.4199,700,1,14.6300,100,1,ARL,331929445
2026,2025-07-17T16:07:00.090194106Z,2025-07-17T16:07:00.090194106Z,10,2,1108,C,A,0,14.5500,100,0,165651,276614378,13.1099,100,1,13.8499,2,1,12.9800,200,2,14.2599,100,1,12.9000,2,1,14.2799,100,1,12.8599,100,1,14.4600,100,1,12.7300,100,1,14.4800,700,1,12.7100,100,1,14.5199,200,2,12.5000,700,1,14.5600,800,2,12.4600,100,1,14.5999,700,1,12.4299,700,1,14.6300,100,1,12.4199,700,1,14.9600,100,1,ARL,331051173
2027,2025-07-17T16:07:00.090194106Z,2025-07-17T16:07:00.090194106Z,10,2,1108,A,A,0,14.9600,100,130,165651,276614378,13.1099,100,1,13.8499,2,1,12.9800,200,2,14.2599,100,1,12.9000,2,1,14.2799,100,1,12.8599,100,1,14.4600,100,1,12.7300,100,1,14.4800,700,1,12.7100,100,1,14.5199,200,2,12.5000,700,1,14.5600,800,2,12.4600,100,1,14.5999,700,1,12.4299,700,1,14.6300,100,1,12.4199,700,1,14.9600,200,2,ARL,331929633
2028,2025-07-17T16:07:00.101927028Z,2025-07-17T16:07:00.101927028Z,10,2,1108,A,A,0,14.6799,700,130,165119,276614699,13.1099,100,1,13.8499,2,1,12.9800,200,2,14.2599,100,1,12.9000,2,1,14.2799,100,1,12.8599,100,1,14.4600,100,1,12.7300,100,1,14.4800,700,1,12.7100,100,1,14.5199,200,2,12.5000,700,1,14.5600,800,2,12.4600,100,1,14.5999,700,1,12.4299,700,1,14.6300,100,1,12.4199,700,1,14.6799,700,1,ARL,331929977
2029,2025-07-17T16:07:00.287416733Z,2025-07-17T16:07:00.287416733Z,10,2,1108,C,A,0,17.2899,100,0,165715,276617288,13.1099,100,1,13.8499,2,1,12.9800,200,2,14.2599,100,1,12.9000,2,1,14.2799,100,1,12.8599,100,1,14.4600,100,1,12.7300,100,1,14.4800,700,1,12.7100,100,1,14.5199,200,2,12.5000,700,1,14.5600,800,2,12.4600,100,1,14.5999,700,1,12.4299,700,1,14.6300,100,1,12.4199,700,1,14.6799,700,1,ARL,330789509
2030,2025-07-17T16:07:00.287416733Z,2025-07-17T16:07:00.287416733Z,10,2,1108,A,A,0,17.7600,100,130,165715,276617288,13.1099,100,1,13.8499,2,1,12.9800,200,2,14.2599,100,1,12.9000,2,1,14.2799,100,1,12.8599,100,1,14.4600,100,1,12.7300,100,1,14.4800,700,1,12.7100,100,1,14.5199,200,2,12.5000,700,1,14.5600,800,2,12.4600,100,1,14.5999,700,1,12.4299,700,1,14.6300,100,1,12.4199,700,1,14.6799,700,1,ARL,331934277
2031,2025-07-17T16:07:00.293454856Z,2025-07-17T16:07:00.293454856Z,10,2,1108,C,A,0,15.6300,100,0,165578,276617317,13.1099,100,1,13.8499,2,1,12.9800,200,2,14.2599,100,1,12.9000,2,1,14.2799,100,1,12.8599,100,1,14.4600,100,1,12.7300,100,1,14.4800,700,1,12.7100,100,1,14.5199,200,2,12.5000,700,1,14.5600,800,2,12.4600,100,1,14.5999,700,1,12.4299,700,1,14.6300,100,1,12.4199,700,1,14.6799,700,1,ARL,331051145
2032,2025-07-17T16:07:00.293454856Z,2025-07-17T16:07:00.293454856Z,10,2,1108,A,A,0,16.0799,100,130,165578,276617317,13.1099,100,1,13.8499,2,1,12.9800,200,2,14.2599,100,1,12.9000,2,1,14.2799,100,1,12.8599,100,1,14.4600,100,1,12.7300,100,1,14.4800,700,1,12.7100,100,1,14.5199,200,2,12.5000,700,1,14.5600,800,2,12.4600,100,1,14.5999,700,1,12.4299,700,1,14.6300,100,1,12.4199,700,1,14.6799,700,1,ARL,331934377
2033,2025-07-17T16:07:00.494492099Z,2025-07-17T16:07:00.494492099Z,10,2,1108,A,A,0,13.8599,100,130,165396,276622423,13.1099,100,1,13.8499,2,1,12.9800,200,2,13.8599,100,1,12.9000,2,1,14.2599,100,1,12.8599,100,1,14.2799,100,1,12.7300,100,1,14.4600,100,1,12.7100,100,1,14.4800,700,1,12.5000,700,1,14.5199,200,2,12.4600,100,1,14.5600,800,2,12.4299,700,1,14.5999,700,1,12.4199,700,1,14.6300,100,1,ARL,331942821
2034,2025-07-17T16:07:00.495152219Z,2025-07-17T16:07:00.495152219Z,10,2,1108,C,B,0,12.3599,100,0,166026,276622452,13.1099,100,1,13.8499,2,1,12.9800,200,2,13.8599,100,1,12.9000,2,1,14.2599,100,1,12.8599,100,1,14.2799,100,1,12.7300,100,1,14.4600,100,1,12.7100,100,1,14.4800,700,1,12.5000,700,1,14.5199,200,2,12.4600,100,1,14.5600,800,2,12.4299,700,1,14.5999,700,1,12.4199,700,1,14.6300,100,1,ARL,288723817
2035,2025-07-17T16:07:00.495152219Z,2025-07-17T16:07:00.495152219Z,10,2,1108,A,B,0,12.4900,100,130,166026,276622452,13.1099,100,1,13.8499,2,1,12.9800,200,2,13.8599,100,1,12.9000,2,1,14.2599,100,1,12.8599,100,1,14.2799,100,1,12.7300,100,1,14.4600,100,1,12.7100,100,1,14.4800,700,1,12.5000,700,1,14.5199,200,2,12.4900,100,1,14.5600,800,2,12.4600,100,1,14.5999,700,1,12.4299,700,1,14.6300,100,1,ARL,331942901
2036,2025-07-17T16:07:00.495233001Z,2025-07-17T16:07:00.495233001Z,10,2,1108,C,A,0,15.0600,100,0,165643,276622455,13.1099,100,1,13.8499,2,1,12.9800,200,2,13.8599,100,1,12.9000,2,1,14.2599,100,1,12.8599,100,1,14.2799,100,1,12.7300,100,1,14.4600,100,1,12.7100,100,1,14.4800,700,1,12.5000,700,1,14.5199,200,2,12.4900,100,1,14.5600,800,2,12.4600,100,1,14.5999,700,1,12.4299,700,1,14.6300,100,1,ARL,331929065
2037,2025-07-17T16:07:00.495233001Z,2025-07-17T16:07:00.495233001Z,10,2,1108,A,A,0,14.9299,100,130,165643,276622455,13.1099,100,1,13.8499,2,1,12.9800,200,2,13.8599,100,1,12.9000,2,1,14.2599,100,1,12.8599,100,1,14.2799,100,1,12.7300,100,1,14.4600,100,1,12.7100,100,1,14.4800,700,1,12.5000,700,1,14.5199,200,2,12.4900,100,1,14.5600,800,2,12.4600,100,1,14.5999,700,1,12.4299,700,1,14.6300,100,1,ARL,331942913
2038,2025-07-17T16:07:00.495823953Z,2025-07-17T16:07:00.495823953Z,10,2,1108,C,B,0,12.3599,100,0,165645,276622469,13.1099,100,1,13.8499,2,1,12.9800,200,2,13.8599,100,1,12.9000,2,1,14.2599,100,1,12.8599,100,1,14.2799,100,1,12.7300,100,1,14.4600,100,1,12.7100,100,1,14.4800,700,1,12.5000,700,1,14.5199,200,2,12.4900,100,1,14.5600,800,2,12.4600,100,1,14.5999,700,1,12.4299,700,1,14.6300,100,1,ARL,288723813
2039,2025-07-17T16:07:00.495823953Z,2025-07-17T16:07:00.495823953Z,10,2,1108,A,B,0,12.4900,100,130,165645,276622469,13.1099,100,1,13.8499,2,1,12.9800,200,2,13.8599,100,1,12.9000,2,1,14.2599,100,1,12.8599,100,1,14.2799,100,1,12.7300,100,1,14.4600,100,1,12.7100,100,1,14.4800,700,1,12.5000,700,1,14.5199,200,2,12.4900,200,2,14.5600,800,2,12.4600,100,1,14.5999,700,1,12.4299,700,1,14.6300,100,1,ARL,331942945
2040,2025-07-17T16:07:00.496317847Z,2025-07-17T16:07:00.496317847Z,10,2,1108,C,A,0,17.7600,100,0,165613,276622478,13.1099,100,1,13.8499,2,1,12.9800,200,2,13.8599,100,1,12.9000,2,1,14.2599,100,1,12.8599,100,1,14.2799,100,1,12.7300,100,1,14.4600,100,1,12.7100,100,1,14.4800,700,1,12.5000,700,1,14.5199,200,2,12.4900,200,2,14.5600,800,2,12.4600,100,1,14.5999,700,1,12.4299,700,1,14.6300,100,1,ARL,331934277
2041,2025-07-17T16:07:00.496317847Z,2025-07-17T16:07:00.496317847Z,10,2,1108,A,A,0,17.6099,100,130,165613,276622478,13.1099,100,1,13.8499,2,1,12.9800,200,2,13.8599,100,1,12.9000,2,1,14.2599,100,1,12.8599,100,1,14.2799,100,1,12.7300,100,1,14.4600,100,1,12.7100,100,1,14.4800,700,1,12.5000,700,1,14.5199,200,2,12.4900,200,2,14.5600,800,2,12.4600,100,1,14.5999,700,1,12.4299,700,1,14.6300,100,1,ARL,331942981
2042,2025-07-17T16:07:00.499501052Z,2025-07-17T16:07:00.499501052Z,10,2,1108,C,A,0,14.2599,100,130,165097,276622569,13.1099,100,1,13.8499,2,1,12.9800,200,2,13.8599,100,1,12.9000,2,1,14.2799,100,1,12.8599,100,1,14.4600,100,1,12.7300,100,1,14.4800,700,1,12.7100,100,1,14.5199,200,2,12.5000,700,1,14.5600,800,2,12.4900,200,2,14.5999,700,1,12.4600,100,1,14.6300,100,1,12.4299,700,1,14.6799,700,1,ARL,331929041
2043,2025-07-17T16:07:00.499549738Z,2025-07-17T16:07:00.499549738Z,10,2,1108,A,A,0,14.1400,100,130,165180,276622571,13.1099,100,1,13.8499,2,1,12.9800,200,2,13.8599,100,1,12.9000,2,1,14.1400,100,1,12.8599,100,1,14.2799,100,1,12.7300,100,1,14.4600,100,1,12.7100,100,1,14.4800,700,1,12.5000,700,1,14.5199,200,2,12.4900,200,2,14.5600,800,2,12.4600,100,1,14.5999,700,1,12.4299,700,1,14.6300,100,1,ARL,331943133
2044,2025-07-17T16:07:22.814776694Z,2025-07-17T16:07:22.814776694Z,10,2,1108,A,A,0,13.6899,15,130,165115,276946179,13.1099,100,1,13.6899,15,1,12.9800,200,2,13.8499,2,1,12.9000,2,1,13.8599,100,1,12.8599,100,1,14.1400,100,1,12.7300,100,1,14.2799,100,1,12.7100,100,1,14.4600,100,1,12.5000,700,1,14.4800,700,1,12.4900,200,2,14.5199,200,2,12.4600,100,1,14.5600,800,2,12.4299,700,1,14.5999,700,1,ARL,332385317
2045,2025-07-17T16:07:22.814891345Z,2025-07-17T16:07:22.814891345Z,10,2,1108,C,A,0,13.8599,100,0,166162,276946183,13.1099,100,1,13.6899,15,1,12.9800,200,2,13.8499,2,1,12.9000,2,1,14.1400,100,1,12.8599,100,1,14.2799,100,1,12.7300,100,1,14.4600,100,1,12.7100,100,1,14.4800,700,1,12.5000,700,1,14.5199,200,2,12.4900,200,2,14.5600,800,2,12.4600,100,1,14.5999,700,1,12.4299,700,1,14.6300,100,1,ARL,331942821
2046,2025-07-17T16:07:22.814891345Z,2025-07-17T16:07:22.814891345Z,10,2,1108,A,A,0,13.6999,100,130,166162,276946183,13.1099,100,1,13.6899,15,1,12.9800,200,2,13.6999,100,1,12.9000,2,1,13.8499,2,1,12.8599,100,1,14.1400,100,1,12.7300,100,1,14.2799,100,1,12.7100,100,1,14.4600,100,1,12.5000,700,1,14.4800,700,1,12.4900,200,2,14.5199,200,2,12.4600,100,1,14.5600,800,2,12.4299,700,1,14.5999,700,1,ARL,332385325
2047,2025-07-17T16:07:22.815625345Z,2025-07-17T16:07:22.815625345Z,10,2,1108,C,A,0,14.9299,100,0,165545,276946264,13.1099,100,1,13.6899,15,1,12.9800,200,2,13.6999,100,1,12.9000,2,1,13.8499,2,1,12.8599,100,1,14.1400,100,1,12.7300,100,1,14.2799,100,1,12.7100,100,1,14.4600,100,1,12.5000,700,1,14.4800,700,1,12.4900,200,2,14.5199,200,2,12.4600,100,1,14.5600,800,2,12.4299,700,1,14.5999,700,1,ARL,331942913
2048,2025-07-17T16:07:22.815625345Z,2025-07-17T16:07:22.815625345Z,10,2,1108,A,A,0,14.7599,100,130,165545,276946264,13.1099,100,1,13.6899,15,1,12.9800,200,2,13.6999,100,1,12.9000,2,1,13.8499,2,1,12.8599,100,1,14.1400,100,1,12.7300,100,1,14.2799,100,1,12.7100,100,1,14.4600,100,1,12.5000,700,1,14.4800,700,1,12.4900,200,2,14.5199,200,2,12.4600,100,1,14.5600,800,2,12.4299,700,1,14.5999,700,1,ARL,332385501
2049,2025-07-17T16:07:22.817341789Z,2025-07-17T16:07:22.817341789Z,10,2,1108,C,A,0,14.9600,100,0,166020,276946309,13.1099,100,1,13.6899,15,1,12.9800,200,2,13.6999,100,1,12.9000,2,1,13.8499,2,1,12.8599,100,1,14.1400,100,1,12.7300,100,1,14.2799,100,1,12.7100,100,1,14.4600,100,1,12.5000,700,1,14.4800,700,1,12.4900,200,2,14.5199,200,2,12.4600,100,1,14.5600,800,2,12.4299,700,1,14.5999,700,1,ARL,331929633
2050,2025-07-17T16:07:22.817341789Z,2025-07-17T16:07:22.817341789Z,10,2,1108,A,A,0,14.6600,100,130,166020,276946309,13.1099,100,1,13.6899,15,1,12.9800,200,2,13.6999,100,1,12.9000,2,1,13.8499,2,1,12.8599,100,1,14.1400,100,1,12.7300,100,1,14.2799,100,1,12.7100,100,1,14.4600,100,1,12.5000,700,1,14.4800,700,1,12.4900,200,2,14.5199,200,2,12.4600,100,1,14.5600,800,2,12.4299,700,1,14.5999,700,1,ARL,332385565
2051,2025-07-17T16:07:22.817459170Z,2025-07-17T16:07:22.817459170Z,10,2,1108,C,A,0,15.3800,100,0,165529,276946313,13.1099,100,1,13.6899,15,1,12.9800,200,2,13.6999,100,1,12.9000,2,1,13.8499,2,1,12.8599,100,1,14.1400,100,1,12.7300,100,1,14.2799,100,1,12.7100,100,1,14.4600,100,1,12.5000,700,1,14.4800,700,1,12.4900,200,2,14.5199,200,2,12.4600,100,1,14.5600,800,2,12.4299,700,1,14.5999,700,1,ARL,331929445
2052,2025-07-17T16:07:22.817459170Z,2025-07-17T16:07:22.817459170Z,10,2,1108,A,A,0,15.0700,100,130,165529,276946313,13.1099,100,1,13.6899,15,1,12.9800,200,2,13.6999,100,1,12.9000,2,1,13.8499,2,1,12.8599,100,1,14.1400,100,1,12.7300,100,1,14.2799,100,1,12.7100,100,1,14.4600,100,1,12.5000,700,1,14.4800,700,1,12.4900,200,2,14.5199,200,2,12.4600,100,1,14.5600,800,2,12.4299,700,1,14.5999,700,1,ARL,332385569
2053,2025-07-17T16:07:22.818400003Z,2025-07-17T16:07:22.818400003Z,10,2,1108,C,A,0,16.0799,100,0,165763,276946327,13.1099,100,1,13.6899,15,1,12.9800,200,2,13.6999,100,1,12.9000,2,1,13.8499,2,1,12.8599,100,1,14.1400,100,1,12.7300,100,1,14.2799,100,1,12.7100,100,1,14.4600,100,1,12.5000,700,1,14.4800,700,1,12.4900,200,2,14.5199,200,2,12.4600,100,1,14.5600,800,2,12.4299,700,1,14.5999,700,1,ARL,331934377
2054,2025-07-17T16:07:22.818400003Z,2025-07-17T16:07:22.818400003Z,10,2,1108,A,A,0,15.7599,100,130,165763,276946327,13.1099,100,1,13.6899,15,1,12.9800,200,2,13.6999,100,1,12.9000,2,1,13.8499,2,1,12.8599,100,1,14.1400,100,1,12.7300,100,1,14.2799,100,1,12.7100,100,1,14.4600,100,1,12.5000,700,1,14.4800,700,1,12.4900,200,2,14.5199,200,2,12.4600,100,1,14.5600,800,2,12.4299,700,1,14.5999,700,1,ARL,332385585
2055,2025-07-17T16:07:22.819545360Z,2025-07-17T16:07:22.819545360Z,10,2,1108,C,A,0,17.6099,100,0,165623,276946336,13.1099,100,1,13.6899,15,1,12.9800,200,2,13.6999,100,1,12.9000,2,1,13.8499,2,1,12.8599,100,1,14.1400,100,1,12.7300,100,1,14.2799,100,1,12.7100,100,1,14.4600,100,1,12.5000,700,1,14.4800,700,1,12.4900,200,2,14.5199,200,2,12.4600,100,1,14.5600,800,2,12.4299,700,1,14.5999,700,1,ARL,331942981
2056,2025-07-17T16:07:22.819545360Z,2025-07-17T16:07:22.819545360Z,10,2,1108,A,A,0,17.3999,100,130,165623,276946336,13.1099,100,1,13.6899,15,1,12.9800,200,2,13.6999,100,1,12.9000,2,1,13.8499,2,1,12.8599,100,1,14.1400,100,1,12.7300,100,1,14.2799,100,1,12.7100,100,1,14.4600,100,1,12.5000,700,1,14.4800,700,1,12.4900,200,2,14.5199,200,2,12.4600,100,1,14.5600,800,2,12.4299,700,1,14.5999,700,1,ARL,332385593
2057,2025-07-17T16:07:22.819606945Z,2025-07-17T16:07:22.819606945Z,10,2,1108,C,A,0,14.6300,100,0,165463,276946337,13.1099,100,1,13.6899,15,1,12.9800,200,2,13.6999,100,1,12.9000,2,1,13.8499,2,1,12.8599,100,1,14.1400,100,1,12.7300,100,1,14.2799,100,1,12.7100,100,1,14.4600,100,1,12.5000,700,1,14.4800,700,1,12.4900,200,2,14.5199,200,2,12.4600,100,1,14.5600,800,2,12.4299,700,1,14.5999,700,1,ARL,331927477
2058,2025-07-17T16:07:22.819606945Z,2025-07-17T16:07:22.819606945Z,10,2,1108,A,A,0,14.4900,100,130,165463,276946337,13.1099,100,1,13.6899,15,1,12.9800,200,2,13.6999,100,1,12.9000,2,1,13.8499,2,1,12.8599,100,1,14.1400,100,1,12.7300,100,1,14.2799,100,1,12.7100,100,1,14.4600,100,1,12.5000,700,1,14.4800,700,1,12.4900,200,2,14.4900,100,1,12.4600,100,1,14.5199,200,2,12.4299,700,1,14.5600,800,2,ARL,332385597
2059,2025-07-17T16:07:22.821000003Z,2025-07-17T16:07:22.821000003Z,10,2,1108,C,A,0,14.1400,100,130,165448,276946343,13.1099,100,1,13.6899,15,1,12.9800,200,2,13.6999,100,1,12.9000,2,1,13.8499,2,1,12.8599,100,1,14.2799,100,1,12.7300,100,1,14.4600,100,1,12.7100,100,1,14.4800,700,1,12.5000,700,1,14.4900,100,1,12.4900,200,2,14.5199,200,2,12.4600,100,1,14.5600,800,2,12.4299,700,1,14.5999,700,1,ARL,331943133
2060,2025-07-17T16:07:22.821052982Z,2025-07-17T16:07:22.821052982Z,10,2,1108,A,A,0,13.9700,100,130,165225,276946344,13.1099,100,1,13.6899,15,1,12.9800,200,2,13.6999,100,1,12.9000,2,1,13.8499,2,1,12.8599,100,1,13.9700,100,1,12.7300,100,1,14.2799,100,1,12.7100,100,1,14.4600,100,1,12.5000,700,1,14.4800,700,1,12.4900,200,2,14.4900,100,1,12.4600,100,1,14.5199,200,2,12.4299,700,1,14.5600,800,2,ARL,332385613
2061,2025-07-17T16:07:22.831949887Z,2025-07-17T16:07:22.831949887Z,10,2,1108,C,A,0,14.9600,100,0,169333,276946801,13.1099,100,1,13.6899,15,1,12.9800,200,2,13.6999,100,1,12.9000,2,1,13.8499,2,1,12.8599,100,1,13.9700,100,1,12.7300,100,1,14.2799,100,1,12.7100,100,1,14.4600,100,1,12.5000,700,1,14.4800,700,1,12.4900,200,2,14.4900,100,1,12.4600,100,1,14.5199,200,2,12.4299,700,1,14.5600,800,2,ARL,331928129
2062,2025-07-17T16:07:22.831949887Z,2025-07-17T16:07:22.831949887Z,10,2,1108,A,A,0,14.6600,100,128,169333,276946801,13.1099,100,1,13.6899,15,1,12.9800,200,2,13.6999,100,1,12.9000,2,1,13.8499,2,1,12.8599,100,1,13.9700,100,1,12.7300,100,1,14.2799,100,1,12.7100,100,1,14.4600,100,1,12.5000,700,1,14.4800,700,1,12.4900,200,2,14.4900,100,1,12.4600,100,1,14.5199,200,2,12.4299,700,1,14.5600,800,2,ARL,332386121
2063,2025-07-17T16:07:28.273658191Z,2025-07-17T16:07:28.273658191Z,10,2,1108,C,A,0,13.6899,15,130,165417,277012951,13.1099,100,1,13.6999,100,1,12.9800,200,2,13.8499,2,1,12.9000,2,1,13.9700,100,1,12.8599,100,1,14.2799,100,1,12.7300,100,1,14.4600,100,1,12.7100,100,1,14.4800,700,1,12.5000,700,1,14.4900,100,1,12.4900,200,2,14.5199,200,2,12.4600,100,1,14.5600,800,2,12.4299,700,1,14.5999,700,1,ARL,332385317
2064,2025-07-17T16:07:28.700815737Z,2025-07-17T16:07:28.700815737Z,10,2,1108,C,A,0,13.6999,100,130,165412,277019711,13.1099,100,1,13.8499,2,1,12.9800,200,2,13.9700,100,1,12.9000,2,1,14.2799,100,1,12.8599,100,1,14.4600,100,1,12.7300,100,1,14.4800,700,1,12.7100,100,1,14.4900,100,1,12.5000,700,1,14.5199,200,2,12.4900,200,2,14.5600,800,2,12.4600,100,1,14.5999,700,1,12.4299,700,1,14.6600,200,2,ARL,332385325
2065,2025-07-17T16:07:28.701230409Z,2025-07-17T16:07:28.701230409Z,10,2,1108,C,B,0,12.9000,2,0,166260,277019718,13.1099,100,1,13.8499,2,1,12.9800,200,2,13.9700,100,1,12.8599,100,1,14.2799,100,1,12.7300,100,1,14.4600,100,1,12.7100,100,1,14.4800,700,1,12.5000,700,1,14.4900,100,1,12.4900,200,2,14.5199,200,2,12.4600,100,1,14.5600,800,2,12.4299,700,1,14.5999,700,1,12.4199,700,1,14.6600,200,2,ARL,331694297
2066,2025-07-17T16:07:28.701230409Z,2025-07-17T16:07:28.701230409Z,10,2,1108,A,B,0,13.0099,2,130,166260,277019718,13.1099,100,1,13.8499,2,1,13.0099,2,1,13.9700,100,1,12.9800,200,2,14.2799,100,1,12.8599,100,1,14.4600,100,1,12.7300,100,1,14.4800,700,1,12.7100,100,1,14.4900,100,1,12.5000,700,1,14.5199,200,2,12.4900,200,2,14.5600,800,2,12.4600,100,1,14.5999,700,1,12.4299,700,1,14.6600,200,2,ARL,332494213
2067,2025-07-17T16:07:28.701547540Z,2025-07-17T16:07:28.701547540Z,10,2,1108,C,A,0,14.7599,100,0,165692,277019720,13.1099,100,1,13.8499,2,1,13.0099,2,1,13.9700,100,1,12.9800,200,2,14.2799,100,1,12.8599,100,1,14.4600,100,1,12.7300,100,1,14.4800,700,1,12.7100,100,1,14.4900,100,1,12.5000,700,1,14.5199,200,2,12.4900,200,2,14.5600,800,2,12.4600,100,1,14.5999,700,1,12.4299,700,1,14.6600,200,2,ARL,332385501
2068,2025-07-17T16:07:28.701547540Z,2025-07-17T16:07:28.701547540Z,10,2,1108,A,A,0,14.8200,100,130,165692,277019720,13.1099,100,1,13.8499,2,1,13.0099,2,1,13.9700,100,1,12.9800,200,2,14.2799,100,1,12.8599,100,1,14.4600,100,1,12.7300,100,1,14.4800,700,1,12.7100,100,1,14.4900,100,1,12.5000,700,1,14.5199,200,2,12.4900,200,2,14.5600,800,2,12.4600,100,1,14.5999,700,1,12.4299,700,1,14.6600,200,2,ARL,332494229
2069,2025-07-17T16:07:28.702000772Z,2025-07-17T16:07:28.702000772Z,10,2,1108,C,A,0,15.7599,100,0,165525,277019722,13.1099,100,1,13.8499,2,1,13.0099,2,1,13.9700,100,1,12.9800,200,2,14.2799,100,1,12.8599,100,1,14.4600,100,1,12.7300,100,1,14.4800,700,1,12.7100,100,1,14.4900,100,1,12.5000,700,1,14.5199,200,2,12.4900,200,2,14.5600,800,2,12.4600,100,1,14.5999,700,1,12.4299,700,1,14.6600,200,2,ARL,332385585
2070,2025-07-17T16:07:28.702000772Z,2025-07-17T16:07:28.702000772Z,10,2,1108,A,A,0,16.0100,100,130,165525,277019722,13.1099,100,1,13.8499,2,1,13.0099,2,1,13.9700,100,1,12.9800,200,2,14.2799,100,1,12.8599,100,1,14.4600,100,1,12.7300,100,1,14.4800,700,1,12.7100,100,1,14.4900,100,1,12.5000,700,1,14.5199,200,2,12.4900,200,2,14.5600,800,2,12.4600,100,1,14.5999,700,1,12.4299,700,1,14.6600,200,2,ARL,332494245
2071,2025-07-17T16:07:28.702476699Z,2025-07-17T16:07:28.702476699Z,10,2,1108,C,A,0,14.6600,100,0,165321,277019729,13.1099,100,1,13.8499,2,1,13.0099,2,1,13.9700,100,1,12.9800,200,2,14.2799,100,1,12.8599,100,1,14.4600,100,1,12.7300,100,1,14.4800,700,1,12.7100,100,1,14.4900,100,1,12.5000,700,1,14.5199,200,2,12.4900,200,2,14.5600,800,2,12.4600,100,1,14.5999,700,1,12.4299,700,1,14.6600,100,1,ARL,332386121
2072,2025-07-17T16:07:28.702476699Z,2025-07-17T16:07:28.702476699Z,10,2,1108,A,A,0,14.9499,100,130,165321,277019729,13.1099,100,1,13.8499,2,1,13.0099,2,1,13.9700,100,1,12.9800,200,2,14.2799,100,1,12.8599,100,1,14.4600,100,1,12.7300,100,1,14.4800,700,1,12.7100,100,1,14.4900,100,1,12.5000,700,1,14.5199,200,2,12.4900,200,2,14.5600,800,2,12.4600,100,1,14.5999,700,1,12.4299,700,1,14.6600,100,1,ARL,332494281
2073,2025-07-17T16:07:28.703357714Z,2025-07-17T16:07:28.703357714Z,10,2,1108,C,A,0,14.6600,100,0,165378,277019733,13.1099,100,1,13.8499,2,1,13.0099,2,1,13.9700,100,1,12.9800,200,2,14.2799,100,1,12.8599,100,1,14.4600,100,1,12.7300,100,1,14.4800,700,1,12.7100,100,1,14.4900,100,1,12.5000,700,1,14.5199,200,2,12.4900,200,2,14.5600,800,2,12.4600,100,1,14.5999,700,1,12.4299,700,1,14.6799,700,1,ARL,332385565
2074,2025-07-17T16:07:28.703357714Z,2025-07-17T16:07:28.703357714Z,10,2,1108,A,A,0,14.9499,100,130,165378,277019733,13.1099,100,1,13.8499,2,1,13.0099,2,1,13.9700,100,1,12.9800,200,2,14.2799,100,1,12.8599,100,1,14.4600,100,1,12.7300,100,1,14.4800,700,1,12.7100,100,1,14.4900,100,1,12.5000,700,1,14.5199,200,2,12.4900,200,2,14.5600,800,2,12.4600,100,1,14.5999,700,1,12.4299,700,1,14.6799,700,1,ARL,332494285
2075,2025-07-17T16:07:28.703754662Z,2025-07-17T16:07:28.703754662Z,10,2,1108,C,A,0,15.0700,100,0,165674,277019735,13.1099,100,1,13.8499,2,1,13.0099,2,1,13.9700,100,1,12.9800,200,2,14.2799,100,1,12.8599,100,1,14.4600,100,1,12.7300,100,1,14.4800,700,1,12.7100,100,1,14.4900,100,1,12.5000,700,1,14.5199,200,2,12.4900,200,2,14.5600,800,2,12.4600,100,1,14.5999,700,1,12.4299,700,1,14.6799,700,1,ARL,332385569
2076,2025-07-17T16:07:28.703754662Z,2025-07-17T16:07:28.703754662Z,10,2,1108,A,A,0,15.3699,100,130,165674,277019735,13.1099,100,1,13.8499,2,1,13.0099,2,1,13.9700,100,1,12.9800,200,2,14.2799,100,1,12.8599,100,1,14.4600,100,1,12.7300,100,1,14.4800,700,1,12.7100,100,1,14.4900,100,1,12.5000,700,1,14.5199,200,2,12.4900,200,2,14.5600,800,2,12.4600,100,1,14.5999,700,1,12.4299,700,1,14.6799,700,1,ARL,332494289
2077,2025-07-17T16:07:28.704032725Z,2025-07-17T16:07:28.704032725Z,10,2,1108,C,A,0,17.3999,100,0,165378,277019738,13.1099,100,1,13.8499,2,1,13.0099,2,1,13.9700,100,1,12.9800,200,2,14.2799,100,1,12.8599,100,1,14.4600,100,1,12.7300,100,1,14.4800,700,1,12.7100,100,1,14.4900,100,1,12.5000,700,1,14.5199,200,2,12.4900,200,2,14.5600,800,2,12.4600,100,1,14.5999,700,1,12.4299,700,1,14.6799,700,1,ARL,332385593
2078,2025-07-17T16:07:28.704032725Z,2025-07-17T16:07:28.704032725Z,10,2,1108,A,A,0,17.7500,100,130,165378,277019738,13.1099,100,1,13.8499,2,1,13.0099,2,1,13.9700,100,1,12.9800,200,2,14.2799,100,1,12.8599,100,1,14.4600,100,1,12.7300,100,1,14.4800,700,1,12.7100,100,1,14.4900,100,1,12.5000,700,1,14.5199,200,2,12.4900,200,2,14.5600,800,2,12.4600,100,1,14.5999,700,1,12.4299,700,1,14.6799,700,1,ARL,332494297
2079,2025-07-17T16:07:28.724036175Z,2025-07-17T16:07:28.724036175Z,10,2,1108,C,A,0,13.9700,100,130,165665,277019926,13.1099,100,1,13.8499,2,1,13.0099,2,1,14.2799,100,1,12.9800,200,2,14.4600,100,1,12.8599,100,1,14.4800,700,1,12.7300,100,1,14.4900,100,1,12.7100,100,1,14.5199,200,2,12.5000,700,1,14.5600,800,2,12.4900,200,2,14.5999,700,1,12.4600,100,1,14.6799,700,1,12.4299,700,1,14.8200,100,1,ARL,332385613
2080,2025-07-17T16:07:28.724085453Z,2025-07-17T16:07:28.724085453Z,10,2,1108,A,A,0,14.1999,100,130,165382,277019929,13.1099,100,1,13.8499,2,1,13.0099,2,1,14.1999,100,1,12.9800,200,2,14.2799,100,1,12.8599,100,1,14.4600,100,1,12.7300,100,1,14.4800,700,1,12.7100,100,1,14.4900,100,1,12.5000,700,1,14.5199,200,2,12.4900,200,2,14.5600,800,2,12.4600,100,1,14.5999,700,1,12.4299,700,1,14.6799,700,1,ARL,332494893
2081,2025-07-17T16:07:28.751662660Z,2025-07-17T16:07:28.751662660Z,10,2,1108,C,A,0,14.8200,100,0,165460,277020284,13.1099,100,1,13.8499,2,1,13.0099,2,1,14.1999,100,1,12.9800,200,2,14.2799,100,1,12.8599,100,1,14.4600,100,1,12.7300,100,1,14.4800,700,1,12.7100,100,1,14.4900,100,1,12.5000,700,1,14.5199,200,2,12.4900,200,2,14.5600,800,2,12.4600,100,1,14.5999,700,1,12.4299,700,1,14.6799,700,1,ARL,332494229
2082,2025-07-17T16:07:28.751662660Z,2025-07-17T16:07:28.751662660Z,10,2,1108,A,A,0,15.0500,100,130,165460,277020284,13.1099,100,1,13.8499,2,1,13.0099,2,1,14.1999,100,1,12.9800,200,2,14.2799,100,1,12.8599,100,1,14.4600,100,1,12.7300,100,1,14.4800,700,1,12.7100,100,1,14.4900,100,1,12.5000,700,1,14.5199,200,2,12.4900,200,2,14.5600,800,2,12.4600,100,1,14.5999,700,1,12.4299,700,1,14.6799,700,1,ARL,332495781
2083,2025-07-17T16:07:28.830995364Z,2025-07-17T16:07:28.830995364Z,10,2,1108,C,A,0,14.4900,100,130,165623,277021007,13.1099,100,1,13.8499,2,1,13.0099,2,1,14.1999,100,1,12.9800,200,2,14.2799,100,1,12.8599,100,1,14.4600,100,1,12.7300,100,1,14.4800,700,1,12.7100,100,1,14.5199,200,2,12.5000,700,1,14.5600,800,2,12.4900,200,2,14.5999,700,1,12.4600,100,1,14.6799,700,1,12.4299,700,1,14.9499,200,2,ARL,332385597
2084,2025-07-17T16:07:28.831125667Z,2025-07-17T16:07:28.831125667Z,10,2,1108,A,A,0,14.7699,100,130,165710,277021012,13.1099,100,1,13.8499,2,1,13.0099,2,1,14.1999,100,1,12.9800,200,2,14.2799,100,1,12.8599,100,1,14.4600,100,1,12.7300,100,1,14.4800,700,1,12.7100,100,1,14.5199,200,2,12.5000,700,1,14.5600,800,2,12.4900,200,2,14.5999,700,1,12.4600,100,1,14.6799,700,1,12.4299,700,1,14.7699,100,1,ARL,332497653
2085,2025-07-17T16:07:29.214500816Z,2025-07-17T16:07:29.214500816Z,10,2,1108,A,A,0,13.8599,100,128,166454,277029015,13.1099,100,1,13.8499,2,1,13.0099,2,1,13.8599,100,1,12.9800,200,2,14.1999,100,1,12.8599,100,1,14.2799,100,1,12.7300,100,1,14.4600,100,1,12.7100,100,1,14.4800,700,1,12.5000,700,1,14.5199,200,2,12.4900,200,2,14.5600,800,2,12.4600,100,1,14.5999,700,1,12.4299,700,1,14.6799,700,1,ARL,332508813
2086,2025-07-17T16:07:29.215292291Z,2025-07-17T16:07:29.215292291Z,10,2,1108,C,A,0,15.0500,100,0,166553,277029273,13.1099,100,1,13.8499,2,1,13.0099,2,1,13.8599,100,1,12.9800,200,2,14.1999,100,1,12.8599,100,1,14.2799,100,1,12.7300,100,1,14.4600,100,1,12.7100,100,1,14.4800,700,1,12.5000,700,1,14.5199,200,2,12.4900,200,2,14.5600,800,2,12.4600,100,1,14.5999,700,1,12.4299,700,1,14.6799,700,1,ARL,332495781
2087,2025-07-17T16:07:29.215292291Z,2025-07-17T16:07:29.215292291Z,10,2,1108,A,A,0,14.9299,100,128,166553,277029273,13.1099,100,1,13.8499,2,1,13.0099,2,1,13.8599,100,1,12.9800,200,2,14.1999,100,1,12.8599,100,1,14.2799,100,1,12.7300,100,1,14.4600,100,1,12.7100,100,1,14.4800,700,1,12.5000,700,1,14.5199,200,2,12.4900,200,2,14.5600,800,2,12.4600,100,1,14.5999,700,1,12.4299,700,1,14.6799,700,1,ARL,332508997
2088,2025-07-17T16:08:20.816087447Z,2025-07-17T16:08:20.816087447Z,10,2,1108,A,A,0,13.6799,15,130,165403,277732167,13.1099,100,1,13.6799,15,1,13.0099,2,1,13.8499,2,1,12.9800,200,2,13.8599,100,1,12.8599,100,1,14.1999,100,1,12.7300,100,1,14.2799,100,1,12.7100,100,1,14.4600,100,1,12.5000,700,1,14.4800,700,1,12.4900,200,2,14.5199,200,2,12.4600,100,1,14.5600,800,2,12.4299,700,1,14.5999,700,1,ARL,333436357
2089,2025-07-17T16:08:20.816200644Z,2025-07-17T16:08:20.816200644Z,10,2,1108,C,A,0,13.8599,100,0,165561,277732170,13.1099,100,1,13.6799,15,1,13.0099,2,1,13.8499,2,1,12.9800,200,2,14.1999,100,1,12.8599,100,1,14.2799,100,1,12.7300,100,1,14.4600,100,1,12.7100,100,1,14.4800,700,1,12.5000,700,1,14.5199,200,2,12.4900,200,2,14.5600,800,2,12.4600,100,1,14.5999,700,1,12.4299,700,1,14.6799,700,1,ARL,332508813
2090,2025-07-17T16:08:20.816200644Z,2025-07-17T16:08:20.816200644Z,10,2,1108,A,A,0,13.6899,100,130,165561,277732170,13.1099,100,1,13.6799,15,1,13.0099,2,1,13.6899,100,1,12.9800,200,2,13.8499,2,1,12.8599,100,1,14.1999,100,1,12.7300,100,1,14.2799,100,1,12.7100,100,1,14.4600,100,1,12.5000,700,1,14.4800,700,1,12.4900,200,2,14.5199,200,2,12.4600,100,1,14.5600,800,2,12.4299,700,1,14.5999,700,1,ARL,333436361
2091,2025-07-17T16:08:20.816932150Z,2025-07-17T16:08:20.816932150Z,10,2,1108,C,A,0,14.9299,100,0,165437,277732194,13.1099,100,1,13.6799,15,1,13.0099,2,1,13.6899,100,1,12.9800,200,2,13.8499,2,1,12.8599,100,1,14.1999,100,1,12.7300,100,1,14.2799,100,1,12.7100,100,1,14.4600,100,1,12.5000,700,1,14.4800,700,1,12.4900,200,2,14.5199,200,2,12.4600,100,1,14.5600,800,2,12.4299,700,1,14.5999,700,1,ARL,332508997
2092,2025-07-17T16:08:20.816932150Z,2025-07-17T16:08:20.816932150Z,10,2,1108,A,A,0,14.7500,100,130,165437,277732194,13.1099,100,1,13.6799,15,1,13.0099,2,1,13.6899,100,1,12.9800,200,2,13.8499,2,1,12.8599,100,1,14.1999,100,1,12.7300,100,1,14.2799,100,1,12.7100,100,1,14.4600,100,1,12.5000,700,1,14.4800,700,1,12.4900,200,2,14.5199,200,2,12.4600,100,1,14.5600,800,2,12.4299,700,1,14.5999,700,1,ARL,333436397
2093,2025-07-17T16:08:20.818559377Z,2025-07-17T16:08:20.818559377Z,10,2,1108,C,A,0,15.3699,100,0,165725,277732213,13.1099,100,1,13.6799,15,1,13.0099,2,1,13.6899,100,1,12.9800,200,2,13.8499,2,1,12.8599,100,1,14.1999,100,1,12.7300,100,1,14.2799,100,1,12.7100,100,1,14.4600,100,1,12.5000,700,1,14.4800,700,1,12.4900,200,2,14.5199,200,2,12.4600,100,1,14.5600,800,2,12.4299,700,1,14.5999,700,1,ARL,332494289
2094,2025-07-17T16:08:20.818559377Z,2025-07-17T16:08:20.818559377Z,10,2,1108,A,A,0,15.0600,100,130,165725,277732213,13.1099,100,1,13.6799,15,1,13.0099,2,1,13.6899,100,1,12.9800,200,2,13.8499,2,1,12.8599,100,1,14.1999,100,1,12.7300,100,1,14.2799,100,1,12.7100,100,1,14.4600,100,1,12.5000,700,1,14.4800,700,1,12.4900,200,2,14.5199,200,2,12.4600,100,1,14.5600,800,2,12.4299,700,1,14.5999,700,1,ARL,333436421
2095,2025-07-17T16:08:20.818965359Z,2025-07-17T16:08:20.818965359Z,10,2,1108,C,A,0,14.9499,100,0,165461,277732216,13.1099,100,1,13.6799,15,1,13.0099,2,1,13.6899,100,1,12.9800,200,2,13.8499,2,1,12.8599,100,1,14.1999,100,1,12.7300,100,1,14.2799,100,1,12.7100,100,1,14.4600,100,1,12.5000,700,1,14.4800,700,1,12.4900,200,2,14.5199,200,2,12.4600,100,1,14.5600,800,2,12.4299,700,1,14.5999,700,1,ARL,332494285
2096,2025-07-17T16:08:20.818965359Z,2025-07-17T16:08:20.818965359Z,10,2,1108,A,A,0,14.6500,100,130,165461,277732216,13.1099,100,1,13.6799,15,1,13.0099,2,1,13.6899,100,1,12.9800,200,2,13.8499,2,1,12.8599,100,1,14.1999,100,1,12.7300,100,1,14.2799,100,1,12.7100,100,1,14.4600,100,1,12.5000,700,1,14.4800,700,1,12.4900,200,2,14.5199,200,2,12.4600,100,1,14.5600,800,2,12.4299,700,1,14.5999,700,1,ARL,333436425
2097,2025-07-17T16:08:20.819601669Z,2025-07-17T16:08:20.819601669Z,10,2,1108,C,A,0,17.7500,100,0,165422,277732221,13.1099,100,1,13.6799,15,1,13.0099,2,1,13.6899,100,1,12.9800,200,2,13.8499,2,1,12.8599,100,1,14.1999,100,1,12.7300,100,1,14.2799,100,1,12.7100,100,1,14.4600,100,1,12.5000,700,1,14.4800,700,1,12.4900,200,2,14.5199,200,2,12.4600,100,1,14.5600,800,2,12.4299,700,1,14.5999,700,1,ARL,332494297
2098,2025-07-17T16:08:20.819601669Z,2025-07-17T16:08:20.819601669Z,10,2,1108,A,A,0,17.3900,100,130,165422,277732221,13.1099,100,1,13.6799,15,1,13.0099,2,1,13.6899,100,1,12.9800,200,2,13.8499,2,1,12.8599,100,1,14.1999,100,1,12.7300,100,1,14.2799,100,1,12.7100,100,1,14.4600,100,1,12.5000,700,1,14.4800,700,1,12.4900,200,2,14.5199,200,2,12.4600,100,1,14.5600,800,2,12.4299,700,1,14.5999,700,1,ARL,333436441
2099,2025-07-17T16:08:20.820500575Z,2025-07-17T16:08:20.820500575Z,10,2,1108,C,A,0,16.0100,100,0,165594,277732228,13.1099,100,1,13.6799,15,1,13.0099,2,1,13.6899,100,1,12.9800,200,2,13.8499,2,1,12.8599,100,1,14.1999,100,1,12.7300,100,1,14.2799,100,1,12.7100,100,1,14.4600,100,1,12.5000,700,1,14.4800,700,1,12.4900,200,2,14.5199,200,2,12.4600,100,1,14.5600,800,2,12.4299,700,1,14.5999,700,1,ARL,332494245
2100,2025-07-17T16:08:20.820500575Z,2025-07-17T16:08:20.820500575Z,10,2,1108,A,A,0,15.7500,100,130,165594,277732228,13.1099,100,1,13.6799,15,1,13.0099,2,1,13.6899,100,1,12.9800,200,2,13.8499,2,1,12.8599,100,1,14.1999,100,1,12.7300,100,1,14.2799,100,1,12.7100,100,1,14.4600,100,1,12.5000,700,1,14.4800,700,1,12.4900,200,2,14.5199,200,2,12.4600,100,1,14.5600,800,2,12.4299,700,1,14.5999,700,1,ARL,333436449
2101,2025-07-17T16:08:20.821924168Z,2025-07-17T16:08:20.821924168Z,10,2,1108,C,A,0,14.1999,100,130,165376,277732239,13.1099,100,1,13.6799,15,1,13.0099,2,1,13.6899,100,1,12.9800,200,2,13.8499,2,1,12.8599,100,1,14.2799,100,1,12.7300,100,1,14.4600,100,1,12.7100,100,1,14.4800,700,1,12.5000,700,1,14.5199,200,2,12.4900,200,2,14.5600,800,2,12.4600,100,1,14.5999,700,1,12.4299,700,1,14.6500,100,1,ARL,332494893
2102,2025-07-17T16:08:20.821974299Z,2025-07-17T16:08:20.821974299Z,10,2,1108,A,A,0,13.9600,100,130,165242,277732240,13.1099,100,1,13.6799,15,1,13.0099,2,1,13.6899,100,1,12.9800,200,2,13.8499,2,1,12.8599,100,1,13.9600,100,1,12.7300,100,1,14.2799,100,1,12.7100,100,1,14.4600,100,1,12.5000,700,1,14.4800,700,1,12.4900,200,2,14.5199,200,2,12.4600,100,1,14.5600,800,2,12.4299,700,1,14.5999,700,1,ARL,333436473
2103,2025-07-17T16:08:20.829945074Z,2025-07-17T16:08:20.829945074Z,10,2,1108,C,A,0,14.9499,100,0,165425,277732299,13.1099,100,1,13.6799,15,1,13.0099,2,1,13.6899,100,1,12.9800,200,2,13.8499,2,1,12.8599,100,1,13.9600,100,1,12.7300,100,1,14.2799,100,1,12.7100,100,1,14.4600,100,1,12.5000,700,1,14.4800,700,1,12.4900,200,2,14.5199,200,2,12.4600,100,1,14.5600,800,2,12.4299,700,1,14.5999,700,1,ARL,332494281
2104,2025-07-17T16:08:20.829945074Z,2025-07-17T16:08:20.829945074Z,10,2,1108,A,A,0,14.6500,100,130,165425,277732299,13.1099,100,1,13.6799,15,1,13.0099,2,1,13.6899,100,1,12.9800,200,2,13.8499,2,1,12.8599,100,1,13.9600,100,1,12.7300,100,1,14.2799,100,1,12.7100,100,1,14.4600,100,1,12.5000,700,1,14.4800,700,1,12.4900,200,2,14.5199,200,2,12.4600,100,1,14.5600,800,2,12.4299,700,1,14.5999,700,1,ARL,333436589
2105,2025-07-17T16:08:20.966063681Z,2025-07-17T16:08:20.966063681Z,10,2,1108,C,A,0,14.7699,100,0,165585,277733304,13.1099,100,1,13.6799,15,1,13.0099,2,1,13.6899,100,1,12.9800,200,2,13.8499,2,1,12.8599,100,1,13.9600,100,1,12.7300,100,1,14.2799,100,1,12.7100,100,1,14.4600,100,1,12.5000,700,1,14.4800,700,1,12.4900,200,2,14.5199,200,2,12.4600,100,1,14.5600,800,2,12.4299,700,1,14.5999,700,1,ARL,332497653
2106,2025-07-17T16:08:20.966063681Z,2025-07-17T16:08:20.966063681Z,10,2,1108,A,A,0,14.4800,100,130,165585,277733304,13.1099,100,1,13.6799,15,1,13.0099,2,1,13.6899,100,1,12.9800,200,2,13.8499,2,1,12.8599,100,1,13.9600,100,1,12.7300,100,1,14.2799,100,1,12.7100,100,1,14.4600,100,1,12.5000,700,1,14.4800,800,2,12.4900,200,2,14.5199,200,2,12.4600,100,1,14.5600,800,2,12.4299,700,1,14.5999,700,1,ARL,333438545
2107,2025-07-17T16:08:22.998002821Z,2025-07-17T16:08:22.998002821Z,10,2,1108,C,A,0,13.6799,15,130,165365,277766492,13.1099,100,1,13.6899,100,1,13.0099,2,1,13.8499,2,1,12.9800,200,2,13.9600,100,1,12.8599,100,1,14.2799,100,1,12.7300,100,1,14.4600,100,1,12.7100,100,1,14.4800,800,2,12.5000,700,1,14.5199,200,2,12.4900,200,2,14.5600,800,2,12.4600,100,1,14.5999,700,1,12.4299,700,1,14.6500,200,2,ARL,333436357
2108,2025-07-17T16:08:27.482344236Z,2025-07-17T16:08:27.482344236Z,10,2,1108,C,A,0,13.6899,100,130,165448,277841171,13.1099,100,1,13.8499,2,1,13.0099,2,1,13.9600,100,1,12.9800,200,2,14.2799,100,1,12.8599,100,1,14.4600,100,1,12.7300,100,1,14.4800,800,2,12.7100,100,1,14.5199,200,2,12.5000,700,1,14.5600,800,2,12.4900,200,2,14.5999,700,1,12.4600,100,1,14.6500,200,2,12.4299,700,1,14.6799,700,1,ARL,333436361
2109,2025-07-17T16:08:27.483075481Z,2025-07-17T16:08:27.483075481Z,10,2,1108,C,A,0,14.7500,100,0,165526,277841175,13.1099,100,1,13.8499,2,1,13.0099,2,1,13.9600,100,1,12.9800,200,2,14.2799,100,1,12.8599,100,1,14.4600,100,1,12.7300,100,1,14.4800,800,2,12.7100,100,1,14.5199,200,2,12.5000,700,1,14.5600,800,2,12.4900,200,2,14.5999,700,1,12.4600,100,1,14.6500,200,2,12.4299,700,1,14.6799,700,1,ARL,333436397
2110,2025-07-17T16:08:27.483075481Z,2025-07-17T16:08:27.483075481Z,10,2,1108,A,A,0,14.9900,100,130,165526,277841175,13.1099,100,1,13.8499,2,1,13.0099,2,1,13.9600,100,1,12.9800,200,2,14.2799,100,1,12.8599,100,1,14.4600,100,1,12.7300,100,1,14.4800,800,2,12.7100,100,1,14.5199,200,2,12.5000,700,1,14.5600,800,2,12.4900,200,2,14.5999,700,1,12.4600,100,1,14.6500,200,2,12.4299,700,1,14.6799,700,1,ARL,333581389
2111,2025-07-17T16:08:27.483420069Z,2025-07-17T16:08:27.483420069Z,10,2,1108,C,A,0,14.5199,100,0,165823,277841178,13.1099,100,1,13.8499,2,1,13.0099,2,1,13.9600,100,1,12.9800,200,2,14.2799,100,1,12.8599,100,1,14.4600,100,1,12.7300,100,1,14.4800,800,2,12.7100,100,1,14.5199,100,1,12.5000,700,1,14.5600,800,2,12.4900,200,2,14.5999,700,1,12.4600,100,1,14.6500,200,2,12.4299,700,1,14.6799,700,1,ARL,328780577
2112,2025-07-17T16:08:27.483420069Z,2025-07-17T16:08:27.483420069Z,10,2,1108,A,A,0,14.7400,100,130,165823,277841178,13.1099,100,1,13.8499,2,1,13.0099,2,1,13.9600,100,1,12.9800,200,2,14.2799,100,1,12.8599,100,1,14.4600,100,1,12.7300,100,1,14.4800,800,2,12.7100,100,1,14.5199,100,1,12.5000,700,1,14.5600,800,2,12.4900,200,2,14.5999,700,1,12.4600,100,1,14.6500,200,2,12.4299,700,1,14.6799,700,1,ARL,333581393
2113,2025-07-17T16:08:27.483913735Z,2025-07-17T16:08:27.483913735Z,10,2,1108,C,A,0,14.6500,100,0,165489,277841218,13.1099,100,1,13.8499,2,1,13.0099,2,1,13.9600,100,1,12.9800,200,2,14.2799,100,1,12.8599,100,1,14.4600,100,1,12.7300,100,1,14.4800,800,2,12.7100,100,1,14.5199,100,1,12.5000,700,1,14.5600,800,2,12.4900,200,2,14.5999,700,1,12.4600,100,1,14.6500,100,1,12.4299,700,1,14.6799,700,1,ARL,333436589
2114,2025-07-17T16:08:27.483913735Z,2025-07-17T16:08:27.483913735Z,10,2,1108,A,A,0,14.9399,100,130,165489,277841218,13.1099,100,1,13.8499,2,1,13.0099,2,1,13.9600,100,1,12.9800,200,2,14.2799,100,1,12.8599,100,1,14.4600,100,1,12.7300,100,1,14.4800,800,2,12.7100,100,1,14.5199,100,1,12.5000,700,1,14.5600,800,2,12.4900,200,2,14.5999,700,1,12.4600,100,1,14.6500,100,1,12.4299,700,1,14.6799,700,1,ARL,333581409
2115,2025-07-17T16:08:27.484693568Z,2025-07-17T16:08:27.484693568Z,10,2,1108,C,A,0,17.3900,100,0,165620,277841226,13.1099,100,1,13.8499,2,1,13.0099,2,1,13.9600,100,1,12.9800,200,2,14.2799,100,1,12.8599,100,1,14.4600,100,1,12.7300,100,1,14.4800,800,2,12.7100,100,1,14.5199,100,1,12.5000,700,1,14.5600,800,2,12.4900,200,2,14.5999,700,1,12.4600,100,1,14.6500,100,1,12.4299,700,1,14.6799,700,1,ARL,333436441
2116,2025-07-17T16:08:27.484693568Z,2025-07-17T16:08:27.484693568Z,10,2,1108,A,A,0,17.7300,100,130,165620,277841226,13.1099,100,1,13.8499,2,1,13.0099,2,1,13.9600,100,1,12.9800,200,2,14.2799,100,1,12.8599,100,1,14.4600,100,1,12.7300,100,1,14.4800,800,2,12.7100,100,1,14.5199,100,1,12.5000,700,1,14.5600,800,2,12.4900,200,2,14.5999,700,1,12.4600,100,1,14.6500,100,1,12.4299,700,1,14.6799,700,1,ARL,333581425
2117,2025-07-17T16:08:27.484800296Z,2025-07-17T16:08:27.484800296Z,10,2,1108,C,A,0,14.6500,100,0,165661,277841228,13.1099,100,1,13.8499,2,1,13.0099,2,1,13.9600,100,1,12.9800,200,2,14.2799,100,1,12.8599,100,1,14.4600,100,1,12.7300,100,1,14.4800,800,2,12.7100,100,1,14.5199,100,1,12.5000,700,1,14.5600,800,2,12.4900,200,2,14.5999,700,1,12.4600,100,1,14.6799,700,1,12.4299,700,1,14.7400,100,1,ARL,333436425
2118,2025-07-17T16:08:27.484800296Z,2025-07-17T16:08:27.484800296Z,10,2,1108,A,A,0,14.9399,100,130,165661,277841228,13.1099,100,1,13.8499,2,1,13.0099,2,1,13.9600,100,1,12.9800,200,2,14.2799,100,1,12.8599,100,1,14.4600,100,1,12.7300,100,1,14.4800,800,2,12.7100,100,1,14.5199,100,1,12.5000,700,1,14.5600,800,2,12.4900,200,2,14.5999,700,1,12.4600,100,1,14.6799,700,1,12.4299,700,1,14.7400,100,1,ARL,333581429
2119,2025-07-17T16:08:27.484813280Z,2025-07-17T16:08:27.484813280Z,10,2,1108,C,A,0,15.7500,100,0,165579,277841229,13.1099,100,1,13.8499,2,1,13.0099,2,1,13.9600,100,1,12.9800,200,2,14.2799,100,1,12.8599,100,1,14.4600,100,1,12.7300,100,1,14.4800,800,2,12.7100,100,1,14.5199,100,1,12.5000,700,1,14.5600,800,2,12.4900,200,2,14.5999,700,1,12.4600,100,1,14.6799,700,1,12.4299,700,1,14.7400,100,1,ARL,333436449
2120,2025-07-17T16:08:27.484813280Z,2025-07-17T16:08:27.484813280Z,10,2,1108,A,A,0,16.0599,100,130,165579,277841229,13.1099,100,1,13.8499,2,1,13.0099,2,1,13.9600,100,1,12.9800,200,2,14.2799,100,1,12.8599,100,1,14.4600,100,1,12.7300,100,1,14.4800,800,2,12.7100,100,1,14.5199,100,1,12.5000,700,1,14.5600,800,2,12.4900,200,2,14.5999,700,1,12.4600,100,1,14.6799,700,1,12.4299,700,1,14.7400,100,1,ARL,333581433
2121,2025-07-17T16:08:27.485186411Z,2025-07-17T16:08:27.485186411Z,10,2,1108,C,A,0,15.0600,100,0,165793,277841231,13.1099,100,1,13.8499,2,1,13.0099,2,1,13.9600,100,1,12.9800,200,2,14.2799,100,1,12.8599,100,1,14.4600,100,1,12.7300,100,1,14.4800,800,2,12.7100,100,1,14.5199,100,1,12.5000,700,1,14.5600,800,2,12.4900,200,2,14.5999,700,1,12.4600,100,1,14.6799,700,1,12.4299,700,1,14.7400,100,1,ARL,333436421
2122,2025-07-17T16:08:27.485186411Z,2025-07-17T16:08:27.485186411Z,10,2,1108,A,A,0,15.3599,100,130,165793,277841231,13.1099,100,1,13.8499,2,1,13.0099,2,1,13.9600,100,1,12.9800,200,2,14.2799,100,1,12.8599,100,1,14.4600,100,1,12.7300,100,1,14.4800,800,2,12.7100,100,1,14.5199,100,1,12.5000,700,1,14.5600,800,2,12.4900,200,2,14.5999,700,1,12.4600,100,1,14.6799,700,1,12.4299,700,1,14.7400,100,1,ARL,333581441
2123,2025-07-17T16:08:27.487097702Z,2025-07-17T16:08:27.487097702Z,10,2,1108,C,A,0,14.5199,100,0,165574,277841319,13.1099,100,1,13.8499,2,1,13.0099,2,1,13.9600,100,1,12.9800,200,2,14.2799,100,1,12.8599,100,1,14.4600,100,1,12.7300,100,1,14.4800,800,2,12.7100,100,1,14.5600,800,2,12.5000,700,1,14.5999,700,1,12.4900,200,2,14.6799,700,1,12.4600,100,1,14.7400,100,1,12.4299,700,1,14.9399,200,2,ARL,328780597
2124,2025-07-17T16:08:27.487097702Z,2025-07-17T16:08:27.487097702Z,10,2,1108,A,A,0,14.7400,100,130,165574,277841319,13.1099,100,1,13.8499,2,1,13.0099,2,1,13.9600,100,1,12.9800,200,2,14.2799,100,1,12.8599,100,1,14.4600,100,1,12.7300,100,1,14.4800,800,2,12.7100,100,1,14.5600,800,2,12.5000,700,1,14.5999,700,1,12.4900,200,2,14.6799,700,1,12.4600,100,1,14.7400,200,2,12.4299,700,1,14.9399,200,2,ARL,333581481
2125,2025-07-17T16:08:27.492093401Z,2025-07-17T16:08:27.492093401Z,10,2,1108,C,A,0,14.4800,100,130,165505,277841396,13.1099,100,1,13.8499,2,1,13.0099,2,1,13.9600,100,1,12.9800,200,2,14.2799,100,1,12.8599,100,1,14.4600,100,1,12.7300,100,1,14.4800,700,1,12.7100,100,1,14.5600,800,2,12.5000,700,1,14.5999,700,1,12.4900,200,2,14.6799,700,1,12.4600,100,1,14.7400,200,2,12.4299,700,1,14.9399,200,2,ARL,333438545
2126,2025-07-17T16:08:27.492220454Z,2025-07-17T16:08:27.492220454Z,10,2,1108,A,A,0,14.7500,100,130,165296,277841397,13.1099,100,1,13.8499,2,1,13.0099,2,1,13.9600,100,1,12.9800,200,2,14.2799,100,1,12.8599,100,1,14.4600,100,1,12.7300,100,1,14.4800,700,1,12.7100,100,1,14.5600,800,2,12.5000,700,1,14.5999,700,1,12.4900,200,2,14.6799,700,1,12.4600,100,1,14.7400,200,2,12.4299,700,1,14.7500,100,1,ARL,333581569
2127,2025-07-17T16:08:27.496770678Z,2025-07-17T16:08:27.496770678Z,10,2,1108,C,A,0,13.9600,100,130,165444,277841427,13.1099,100,1,13.8499,2,1,13.0099,2,1,14.2799,100,1,12.9800,200,2,14.4600,100,1,12.8599,100,1,14.4800,700,1,12.7300,100,1,14.5600,800,2,12.7100,100,1,14.5999,700,1,12.5000,700,1,14.6799,700,1,12.4900,200,2,14.7400,200,2,12.4600,100,1,14.7500,100,1,12.4299,700,1,14.9399,200,2,ARL,333436473
2128,2025-07-17T16:08:27.496822540Z,2025-07-17T16:08:27.496822540Z,10,2,1108,A,A,0,14.1899,100,130,165292,277841428,13.1099,100,1,13.8499,2,1,13.0099,2,1,14.1899,100,1,12.9800,200,2,14.2799,100,1,12.8599,100,1,14.4600,100,1,12.7300,100,1,14.4800,700,1,12.7100,100,1,14.5600,800,2,12.5000,700,1,14.5999,700,1,12.4900,200,2,14.6799,700,1,12.4600,100,1,14.7400,200,2,12.4299,700,1,14.7500,100,1,ARL,333581625
2129,2025-07-17T16:08:27.500928061Z,2025-07-17T16:08:27.500928061Z,10,2,1108,C,A,0,13.8499,2,0,165557,277841469,13.1099,100,1,14.1899,100,1,13.0099,2,1,14.2799,100,1,12.9800,200,2,14.4600,100,1,12.8599,100,1,14.4800,700,1,12.7300,100,1,14.5600,800,2,12.7100,100,1,14.5999,700,1,12.5000,700,1,14.6799,700,1,12.4900,200,2,14.7400,200,2,12.4600,100,1,14.7500,100,1,12.4299,700,1,14.9399,200,2,ARL,331155889
2130,2025-07-17T16:08:27.500928061Z,2025-07-17T16:08:27.500928061Z,10,2,1108,A,A,0,13.9800,2,130,165557,277841469,13.1099,100,1,13.9800,2,1,13.0099,2,1,14.1899,100,1,12.9800,200,2,14.2799,100,1,12.8599,100,1,14.4600,100,1,12.7300,100,1,14.4800,700,1,12.7100,100,1,14.5600,800,2,12.5000,700,1,14.5999,700,1,12.4900,200,2,14.6799,700,1,12.4600,100,1,14.7400,200,2,12.4299,700,1,14.7500,100,1,ARL,333581677
2131,2025-07-17T16:08:27.516449334Z,2025-07-17T16:08:27.516449334Z,10,2,1108,C,A,0,14.1899,100,130,165039,277841551,13.1099,100,1,13.9800,2,1,13.0099,2,1,14.2799,100,1,12.9800,200,2,14.4600,100,1,12.8599,100,1,14.4800,700,1,12.7300,100,1,14.5600,800,2,12.7100,100,1,14.5999,700,1,12.5000,700,1,14.6799,700,1,12.4900,200,2,14.7400,200,2,12.4600,100,1,14.7500,100,1,12.4299,700,1,14.9399,200,2,ARL,333581625
2132,2025-07-17T16:08:27.516496962Z,2025-07-17T16:08:27.516496962Z,10,2,1108,A,A,0,14.2599,100,130,165137,277841552,13.1099,100,1,13.9800,2,1,13.0099,2,1,14.2599,100,1,12.9800,200,2,14.2799,100,1,12.8599,100,1,14.4600,100,1,12.7300,100,1,14.4800,700,1,12.7100,100,1,14.5600,800,2,12.5000,700,1,14.5999,700,1,12.4900,200,2,14.6799,700,1,12.4600,100,1,14.7400,200,2,12.4299,700,1,14.7500,100,1,ARL,333581765
2133,2025-07-17T16:08:27.533773259Z,2025-07-17T16:08:27.533773259Z,10,2,1108,C,A,0,14.9900,100,0,165191,277841588,13.1099,100,1,13.9800,2,1,13.0099,2,1,14.2599,100,1,12.9800,200,2,14.2799,100,1,12.8599,100,1,14.4600,100,1,12.7300,100,1,14.4800,700,1,12.7100,100,1,14.5600,800,2,12.5000,700,1,14.5999,700,1,12.4900,200,2,14.6799,700,1,12.4600,100,1,14.7400,200,2,12.4299,700,1,14.7500,100,1,ARL,333581389
2134,2025-07-17T16:08:27.533773259Z,2025-07-17T16:08:27.533773259Z,10,2,1108,A,A,0,15.0399,100,130,165191,277841588,13.1099,100,1,13.9800,2,1,13.0099,2,1,14.2599,100,1,12.9800,200,2,14.2799,100,1,12.8599,100,1,14.4600,100,1,12.7300,100,1,14.4800,700,1,12.7100,100,1,14.5600,800,2,12.5000,700,1,14.5999,700,1,12.4900,200,2,14.6799,700,1,12.4600,100,1,14.7400,200,2,12.4299,700,1,14.7500,100,1,ARL,333581845
2135,2025-07-17T16:08:27.987513451Z,2025-07-17T16:08:27.987513451Z,10,2,1108,A,A,0,13.9900,100,130,165288,277846288,13.1099,100,1,13.9800,2,1,13.0099,2,1,13.9900,100,1,12.9800,200,2,14.2599,100,1,12.8599,100,1,14.2799,100,1,12.7300,100,1,14.4600,100,1,12.7100,100,1,14.4800,700,1,12.5000,700,1,14.5600,800,2,12.4900,200,2,14.5999,700,1,12.4600,100,1,14.6799,700,1,12.4299,700,1,14.7400,200,2,ARL,333590057
2136,2025-07-17T16:08:58.024814068Z,2025-07-17T16:08:58.024814068Z,10,2,1108,A,A,0,13.8100,15,130,165314,278261182,13.1099,100,1,13.8100,15,1,13.0099,2,1,13.9800,2,1,12.9800,200,2,13.9900,100,1,12.8599,100,1,14.2599,100,1,12.7300,100,1,14.2799,100,1,12.7100,100,1,14.4600,100,1,12.5000,700,1,14.4800,700,1,12.4900,200,2,14.5600,800,2,12.4600,100,1,14.5999,700,1,12.4299,700,1,14.6799,700,1,ARL,334141429
2137,2025-07-17T16:09:00.222509491Z,2025-07-17T16:09:00.222509491Z,10,2,1108,C,A,0,13.9900,100,0,165743,278295684,13.1099,100,1,13.8100,15,1,13.0099,2,1,13.9800,2,1,12.9800,200,2,14.2599,100,1,12.8599,100,1,14.2799,100,1,12.7300,100,1,14.4600,100,1,12.7100,100,1,14.4800,700,1,12.5000,700,1,14.5600,800,2,12.4900,200,2,14.5999,700,1,12.4600,100,1,14.6799,700,1,12.4299,700,1,14.7400,200,2,ARL,333590057
2138,2025-07-17T16:09:00.222509491Z,2025-07-17T16:09:00.222509491Z,10,2,1108,A,A,0,13.8200,100,130,165743,278295684,13.1099,100,1,13.8100,15,1,13.0099,2,1,13.8200,100,1,12.9800,200,2,13.9800,2,1,12.8599,100,1,14.2599,100,1,12.7300,100,1,14.2799,100,1,12.7100,100,1,14.4600,100,1,12.5000,700,1,14.4800,700,1,12.4900,200,2,14.5600,800,2,12.4600,100,1,14.5999,700,1,12.4299,700,1,14.6799,700,1,ARL,334189729
2139,2025-07-17T16:09:00.223269382Z,2025-07-17T16:09:00.223269382Z,10,2,1108,C,A,0,15.0399,100,0,167375,278295848,13.1099,100,1,13.8100,15,1,13.0099,2,1,13.8200,100,1,12.9800,200,2,13.9800,2,1,12.8599,100,1,14.2599,100,1,12.7300,100,1,14.2799,100,1,12.7100,100,1,14.4600,100,1,12.5000,700,1,14.4800,700,1,12.4900,200,2,14.5600,800,2,12.4600,100,1,14.5999,700,1,12.4299,700,1,14.6799,700,1,ARL,333581845
2140,2025-07-17T16:09:00.223269382Z,2025-07-17T16:09:00.223269382Z,10,2,1108,A,A,0,14.8900,100,128,167375,278295848,13.1099,100,1,13.8100,15,1,13.0099,2,1,13.8200,100,1,12.9800,200,2,13.9800,2,1,12.8599,100,1,14.2599,100,1,12.7300,100,1,14.2799,100,1,12.7100,100,1,14.4600,100,1,12.5000,700,1,14.4800,700,1,12.4900,200,2,14.5600,800,2,12.4600,100,1,14.5999,700,1,12.4299,700,1,14.6799,700,1,ARL,334189777
2141,2025-07-17T16:09:00.226338384Z,2025-07-17T16:09:00.226338384Z,10,2,1108,C,A,0,14.7500,100,0,165962,278296281,13.1099,100,1,13.8100,15,1,13.0099,2,1,13.8200,100,1,12.9800,200,2,13.9800,2,1,12.8599,100,1,14.2599,100,1,12.7300,100,1,14.2799,100,1,12.7100,100,1,14.4600,100,1,12.5000,700,1,14.4800,700,1,12.4900,200,2,14.5600,800,2,12.4600,100,1,14.5999,700,1,12.4299,700,1,14.6799,700,1,ARL,333581569
2142,2025-07-17T16:09:00.226338384Z,2025-07-17T16:09:00.226338384Z,10,2,1108,A,A,0,14.6099,100,130,165962,278296281,13.1099,100,1,13.8100,15,1,13.0099,2,1,13.8200,100,1,12.9800,200,2,13.9800,2,1,12.8599,100,1,14.2599,100,1,12.7300,100,1,14.2799,100,1,12.7100,100,1,14.4600,100,1,12.5000,700,1,14.4800,700,1,12.4900,200,2,14.5600,800,2,12.4600,100,1,14.5999,700,1,12.4299,700,1,14.6099,100,1,ARL,334190189
2143,2025-07-17T16:09:00.227763275Z,2025-07-17T16:09:00.227763275Z,10,2,1108,C,A,0,14.2599,100,130,165786,278296402,13.1099,100,1,13.8100,15,1,13.0099,2,1,13.8200,100,1,12.9800,200,2,13.9800,2,1,12.8599,100,1,14.2799,100,1,12.7300,100,1,14.4600,100,1,12.7100,100,1,14.4800,700,1,12.5000,700,1,14.5600,800,2,12.4900,200,2,14.5999,700,1,12.4600,100,1,14.6099,100,1,12.4299,700,1,14.6799,700,1,ARL,333581765
2144,2025-07-17T16:09:00.227818153Z,2025-07-17T16:09:00.227818153Z,10,2,1108,A,A,0,14.0999,100,130,165330,278296411,13.1099,100,1,13.8100,15,1,13.0099,2,1,13.8200,100,1,12.9800,200,2,13.9800,2,1,12.8599,100,1,14.0999,100,1,12.7300,100,1,14.2799,100,1,12.7100,100,1,14.4600,100,1,12.5000,700,1,14.4800,700,1,12.4900,200,2,14.5600,800,2,12.4600,100,1,14.5999,700,1,12.4299,700,1,14.6099,100,1,ARL,334190225
2145,2025-07-17T16:09:00.232743323Z,2025-07-17T16:09:00.232743323Z,10,2,1108,C,A,0,14.9399,100,0,165559,278296544,13.1099,100,1,13.8100,15,1,13.0099,2,1,13.8200,100,1,12.9800,200,2,13.9800,2,1,12.8599,100,1,14.0999,100,1,12.7300,100,1,14.2799,100,1,12.7100,100,1,14.4600,100,1,12.5000,700,1,14.4800,700,1,12.4900,200,2,14.5600,800,2,12.4600,100,1,14.5999,700,1,12.4299,700,1,14.6099,100,1,ARL,333581429
2146,2025-07-17T16:09:00.232743323Z,2025-07-17T16:09:00.232743323Z,10,2,1108,A,A,0,14.7899,100,130,165559,278296544,13.1099,100,1,13.8100,15,1,13.0099,2,1,13.8200,100,1,12.9800,200,2,13.9800,2,1,12.8599,100,1,14.0999,100,1,12.7300,100,1,14.2799,100,1,12.7100,100,1,14.4600,100,1,12.5000,700,1,14.4800,700,1,12.4900,200,2,14.5600,800,2,12.4600,100,1,14.5999,700,1,12.4299,700,1,14.6099,100,1,ARL,334190353
2147,2025-07-17T16:09:00.326127587Z,2025-07-17T16:09:00.326127587Z,10,2,1108,C,A,0,17.7300,100,0,165699,278298302,13.1099,100,1,13.8100,15,1,13.0099,2,1,13.8200,100,1,12.9800,200,2,13.9800,2,1,12.8599,100,1,14.0999,100,1,12.7300,100,1,14.2799,100,1,12.7100,100,1,14.4600,100,1,12.5000,700,1,14.4800,700,1,12.4900,200,2,14.5600,800,2,12.4600,100,1,14.5999,700,1,12.4299,700,1,14.6099,100,1,ARL,333581425
2148,2025-07-17T16:09:00.326127587Z,2025-07-17T16:09:00.326127587Z,10,2,1108,A,A,0,17.5599,100,130,165699,278298302,13.1099,100,1,13.8100,15,1,13.0099,2,1,13.8200,100,1,12.9800,200,2,13.9800,2,1,12.8599,100,1,14.0999,100,1,12.7300,100,1,14.2799,100,1,12.7100,100,1,14.4600,100,1,12.5000,700,1,14.4800,700,1,12.4900,200,2,14.5600,800,2,12.4600,100,1,14.5999,700,1,12.4299,700,1,14.6099,100,1,ARL,334192253
2149,2025-07-17T16:09:00.335442266Z,2025-07-17T16:09:00.335442266Z,10,2,1108,C,A,0,16.0599,100,0,165561,278298372,13.1099,100,1,13.8100,15,1,13.0099,2,1,13.8200,100,1,12.9800,200,2,13.9800,2,1,12.8599,100,1,14.0999,100,1,12.7300,100,1,14.2799,100,1,12.7100,100,1,14.4600,100,1,12.5000,700,1,14.4800,700,1,12.4900,200,2,14.5600,800,2,12.4600,100,1,14.5999,700,1,12.4299,700,1,14.6099,100,1,ARL,333581433
2150,2025-07-17T16:09:00.335442266Z,2025-07-17T16:09:00.335442266Z,10,2,1108,A,A,0,15.9000,100,130,165561,278298372,13.1099,100,1,13.8100,15,1,13.0099,2,1,13.8200,100,1,12.9800,200,2,13.9800,2,1,12.8599,100,1,14.0999,100,1,12.7300,100,1,14.2799,100,1,12.7100,100,1,14.4600,100,1,12.5000,700,1,14.4800,700,1,12.4900,200,2,14.5600,800,2,12.4600,100,1,14.5999,700,1,12.4299,700,1,14.6099,100,1,ARL,334192405
2151,2025-07-17T16:09:00.695610142Z,2025-07-17T16:09:00.695610142Z,10,2,1108,C,A,0,14.9399,100,0,165868,278304343,13.1099,100,1,13.8100,15,1,13.0099,2,1,13.8200,100,1,12.9800,200,2,13.9800,2,1,12.8599,100,1,14.0999,100,1,12.7300,100,1,14.2799,100,1,12.7100,100,1,14.4600,100,1,12.5000,700,1,14.4800,700,1,12.4900,200,2,14.5600,800,2,12.4600,100,1,14.5999,700,1,12.4299,700,1,14.6099,100,1,ARL,333581409
2152,2025-07-17T16:09:00.695610142Z,2025-07-17T16:09:00.695610142Z,10,2,1108,A,A,0,14.7899,100,130,165868,278304343,13.1099,100,1,13.8100,15,1,13.0099,2,1,13.8200,100,1,12.9800,200,2,13.9800,2,1,12.8599,100,1,14.0999,100,1,12.7300,100,1,14.2799,100,1,12.7100,100,1,14.4600,100,1,12.5000,700,1,14.4800,700,1,12.4900,200,2,14.5600,800,2,12.4600,100,1,14.5999,700,1,12.4299,700,1,14.6099,100,1,ARL,334199009
2153,2025-07-17T16:09:08.719524374Z,2025-07-17T16:09:08.719524374Z,10,2,1108,A,A,0,13.7500,15,130,166319,278436950,13.1099,100,1,13.7500,15,1,13.0099,2,1,13.8100,15,1,12.9800,200,2,13.8200,100,1,12.8599,100,1,13.9800,2,1,12.7300,100,1,14.0999,100,1,12.7100,100,1,14.2799,100,1,12.5000,700,1,14.4600,100,1,12.4900,200,2,14.4800,700,1,12.4600,100,1,14.5600,800,2,12.4299,700,1,14.5999,700,1,ARL,334366613
2154,2025-07-17T16:09:08.719706070Z,2025-07-17T16:09:08.719706070Z,10,2,1108,C,A,0,13.8200,100,0,165340,278436967,13.1099,100,1,13.7500,15,1,13.0099,2,1,13.8100,15,1,12.9800,200,2,13.9800,2,1,12.8599,100,1,14.0999,100,1,12.7300,100,1,14.2799,100,1,12.7100,100,1,14.4600,100,1,12.5000,700,1,14.4800,700,1,12.4900,200,2,14.5600,800,2,12.4600,100,1,14.5999,700,1,12.4299,700,1,14.6099,100,1,ARL,334189729
2155,2025-07-17T16:09:08.719706070Z,2025-07-17T16:09:08.719706070Z,10,2,1108,A,A,0,13.7599,100,130,165340,278436967,13.1099,100,1,13.7500,15,1,13.0099,2,1,13.7599,100,1,12.9800,200,2,13.8100,15,1,12.8599,100,1,13.9800,2,1,12.7300,100,1,14.0999,100,1,12.7100,100,1,14.2799,100,1,12.5000,700,1,14.4600,100,1,12.4900,200,2,14.4800,700,1,12.4600,100,1,14.5600,800,2,12.4299,700,1,14.5999,700,1,ARL,334366617
2156,2025-07-17T16:09:08.720442245Z,2025-07-17T16:09:08.720442245Z,10,2,1108,C,A,0,14.8900,100,0,165687,278436994,13.1099,100,1,13.7500,15,1,13.0099,2,1,13.7599,100,1,12.9800,200,2,13.8100,15,1,12.8599,100,1,13.9800,2,1,12.7300,100,1,14.0999,100,1,12.7100,100,1,14.2799,100,1,12.5000,700,1,14.4600,100,1,12.4900,200,2,14.4800,700,1,12.4600,100,1,14.5600,800,2,12.4299,700,1,14.5999,700,1,ARL,334189777
2157,2025-07-17T16:09:08.720442245Z,2025-07-17T16:09:08.720442245Z,10,2,1108,A,A,0,14.8300,100,130,165687,278436994,13.1099,100,1,13.7500,15,1,13.0099,2,1,13.7599,100,1,12.9800,200,2,13.8100,15,1,12.8599,100,1,13.9800,2,1,12.7300,100,1,14.0999,100,1,12.7100,100,1,14.2799,100,1,12.5000,700,1,14.4600,100,1,12.4900,200,2,14.4800,700,1,12.4600,100,1,14.5600,800,2,12.4299,700,1,14.5999,700,1,ARL,334366645
2158,2025-07-17T16:09:18.819135505Z,2025-07-17T16:09:18.819135505Z,10,2,1108,C,A,0,13.8100,15,130,165230,278596985,13.1099,100,1,13.7500,15,1,13.0099,2,1,13.7599,100,1,12.9800,200,2,13.9800,2,1,12.8599,100,1,14.0999,100,1,12.7300,100,1,14.2799,100,1,12.7100,100,1,14.4600,100,1,12.5000,700,1,14.4800,700,1,12.4900,200,2,14.5600,800,2,12.4600,100,1,14.5999,700,1,12.4299,700,1,14.6099,100,1,ARL,334141429
2159,2025-07-17T16:09:19.927039122Z,2025-07-17T16:09:19.927039122Z,10,2,1108,A,A,0,13.7300,15,130,165901,278621672,13.1099,100,1,13.7300,15,1,13.0099,2,1,13.7500,15,1,12.9800,200,2,13.7599,100,1,12.8599,100,1,13.9800,2,1,12.7300,100,1,14.0999,100,1,12.7100,100,1,14.2799,100,1,12.5000,700,1,14.4600,100,1,12.4900,200,2,14.4800,700,1,12.4600,100,1,14.5600,800,2,12.4299,700,1,14.5999,700,1,ARL,334583329
2160,2025-07-17T16:09:19.927745104Z,2025-07-17T16:09:19.927745104Z,10,2,1108,C,A,0,14.7400,100,0,165599,278621693,13.1099,100,1,13.7300,15,1,13.0099,2,1,13.7500,15,1,12.9800,200,2,13.7599,100,1,12.8599,100,1,13.9800,2,1,12.7300,100,1,14.0999,100,1,12.7100,100,1,14.2799,100,1,12.5000,700,1,14.4600,100,1,12.4900,200,2,14.4800,700,1,12.4600,100,1,14.5600,800,2,12.4299,700,1,14.5999,700,1,ARL,333581393
2161,2025-07-17T16:09:19.927745104Z,2025-07-17T16:09:19.927745104Z,10,2,1108,A,A,0,14.6199,100,130,165599,278621693,13.1099,100,1,13.7300,15,1,13.0099,2,1,13.7500,15,1,12.9800,200,2,13.7599,100,1,12.8599,100,1,13.9800,2,1,12.7300,100,1,14.0999,100,1,12.7100,100,1,14.2799,100,1,12.5000,700,1,14.4600,100,1,12.4900,200,2,14.4800,700,1,12.4600,100,1,14.5600,800,2,12.4299,700,1,14.5999,700,1,ARL,334583349
2162,2025-07-17T16:09:19.928153837Z,2025-07-17T16:09:19.928153837Z,10,2,1108,C,A,0,14.7400,100,0,165532,278621695,13.1099,100,1,13.7300,15,1,13.0099,2,1,13.7500,15,1,12.9800,200,2,13.7599,100,1,12.8599,100,1,13.9800,2,1,12.7300,100,1,14.0999,100,1,12.7100,100,1,14.2799,100,1,12.5000,700,1,14.4600,100,1,12.4900,200,2,14.4800,700,1,12.4600,100,1,14.5600,800,2,12.4299,700,1,14.5999,700,1,ARL,333581481
2163,2025-07-17T16:09:19.928153837Z,2025-07-17T16:09:19.928153837Z,10,2,1108,A,A,0,14.6199,100,130,165532,278621695,13.1099,100,1,13.7300,15,1,13.0099,2,1,13.7500,15,1,12.9800,200,2,13.7599,100,1,12.8599,100,1,13.9800,2,1,12.7300,100,1,14.0999,100,1,12.7100,100,1,14.2799,100,1,12.5000,700,1,14.4600,100,1,12.4900,200,2,14.4800,700,1,12.4600,100,1,14.5600,800,2,12.4299,700,1,14.5999,700,1,ARL,334583361
2164,2025-07-17T16:09:20.284695585Z,2025-07-17T16:09:20.284695585Z,10,2,1108,C,A,0,13.7599,100,0,165490,278629057,13.1099,100,1,13.7300,15,1,13.0099,2,1,13.7500,15,1,12.9800,200,2,13.9800,2,1,12.8599,100,1,14.0999,100,1,12.7300,100,1,14.2799,100,1,12.7100,100,1,14.4600,100,1,12.5000,700,1,14.4800,700,1,12.4900,200,2,14.5600,800,2,12.4600,100,1,14.5999,700,1,12.4299,700,1,14.6099,100,1,ARL,334366617
2165,2025-07-17T16:09:20.284695585Z,2025-07-17T16:09:20.284695585Z,10,2,1108,A,A,0,13.7400,100,130,165490,278629057,13.1099,100,1,13.7300,15,1,13.0099,2,1,13.7400,100,1,12.9800,200,2,13.7500,15,1,12.8599,100,1,13.9800,2,1,12.7300,100,1,14.0999,100,1,12.7100,100,1,14.2799,100,1,12.5000,700,1,14.4600,100,1,12.4900,200,2,14.4800,700,1,12.4600,100,1,14.5600,800,2,12.4299,700,1,14.5999,700,1,ARL,334593569
2166,2025-07-17T16:09:20.293106270Z,2025-07-17T16:09:20.293106270Z,10,2,1108,C,A,0,14.0999,100,130,165350,278629219,13.1099,100,1,13.7300,15,1,13.0099,2,1,13.7400,100,1,12.9800,200,2,13.7500,15,1,12.8599,100,1,13.9800,2,1,12.7300,100,1,14.2799,100,1,12.7100,100,1,14.4600,100,1,12.5000,700,1,14.4800,700,1,12.4900,200,2,14.5600,800,2,12.4600,100,1,14.5999,700,1,12.4299,700,1,14.6099,100,1,ARL,334190225
2167,2025-07-17T16:09:20.293161454Z,2025-07-17T16:09:20.293161454Z,10,2,1108,A,A,0,14.0099,100,130,165187,278629220,13.1099,100,1,13.7300,15,1,13.0099,2,1,13.7400,100,1,12.9800,200,2,13.7500,15,1,12.8599,100,1,13.9800,2,1,12.7300,100,1,14.0099,100,1,12.7100,100,1,14.2799,100,1,12.5000,700,1,14.4600,100,1,12.4900,200,2,14.4800,700,1,12.4600,100,1,14.5600,800,2,12.4299,700,1,14.5999,700,1,ARL,334593753
2168,2025-07-17T16:09:20.818648795Z,2025-07-17T16:09:20.818648795Z,10,2,1108,C,A,0,13.7300,15,130,165140,278640667,13.1099,100,1,13.7400,100,1,13.0099,2,1,13.7500,15,1,12.9800,200,2,13.9800,2,1,12.8599,100,1,14.0099,100,1,12.7300,100,1,14.2799,100,1,12.7100,100,1,14.4600,100,1,12.5000,700,1,14.4800,700,1,12.4900,200,2,14.5600,800,2,12.4600,100,1,14.5999,700,1,12.4299,700,1,14.6099,100,1,ARL,334583329
2169,2025-07-17T16:09:20.818761228Z,2025-07-17T16:09:20.818761228Z,10,2,1108,C,A,0,13.7500,15,130,165128,278640670,13.1099,100,1,13.7400,100,1,13.0099,2,1,13.9800,2,1,12.9800,200,2,14.0099,100,1,12.8599,100,1,14.2799,100,1,12.7300,100,1,14.4600,100,1,12.7100,100,1,14.4800,700,1,12.5000,700,1,14.5600,800,2,12.4900,200,2,14.5999,700,1,12.4600,100,1,14.6099,100,1,12.4299,700,1,14.6199,200,2,ARL,334366613
2170,2025-07-17T16:09:28.985956629Z,2025-07-17T16:09:28.985956629Z,10,2,1108,C,A,0,13.9800,2,0,165803,278784943,13.1099,100,1,13.7400,100,1,13.0099,2,1,14.0099,100,1,12.9800,200,2,14.2799,100,1,12.8599,100,1,14.4600,100,1,12.7300,100,1,14.4800,700,1,12.7100,100,1,14.5600,800,2,12.5000,700,1,14.5999,700,1,12.4900,200,2,14.6099,100,1,12.4600,100,1,14.6199,200,2,12.4299,700,1,14.6799,700,1,ARL,333581677
2171,2025-07-17T16:09:28.985956629Z,2025-07-17T16:09:28.985956629Z,10,2,1108,A,A,0,13.9000,2,130,165803,278784943,13.1099,100,1,13.7400,100,1,13.0099,2,1,13.9000,2,1,12.9800,200,2,14.0099,100,1,12.8599,100,1,14.2799,100,1,12.7300,100,1,14.4600,100,1,12.7100,100,1,14.4800,700,1,12.5000,700,1,14.5600,800,2,12.4900,200,2,14.5999,700,1,12.4600,100,1,14.6099,100,1,12.4299,700,1,14.6199,200,2,ARL,334804177
2172,2025-07-17T16:09:40.821522565Z,2025-07-17T16:09:40.821522565Z,10,2,1108,A,A,0,13.6999,15,130,165340,278938091,13.1099,100,1,13.6999,15,1,13.0099,2,1,13.7400,100,1,12.9800,200,2,13.9000,2,1,12.8599,100,1,14.0099,100,1,12.7300,100,1,14.2799,100,1,12.7100,100,1,14.4600,100,1,12.5000,700,1,14.4800,700,1,12.4900,200,2,14.5600,800,2,12.4600,100,1,14.5999,700,1,12.4299,700,1,14.6099,100,1,ARL,335003269
2173,2025-07-17T16:09:40.853439053Z,2025-07-17T16:09:40.853439053Z,10,2,1108,C,A,0,13.7400,100,0,165524,278938747,13.1099,100,1,13.6999,15,1,13.0099,2,1,13.9000,2,1,12.9800,200,2,14.0099,100,1,12.8599,100,1,14.2799,100,1,12.7300,100,1,14.4600,100,1,12.7100,100,1,14.4800,700,1,12.5000,700,1,14.5600,800,2,12.4900,200,2,14.5999,700,1,12.4600,100,1,14.6099,100,1,12.4299,700,1,14.6199,200,2,ARL,334593569
2174,2025-07-17T16:09:40.853439053Z,2025-07-17T16:09:40.853439053Z,10,2,1108,A,A,0,13.7100,100,130,165524,278938747,13.1099,100,1,13.6999,15,1,13.0099,2,1,13.7100,100,1,12.9800,200,2,13.9000,2,1,12.8599,100,1,14.0099,100,1,12.7300,100,1,14.2799,100,1,12.7100,100,1,14.4600,100,1,12.5000,700,1,14.4800,700,1,12.4900,200,2,14.5600,800,2,12.4600,100,1,14.5999,700,1,12.4299,700,1,14.6099,100,1,ARL,335003813
2175,2025-07-17T16:09:40.854190408Z,2025-07-17T16:09:40.854190408Z,10,2,1108,C,A,0,14.8300,100,0,165614,278938765,13.1099,100,1,13.6999,15,1,13.0099,2,1,13.7100,100,1,12.9800,200,2,13.9000,2,1,12.8599,100,1,14.0099,100,1,12.7300,100,1,14.2799,100,1,12.7100,100,1,14.4600,100,1,12.5000,700,1,14.4800,700,1,12.4900,200,2,14.5600,800,2,12.4600,100,1,14.5999,700,1,12.4299,700,1,14.6099,100,1,ARL,334366645
2176,2025-07-17T16:09:40.854190408Z,2025-07-17T16:09:40.854190408Z,10,2,1108,A,A,0,14.7699,100,130,165614,278938765,13.1099,100,1,13.6999,15,1,13.0099,2,1,13.7100,100,1,12.9800,200,2,13.9000,2,1,12.8599,100,1,14.0099,100,1,12.7300,100,1,14.2799,100,1,12.7100,100,1,14.4600,100,1,12.5000,700,1,14.4800,700,1,12.4900,200,2,14.5600,800,2,12.4600,100,1,14.5999,700,1,12.4299,700,1,14.6099,100,1,ARL,335003845
2177,2025-07-17T16:09:40.855558831Z,2025-07-17T16:09:40.855558831Z,10,2,1108,C,A,0,17.5599,100,0,165591,278938788,13.1099,100,1,13.6999,15,1,13.0099,2,1,13.7100,100,1,12.9800,200,2,13.9000,2,1,12.8599,100,1,14.0099,100,1,12.7300,100,1,14.2799,100,1,12.7100,100,1,14.4600,100,1,12.5000,700,1,14.4800,700,1,12.4900,200,2,14.5600,800,2,12.4600,100,1,14.5999,700,1,12.4299,700,1,14.6099,100,1,ARL,334192253
2178,2025-07-17T16:09:40.855558831Z,2025-07-17T16:09:40.855558831Z,10,2,1108,A,A,0,17.4200,100,130,165591,278938788,13.1099,100,1,13.6999,15,1,13.0099,2,1,13.7100,100,1,12.9800,200,2,13.9000,2,1,12.8599,100,1,14.0099,100,1,12.7300,100,1,14.2799,100,1,12.7100,100,1,14.4600,100,1,12.5000,700,1,14.4800,700,1,12.4900,200,2,14.5600,800,2,12.4600,100,1,14.5999,700,1,12.4299,700,1,14.6099,100,1,ARL,335003849
2179,2025-07-17T16:09:50.820783486Z,2025-07-17T16:09:50.820783486Z,10,2,1108,A,A,0,13.6699,15,130,165645,279081140,13.1099,100,1,13.6699,15,1,13.0099,2,1,13.6999,15,1,12.9800,200,2,13.7100,100,1,12.8599,100,1,13.9000,2,1,12.7300,100,1,14.0099,100,1,12.7100,100,1,14.2799,100,1,12.5000,700,1,14.4600,100,1,12.4900,200,2,14.4800,700,1,12.4600,100,1,14.5600,800,2,12.4299,700,1,14.5999,700,1,ARL,335178437
2180,2025-07-17T16:09:52.678611805Z,2025-07-17T16:09:52.678611805Z,10,2,1108,C,A,0,13.7100,100,0,165553,279109959,13.1099,100,1,13.6699,15,1,13.0099,2,1,13.6999,15,1,12.9800,200,2,13.9000,2,1,12.8599,100,1,14.0099,100,1,12.7300,100,1,14.2799,100,1,12.7100,100,1,14.4600,100,1,12.5000,700,1,14.4800,700,1,12.4900,200,2,14.5600,800,2,12.4600,100,1,14.5999,700,1,12.4299,700,1,14.6099,100,1,ARL,335003813
2181,2025-07-17T16:09:52.678611805Z,2025-07-17T16:09:52.678611805Z,10,2,1108,A,A,0,13.6799,100,130,165553,279109959,13.1099,100,1,13.6699,15,1,13.0099,2,1,13.6799,100,1,12.9800,200,2,13.6999,15,1,12.8599,100,1,13.9000,2,1,12.7300,100,1,14.0099,100,1,12.7100,100,1,14.2799,100,1,12.5000,700,1,14.4600,100,1,12.4900,200,2,14.4800,700,1,12.4600,100,1,14.5600,800,2,12.4299,700,1,14.5999,700,1,ARL,335220349
2182,2025-07-17T16:09:52.679678566Z,2025-07-17T16:09:52.679678566Z,10,2,1108,C,A,0,15.9000,100,0,165772,279109991,13.1099,100,1,13.6699,15,1,13.0099,2,1,13.6799,100,1,12.9800,200,2,13.6999,15,1,12.8599,100,1,13.9000,2,1,12.7300,100,1,14.0099,100,1,12.7100,100,1,14.2799,100,1,12.5000,700,1,14.4600,100,1,12.4900,200,2,14.4800,700,1,12.4600,100,1,14.5600,800,2,12.4299,700,1,14.5999,700,1,ARL,334192405
2183,2025-07-17T16:09:52.679678566Z,2025-07-17T16:09:52.679678566Z,10,2,1108,A,A,0,15.7400,100,130,165772,279109991,13.1099,100,1,13.6699,15,1,13.0099,2,1,13.6799,100,1,12.9800,200,2,13.6999,15,1,12.8599,100,1,13.9000,2,1,12.7300,100,1,14.0099,100,1,12.7100,100,1,14.2799,100,1,12.5000,700,1,14.4600,100,1,12.4900,200,2,14.4800,700,1,12.4600,100,1,14.5600,800,2,12.4299,700,1,14.5999,700,1,ARL,335220497
2184,2025-07-17T16:09:52.679769832Z,2025-07-17T16:09:52.679769832Z,10,2,1108,C,A,0,14.7899,100,0,166994,279109996,13.1099,100,1,13.6699,15,1,13.0099,2,1,13.6799,100,1,12.9800,200,2,13.6999,15,1,12.8599,100,1,13.9000,2,1,12.7300,100,1,14.0099,100,1,12.7100,100,1,14.2799,100,1,12.5000,700,1,14.4600,100,1,12.4900,200,2,14.4800,700,1,12.4600,100,1,14.5600,800,2,12.4299,700,1,14.5999,700,1,ARL,334190353
2185,2025-07-17T16:09:52.679769832Z,2025-07-17T16:09:52.679769832Z,10,2,1108,A,A,0,14.6400,100,130,166994,279109996,13.1099,100,1,13.6699,15,1,13.0099,2,1,13.6799,100,1,12.9800,200,2,13.6999,15,1,12.8599,100,1,13.9000,2,1,12.7300,100,1,14.0099,100,1,12.7100,100,1,14.2799,100,1,12.5000,700,1,14.4600,100,1,12.4900,200,2,14.4800,700,1,12.4600,100,1,14.5600,800,2,12.4299,700,1,14.5999,700,1,ARL,335220525
2186,2025-07-17T16:09:52.680672148Z,2025-07-17T16:09:52.680672148Z,10,2,1108,C,A,0,15.3599,100,0,165588,279110032,13.1099,100,1,13.6699,15,1,13.0099,2,1,13.6799,100,1,12.9800,200,2,13.6999,15,1,12.8599,100,1,13.9000,2,1,12.7300,100,1,14.0099,100,1,12.7100,100,1,14.2799,100,1,12.5000,700,1,14.4600,100,1,12.4900,200,2,14.4800,700,1,12.4600,100,1,14.5600,800,2,12.4299,700,1,14.5999,700,1,ARL,333581441
2187,2025-07-17T16:09:52.680672148Z,2025-07-17T16:09:52.680672148Z,10,2,1108,A,A,0,15.0500,100,130,165588,279110032,13.1099,100,1,13.6699,15,1,13.0099,2,1,13.6799,100,1,12.9800,200,2,13.6999,15,1,12.8599,100,1,13.9000,2,1,12.7300,100,1,14.0099,100,1,12.7100,100,1,14.2799,100,1,12.5000,700,1,14.4600,100,1,12.4900,200,2,14.4800,700,1,12.4600,100,1,14.5600,800,2,12.4299,700,1,14.5999,700,1,ARL,335220549
2188,2025-07-17T16:09:52.681844377Z,2025-07-17T16:09:52.681844377Z,10,2,1108,C,A,0,14.6099,100,130,165561,279110066,13.1099,100,1,13.6699,15,1,13.0099,2,1,13.6799,100,1,12.9800,200,2,13.6999,15,1,12.8599,100,1,13.9000,2,1,12.7300,100,1,14.0099,100,1,12.7100,100,1,14.2799,100,1,12.5000,700,1,14.4600,100,1,12.4900,200,2,14.4800,700,1,12.4600,100,1,14.5600,800,2,12.4299,700,1,14.5999,700,1,ARL,334190189
2189,2025-07-17T16:09:52.681961200Z,2025-07-17T16:09:52.681961200Z,10,2,1108,A,A,0,14.4700,100,130,166330,279110068,13.1099,100,1,13.6699,15,1,13.0099,2,1,13.6799,100,1,12.9800,200,2,13.6999,15,1,12.8599,100,1,13.9000,2,1,12.7300,100,1,14.0099,100,1,12.7100,100,1,14.2799,100,1,12.5000,700,1,14.4600,100,1,12.4900,200,2,14.4700,100,1,12.4600,100,1,14.4800,700,1,12.4299,700,1,14.5600,800,2,ARL,335220561
2190,2025-07-17T16:09:52.683757265Z,2025-07-17T16:09:52.683757265Z,10,2,1108,C,A,0,14.7899,100,0,165442,279110090,13.1099,100,1,13.6699,15,1,13.0099,2,1,13.6799,100,1,12.9800,200,2,13.6999,15,1,12.8599,100,1,13.9000,2,1,12.7300,100,1,14.0099,100,1,12.7100,100,1,14.2799,100,1,12.5000,700,1,14.4600,100,1,12.4900,200,2,14.4700,100,1,12.4600,100,1,14.4800,700,1,12.4299,700,1,14.5600,800,2,ARL,334199009
2191,2025-07-17T16:09:52.683757265Z,2025-07-17T16:09:52.683757265Z,10,2,1108,A,A,0,14.6400,100,130,165442,279110090,13.1099,100,1,13.6699,15,1,13.0099,2,1,13.6799,100,1,12.9800,200,2,13.6999,15,1,12.8599,100,1,13.9000,2,1,12.7300,100,1,14.0099,100,1,12.7100,100,1,14.2799,100,1,12.5000,700,1,14.4600,100,1,12.4900,200,2,14.4700,100,1,12.4600,100,1,14.4800,700,1,12.4299,700,1,14.5600,800,2,ARL,335220629
2192,2025-07-17T16:10:04.521306513Z,2025-07-17T16:10:04.521306513Z,10,2,1108,C,A,0,13.6699,15,130,165291,279306715,13.1099,100,1,13.6799,100,1,13.0099,2,1,13.6999,15,1,12.9800,200,2,13.9000,2,1,12.8599,100,1,14.0099,100,1,12.7300,100,1,14.2799,100,1,12.7100,100,1,14.4600,100,1,12.5000,700,1,14.4700,100,1,12.4900,200,2,14.4800,700,1,12.4600,100,1,14.5600,800,2,12.4299,700,1,14.5999,700,1,ARL,335178437
2193,2025-07-17T16:10:04.561688313Z,2025-07-17T16:10:04.561688313Z,10,2,1108,C,A,0,13.6999,15,128,166543,279312083,13.1099,100,1,13.6799,100,1,13.0099,2,1,13.9000,2,1,12.9800,200,2,14.0099,100,1,12.8599,100,1,14.2799,100,1,12.7300,100,1,14.4600,100,1,12.7100,100,1,14.4700,100,1,12.5000,700,1,14.4800,700,1,12.4900,200,2,14.5600,800,2,12.4600,100,1,14.5999,700,1,12.4299,700,1,14.6199,200,2,ARL,335003269
2194,2025-07-17T16:10:32.822495087Z,2025-07-17T16:10:32.822495087Z,10,2,1108,A,A,0,13.6500,15,130,165411,279705339,13.1099,100,1,13.6500,15,1,13.0099,2,1,13.6799,100,1,12.9800,200,2,13.9000,2,1,12.8599,100,1,14.0099,100,1,12.7300,100,1,14.2799,100,1,12.7100,100,1,14.4600,100,1,12.5000,700,1,14.4700,100,1,12.4900,200,2,14.4800,700,1,12.4600,100,1,14.5600,800,2,12.4299,700,1,14.5999,700,1,ARL,335996705
2195,2025-07-17T16:10:32.822757517Z,2025-07-17T16:10:32.822757517Z,10,2,1108,C,A,0,13.6799,100,0,165621,279705347,13.1099,100,1,13.6500,15,1,13.0099,2,1,13.9000,2,1,12.9800,200,2,14.0099,100,1,12.8599,100,1,14.2799,100,1,12.7300,100,1,14.4600,100,1,12.7100,100,1,14.4700,100,1,12.5000,700,1,14.4800,700,1,12.4900,200,2,14.5600,800,2,12.4600,100,1,14.5999,700,1,12.4299,700,1,14.6199,200,2,ARL,335220349
2196,2025-07-17T16:10:32.822757517Z,2025-07-17T16:10:32.822757517Z,10,2,1108,A,A,0,13.6600,100,130,165621,279705347,13.1099,100,1,13.6500,15,1,13.0099,2,1,13.6600,100,1,12.9800,200,2,13.9000,2,1,12.8599,100,1,14.0099,100,1,12.7300,100,1,14.2799,100,1,12.7100,100,1,14.4600,100,1,12.5000,700,1,14.4700,100,1,12.4900,200,2,14.4800,700,1,12.4600,100,1,14.5600,800,2,12.4299,700,1,14.5999,700,1,ARL,335996709
2197,2025-07-17T16:10:32.823491276Z,2025-07-17T16:10:32.823491276Z,10,2,1108,C,A,0,14.7699,100,0,165627,279705362,13.1099,100,1,13.6500,15,1,13.0099,2,1,13.6600,100,1,12.9800,200,2,13.9000,2,1,12.8599,100,1,14.0099,100,1,12.7300,100,1,14.2799,100,1,12.7100,100,1,14.4600,100,1,12.5000,700,1,14.4700,100,1,12.4900,200,2,14.4800,700,1,12.4600,100,1,14.5600,800,2,12.4299,700,1,14.5999,700,1,ARL,335003845
2198,2025-07-17T16:10:32.823491276Z,2025-07-17T16:10:32.823491276Z,10,2,1108,A,A,0,14.7200,100,130,165627,279705362,13.1099,100,1,13.6500,15,1,13.0099,2,1,13.6600,100,1,12.9800,200,2,13.9000,2,1,12.8599,100,1,14.0099,100,1,12.7300,100,1,14.2799,100,1,12.7100,100,1,14.4600,100,1,12.5000,700,1,14.4700,100,1,12.4900,200,2,14.4800,700,1,12.4600,100,1,14.5600,800,2,12.4299,700,1,14.5999,700,1,ARL,335996725
2199,2025-07-17T16:10:32.830032662Z,2025-07-17T16:10:32.830032662Z,10,2,1108,C,A,0,14.0099,100,130,168182,279705485,13.1099,100,1,13.6500,15,1,13.0099,2,1,13.6600,100,1,12.9800,200,2,13.9000,2,1,12.8599,100,1,14.2799,100,1,12.7300,100,1,14.4600,100,1,12.7100,100,1,14.4700,100,1,12.5000,700,1,14.4800,700,1,12.4900,200,2,14.5600,800,2,12.4600,100,1,14.5999,700,1,12.4299,700,1,14.6199,200,2,ARL,334593753
2200,2025-07-17T16:10:32.830085472Z,2025-07-17T16:10:32.830085472Z,10,2,1108,A,A,0,13.9299,100,130,165248,279705486,13.1099,100,1,13.6500,15,1,13.0099,2,1,13.6600,100,1,12.9800,200,2,13.9000,2,1,12.8599,100,1,13.9299,100,1,12.7300,100,1,14.2799,100,1,12.7100,100,1,14.4600,100,1,12.5000,700,1,14.4700,100,1,12.4900,200,2,14.4800,700,1,12.4600,100,1,14.5600,800,2,12.4299,700,1,14.5999,700,1,ARL,335996777
2201,2025-07-17T16:10:42.822189504Z,2025-07-17T16:10:42.822189504Z,10,2,1108,A,A,0,13.6300,15,130,165365,279834760,13.1099,100,1,13.6300,15,1,13.0099,2,1,13.6500,15,1,12.9800,200,2,13.6600,100,1,12.8599,100,1,13.9000,2,1,12.7300,100,1,13.9299,100,1,12.7100,100,1,14.2799,100,1,12.5000,700,1,14.4600,100,1,12.4900,200,2,14.4700,100,1,12.4600,100,1,14.4800,700,1,12.4299,700,1,14.5600,800,2,ARL,336161333
2202,2025-07-17T16:10:42.822258887Z,2025-07-17T16:10:42.822258887Z,10,2,1108,C,A,0,13.6600,100,0,165776,279834761,13.1099,100,1,13.6300,15,1,13.0099,2,1,13.6500,15,1,12.9800,200,2,13.9000,2,1,12.8599,100,1,13.9299,100,1,12.7300,100,1,14.2799,100,1,12.7100,100,1,14.4600,100,1,12.5000,700,1,14.4700,100,1,12.4900,200,2,14.4800,700,1,12.4600,100,1,14.5600,800,2,12.4299,700,1,14.5999,700,1,ARL,335996709
2203,2025-07-17T16:10:42.822258887Z,2025-07-17T16:10:42.822258887Z,10,2,1108,A,A,0,13.6400,100,130,165776,279834761,13.1099,100,1,13.6300,15,1,13.0099,2,1,13.6400,100,1,12.9800,200,2,13.6500,15,1,12.8599,100,1,13.9000,2,1,12.7300,100,1,13.9299,100,1,12.7100,100,1,14.2799,100,1,12.5000,700,1,14.4600,100,1,12.4900,200,2,14.4700,100,1,12.4600,100,1,14.4800,700,1,12.4299,700,1,14.5600,800,2,ARL,336161337
2204,2025-07-17T16:10:42.822998664Z,2025-07-17T16:10:42.822998664Z,10,2,1108,C,A,0,14.4600,100,130,165265,279834765,13.1099,100,1,13.6300,15,1,13.0099,2,1,13.6400,100,1,12.9800,200,2,13.6500,15,1,12.8599,100,1,13.9000,2,1,12.7300,100,1,13.9299,100,1,12.7100,100,1,14.2799,100,1,12.5000,700,1,14.4700,100,1,12.4900,200,2,14.4800,700,1,12.4600,100,1,14.5600,800,2,12.4299,700,1,14.5999,700,1,ARL,331927161
2205,2025-07-17T16:10:42.823352130Z,2025-07-17T16:10:42.823352130Z,10,2,1108,A,A,0,14.2500,100,130,165314,279834767,13.1099,100,1,13.6300,15,1,13.0099,2,1,13.6400,100,1,12.9800,200,2,13.6500,15,1,12.8599,100,1,13.9000,2,1,12.7300,100,1,13.9299,100,1,12.7100,100,1,14.2500,100,1,12.5000,700,1,14.2799,100,1,12.4900,200,2,14.4700,100,1,12.4600,100,1,14.4800,700,1,12.4299,700,1,14.5600,800,2,ARL,336161365
2206,2025-07-17T16:10:46.533890361Z,2025-07-17T16:10:46.533890361Z,10,2,1108,C,A,0,14.6199,100,0,165581,279921726,13.1099,100,1,13.6300,15,1,13.0099,2,1,13.6400,100,1,12.9800,200,2,13.6500,15,1,12.8599,100,1,13.9000,2,1,12.7300,100,1,13.9299,100,1,12.7100,100,1,14.2500,100,1,12.5000,700,1,14.2799,100,1,12.4900,200,2,14.4700,100,1,12.4600,100,1,14.4800,700,1,12.4299,700,1,14.5600,800,2,ARL,334583349
2207,2025-07-17T16:10:46.533890361Z,2025-07-17T16:10:46.533890361Z,10,2,1108,A,A,0,14.5099,100,130,165581,279921726,13.1099,100,1,13.6300,15,1,13.0099,2,1,13.6400,100,1,12.9800,200,2,13.6500,15,1,12.8599,100,1,13.9000,2,1,12.7300,100,1,13.9299,100,1,12.7100,100,1,14.2500,100,1,12.5000,700,1,14.2799,100,1,12.4900,200,2,14.4700,100,1,12.4600,100,1,14.4800,700,1,12.4299,700,1,14.5099,100,1,ARL,336259225
2208,2025-07-17T16:10:46.537992315Z,2025-07-17T16:10:46.537992315Z,10,2,1108,C,A,0,13.6500,15,128,166559,279921911,13.1099,100,1,13.6300,15,1,13.0099,2,1,13.6400,100,1,12.9800,200,2,13.9000,2,1,12.8599,100,1,13.9299,100,1,12.7300,100,1,14.2500,100,1,12.7100,100,1,14.2799,100,1,12.5000,700,1,14.4700,100,1,12.4900,200,2,14.4800,700,1,12.4600,100,1,14.5099,100,1,12.4299,700,1,14.5600,800,2,ARL,335996705
2209,2025-07-17T16:10:46.561080616Z,2025-07-17T16:10:46.561080616Z,10,2,1108,C,A,0,14.6199,100,0,165414,279924883,13.1099,100,1,13.6300,15,1,13.0099,2,1,13.6400,100,1,12.9800,200,2,13.9000,2,1,12.8599,100,1,13.9299,100,1,12.7300,100,1,14.2500,100,1,12.7100,100,1,14.2799,100,1,12.5000,700,1,14.4700,100,1,12.4900,200,2,14.4800,700,1,12.4600,100,1,14.5099,100,1,12.4299,700,1,14.5600,800,2,ARL,334583361
2210,2025-07-17T16:10:46.561080616Z,2025-07-17T16:10:46.561080616Z,10,2,1108,A,A,0,14.5099,100,130,165414,279924883,13.1099,100,1,13.6300,15,1,13.0099,2,1,13.6400,100,1,12.9800,200,2,13.9000,2,1,12.8599,100,1,13.9299,100,1,12.7300,100,1,14.2500,100,1,12.7100,100,1,14.2799,100,1,12.5000,700,1,14.4700,100,1,12.4900,200,2,14.4800,700,1,12.4600,100,1,14.5099,200,2,12.4299,700,1,14.5600,800,2,ARL,336261905
2211,2025-07-17T16:10:47.543238729Z,2025-07-17T16:10:47.543238729Z,10,2,1108,A,A,0,13.6099,15,130,165272,279938097,13.1099,100,1,13.6099,15,1,13.0099,2,1,13.6300,15,1,12.9800,200,2,13.6400,100,1,12.8599,100,1,13.9000,2,1,12.7300,100,1,13.9299,100,1,12.7100,100,1,14.2500,100,1,12.5000,700,1,14.2799,100,1,12.4900,200,2,14.4700,100,1,12.4600,100,1,14.4800,700,1,12.4299,700,1,14.5099,200,2,ARL,336278197
2212,2025-07-17T16:10:48.657290980Z,2025-07-17T16:10:48.657290980Z,10,2,1108,C,A,0,13.6400,100,0,165415,279952266,13.1099,100,1,13.6099,15,1,13.0099,2,1,13.6300,15,1,12.9800,200,2,13.9000,2,1,12.8599,100,1,13.9299,100,1,12.7300,100,1,14.2500,100,1,12.7100,100,1,14.2799,100,1,12.5000,700,1,14.4700,100,1,12.4900,200,2,14.4800,700,1,12.4600,100,1,14.5099,200,2,12.4299,700,1,14.5600,800,2,ARL,336161337
2213,2025-07-17T16:10:48.657290980Z,2025-07-17T16:10:48.657290980Z,10,2,1108,A,A,0,13.6199,100,130,165415,279952266,13.1099,100,1,13.6099,15,1,13.0099,2,1,13.6199,100,1,12.9800,200,2,13.6300,15,1,12.8599,100,1,13.9000,2,1,12.7300,100,1,13.9299,100,1,12.7100,100,1,14.2500,100,1,12.5000,700,1,14.2799,100,1,12.4900,200,2,14.4700,100,1,12.4600,100,1,14.4800,700,1,12.4299,700,1,14.5099,200,2,ARL,336295769
2214,2025-07-17T16:10:48.658033954Z,2025-07-17T16:10:48.658033954Z,10,2,1108,C,A,0,14.7200,100,0,165471,279952282,13.1099,100,1,13.6099,15,1,13.0099,2,1,13.6199,100,1,12.9800,200,2,13.6300,15,1,12.8599,100,1,13.9000,2,1,12.7300,100,1,13.9299,100,1,12.7100,100,1,14.2500,100,1,12.5000,700,1,14.2799,100,1,12.4900,200,2,14.4700,100,1,12.4600,100,1,14.4800,700,1,12.4299,700,1,14.5099,200,2,ARL,335996725
2215,2025-07-17T16:10:48.658033954Z,2025-07-17T16:10:48.658033954Z,10,2,1108,A,A,0,14.6799,100,130,165471,279952282,13.1099,100,1,13.6099,15,1,13.0099,2,1,13.6199,100,1,12.9800,200,2,13.6300,15,1,12.8599,100,1,13.9000,2,1,12.7300,100,1,13.9299,100,1,12.7100,100,1,14.2500,100,1,12.5000,700,1,14.2799,100,1,12.4900,200,2,14.4700,100,1,12.4600,100,1,14.4800,700,1,12.4299,700,1,14.5099,200,2,ARL,336295845
2216,2025-07-17T16:10:51.058878264Z,2025-07-17T16:10:51.058878264Z,10,2,1108,C,A,0,13.6099,15,128,166028,280001840,13.1099,100,1,13.6199,100,1,13.0099,2,1,13.6300,15,1,12.9800,200,2,13.9000,2,1,12.8599,100,1,13.9299,100,1,12.7300,100,1,14.2500,100,1,12.7100,100,1,14.2799,100,1,12.5000,700,1,14.4700,100,1,12.4900,200,2,14.4800,700,1,12.4600,100,1,14.5099,200,2,12.4299,700,1,14.5600,800,2,ARL,336278197
2217,2025-07-17T16:10:51.059016199Z,2025-07-17T16:10:51.059016199Z,10,2,1108,C,A,0,13.6300,15,128,167724,280001873,13.1099,100,1,13.6199,100,1,13.0099,2,1,13.9000,2,1,12.9800,200,2,13.9299,100,1,12.8599,100,1,14.2500,100,1,12.7300,100,1,14.2799,100,1,12.7100,100,1,14.4700,100,1,12.5000,700,1,14.4800,700,1,12.4900,200,2,14.5099,200,2,12.4600,100,1,14.5600,800,2,12.4299,700,1,14.5999,700,1,ARL,336161333
2218,2025-07-17T16:10:51.059443298Z,2025-07-17T16:10:51.059443298Z,10,2,1108,C,A,0,13.6199,100,130,165455,280001952,13.1099,100,1,13.9000,2,1,13.0099,2,1,13.9299,100,1,12.9800,200,2,14.2500,100,1,12.8599,100,1,14.2799,100,1,12.7300,100,1,14.4700,100,1,12.7100,100,1,14.4800,700,1,12.5000,700,1,14.5099,200,2,12.4900,200,2,14.5600,800,2,12.4600,100,1,14.5999,700,1,12.4299,700,1,14.6400,200,2,ARL,336295769
2219,2025-07-17T16:10:51.170545251Z,2025-07-17T16:10:51.170545251Z,10,2,1108,A,A,0,13.9100,100,130,165358,280003702,13.1099,100,1,13.9000,2,1,13.0099,2,1,13.9100,100,1,12.9800,200,2,13.9299,100,1,12.8599,100,1,14.2500,100,1,12.7300,100,1,14.2799,100,1,12.7100,100,1,14.4700,100,1,12.5000,700,1,14.4800,700,1,12.4900,200,2,14.5099,200,2,12.4600,100,1,14.5600,800,2,12.4299,700,1,14.5999,700,1,ARL,336351081
2220,2025-07-17T16:10:52.958288317Z,2025-07-17T16:10:52.958288317Z,10,2,1108,A,A,0,13.5999,15,130,165324,280050139,13.1099,100,1,13.5999,15,1,13.0099,2,1,13.9000,2,1,12.9800,200,2,13.9100,100,1,12.8599,100,1,13.9299,100,1,12.7300,100,1,14.2500,100,1,12.7100,100,1,14.2799,100,1,12.5000,700,1,14.4700,100,1,12.4900,200,2,14.4800,700,1,12.4600,100,1,14.5099,200,2,12.4299,700,1,14.5600,800,2,ARL,336402845
2221,2025-07-17T16:10:53.101871639Z,2025-07-17T16:10:53.101871639Z,10,2,1108,C,A,0,13.9100,100,0,165534,280057228,13.1099,100,1,13.5999,15,1,13.0099,2,1,13.9000,2,1,12.9800,200,2,13.9299,100,1,12.8599,100,1,14.2500,100,1,12.7300,100,1,14.2799,100,1,12.7100,100,1,14.4700,100,1,12.5000,700,1,14.4800,700,1,12.4900,200,2,14.5099,200,2,12.4600,100,1,14.5600,800,2,12.4299,700,1,14.5999,700,1,ARL,336351081
2222,2025-07-17T16:10:53.101871639Z,2025-07-17T16:10:53.101871639Z,10,2,1108,A,A,0,13.6099,100,130,165534,280057228,13.1099,100,1,13.5999,15,1,13.0099,2,1,13.6099,100,1,12.9800,200,2,13.9000,2,1,12.8599,100,1,13.9299,100,1,12.7300,100,1,14.2500,100,1,12.7100,100,1,14.2799,100,1,12.5000,700,1,14.4700,100,1,12.4900,200,2,14.4800,700,1,12.4600,100,1,14.5099,200,2,12.4299,700,1,14.5600,800,2,ARL,336410125
2223,2025-07-17T16:10:54.959141873Z,2025-07-17T16:10:54.959141873Z,10,2,1108,C,A,0,13.9000,2,0,165719,280084546,13.1099,100,1,13.5999,15,1,13.0099,2,1,13.6099,100,1,12.9800,200,2,13.9299,100,1,12.8599,100,1,14.2500,100,1,12.7300,100,1,14.2799,100,1,12.7100,100,1,14.4700,100,1,12.5000,700,1,14.4800,700,1,12.4900,200,2,14.5099,200,2,12.4600,100,1,14.5600,800,2,12.4299,700,1,14.5999,700,1,ARL,334804177
2224,2025-07-17T16:10:54.959141873Z,2025-07-17T16:10:54.959141873Z,10,2,1108,A,A,0,13.8200,2,130,165719,280084546,13.1099,100,1,13.5999,15,1,13.0099,2,1,13.6099,100,1,12.9800,200,2,13.8200,2,1,12.8599,100,1,13.9299,100,1,12.7300,100,1,14.2500,100,1,12.7100,100,1,14.2799,100,1,12.5000,700,1,14.4700,100,1,12.4900,200,2,14.4800,700,1,12.4600,100,1,14.5099,200,2,12.4299,700,1,14.5600,800,2,ARL,336447325
2225,2025-07-17T16:10:59.517870358Z,2025-07-17T16:10:59.517870358Z,10,2,1108,A,A,0,13.5800,15,130,165447,280173685,13.1099,100,1,13.5800,15,1,13.0099,2,1,13.5999,15,1,12.9800,200,2,13.6099,100,1,12.8599,100,1,13.8200,2,1,12.7300,100,1,13.9299,100,1,12.7100,100,1,14.2500,100,1,12.5000,700,1,14.2799,100,1,12.4900,200,2,14.4700,100,1,12.4600,100,1,14.4800,700,1,12.4299,700,1,14.5099,200,2,ARL,336555153
2226,2025-07-17T16:11:00.215719725Z,2025-07-17T16:11:00.215719725Z,10,2,1108,C,A,0,13.6099,100,0,165569,280184406,13.1099,100,1,13.5800,15,1,13.0099,2,1,13.5999,15,1,12.9800,200,2,13.8200,2,1,12.8599,100,1,13.9299,100,1,12.7300,100,1,14.2500,100,1,12.7100,100,1,14.2799,100,1,12.5000,700,1,14.4700,100,1,12.4900,200,2,14.4800,700,1,12.4600,100,1,14.5099,200,2,12.4299,700,1,14.5600,800,2,ARL,336410125
2227,2025-07-17T16:11:00.215719725Z,2025-07-17T16:11:00.215719725Z,10,2,1108,A,A,0,13.5899,100,130,165569,280184406,13.1099,100,1,13.5800,15,1,13.0099,2,1,13.5899,100,1,12.9800,200,2,13.5999,15,1,12.8599,100,1,13.8200,2,1,12.7300,100,1,13.9299,100,1,12.7100,100,1,14.2500,100,1,12.5000,700,1,14.2799,100,1,12.4900,200,2,14.4700,100,1,12.4600,100,1,14.4800,700,1,12.4299,700,1,14.5099,200,2,ARL,336567189
2228,2025-07-17T16:11:00.216456547Z,2025-07-17T16:11:00.216456547Z,10,2,1108,C,A,0,14.6799,100,0,165574,280184418,13.1099,100,1,13.5800,15,1,13.0099,2,1,13.5899,100,1,12.9800,200,2,13.5999,15,1,12.8599,100,1,13.8200,2,1,12.7300,100,1,13.9299,100,1,12.7100,100,1,14.2500,100,1,12.5000,700,1,14.2799,100,1,12.4900,200,2,14.4700,100,1,12.4600,100,1,14.4800,700,1,12.4299,700,1,14.5099,200,2,ARL,336295845
2229,2025-07-17T16:11:00.216456547Z,2025-07-17T16:11:00.216456547Z,10,2,1108,A,A,0,14.6400,100,130,165574,280184418,13.1099,100,1,13.5800,15,1,13.0099,2,1,13.5899,100,1,12.9800,200,2,13.5999,15,1,12.8599,100,1,13.8200,2,1,12.7300,100,1,13.9299,100,1,12.7100,100,1,14.2500,100,1,12.5000,700,1,14.2799,100,1,12.4900,200,2,14.4700,100,1,12.4600,100,1,14.4800,700,1,12.4299,700,1,14.5099,200,2,ARL,336567213
2230,2025-07-17T16:11:00.228833925Z,2025-07-17T16:11:00.228833925Z,10,2,1108,C,A,0,13.9299,100,130,165452,280184613,13.1099,100,1,13.5800,15,1,13.0099,2,1,13.5899,100,1,12.9800,200,2,13.5999,15,1,12.8599,100,1,13.8200,2,1,12.7300,100,1,14.2500,100,1,12.7100,100,1,14.2799,100,1,12.5000,700,1,14.4700,100,1,12.4900,200,2,14.4800,700,1,12.4600,100,1,14.5099,200,2,12.4299,700,1,14.5600,800,2,ARL,335996777
2231,2025-07-17T16:11:00.228885790Z,2025-07-17T16:11:00.228885790Z,10,2,1108,A,A,0,13.8599,100,130,165334,280184614,13.1099,100,1,13.5800,15,1,13.0099,2,1,13.5899,100,1,12.9800,200,2,13.5999,15,1,12.8599,100,1,13.8200,2,1,12.7300,100,1,13.8599,100,1,12.7100,100,1,14.2500,100,1,12.5000,700,1,14.2799,100,1,12.4900,200,2,14.4700,100,1,12.4600,100,1,14.4800,700,1,12.4299,700,1,14.5099,200,2,ARL,336567333
2232,2025-07-17T16:11:00.312921679Z,2025-07-17T16:11:00.312921679Z,10,2,1108,C,A,0,17.4200,100,0,165450,280188038,13.1099,100,1,13.5800,15,1,13.0099,2,1,13.5899,100,1,12.9800,200,2,13.5999,15,1,12.8599,100,1,13.8200,2,1,12.7300,100,1,13.8599,100,1,12.7100,100,1,14.2500,100,1,12.5000,700,1,14.2799,100,1,12.4900,200,2,14.4700,100,1,12.4600,100,1,14.4800,700,1,12.4299,700,1,14.5099,200,2,ARL,335003849
2233,2025-07-17T16:11:00.312921679Z,2025-07-17T16:11:00.312921679Z,10,2,1108,A,A,0,17.2600,100,130,165450,280188038,13.1099,100,1,13.5800,15,1,13.0099,2,1,13.5899,100,1,12.9800,200,2,13.5999,15,1,12.8599,100,1,13.8200,2,1,12.7300,100,1,13.8599,100,1,12.7100,100,1,14.2500,100,1,12.5000,700,1,14.2799,100,1,12.4900,200,2,14.4700,100,1,12.4600,100,1,14.4800,700,1,12.4299,700,1,14.5099,200,2,ARL,336570921
2234,2025-07-17T16:11:00.366645846Z,2025-07-17T16:11:00.366645846Z,10,2,1108,A,A,0,13.6199,1,130,165695,280189435,13.1099,100,1,13.5800,15,1,13.0099,2,1,13.5899,100,1,12.9800,200,2,13.5999,15,1,12.8599,100,1,13.6199,1,1,12.7300,100,1,13.8200,2,1,12.7100,100,1,13.8599,100,1,12.5000,700,1,14.2500,100,1,12.4900,200,2,14.2799,100,1,12.4600,100,1,14.4700,100,1,12.4299,700,1,14.4800,700,1,ARL,336572049
2235,2025-07-17T16:11:00.367209243Z,2025-07-17T16:11:00.367209243Z,10,2,1108,C,B,0,12.4900,100,0,165530,280189439,13.1099,100,1,13.5800,15,1,13.0099,2,1,13.5899,100,1,12.9800,200,2,13.5999,15,1,12.8599,100,1,13.6199,1,1,12.7300,100,1,13.8200,2,1,12.7100,100,1,13.8599,100,1,12.5000,700,1,14.2500,100,1,12.4900,100,1,14.2799,100,1,12.4600,100,1,14.4700,100,1,12.4299,700,1,14.4800,700,1,ARL,331942945
2236,2025-07-17T16:11:00.367209243Z,2025-07-17T16:11:00.367209243Z,10,2,1108,A,B,0,12.3599,100,130,165530,280189439,13.1099,100,1,13.5800,15,1,13.0099,2,1,13.5899,100,1,12.9800,200,2,13.5999,15,1,12.8599,100,1,13.6199,1,1,12.7300,100,1,13.8200,2,1,12.7100,100,1,13.8599,100,1,12.5000,700,1,14.2500,100,1,12.4900,100,1,14.2799,100,1,12.4600,100,1,14.4700,100,1,12.4299,700,1,14.4800,700,1,ARL,336572057
2237,2025-07-17T16:11:00.367319059Z,2025-07-17T16:11:00.367319059Z,10,2,1108,C,B,0,12.4900,100,0,166035,280189441,13.1099,100,1,13.5800,15,1,13.0099,2,1,13.5899,100,1,12.9800,200,2,13.5999,15,1,12.8599,100,1,13.6199,1,1,12.7300,100,1,13.8200,2,1,12.7100,100,1,13.8599,100,1,12.5000,700,1,14.2500,100,1,12.4600,100,1,14.2799,100,1,12.4299,700,1,14.4700,100,1,12.4199,700,1,14.4800,700,1,ARL,331942901
2238,2025-07-17T16:11:00.367319059Z,2025-07-17T16:11:00.367319059Z,10,2,1108,A,B,0,12.3599,100,130,166035,280189441,13.1099,100,1,13.5800,15,1,13.0099,2,1,13.5899,100,1,12.9800,200,2,13.5999,15,1,12.8599,100,1,13.6199,1,1,12.7300,100,1,13.8200,2,1,12.7100,100,1,13.8599,100,1,12.5000,700,1,14.2500,100,1,12.4600,100,1,14.2799,100,1,12.4299,700,1,14.4700,100,1,12.4199,700,1,14.4800,700,1,ARL,336572069
2239,2025-07-17T16:11:00.466703632Z,2025-07-17T16:11:00.466703632Z,10,2,1108,C,A,0,13.6199,1,130,164992,280191783,13.1099,100,1,13.5800,15,1,13.0099,2,1,13.5899,100,1,12.9800,200,2,13.5999,15,1,12.8599,100,1,13.8200,2,1,12.7300,100,1,13.8599,100,1,12.7100,100,1,14.2500,100,1,12.5000,700,1,14.2799,100,1,12.4600,100,1,14.4700,100,1,12.4299,700,1,14.4800,700,1,12.4199,700,1,14.5099,200,2,ARL,336572049
2240,2025-07-17T16:11:06.626666474Z,2025-07-17T16:11:06.626666474Z,10,2,1108,A,A,0,14.2699,700,130,165325,280342316,13.1099,100,1,13.5800,15,1,13.0099,2,1,13.5899,100,1,12.9800,200,2,13.5999,15,1,12.8599,100,1,13.8200,2,1,12.7300,100,1,13.8599,100,1,12.7100,100,1,14.2500,100,1,12.5000,700,1,14.2699,700,1,12.4600,100,1,14.2799,100,1,12.4299,700,1,14.4700,100,1,12.4199,700,1,14.4800,700,1,ARL,336747457
2241,2025-07-17T16:11:06.626741446Z,2025-07-17T16:11:06.626741446Z,10,2,1108,C,A,0,14.6799,700,130,165254,280342318,13.1099,100,1,13.5800,15,1,13.0099,2,1,13.5899,100,1,12.9800,200,2,13.5999,15,1,12.8599,100,1,13.8200,2,1,12.7300,100,1,13.8599,100,1,12.7100,100,1,14.2500,100,1,12.5000,700,1,14.2699,700,1,12.4600,100,1,14.2799,100,1,12.4299,700,1,14.4700,100,1,12.4199,700,1,14.4800,700,1,ARL,331929977
2242,2025-07-17T16:11:08.307868957Z,2025-07-17T16:11:08.307868957Z,10,2,1108,C,A,0,13.5999,15,130,165581,280374785,13.1099,100,1,13.5800,15,1,13.0099,2,1,13.5899,100,1,12.9800,200,2,13.8200,2,1,12.8599,100,1,13.8599,100,1,12.7300,100,1,14.2500,100,1,12.7100,100,1,14.2699,700,1,12.5000,700,1,14.2799,100,1,12.4600,100,1,14.4700,100,1,12.4299,700,1,14.4800,700,1,12.4199,700,1,14.5099,200,2,ARL,336402845
2243,2025-07-17T16:11:09.568370995Z,2025-07-17T16:11:09.568370995Z,10,2,1108,A,A,0,13.5600,15,130,165297,280401189,13.1099,100,1,13.5600,15,1,13.0099,2,1,13.5800,15,1,12.9800,200,2,13.5899,100,1,12.8599,100,1,13.8200,2,1,12.7300,100,1,13.8599,100,1,12.7100,100,1,14.2500,100,1,12.5000,700,1,14.2699,700,1,12.4600,100,1,14.2799,100,1,12.4299,700,1,14.4700,100,1,12.4199,700,1,14.4800,700,1,ARL,336816813
2244,2025-07-17T16:11:10.341788521Z,2025-07-17T16:11:10.341788521Z,10,2,1108,C,A,0,13.5899,100,0,165450,280411396,13.1099,100,1,13.5600,15,1,13.0099,2,1,13.5800,15,1,12.9800,200,2,13.8200,2,1,12.8599,100,1,13.8599,100,1,12.7300,100,1,14.2500,100,1,12.7100,100,1,14.2699,700,1,12.5000,700,1,14.2799,100,1,12.4600,100,1,14.4700,100,1,12.4299,700,1,14.4800,700,1,12.4199,700,1,14.5099,200,2,ARL,336567189
2245,2025-07-17T16:11:10.341788521Z,2025-07-17T16:11:10.341788521Z,10,2,1108,A,A,0,13.5700,100,130,165450,280411396,13.1099,100,1,13.5600,15,1,13.0099,2,1,13.5700,100,1,12.9800,200,2,13.5800,15,1,12.8599,100,1,13.8200,2,1,12.7300,100,1,13.8599,100,1,12.7100,100,1,14.2500,100,1,12.5000,700,1,14.2699,700,1,12.4600,100,1,14.2799,100,1,12.4299,700,1,14.4700,100,1,12.4199,700,1,14.4800,700,1,ARL,336828765
2246,2025-07-17T16:11:14.610535763Z,2025-07-17T16:11:14.610535763Z,10,2,1108,C,A,0,13.5800,15,130,165687,280482371,13.1099,100,1,13.5600,15,1,13.0099,2,1,13.5700,100,1,12.9800,200,2,13.8200,2,1,12.8599,100,1,13.8599,100,1,12.7300,100,1,14.2500,100,1,12.7100,100,1,14.2699,700,1,12.5000,700,1,14.2799,100,1,12.4600,100,1,14.4700,100,1,12.4299,700,1,14.4800,700,1,12.4199,700,1,14.5099,200,2,ARL,336555153
2247,2025-07-17T16:11:16.025292936Z,2025-07-17T16:11:16.025292936Z,10,2,1108,C,A,0,13.5600,15,130,165295,280514282,13.1099,100,1,13.5700,100,1,13.0099,2,1,13.8200,2,1,12.9800,200,2,13.8599,100,1,12.8599,100,1,14.2500,100,1,12.7300,100,1,14.2699,700,1,12.7100,100,1,14.2799,100,1,12.5000,700,1,14.4700,100,1,12.4600,100,1,14.4800,700,1,12.4299,700,1,14.5099,200,2,12.4199,700,1,14.5600,800,2,ARL,336816813
2248,2025-07-17T16:11:50.026672014Z,2025-07-17T16:11:50.026672014Z,10,2,1108,A,A,0,13.5500,15,130,165344,281078802,13.1099,100,1,13.5500,15,1,13.0099,2,1,13.5700,100,1,12.9800,200,2,13.8200,2,1,12.8599,100,1,13.8599,100,1,12.7300,100,1,14.2500,100,1,12.7100,100,1,14.2699,700,1,12.5000,700,1,14.2799,100,1,12.4600,100,1,14.4700,100,1,12.4299,700,1,14.4800,700,1,12.4199,700,1,14.5099,200,2,ARL,337690189
2249,2025-07-17T16:11:50.026839463Z,2025-07-17T16:11:50.026839463Z,10,2,1108,C,A,0,13.5700,100,0,165514,281078803,13.1099,100,1,13.5500,15,1,13.0099,2,1,13.8200,2,1,12.9800,200,2,13.8599,100,1,12.8599,100,1,14.2500,100,1,12.7300,100,1,14.2699,700,1,12.7100,100,1,14.2799,100,1,12.5000,700,1,14.4700,100,1,12.4600,100,1,14.4800,700,1,12.4299,700,1,14.5099,200,2,12.4199,700,1,14.5600,800,2,ARL,336828765
2250,2025-07-17T16:11:50.026839463Z,2025-07-17T16:11:50.026839463Z,10,2,1108,A,A,0,13.5600,100,130,165514,281078803,13.1099,100,1,13.5500,15,1,13.0099,2,1,13.5600,100,1,12.9800,200,2,13.8200,2,1,12.8599,100,1,13.8599,100,1,12.7300,100,1,14.2500,100,1,12.7100,100,1,14.2699,700,1,12.5000,700,1,14.2799,100,1,12.4600,100,1,14.4700,100,1,12.4299,700,1,14.4800,700,1,12.4199,700,1,14.5099,200,2,ARL,337690193
2251,2025-07-17T16:11:50.032845393Z,2025-07-17T16:11:50.032845393Z,10,2,1108,C,A,0,15.7400,100,0,165405,281078903,13.1099,100,1,13.5500,15,1,13.0099,2,1,13.5600,100,1,12.9800,200,2,13.8200,2,1,12.8599,100,1,13.8599,100,1,12.7300,100,1,14.2500,100,1,12.7100,100,1,14.2699,700,1,12.5000,700,1,14.2799,100,1,12.4600,100,1,14.4700,100,1,12.4299,700,1,14.4800,700,1,12.4199,700,1,14.5099,200,2,ARL,335220497
2252,2025-07-17T16:11:50.032845393Z,2025-07-17T16:11:50.032845393Z,10,2,1108,A,A,0,15.5999,100,130,165405,281078903,13.1099,100,1,13.5500,15,1,13.0099,2,1,13.5600,100,1,12.9800,200,2,13.8200,2,1,12.8599,100,1,13.8599,100,1,12.7300,100,1,14.2500,100,1,12.7100,100,1,14.2699,700,1,12.5000,700,1,14.2799,100,1,12.4600,100,1,14.4700,100,1,12.4299,700,1,14.4800,700,1,12.4199,700,1,14.5099,200,2,ARL,337690641
2253,2025-07-17T16:11:53.859743991Z,2025-07-17T16:11:53.859743991Z,10,2,1108,A,A,0,13.5299,15,130,165471,281142794,13.1099,100,1,13.5299,15,1,13.0099,2,1,13.5500,15,1,12.9800,200,2,13.5600,100,1,12.8599,100,1,13.8200,2,1,12.7300,100,1,13.8599,100,1,12.7100,100,1,14.2500,100,1,12.5000,700,1,14.2699,700,1,12.4600,100,1,14.2799,100,1,12.4299,700,1,14.4700,100,1,12.4199,700,1,14.4800,700,1,ARL,337772837
2254,2025-07-17T16:11:54.662361841Z,2025-07-17T16:11:54.662361841Z,10,2,1108,C,A,0,13.5600,100,0,165491,281156215,13.1099,100,1,13.5299,15,1,13.0099,2,1,13.5500,15,1,12.9800,200,2,13.8200,2,1,12.8599,100,1,13.8599,100,1,12.7300,100,1,14.2500,100,1,12.7100,100,1,14.2699,700,1,12.5000,700,1,14.2799,100,1,12.4600,100,1,14.4700,100,1,12.4299,700,1,14.4800,700,1,12.4199,700,1,14.5099,200,2,ARL,337690193
2255,2025-07-17T16:11:54.662361841Z,2025-07-17T16:11:54.662361841Z,10,2,1108,A,A,0,13.5399,100,130,165491,281156215,13.1099,100,1,13.5299,15,1,13.0099,2,1,13.5399,100,1,12.9800,200,2,13.5500,15,1,12.8599,100,1,13.8200,2,1,12.7300,100,1,13.8599,100,1,12.7100,100,1,14.2500,100,1,12.5000,700,1,14.2699,700,1,12.4600,100,1,14.2799,100,1,12.4299,700,1,14.4700,100,1,12.4199,700,1,14.4800,700,1,ARL,337790717
2256,2025-07-17T16:11:54.663112543Z,2025-07-17T16:11:54.663112543Z,10,2,1108,C,A,0,14.6400,100,0,165657,281156222,13.1099,100,1,13.5299,15,1,13.0099,2,1,13.5399,100,1,12.9800,200,2,13.5500,15,1,12.8599,100,1,13.8200,2,1,12.7300,100,1,13.8599,100,1,12.7100,100,1,14.2500,100,1,12.5000,700,1,14.2699,700,1,12.4600,100,1,14.2799,100,1,12.4299,700,1,14.4700,100,1,12.4199,700,1,14.4800,700,1,ARL,336567213
2257,2025-07-17T16:11:54.663112543Z,2025-07-17T16:11:54.663112543Z,10,2,1108,A,A,0,14.5899,100,130,165657,281156222,13.1099,100,1,13.5299,15,1,13.0099,2,1,13.5399,100,1,12.9800,200,2,13.5500,15,1,12.8599,100,1,13.8200,2,1,12.7300,100,1,13.8599,100,1,12.7100,100,1,14.2500,100,1,12.5000,700,1,14.2699,700,1,12.4600,100,1,14.2799,100,1,12.4299,700,1,14.4700,100,1,12.4199,700,1,14.4800,700,1,ARL,337790737
2258,2025-07-17T16:11:54.663968656Z,2025-07-17T16:11:54.663968656Z,10,2,1108,C,A,0,14.6400,100,0,165370,281156223,13.1099,100,1,13.5299,15,1,13.0099,2,1,13.5399,100,1,12.9800,200,2,13.5500,15,1,12.8599,100,1,13.8200,2,1,12.7300,100,1,13.8599,100,1,12.7100,100,1,14.2500,100,1,12.5000,700,1,14.2699,700,1,12.4600,100,1,14.2799,100,1,12.4299,700,1,14.4700,100,1,12.4199,700,1,14.4800,700,1,ARL,335220525
2259,2025-07-17T16:11:54.663968656Z,2025-07-17T16:11:54.663968656Z,10,2,1108,A,A,0,14.4900,100,130,165370,281156223,13.1099,100,1,13.5299,15,1,13.0099,2,1,13.5399,100,1,12.9800,200,2,13.5500,15,1,12.8599,100,1,13.8200,2,1,12.7300,100,1,13.8599,100,1,12.7100,100,1,14.2500,100,1,12.5000,700,1,14.2699,700,1,12.4600,100,1,14.2799,100,1,12.4299,700,1,14.4700,100,1,12.4199,700,1,14.4800,700,1,ARL,337790745
2260,2025-07-17T16:11:54.666160990Z,2025-07-17T16:11:54.666160990Z,10,2,1108,C,A,0,14.4700,100,0,165610,281156243,13.1099,100,1,13.5299,15,1,13.0099,2,1,13.5399,100,1,12.9800,200,2,13.5500,15,1,12.8599,100,1,13.8200,2,1,12.7300,100,1,13.8599,100,1,12.7100,100,1,14.2500,100,1,12.5000,700,1,14.2699,700,1,12.4600,100,1,14.2799,100,1,12.4299,700,1,14.4800,700,1,12.4199,700,1,14.4900,100,1,ARL,335220561
2261,2025-07-17T16:11:54.666160990Z,2025-07-17T16:11:54.666160990Z,10,2,1108,A,A,0,14.3300,100,130,165610,281156243,13.1099,100,1,13.5299,15,1,13.0099,2,1,13.5399,100,1,12.9800,200,2,13.5500,15,1,12.8599,100,1,13.8200,2,1,12.7300,100,1,13.8599,100,1,12.7100,100,1,14.2500,100,1,12.5000,700,1,14.2699,700,1,12.4600,100,1,14.2799,100,1,12.4299,700,1,14.3300,100,1,12.4199,700,1,14.4800,700,1,ARL,337790761
2262,2025-07-17T16:11:54.667339002Z,2025-07-17T16:11:54.667339002Z,10,2,1108,C,A,0,14.6400,100,0,165544,281156250,13.1099,100,1,13.5299,15,1,13.0099,2,1,13.5399,100,1,12.9800,200,2,13.5500,15,1,12.8599,100,1,13.8200,2,1,12.7300,100,1,13.8599,100,1,12.7100,100,1,14.2500,100,1,12.5000,700,1,14.2699,700,1,12.4600,100,1,14.2799,100,1,12.4299,700,1,14.3300,100,1,12.4199,700,1,14.4800,700,1,ARL,335220629
2263,2025-07-17T16:11:54.667339002Z,2025-07-17T16:11:54.667339002Z,10,2,1108,A,A,0,14.4900,100,130,165544,281156250,13.1099,100,1,13.5299,15,1,13.0099,2,1,13.5399,100,1,12.9800,200,2,13.5500,15,1,12.8599,100,1,13.8200,2,1,12.7300,100,1,13.8599,100,1,12.7100,100,1,14.2500,100,1,12.5000,700,1,14.2699,700,1,12.4600,100,1,14.2799,100,1,12.4299,700,1,14.3300,100,1,12.4199,700,1,14.4800,700,1,ARL,337790777
2264,2025-07-17T16:11:59.382350338Z,2025-07-17T16:11:59.382350338Z,10,2,1108,C,A,0,13.5500,15,130,165340,281270010,13.1099,100,1,13.5299,15,1,13.0099,2,1,13.5399,100,1,12.9800,200,2,13.8200,2,1,12.8599,100,1,13.8599,100,1,12.7300,100,1,14.2500,100,1,12.7100,100,1,14.2699,700,1,12.5000,700,1,14.2799,100,1,12.4600,100,1,14.3300,100,1,12.4299,700,1,14.4800,700,1,12.4199,700,1,14.4900,200,2,ARL,337690189
2265,2025-07-17T16:12:02.981913204Z,2025-07-17T16:12:02.981913204Z,10,2,1108,A,A,0,13.5099,15,130,165515,281348152,13.1099,100,1,13.5099,15,1,13.0099,2,1,13.5299,15,1,12.9800,200,2,13.5399,100,1,12.8599,100,1,13.8200,2,1,12.7300,100,1,13.8599,100,1,12.7100,100,1,14.2500,100,1,12.5000,700,1,14.2699,700,1,12.4600,100,1,14.2799,100,1,12.4299,700,1,14.3300,100,1,12.4199,700,1,14.4800,700,1,ARL,338041605
2266,2025-07-17T16:12:03.063997054Z,2025-07-17T16:12:03.063997054Z,10,2,1108,C,A,0,13.5399,100,0,165551,281351122,13.1099,100,1,13.5099,15,1,13.0099,2,1,13.5299,15,1,12.9800,200,2,13.8200,2,1,12.8599,100,1,13.8599,100,1,12.7300,100,1,14.2500,100,1,12.7100,100,1,14.2699,700,1,12.5000,700,1,14.2799,100,1,12.4600,100,1,14.3300,100,1,12.4299,700,1,14.4800,700,1,12.4199,700,1,14.4900,200,2,ARL,337790717
2267,2025-07-17T16:12:03.063997054Z,2025-07-17T16:12:03.063997054Z,10,2,1108,A,A,0,13.5199,100,130,165551,281351122,13.1099,100,1,13.5099,15,1,13.0099,2,1,13.5199,100,1,12.9800,200,2,13.5299,15,1,12.8599,100,1,13.8200,2,1,12.7300,100,1,13.8599,100,1,12.7100,100,1,14.2500,100,1,12.5000,700,1,14.2699,700,1,12.4600,100,1,14.2799,100,1,12.4299,700,1,14.3300,100,1,12.4199,700,1,14.4800,700,1,ARL,338044041
2268,2025-07-17T16:12:03.068301745Z,2025-07-17T16:12:03.068301745Z,10,2,1108,C,B,0,13.0099,2,0,165401,281351235,13.1099,100,1,13.5099,15,1,12.9800,200,2,13.5199,100,1,12.8599,100,1,13.5299,15,1,12.7300,100,1,13.8200,2,1,12.7100,100,1,13.8599,100,1,12.5000,700,1,14.2500,100,1,12.4600,100,1,14.2699,700,1,12.4299,700,1,14.2799,100,1,12.4199,700,1,14.3300,100,1,12.3699,700,1,14.4800,700,1,ARL,332494213
2269,2025-07-17T16:12:03.068301745Z,2025-07-17T16:12:03.068301745Z,10,2,1108,A,B,0,12.9199,2,130,165401,281351235,13.1099,100,1,13.5099,15,1,12.9800,200,2,13.5199,100,1,12.9199,2,1,13.5299,15,1,12.8599,100,1,13.8200,2,1,12.7300,100,1,13.8599,100,1,12.7100,100,1,14.2500,100,1,12.5000,700,1,14.2699,700,1,12.4600,100,1,14.2799,100,1,12.4299,700,1,14.3300,100,1,12.4199,700,1,14.4800,700,1,ARL,338044113
2270,2025-07-17T16:12:03.075034550Z,2025-07-17T16:12:03.075034550Z,10,2,1108,C,A,0,13.8599,100,130,165488,281351372,13.1099,100,1,13.5099,15,1,12.9800,200,2,13.5199,100,1,12.9199,2,1,13.5299,15,1,12.8599,100,1,13.8200,2,1,12.7300,100,1,14.2500,100,1,12.7100,100,1,14.2699,700,1,12.5000,700,1,14.2799,100,1,12.4600,100,1,14.3300,100,1,12.4299,700,1,14.4800,700,1,12.4199,700,1,14.4900,200,2,ARL,336567333
2271,2025-07-17T16:12:03.075095341Z,2025-07-17T16:12:03.075095341Z,10,2,1108,A,A,0,13.7899,100,130,165188,281351373,13.1099,100,1,13.5099,15,1,12.9800,200,2,13.5199,100,1,12.9199,2,1,13.5299,15,1,12.8599,100,1,13.7899,100,1,12.7300,100,1,13.8200,2,1,12.7100,100,1,14.2500,100,1,12.5000,700,1,14.2699,700,1,12.4600,100,1,14.2799,100,1,12.4299,700,1,14.3300,100,1,12.4199,700,1,14.4800,700,1,ARL,338044233
2272,2025-07-17T16:12:06.775011783Z,2025-07-17T16:12:06.775011783Z,10,2,1108,C,A,0,14.5099,100,0,165854,281422697,13.1099,100,1,13.5099,15,1,12.9800,200,2,13.5199,100,1,12.9199,2,1,13.5299,15,1,12.8599,100,1,13.7899,100,1,12.7300,100,1,13.8200,2,1,12.7100,100,1,14.2500,100,1,12.5000,700,1,14.2699,700,1,12.4600,100,1,14.2799,100,1,12.4299,700,1,14.3300,100,1,12.4199,700,1,14.4800,700,1,ARL,336259225
2273,2025-07-17T16:12:06.775011783Z,2025-07-17T16:12:06.775011783Z,10,2,1108,A,A,0,14.4000,100,130,165854,281422697,13.1099,100,1,13.5099,15,1,12.9800,200,2,13.5199,100,1,12.9199,2,1,13.5299,15,1,12.8599,100,1,13.7899,100,1,12.7300,100,1,13.8200,2,1,12.7100,100,1,14.2500,100,1,12.5000,700,1,14.2699,700,1,12.4600,100,1,14.2799,100,1,12.4299,700,1,14.3300,100,1,12.4199,700,1,14.4000,100,1,ARL,338139585
2274,2025-07-17T16:12:06.775449017Z,2025-07-17T16:12:06.775449017Z,10,2,1108,C,A,0,14.5099,100,0,165519,281422702,13.1099,100,1,13.5099,15,1,12.9800,200,2,13.5199,100,1,12.9199,2,1,13.5299,15,1,12.8599,100,1,13.7899,100,1,12.7300,100,1,13.8200,2,1,12.7100,100,1,14.2500,100,1,12.5000,700,1,14.2699,700,1,12.4600,100,1,14.2799,100,1,12.4299,700,1,14.3300,100,1,12.4199,700,1,14.4000,100,1,ARL,336261905
2275,2025-07-17T16:12:06.775449017Z,2025-07-17T16:12:06.775449017Z,10,2,1108,A,A,0,14.4000,100,130,165519,281422702,13.1099,100,1,13.5099,15,1,12.9800,200,2,13.5199,100,1,12.9199,2,1,13.5299,15,1,12.8599,100,1,13.7899,100,1,12.7300,100,1,13.8200,2,1,12.7100,100,1,14.2500,100,1,12.5000,700,1,14.2699,700,1,12.4600,100,1,14.2799,100,1,12.4299,700,1,14.3300,100,1,12.4199,700,1,14.4000,200,2,ARL,338139601
2276,2025-07-17T16:12:06.779540143Z,2025-07-17T16:12:06.779540143Z,10,2,1108,C,A,0,13.5299,15,130,165574,281422782,13.1099,100,1,13.5099,15,1,12.9800,200,2,13.5199,100,1,12.9199,2,1,13.7899,100,1,12.8599,100,1,13.8200,2,1,12.7300,100,1,14.2500,100,1,12.7100,100,1,14.2699,700,1,12.5000,700,1,14.2799,100,1,12.4600,100,1,14.3300,100,1,12.4299,700,1,14.4000,200,2,12.4199,700,1,14.4800,700,1,ARL,337772837
2277,2025-07-17T16:12:07.784533539Z,2025-07-17T16:12:07.784533539Z,10,2,1108,A,A,0,13.4900,15,130,165354,281443568,13.1099,100,1,13.4900,15,1,12.9800,200,2,13.5099,15,1,12.9199,2,1,13.5199,100,1,12.8599,100,1,13.7899,100,1,12.7300,100,1,13.8200,2,1,12.7100,100,1,14.2500,100,1,12.5000,700,1,14.2699,700,1,12.4600,100,1,14.2799,100,1,12.4299,700,1,14.3300,100,1,12.4199,700,1,14.4000,200,2,ARL,338167057
2278,2025-07-17T16:12:08.585029039Z,2025-07-17T16:12:08.585029039Z,10,2,1108,C,A,0,13.5199,100,0,165546,281451898,13.1099,100,1,13.4900,15,1,12.9800,200,2,13.5099,15,1,12.9199,2,1,13.7899,100,1,12.8599,100,1,13.8200,2,1,12.7300,100,1,14.2500,100,1,12.7100,100,1,14.2699,700,1,12.5000,700,1,14.2799,100,1,12.4600,100,1,14.3300,100,1,12.4299,700,1,14.4000,200,2,12.4199,700,1,14.4800,700,1,ARL,338044041
2279,2025-07-17T16:12:08.585029039Z,2025-07-17T16:12:08.585029039Z,10,2,1108,A,A,0,13.5000,100,130,165546,281451898,13.1099,100,1,13.4900,15,1,12.9800,200,2,13.5000,100,1,12.9199,2,1,13.5099,15,1,12.8599,100,1,13.7899,100,1,12.7300,100,1,13.8200,2,1,12.7100,100,1,14.2500,100,1,12.5000,700,1,14.2699,700,1,12.4600,100,1,14.2799,100,1,12.4299,700,1,14.3300,100,1,12.4199,700,1,14.4000,200,2,ARL,338180793
2280,2025-07-17T16:12:08.585776508Z,2025-07-17T16:12:08.585776508Z,10,2,1108,C,A,0,14.5899,100,0,165541,281451903,13.1099,100,1,13.4900,15,1,12.9800,200,2,13.5000,100,1,12.9199,2,1,13.5099,15,1,12.8599,100,1,13.7899,100,1,12.7300,100,1,13.8200,2,1,12.7100,100,1,14.2500,100,1,12.5000,700,1,14.2699,700,1,12.4600,100,1,14.2799,100,1,12.4299,700,1,14.3300,100,1,12.4199,700,1,14.4000,200,2,ARL,337790737
2281,2025-07-17T16:12:08.585776508Z,2025-07-17T16:12:08.585776508Z,10,2,1108,A,A,0,14.5500,100,130,165541,281451903,13.1099,100,1,13.4900,15,1,12.9800,200,2,13.5000,100,1,12.9199,2,1,13.5099,15,1,12.8599,100,1,13.7899,100,1,12.7300,100,1,13.8200,2,1,12.7100,100,1,14.2500,100,1,12.5000,700,1,14.2699,700,1,12.4600,100,1,14.2799,100,1,12.4299,700,1,14.3300,100,1,12.4199,700,1,14.4000,200,2,ARL,338180841
2282,2025-07-17T16:12:18.789756367Z,2025-07-17T16:12:18.789756367Z,10,2,1108,C,A,0,13.8200,2,0,165655,281613266,13.1099,100,1,13.4900,15,1,12.9800,200,2,13.5000,100,1,12.9199,2,1,13.5099,15,1,12.8599,100,1,13.7899,100,1,12.7300,100,1,14.2500,100,1,12.7100,100,1,14.2699,700,1,12.5000,700,1,14.2799,100,1,12.4600,100,1,14.3300,100,1,12.4299,700,1,14.4000,200,2,12.4199,700,1,14.4800,700,1,ARL,336447325
2283,2025-07-17T16:12:18.789756367Z,2025-07-17T16:12:18.789756367Z,10,2,1108,A,A,0,13.7400,2,130,165655,281613266,13.1099,100,1,13.4900,15,1,12.9800,200,2,13.5000,100,1,12.9199,2,1,13.5099,15,1,12.8599,100,1,13.7400,2,1,12.7300,100,1,13.7899,100,1,12.7100,100,1,14.2500,100,1,12.5000,700,1,14.2699,700,1,12.4600,100,1,14.2799,100,1,12.4299,700,1,14.3300,100,1,12.4199,700,1,14.4000,200,2,ARL,338371797
2284,2025-07-17T16:12:19.370820933Z,2025-07-17T16:12:19.370820933Z,10,2,1108,A,A,0,14.2699,700,130,165471,281622545,13.1099,100,1,13.4900,15,1,12.9800,200,2,13.5000,100,1,12.9199,2,1,13.5099,15,1,12.8599,100,1,13.7400,2,1,12.7300,100,1,13.7899,100,1,12.7100,100,1,14.2500,100,1,12.5000,700,1,14.2699,1400,2,12.4600,100,1,14.2799,100,1,12.4299,700,1,14.3300,100,1,12.4199,700,1,14.4000,200,2,ARL,338382329
2285,2025-07-17T16:12:19.370875240Z,2025-07-17T16:12:19.370875240Z,10,2,1108,C,A,0,14.5999,700,130,165809,281622547,13.1099,100,1,13.4900,15,1,12.9800,200,2,13.5000,100,1,12.9199,2,1,13.5099,15,1,12.8599,100,1,13.7400,2,1,12.7300,100,1,13.7899,100,1,12.7100,100,1,14.2500,100,1,12.5000,700,1,14.2699,1400,2,12.4600,100,1,14.2799,100,1,12.4299,700,1,14.3300,100,1,12.4199,700,1,14.4000,200,2,ARL,282920685
2286,2025-07-17T16:12:19.696521343Z,2025-07-17T16:12:19.696521343Z,10,2,1108,C,A,0,13.4900,15,128,168375,281630053,13.1099,100,1,13.5000,100,1,12.9800,200,2,13.5099,15,1,12.9199,2,1,13.7400,2,1,12.8599,100,1,13.7899,100,1,12.7300,100,1,14.2500,100,1,12.7100,100,1,14.2699,1400,2,12.5000,700,1,14.2799,100,1,12.4600,100,1,14.3300,100,1,12.4299,700,1,14.4000,200,2,12.4199,700,1,14.4800,700,1,ARL,338167057
2287,2025-07-17T16:12:19.711591494Z,2025-07-17T16:12:19.711591494Z,10,2,1108,C,A,0,13.5099,15,128,181870,281634812,13.1099,100,1,13.5000,100,1,12.9800,200,2,13.7400,2,1,12.9199,2,1,13.7899,100,1,12.8599,100,1,14.2500,100,1,12.7300,100,1,14.2699,1400,2,12.7100,100,1,14.2799,100,1,12.5000,700,1,14.3300,100,1,12.4600,100,1,14.4000,200,2,12.4299,700,1,14.4800,700,1,12.4199,700,1,14.4900,200,2,ARL,338041605
2288,2025-07-17T16:12:32.761112078Z,2025-07-17T16:12:32.761112078Z,10,2,1108,A,A,0,13.4800,15,130,165346,281880398,13.1099,100,1,13.4800,15,1,12.9800,200,2,13.5000,100,1,12.9199,2,1,13.7400,2,1,12.8599,100,1,13.7899,100,1,12.7300,100,1,14.2500,100,1,12.7100,100,1,14.2699,1400,2,12.5000,700,1,14.2799,100,1,12.4600,100,1,14.3300,100,1,12.4299,700,1,14.4000,200,2,12.4199,700,1,14.4800,700,1,ARL,338707945
2289,2025-07-17T16:12:32.761246859Z,2025-07-17T16:12:32.761246859Z,10,2,1108,C,A,0,13.5000,100,0,166343,281880409,13.1099,100,1,13.4800,15,1,12.9800,200,2,13.7400,2,1,12.9199,2,1,13.7899,100,1,12.8599,100,1,14.2500,100,1,12.7300,100,1,14.2699,1400,2,12.7100,100,1,14.2799,100,1,12.5000,700,1,14.3300,100,1,12.4600,100,1,14.4000,200,2,12.4299,700,1,14.4800,700,1,12.4199,700,1,14.4900,200,2,ARL,338180793
2290,2025-07-17T16:12:32.761246859Z,2025-07-17T16:12:32.761246859Z,10,2,1108,A,A,0,13.4900,100,130,166343,281880409,13.1099,100,1,13.4800,15,1,12.9800,200,2,13.4900,100,1,12.9199,2,1,13.7400,2,1,12.8599,100,1,13.7899,100,1,12.7300,100,1,14.2500,100,1,12.7100,100,1,14.2699,1400,2,12.5000,700,1,14.2799,100,1,12.4600,100,1,14.3300,100,1,12.4299,700,1,14.4000,200,2,12.4199,700,1,14.4800,700,1,ARL,338707949
2291,2025-07-17T16:12:32.778890447Z,2025-07-17T16:12:32.778890447Z,10,2,1108,C,A,0,15.1199,100,0,165549,281880579,13.1099,100,1,13.4800,15,1,12.9800,200,2,13.4900,100,1,12.9199,2,1,13.7400,2,1,12.8599,100,1,13.7899,100,1,12.7300,100,1,14.2500,100,1,12.7100,100,1,14.2699,1400,2,12.5000,700,1,14.2799,100,1,12.4600,100,1,14.3300,100,1,12.4299,700,1,14.4000,200,2,12.4199,700,1,14.4800,700,1,ARL,296387089
2292,2025-07-17T16:12:32.778890447Z,2025-07-17T16:12:32.778890447Z,10,2,1108,A,A,0,14.8399,100,130,165549,281880579,13.1099,100,1,13.4800,15,1,12.9800,200,2,13.4900,100,1,12.9199,2,1,13.7400,2,1,12.8599,100,1,13.7899,100,1,12.7300,100,1,14.2500,100,1,12.7100,100,1,14.2699,1400,2,12.5000,700,1,14.2799,100,1,12.4600,100,1,14.3300,100,1,12.4299,700,1,14.4000,200,2,12.4199,700,1,14.4800,700,1,ARL,338708241
2293,2025-07-17T16:12:32.804152457Z,2025-07-17T16:12:32.804152457Z,10,2,1108,A,A,0,15.3800,100,130,165548,281880972,13.1099,100,1,13.4800,15,1,12.9800,200,2,13.4900,100,1,12.9199,2,1,13.7400,2,1,12.8599,100,1,13.7899,100,1,12.7300,100,1,14.2500,100,1,12.7100,100,1,14.2699,1400,2,12.5000,700,1,14.2799,100,1,12.4600,100,1,14.3300,100,1,12.4299,700,1,14.4000,200,2,12.4199,700,1,14.4800,700,1,ARL,338709513
2294,2025-07-17T16:12:32.804166092Z,2025-07-17T16:12:32.804166092Z,10,2,1108,C,A,0,15.6600,100,130,166494,281880973,13.1099,100,1,13.4800,15,1,12.9800,200,2,13.4900,100,1,12.9199,2,1,13.7400,2,1,12.8599,100,1,13.7899,100,1,12.7300,100,1,14.2500,100,1,12.7100,100,1,14.2699,1400,2,12.5000,700,1,14.2799,100,1,12.4600,100,1,14.3300,100,1,12.4299,700,1,14.4000,200,2,12.4199,700,1,14.4800,700,1,ARL,326730513
2295,2025-07-17T16:12:40.992898990Z,2025-07-17T16:12:40.992898990Z,10,2,1108,C,A,0,13.4900,100,130,165306,282007871,13.1099,100,1,13.4800,15,1,12.9800,200,2,13.7400,2,1,12.9199,2,1,13.7899,100,1,12.8599,100,1,14.2500,100,1,12.7300,100,1,14.2699,1400,2,12.7100,100,1,14.2799,100,1,12.5000,700,1,14.3300,100,1,12.4600,100,1,14.4000,200,2,12.4299,700,1,14.4800,700,1,12.4199,700,1,14.4900,200,2,ARL,338707949
2296,2025-07-17T16:12:40.993167418Z,2025-07-17T16:12:40.993167418Z,10,2,1108,C,A,0,14.2699,700,130,165246,282007875,13.1099,100,1,13.4800,15,1,12.9800,200,2,13.7400,2,1,12.9199,2,1,13.7899,100,1,12.8599,100,1,14.2500,100,1,12.7300,100,1,14.2699,700,1,12.7100,100,1,14.2799,100,1,12.5000,700,1,14.3300,100,1,12.4600,100,1,14.4000,200,2,12.4299,700,1,14.4800,700,1,12.4199,700,1,14.4900,200,2,ARL,338382329
2297,2025-07-17T16:12:40.993168470Z,2025-07-17T16:12:40.993168470Z,10,2,1108,C,A,0,14.2699,700,130,165320,282007876,13.1099,100,1,13.4800,15,1,12.9800,200,2,13.7400,2,1,12.9199,2,1,13.7899,100,1,12.8599,100,1,14.2500,100,1,12.7300,100,1,14.2799,100,1,12.7100,100,1,14.3300,100,1,12.5000,700,1,14.4000,200,2,12.4600,100,1,14.4800,700,1,12.4299,700,1,14.4900,200,2,12.4199,700,1,14.5500,100,1,ARL,336747457
2298,2025-07-17T16:12:40.993214193Z,2025-07-17T16:12:40.993214193Z,10,2,1108,A,A,0,14.5399,700,130,165433,282007877,13.1099,100,1,13.4800,15,1,12.9800,200,2,13.7400,2,1,12.9199,2,1,13.7899,100,1,12.8599,100,1,14.2500,100,1,12.7300,100,1,14.2799,100,1,12.7100,100,1,14.3300,100,1,12.5000,700,1,14.4000,200,2,12.4600,100,1,14.4800,700,1,12.4299,700,1,14.4900,200,2,12.4199,700,1,14.5399,700,1,ARL,338864169
2299,2025-07-17T16:12:40.993227993Z,2025-07-17T16:12:40.993227993Z,10,2,1108,A,A,0,14.4700,700,130,165447,282007878,13.1099,100,1,13.4800,15,1,12.9800,200,2,13.7400,2,1,12.9199,2,1,13.7899,100,1,12.8599,100,1,14.2500,100,1,12.7300,100,1,14.2799,100,1,12.7100,100,1,14.3300,100,1,12.5000,700,1,14.4000,200,2,12.4600,100,1,14.4700,700,1,12.4299,700,1,14.4800,700,1,12.4199,700,1,14.4900,200,2,ARL,338864173
2300,2025-07-17T16:12:40.993266591Z,2025-07-17T16:12:40.993266591Z,10,2,1108,A,A,0,15.7100,100,130,165524,282007879,13.1099,100,1,13.4800,15,1,12.9800,200,2,13.7400,2,1,12.9199,2,1,13.7899,100,1,12.8599,100,1,14.2500,100,1,12.7300,100,1,14.2799,100,1,12.7100,100,1,14.3300,100,1,12.5000,700,1,14.4000,200,2,12.4600,100,1,14.4700,700,1,12.4299,700,1,14.4800,700,1,12.4199,700,1,14.4900,200,2,ARL,338864177
2301,2025-07-17T16:12:40.993279810Z,2025-07-17T16:12:40.993279810Z,10,2,1108,C,A,0,15.3800,100,130,165232,282007880,13.1099,100,1,13.4800,15,1,12.9800,200,2,13.7400,2,1,12.9199,2,1,13.7899,100,1,12.8599,100,1,14.2500,100,1,12.7300,100,1,14.2799,100,1,12.7100,100,1,14.3300,100,1,12.5000,700,1,14.4000,200,2,12.4600,100,1,14.4700,700,1,12.4299,700,1,14.4800,700,1,12.4199,700,1,14.4900,200,2,ARL,338709513
2302,2025-07-17T16:12:40.993652511Z,2025-07-17T16:12:40.993652511Z,10,2,1108,C,A,0,14.5500,100,0,165619,282007882,13.1099,100,1,13.4800,15,1,12.9800,200,2,13.7400,2,1,12.9199,2,1,13.7899,100,1,12.8599,100,1,14.2500,100,1,12.7300,100,1,14.2799,100,1,12.7100,100,1,14.3300,100,1,12.5000,700,1,14.4000,200,2,12.4600,100,1,14.4700,700,1,12.4299,700,1,14.4800,700,1,12.4199,700,1,14.4900,200,2,ARL,338180841
2303,2025-07-17T16:12:40.993652511Z,2025-07-17T16:12:40.993652511Z,10,2,1108,A,A,0,14.8499,100,130,165619,282007882,13.1099,100,1,13.4800,15,1,12.9800,200,2,13.7400,2,1,12.9199,2,1,13.7899,100,1,12.8599,100,1,14.2500,100,1,12.7300,100,1,14.2799,100,1,12.7100,100,1,14.3300,100,1,12.5000,700,1,14.4000,200,2,12.4600,100,1,14.4700,700,1,12.4299,700,1,14.4800,700,1,12.4199,700,1,14.4900,200,2,ARL,338864189
2304,2025-07-17T16:12:40.994617858Z,2025-07-17T16:12:40.994617858Z,10,2,1108,C,A,0,14.4900,100,0,165439,282007892,13.1099,100,1,13.4800,15,1,12.9800,200,2,13.7400,2,1,12.9199,2,1,13.7899,100,1,12.8599,100,1,14.2500,100,1,12.7300,100,1,14.2799,100,1,12.7100,100,1,14.3300,100,1,12.5000,700,1,14.4000,200,2,12.4600,100,1,14.4700,700,1,12.4299,700,1,14.4800,700,1,12.4199,700,1,14.4900,100,1,ARL,337790745
2305,2025-07-17T16:12:40.994617858Z,2025-07-17T16:12:40.994617858Z,10,2,1108,A,A,0,14.7599,100,130,165439,282007892,13.1099,100,1,13.4800,15,1,12.9800,200,2,13.7400,2,1,12.9199,2,1,13.7899,100,1,12.8599,100,1,14.2500,100,1,12.7300,100,1,14.2799,100,1,12.7100,100,1,14.3300,100,1,12.5000,700,1,14.4000,200,2,12.4600,100,1,14.4700,700,1,12.4299,700,1,14.4800,700,1,12.4199,700,1,14.4900,100,1,ARL,338864217
2306,2025-07-17T16:12:40.994913404Z,2025-07-17T16:12:40.994913404Z,10,2,1108,C,A,0,14.8399,100,0,165452,282007894,13.1099,100,1,13.4800,15,1,12.9800,200,2,13.7400,2,1,12.9199,2,1,13.7899,100,1,12.8599,100,1,14.2500,100,1,12.7300,100,1,14.2799,100,1,12.7100,100,1,14.3300,100,1,12.5000,700,1,14.4000,200,2,12.4600,100,1,14.4700,700,1,12.4299,700,1,14.4800,700,1,12.4199,700,1,14.4900,100,1,ARL,338708241
2307,2025-07-17T16:12:40.994913404Z,2025-07-17T16:12:40.994913404Z,10,2,1108,A,A,0,15.1699,100,130,165452,282007894,13.1099,100,1,13.4800,15,1,12.9800,200,2,13.7400,2,1,12.9199,2,1,13.7899,100,1,12.8599,100,1,14.2500,100,1,12.7300,100,1,14.2799,100,1,12.7100,100,1,14.3300,100,1,12.5000,700,1,14.4000,200,2,12.4600,100,1,14.4700,700,1,12.4299,700,1,14.4800,700,1,12.4199,700,1,14.4900,100,1,ARL,338864221
2308,2025-07-17T16:12:40.995183768Z,2025-07-17T16:12:40.995183768Z,10,2,1108,C,A,0,15.5999,100,0,165535,282007898,13.1099,100,1,13.4800,15,1,12.9800,200,2,13.7400,2,1,12.9199,2,1,13.7899,100,1,12.8599,100,1,14.2500,100,1,12.7300,100,1,14.2799,100,1,12.7100,100,1,14.3300,100,1,12.5000,700,1,14.4000,200,2,12.4600,100,1,14.4700,700,1,12.4299,700,1,14.4800,700,1,12.4199,700,1,14.4900,100,1,ARL,337690641
2309,2025-07-17T16:12:40.995183768Z,2025-07-17T16:12:40.995183768Z,10,2,1108,A,A,0,15.8599,100,130,165535,282007898,13.1099,100,1,13.4800,15,1,12.9800,200,2,13.7400,2,1,12.9199,2,1,13.7899,100,1,12.8599,100,1,14.2500,100,1,12.7300,100,1,14.2799,100,1,12.7100,100,1,14.3300,100,1,12.5000,700,1,14.4000,200,2,12.4600,100,1,14.4700,700,1,12.4299,700,1,14.4800,700,1,12.4199,700,1,14.4900,100,1,ARL,338864245
2310,2025-07-17T16:12:40.996294601Z,2025-07-17T16:12:40.996294601Z,10,2,1108,C,A,0,17.2600,100,0,165479,282007909,13.1099,100,1,13.4800,15,1,12.9800,200,2,13.7400,2,1,12.9199,2,1,13.7899,100,1,12.8599,100,1,14.2500,100,1,12.7300,100,1,14.2799,100,1,12.7100,100,1,14.3300,100,1,12.5000,700,1,14.4000,200,2,12.4600,100,1,14.4700,700,1,12.4299,700,1,14.4800,700,1,12.4199,700,1,14.4900,100,1,ARL,336570921
2311,2025-07-17T16:12:40.996294601Z,2025-07-17T16:12:40.996294601Z,10,2,1108,A,A,0,17.5199,100,130,165479,282007909,13.1099,100,1,13.4800,15,1,12.9800,200,2,13.7400,2,1,12.9199,2,1,13.7899,100,1,12.8599,100,1,14.2500,100,1,12.7300,100,1,14.2799,100,1,12.7100,100,1,14.3300,100,1,12.5000,700,1,14.4000,200,2,12.4600,100,1,14.4700,700,1,12.4299,700,1,14.4800,700,1,12.4199,700,1,14.4900,100,1,ARL,338864289
2312,2025-07-17T16:12:40.997135307Z,2025-07-17T16:12:40.997135307Z,10,2,1108,C,A,0,14.3300,100,130,165393,282007914,13.1099,100,1,13.4800,15,1,12.9800,200,2,13.7400,2,1,12.9199,2,1,13.7899,100,1,12.8599,100,1,14.2500,100,1,12.7300,100,1,14.2799,100,1,12.7100,100,1,14.4000,200,2,12.5000,700,1,14.4700,700,1,12.4600,100,1,14.4800,700,1,12.4299,700,1,14.4900,100,1,12.4199,700,1,14.5399,700,1,ARL,337790761
2313,2025-07-17T16:12:40.997257014Z,2025-07-17T16:12:40.997257014Z,10,2,1108,A,A,0,14.5800,100,130,165342,282007916,13.1099,100,1,13.4800,15,1,12.9800,200,2,13.7400,2,1,12.9199,2,1,13.7899,100,1,12.8599,100,1,14.2500,100,1,12.7300,100,1,14.2799,100,1,12.7100,100,1,14.4000,200,2,12.5000,700,1,14.4700,700,1,12.4600,100,1,14.4800,700,1,12.4299,700,1,14.4900,100,1,12.4199,700,1,14.5399,700,1,ARL,338864317
2314,2025-07-17T16:12:41.004063876Z,2025-07-17T16:12:41.004063876Z,10,2,1108,C,A,0,14.4900,100,0,165746,282007959,13.1099,100,1,13.4800,15,1,12.9800,200,2,13.7400,2,1,12.9199,2,1,13.7899,100,1,12.8599,100,1,14.2500,100,1,12.7300,100,1,14.2799,100,1,12.7100,100,1,14.4000,200,2,12.5000,700,1,14.4700,700,1,12.4600,100,1,14.4800,700,1,12.4299,700,1,14.5399,700,1,12.4199,700,1,14.5600,800,2,ARL,337790777
2315,2025-07-17T16:12:41.004063876Z,2025-07-17T16:12:41.004063876Z,10,2,1108,A,A,0,14.7599,100,130,165746,282007959,13.1099,100,1,13.4800,15,1,12.9800,200,2,13.7400,2,1,12.9199,2,1,13.7899,100,1,12.8599,100,1,14.2500,100,1,12.7300,100,1,14.2799,100,1,12.7100,100,1,14.4000,200,2,12.5000,700,1,14.4700,700,1,12.4600,100,1,14.4800,700,1,12.4299,700,1,14.5399,700,1,12.4199,700,1,14.5600,800,2,ARL,338864405
2316,2025-07-17T16:12:41.005406614Z,2025-07-17T16:12:41.005406614Z,10,2,1108,A,A,0,13.4900,100,128,169439,282008256,13.1099,100,1,13.4800,15,1,12.9800,200,2,13.4900,100,1,12.9199,2,1,13.7400,2,1,12.8599,100,1,13.7899,100,1,12.7300,100,1,14.2500,100,1,12.7100,100,1,14.2799,100,1,12.5000,700,1,14.4000,200,2,12.4600,100,1,14.4700,700,1,12.4299,700,1,14.4800,700,1,12.4199,700,1,14.5399,700,1,ARL,338864581
2317,2025-07-17T16:12:41.010473041Z,2025-07-17T16:12:41.010473041Z,10,2,1108,C,A,0,14.7599,100,0,165310,282008884,13.1099,100,1,13.4800,15,1,12.9800,200,2,13.4900,100,1,12.9199,2,1,13.7400,2,1,12.8599,100,1,13.7899,100,1,12.7300,100,1,14.2500,100,1,12.7100,100,1,14.2799,100,1,12.5000,700,1,14.4000,200,2,12.4600,100,1,14.4700,700,1,12.4299,700,1,14.4800,700,1,12.4199,700,1,14.5399,700,1,ARL,338864405
2318,2025-07-17T16:12:41.010473041Z,2025-07-17T16:12:41.010473041Z,10,2,1108,A,A,0,14.4399,100,130,165310,282008884,13.1099,100,1,13.4800,15,1,12.9800,200,2,13.4900,100,1,12.9199,2,1,13.7400,2,1,12.8599,100,1,13.7899,100,1,12.7300,100,1,14.2500,100,1,12.7100,100,1,14.2799,100,1,12.5000,700,1,14.4000,200,2,12.4600,100,1,14.4399,100,1,12.4299,700,1,14.4700,700,1,12.4199,700,1,14.4800,700,1,ARL,338865133
2319,2025-07-17T16:12:41.010994859Z,2025-07-17T16:12:41.010994859Z,10,2,1108,C,A,0,13.7899,100,130,165482,282008914,13.1099,100,1,13.4800,15,1,12.9800,200,2,13.4900,100,1,12.9199,2,1,13.7400,2,1,12.8599,100,1,14.2500,100,1,12.7300,100,1,14.2799,100,1,12.7100,100,1,14.4000,200,2,12.5000,700,1,14.4399,100,1,12.4600,100,1,14.4700,700,1,12.4299,700,1,14.4800,700,1,12.4199,700,1,14.5399,700,1,ARL,338044233
2320,2025-07-17T16:12:41.011046717Z,2025-07-17T16:12:41.011046717Z,10,2,1108,A,A,0,14.0600,100,130,165269,282008916,13.1099,100,1,13.4800,15,1,12.9800,200,2,13.4900,100,1,12.9199,2,1,13.7400,2,1,12.8599,100,1,14.0600,100,1,12.7300,100,1,14.2500,100,1,12.7100,100,1,14.2799,100,1,12.5000,700,1,14.4000,200,2,12.4600,100,1,14.4399,100,1,12.4299,700,1,14.4700,700,1,12.4199,700,1,14.4800,700,1,ARL,338865141
2321,2025-07-17T16:12:41.011390077Z,2025-07-17T16:12:41.011390077Z,10,2,1108,C,A,0,14.7599,100,0,165265,282008942,13.1099,100,1,13.4800,15,1,12.9800,200,2,13.4900,100,1,12.9199,2,1,13.7400,2,1,12.8599,100,1,14.0600,100,1,12.7300,100,1,14.2500,100,1,12.7100,100,1,14.2799,100,1,12.5000,700,1,14.4000,200,2,12.4600,100,1,14.4399,100,1,12.4299,700,1,14.4700,700,1,12.4199,700,1,14.4800,700,1,ARL,338864217
2322,2025-07-17T16:12:41.011390077Z,2025-07-17T16:12:41.011390077Z,10,2,1108,A,A,0,14.4399,100,130,165265,282008942,13.1099,100,1,13.4800,15,1,12.9800,200,2,13.4900,100,1,12.9199,2,1,13.7400,2,1,12.8599,100,1,14.0600,100,1,12.7300,100,1,14.2500,100,1,12.7100,100,1,14.2799,100,1,12.5000,700,1,14.4000,200,2,12.4600,100,1,14.4399,200,2,12.4299,700,1,14.4700,700,1,12.4199,700,1,14.4800,700,1,ARL,338865165
2323,2025-07-17T16:12:41.011879795Z,2025-07-17T16:12:41.011879795Z,10,2,1108,C,A,0,14.0600,100,130,165124,282008953,13.1099,100,1,13.4800,15,1,12.9800,200,2,13.4900,100,1,12.9199,2,1,13.7400,2,1,12.8599,100,1,14.2500,100,1,12.7300,100,1,14.2799,100,1,12.7100,100,1,14.4000,200,2,12.5000,700,1,14.4399,200,2,12.4600,100,1,14.4700,700,1,12.4299,700,1,14.4800,700,1,12.4199,700,1,14.5399,700,1,ARL,338865141
2324,2025-07-17T16:12:41.011929033Z,2025-07-17T16:12:41.011929033Z,10,2,1108,A,A,0,13.7599,100,130,165461,282008954,13.1099,100,1,13.4800,15,1,12.9800,200,2,13.4900,100,1,12.9199,2,1,13.7400,2,1,12.8599,100,1,13.7599,100,1,12.7300,100,1,14.2500,100,1,12.7100,100,1,14.2799,100,1,12.5000,700,1,14.4000,200,2,12.4600,100,1,14.4399,200,2,12.4299,700,1,14.4700,700,1,12.4199,700,1,14.4800,700,1,ARL,338865177
2325,2025-07-17T16:12:41.014809197Z,2025-07-17T16:12:41.014809197Z,10,2,1108,C,A,0,17.5199,100,0,165294,282008990,13.1099,100,1,13.4800,15,1,12.9800,200,2,13.4900,100,1,12.9199,2,1,13.7400,2,1,12.8599,100,1,13.7599,100,1,12.7300,100,1,14.2500,100,1,12.7100,100,1,14.2799,100,1,12.5000,700,1,14.4000,200,2,12.4600,100,1,14.4399,200,2,12.4299,700,1,14.4700,700,1,12.4199,700,1,14.4800,700,1,ARL,338864289
2326,2025-07-17T16:12:41.014809197Z,2025-07-17T16:12:41.014809197Z,10,2,1108,A,A,0,17.1400,100,130,165294,282008990,13.1099,100,1,13.4800,15,1,12.9800,200,2,13.4900,100,1,12.9199,2,1,13.7400,2,1,12.8599,100,1,13.7599,100,1,12.7300,100,1,14.2500,100,1,12.7100,100,1,14.2799,100,1,12.5000,700,1,14.4000,200,2,12.4600,100,1,14.4399,200,2,12.4299,700,1,14.4700,700,1,12.4199,700,1,14.4800,700,1,ARL,338865253
2327,2025-07-17T16:12:41.017672033Z,2025-07-17T16:12:41.017672033Z,10,2,1108,C,A,0,15.8599,100,0,165345,282009053,13.1099,100,1,13.4800,15,1,12.9800,200,2,13.4900,100,1,12.9199,2,1,13.7400,2,1,12.8599,100,1,13.7599,100,1,12.7300,100,1,14.2500,100,1,12.7100,100,1,14.2799,100,1,12.5000,700,1,14.4000,200,2,12.4600,100,1,14.4399,200,2,12.4299,700,1,14.4700,700,1,12.4199,700,1,14.4800,700,1,ARL,338864245
2328,2025-07-17T16:12:41.017672033Z,2025-07-17T16:12:41.017672033Z,10,2,1108,A,A,0,15.5199,100,130,165345,282009053,13.1099,100,1,13.4800,15,1,12.9800,200,2,13.4900,100,1,12.9199,2,1,13.7400,2,1,12.8599,100,1,13.7599,100,1,12.7300,100,1,14.2500,100,1,12.7100,100,1,14.2799,100,1,12.5000,700,1,14.4000,200,2,12.4600,100,1,14.4399,200,2,12.4299,700,1,14.4700,700,1,12.4199,700,1,14.4800,700,1,ARL,338865301
2329,2025-07-17T16:12:41.032105565Z,2025-07-17T16:12:41.032105565Z,10,2,1108,C,A,0,15.1699,100,0,165252,282009412,13.1099,100,1,13.4800,15,1,12.9800,200,2,13.4900,100,1,12.9199,2,1,13.7400,2,1,12.8599,100,1,13.7599,100,1,12.7300,100,1,14.2500,100,1,12.7100,100,1,14.2799,100,1,12.5000,700,1,14.4000,200,2,12.4600,100,1,14.4399,200,2,12.4299,700,1,14.4700,700,1,12.4199,700,1,14.4800,700,1,ARL,338864221
2330,2025-07-17T16:12:41.032105565Z,2025-07-17T16:12:41.032105565Z,10,2,1108,A,A,0,14.8399,100,130,165252,282009412,13.1099,100,1,13.4800,15,1,12.9800,200,2,13.4900,100,1,12.9199,2,1,13.7400,2,1,12.8599,100,1,13.7599,100,1,12.7300,100,1,14.2500,100,1,12.7100,100,1,14.2799,100,1,12.5000,700,1,14.4000,200,2,12.4600,100,1,14.4399,200,2,12.4299,700,1,14.4700,700,1,12.4199,700,1,14.4800,700,1,ARL,338866081
2331,2025-07-17T16:12:41.032147083Z,2025-07-17T16:12:41.032147083Z,10,2,1108,A,A,0,15.3800,100,130,165337,282009414,13.1099,100,1,13.4800,15,1,12.9800,200,2,13.4900,100,1,12.9199,2,1,13.7400,2,1,12.8599,100,1,13.7599,100,1,12.7300,100,1,14.2500,100,1,12.7100,100,1,14.2799,100,1,12.5000,700,1,14.4000,200,2,12.4600,100,1,14.4399,200,2,12.4299,700,1,14.4700,700,1,12.4199,700,1,14.4800,700,1,ARL,338866089
2332,2025-07-17T16:12:41.032159348Z,2025-07-17T16:12:41.032159348Z,10,2,1108,C,A,0,15.7100,100,130,165090,282009415,13.1099,100,1,13.4800,15,1,12.9800,200,2,13.4900,100,1,12.9199,2,1,13.7400,2,1,12.8599,100,1,13.7599,100,1,12.7300,100,1,14.2500,100,1,12.7100,100,1,14.2799,100,1,12.5000,700,1,14.4000,200,2,12.4600,100,1,14.4399,200,2,12.4299,700,1,14.4700,700,1,12.4199,700,1,14.4800,700,1,ARL,338864177
2333,2025-07-17T16:12:41.043241012Z,2025-07-17T16:12:41.043241012Z,10,2,1108,C,A,0,14.8499,100,0,165371,282009482,13.1099,100,1,13.4800,15,1,12.9800,200,2,13.4900,100,1,12.9199,2,1,13.7400,2,1,12.8599,100,1,13.7599,100,1,12.7300,100,1,14.2500,100,1,12.7100,100,1,14.2799,100,1,12.5000,700,1,14.4000,200,2,12.4600,100,1,14.4399,200,2,12.4299,700,1,14.4700,700,1,12.4199,700,1,14.4800,700,1,ARL,338864189
2334,2025-07-17T16:12:41.043241012Z,2025-07-17T16:12:41.043241012Z,10,2,1108,A,A,0,14.5399,100,130,165371,282009482,13.1099,100,1,13.4800,15,1,12.9800,200,2,13.4900,100,1,12.9199,2,1,13.7400,2,1,12.8599,100,1,13.7599,100,1,12.7300,100,1,14.2500,100,1,12.7100,100,1,14.2799,100,1,12.5000,700,1,14.4000,200,2,12.4600,100,1,14.4399,200,2,12.4299,700,1,14.4700,700,1,12.4199,700,1,14.4800,700,1,ARL,338866245
2335,2025-07-17T16:12:42.001182016Z,2025-07-17T16:12:42.001182016Z,10,2,1108,C,A,0,14.5800,100,0,165828,282033913,13.1099,100,1,13.4800,15,1,12.9800,200,2,13.4900,100,1,12.9199,2,1,13.7400,2,1,12.8599,100,1,13.7599,100,1,12.7300,100,1,14.2500,100,1,12.7100,100,1,14.2799,100,1,12.5000,700,1,14.4000,200,2,12.4600,100,1,14.4399,200,2,12.4299,700,1,14.4700,700,1,12.4199,700,1,14.4800,700,1,ARL,338864317
2336,2025-07-17T16:12:42.001182016Z,2025-07-17T16:12:42.001182016Z,10,2,1108,A,A,0,14.2799,100,130,165828,282033913,13.1099,100,1,13.4800,15,1,12.9800,200,2,13.4900,100,1,12.9199,2,1,13.7400,2,1,12.8599,100,1,13.7599,100,1,12.7300,100,1,14.2500,100,1,12.7100,100,1,14.2799,200,2,12.5000,700,1,14.4000,200,2,12.4600,100,1,14.4399,200,2,12.4299,700,1,14.4700,700,1,12.4199,700,1,14.4800,700,1,ARL,338894329
2337,2025-07-17T16:12:42.761989222Z,2025-07-17T16:12:42.761989222Z,10,2,1108,A,A,0,13.4600,15,130,165247,282042242,13.1099,100,1,13.4600,15,1,12.9800,200,2,13.4800,15,1,12.9199,2,1,13.4900,100,1,12.8599,100,1,13.7400,2,1,12.7300,100,1,13.7599,100,1,12.7100,100,1,14.2500,100,1,12.5000,700,1,14.2799,200,2,12.4600,100,1,14.4000,200,2,12.4299,700,1,14.4399,200,2,12.4199,700,1,14.4700,700,1,ARL,338904977
2338,2025-07-17T16:12:43.021951997Z,2025-07-17T16:12:43.021951997Z,10,2,1108,C,A,0,13.4900,100,0,175905,282057719,13.1099,100,1,13.4600,15,1,12.9800,200,2,13.4800,15,1,12.9199,2,1,13.7400,2,1,12.8599,100,1,13.7599,100,1,12.7300,100,1,14.2500,100,1,12.7100,100,1,14.2799,200,2,12.5000,700,1,14.4000,200,2,12.4600,100,1,14.4399,200,2,12.4299,700,1,14.4700,700,1,12.4199,700,1,14.4800,700,1,ARL,338864581
2339,2025-07-17T16:12:43.021951997Z,2025-07-17T16:12:43.021951997Z,10,2,1108,A,A,0,13.4700,100,128,175905,282057719,13.1099,100,1,13.4600,15,1,12.9800,200,2,13.4700,100,1,12.9199,2,1,13.4800,15,1,12.8599,100,1,13.7400,2,1,12.7300,100,1,13.7599,100,1,12.7100,100,1,14.2500,100,1,12.5000,700,1,14.2799,200,2,12.4600,100,1,14.4000,200,2,12.4299,700,1,14.4399,200,2,12.4199,700,1,14.4700,700,1,ARL,338918217
2340,2025-07-17T16:12:43.022444956Z,2025-07-17T16:12:43.022444956Z,10,2,1108,A,A,0,15.6899,100,128,167221,282058085,13.1099,100,1,13.4600,15,1,12.9800,200,2,13.4700,100,1,12.9199,2,1,13.4800,15,1,12.8599,100,1,13.7400,2,1,12.7300,100,1,13.7599,100,1,12.7100,100,1,14.2500,100,1,12.5000,700,1,14.2799,200,2,12.4600,100,1,14.4000,200,2,12.4299,700,1,14.4399,200,2,12.4199,700,1,14.4700,700,1,ARL,338918553
2341,2025-07-17T16:12:43.022461725Z,2025-07-17T16:12:43.022461725Z,10,2,1108,C,A,0,15.3800,100,130,165867,282058088,13.1099,100,1,13.4600,15,1,12.9800,200,2,13.4700,100,1,12.9199,2,1,13.4800,15,1,12.8599,100,1,13.7400,2,1,12.7300,100,1,13.7599,100,1,12.7100,100,1,14.2500,100,1,12.5000,700,1,14.2799,200,2,12.4600,100,1,14.4000,200,2,12.4299,700,1,14.4399,200,2,12.4199,700,1,14.4700,700,1,ARL,338866089
2342,2025-07-17T16:12:43.049119139Z,2025-07-17T16:12:43.049119139Z,10,2,1108,A,A,0,15.3599,100,130,165216,282065940,13.1099,100,1,13.4600,15,1,12.9800,200,2,13.4700,100,1,12.9199,2,1,13.4800,15,1,12.8599,100,1,13.7400,2,1,12.7300,100,1,13.7599,100,1,12.7100,100,1,14.2500,100,1,12.5000,700,1,14.2799,200,2,12.4600,100,1,14.4000,200,2,12.4299,700,1,14.4399,200,2,12.4199,700,1,14.4700,700,1,ARL,338926929
2343,2025-07-17T16:12:43.049132842Z,2025-07-17T16:12:43.049132842Z,10,2,1108,C,A,0,15.6899,100,128,166147,282065943,13.1099,100,1,13.4600,15,1,12.9800,200,2,13.4700,100,1,12.9199,2,1,13.4800,15,1,12.8599,100,1,13.7400,2,1,12.7300,100,1,13.7599,100,1,12.7100,100,1,14.2500,100,1,12.5000,700,1,14.2799,200,2,12.4600,100,1,14.4000,200,2,12.4299,700,1,14.4399,200,2,12.4199,700,1,14.4700,700,1,ARL,338918553
2344,2025-07-17T16:12:43.154787212Z,2025-07-17T16:12:43.154787212Z,10,2,1108,A,A,0,14.2699,100,130,165163,282073056,13.1099,100,1,13.4600,15,1,12.9800,200,2,13.4700,100,1,12.9199,2,1,13.4800,15,1,12.8599,100,1,13.7400,2,1,12.7300,100,1,13.7599,100,1,12.7100,100,1,14.2500,100,1,12.5000,700,1,14.2699,100,1,12.4600,100,1,14.2799,200,2,12.4299,700,1,14.4000,200,2,12.4199,700,1,14.4399,200,2,ARL,338932853
2345,2025-07-17T16:12:43.154800020Z,2025-07-17T16:12:43.154800020Z,10,2,1108,C,A,0,14.5600,100,130,165163,282073058,13.1099,100,1,13.4600,15,1,12.9800,200,2,13.4700,100,1,12.9199,2,1,13.4800,15,1,12.8599,100,1,13.7400,2,1,12.7300,100,1,13.7599,100,1,12.7100,100,1,14.2500,100,1,12.5000,700,1,14.2699,100,1,12.4600,100,1,14.2799,200,2,12.4299,700,1,14.4000,200,2,12.4199,700,1,14.4399,200,2,ARL,296391881
2346,2025-07-17T16:12:43.915387059Z,2025-07-17T16:12:43.915387059Z,10,2,1108,C,A,0,14.2799,100,130,165467,282085822,13.1099,100,1,13.4600,15,1,12.9800,200,2,13.4700,100,1,12.9199,2,1,13.4800,15,1,12.8599,100,1,13.7400,2,1,12.7300,100,1,13.7599,100,1,12.7100,100,1,14.2500,100,1,12.5000,700,1,14.2699,100,1,12.4600,100,1,14.2799,100,1,12.4299,700,1,14.4000,200,2,12.4199,700,1,14.4399,200,2,ARL,302681357
2347,2025-07-17T16:12:43.915389642Z,2025-07-17T16:12:43.915389642Z,10,2,1108,A,A,0,14.0000,100,130,165698,282085823,13.1099,100,1,13.4600,15,1,12.9800,200,2,13.4700,100,1,12.9199,2,1,13.4800,15,1,12.8599,100,1,13.7400,2,1,12.7300,100,1,13.7599,100,1,12.7100,100,1,14.0000,100,1,12.5000,700,1,14.2500,100,1,12.4600,100,1,14.2699,100,1,12.4299,700,1,14.2799,100,1,12.4199,700,1,14.4000,200,2,ARL,338945933
2348,2025-07-17T16:12:50.729079105Z,2025-07-17T16:12:50.729079105Z,10,2,1108,C,A,0,13.4600,15,130,165344,282168721,13.1099,100,1,13.4700,100,1,12.9800,200,2,13.4800,15,1,12.9199,2,1,13.7400,2,1,12.8599,100,1,13.7599,100,1,12.7300,100,1,14.0000,100,1,12.7100,100,1,14.2500,100,1,12.5000,700,1,14.2699,100,1,12.4600,100,1,14.2799,100,1,12.4299,700,1,14.4000,200,2,12.4199,700,1,14.4399,200,2,ARL,338904977
2349,2025-07-17T16:12:50.729252907Z,2025-07-17T16:12:50.729252907Z,10,2,1108,C,A,0,13.4800,15,130,165330,282168744,13.1099,100,1,13.4700,100,1,12.9800,200,2,13.7400,2,1,12.9199,2,1,13.7599,100,1,12.8599,100,1,14.0000,100,1,12.7300,100,1,14.2500,100,1,12.7100,100,1,14.2699,100,1,12.5000,700,1,14.2799,100,1,12.4600,100,1,14.4000,200,2,12.4299,700,1,14.4399,200,2,12.4199,700,1,14.4700,700,1,ARL,338707945
2350,2025-07-17T16:12:50.729409745Z,2025-07-17T16:12:50.729409745Z,10,2,1108,A,A,0,13.4700,96,130,165996,282168754,13.1099,100,1,13.4700,196,2,12.9800,200,2,13.7400,2,1,12.9199,2,1,13.7599,100,1,12.8599,100,1,14.0000,100,1,12.7300,100,1,14.2500,100,1,12.7100,100,1,14.2699,100,1,12.5000,700,1,14.2799,100,1,12.4600,100,1,14.4000,200,2,12.4299,700,1,14.4399,200,2,12.4199,700,1,14.4700,700,1,ARL,339054149
2351,2025-07-17T16:12:53.021749348Z,2025-07-17T16:12:53.021749348Z,10,2,1108,A,A,0,13.4600,15,130,165304,282194154,13.1099,100,1,13.4600,15,1,12.9800,200,2,13.4700,196,2,12.9199,2,1,13.7400,2,1,12.8599,100,1,13.7599,100,1,12.7300,100,1,14.0000,100,1,12.7100,100,1,14.2500,100,1,12.5000,700,1,14.2699,100,1,12.4600,100,1,14.2799,100,1,12.4299,700,1,14.4000,200,2,12.4199,700,1,14.4399,200,2,ARL,339096733
2352,2025-07-17T16:12:53.021793735Z,2025-07-17T16:12:53.021793735Z,10,2,1108,C,A,0,13.4700,100,130,165406,282194157,13.1099,100,1,13.4600,15,1,12.9800,200,2,13.4700,96,1,12.9199,2,1,13.7400,2,1,12.8599,100,1,13.7599,100,1,12.7300,100,1,14.0000,100,1,12.7100,100,1,14.2500,100,1,12.5000,700,1,14.2699,100,1,12.4600,100,1,14.2799,100,1,12.4299,700,1,14.4000,200,2,12.4199,700,1,14.4399,200,2,ARL,338918217
2353,2025-07-17T16:12:53.022064745Z,2025-07-17T16:12:53.022064745Z,10,2,1108,C,A,0,13.4700,96,130,165377,282194159,13.1099,100,1,13.4600,15,1,12.9800,200,2,13.7400,2,1,12.9199,2,1,13.7599,100,1,12.8599,100,1,14.0000,100,1,12.7300,100,1,14.2500,100,1,12.7100,100,1,14.2699,100,1,12.5000,700,1,14.2799,100,1,12.4600,100,1,14.4000,200,2,12.4299,700,1,14.4399,200,2,12.4199,700,1,14.4700,700,1,ARL,339054149
2354,2025-07-17T16:12:53.022406202Z,2025-07-17T16:12:53.022406202Z,10,2,1108,A,A,0,15.6899,100,130,165821,282194161,13.1099,100,1,13.4600,15,1,12.9800,200,2,13.7400,2,1,12.9199,2,1,13.7599,100,1,12.8599,100,1,14.0000,100,1,12.7300,100,1,14.2500,100,1,12.7100,100,1,14.2699,100,1,12.5000,700,1,14.2799,100,1,12.4600,100,1,14.4000,200,2,12.4299,700,1,14.4399,200,2,12.4199,700,1,14.4700,700,1,ARL,339096757
2355,2025-07-17T16:12:53.022418950Z,2025-07-17T16:12:53.022418950Z,10,2,1108,C,A,0,15.3599,100,130,165314,282194162,13.1099,100,1,13.4600,15,1,12.9800,200,2,13.7400,2,1,12.9199,2,1,13.7599,100,1,12.8599,100,1,14.0000,100,1,12.7300,100,1,14.2500,100,1,12.7100,100,1,14.2699,100,1,12.5000,700,1,14.2799,100,1,12.4600,100,1,14.4000,200,2,12.4299,700,1,14.4399,200,2,12.4199,700,1,14.4700,700,1,ARL,338926929
2356,2025-07-17T16:12:53.022797046Z,2025-07-17T16:12:53.022797046Z,10,2,1108,C,A,0,14.5399,100,0,165894,282194167,13.1099,100,1,13.4600,15,1,12.9800,200,2,13.7400,2,1,12.9199,2,1,13.7599,100,1,12.8599,100,1,14.0000,100,1,12.7300,100,1,14.2500,100,1,12.7100,100,1,14.2699,100,1,12.5000,700,1,14.2799,100,1,12.4600,100,1,14.4000,200,2,12.4299,700,1,14.4399,200,2,12.4199,700,1,14.4700,700,1,ARL,338866245
2357,2025-07-17T16:12:53.022797046Z,2025-07-17T16:12:53.022797046Z,10,2,1108,A,A,0,14.8300,100,130,165894,282194167,13.1099,100,1,13.4600,15,1,12.9800,200,2,13.7400,2,1,12.9199,2,1,13.7599,100,1,12.8599,100,1,14.0000,100,1,12.7300,100,1,14.2500,100,1,12.7100,100,1,14.2699,100,1,12.5000,700,1,14.2799,100,1,12.4600,100,1,14.4000,200,2,12.4299,700,1,14.4399,200,2,12.4199,700,1,14.4700,700,1,ARL,339096773
2358,2025-07-17T16:12:53.023423468Z,2025-07-17T16:12:53.023423468Z,10,2,1108,C,A,0,14.4399,100,0,166062,282194181,13.1099,100,1,13.4600,15,1,12.9800,200,2,13.7400,2,1,12.9199,2,1,13.7599,100,1,12.8599,100,1,14.0000,100,1,12.7300,100,1,14.2500,100,1,12.7100,100,1,14.2699,100,1,12.5000,700,1,14.2799,100,1,12.4600,100,1,14.4000,200,2,12.4299,700,1,14.4399,100,1,12.4199,700,1,14.4700,700,1,ARL,338865165
2359,2025-07-17T16:12:53.023423468Z,2025-07-17T16:12:53.023423468Z,10,2,1108,A,A,0,14.7300,100,130,166062,282194181,13.1099,100,1,13.4600,15,1,12.9800,200,2,13.7400,2,1,12.9199,2,1,13.7599,100,1,12.8599,100,1,14.0000,100,1,12.7300,100,1,14.2500,100,1,12.7100,100,1,14.2699,100,1,12.5000,700,1,14.2799,100,1,12.4600,100,1,14.4000,200,2,12.4299,700,1,14.4399,100,1,12.4199,700,1,14.4700,700,1,ARL,339096797
2360,2025-07-17T16:12:53.023903582Z,2025-07-17T16:12:53.023903582Z,10,2,1108,C,A,0,17.1400,100,0,165571,282194183,13.1099,100,1,13.4600,15,1,12.9800,200,2,13.7400,2,1,12.9199,2,1,13.7599,100,1,12.8599,100,1,14.0000,100,1,12.7300,100,1,14.2500,100,1,12.7100,100,1,14.2699,100,1,12.5000,700,1,14.2799,100,1,12.4600,100,1,14.4000,200,2,12.4299,700,1,14.4399,100,1,12.4199,700,1,14.4700,700,1,ARL,338865253
2361,2025-07-17T16:12:53.023903582Z,2025-07-17T16:12:53.023903582Z,10,2,1108,A,A,0,17.4800,100,130,165571,282194183,13.1099,100,1,13.4600,15,1,12.9800,200,2,13.7400,2,1,12.9199,2,1,13.7599,100,1,12.8599,100,1,14.0000,100,1,12.7300,100,1,14.2500,100,1,12.7100,100,1,14.2699,100,1,12.5000,700,1,14.2799,100,1,12.4600,100,1,14.4000,200,2,12.4299,700,1,14.4399,100,1,12.4199,700,1,14.4700,700,1,ARL,339096809
2362,2025-07-17T16:12:53.025418159Z,2025-07-17T16:12:53.025418159Z,10,2,1108,C,A,0,14.8399,100,0,165625,282194188,13.1099,100,1,13.4600,15,1,12.9800,200,2,13.7400,2,1,12.9199,2,1,13.7599,100,1,12.8599,100,1,14.0000,100,1,12.7300,100,1,14.2500,100,1,12.7100,100,1,14.2699,100,1,12.5000,700,1,14.2799,100,1,12.4600,100,1,14.4000,200,2,12.4299,700,1,14.4399,100,1,12.4199,700,1,14.4700,700,1,ARL,338866081
2363,2025-07-17T16:12:53.025418159Z,2025-07-17T16:12:53.025418159Z,10,2,1108,A,A,0,15.1400,100,130,165625,282194188,13.1099,100,1,13.4600,15,1,12.9800,200,2,13.7400,2,1,12.9199,2,1,13.7599,100,1,12.8599,100,1,14.0000,100,1,12.7300,100,1,14.2500,100,1,12.7100,100,1,14.2699,100,1,12.5000,700,1,14.2799,100,1,12.4600,100,1,14.4000,200,2,12.4299,700,1,14.4399,100,1,12.4199,700,1,14.4700,700,1,ARL,339096813
2364,2025-07-17T16:12:53.025486466Z,2025-07-17T16:12:53.025486466Z,10,2,1108,C,A,0,14.4399,100,0,165517,282194189,13.1099,100,1,13.4600,15,1,12.9800,200,2,13.7400,2,1,12.9199,2,1,13.7599,100,1,12.8599,100,1,14.0000,100,1,12.7300,100,1,14.2500,100,1,12.7100,100,1,14.2699,100,1,12.5000,700,1,14.2799,100,1,12.4600,100,1,14.4000,200,2,12.4299,700,1,14.4700,700,1,12.4199,700,1,14.4800,700,1,ARL,338865133
2365,2025-07-17T16:12:53.025486466Z,2025-07-17T16:12:53.025486466Z,10,2,1108,A,A,0,14.7300,100,130,165517,282194189,13.1099,100,1,13.4600,15,1,12.9800,200,2,13.7400,2,1,12.9199,2,1,13.7599,100,1,12.8599,100,1,14.0000,100,1,12.7300,100,1,14.2500,100,1,12.7100,100,1,14.2699,100,1,12.5000,700,1,14.2799,100,1,12.4600,100,1,14.4000,200,2,12.4299,700,1,14.4700,700,1,12.4199,700,1,14.4800,700,1,ARL,339096817
2366,2025-07-17T16:12:53.027549524Z,2025-07-17T16:12:53.027549524Z,10,2,1108,C,A,0,14.2799,100,130,165502,282194224,13.1099,100,1,13.4600,15,1,12.9800,200,2,13.7400,2,1,12.9199,2,1,13.7599,100,1,12.8599,100,1,14.0000,100,1,12.7300,100,1,14.2500,100,1,12.7100,100,1,14.2699,100,1,12.5000,700,1,14.4000,200,2,12.4600,100,1,14.4700,700,1,12.4299,700,1,14.4800,700,1,12.4199,700,1,14.5399,700,1,ARL,338894329
2367,2025-07-17T16:12:53.027701439Z,2025-07-17T16:12:53.027701439Z,10,2,1108,A,A,0,14.5500,100,130,165338,282194226,13.1099,100,1,13.4600,15,1,12.9800,200,2,13.7400,2,1,12.9199,2,1,13.7599,100,1,12.8599,100,1,14.0000,100,1,12.7300,100,1,14.2500,100,1,12.7100,100,1,14.2699,100,1,12.5000,700,1,14.4000,200,2,12.4600,100,1,14.4700,700,1,12.4299,700,1,14.4800,700,1,12.4199,700,1,14.5399,700,1,ARL,339096833
2368,2025-07-17T16:12:53.027821450Z,2025-07-17T16:12:53.027821450Z,10,2,1108,C,A,0,15.5199,100,0,165580,282194228,13.1099,100,1,13.4600,15,1,12.9800,200,2,13.7400,2,1,12.9199,2,1,13.7599,100,1,12.8599,100,1,14.0000,100,1,12.7300,100,1,14.2500,100,1,12.7100,100,1,14.2699,100,1,12.5000,700,1,14.4000,200,2,12.4600,100,1,14.4700,700,1,12.4299,700,1,14.4800,700,1,12.4199,700,1,14.5399,700,1,ARL,338865301
2369,2025-07-17T16:12:53.027821450Z,2025-07-17T16:12:53.027821450Z,10,2,1108,A,A,0,15.8300,100,130,165580,282194228,13.1099,100,1,13.4600,15,1,12.9800,200,2,13.7400,2,1,12.9199,2,1,13.7599,100,1,12.8599,100,1,14.0000,100,1,12.7300,100,1,14.2500,100,1,12.7100,100,1,14.2699,100,1,12.5000,700,1,14.4000,200,2,12.4600,100,1,14.4700,700,1,12.4299,700,1,14.4800,700,1,12.4199,700,1,14.5399,700,1,ARL,339096837
2370,2025-07-17T16:12:53.033101265Z,2025-07-17T16:12:53.033101265Z,10,2,1108,C,A,0,13.7599,100,130,165272,282194348,13.1099,100,1,13.4600,15,1,12.9800,200,2,13.7400,2,1,12.9199,2,1,14.0000,100,1,12.8599,100,1,14.2500,100,1,12.7300,100,1,14.2699,100,1,12.7100,100,1,14.4000,200,2,12.5000,700,1,14.4700,700,1,12.4600,100,1,14.4800,700,1,12.4299,700,1,14.5399,700,1,12.4199,700,1,14.5500,100,1,ARL,338865177
2371,2025-07-17T16:12:53.033137644Z,2025-07-17T16:12:53.033137644Z,10,2,1108,C,A,0,14.4700,700,130,165204,282194349,13.1099,100,1,13.4600,15,1,12.9800,200,2,13.7400,2,1,12.9199,2,1,14.0000,100,1,12.8599,100,1,14.2500,100,1,12.7300,100,1,14.2699,100,1,12.7100,100,1,14.4000,200,2,12.5000,700,1,14.4800,700,1,12.4600,100,1,14.5399,700,1,12.4299,700,1,14.5500,100,1,12.4199,700,1,14.5600,700,1,ARL,338864173
2372,2025-07-17T16:12:53.033153612Z,2025-07-17T16:12:53.033153612Z,10,2,1108,A,A,0,14.0399,100,130,165206,282194350,13.1099,100,1,13.4600,15,1,12.9800,200,2,13.7400,2,1,12.9199,2,1,14.0000,100,1,12.8599,100,1,14.0399,100,1,12.7300,100,1,14.2500,100,1,12.7100,100,1,14.2699,100,1,12.5000,700,1,14.4000,200,2,12.4600,100,1,14.4800,700,1,12.4299,700,1,14.5399,700,1,12.4199,700,1,14.5500,100,1,ARL,339096893
2373,2025-07-17T16:12:53.033183560Z,2025-07-17T16:12:53.033183560Z,10,2,1108,A,A,0,14.6799,700,130,165763,282194351,13.1099,100,1,13.4600,15,1,12.9800,200,2,13.7400,2,1,12.9199,2,1,14.0000,100,1,12.8599,100,1,14.0399,100,1,12.7300,100,1,14.2500,100,1,12.7100,100,1,14.2699,100,1,12.5000,700,1,14.4000,200,2,12.4600,100,1,14.4800,700,1,12.4299,700,1,14.5399,700,1,12.4199,700,1,14.5500,100,1,ARL,339096897
2374,2025-07-17T16:12:53.033596046Z,2025-07-17T16:12:53.033596046Z,10,2,1108,C,A,0,13.7400,2,0,166026,282194354,13.1099,100,1,13.4600,15,1,12.9800,200,2,14.0000,100,1,12.9199,2,1,14.0399,100,1,12.8599,100,1,14.2500,100,1,12.7300,100,1,14.2699,100,1,12.7100,100,1,14.4000,200,2,12.5000,700,1,14.4800,700,1,12.4600,100,1,14.5399,700,1,12.4299,700,1,14.5500,100,1,12.4199,700,1,14.5600,700,1,ARL,338371797
2375,2025-07-17T16:12:53.033596046Z,2025-07-17T16:12:53.033596046Z,10,2,1108,A,A,0,13.9800,2,130,166026,282194354,13.1099,100,1,13.4600,15,1,12.9800,200,2,13.9800,2,1,12.9199,2,1,14.0000,100,1,12.8599,100,1,14.0399,100,1,12.7300,100,1,14.2500,100,1,12.7100,100,1,14.2699,100,1,12.5000,700,1,14.4000,200,2,12.4600,100,1,14.4800,700,1,12.4299,700,1,14.5399,700,1,12.4199,700,1,14.5500,100,1,ARL,339096909
2376,2025-07-17T16:12:53.033835120Z,2025-07-17T16:12:53.033835120Z,10,2,1108,C,A,0,14.2500,100,130,165526,282194360,13.1099,100,1,13.4600,15,1,12.9800,200,2,13.9800,2,1,12.9199,2,1,14.0000,100,1,12.8599,100,1,14.0399,100,1,12.7300,100,1,14.2699,100,1,12.7100,100,1,14.4000,200,2,12.5000,700,1,14.4800,700,1,12.4600,100,1,14.5399,700,1,12.4299,700,1,14.5500,100,1,12.4199,700,1,14.5600,700,1,ARL,336161365
2377,2025-07-17T16:12:53.033977054Z,2025-07-17T16:12:53.033977054Z,10,2,1108,C,A,0,14.7300,100,0,165417,282194361,13.1099,100,1,13.4600,15,1,12.9800,200,2,13.9800,2,1,12.9199,2,1,14.0000,100,1,12.8599,100,1,14.0399,100,1,12.7300,100,1,14.2699,100,1,12.7100,100,1,14.4000,200,2,12.5000,700,1,14.4800,700,1,12.4600,100,1,14.5399,700,1,12.4299,700,1,14.5500,100,1,12.4199,700,1,14.5600,700,1,ARL,339096797
2378,2025-07-17T16:12:53.033977054Z,2025-07-17T16:12:53.033977054Z,10,2,1108,A,A,0,14.9600,100,130,165417,282194361,13.1099,100,1,13.4600,15,1,12.9800,200,2,13.9800,2,1,12.9199,2,1,14.0000,100,1,12.8599,100,1,14.0399,100,1,12.7300,100,1,14.2699,100,1,12.7100,100,1,14.4000,200,2,12.5000,700,1,14.4800,700,1,12.4600,100,1,14.5399,700,1,12.4299,700,1,14.5500,100,1,12.4199,700,1,14.5600,700,1,ARL,339096917
2379,2025-07-17T16:12:53.034012618Z,2025-07-17T16:12:53.034012618Z,10,2,1108,C,A,0,15.8300,100,0,165558,282194362,13.1099,100,1,13.4600,15,1,12.9800,200,2,13.9800,2,1,12.9199,2,1,14.0000,100,1,12.8599,100,1,14.0399,100,1,12.7300,100,1,14.2699,100,1,12.7100,100,1,14.4000,200,2,12.5000,700,1,14.4800,700,1,12.4600,100,1,14.5399,700,1,12.4299,700,1,14.5500,100,1,12.4199,700,1,14.5600,700,1,ARL,339096837
2380,2025-07-17T16:12:53.034012618Z,2025-07-17T16:12:53.034012618Z,10,2,1108,A,A,0,16.0799,100,130,165558,282194362,13.1099,100,1,13.4600,15,1,12.9800,200,2,13.9800,2,1,12.9199,2,1,14.0000,100,1,12.8599,100,1,14.0399,100,1,12.7300,100,1,14.2699,100,1,12.7100,100,1,14.4000,200,2,12.5000,700,1,14.4800,700,1,12.4600,100,1,14.5399,700,1,12.4299,700,1,14.5500,100,1,12.4199,700,1,14.5600,700,1,ARL,339096921
2381,2025-07-17T16:12:53.034187864Z,2025-07-17T16:12:53.034187864Z,10,2,1108,A,A,0,14.5999,100,130,165276,282194365,13.1099,100,1,13.4600,15,1,12.9800,200,2,13.9800,2,1,12.9199,2,1,14.0000,100,1,12.8599,100,1,14.0399,100,1,12.7300,100,1,14.2699,100,1,12.7100,100,1,14.4000,200,2,12.5000,700,1,14.4800,700,1,12.4600,100,1,14.5399,700,1,12.4299,700,1,14.5500,100,1,12.4199,700,1,14.5600,700,1,ARL,339096925
2382,2025-07-17T16:12:53.035246187Z,2025-07-17T16:12:53.035246187Z,10,2,1108,C,A,0,15.0500,100,0,165561,282194373,13.1099,100,1,13.4600,15,1,12.9800,200,2,13.9800,2,1,12.9199,2,1,14.0000,100,1,12.8599,100,1,14.0399,100,1,12.7300,100,1,14.2699,100,1,12.7100,100,1,14.4000,200,2,12.5000,700,1,14.4800,700,1,12.4600,100,1,14.5399,700,1,12.4299,700,1,14.5500,100,1,12.4199,700,1,14.5600,700,1,ARL,335220549
2383,2025-07-17T16:12:53.035246187Z,2025-07-17T16:12:53.035246187Z,10,2,1108,A,A,0,15.3800,100,130,165561,282194373,13.1099,100,1,13.4600,15,1,12.9800,200,2,13.9800,2,1,12.9199,2,1,14.0000,100,1,12.8599,100,1,14.0399,100,1,12.7300,100,1,14.2699,100,1,12.7100,100,1,14.4000,200,2,12.5000,700,1,14.4800,700,1,12.4600,100,1,14.5399,700,1,12.4299,700,1,14.5500,100,1,12.4199,700,1,14.5600,700,1,ARL,339096929
2384,2025-07-17T16:12:53.036142164Z,2025-07-17T16:12:53.036142164Z,10,2,1108,C,A,0,17.4800,100,0,165218,282194381,13.1099,100,1,13.4600,15,1,12.9800,200,2,13.9800,2,1,12.9199,2,1,14.0000,100,1,12.8599,100,1,14.0399,100,1,12.7300,100,1,14.2699,100,1,12.7100,100,1,14.4000,200,2,12.5000,700,1,14.4800,700,1,12.4600,100,1,14.5399,700,1,12.4299,700,1,14.5500,100,1,12.4199,700,1,14.5600,700,1,ARL,339096809
2385,2025-07-17T16:12:53.036142164Z,2025-07-17T16:12:53.036142164Z,10,2,1108,A,A,0,17.7600,100,130,165218,282194381,13.1099,100,1,13.4600,15,1,12.9800,200,2,13.9800,2,1,12.9199,2,1,14.0000,100,1,12.8599,100,1,14.0399,100,1,12.7300,100,1,14.2699,100,1,12.7100,100,1,14.4000,200,2,12.5000,700,1,14.4800,700,1,12.4600,100,1,14.5399,700,1,12.4299,700,1,14.5500,100,1,12.4199,700,1,14.5600,700,1,ARL,339096949
2386,2025-07-17T16:12:53.039879965Z,2025-07-17T16:12:53.039879965Z,10,2,1108,C,A,0,14.7300,100,0,165252,282194416,13.1099,100,1,13.4600,15,1,12.9800,200,2,13.9800,2,1,12.9199,2,1,14.0000,100,1,12.8599,100,1,14.0399,100,1,12.7300,100,1,14.2699,100,1,12.7100,100,1,14.4000,200,2,12.5000,700,1,14.4800,700,1,12.4600,100,1,14.5399,700,1,12.4299,700,1,14.5500,100,1,12.4199,700,1,14.5600,700,1,ARL,339096817
2387,2025-07-17T16:12:53.039879965Z,2025-07-17T16:12:53.039879965Z,10,2,1108,A,A,0,14.9600,100,130,165252,282194416,13.1099,100,1,13.4600,15,1,12.9800,200,2,13.9800,2,1,12.9199,2,1,14.0000,100,1,12.8599,100,1,14.0399,100,1,12.7300,100,1,14.2699,100,1,12.7100,100,1,14.4000,200,2,12.5000,700,1,14.4800,700,1,12.4600,100,1,14.5399,700,1,12.4299,700,1,14.5500,100,1,12.4199,700,1,14.5600,700,1,ARL,339096977
2388,2025-07-17T16:12:53.043562198Z,2025-07-17T16:12:53.043562198Z,10,2,1108,C,A,0,14.0399,100,130,165027,282194436,13.1099,100,1,13.4600,15,1,12.9800,200,2,13.9800,2,1,12.9199,2,1,14.0000,100,1,12.8599,100,1,14.2699,100,1,12.7300,100,1,14.4000,200,2,12.7100,100,1,14.4800,700,1,12.5000,700,1,14.5399,700,1,12.4600,100,1,14.5500,100,1,12.4299,700,1,14.5600,700,1,12.4199,700,1,14.5999,100,1,ARL,339096893
2389,2025-07-17T16:12:53.043610101Z,2025-07-17T16:12:53.043610101Z,10,2,1108,A,A,0,14.2599,100,130,165198,282194438,13.1099,100,1,13.4600,15,1,12.9800,200,2,13.9800,2,1,12.9199,2,1,14.0000,100,1,12.8599,100,1,14.2599,100,1,12.7300,100,1,14.2699,100,1,12.7100,100,1,14.4000,200,2,12.5000,700,1,14.4800,700,1,12.4600,100,1,14.5399,700,1,12.4299,700,1,14.5500,100,1,12.4199,700,1,14.5600,700,1,ARL,339097005
2390,2025-07-17T16:12:53.072887133Z,2025-07-17T16:12:53.072887133Z,10,2,1108,C,A,0,14.8300,100,0,165464,282194725,13.1099,100,1,13.4600,15,1,12.9800,200,2,13.9800,2,1,12.9199,2,1,14.0000,100,1,12.8599,100,1,14.2599,100,1,12.7300,100,1,14.2699,100,1,12.7100,100,1,14.4000,200,2,12.5000,700,1,14.4800,700,1,12.4600,100,1,14.5399,700,1,12.4299,700,1,14.5500,100,1,12.4199,700,1,14.5600,700,1,ARL,339096773
2391,2025-07-17T16:12:53.072887133Z,2025-07-17T16:12:53.072887133Z,10,2,1108,A,A,0,15.0600,100,130,165464,282194725,13.1099,100,1,13.4600,15,1,12.9800,200,2,13.9800,2,1,12.9199,2,1,14.0000,100,1,12.8599,100,1,14.2599,100,1,12.7300,100,1,14.2699,100,1,12.7100,100,1,14.4000,200,2,12.5000,700,1,14.4800,700,1,12.4600,100,1,14.5399,700,1,12.4299,700,1,14.5500,100,1,12.4199,700,1,14.5600,700,1,ARL,339097245
2392,2025-07-17T16:12:53.332564148Z,2025-07-17T16:12:53.332564148Z,10,2,1108,C,A,0,14.0000,100,130,165339,282196976,13.1099,100,1,13.4600,15,1,12.9800,200,2,13.9800,2,1,12.9199,2,1,14.2599,100,1,12.8599,100,1,14.2699,100,1,12.7300,100,1,14.4000,200,2,12.7100,100,1,14.4800,700,1,12.5000,700,1,14.5399,700,1,12.4600,100,1,14.5500,100,1,12.4299,700,1,14.5600,700,1,12.4199,700,1,14.5999,100,1,ARL,338945933
2393,2025-07-17T16:12:53.332565150Z,2025-07-17T16:12:53.332565150Z,10,2,1108,A,A,0,14.5299,100,130,165358,282196977,13.1099,100,1,13.4600,15,1,12.9800,200,2,13.9800,2,1,12.9199,2,1,14.2599,100,1,12.8599,100,1,14.2699,100,1,12.7300,100,1,14.4000,200,2,12.7100,100,1,14.4800,700,1,12.5000,700,1,14.5299,100,1,12.4600,100,1,14.5399,700,1,12.4299,700,1,14.5500,100,1,12.4199,700,1,14.5600,700,1,ARL,339100477
2394,2025-07-17T16:12:53.587623157Z,2025-07-17T16:12:53.587623157Z,10,2,1108,A,A,0,14.8100,100,130,165458,282200199,13.1099,100,1,13.4600,15,1,12.9800,200,2,13.9800,2,1,12.9199,2,1,14.2599,100,1,12.8599,100,1,14.2699,100,1,12.7300,100,1,14.4000,200,2,12.7100,100,1,14.4800,700,1,12.5000,700,1,14.5299,100,1,12.4600,100,1,14.5399,700,1,12.4299,700,1,14.5500,100,1,12.4199,700,1,14.5600,700,1,ARL,339103269
2395,2025-07-17T16:12:53.587644886Z,2025-07-17T16:12:53.587644886Z,10,2,1108,C,A,0,14.2699,100,130,165356,282200200,13.1099,100,1,13.4600,15,1,12.9800,200,2,13.9800,2,1,12.9199,2,1,14.2599,100,1,12.8599,100,1,14.4000,200,2,12.7300,100,1,14.4800,700,1,12.7100,100,1,14.5299,100,1,12.5000,700,1,14.5399,700,1,12.4600,100,1,14.5500,100,1,12.4299,700,1,14.5600,700,1,12.4199,700,1,14.5999,100,1,ARL,338932853
2396,2025-07-17T16:12:54.015051915Z,2025-07-17T16:12:54.015051915Z,10,2,1108,A,A,0,13.4700,100,130,165364,282207405,13.1099,100,1,13.4600,15,1,12.9800,200,2,13.4700,100,1,12.9199,2,1,13.9800,2,1,12.8599,100,1,14.2599,100,1,12.7300,100,1,14.4000,200,2,12.7100,100,1,14.4800,700,1,12.5000,700,1,14.5299,100,1,12.4600,100,1,14.5399,700,1,12.4299,700,1,14.5500,100,1,12.4199,700,1,14.5600,700,1,ARL,339110853
2397,2025-07-17T16:12:54.015785325Z,2025-07-17T16:12:54.015785325Z,10,2,1108,C,A,0,14.5999,100,130,165994,282207428,13.1099,100,1,13.4600,15,1,12.9800,200,2,13.4700,100,1,12.9199,2,1,13.9800,2,1,12.8599,100,1,14.2599,100,1,12.7300,100,1,14.4000,200,2,12.7100,100,1,14.4800,700,1,12.5000,700,1,14.5299,100,1,12.4600,100,1,14.5399,700,1,12.4299,700,1,14.5500,100,1,12.4199,700,1,14.5600,700,1,ARL,339096925
2398,2025-07-17T16:12:54.015788678Z,2025-07-17T16:12:54.015788678Z,10,2,1108,C,A,0,15.0600,100,0,165381,282207429,13.1099,100,1,13.4600,15,1,12.9800,200,2,13.4700,100,1,12.9199,2,1,13.9800,2,1,12.8599,100,1,14.2599,100,1,12.7300,100,1,14.4000,200,2,12.7100,100,1,14.4800,700,1,12.5000,700,1,14.5299,100,1,12.4600,100,1,14.5399,700,1,12.4299,700,1,14.5500,100,1,12.4199,700,1,14.5600,700,1,ARL,339097245
2399,2025-07-17T16:12:54.015788678Z,2025-07-17T16:12:54.015788678Z,10,2,1108,A,A,0,14.5199,100,130,165381,282207429,13.1099,100,1,13.4600,15,1,12.9800,200,2,13.4700,100,1,12.9199,2,1,13.9800,2,1,12.8599,100,1,14.2599,100,1,12.7300,100,1,14.4000,200,2,12.7100,100,1,14.4800,700,1,12.5000,700,1,14.5199,100,1,12.4600,100,1,14.5299,100,1,12.4299,700,1,14.5399,700,1,12.4199,700,1,14.5500,100,1,ARL,339110897
2400,2025-07-17T16:12:54.016139684Z,2025-07-17T16:12:54.016139684Z,10,2,1108,A,A,0,14.0700,100,130,165352,282207437,13.1099,100,1,13.4600,15,1,12.9800,200,2,13.4700,100,1,12.9199,2,1,13.9800,2,1,12.8599,100,1,14.0700,100,1,12.7300,100,1,14.2599,100,1,12.7100,100,1,14.4000,200,2,12.5000,700,1,14.4800,700,1,12.4600,100,1,14.5199,100,1,12.4299,700,1,14.5299,100,1,12.4199,700,1,14.5399,700,1,ARL,339110909
2401,2025-07-17T16:12:54.016988897Z,2025-07-17T16:12:54.016988897Z,10,2,1108,C,A,0,14.9600,100,0,165596,282207488,13.1099,100,1,13.4600,15,1,12.9800,200,2,13.4700,100,1,12.9199,2,1,13.9800,2,1,12.8599,100,1,14.0700,100,1,12.7300,100,1,14.2599,100,1,12.7100,100,1,14.4000,200,2,12.5000,700,1,14.4800,700,1,12.4600,100,1,14.5199,100,1,12.4299,700,1,14.5299,100,1,12.4199,700,1,14.5399,700,1,ARL,339096917
2402,2025-07-17T16:12:54.016988897Z,2025-07-17T16:12:54.016988897Z,10,2,1108,A,A,0,14.4199,100,130,165596,282207488,13.1099,100,1,13.4600,15,1,12.9800,200,2,13.4700,100,1,12.9199,2,1,13.9800,2,1,12.8599,100,1,14.0700,100,1,12.7300,100,1,14.2599,100,1,12.7100,100,1,14.4000,200,2,12.5000,700,1,14.4199,100,1,12.4600,100,1,14.4800,700,1,12.4299,700,1,14.5199,100,1,12.4199,700,1,14.5299,100,1,ARL,339110981
2403,2025-07-17T16:12:54.017215883Z,2025-07-17T16:12:54.017215883Z,10,2,1108,C,A,0,13.9800,2,0,165243,282207495,13.1099,100,1,13.4600,15,1,12.9800,200,2,13.4700,100,1,12.9199,2,1,14.0700,100,1,12.8599,100,1,14.2599,100,1,12.7300,100,1,14.4000,200,2,12.7100,100,1,14.4199,100,1,12.5000,700,1,14.4800,700,1,12.4600,100,1,14.5199,100,1,12.4299,700,1,14.5299,100,1,12.4199,700,1,14.5399,700,1,ARL,339096909
2404,2025-07-17T16:12:54.017215883Z,2025-07-17T16:12:54.017215883Z,10,2,1108,A,A,0,13.7300,2,130,165243,282207495,13.1099,100,1,13.4600,15,1,12.9800,200,2,13.4700,100,1,12.9199,2,1,13.7300,2,1,12.8599,100,1,14.0700,100,1,12.7300,100,1,14.2599,100,1,12.7100,100,1,14.4000,200,2,12.5000,700,1,14.4199,100,1,12.4600,100,1,14.4800,700,1,12.4299,700,1,14.5199,100,1,12.4199,700,1,14.5299,100,1,ARL,339110993
2405,2025-07-17T16:12:54.017622232Z,2025-07-17T16:12:54.017622232Z,10,2,1108,C,A,0,15.3800,100,0,165534,282207502,13.1099,100,1,13.4600,15,1,12.9800,200,2,13.4700,100,1,12.9199,2,1,13.7300,2,1,12.8599,100,1,14.0700,100,1,12.7300,100,1,14.2599,100,1,12.7100,100,1,14.4000,200,2,12.5000,700,1,14.4199,100,1,12.4600,100,1,14.4800,700,1,12.4299,700,1,14.5199,100,1,12.4199,700,1,14.5299,100,1,ARL,339096929
2406,2025-07-17T16:12:54.017622232Z,2025-07-17T16:12:54.017622232Z,10,2,1108,A,A,0,14.8200,100,130,165534,282207502,13.1099,100,1,13.4600,15,1,12.9800,200,2,13.4700,100,1,12.9199,2,1,13.7300,2,1,12.8599,100,1,14.0700,100,1,12.7300,100,1,14.2599,100,1,12.7100,100,1,14.4000,200,2,12.5000,700,1,14.4199,100,1,12.4600,100,1,14.4800,700,1,12.4299,700,1,14.5199,100,1,12.4199,700,1,14.5299,100,1,ARL,339111005
2407,2025-07-17T16:12:54.020013940Z,2025-07-17T16:12:54.020013940Z,10,2,1108,C,A,0,14.2599,100,130,165238,282207539,13.1099,100,1,13.4600,15,1,12.9800,200,2,13.4700,100,1,12.9199,2,1,13.7300,2,1,12.8599,100,1,14.0700,100,1,12.7300,100,1,14.4000,200,2,12.7100,100,1,14.4199,100,1,12.5000,700,1,14.4800,700,1,12.4600,100,1,14.5199,100,1,12.4299,700,1,14.5299,100,1,12.4199,700,1,14.5399,700,1,ARL,339097005
2408,2025-07-17T16:12:54.020067630Z,2025-07-17T16:12:54.020067630Z,10,2,1108,A,A,0,13.7400,100,130,165389,282207540,13.1099,100,1,13.4600,15,1,12.9800,200,2,13.4700,100,1,12.9199,2,1,13.7300,2,1,12.8599,100,1,13.7400,100,1,12.7300,100,1,14.0700,100,1,12.7100,100,1,14.4000,200,2,12.5000,700,1,14.4199,100,1,12.4600,100,1,14.4800,700,1,12.4299,700,1,14.5199,100,1,12.4199,700,1,14.5299,100,1,ARL,339111029
2409,2025-07-17T16:12:54.022862493Z,2025-07-17T16:12:54.022862493Z,10,2,1108,C,A,0,17.7600,100,0,165450,282207651,13.1099,100,1,13.4600,15,1,12.9800,200,2,13.4700,100,1,12.9199,2,1,13.7300,2,1,12.8599,100,1,13.7400,100,1,12.7300,100,1,14.0700,100,1,12.7100,100,1,14.4000,200,2,12.5000,700,1,14.4199,100,1,12.4600,100,1,14.4800,700,1,12.4299,700,1,14.5199,100,1,12.4199,700,1,14.5299,100,1,ARL,339096949
2410,2025-07-17T16:12:54.022862493Z,2025-07-17T16:12:54.022862493Z,10,2,1108,A,A,0,17.1099,100,130,165450,282207651,13.1099,100,1,13.4600,15,1,12.9800,200,2,13.4700,100,1,12.9199,2,1,13.7300,2,1,12.8599,100,1,13.7400,100,1,12.7300,100,1,14.0700,100,1,12.7100,100,1,14.4000,200,2,12.5000,700,1,14.4199,100,1,12.4600,100,1,14.4800,700,1,12.4299,700,1,14.5199,100,1,12.4199,700,1,14.5299,100,1,ARL,339111097
2411,2025-07-17T16:12:54.026021681Z,2025-07-17T16:12:54.026021681Z,10,2,1108,C,A,0,16.0799,100,0,165673,282207700,13.1099,100,1,13.4600,15,1,12.9800,200,2,13.4700,100,1,12.9199,2,1,13.7300,2,1,12.8599,100,1,13.7400,100,1,12.7300,100,1,14.0700,100,1,12.7100,100,1,14.4000,200,2,12.5000,700,1,14.4199,100,1,12.4600,100,1,14.4800,700,1,12.4299,700,1,14.5199,100,1,12.4199,700,1,14.5299,100,1,ARL,339096921
2412,2025-07-17T16:12:54.026021681Z,2025-07-17T16:12:54.026021681Z,10,2,1108,A,A,0,15.5000,100,130,165673,282207700,13.1099,100,1,13.4600,15,1,12.9800,200,2,13.4700,100,1,12.9199,2,1,13.7300,2,1,12.8599,100,1,13.7400,100,1,12.7300,100,1,14.0700,100,1,12.7100,100,1,14.4000,200,2,12.5000,700,1,14.4199,100,1,12.4600,100,1,14.4800,700,1,12.4299,700,1,14.5199,100,1,12.4199,700,1,14.5299,100,1,ARL,339111149
2413,2025-07-17T16:12:54.029066847Z,2025-07-17T16:12:54.029066847Z,10,2,1108,C,A,0,14.5500,100,0,165532,282207737,13.1099,100,1,13.4600,15,1,12.9800,200,2,13.4700,100,1,12.9199,2,1,13.7300,2,1,12.8599,100,1,13.7400,100,1,12.7300,100,1,14.0700,100,1,12.7100,100,1,14.4000,200,2,12.5000,700,1,14.4199,100,1,12.4600,100,1,14.4800,700,1,12.4299,700,1,14.5199,100,1,12.4199,700,1,14.5299,100,1,ARL,339096833
2414,2025-07-17T16:12:54.029066847Z,2025-07-17T16:12:54.029066847Z,10,2,1108,A,A,0,14.2599,100,130,165532,282207737,13.1099,100,1,13.4600,15,1,12.9800,200,2,13.4700,100,1,12.9199,2,1,13.7300,2,1,12.8599,100,1,13.7400,100,1,12.7300,100,1,14.0700,100,1,12.7100,100,1,14.2599,100,1,12.5000,700,1,14.4000,200,2,12.4600,100,1,14.4199,100,1,12.4299,700,1,14.4800,700,1,12.4199,700,1,14.5199,100,1,ARL,339111189
2415,2025-07-17T16:12:54.055092122Z,2025-07-17T16:12:54.055092122Z,10,2,1108,A,A,0,15.3599,100,130,165279,282209385,13.1099,100,1,13.4600,15,1,12.9800,200,2,13.4700,100,1,12.9199,2,1,13.7300,2,1,12.8599,100,1,13.7400,100,1,12.7300,100,1,14.0700,100,1,12.7100,100,1,14.2599,100,1,12.5000,700,1,14.4000,200,2,12.4600,100,1,14.4199,100,1,12.4299,700,1,14.4800,700,1,12.4199,700,1,14.5199,100,1,ARL,339112469
2416,2025-07-17T16:12:54.055104415Z,2025-07-17T16:12:54.055104415Z,10,2,1108,C,A,0,15.6899,100,130,164991,282209392,13.1099,100,1,13.4600,15,1,12.9800,200,2,13.4700,100,1,12.9199,2,1,13.7300,2,1,12.8599,100,1,13.7400,100,1,12.7300,100,1,14.0700,100,1,12.7100,100,1,14.2599,100,1,12.5000,700,1,14.4000,200,2,12.4600,100,1,14.4199,100,1,12.4299,700,1,14.4800,700,1,12.4199,700,1,14.5199,100,1,ARL,339096757
2417,2025-07-17T16:12:54.069614114Z,2025-07-17T16:12:54.069614114Z,10,2,1108,C,A,0,14.9600,100,0,165696,282210148,13.1099,100,1,13.4600,15,1,12.9800,200,2,13.4700,100,1,12.9199,2,1,13.7300,2,1,12.8599,100,1,13.7400,100,1,12.7300,100,1,14.0700,100,1,12.7100,100,1,14.2599,100,1,12.5000,700,1,14.4000,200,2,12.4600,100,1,14.4199,100,1,12.4299,700,1,14.4800,700,1,12.4199,700,1,14.5199,100,1,ARL,339096977
2418,2025-07-17T16:12:54.069614114Z,2025-07-17T16:12:54.069614114Z,10,2,1108,A,A,0,14.4199,100,130,165696,282210148,13.1099,100,1,13.4600,15,1,12.9800,200,2,13.4700,100,1,12.9199,2,1,13.7300,2,1,12.8599,100,1,13.7400,100,1,12.7300,100,1,14.0700,100,1,12.7100,100,1,14.2599,100,1,12.5000,700,1,14.4000,200,2,12.4600,100,1,14.4199,200,2,12.4299,700,1,14.4800,700,1,12.4199,700,1,14.5199,100,1,ARL,339112945
2419,2025-07-17T16:12:54.072716256Z,2025-07-17T16:12:54.072716256Z,10,2,1108,C,A,0,15.1400,100,0,165340,282210181,13.1099,100,1,13.4600,15,1,12.9800,200,2,13.4700,100,1,12.9199,2,1,13.7300,2,1,12.8599,100,1,13.7400,100,1,12.7300,100,1,14.0700,100,1,12.7100,100,1,14.2599,100,1,12.5000,700,1,14.4000,200,2,12.4600,100,1,14.4199,200,2,12.4299,700,1,14.4800,700,1,12.4199,700,1,14.5199,100,1,ARL,339096813
2420,2025-07-17T16:12:54.072716256Z,2025-07-17T16:12:54.072716256Z,10,2,1108,A,A,0,14.8200,100,130,165340,282210181,13.1099,100,1,13.4600,15,1,12.9800,200,2,13.4700,100,1,12.9199,2,1,13.7300,2,1,12.8599,100,1,13.7400,100,1,12.7300,100,1,14.0700,100,1,12.7100,100,1,14.2599,100,1,12.5000,700,1,14.4000,200,2,12.4600,100,1,14.4199,200,2,12.4299,700,1,14.4800,700,1,12.4199,700,1,14.5199,100,1,ARL,339112981
2421,2025-07-17T16:12:54.694630780Z,2025-07-17T16:12:54.694630780Z,10,2,1108,A,A,0,14.2699,100,130,165283,282224916,13.1099,100,1,13.4600,15,1,12.9800,200,2,13.4700,100,1,12.9199,2,1,13.7300,2,1,12.8599,100,1,13.7400,100,1,12.7300,100,1,14.0700,100,1,12.7100,100,1,14.2599,100,1,12.5000,700,1,14.2699,100,1,12.4600,100,1,14.4000,200,2,12.4299,700,1,14.4199,200,2,12.4199,700,1,14.4800,700,1,ARL,339126221
2422,2025-07-17T16:12:54.694644316Z,2025-07-17T16:12:54.694644316Z,10,2,1108,C,A,0,14.8100,100,130,165204,282224917,13.1099,100,1,13.4600,15,1,12.9800,200,2,13.4700,100,1,12.9199,2,1,13.7300,2,1,12.8599,100,1,13.7400,100,1,12.7300,100,1,14.0700,100,1,12.7100,100,1,14.2599,100,1,12.5000,700,1,14.2699,100,1,12.4600,100,1,14.4000,200,2,12.4299,700,1,14.4199,200,2,12.4199,700,1,14.4800,700,1,ARL,339103269
2423,2025-07-17T16:12:55.255162003Z,2025-07-17T16:12:55.255162003Z,10,2,1108,A,A,0,14.0000,100,130,165583,282231441,13.1099,100,1,13.4600,15,1,12.9800,200,2,13.4700,100,1,12.9199,2,1,13.7300,2,1,12.8599,100,1,13.7400,100,1,12.7300,100,1,14.0000,100,1,12.7100,100,1,14.0700,100,1,12.5000,700,1,14.2599,100,1,12.4600,100,1,14.2699,100,1,12.4299,700,1,14.4000,200,2,12.4199,700,1,14.4199,200,2,ARL,339133353
2424,2025-07-17T16:12:55.255163083Z,2025-07-17T16:12:55.255163083Z,10,2,1108,C,A,0,14.5299,100,130,165186,282231442,13.1099,100,1,13.4600,15,1,12.9800,200,2,13.4700,100,1,12.9199,2,1,13.7300,2,1,12.8599,100,1,13.7400,100,1,12.7300,100,1,14.0000,100,1,12.7100,100,1,14.0700,100,1,12.5000,700,1,14.2599,100,1,12.4600,100,1,14.2699,100,1,12.4299,700,1,14.4000,200,2,12.4199,700,1,14.4199,200,2,ARL,339100477
2425,2025-07-17T16:12:58.302017238Z,2025-07-17T16:12:58.302017238Z,10,2,1108,C,A,0,13.4600,15,128,166209,282279351,13.1099,100,1,13.4700,100,1,12.9800,200,2,13.7300,2,1,12.9199,2,1,13.7400,100,1,12.8599,100,1,14.0000,100,1,12.7300,100,1,14.0700,100,1,12.7100,100,1,14.2599,100,1,12.5000,700,1,14.2699,100,1,12.4600,100,1,14.4000,200,2,12.4299,700,1,14.4199,200,2,12.4199,700,1,14.4800,700,1,ARL,339096733
2426,2025-07-17T16:12:58.420710579Z,2025-07-17T16:12:58.420710579Z,10,2,1108,C,A,0,13.4700,100,128,177167,282288716,13.1099,100,1,13.7300,2,1,12.9800,200,2,13.7400,100,1,12.9199,2,1,14.0000,100,1,12.8599,100,1,14.0700,100,1,12.7300,100,1,14.2599,100,1,12.7100,100,1,14.2699,100,1,12.5000,700,1,14.4000,200,2,12.4600,100,1,14.4199,200,2,12.4299,700,1,14.4800,700,1,12.4199,700,1,14.5199,100,1,ARL,339110853
2427,2025-07-17T16:12:58.420776003Z,2025-07-17T16:12:58.420776003Z,10,2,1108,A,A,0,13.4700,96,128,174584,282288757,13.1099,100,1,13.4700,96,1,12.9800,200,2,13.7300,2,1,12.9199,2,1,13.7400,100,1,12.8599,100,1,14.0000,100,1,12.7300,100,1,14.0700,100,1,12.7100,100,1,14.2599,100,1,12.5000,700,1,14.2699,100,1,12.4600,100,1,14.4000,200,2,12.4299,700,1,14.4199,200,2,12.4199,700,1,14.4800,700,1,ARL,339201549
2428,2025-07-17T16:12:58.421165414Z,2025-07-17T16:12:58.421165414Z,10,2,1108,C,A,0,13.4700,96,130,173139,282289082,13.1099,100,1,13.7300,2,1,12.9800,200,2,13.7400,100,1,12.9199,2,1,14.0000,100,1,12.8599,100,1,14.0700,100,1,12.7300,100,1,14.2599,100,1,12.7100,100,1,14.2699,100,1,12.5000,700,1,14.4000,200,2,12.4600,100,1,14.4199,200,2,12.4299,700,1,14.4800,700,1,12.4199,700,1,14.5199,100,1,ARL,339201549
2429,2025-07-17T16:12:58.421205027Z,2025-07-17T16:12:58.421205027Z,10,2,1108,A,A,0,15.6699,100,128,174897,282289111,13.1099,100,1,13.7300,2,1,12.9800,200,2,13.7400,100,1,12.9199,2,1,14.0000,100,1,12.8599,100,1,14.0700,100,1,12.7300,100,1,14.2599,100,1,12.7100,100,1,14.2699,100,1,12.5000,700,1,14.4000,200,2,12.4600,100,1,14.4199,200,2,12.4299,700,1,14.4800,700,1,12.4199,700,1,14.5199,100,1,ARL,339202065
2430,2025-07-17T16:12:58.421248082Z,2025-07-17T16:12:58.421248082Z,10,2,1108,C,A,0,15.3599,100,128,175193,282289154,13.1099,100,1,13.7300,2,1,12.9800,200,2,13.7400,100,1,12.9199,2,1,14.0000,100,1,12.8599,100,1,14.0700,100,1,12.7300,100,1,14.2599,100,1,12.7100,100,1,14.2699,100,1,12.5000,700,1,14.4000,200,2,12.4600,100,1,14.4199,200,2,12.4299,700,1,14.4800,700,1,12.4199,700,1,14.5199,100,1,ARL,339112469
2431,2025-07-17T16:12:58.421581692Z,2025-07-17T16:12:58.421581692Z,10,2,1108,C,A,0,14.0700,100,130,175034,282289338,13.1099,100,1,13.7300,2,1,12.9800,200,2,13.7400,100,1,12.9199,2,1,14.0000,100,1,12.8599,100,1,14.2599,100,1,12.7300,100,1,14.2699,100,1,12.7100,100,1,14.4000,200,2,12.5000,700,1,14.4199,200,2,12.4600,100,1,14.4800,700,1,12.4299,700,1,14.5199,100,1,12.4199,700,1,14.5399,700,1,ARL,339110909
2432,2025-07-17T16:12:58.421969675Z,2025-07-17T16:12:58.421969675Z,10,2,1108,A,A,0,14.3499,100,128,176110,282289650,13.1099,100,1,13.7300,2,1,12.9800,200,2,13.7400,100,1,12.9199,2,1,14.0000,100,1,12.8599,100,1,14.2599,100,1,12.7300,100,1,14.2699,100,1,12.7100,100,1,14.3499,100,1,12.5000,700,1,14.4000,200,2,12.4600,100,1,14.4199,200,2,12.4299,700,1,14.4800,700,1,12.4199,700,1,14.5199,100,1,ARL,339202733
2433,2025-07-17T16:12:58.422073305Z,2025-07-17T16:12:58.422073305Z,10,2,1108,C,A,0,14.5199,100,0,174572,282289747,13.1099,100,1,13.7300,2,1,12.9800,200,2,13.7400,100,1,12.9199,2,1,14.0000,100,1,12.8599,100,1,14.2599,100,1,12.7300,100,1,14.2699,100,1,12.7100,100,1,14.3499,100,1,12.5000,700,1,14.4000,200,2,12.4600,100,1,14.4199,200,2,12.4299,700,1,14.4800,700,1,12.4199,700,1,14.5399,700,1,ARL,339110897
2434,2025-07-17T16:12:58.422073305Z,2025-07-17T16:12:58.422073305Z,10,2,1108,A,A,0,14.8100,100,128,174572,282289747,13.1099,100,1,13.7300,2,1,12.9800,200,2,13.7400,100,1,12.9199,2,1,14.0000,100,1,12.8599,100,1,14.2599,100,1,12.7300,100,1,14.2699,100,1,12.7100,100,1,14.3499,100,1,12.5000,700,1,14.4000,200,2,12.4600,100,1,14.4199,200,2,12.4299,700,1,14.4800,700,1,12.4199,700,1,14.5399,700,1,ARL,339202805
2435,2025-07-17T16:12:58.424789366Z,2025-07-17T16:12:58.424789366Z,10,2,1108,C,A,0,14.4000,100,0,169004,282290622,13.1099,100,1,13.7300,2,1,12.9800,200,2,13.7400,100,1,12.9199,2,1,14.0000,100,1,12.8599,100,1,14.2599,100,1,12.7300,100,1,14.2699,100,1,12.7100,100,1,14.3499,100,1,12.5000,700,1,14.4000,100,1,12.4600,100,1,14.4199,200,2,12.4299,700,1,14.4800,700,1,12.4199,700,1,14.5399,700,1,ARL,338139585
2436,2025-07-17T16:12:58.424789366Z,2025-07-17T16:12:58.424789366Z,10,2,1108,A,A,0,14.5700,100,128,169004,282290622,13.1099,100,1,13.7300,2,1,12.9800,200,2,13.7400,100,1,12.9199,2,1,14.0000,100,1,12.8599,100,1,14.2599,100,1,12.7300,100,1,14.2699,100,1,12.7100,100,1,14.3499,100,1,12.5000,700,1,14.4000,100,1,12.4600,100,1,14.4199,200,2,12.4299,700,1,14.4800,700,1,12.4199,700,1,14.5399,700,1,ARL,339203693
2437,2025-07-17T16:12:58.425283932Z,2025-07-17T16:12:58.425283932Z,10,2,1108,C,A,0,14.4000,100,0,166244,282290769,13.1099,100,1,13.7300,2,1,12.9800,200,2,13.7400,100,1,12.9199,2,1,14.0000,100,1,12.8599,100,1,14.2599,100,1,12.7300,100,1,14.2699,100,1,12.7100,100,1,14.3499,100,1,12.5000,700,1,14.4199,200,2,12.4600,100,1,14.4800,700,1,12.4299,700,1,14.5399,700,1,12.4199,700,1,14.5600,700,1,ARL,338139601
2438,2025-07-17T16:12:58.425283932Z,2025-07-17T16:12:58.425283932Z,10,2,1108,A,A,0,14.5700,100,128,166244,282290769,13.1099,100,1,13.7300,2,1,12.9800,200,2,13.7400,100,1,12.9199,2,1,14.0000,100,1,12.8599,100,1,14.2599,100,1,12.7300,100,1,14.2699,100,1,12.7100,100,1,14.3499,100,1,12.5000,700,1,14.4199,200,2,12.4600,100,1,14.4800,700,1,12.4299,700,1,14.5399,700,1,12.4199,700,1,14.5600,700,1,ARL,339203897
2439,2025-07-17T16:12:58.426258092Z,2025-07-17T16:12:58.426258092Z,10,2,1108,C,A,0,14.2599,100,130,165530,282290946,13.1099,100,1,13.7300,2,1,12.9800,200,2,13.7400,100,1,12.9199,2,1,14.0000,100,1,12.8599,100,1,14.2699,100,1,12.7300,100,1,14.3499,100,1,12.7100,100,1,14.4199,200,2,12.5000,700,1,14.4800,700,1,12.4600,100,1,14.5399,700,1,12.4299,700,1,14.5600,700,1,12.4199,700,1,14.5700,200,2,ARL,339111189
2440,2025-07-17T16:12:58.426378483Z,2025-07-17T16:12:58.426378483Z,10,2,1108,A,A,0,14.5299,100,130,165994,282290959,13.1099,100,1,13.7300,2,1,12.9800,200,2,13.7400,100,1,12.9199,2,1,14.0000,100,1,12.8599,100,1,14.2699,100,1,12.7300,100,1,14.3499,100,1,12.7100,100,1,14.4199,200,2,12.5000,700,1,14.4800,700,1,12.4600,100,1,14.5299,100,1,12.4299,700,1,14.5399,700,1,12.4199,700,1,14.5600,700,1,ARL,339204077
2441,2025-07-17T16:12:58.430665639Z,2025-07-17T16:12:58.430665639Z,10,2,1108,C,A,0,13.7400,100,130,165055,282291933,13.1099,100,1,13.7300,2,1,12.9800,200,2,14.0000,100,1,12.9199,2,1,14.2699,100,1,12.8599,100,1,14.3499,100,1,12.7300,100,1,14.4199,200,2,12.7100,100,1,14.4800,700,1,12.5000,700,1,14.5299,100,1,12.4600,100,1,14.5399,700,1,12.4299,700,1,14.5600,700,1,12.4199,700,1,14.5700,200,2,ARL,339111029
2442,2025-07-17T16:12:58.430720526Z,2025-07-17T16:12:58.430720526Z,10,2,1108,A,A,0,14.0099,100,128,168000,282291946,13.1099,100,1,13.7300,2,1,12.9800,200,2,14.0000,100,1,12.9199,2,1,14.0099,100,1,12.8599,100,1,14.2699,100,1,12.7300,100,1,14.3499,100,1,12.7100,100,1,14.4199,200,2,12.5000,700,1,14.4800,700,1,12.4600,100,1,14.5299,100,1,12.4299,700,1,14.5399,700,1,12.4199,700,1,14.5600,700,1,ARL,339205213
2443,2025-07-17T16:12:58.432736189Z,2025-07-17T16:12:58.432736189Z,10,2,1108,C,A,0,14.8200,100,0,165606,282292390,13.1099,100,1,13.7300,2,1,12.9800,200,2,14.0000,100,1,12.9199,2,1,14.0099,100,1,12.8599,100,1,14.2699,100,1,12.7300,100,1,14.3499,100,1,12.7100,100,1,14.4199,200,2,12.5000,700,1,14.4800,700,1,12.4600,100,1,14.5299,100,1,12.4299,700,1,14.5399,700,1,12.4199,700,1,14.5600,700,1,ARL,339111005
2444,2025-07-17T16:12:58.432736189Z,2025-07-17T16:12:58.432736189Z,10,2,1108,A,A,0,15.3800,100,130,165606,282292390,13.1099,100,1,13.7300,2,1,12.9800,200,2,14.0000,100,1,12.9199,2,1,14.0099,100,1,12.8599,100,1,14.2699,100,1,12.7300,100,1,14.3499,100,1,12.7100,100,1,14.4199,200,2,12.5000,700,1,14.4800,700,1,12.4600,100,1,14.5299,100,1,12.4299,700,1,14.5399,700,1,12.4199,700,1,14.5600,700,1,ARL,339206141
2445,2025-07-17T16:12:58.437907652Z,2025-07-17T16:12:58.437907652Z,10,2,1108,C,B,0,12.9199,2,0,165687,282292938,13.1099,100,1,13.7300,2,1,12.9800,200,2,14.0000,100,1,12.8599,100,1,14.0099,100,1,12.7300,100,1,14.2699,100,1,12.7100,100,1,14.3499,100,1,12.5000,700,1,14.4199,200,2,12.4600,100,1,14.4800,700,1,12.4299,700,1,14.5299,100,1,12.4199,700,1,14.5399,700,1,12.3699,700,1,14.5600,700,1,ARL,338044113
2446,2025-07-17T16:12:58.437907652Z,2025-07-17T16:12:58.437907652Z,10,2,1108,A,B,0,13.0199,2,130,165687,282292938,13.1099,100,1,13.7300,2,1,13.0199,2,1,14.0000,100,1,12.9800,200,2,14.0099,100,1,12.8599,100,1,14.2699,100,1,12.7300,100,1,14.3499,100,1,12.7100,100,1,14.4199,200,2,12.5000,700,1,14.4800,700,1,12.4600,100,1,14.5299,100,1,12.4299,700,1,14.5399,700,1,12.4199,700,1,14.5600,700,1,ARL,339207125
2447,2025-07-17T16:12:58.437911392Z,2025-07-17T16:12:58.437911392Z,10,2,1108,C,A,0,13.7300,2,0,165370,282292939,13.1099,100,1,14.0000,100,1,13.0199,2,1,14.0099,100,1,12.9800,200,2,14.2699,100,1,12.8599,100,1,14.3499,100,1,12.7300,100,1,14.4199,200,2,12.7100,100,1,14.4800,700,1,12.5000,700,1,14.5299,100,1,12.4600,100,1,14.5399,700,1,12.4299,700,1,14.5600,700,1,12.4199,700,1,14.5700,200,2,ARL,339110993
2448,2025-07-17T16:12:58.437911392Z,2025-07-17T16:12:58.437911392Z,10,2,1108,A,A,0,13.9800,2,130,165370,282292939,13.1099,100,1,13.9800,2,1,13.0199,2,1,14.0000,100,1,12.9800,200,2,14.0099,100,1,12.8599,100,1,14.2699,100,1,12.7300,100,1,14.3499,100,1,12.7100,100,1,14.4199,200,2,12.5000,700,1,14.4800,700,1,12.4600,100,1,14.5299,100,1,12.4299,700,1,14.5399,700,1,12.4199,700,1,14.5600,700,1,ARL,339207129
2449,2025-07-17T16:12:58.438678961Z,2025-07-17T16:12:58.438678961Z,10,2,1108,C,A,0,14.0099,100,130,164983,282293023,13.1099,100,1,13.9800,2,1,13.0199,2,1,14.0000,100,1,12.9800,200,2,14.2699,100,1,12.8599,100,1,14.3499,100,1,12.7300,100,1,14.4199,200,2,12.7100,100,1,14.4800,700,1,12.5000,700,1,14.5299,100,1,12.4600,100,1,14.5399,700,1,12.4299,700,1,14.5600,700,1,12.4199,700,1,14.5700,200,2,ARL,339205213
2450,2025-07-17T16:12:58.438728994Z,2025-07-17T16:12:58.438728994Z,10,2,1108,A,A,0,14.2400,100,130,165342,282293026,13.1099,100,1,13.9800,2,1,13.0199,2,1,14.0000,100,1,12.9800,200,2,14.2400,100,1,12.8599,100,1,14.2699,100,1,12.7300,100,1,14.3499,100,1,12.7100,100,1,14.4199,200,2,12.5000,700,1,14.4800,700,1,12.4600,100,1,14.5299,100,1,12.4299,700,1,14.5399,700,1,12.4199,700,1,14.5600,700,1,ARL,339207197
2451,2025-07-17T16:12:58.441669159Z,2025-07-17T16:12:58.441669159Z,10,2,1108,C,A,0,14.4199,100,0,165338,282293191,13.1099,100,1,13.9800,2,1,13.0199,2,1,14.0000,100,1,12.9800,200,2,14.2400,100,1,12.8599,100,1,14.2699,100,1,12.7300,100,1,14.3499,100,1,12.7100,100,1,14.4199,100,1,12.5000,700,1,14.4800,700,1,12.4600,100,1,14.5299,100,1,12.4299,700,1,14.5399,700,1,12.4199,700,1,14.5600,700,1,ARL,339110981
2452,2025-07-17T16:12:58.441669159Z,2025-07-17T16:12:58.441669159Z,10,2,1108,A,A,0,14.9600,100,130,165338,282293191,13.1099,100,1,13.9800,2,1,13.0199,2,1,14.0000,100,1,12.9800,200,2,14.2400,100,1,12.8599,100,1,14.2699,100,1,12.7300,100,1,14.3499,100,1,12.7100,100,1,14.4199,100,1,12.5000,700,1,14.4800,700,1,12.4600,100,1,14.5299,100,1,12.4299,700,1,14.5399,700,1,12.4199,700,1,14.5600,700,1,ARL,339207505
2453,2025-07-17T16:12:58.454211242Z,2025-07-17T16:12:58.454211242Z,10,2,1108,C,A,0,17.1099,100,0,165433,282293811,13.1099,100,1,13.9800,2,1,13.0199,2,1,14.0000,100,1,12.9800,200,2,14.2400,100,1,12.8599,100,1,14.2699,100,1,12.7300,100,1,14.3499,100,1,12.7100,100,1,14.4199,100,1,12.5000,700,1,14.4800,700,1,12.4600,100,1,14.5299,100,1,12.4299,700,1,14.5399,700,1,12.4199,700,1,14.5600,700,1,ARL,339111097
2454,2025-07-17T16:12:58.454211242Z,2025-07-17T16:12:58.454211242Z,10,2,1108,A,A,0,17.7600,100,130,165433,282293811,13.1099,100,1,13.9800,2,1,13.0199,2,1,14.0000,100,1,12.9800,200,2,14.2400,100,1,12.8599,100,1,14.2699,100,1,12.7300,100,1,14.3499,100,1,12.7100,100,1,14.4199,100,1,12.5000,700,1,14.4800,700,1,12.4600,100,1,14.5299,100,1,12.4299,700,1,14.5399,700,1,12.4199,700,1,14.5600,700,1,ARL,339208377
2455,2025-07-17T16:12:58.472126777Z,2025-07-17T16:12:58.472126777Z,10,2,1108,C,A,0,15.5000,100,0,165699,282294411,13.1099,100,1,13.9800,2,1,13.0199,2,1,14.0000,100,1,12.9800,200,2,14.2400,100,1,12.8599,100,1,14.2699,100,1,12.7300,100,1,14.3499,100,1,12.7100,100,1,14.4199,100,1,12.5000,700,1,14.4800,700,1,12.4600,100,1,14.5299,100,1,12.4299,700,1,14.5399,700,1,12.4199,700,1,14.5600,700,1,ARL,339111149
2456,2025-07-17T16:12:58.472126777Z,2025-07-17T16:12:58.472126777Z,10,2,1108,A,A,0,16.0799,100,130,165699,282294411,13.1099,100,1,13.9800,2,1,13.0199,2,1,14.0000,100,1,12.9800,200,2,14.2400,100,1,12.8599,100,1,14.2699,100,1,12.7300,100,1,14.3499,100,1,12.7100,100,1,14.4199,100,1,12.5000,700,1,14.4800,700,1,12.4600,100,1,14.5299,100,1,12.4299,700,1,14.5399,700,1,12.4199,700,1,14.5600,700,1,ARL,339209241
2457,2025-07-17T16:12:58.472458830Z,2025-07-17T16:12:58.472458830Z,10,2,1108,C,A,0,14.8100,100,0,165949,282294423,13.1099,100,1,13.9800,2,1,13.0199,2,1,14.0000,100,1,12.9800,200,2,14.2400,100,1,12.8599,100,1,14.2699,100,1,12.7300,100,1,14.3499,100,1,12.7100,100,1,14.4199,100,1,12.5000,700,1,14.4800,700,1,12.4600,100,1,14.5299,100,1,12.4299,700,1,14.5399,700,1,12.4199,700,1,14.5600,700,1,ARL,339202805
2458,2025-07-17T16:12:58.472458830Z,2025-07-17T16:12:58.472458830Z,10,2,1108,A,A,0,15.0399,100,130,165949,282294423,13.1099,100,1,13.9800,2,1,13.0199,2,1,14.0000,100,1,12.9800,200,2,14.2400,100,1,12.8599,100,1,14.2699,100,1,12.7300,100,1,14.3499,100,1,12.7100,100,1,14.4199,100,1,12.5000,700,1,14.4800,700,1,12.4600,100,1,14.5299,100,1,12.4299,700,1,14.5399,700,1,12.4199,700,1,14.5600,700,1,ARL,339209257
2459,2025-07-17T16:12:58.571679985Z,2025-07-17T16:12:58.571679985Z,10,2,1108,C,A,0,14.8200,100,0,165723,282298942,13.1099,100,1,13.9800,2,1,13.0199,2,1,14.0000,100,1,12.9800,200,2,14.2400,100,1,12.8599,100,1,14.2699,100,1,12.7300,100,1,14.3499,100,1,12.7100,100,1,14.4199,100,1,12.5000,700,1,14.4800,700,1,12.4600,100,1,14.5299,100,1,12.4299,700,1,14.5399,700,1,12.4199,700,1,14.5600,700,1,ARL,339112981
2460,2025-07-17T16:12:58.571679985Z,2025-07-17T16:12:58.571679985Z,10,2,1108,A,A,0,15.3800,100,130,165723,282298942,13.1099,100,1,13.9800,2,1,13.0199,2,1,14.0000,100,1,12.9800,200,2,14.2400,100,1,12.8599,100,1,14.2699,100,1,12.7300,100,1,14.3499,100,1,12.7100,100,1,14.4199,100,1,12.5000,700,1,14.4800,700,1,12.4600,100,1,14.5299,100,1,12.4299,700,1,14.5399,700,1,12.4199,700,1,14.5600,700,1,ARL,339215205
2461,2025-07-17T16:12:58.619238614Z,2025-07-17T16:12:58.619238614Z,10,2,1108,C,A,0,14.4199,100,0,165488,282299781,13.1099,100,1,13.9800,2,1,13.0199,2,1,14.0000,100,1,12.9800,200,2,14.2400,100,1,12.8599,100,1,14.2699,100,1,12.7300,100,1,14.3499,100,1,12.7100,100,1,14.4800,700,1,12.5000,700,1,14.5299,100,1,12.4600,100,1,14.5399,700,1,12.4299,700,1,14.5600,700,1,12.4199,700,1,14.5700,200,2,ARL,339112945
2462,2025-07-17T16:12:58.619238614Z,2025-07-17T16:12:58.619238614Z,10,2,1108,A,A,0,14.9600,100,130,165488,282299781,13.1099,100,1,13.9800,2,1,13.0199,2,1,14.0000,100,1,12.9800,200,2,14.2400,100,1,12.8599,100,1,14.2699,100,1,12.7300,100,1,14.3499,100,1,12.7100,100,1,14.4800,700,1,12.5000,700,1,14.5299,100,1,12.4600,100,1,14.5399,700,1,12.4299,700,1,14.5600,700,1,12.4199,700,1,14.5700,200,2,ARL,339216161
2463,2025-07-17T16:12:58.985928594Z,2025-07-17T16:12:58.985928594Z,10,2,1108,C,B,0,13.0199,2,0,165354,282305386,13.1099,100,1,13.9800,2,1,12.9800,200,2,14.0000,100,1,12.8599,100,1,14.2400,100,1,12.7300,100,1,14.2699,100,1,12.7100,100,1,14.3499,100,1,12.5000,700,1,14.4800,700,1,12.4600,100,1,14.5299,100,1,12.4299,700,1,14.5399,700,1,12.4199,700,1,14.5600,700,1,12.3699,700,1,14.5700,200,2,ARL,339207125
2464,2025-07-17T16:12:58.985928594Z,2025-07-17T16:12:58.985928594Z,10,2,1108,A,B,0,12.8599,2,130,165354,282305386,13.1099,100,1,13.9800,2,1,12.9800,200,2,14.0000,100,1,12.8599,102,2,14.2400,100,1,12.7300,100,1,14.2699,100,1,12.7100,100,1,14.3499,100,1,12.5000,700,1,14.4800,700,1,12.4600,100,1,14.5299,100,1,12.4299,700,1,14.5399,700,1,12.4199,700,1,14.5600,700,1,12.3699,700,1,14.5700,200,2,ARL,339222617
2465,2025-07-17T16:12:59.062943193Z,2025-07-17T16:12:59.062943193Z,10,2,1108,A,A,0,13.9900,100,130,165219,282306400,13.1099,100,1,13.9800,2,1,12.9800,200,2,13.9900,100,1,12.8599,102,2,14.0000,100,1,12.7300,100,1,14.2400,100,1,12.7100,100,1,14.2699,100,1,12.5000,700,1,14.3499,100,1,12.4600,100,1,14.4800,700,1,12.4299,700,1,14.5299,100,1,12.4199,700,1,14.5399,700,1,12.3699,700,1,14.5600,700,1,ARL,339224109
2466,2025-07-17T16:12:59.082690430Z,2025-07-17T16:12:59.082690430Z,10,2,1108,C,A,0,14.0000,100,130,165140,282307908,13.1099,100,1,13.9800,2,1,12.9800,200,2,13.9900,100,1,12.8599,102,2,14.2400,100,1,12.7300,100,1,14.2699,100,1,12.7100,100,1,14.3499,100,1,12.5000,700,1,14.4800,700,1,12.4600,100,1,14.5299,100,1,12.4299,700,1,14.5399,700,1,12.4199,700,1,14.5600,700,1,12.3699,700,1,14.5700,200,2,ARL,339133353
2467,2025-07-17T16:12:59.082691385Z,2025-07-17T16:12:59.082691385Z,10,2,1108,A,A,0,14.5299,100,130,165255,282307909,13.1099,100,1,13.9800,2,1,12.9800,200,2,13.9900,100,1,12.8599,102,2,14.2400,100,1,12.7300,100,1,14.2699,100,1,12.7100,100,1,14.3499,100,1,12.5000,700,1,14.4800,700,1,12.4600,100,1,14.5299,200,2,12.4299,700,1,14.5399,700,1,12.4199,700,1,14.5600,700,1,12.3699,700,1,14.5700,200,2,ARL,339225769
2468,2025-07-17T16:12:59.088629294Z,2025-07-17T16:12:59.088629294Z,10,2,1108,A,A,0,14.8100,100,130,165276,282308093,13.1099,100,1,13.9800,2,1,12.9800,200,2,13.9900,100,1,12.8599,102,2,14.2400,100,1,12.7300,100,1,14.2699,100,1,12.7100,100,1,14.3499,100,1,12.5000,700,1,14.4800,700,1,12.4600,100,1,14.5299,200,2,12.4299,700,1,14.5399,700,1,12.4199,700,1,14.5600,700,1,12.3699,700,1,14.5700,200,2,ARL,339225885
2469,2025-07-17T16:12:59.088642718Z,2025-07-17T16:12:59.088642718Z,10,2,1108,C,A,0,14.2699,100,130,165399,282308094,13.1099,100,1,13.9800,2,1,12.9800,200,2,13.9900,100,1,12.8599,102,2,14.2400,100,1,12.7300,100,1,14.3499,100,1,12.7100,100,1,14.4800,700,1,12.5000,700,1,14.5299,200,2,12.4600,100,1,14.5399,700,1,12.4299,700,1,14.5600,700,1,12.4199,700,1,14.5700,200,2,12.3699,700,1,14.6799,700,1,ARL,339126221
2470,2025-07-17T16:12:59.092762564Z,2025-07-17T16:12:59.092762564Z,10,2,1108,C,A,0,14.3499,100,130,165278,282308154,13.1099,100,1,13.9800,2,1,12.9800,200,2,13.9900,100,1,12.8599,102,2,14.2400,100,1,12.7300,100,1,14.4800,700,1,12.7100,100,1,14.5299,200,2,12.5000,700,1,14.5399,700,1,12.4600,100,1,14.5600,700,1,12.4299,700,1,14.5700,200,2,12.4199,700,1,14.6799,700,1,12.3699,700,1,14.8100,100,1,ARL,339202733
2471,2025-07-17T16:12:59.093113488Z,2025-07-17T16:12:59.093113488Z,10,2,1108,A,A,0,14.5999,100,130,165427,282308163,13.1099,100,1,13.9800,2,1,12.9800,200,2,13.9900,100,1,12.8599,102,2,14.2400,100,1,12.7300,100,1,14.4800,700,1,12.7100,100,1,14.5299,200,2,12.5000,700,1,14.5399,700,1,12.4600,100,1,14.5600,700,1,12.4299,700,1,14.5700,200,2,12.4199,700,1,14.5999,100,1,12.3699,700,1,14.6799,700,1,ARL,339226021
2472,2025-07-17T16:12:59.430320610Z,2025-07-17T16:12:59.430320610Z,10,2,1108,C,A,0,14.5299,100,0,165402,282313368,13.1099,100,1,13.9800,2,1,12.9800,200,2,13.9900,100,1,12.8599,102,2,14.2400,100,1,12.7300,100,1,14.4800,700,1,12.7100,100,1,14.5299,100,1,12.5000,700,1,14.5399,700,1,12.4600,100,1,14.5600,700,1,12.4299,700,1,14.5700,200,2,12.4199,700,1,14.5999,100,1,12.3699,700,1,14.6799,700,1,ARL,339204077
2473,2025-07-17T16:12:59.430320610Z,2025-07-17T16:12:59.430320610Z,10,2,1108,A,A,0,14.7699,100,130,165402,282313368,13.1099,100,1,13.9800,2,1,12.9800,200,2,13.9900,100,1,12.8599,102,2,14.2400,100,1,12.7300,100,1,14.4800,700,1,12.7100,100,1,14.5299,100,1,12.5000,700,1,14.5399,700,1,12.4600,100,1,14.5600,700,1,12.4299,700,1,14.5700,200,2,12.4199,700,1,14.5999,100,1,12.3699,700,1,14.6799,700,1,ARL,339232213
2474,2025-07-17T16:13:04.825736034Z,2025-07-17T16:13:04.825736034Z,10,2,1108,A,A,0,13.6600,15,128,166132,282392593,13.1099,100,1,13.6600,15,1,12.9800,200,2,13.9800,2,1,12.8599,102,2,13.9900,100,1,12.7300,100,1,14.2400,100,1,12.7100,100,1,14.4800,700,1,12.5000,700,1,14.5299,100,1,12.4600,100,1,14.5399,700,1,12.4299,700,1,14.5600,700,1,12.4199,700,1,14.5700,200,2,12.3699,700,1,14.5999,100,1,ARL,339332865
2475,2025-07-17T16:13:06.189110140Z,2025-07-17T16:13:06.189110140Z,10,2,1108,C,B,0,12.8599,2,0,165672,282411935,13.1099,100,1,13.6600,15,1,12.9800,200,2,13.9800,2,1,12.8599,100,1,13.9900,100,1,12.7300,100,1,14.2400,100,1,12.7100,100,1,14.4800,700,1,12.5000,700,1,14.5299,100,1,12.4600,100,1,14.5399,700,1,12.4299,700,1,14.5600,700,1,12.4199,700,1,14.5700,200,2,12.3699,700,1,14.5999,100,1,ARL,339222617
2476,2025-07-17T16:13:06.189110140Z,2025-07-17T16:13:06.189110140Z,10,2,1108,A,B,0,12.9600,2,130,165672,282411935,13.1099,100,1,13.6600,15,1,12.9800,200,2,13.9800,2,1,12.9600,2,1,13.9900,100,1,12.8599,100,1,14.2400,100,1,12.7300,100,1,14.4800,700,1,12.7100,100,1,14.5299,100,1,12.5000,700,1,14.5399,700,1,12.4600,100,1,14.5600,700,1,12.4299,700,1,14.5700,200,2,12.4199,700,1,14.5999,100,1,ARL,339356397
2477,2025-07-17T16:13:06.224732787Z,2025-07-17T16:13:06.224732787Z,10,2,1108,C,A,0,13.9900,100,0,165602,282413599,13.1099,100,1,13.6600,15,1,12.9800,200,2,13.9800,2,1,12.9600,2,1,14.2400,100,1,12.8599,100,1,14.4800,700,1,12.7300,100,1,14.5299,100,1,12.7100,100,1,14.5399,700,1,12.5000,700,1,14.5600,700,1,12.4600,100,1,14.5700,200,2,12.4299,700,1,14.5999,100,1,12.4199,700,1,14.6799,700,1,ARL,339224109
2478,2025-07-17T16:13:06.224732787Z,2025-07-17T16:13:06.224732787Z,10,2,1108,A,A,0,13.6699,100,130,165602,282413599,13.1099,100,1,13.6600,15,1,12.9800,200,2,13.6699,100,1,12.9600,2,1,13.9800,2,1,12.8599,100,1,14.2400,100,1,12.7300,100,1,14.4800,700,1,12.7100,100,1,14.5299,100,1,12.5000,700,1,14.5399,700,1,12.4600,100,1,14.5600,700,1,12.4299,700,1,14.5700,200,2,12.4199,700,1,14.5999,100,1,ARL,339358233
2479,2025-07-17T16:13:06.225475518Z,2025-07-17T16:13:06.225475518Z,10,2,1108,C,A,0,15.0399,100,0,167263,282413677,13.1099,100,1,13.6600,15,1,12.9800,200,2,13.6699,100,1,12.9600,2,1,13.9800,2,1,12.8599,100,1,14.2400,100,1,12.7300,100,1,14.4800,700,1,12.7100,100,1,14.5299,100,1,12.5000,700,1,14.5399,700,1,12.4600,100,1,14.5600,700,1,12.4299,700,1,14.5700,200,2,12.4199,700,1,14.5999,100,1,ARL,339209257
2480,2025-07-17T16:13:06.225475518Z,2025-07-17T16:13:06.225475518Z,10,2,1108,A,A,0,14.7300,100,0,167263,282413677,13.1099,100,1,13.6600,15,1,12.9800,200,2,13.6699,100,1,12.9600,2,1,13.9800,2,1,12.8599,100,1,14.2400,100,1,12.7300,100,1,14.4800,700,1,12.7100,100,1,14.5299,100,1,12.5000,700,1,14.5399,700,1,12.4600,100,1,14.5600,700,1,12.4299,700,1,14.5700,200,2,12.4199,700,1,14.5999,100,1,ARL,339358293
2481,2025-07-17T16:13:06.225475906Z,2025-07-17T16:13:06.225475906Z,10,2,1108,C,A,0,14.5999,100,128,166875,282413678,13.1099,100,1,13.6600,15,1,12.9800,200,2,13.6699,100,1,12.9600,2,1,13.9800,2,1,12.8599,100,1,14.2400,100,1,12.7300,100,1,14.4800,700,1,12.7100,100,1,14.5299,100,1,12.5000,700,1,14.5399,700,1,12.4600,100,1,14.5600,700,1,12.4299,700,1,14.5700,200,2,12.4199,700,1,14.6799,700,1,ARL,339226021
2482,2025-07-17T16:13:06.225829921Z,2025-07-17T16:13:06.225829921Z,10,2,1108,A,A,0,14.2799,100,130,165376,282413699,13.1099,100,1,13.6600,15,1,12.9800,200,2,13.6699,100,1,12.9600,2,1,13.9800,2,1,12.8599,100,1,14.2400,100,1,12.7300,100,1,14.2799,100,1,12.7100,100,1,14.4800,700,1,12.5000,700,1,14.5299,100,1,12.4600,100,1,14.5399,700,1,12.4299,700,1,14.5600,700,1,12.4199,700,1,14.5700,200,2,ARL,339358333
2483,2025-07-17T16:13:06.226624084Z,2025-07-17T16:13:06.226624084Z,10,2,1108,C,A,0,15.3800,100,0,165829,282413738,13.1099,100,1,13.6600,15,1,12.9800,200,2,13.6699,100,1,12.9600,2,1,13.9800,2,1,12.8599,100,1,14.2400,100,1,12.7300,100,1,14.2799,100,1,12.7100,100,1,14.4800,700,1,12.5000,700,1,14.5299,100,1,12.4600,100,1,14.5399,700,1,12.4299,700,1,14.5600,700,1,12.4199,700,1,14.5700,200,2,ARL,339206141
2484,2025-07-17T16:13:06.226624084Z,2025-07-17T16:13:06.226624084Z,10,2,1108,A,A,0,15.0399,100,130,165829,282413738,13.1099,100,1,13.6600,15,1,12.9800,200,2,13.6699,100,1,12.9600,2,1,13.9800,2,1,12.8599,100,1,14.2400,100,1,12.7300,100,1,14.2799,100,1,12.7100,100,1,14.4800,700,1,12.5000,700,1,14.5299,100,1,12.4600,100,1,14.5399,700,1,12.4299,700,1,14.5600,700,1,12.4199,700,1,14.5700,200,2,ARL,339358349
2485,2025-07-17T16:13:06.226716697Z,2025-07-17T16:13:06.226716697Z,10,2,1108,C,A,0,14.9600,100,0,165605,282413745,13.1099,100,1,13.6600,15,1,12.9800,200,2,13.6699,100,1,12.9600,2,1,13.9800,2,1,12.8599,100,1,14.2400,100,1,12.7300,100,1,14.2799,100,1,12.7100,100,1,14.4800,700,1,12.5000,700,1,14.5299,100,1,12.4600,100,1,14.5399,700,1,12.4299,700,1,14.5600,700,1,12.4199,700,1,14.5700,200,2,ARL,339207505
2486,2025-07-17T16:13:06.226716697Z,2025-07-17T16:13:06.226716697Z,10,2,1108,A,A,0,14.6300,100,130,165605,282413745,13.1099,100,1,13.6600,15,1,12.9800,200,2,13.6699,100,1,12.9600,2,1,13.9800,2,1,12.8599,100,1,14.2400,100,1,12.7300,100,1,14.2799,100,1,12.7100,100,1,14.4800,700,1,12.5000,700,1,14.5299,100,1,12.4600,100,1,14.5399,700,1,12.4299,700,1,14.5600,700,1,12.4199,700,1,14.5700,200,2,ARL,339358353
2487,2025-07-17T16:13:06.229693020Z,2025-07-17T16:13:06.229693020Z,10,2,1108,C,A,0,13.9800,2,0,165518,282413801,13.1099,100,1,13.6600,15,1,12.9800,200,2,13.6699,100,1,12.9600,2,1,14.2400,100,1,12.8599,100,1,14.2799,100,1,12.7300,100,1,14.4800,700,1,12.7100,100,1,14.5299,100,1,12.5000,700,1,14.5399,700,1,12.4600,100,1,14.5600,700,1,12.4299,700,1,14.5700,200,2,12.4199,700,1,14.6300,100,1,ARL,339207129
2488,2025-07-17T16:13:06.229693020Z,2025-07-17T16:13:06.229693020Z,10,2,1108,A,A,0,13.8100,2,130,165518,282413801,13.1099,100,1,13.6600,15,1,12.9800,200,2,13.6699,100,1,12.9600,2,1,13.8100,2,1,12.8599,100,1,14.2400,100,1,12.7300,100,1,14.2799,100,1,12.7100,100,1,14.4800,700,1,12.5000,700,1,14.5299,100,1,12.4600,100,1,14.5399,700,1,12.4299,700,1,14.5600,700,1,12.4199,700,1,14.5700,200,2,ARL,339358409
2489,2025-07-17T16:13:06.235428434Z,2025-07-17T16:13:06.235428434Z,10,2,1108,C,A,0,17.7600,100,0,165681,282414050,13.1099,100,1,13.6600,15,1,12.9800,200,2,13.6699,100,1,12.9600,2,1,13.8100,2,1,12.8599,100,1,14.2400,100,1,12.7300,100,1,14.2799,100,1,12.7100,100,1,14.4800,700,1,12.5000,700,1,14.5299,100,1,12.4600,100,1,14.5399,700,1,12.4299,700,1,14.5600,700,1,12.4199,700,1,14.5700,200,2,ARL,339208377
2490,2025-07-17T16:13:06.235428434Z,2025-07-17T16:13:06.235428434Z,10,2,1108,A,A,0,17.3700,100,130,165681,282414050,13.1099,100,1,13.6600,15,1,12.9800,200,2,13.6699,100,1,12.9600,2,1,13.8100,2,1,12.8599,100,1,14.2400,100,1,12.7300,100,1,14.2799,100,1,12.7100,100,1,14.4800,700,1,12.5000,700,1,14.5299,100,1,12.4600,100,1,14.5399,700,1,12.4299,700,1,14.5600,700,1,12.4199,700,1,14.5700,200,2,ARL,339358609
2491,2025-07-17T16:13:06.236401579Z,2025-07-17T16:13:06.236401579Z,10,2,1108,C,A,0,14.2400,100,130,166211,282414131,13.1099,100,1,13.6600,15,1,12.9800,200,2,13.6699,100,1,12.9600,2,1,13.8100,2,1,12.8599,100,1,14.2799,100,1,12.7300,100,1,14.4800,700,1,12.7100,100,1,14.5299,100,1,12.5000,700,1,14.5399,700,1,12.4600,100,1,14.5600,700,1,12.4299,700,1,14.5700,200,2,12.4199,700,1,14.6300,100,1,ARL,339207197
2492,2025-07-17T16:13:06.236456489Z,2025-07-17T16:13:06.236456489Z,10,2,1108,A,A,0,13.9399,100,130,165046,282414141,13.1099,100,1,13.6600,15,1,12.9800,200,2,13.6699,100,1,12.9600,2,1,13.8100,2,1,12.8599,100,1,13.9399,100,1,12.7300,100,1,14.2799,100,1,12.7100,100,1,14.4800,700,1,12.5000,700,1,14.5299,100,1,12.4600,100,1,14.5399,700,1,12.4299,700,1,14.5600,700,1,12.4199,700,1,14.5700,200,2,ARL,339358741
2493,2025-07-17T16:13:06.243743642Z,2025-07-17T16:13:06.243743642Z,10,2,1108,C,A,0,16.0799,100,0,165470,282414340,13.1099,100,1,13.6600,15,1,12.9800,200,2,13.6699,100,1,12.9600,2,1,13.8100,2,1,12.8599,100,1,13.9399,100,1,12.7300,100,1,14.2799,100,1,12.7100,100,1,14.4800,700,1,12.5000,700,1,14.5299,100,1,12.4600,100,1,14.5399,700,1,12.4299,700,1,14.5600,700,1,12.4199,700,1,14.5700,200,2,ARL,339209241
2494,2025-07-17T16:13:06.243743642Z,2025-07-17T16:13:06.243743642Z,10,2,1108,A,A,0,15.7300,100,130,165470,282414340,13.1099,100,1,13.6600,15,1,12.9800,200,2,13.6699,100,1,12.9600,2,1,13.8100,2,1,12.8599,100,1,13.9399,100,1,12.7300,100,1,14.2799,100,1,12.7100,100,1,14.4800,700,1,12.5000,700,1,14.5299,100,1,12.4600,100,1,14.5399,700,1,12.4299,700,1,14.5600,700,1,12.4199,700,1,14.5700,200,2,ARL,339359077
2495,2025-07-17T16:13:06.267886189Z,2025-07-17T16:13:06.267886189Z,10,2,1108,C,A,0,15.3800,100,0,165904,282414570,13.1099,100,1,13.6600,15,1,12.9800,200,2,13.6699,100,1,12.9600,2,1,13.8100,2,1,12.8599,100,1,13.9399,100,1,12.7300,100,1,14.2799,100,1,12.7100,100,1,14.4800,700,1,12.5000,700,1,14.5299,100,1,12.4600,100,1,14.5399,700,1,12.4299,700,1,14.5600,700,1,12.4199,700,1,14.5700,200,2,ARL,339215205
2496,2025-07-17T16:13:06.267886189Z,2025-07-17T16:13:06.267886189Z,10,2,1108,A,A,0,15.0399,100,130,165904,282414570,13.1099,100,1,13.6600,15,1,12.9800,200,2,13.6699,100,1,12.9600,2,1,13.8100,2,1,12.8599,100,1,13.9399,100,1,12.7300,100,1,14.2799,100,1,12.7100,100,1,14.4800,700,1,12.5000,700,1,14.5299,100,1,12.4600,100,1,14.5399,700,1,12.4299,700,1,14.5600,700,1,12.4199,700,1,14.5700,200,2,ARL,339359357
2497,2025-07-17T16:13:06.275720866Z,2025-07-17T16:13:06.275720866Z,10,2,1108,C,A,0,14.9600,100,0,165595,282414642,13.1099,100,1,13.6600,15,1,12.9800,200,2,13.6699,100,1,12.9600,2,1,13.8100,2,1,12.8599,100,1,13.9399,100,1,12.7300,100,1,14.2799,100,1,12.7100,100,1,14.4800,700,1,12.5000,700,1,14.5299,100,1,12.4600,100,1,14.5399,700,1,12.4299,700,1,14.5600,700,1,12.4199,700,1,14.5700,200,2,ARL,339216161
2498,2025-07-17T16:13:06.275720866Z,2025-07-17T16:13:06.275720866Z,10,2,1108,A,A,0,14.6300,100,130,165595,282414642,13.1099,100,1,13.6600,15,1,12.9800,200,2,13.6699,100,1,12.9600,2,1,13.8100,2,1,12.8599,100,1,13.9399,100,1,12.7300,100,1,14.2799,100,1,12.7100,100,1,14.4800,700,1,12.5000,700,1,14.5299,100,1,12.4600,100,1,14.5399,700,1,12.4299,700,1,14.5600,700,1,12.4199,700,1,14.5700,200,2,ARL,339359401
2499,2025-07-17T16:13:06.276882863Z,2025-07-17T16:13:06.276882863Z,10,2,1108,C,A,0,14.7699,100,130,165397,282414659,13.1099,100,1,13.6600,15,1,12.9800,200,2,13.6699,100,1,12.9600,2,1,13.8100,2,1,12.8599,100,1,13.9399,100,1,12.7300,100,1,14.2799,100,1,12.7100,100,1,14.4800,700,1,12.5000,700,1,14.5299,100,1,12.4600,100,1,14.5399,700,1,12.4299,700,1,14.5600,700,1,12.4199,700,1,14.5700,200,2,ARL,339232213
2500,2025-07-17T16:13:06.277013512Z,2025-07-17T16:13:06.277013512Z,10,2,1108,A,A,0,14.4600,100,130,165402,282414660,13.1099,100,1,13.6600,15,1,12.9800,200,2,13.6699,100,1,12.9600,2,1,13.8100,2,1,12.8599,100,1,13.9399,100,1,12.7300,100,1,14.2799,100,1,12.7100,100,1,14.4600,100,1,12.5000,700,1,14.4800,700,1,12.4600,100,1,14.5299,100,1,12.4299,700,1,14.5399,700,1,12.4199,700,1,14.5600,700,1,ARL,339359421
2501,2025-07-17T16:13:06.622493734Z,2025-07-17T16:13:06.622493734Z,10,2,1108,A,A,0,14.2200,100,130,165368,282418746,13.1099,100,1,13.6600,15,1,12.9800,200,2,13.6699,100,1,12.9600,2,1,13.8100,2,1,12.8599,100,1,13.9399,100,1,12.7300,100,1,14.2200,100,1,12.7100,100,1,14.2799,100,1,12.5000,700,1,14.4600,100,1,12.4600,100,1,14.4800,700,1,12.4299,700,1,14.5299,100,1,12.4199,700,1,14.5399,700,1,ARL,339365193
2502,2025-07-17T16:13:06.663671305Z,2025-07-17T16:13:06.663671305Z,10,2,1108,C,A,0,14.5299,100,130,165439,282418921,13.1099,100,1,13.6600,15,1,12.9800,200,2,13.6699,100,1,12.9600,2,1,13.8100,2,1,12.8599,100,1,13.9399,100,1,12.7300,100,1,14.2200,100,1,12.7100,100,1,14.2799,100,1,12.5000,700,1,14.4600,100,1,12.4600,100,1,14.4800,700,1,12.4299,700,1,14.5399,700,1,12.4199,700,1,14.5600,700,1,ARL,339225769
2503,2025-07-17T16:13:06.759625628Z,2025-07-17T16:13:06.759625628Z,10,2,1108,A,A,0,14.4900,100,130,165475,282419471,13.1099,100,1,13.6600,15,1,12.9800,200,2,13.6699,100,1,12.9600,2,1,13.8100,2,1,12.8599,100,1,13.9399,100,1,12.7300,100,1,14.2200,100,1,12.7100,100,1,14.2799,100,1,12.5000,700,1,14.4600,100,1,12.4600,100,1,14.4800,700,1,12.4299,700,1,14.4900,100,1,12.4199,700,1,14.5399,700,1,ARL,339366385
2504,2025-07-17T16:13:06.759638890Z,2025-07-17T16:13:06.759638890Z,10,2,1108,C,A,0,14.8100,100,130,165751,282419472,13.1099,100,1,13.6600,15,1,12.9800,200,2,13.6699,100,1,12.9600,2,1,13.8100,2,1,12.8599,100,1,13.9399,100,1,12.7300,100,1,14.2200,100,1,12.7100,100,1,14.2799,100,1,12.5000,700,1,14.4600,100,1,12.4600,100,1,14.4800,700,1,12.4299,700,1,14.4900,100,1,12.4199,700,1,14.5399,700,1,ARL,339225885
2505,2025-07-17T16:13:09.353883614Z,2025-07-17T16:13:09.353883614Z,10,2,1108,A,A,0,13.6400,15,130,165126,282469242,13.1099,100,1,13.6400,15,1,12.9800,200,2,13.6600,15,1,12.9600,2,1,13.6699,100,1,12.8599,100,1,13.8100,2,1,12.7300,100,1,13.9399,100,1,12.7100,100,1,14.2200,100,1,12.5000,700,1,14.2799,100,1,12.4600,100,1,14.4600,100,1,12.4299,700,1,14.4800,700,1,12.4199,700,1,14.4900,100,1,ARL,339425837
2506,2025-07-17T16:13:09.368030843Z,2025-07-17T16:13:09.368030843Z,10,2,1108,C,A,0,13.6699,100,0,166816,282470466,13.1099,100,1,13.6400,15,1,12.9800,200,2,13.6600,15,1,12.9600,2,1,13.8100,2,1,12.8599,100,1,13.9399,100,1,12.7300,100,1,14.2200,100,1,12.7100,100,1,14.2799,100,1,12.5000,700,1,14.4600,100,1,12.4600,100,1,14.4800,700,1,12.4299,700,1,14.4900,100,1,12.4199,700,1,14.5399,700,1,ARL,339358233
2507,2025-07-17T16:13:09.368030843Z,2025-07-17T16:13:09.368030843Z,10,2,1108,A,A,0,13.6500,100,128,166816,282470466,13.1099,100,1,13.6400,15,1,12.9800,200,2,13.6500,100,1,12.9600,2,1,13.6600,15,1,12.8599,100,1,13.8100,2,1,12.7300,100,1,13.9399,100,1,12.7100,100,1,14.2200,100,1,12.5000,700,1,14.2799,100,1,12.4600,100,1,14.4600,100,1,12.4299,700,1,14.4800,700,1,12.4199,700,1,14.4900,100,1,ARL,339427217
2508,2025-07-17T16:13:14.046102556Z,2025-07-17T16:13:14.046102556Z,10,2,1108,C,A,0,13.6600,15,130,165319,282563502,13.1099,100,1,13.6400,15,1,12.9800,200,2,13.6500,100,1,12.9600,2,1,13.8100,2,1,12.8599,100,1,13.9399,100,1,12.7300,100,1,14.2200,100,1,12.7100,100,1,14.2799,100,1,12.5000,700,1,14.4600,100,1,12.4600,100,1,14.4800,700,1,12.4299,700,1,14.4900,100,1,12.4199,700,1,14.5399,700,1,ARL,339332865
2509,2025-07-17T16:13:17.775045316Z,2025-07-17T16:13:17.775045316Z,10,2,1108,A,A,0,13.5700,15,130,165600,282616566,13.1099,100,1,13.5700,15,1,12.9800,200,2,13.6400,15,1,12.9600,2,1,13.6500,100,1,12.8599,100,1,13.8100,2,1,12.7300,100,1,13.9399,100,1,12.7100,100,1,14.2200,100,1,12.5000,700,1,14.2799,100,1,12.4600,100,1,14.4600,100,1,12.4299,700,1,14.4800,700,1,12.4199,700,1,14.4900,100,1,ARL,339610637
